{
  "version": 8,
  "blockIdVersion": 11,
  "anchorX": 0,
  "anchorY": 2,
  "anchorZ": 1,
  "blocks": [
    {
      "x": -5,
      "y": 2,
      "z": 0,
      "name": "Soil_Dirt_Half",
      "rotation": 7
    },
    {
      "x": -5,
      "y": 2,
      "z": 1,
      "name": "Soil_Dirt_Half",
      "rotation": 7
    },
    {
      "x": -5,
      "y": 2,
      "z": 2,
      "name": "Soil_Dirt_Half",
      "rotation": 7
    },
    {
      "x": -4,
      "y": 2,
      "z": -2,
      "name": "Soil_Dirt_Half",
      "rotation": 7
    },
    {
      "x": -4,
      "y": 0,
      "z": -1,
      "name": "Rock_Stone"
    },
    {
      "x": -4,
      "y": 1,
      "z": -1,
      "name": "Soil_Dirt"
    },
    {
      "x": -4,
      "y": 2,
      "z": -1,
      "name": "Soil_Dirt"
    },
    {
      "x": -4,
      "y": 3,
      "z": -1,
      "name": "Soil_Dirt_Stairs",
      "rotation": 3
    },
    {
      "x": -4,
      "y": 0,
      "z": 0,
      "name": "Rock_Stone"
    },
    {
      "x": -4,
      "y": 1,
      "z": 0,
      "name": "Soil_Pathway"
    },
    {
      "x": -4,
      "y": 2,
      "z": 0,
      "name": "Soil_Dirt"
    },
    {
      "x": -4,
      "y": 3,
      "z": 0,
      "name": "Soil_Dirt_Stairs",
      "rotation": 3
    },
    {
      "x": -4,
      "y": 0,
      "z": 1,
      "name": "Rock_Stone"
    },
    {
      "x": -4,
      "y": 1,
      "z": 1,
      "name": "Soil_Pathway"
    },
    {
      "x": -4,
      "y": 2,
      "z": 1,
      "name": "Soil_Dirt"
    },
    {
      "x": -4,
      "y": 3,
      "z": 1,
      "name": "Soil_Dirt"
    },
    {
      "x": -4,
      "y": 4,
      "z": 1,
      "name": "Soil_Dirt_Half"
    },
    {
      "x": -4,
      "y": -2,
      "z": 2,
      "name": "Rock_Stone"
    },
    {
      "x": -4,
      "y": -1,
      "z": 2,
      "name": "Rock_Stone"
    },
    {
      "x": -4,
      "y": 0,
      "z": 2,
      "name": "Rock_Stone"
    },
    {
      "x": -4,
      "y": 1,
      "z": 2,
      "name": "Rock_Stone"
    },
    {
      "x": -4,
      "y": 2,
      "z": 2,
      "name": "Soil_Dirt"
    },
    {
      "x": -4,
      "y": 3,
      "z": 2,
      "name": "Soil_Dirt_Stairs",
      "rotation": 3
    },
    {
      "x": -4,
      "y": 0,
      "z": 3,
      "name": "Rock_Stone"
    },
    {
      "x": -4,
      "y": 1,
      "z": 3,
      "name": "Rock_Stone"
    },
    {
      "x": -4,
      "y": 2,
      "z": 3,
      "name": "Soil_Dirt"
    },
    {
      "x": -4,
      "y": 3,
      "z": 3,
      "name": "Soil_Dirt_Stairs",
      "rotation": 3
    },
    {
      "x": -3,
      "y": 2,
      "z": -3,
      "name": "Soil_Dirt_Half",
      "rotation": 7
    },
    {
      "x": -3,
      "y": -1,
      "z": -2,
      "name": "Rock_Stone"
    },
    {
      "x": -3,
      "y": 0,
      "z": -2,
      "name": "Rock_Stone"
    },
    {
      "x": -3,
      "y": 1,
      "z": -2,
      "name": "Soil_Dirt"
    },
    {
      "x": -3,
      "y": 2,
      "z": -2,
      "name": "Soil_Dirt"
    },
    {
      "x": -3,
      "y": 3,
      "z": -2,
      "name": "Soil_Dirt_Stairs",
      "rotation": 2
    },
    {
      "x": -3,
      "y": -2,
      "z": -1,
      "name": "Rock_Stone"
    },
    {
      "x": -3,
      "y": -1,
      "z": -1,
      "name": "Rock_Stone"
    },
    {
      "x": -3,
      "y": 0,
      "z": -1,
      "name": "Rock_Stone"
    },
    {
      "x": -3,
      "y": 1,
      "z": -1,
      "name": "Rock_Stone"
    },
    {
      "x": -3,
      "y": 2,
      "z": -1,
      "name": "Soil_Dirt"
    },
    {
      "x": -3,
      "y": 3,
      "z": -1,
      "name": "Soil_Dirt"
    },
    {
      "x": -3,
      "y": 4,
      "z": -1,
      "name": "Soil_Dirt_Half"
    },
    {
      "x": -3,
      "y": -3,
      "z": 0,
      "name": "Rock_Stone"
    },
    {
      "x": -3,
      "y": -2,
      "z": 0,
      "name": "Rock_Stone"
    },
    {
      "x": -3,
      "y": -1,
      "z": 0,
      "name": "Rock_Stone"
    },
    {
      "x": -3,
      "y": 0,
      "z": 0,
      "name": "Rock_Stone"
    },
    {
      "x": -3,
      "y": 1,
      "z": 0,
      "name": "Rock_Stone"
    },
    {
      "x": -3,
      "y": 2,
      "z": 0,
      "name": "Soil_Dirt"
    },
    {
      "x": -3,
      "y": 3,
      "z": 0,
      "name": "Soil_Dirt"
    },
    {
      "x": -3,
      "y": 4,
      "z": 0,
      "name": "Soil_Dirt_Half"
    },
    {
      "x": -3,
      "y": -3,
      "z": 1,
      "name": "Rock_Stone"
    },
    {
      "x": -3,
      "y": -2,
      "z": 1,
      "name": "Rock_Stone"
    },
    {
      "x": -3,
      "y": -1,
      "z": 1,
      "name": "Rock_Stone"
    },
    {
      "x": -3,
      "y": 0,
      "z": 1,
      "name": "Rock_Stone"
    },
    {
      "x": -3,
      "y": 1,
      "z": 1,
      "name": "Rock_Stone"
    },
    {
      "x": -3,
      "y": 2,
      "z": 1,
      "name": "Soil_Dirt"
    },
    {
      "x": -3,
      "y": 3,
      "z": 1,
      "name": "Soil_Dirt"
    },
    {
      "x": -3,
      "y": 4,
      "z": 1,
      "name": "Soil_Dirt_Half"
    },
    {
      "x": -3,
      "y": -3,
      "z": 2,
      "name": "Rock_Stone"
    },
    {
      "x": -3,
      "y": -2,
      "z": 2,
      "name": "Rock_Stone"
    },
    {
      "x": -3,
      "y": -1,
      "z": 2,
      "name": "Rock_Stone"
    },
    {
      "x": -3,
      "y": 0,
      "z": 2,
      "name": "Rock_Stone"
    },
    {
      "x": -3,
      "y": 1,
      "z": 2,
      "name": "Rock_Stone"
    },
    {
      "x": -3,
      "y": 2,
      "z": 2,
      "name": "Rock_Stone"
    },
    {
      "x": -3,
      "y": 3,
      "z": 2,
      "name": "Soil_Dirt"
    },
    {
      "x": -3,
      "y": 4,
      "z": 2,
      "name": "Soil_Dirt_Half"
    },
    {
      "x": -3,
      "y": -3,
      "z": 3,
      "name": "Rock_Stone"
    },
    {
      "x": -3,
      "y": -2,
      "z": 3,
      "name": "Rock_Stone"
    },
    {
      "x": -3,
      "y": -1,
      "z": 3,
      "name": "Rock_Stone"
    },
    {
      "x": -3,
      "y": 0,
      "z": 3,
      "name": "Rock_Stone"
    },
    {
      "x": -3,
      "y": 1,
      "z": 3,
      "name": "Rock_Stone"
    },
    {
      "x": -3,
      "y": 2,
      "z": 3,
      "name": "Rock_Stone"
    },
    {
      "x": -3,
      "y": 3,
      "z": 3,
      "name": "Soil_Dirt"
    },
    {
      "x": -3,
      "y": 4,
      "z": 3,
      "name": "Soil_Dirt_Half"
    },
    {
      "x": -3,
      "y": -1,
      "z": 4,
      "name": "Rock_Stone"
    },
    {
      "x": -3,
      "y": 0,
      "z": 4,
      "name": "Rock_Stone"
    },
    {
      "x": -3,
      "y": 1,
      "z": 4,
      "name": "Rock_Stone"
    },
    {
      "x": -3,
      "y": 2,
      "z": 4,
      "name": "Rock_Stone"
    },
    {
      "x": -3,
      "y": 3,
      "z": 4,
      "name": "Soil_Dirt_Stairs",
      "rotation": 3
    },
    {
      "x": -3,
      "y": 2,
      "z": 5,
      "name": "Soil_Dirt_Half",
      "rotation": 7
    },
    {
      "x": -2,
      "y": 2,
      "z": -4,
      "name": "Soil_Dirt_Half",
      "rotation": 6
    },
    {
      "x": -2,
      "y": 1,
      "z": -3,
      "name": "Soil_Dirt"
    },
    {
      "x": -2,
      "y": 2,
      "z": -3,
      "name": "Soil_Dirt"
    },
    {
      "x": -2,
      "y": 3,
      "z": -3,
      "name": "Soil_Dirt_Stairs",
      "rotation": 3
    },
    {
      "x": -2,
      "y": -2,
      "z": -2,
      "name": "Rock_Stone"
    },
    {
      "x": -2,
      "y": -1,
      "z": -2,
      "name": "Rock_Stone"
    },
    {
      "x": -2,
      "y": 0,
      "z": -2,
      "name": "Rock_Stone"
    },
    {
      "x": -2,
      "y": 1,
      "z": -2,
      "name": "Soil_Dirt"
    },
    {
      "x": -2,
      "y": 2,
      "z": -2,
      "name": "Soil_Dirt"
    },
    {
      "x": -2,
      "y": 3,
      "z": -2,
      "name": "Soil_Dirt"
    },
    {
      "x": -2,
      "y": 4,
      "z": -2,
      "name": "Soil_Dirt_Half"
    },
    {
      "x": -2,
      "y": -3,
      "z": -1,
      "name": "Rock_Stone"
    },
    {
      "x": -2,
      "y": -2,
      "z": -1,
      "name": "Rock_Stone"
    },
    {
      "x": -2,
      "y": -1,
      "z": -1,
      "name": "Rock_Stone"
    },
    {
      "x": -2,
      "y": 0,
      "z": -1,
      "name": "Rock_Stone"
    },
    {
      "x": -2,
      "y": 1,
      "z": -1,
      "name": "Rock_Stone"
    },
    {
      "x": -2,
      "y": 2,
      "z": -1,
      "name": "Soil_Dirt"
    },
    {
      "x": -2,
      "y": 3,
      "z": -1,
      "name": "Soil_Dirt"
    },
    {
      "x": -2,
      "y": 4,
      "z": -1,
      "name": "Soil_Pathway_Half"
    },
    {
      "x": -2,
      "y": -3,
      "z": 0,
      "name": "Rock_Stone"
    },
    {
      "x": -2,
      "y": -2,
      "z": 0,
      "name": "Rock_Stone"
    },
    {
      "x": -2,
      "y": -1,
      "z": 0,
      "name": "Rock_Stone"
    },
    {
      "x": -2,
      "y": 0,
      "z": 0,
      "name": "Rock_Stone"
    },
    {
      "x": -2,
      "y": 1,
      "z": 0,
      "name": "Soil_Dirt"
    },
    {
      "x": -2,
      "y": 2,
      "z": 0,
      "name": "Soil_Dirt"
    },
    {
      "x": -2,
      "y": 3,
      "z": 0,
      "name": "Soil_Dirt"
    },
    {
      "x": -2,
      "y": 4,
      "z": 0,
      "name": "Plant_Bush_Arid_Sharp",
      "support": 15
    },
    {
      "x": -2,
      "y": -4,
      "z": 1,
      "name": "Rock_Stone"
    },
    {
      "x": -2,
      "y": -3,
      "z": 1,
      "name": "Rock_Stone"
    },
    {
      "x": -2,
      "y": -2,
      "z": 1,
      "name": "Rock_Stone"
    },
    {
      "x": -2,
      "y": -1,
      "z": 1,
      "name": "Rock_Stone"
    },
    {
      "x": -2,
      "y": 0,
      "z": 1,
      "name": "Rock_Stone"
    },
    {
      "x": -2,
      "y": 1,
      "z": 1,
      "name": "Rock_Stone"
    },
    {
      "x": -2,
      "y": 2,
      "z": 1,
      "name": "Soil_Dirt"
    },
    {
      "x": -2,
      "y": 3,
      "z": 1,
      "name": "Soil_Dirt"
    },
    {
      "x": -2,
      "y": 4,
      "z": 1,
      "name": "Plant_Bush_Arid_Sharp",
      "support": 15
    },
    {
      "x": -2,
      "y": -3,
      "z": 2,
      "name": "Rock_Stone"
    },
    {
      "x": -2,
      "y": -2,
      "z": 2,
      "name": "Rock_Stone"
    },
    {
      "x": -2,
      "y": -1,
      "z": 2,
      "name": "Rock_Stone"
    },
    {
      "x": -2,
      "y": 0,
      "z": 2,
      "name": "Rock_Stone"
    },
    {
      "x": -2,
      "y": 1,
      "z": 2,
      "name": "Rock_Stone"
    },
    {
      "x": -2,
      "y": 2,
      "z": 2,
      "name": "Soil_Dirt"
    },
    {
      "x": -2,
      "y": 3,
      "z": 2,
      "name": "Soil_Dirt"
    },
    {
      "x": -2,
      "y": 4,
      "z": 2,
      "name": "Plant_Bush_Arid_Sharp",
      "support": 15
    },
    {
      "x": -2,
      "y": -3,
      "z": 3,
      "name": "Rock_Stone"
    },
    {
      "x": -2,
      "y": -2,
      "z": 3,
      "name": "Rock_Stone"
    },
    {
      "x": -2,
      "y": -1,
      "z": 3,
      "name": "Rock_Stone"
    },
    {
      "x": -2,
      "y": 0,
      "z": 3,
      "name": "Rock_Stone"
    },
    {
      "x": -2,
      "y": 1,
      "z": 3,
      "name": "Rock_Stone"
    },
    {
      "x": -2,
      "y": 2,
      "z": 3,
      "name": "Soil_Dirt"
    },
    {
      "x": -2,
      "y": 3,
      "z": 3,
      "name": "Soil_Dirt"
    },
    {
      "x": -2,
      "y": 4,
      "z": 3,
      "name": "Soil_Pathway_Half"
    },
    {
      "x": -2,
      "y": -2,
      "z": 4,
      "name": "Rock_Stone"
    },
    {
      "x": -2,
      "y": -1,
      "z": 4,
      "name": "Rock_Stone"
    },
    {
      "x": -2,
      "y": 0,
      "z": 4,
      "name": "Rock_Stone"
    },
    {
      "x": -2,
      "y": 1,
      "z": 4,
      "name": "Rock_Stone"
    },
    {
      "x": -2,
      "y": 2,
      "z": 4,
      "name": "Soil_Dirt"
    },
    {
      "x": -2,
      "y": 3,
      "z": 4,
      "name": "Soil_Dirt"
    },
    {
      "x": -2,
      "y": 4,
      "z": 4,
      "name": "Soil_Dirt_Half"
    },
    {
      "x": -2,
      "y": -1,
      "z": 5,
      "name": "Rock_Stone"
    },
    {
      "x": -2,
      "y": 0,
      "z": 5,
      "name": "Rock_Stone"
    },
    {
      "x": -2,
      "y": 1,
      "z": 5,
      "name": "Soil_Pathway"
    },
    {
      "x": -2,
      "y": 2,
      "z": 5,
      "name": "Soil_Dirt"
    },
    {
      "x": -2,
      "y": 3,
      "z": 5,
      "name": "Soil_Dirt_Stairs"
    },
    {
      "x": -2,
      "y": 2,
      "z": 6,
      "name": "Soil_Dirt_Half",
      "rotation": 4
    },
    {
      "x": -1,
      "y": 0,
      "z": -4,
      "name": "Soil_Dirt"
    },
    {
      "x": -1,
      "y": 1,
      "z": -4,
      "name": "Soil_Dirt"
    },
    {
      "x": -1,
      "y": 2,
      "z": -4,
      "name": "Soil_Dirt"
    },
    {
      "x": -1,
      "y": 3,
      "z": -4,
      "name": "Soil_Dirt_Stairs",
      "rotation": 2
    },
    {
      "x": -1,
      "y": -2,
      "z": -3,
      "name": "Rock_Stone"
    },
    {
      "x": -1,
      "y": -1,
      "z": -3,
      "name": "Rock_Stone"
    },
    {
      "x": -1,
      "y": 0,
      "z": -3,
      "name": "Rock_Stone"
    },
    {
      "x": -1,
      "y": 1,
      "z": -3,
      "name": "Soil_Dirt"
    },
    {
      "x": -1,
      "y": 2,
      "z": -3,
      "name": "Soil_Dirt"
    },
    {
      "x": -1,
      "y": 3,
      "z": -3,
      "name": "Soil_Dirt"
    },
    {
      "x": -1,
      "y": 4,
      "z": -3,
      "name": "Soil_Dirt_Half"
    },
    {
      "x": -1,
      "y": -2,
      "z": -2,
      "name": "Rock_Stone"
    },
    {
      "x": -1,
      "y": -1,
      "z": -2,
      "name": "Rock_Stone"
    },
    {
      "x": -1,
      "y": 0,
      "z": -2,
      "name": "Rock_Stone"
    },
    {
      "x": -1,
      "y": 1,
      "z": -2,
      "name": "Soil_Dirt"
    },
    {
      "x": -1,
      "y": 2,
      "z": -2,
      "name": "Soil_Dirt"
    },
    {
      "x": -1,
      "y": 3,
      "z": -2,
      "name": "Soil_Dirt"
    },
    {
      "x": -1,
      "y": 4,
      "z": -2,
      "name": "Soil_Dirt_Half"
    },
    {
      "x": -1,
      "y": -3,
      "z": -1,
      "name": "Rock_Stone"
    },
    {
      "x": -1,
      "y": -2,
      "z": -1,
      "name": "Rock_Stone"
    },
    {
      "x": -1,
      "y": -1,
      "z": -1,
      "name": "Rock_Stone"
    },
    {
      "x": -1,
      "y": 0,
      "z": -1,
      "name": "Rock_Stone"
    },
    {
      "x": -1,
      "y": 1,
      "z": -1,
      "name": "Rock_Stone"
    },
    {
      "x": -1,
      "y": 2,
      "z": -1,
      "name": "Soil_Dirt"
    },
    {
      "x": -1,
      "y": 3,
      "z": -1,
      "name": "Soil_Dirt"
    },
    {
      "x": -1,
      "y": 4,
      "z": -1,
      "name": "Plant_Bush_Arid_Sharp",
      "support": 15
    },
    {
      "x": -1,
      "y": -4,
      "z": 0,
      "name": "Rock_Stone"
    },
    {
      "x": -1,
      "y": -3,
      "z": 0,
      "name": "Rock_Stone"
    },
    {
      "x": -1,
      "y": -2,
      "z": 0,
      "name": "Rock_Stone"
    },
    {
      "x": -1,
      "y": -1,
      "z": 0,
      "name": "Rock_Stone"
    },
    {
      "x": -1,
      "y": 0,
      "z": 0,
      "name": "Rock_Stone"
    },
    {
      "x": -1,
      "y": 1,
      "z": 0,
      "name": "Rock_Stone"
    },
    {
      "x": -1,
      "y": 2,
      "z": 0,
      "name": "Soil_Dirt"
    },
    {
      "x": -1,
      "y": 3,
      "z": 0,
      "name": "Soil_Dirt"
    },
    {
      "x": -1,
      "y": 4,
      "z": 0,
      "name": "Plant_Leaves_Jungle_Floor",
      "support": 15
    },
    {
      "x": -1,
      "y": -4,
      "z": 1,
      "name": "Rock_Stone"
    },
    {
      "x": -1,
      "y": -3,
      "z": 1,
      "name": "Rock_Stone"
    },
    {
      "x": -1,
      "y": -2,
      "z": 1,
      "name": "Rock_Stone"
    },
    {
      "x": -1,
      "y": -1,
      "z": 1,
      "name": "Rock_Stone"
    },
    {
      "x": -1,
      "y": 0,
      "z": 1,
      "name": "Rock_Stone"
    },
    {
      "x": -1,
      "y": 1,
      "z": 1,
      "name": "Soil_Dirt"
    },
    {
      "x": -1,
      "y": 2,
      "z": 1,
      "name": "Soil_Dirt"
    },
    {
      "x": -1,
      "y": 3,
      "z": 1,
      "name": "Soil_Dirt"
    },
    {
      "x": -1,
      "y": 4,
      "z": 1,
      "name": "Deco_Raptor_Eggs"
    },
    {
      "x": -1,
      "y": -4,
      "z": 2,
      "name": "Rock_Stone"
    },
    {
      "x": -1,
      "y": -3,
      "z": 2,
      "name": "Rock_Stone"
    },
    {
      "x": -1,
      "y": -2,
      "z": 2,
      "name": "Rock_Stone"
    },
    {
      "x": -1,
      "y": -1,
      "z": 2,
      "name": "Rock_Stone"
    },
    {
      "x": -1,
      "y": 0,
      "z": 2,
      "name": "Rock_Stone"
    },
    {
      "x": -1,
      "y": 1,
      "z": 2,
      "name": "Rock_Stone"
    },
    {
      "x": -1,
      "y": 2,
      "z": 2,
      "name": "Soil_Dirt"
    },
    {
      "x": -1,
      "y": 3,
      "z": 2,
      "name": "Soil_Dirt"
    },
    {
      "x": -1,
      "y": 4,
      "z": 2,
      "name": "Plant_Leaves_Jungle_Floor",
      "support": 15
    },
    {
      "x": -1,
      "y": -3,
      "z": 3,
      "name": "Rock_Stone"
    },
    {
      "x": -1,
      "y": -2,
      "z": 3,
      "name": "Rock_Stone"
    },
    {
      "x": -1,
      "y": -1,
      "z": 3,
      "name": "Rock_Stone"
    },
    {
      "x": -1,
      "y": 0,
      "z": 3,
      "name": "Rock_Stone"
    },
    {
      "x": -1,
      "y": 1,
      "z": 3,
      "name": "Rock_Stone"
    },
    {
      "x": -1,
      "y": 2,
      "z": 3,
      "name": "Soil_Dirt"
    },
    {
      "x": -1,
      "y": 3,
      "z": 3,
      "name": "Soil_Dirt"
    },
    {
      "x": -1,
      "y": 4,
      "z": 3,
      "name": "Plant_Bush_Arid_Sharp",
      "support": 15
    },
    {
      "x": -1,
      "y": -2,
      "z": 4,
      "name": "Rock_Stone"
    },
    {
      "x": -1,
      "y": -1,
      "z": 4,
      "name": "Rock_Stone"
    },
    {
      "x": -1,
      "y": 0,
      "z": 4,
      "name": "Rock_Stone"
    },
    {
      "x": -1,
      "y": 1,
      "z": 4,
      "name": "Soil_Dirt"
    },
    {
      "x": -1,
      "y": 2,
      "z": 4,
      "name": "Soil_Dirt"
    },
    {
      "x": -1,
      "y": 3,
      "z": 4,
      "name": "Soil_Dirt"
    },
    {
      "x": -1,
      "y": 4,
      "z": 4,
      "name": "Soil_Dirt_Half"
    },
    {
      "x": -1,
      "y": -2,
      "z": 5,
      "name": "Rock_Stone"
    },
    {
      "x": -1,
      "y": -1,
      "z": 5,
      "name": "Rock_Stone"
    },
    {
      "x": -1,
      "y": 0,
      "z": 5,
      "name": "Rock_Stone"
    },
    {
      "x": -1,
      "y": 1,
      "z": 5,
      "name": "Soil_Pathway"
    },
    {
      "x": -1,
      "y": 2,
      "z": 5,
      "name": "Soil_Dirt"
    },
    {
      "x": -1,
      "y": 3,
      "z": 5,
      "name": "Soil_Dirt_Stairs"
    },
    {
      "x": -1,
      "y": 2,
      "z": 6,
      "name": "Soil_Dirt_Half",
      "rotation": 4
    },
    {
      "x": 0,
      "y": 2,
      "z": -5,
      "name": "Soil_Dirt_Half",
      "rotation": 6
    },
    {
      "x": 0,
      "y": -1,
      "z": -4,
      "name": "Rock_Stone"
    },
    {
      "x": 0,
      "y": 0,
      "z": -4,
      "name": "Rock_Stone"
    },
    {
      "x": 0,
      "y": 1,
      "z": -4,
      "name": "Soil_Dirt"
    },
    {
      "x": 0,
      "y": 2,
      "z": -4,
      "name": "Soil_Dirt"
    },
    {
      "x": 0,
      "y": 3,
      "z": -4,
      "name": "Soil_Dirt_Stairs",
      "rotation": 2
    },
    {
      "x": 0,
      "y": -2,
      "z": -3,
      "name": "Rock_Stone"
    },
    {
      "x": 0,
      "y": -1,
      "z": -3,
      "name": "Rock_Stone"
    },
    {
      "x": 0,
      "y": 0,
      "z": -3,
      "name": "Rock_Stone"
    },
    {
      "x": 0,
      "y": 1,
      "z": -3,
      "name": "Rock_Stone"
    },
    {
      "x": 0,
      "y": 2,
      "z": -3,
      "name": "Soil_Dirt"
    },
    {
      "x": 0,
      "y": 3,
      "z": -3,
      "name": "Soil_Dirt"
    },
    {
      "x": 0,
      "y": 4,
      "z": -3,
      "name": "Soil_Dirt_Half"
    },
    {
      "x": 0,
      "y": -3,
      "z": -2,
      "name": "Rock_Stone"
    },
    {
      "x": 0,
      "y": -2,
      "z": -2,
      "name": "Rock_Stone"
    },
    {
      "x": 0,
      "y": -1,
      "z": -2,
      "name": "Rock_Stone"
    },
    {
      "x": 0,
      "y": 0,
      "z": -2,
      "name": "Rock_Stone"
    },
    {
      "x": 0,
      "y": 1,
      "z": -2,
      "name": "Soil_Dirt"
    },
    {
      "x": 0,
      "y": 2,
      "z": -2,
      "name": "Soil_Dirt"
    },
    {
      "x": 0,
      "y": 3,
      "z": -2,
      "name": "Soil_Dirt"
    },
    {
      "x": 0,
      "y": 4,
      "z": -2,
      "name": "Plant_Bush_Arid_Sharp",
      "support": 15
    },
    {
      "x": 0,
      "y": -4,
      "z": -1,
      "name": "Rock_Stone"
    },
    {
      "x": 0,
      "y": -3,
      "z": -1,
      "name": "Rock_Stone"
    },
    {
      "x": 0,
      "y": -2,
      "z": -1,
      "name": "Rock_Stone"
    },
    {
      "x": 0,
      "y": -1,
      "z": -1,
      "name": "Rock_Stone"
    },
    {
      "x": 0,
      "y": 0,
      "z": -1,
      "name": "Rock_Stone"
    },
    {
      "x": 0,
      "y": 1,
      "z": -1,
      "name": "Rock_Stone"
    },
    {
      "x": 0,
      "y": 2,
      "z": -1,
      "name": "Soil_Dirt"
    },
    {
      "x": 0,
      "y": 3,
      "z": -1,
      "name": "Soil_Dirt"
    },
    {
      "x": 0,
      "y": 4,
      "z": -1,
      "name": "Plant_Petals_White"
    },
    {
      "x": 0,
      "y": -4,
      "z": 0,
      "name": "Rock_Stone"
    },
    {
      "x": 0,
      "y": -3,
      "z": 0,
      "name": "Rock_Stone"
    },
    {
      "x": 0,
      "y": -2,
      "z": 0,
      "name": "Rock_Stone"
    },
    {
      "x": 0,
      "y": -1,
      "z": 0,
      "name": "Rock_Stone"
    },
    {
      "x": 0,
      "y": 0,
      "z": 0,
      "name": "Rock_Stone"
    },
    {
      "x": 0,
      "y": 1,
      "z": 0,
      "name": "Soil_Dirt"
    },
    {
      "x": 0,
      "y": 2,
      "z": 0,
      "name": "Soil_Dirt"
    },
    {
      "x": 0,
      "y": 3,
      "z": 0,
      "name": "Soil_Dirt"
    },
    {
      "x": 0,
      "y": 4,
      "z": 0,
      "name": "Deco_Raptor_Eggs"
    },
    {
      "x": 0,
      "y": -4,
      "z": 1,
      "name": "Rock_Stone"
    },
    {
      "x": 0,
      "y": -3,
      "z": 1,
      "name": "Rock_Stone"
    },
    {
      "x": 0,
      "y": -2,
      "z": 1,
      "name": "Rock_Stone"
    },
    {
      "x": 0,
      "y": -1,
      "z": 1,
      "name": "Rock_Stone"
    },
    {
      "x": 0,
      "y": 0,
      "z": 1,
      "name": "Rock_Stone"
    },
    {
      "x": 0,
      "y": 1,
      "z": 1,
      "name": "Soil_Dirt"
    },
    {
      "x": 0,
      "y": 2,
      "z": 1,
      "name": "Soil_Dirt"
    },
    {
      "x": 0,
      "y": 3,
      "z": 1,
      "name": "Ore_Thorium_Mud"
    },
    {
      "x": 0,
      "y": -4,
      "z": 2,
      "name": "Rock_Stone"
    },
    {
      "x": 0,
      "y": -3,
      "z": 2,
      "name": "Rock_Stone"
    },
    {
      "x": 0,
      "y": -2,
      "z": 2,
      "name": "Rock_Stone"
    },
    {
      "x": 0,
      "y": -1,
      "z": 2,
      "name": "Rock_Stone"
    },
    {
      "x": 0,
      "y": 0,
      "z": 2,
      "name": "Rock_Stone"
    },
    {
      "x": 0,
      "y": 1,
      "z": 2,
      "name": "Soil_Dirt"
    },
    {
      "x": 0,
      "y": 2,
      "z": 2,
      "name": "Soil_Dirt"
    },
    {
      "x": 0,
      "y": 3,
      "z": 2,
      "name": "Soil_Dirt"
    },
    {
      "x": 0,
      "y": 4,
      "z": 2,
      "name": "Deco_Raptor_Eggs"
    },
    {
      "x": 0,
      "y": -3,
      "z": 3,
      "name": "Rock_Stone"
    },
    {
      "x": 0,
      "y": -2,
      "z": 3,
      "name": "Rock_Stone"
    },
    {
      "x": 0,
      "y": -1,
      "z": 3,
      "name": "Rock_Stone"
    },
    {
      "x": 0,
      "y": 0,
      "z": 3,
      "name": "Rock_Stone"
    },
    {
      "x": 0,
      "y": 1,
      "z": 3,
      "name": "Soil_Dirt"
    },
    {
      "x": 0,
      "y": 2,
      "z": 3,
      "name": "Soil_Dirt"
    },
    {
      "x": 0,
      "y": 3,
      "z": 3,
      "name": "Soil_Dirt"
    },
    {
      "x": 0,
      "y": 4,
      "z": 3,
      "name": "Plant_Bush_Arid_Sharp",
      "support": 15
    },
    {
      "x": 0,
      "y": -2,
      "z": 4,
      "name": "Rock_Stone"
    },
    {
      "x": 0,
      "y": -1,
      "z": 4,
      "name": "Rock_Stone"
    },
    {
      "x": 0,
      "y": 0,
      "z": 4,
      "name": "Rock_Stone"
    },
    {
      "x": 0,
      "y": 1,
      "z": 4,
      "name": "Rock_Stone"
    },
    {
      "x": 0,
      "y": 2,
      "z": 4,
      "name": "Soil_Dirt"
    },
    {
      "x": 0,
      "y": 3,
      "z": 4,
      "name": "Soil_Dirt"
    },
    {
      "x": 0,
      "y": 4,
      "z": 4,
      "name": "Soil_Dirt_Half"
    },
    {
      "x": 0,
      "y": -1,
      "z": 5,
      "name": "Rock_Stone"
    },
    {
      "x": 0,
      "y": 0,
      "z": 5,
      "name": "Rock_Stone"
    },
    {
      "x": 0,
      "y": 1,
      "z": 5,
      "name": "Soil_Pathway"
    },
    {
      "x": 0,
      "y": 2,
      "z": 5,
      "name": "Soil_Dirt"
    },
    {
      "x": 0,
      "y": 3,
      "z": 5,
      "name": "Soil_Dirt_Stairs"
    },
    {
      "x": 1,
      "y": -1,
      "z": -4,
      "name": "Rock_Stone"
    },
    {
      "x": 1,
      "y": 0,
      "z": -4,
      "name": "Rock_Stone"
    },
    {
      "x": 1,
      "y": 1,
      "z": -4,
      "name": "Soil_Dirt"
    },
    {
      "x": 1,
      "y": 2,
      "z": -4,
      "name": "Soil_Dirt"
    },
    {
      "x": 1,
      "y": 3,
      "z": -4,
      "name": "Soil_Dirt_Half"
    },
    {
      "x": 1,
      "y": -2,
      "z": -3,
      "name": "Rock_Stone"
    },
    {
      "x": 1,
      "y": -1,
      "z": -3,
      "name": "Rock_Stone"
    },
    {
      "x": 1,
      "y": 0,
      "z": -3,
      "name": "Rock_Stone"
    },
    {
      "x": 1,
      "y": 1,
      "z": -3,
      "name": "Rock_Stone"
    },
    {
      "x": 1,
      "y": 2,
      "z": -3,
      "name": "Soil_Dirt"
    },
    {
      "x": 1,
      "y": 3,
      "z": -3,
      "name": "Soil_Dirt"
    },
    {
      "x": 1,
      "y": -2,
      "z": -2,
      "name": "Rock_Stone"
    },
    {
      "x": 1,
      "y": -1,
      "z": -2,
      "name": "Rock_Stone"
    },
    {
      "x": 1,
      "y": 0,
      "z": -2,
      "name": "Rock_Stone"
    },
    {
      "x": 1,
      "y": 1,
      "z": -2,
      "name": "Soil_Dirt"
    },
    {
      "x": 1,
      "y": 2,
      "z": -2,
      "name": "Soil_Dirt"
    },
    {
      "x": 1,
      "y": 3,
      "z": -2,
      "name": "Soil_Dirt"
    },
    {
      "x": 1,
      "y": 4,
      "z": -2,
      "name": "Plant_Bush_Arid_Sharp",
      "support": 15
    },
    {
      "x": 1,
      "y": -4,
      "z": -1,
      "name": "Rock_Stone"
    },
    {
      "x": 1,
      "y": -3,
      "z": -1,
      "name": "Rock_Stone"
    },
    {
      "x": 1,
      "y": -2,
      "z": -1,
      "name": "Rock_Stone"
    },
    {
      "x": 1,
      "y": -1,
      "z": -1,
      "name": "Rock_Stone"
    },
    {
      "x": 1,
      "y": 0,
      "z": -1,
      "name": "Rock_Stone"
    },
    {
      "x": 1,
      "y": 1,
      "z": -1,
      "name": "Soil_Dirt"
    },
    {
      "x": 1,
      "y": 2,
      "z": -1,
      "name": "Soil_Dirt"
    },
    {
      "x": 1,
      "y": 3,
      "z": -1,
      "name": "Soil_Dirt"
    },
    {
      "x": 1,
      "y": 4,
      "z": -1,
      "name": "Plant_Bush_Arid_Sharp",
      "support": 15
    },
    {
      "x": 1,
      "y": -4,
      "z": 0,
      "name": "Rock_Stone"
    },
    {
      "x": 1,
      "y": -3,
      "z": 0,
      "name": "Rock_Stone"
    },
    {
      "x": 1,
      "y": -2,
      "z": 0,
      "name": "Rock_Stone"
    },
    {
      "x": 1,
      "y": -1,
      "z": 0,
      "name": "Rock_Stone"
    },
    {
      "x": 1,
      "y": 0,
      "z": 0,
      "name": "Rock_Stone"
    },
    {
      "x": 1,
      "y": 1,
      "z": 0,
      "name": "Rock_Stone"
    },
    {
      "x": 1,
      "y": 2,
      "z": 0,
      "name": "Soil_Dirt"
    },
    {
      "x": 1,
      "y": 3,
      "z": 0,
      "name": "Soil_Dirt"
    },
    {
      "x": 1,
      "y": 4,
      "z": 0,
      "name": "Plant_Petals_White"
    },
    {
      "x": 1,
      "y": -4,
      "z": 1,
      "name": "Rock_Stone"
    },
    {
      "x": 1,
      "y": -3,
      "z": 1,
      "name": "Rock_Stone"
    },
    {
      "x": 1,
      "y": -2,
      "z": 1,
      "name": "Rock_Stone"
    },
    {
      "x": 1,
      "y": -1,
      "z": 1,
      "name": "Rock_Stone"
    },
    {
      "x": 1,
      "y": 0,
      "z": 1,
      "name": "Rock_Stone"
    },
    {
      "x": 1,
      "y": 1,
      "z": 1,
      "name": "Rock_Stone"
    },
    {
      "x": 1,
      "y": 2,
      "z": 1,
      "name": "Soil_Dirt"
    },
    {
      "x": 1,
      "y": 3,
      "z": 1,
      "name": "Soil_Dirt"
    },
    {
      "x": 1,
      "y": 4,
      "z": 1,
      "name": "Deco_Raptor_Eggs"
    },
    {
      "x": 1,
      "y": -4,
      "z": 2,
      "name": "Rock_Stone"
    },
    {
      "x": 1,
      "y": -3,
      "z": 2,
      "name": "Rock_Stone"
    },
    {
      "x": 1,
      "y": -2,
      "z": 2,
      "name": "Rock_Stone"
    },
    {
      "x": 1,
      "y": -1,
      "z": 2,
      "name": "Rock_Stone"
    },
    {
      "x": 1,
      "y": 0,
      "z": 2,
      "name": "Rock_Stone"
    },
    {
      "x": 1,
      "y": 1,
      "z": 2,
      "name": "Soil_Dirt"
    },
    {
      "x": 1,
      "y": 2,
      "z": 2,
      "name": "Soil_Dirt"
    },
    {
      "x": 1,
      "y": 3,
      "z": 2,
      "name": "Soil_Dirt"
    },
    {
      "x": 1,
      "y": 4,
      "z": 2,
      "name": "Plant_Bush_Arid_Sharp",
      "support": 15
    },
    {
      "x": 1,
      "y": -3,
      "z": 3,
      "name": "Rock_Stone"
    },
    {
      "x": 1,
      "y": -2,
      "z": 3,
      "name": "Rock_Stone"
    },
    {
      "x": 1,
      "y": -1,
      "z": 3,
      "name": "Rock_Stone"
    },
    {
      "x": 1,
      "y": 0,
      "z": 3,
      "name": "Rock_Stone"
    },
    {
      "x": 1,
      "y": 1,
      "z": 3,
      "name": "Soil_Dirt"
    },
    {
      "x": 1,
      "y": 2,
      "z": 3,
      "name": "Soil_Dirt"
    },
    {
      "x": 1,
      "y": 3,
      "z": 3,
      "name": "Soil_Dirt"
    },
    {
      "x": 1,
      "y": -2,
      "z": 4,
      "name": "Rock_Stone"
    },
    {
      "x": 1,
      "y": -1,
      "z": 4,
      "name": "Rock_Stone"
    },
    {
      "x": 1,
      "y": 0,
      "z": 4,
      "name": "Rock_Stone"
    },
    {
      "x": 1,
      "y": 1,
      "z": 4,
      "name": "Soil_Dirt"
    },
    {
      "x": 1,
      "y": 2,
      "z": 4,
      "name": "Soil_Dirt"
    },
    {
      "x": 1,
      "y": 3,
      "z": 4,
      "name": "Soil_Dirt"
    },
    {
      "x": 1,
      "y": 4,
      "z": 4,
      "name": "Soil_Dirt_Half"
    },
    {
      "x": 1,
      "y": 2,
      "z": 5,
      "name": "Soil_Dirt_Half",
      "rotation": 4
    },
    {
      "x": 2,
      "y": 2,
      "z": -4,
      "name": "Soil_Dirt_Half",
      "rotation": 6
    },
    {
      "x": 2,
      "y": -2,
      "z": -3,
      "name": "Rock_Stone"
    },
    {
      "x": 2,
      "y": -1,
      "z": -3,
      "name": "Rock_Stone"
    },
    {
      "x": 2,
      "y": 0,
      "z": -3,
      "name": "Rock_Stone"
    },
    {
      "x": 2,
      "y": 1,
      "z": -3,
      "name": "Soil_Dirt"
    },
    {
      "x": 2,
      "y": 2,
      "z": -3,
      "name": "Soil_Dirt"
    },
    {
      "x": 2,
      "y": 3,
      "z": -3,
      "name": "Soil_Dirt_Half"
    },
    {
      "x": 2,
      "y": -3,
      "z": -2,
      "name": "Rock_Stone"
    },
    {
      "x": 2,
      "y": -2,
      "z": -2,
      "name": "Rock_Stone"
    },
    {
      "x": 2,
      "y": -1,
      "z": -2,
      "name": "Rock_Stone"
    },
    {
      "x": 2,
      "y": 0,
      "z": -2,
      "name": "Rock_Stone"
    },
    {
      "x": 2,
      "y": 1,
      "z": -2,
      "name": "Rock_Stone"
    },
    {
      "x": 2,
      "y": 2,
      "z": -2,
      "name": "Soil_Dirt"
    },
    {
      "x": 2,
      "y": 3,
      "z": -2,
      "name": "Soil_Dirt_Half"
    },
    {
      "x": 2,
      "y": -4,
      "z": -1,
      "name": "Rock_Stone"
    },
    {
      "x": 2,
      "y": -3,
      "z": -1,
      "name": "Rock_Stone"
    },
    {
      "x": 2,
      "y": -2,
      "z": -1,
      "name": "Rock_Stone"
    },
    {
      "x": 2,
      "y": -1,
      "z": -1,
      "name": "Rock_Stone"
    },
    {
      "x": 2,
      "y": 0,
      "z": -1,
      "name": "Rock_Stone"
    },
    {
      "x": 2,
      "y": 1,
      "z": -1,
      "name": "Rock_Stone"
    },
    {
      "x": 2,
      "y": 2,
      "z": -1,
      "name": "Soil_Dirt"
    },
    {
      "x": 2,
      "y": 3,
      "z": -1,
      "name": "Soil_Dirt"
    },
    {
      "x": 2,
      "y": -4,
      "z": 0,
      "name": "Rock_Stone"
    },
    {
      "x": 2,
      "y": -3,
      "z": 0,
      "name": "Rock_Stone"
    },
    {
      "x": 2,
      "y": -2,
      "z": 0,
      "name": "Rock_Stone"
    },
    {
      "x": 2,
      "y": -1,
      "z": 0,
      "name": "Rock_Stone"
    },
    {
      "x": 2,
      "y": 0,
      "z": 0,
      "name": "Rock_Stone"
    },
    {
      "x": 2,
      "y": 1,
      "z": 0,
      "name": "Soil_Dirt"
    },
    {
      "x": 2,
      "y": 2,
      "z": 0,
      "name": "Soil_Dirt"
    },
    {
      "x": 2,
      "y": 3,
      "z": 0,
      "name": "Soil_Dirt"
    },
    {
      "x": 2,
      "y": 4,
      "z": 0,
      "name": "Plant_Bush_Arid_Sharp",
      "support": 15
    },
    {
      "x": 2,
      "y": -4,
      "z": 1,
      "name": "Rock_Stone"
    },
    {
      "x": 2,
      "y": -3,
      "z": 1,
      "name": "Rock_Stone"
    },
    {
      "x": 2,
      "y": -2,
      "z": 1,
      "name": "Rock_Stone"
    },
    {
      "x": 2,
      "y": -1,
      "z": 1,
      "name": "Rock_Stone"
    },
    {
      "x": 2,
      "y": 0,
      "z": 1,
      "name": "Rock_Stone"
    },
    {
      "x": 2,
      "y": 1,
      "z": 1,
      "name": "Soil_Dirt"
    },
    {
      "x": 2,
      "y": 2,
      "z": 1,
      "name": "Soil_Dirt"
    },
    {
      "x": 2,
      "y": 3,
      "z": 1,
      "name": "Soil_Dirt"
    },
    {
      "x": 2,
      "y": 4,
      "z": 1,
      "name": "Plant_Leaves_Jungle_Floor",
      "support": 15
    },
    {
      "x": 2,
      "y": -3,
      "z": 2,
      "name": "Rock_Stone"
    },
    {
      "x": 2,
      "y": -2,
      "z": 2,
      "name": "Rock_Stone"
    },
    {
      "x": 2,
      "y": -1,
      "z": 2,
      "name": "Rock_Stone"
    },
    {
      "x": 2,
      "y": 0,
      "z": 2,
      "name": "Soil_Dirt"
    },
    {
      "x": 2,
      "y": 1,
      "z": 2,
      "name": "Soil_Dirt"
    },
    {
      "x": 2,
      "y": 2,
      "z": 2,
      "name": "Soil_Dirt"
    },
    {
      "x": 2,
      "y": 3,
      "z": 2,
      "name": "Soil_Dirt"
    },
    {
      "x": 2,
      "y": 4,
      "z": 2,
      "name": "Plant_Bush_Arid_Sharp",
      "support": 15
    },
    {
      "x": 2,
      "y": -3,
      "z": 3,
      "name": "Rock_Stone"
    },
    {
      "x": 2,
      "y": -2,
      "z": 3,
      "name": "Rock_Stone"
    },
    {
      "x": 2,
      "y": -1,
      "z": 3,
      "name": "Rock_Stone"
    },
    {
      "x": 2,
      "y": 0,
      "z": 3,
      "name": "Rock_Stone"
    },
    {
      "x": 2,
      "y": 1,
      "z": 3,
      "name": "Soil_Dirt"
    },
    {
      "x": 2,
      "y": 2,
      "z": 3,
      "name": "Soil_Dirt"
    },
    {
      "x": 2,
      "y": 3,
      "z": 3,
      "name": "Soil_Dirt"
    },
    {
      "x": 2,
      "y": -3,
      "z": 4,
      "name": "Rock_Stone"
    },
    {
      "x": 2,
      "y": -2,
      "z": 4,
      "name": "Rock_Stone"
    },
    {
      "x": 2,
      "y": -1,
      "z": 4,
      "name": "Rock_Stone"
    },
    {
      "x": 2,
      "y": 0,
      "z": 4,
      "name": "Rock_Stone"
    },
    {
      "x": 2,
      "y": 1,
      "z": 4,
      "name": "Soil_Pathway"
    },
    {
      "x": 2,
      "y": 2,
      "z": 4,
      "name": "Soil_Dirt"
    },
    {
      "x": 2,
      "y": 3,
      "z": 4,
      "name": "Soil_Dirt_Half",
      "rotation": 4
    },
    {
      "x": 2,
      "y": 2,
      "z": 5,
      "name": "Soil_Dirt_Half",
      "rotation": 4
    },
    {
      "x": 3,
      "y": 2,
      "z": -3,
      "name": "Soil_Dirt_Half",
      "rotation": 6
    },
    {
      "x": 3,
      "y": -1,
      "z": -2,
      "name": "Rock_Stone"
    },
    {
      "x": 3,
      "y": 0,
      "z": -2,
      "name": "Rock_Stone"
    },
    {
      "x": 3,
      "y": 1,
      "z": -2,
      "name": "Soil_Dirt"
    },
    {
      "x": 3,
      "y": 2,
      "z": -2,
      "name": "Soil_Dirt"
    },
    {
      "x": 3,
      "y": 3,
      "z": -2,
      "name": "Soil_Dirt_Half"
    },
    {
      "x": 3,
      "y": -2,
      "z": -1,
      "name": "Rock_Stone"
    },
    {
      "x": 3,
      "y": -1,
      "z": -1,
      "name": "Rock_Stone"
    },
    {
      "x": 3,
      "y": 0,
      "z": -1,
      "name": "Rock_Stone"
    },
    {
      "x": 3,
      "y": 1,
      "z": -1,
      "name": "Soil_Dirt"
    },
    {
      "x": 3,
      "y": 2,
      "z": -1,
      "name": "Soil_Dirt"
    },
    {
      "x": 3,
      "y": 3,
      "z": -1,
      "name": "Soil_Dirt"
    },
    {
      "x": 3,
      "y": -4,
      "z": 0,
      "name": "Rock_Stone"
    },
    {
      "x": 3,
      "y": -3,
      "z": 0,
      "name": "Rock_Stone"
    },
    {
      "x": 3,
      "y": -2,
      "z": 0,
      "name": "Rock_Stone"
    },
    {
      "x": 3,
      "y": -1,
      "z": 0,
      "name": "Rock_Stone"
    },
    {
      "x": 3,
      "y": 0,
      "z": 0,
      "name": "Rock_Stone"
    },
    {
      "x": 3,
      "y": 1,
      "z": 0,
      "name": "Rock_Stone"
    },
    {
      "x": 3,
      "y": 2,
      "z": 0,
      "name": "Soil_Dirt"
    },
    {
      "x": 3,
      "y": 3,
      "z": 0,
      "name": "Soil_Dirt"
    },
    {
      "x": 3,
      "y": 4,
      "z": 0,
      "name": "Plant_Bush_Arid_Sharp",
      "support": 15
    },
    {
      "x": 3,
      "y": -3,
      "z": 1,
      "name": "Rock_Stone"
    },
    {
      "x": 3,
      "y": -2,
      "z": 1,
      "name": "Rock_Stone"
    },
    {
      "x": 3,
      "y": -1,
      "z": 1,
      "name": "Rock_Stone"
    },
    {
      "x": 3,
      "y": 0,
      "z": 1,
      "name": "Rock_Stone"
    },
    {
      "x": 3,
      "y": 1,
      "z": 1,
      "name": "Soil_Dirt"
    },
    {
      "x": 3,
      "y": 2,
      "z": 1,
      "name": "Soil_Dirt"
    },
    {
      "x": 3,
      "y": 3,
      "z": 1,
      "name": "Soil_Dirt"
    },
    {
      "x": 3,
      "y": 4,
      "z": 1,
      "name": "Plant_Bush_Arid_Sharp",
      "support": 15
    },
    {
      "x": 3,
      "y": -3,
      "z": 2,
      "name": "Rock_Stone"
    },
    {
      "x": 3,
      "y": -2,
      "z": 2,
      "name": "Rock_Stone"
    },
    {
      "x": 3,
      "y": -1,
      "z": 2,
      "name": "Rock_Stone"
    },
    {
      "x": 3,
      "y": 0,
      "z": 2,
      "name": "Soil_Dirt"
    },
    {
      "x": 3,
      "y": 1,
      "z": 2,
      "name": "Soil_Dirt"
    },
    {
      "x": 3,
      "y": 2,
      "z": 2,
      "name": "Soil_Dirt"
    },
    {
      "x": 3,
      "y": 3,
      "z": 2,
      "name": "Soil_Dirt"
    },
    {
      "x": 3,
      "y": -3,
      "z": 3,
      "name": "Rock_Stone"
    },
    {
      "x": 3,
      "y": -2,
      "z": 3,
      "name": "Rock_Stone"
    },
    {
      "x": 3,
      "y": -1,
      "z": 3,
      "name": "Rock_Stone"
    },
    {
      "x": 3,
      "y": 0,
      "z": 3,
      "name": "Soil_Dirt"
    },
    {
      "x": 3,
      "y": 1,
      "z": 3,
      "name": "Soil_Dirt"
    },
    {
      "x": 3,
      "y": 2,
      "z": 3,
      "name": "Soil_Dirt"
    },
    {
      "x": 3,
      "y": 3,
      "z": 3,
      "name": "Soil_Dirt"
    },
    {
      "x": 3,
      "y": -2,
      "z": 4,
      "name": "Rock_Stone"
    },
    {
      "x": 3,
      "y": -1,
      "z": 4,
      "name": "Rock_Stone"
    },
    {
      "x": 3,
      "y": 0,
      "z": 4,
      "name": "Rock_Stone"
    },
    {
      "x": 3,
      "y": 1,
      "z": 4,
      "name": "Soil_Dirt"
    },
    {
      "x": 3,
      "y": 2,
      "z": 4,
      "name": "Soil_Dirt"
    },
    {
      "x": 3,
      "y": 3,
      "z": 4,
      "name": "Soil_Dirt_Half",
      "rotation": 4
    },
    {
      "x": 4,
      "y": 2,
      "z": -2,
      "name": "Soil_Dirt_Half",
      "rotation": 5
    },
    {
      "x": 4,
      "y": 1,
      "z": -1,
      "name": "Soil_Dirt"
    },
    {
      "x": 4,
      "y": 2,
      "z": -1,
      "name": "Soil_Dirt"
    },
    {
      "x": 4,
      "y": 3,
      "z": -1,
      "name": "Soil_Dirt_Half"
    },
    {
      "x": 4,
      "y": -1,
      "z": 0,
      "name": "Rock_Stone"
    },
    {
      "x": 4,
      "y": 0,
      "z": 0,
      "name": "Rock_Stone"
    },
    {
      "x": 4,
      "y": 1,
      "z": 0,
      "name": "Soil_Dirt"
    },
    {
      "x": 4,
      "y": 2,
      "z": 0,
      "name": "Soil_Dirt"
    },
    {
      "x": 4,
      "y": 3,
      "z": 0,
      "name": "Soil_Dirt"
    },
    {
      "x": 4,
      "y": 4,
      "z": 0,
      "name": "Soil_Pathway_Half"
    },
    {
      "x": 4,
      "y": -1,
      "z": 1,
      "name": "Rock_Stone"
    },
    {
      "x": 4,
      "y": 0,
      "z": 1,
      "name": "Soil_Dirt"
    },
    {
      "x": 4,
      "y": 1,
      "z": 1,
      "name": "Soil_Dirt"
    },
    {
      "x": 4,
      "y": 2,
      "z": 1,
      "name": "Soil_Dirt"
    },
    {
      "x": 4,
      "y": 3,
      "z": 1,
      "name": "Soil_Dirt"
    },
    {
      "x": 4,
      "y": 4,
      "z": 1,
      "name": "Soil_Pathway_Half"
    },
    {
      "x": 4,
      "y": -1,
      "z": 2,
      "name": "Soil_Dirt"
    },
    {
      "x": 4,
      "y": 0,
      "z": 2,
      "name": "Soil_Dirt"
    },
    {
      "x": 4,
      "y": 1,
      "z": 2,
      "name": "Soil_Dirt"
    },
    {
      "x": 4,
      "y": 2,
      "z": 2,
      "name": "Soil_Dirt"
    },
    {
      "x": 4,
      "y": 3,
      "z": 2,
      "name": "Soil_Dirt"
    },
    {
      "x": 4,
      "y": 4,
      "z": 2,
      "name": "Soil_Pathway_Half"
    },
    {
      "x": 4,
      "y": 1,
      "z": 3,
      "name": "Soil_Dirt"
    },
    {
      "x": 4,
      "y": 2,
      "z": 3,
      "name": "Soil_Dirt"
    },
    {
      "x": 4,
      "y": 3,
      "z": 3,
      "name": "Soil_Dirt_Stairs",
      "rotation": 1
    },
    {
      "x": 4,
      "y": 2,
      "z": 4,
      "name": "Soil_Dirt_Half",
      "rotation": 5
    },
    {
      "x": 5,
      "y": 2,
      "z": -1,
      "name": "Soil_Dirt_Half",
      "rotation": 6
    },
    {
      "x": 5,
      "y": 2,
      "z": 0,
      "name": "Soil_Dirt"
    },
    {
      "x": 5,
      "y": 3,
      "z": 0,
      "name": "Soil_Dirt_Stairs",
      "rotation": 1
    },
    {
      "x": 5,
      "y": 1,
      "z": 1,
      "name": "Soil_Dirt"
    },
    {
      "x": 5,
      "y": 2,
      "z": 1,
      "name": "Soil_Dirt"
    },
    {
      "x": 5,
      "y": 3,
      "z": 1,
      "name": "Soil_Dirt_Stairs",
      "rotation": 1
    },
    {
      "x": 5,
      "y": 1,
      "z": 2,
      "name": "Soil_Dirt"
    },
    {
      "x": 5,
      "y": 2,
      "z": 2,
      "name": "Soil_Dirt"
    },
    {
      "x": 5,
      "y": 3,
      "z": 2,
      "name": "Soil_Dirt_Stairs",
      "rotation": 1
    },
    {
      "x": 5,
      "y": 2,
      "z": 3,
      "name": "Soil_Dirt_Half",
      "rotation": 5
    },
    {
      "x": 6,
      "y": 2,
      "z": 1,
      "name": "Soil_Dirt_Half",
      "rotation": 5
    },
    {
      "x": 6,
      "y": 2,
      "z": 2,
      "name": "Soil_Dirt_Half",
      "rotation": 5
    }
  ]
}