{
  "version": 8,
  "blockIdVersion": 11,
  "anchorX": 0,
  "anchorY": 0,
  "anchorZ": 0,
  "blocks": [
    {
      "x": -4,
      "y": 0,
      "z": -1,
      "name": "Soil_Pathway_Half",
      "rotation": 7
    },
    {
      "x": -4,
      "y": 0,
      "z": 0,
      "name": "Soil_Dirt_Half",
      "rotation": 7
    },
    {
      "x": -4,
      "y": 0,
      "z": 1,
      "name": "Soil_Dirt_Half",
      "rotation": 7
    },
    {
      "x": -4,
      "y": 0,
      "z": 2,
      "name": "Soil_Dirt_Half",
      "rotation": 7
    },
    {
      "x": -3,
      "y": 0,
      "z": -2,
      "name": "Soil_Dirt_Stairs",
      "rotation": 3
    },
    {
      "x": -3,
      "y": 0,
      "z": -1,
      "name": "Soil_Pathway"
    },
    {
      "x": -3,
      "y": 1,
      "z": -1,
      "name": "Soil_Pathway_Half"
    },
    {
      "x": -3,
      "y": 0,
      "z": 0,
      "name": "Soil_Pathway"
    },
    {
      "x": -3,
      "y": 1,
      "z": 0,
      "name": "Soil_Dirt_Stairs",
      "rotation": 3
    },
    {
      "x": -3,
      "y": 0,
      "z": 1,
      "name": "Soil_Pathway"
    },
    {
      "x": -3,
      "y": 1,
      "z": 1,
      "name": "Soil_Dirt_Stairs",
      "rotation": 3
    },
    {
      "x": -3,
      "y": 0,
      "z": 2,
      "name": "Soil_Pathway"
    },
    {
      "x": -3,
      "y": 1,
      "z": 2,
      "name": "Soil_Dirt_Stairs",
      "rotation": 3
    },
    {
      "x": -3,
      "y": 0,
      "z": 3,
      "name": "Soil_Pathway"
    },
    {
      "x": -3,
      "y": 1,
      "z": 3,
      "name": "Soil_Dirt_Half"
    },
    {
      "x": -2,
      "y": 0,
      "z": -3,
      "name": "Soil_Dirt_Stairs",
      "rotation": 2
    },
    {
      "x": -2,
      "y": 0,
      "z": -2,
      "name": "Soil_Pathway"
    },
    {
      "x": -2,
      "y": 1,
      "z": -2,
      "name": "Soil_Dirt_Stairs",
      "rotation": 2
    },
    {
      "x": -2,
      "y": 0,
      "z": -1,
      "name": "Soil_Pathway"
    },
    {
      "x": -2,
      "y": 1,
      "z": -1,
      "name": "Ore_Thorium_Mud_Cracked"
    },
    {
      "x": -2,
      "y": 2,
      "z": -1,
      "name": "Plant_Leaves_Jungle_Floor"
    },
    {
      "x": -2,
      "y": 0,
      "z": 0,
      "name": "Soil_Pathway"
    },
    {
      "x": -2,
      "y": 1,
      "z": 0,
      "name": "Soil_Pathway"
    },
    {
      "x": -2,
      "y": 2,
      "z": 0,
      "name": "Plant_Vine_Rug"
    },
    {
      "x": -2,
      "y": 0,
      "z": 1,
      "name": "Soil_Pathway"
    },
    {
      "x": -2,
      "y": 1,
      "z": 1,
      "name": "Soil_Pathway"
    },
    {
      "x": -2,
      "y": 2,
      "z": 1,
      "name": "Plant_Bush_Arid_Sharp"
    },
    {
      "x": -2,
      "y": 0,
      "z": 2,
      "name": "Soil_Pathway"
    },
    {
      "x": -2,
      "y": 1,
      "z": 2,
      "name": "Soil_Pathway"
    },
    {
      "x": -2,
      "y": 2,
      "z": 2,
      "name": "Plant_Leaves_Jungle_Floor"
    },
    {
      "x": -2,
      "y": 0,
      "z": 3,
      "name": "Soil_Pathway"
    },
    {
      "x": -2,
      "y": 1,
      "z": 3,
      "name": "Soil_Pathway"
    },
    {
      "x": -2,
      "y": 0,
      "z": 4,
      "name": "Soil_Dirt_Stairs"
    },
    {
      "x": -1,
      "y": 0,
      "z": -3,
      "name": "Soil_Dirt_Stairs",
      "rotation": 2
    },
    {
      "x": -1,
      "y": 0,
      "z": -2,
      "name": "Soil_Pathway"
    },
    {
      "x": -1,
      "y": 1,
      "z": -2,
      "name": "Soil_Dirt_Stairs",
      "rotation": 2
    },
    {
      "x": -1,
      "y": 0,
      "z": -1,
      "name": "Soil_Pathway"
    },
    {
      "x": -1,
      "y": 1,
      "z": -1,
      "name": "Ore_Thorium_Mud_Cracked"
    },
    {
      "x": -1,
      "y": 2,
      "z": -1,
      "name": "Plant_Vine_Rug"
    },
    {
      "x": -1,
      "y": 0,
      "z": 0,
      "name": "Soil_Pathway"
    },
    {
      "x": -1,
      "y": 1,
      "z": 0,
      "name": "Soil_Pathway"
    },
    {
      "x": -1,
      "y": 2,
      "z": 0,
      "name": "Plant_Bush_Arid_Sharp"
    },
    {
      "x": -1,
      "y": 0,
      "z": 1,
      "name": "Soil_Pathway"
    },
    {
      "x": -1,
      "y": 1,
      "z": 1,
      "name": "Soil_Grass_Dry_Full"
    },
    {
      "x": -1,
      "y": 2,
      "z": 1,
      "name": "Deco_Scarak_Eggsacks"
    },
    {
      "x": -1,
      "y": 0,
      "z": 2,
      "name": "Soil_Pathway"
    },
    {
      "x": -1,
      "y": 1,
      "z": 2,
      "name": "Soil_Pathway"
    },
    {
      "x": -1,
      "y": 2,
      "z": 2,
      "name": "Plant_Bush_Arid_Sharp"
    },
    {
      "x": -1,
      "y": 0,
      "z": 3,
      "name": "Soil_Pathway"
    },
    {
      "x": -1,
      "y": 1,
      "z": 3,
      "name": "Soil_Pathway"
    },
    {
      "x": -1,
      "y": 2,
      "z": 3,
      "name": "Plant_Leaves_Jungle_Floor"
    },
    {
      "x": -1,
      "y": 0,
      "z": 4,
      "name": "Soil_Pathway"
    },
    {
      "x": -1,
      "y": 1,
      "z": 4,
      "name": "Soil_Dirt_Half"
    },
    {
      "x": 0,
      "y": 0,
      "z": -4,
      "name": "Soil_Dirt_Half",
      "rotation": 6
    },
    {
      "x": 0,
      "y": 0,
      "z": -3,
      "name": "Soil_Pathway"
    },
    {
      "x": 0,
      "y": 1,
      "z": -3,
      "name": "Soil_Dirt_Stairs",
      "rotation": 2
    },
    {
      "x": 0,
      "y": 0,
      "z": -2,
      "name": "Soil_Pathway"
    },
    {
      "x": 0,
      "y": 1,
      "z": -2,
      "name": "Ore_Thorium_Mud_Cracked"
    },
    {
      "x": 0,
      "y": 2,
      "z": -2,
      "name": "Plant_Leaves_Jungle_Floor"
    },
    {
      "x": 0,
      "y": 0,
      "z": -1,
      "name": "Soil_Pathway"
    },
    {
      "x": 0,
      "y": 1,
      "z": -1,
      "name": "Soil_Pathway"
    },
    {
      "x": 0,
      "y": 2,
      "z": -1,
      "name": "Plant_Vine_Rug"
    },
    {
      "x": 0,
      "y": 0,
      "z": 0,
      "name": "Soil_Pathway"
    },
    {
      "x": 0,
      "y": 1,
      "z": 0,
      "name": "Soil_Grass_Dry_Full"
    },
    {
      "x": 0,
      "y": 2,
      "z": 0,
      "name": "Plant_Bush_Arid_Sharp"
    },
    {
      "x": 0,
      "y": 0,
      "z": 1,
      "name": "Soil_Pathway"
    },
    {
      "x": 0,
      "y": 1,
      "z": 1,
      "name": "Ore_Thorium_Mud"
    },
    {
      "x": 0,
      "y": 0,
      "z": 2,
      "name": "Soil_Pathway"
    },
    {
      "x": 0,
      "y": 1,
      "z": 2,
      "name": "Soil_Pathway"
    },
    {
      "x": 0,
      "y": 2,
      "z": 2,
      "name": "Plant_Bush_Arid_Sharp"
    },
    {
      "x": 0,
      "y": 0,
      "z": 3,
      "name": "Soil_Pathway"
    },
    {
      "x": 0,
      "y": 1,
      "z": 3,
      "name": "Soil_Pathway"
    },
    {
      "x": 0,
      "y": 2,
      "z": 3,
      "name": "Plant_Vine_Rug"
    },
    {
      "x": 0,
      "y": 0,
      "z": 4,
      "name": "Soil_Pathway"
    },
    {
      "x": 0,
      "y": 1,
      "z": 4,
      "name": "Soil_Dirt_Stairs"
    },
    {
      "x": 0,
      "y": 0,
      "z": 5,
      "name": "Soil_Dirt_Half",
      "rotation": 4
    },
    {
      "x": 1,
      "y": 0,
      "z": -4,
      "name": "Soil_Dirt_Half",
      "rotation": 6
    },
    {
      "x": 1,
      "y": 0,
      "z": -3,
      "name": "Soil_Pathway"
    },
    {
      "x": 1,
      "y": 1,
      "z": -3,
      "name": "Soil_Dirt_Stairs",
      "rotation": 2
    },
    {
      "x": 1,
      "y": 0,
      "z": -2,
      "name": "Soil_Pathway"
    },
    {
      "x": 1,
      "y": 1,
      "z": -2,
      "name": "Ore_Thorium_Mud_Cracked"
    },
    {
      "x": 1,
      "y": 2,
      "z": -2,
      "name": "Plant_Leaves_Jungle_Floor"
    },
    {
      "x": 1,
      "y": 0,
      "z": -1,
      "name": "Soil_Pathway"
    },
    {
      "x": 1,
      "y": 1,
      "z": -1,
      "name": "Soil_Pathway"
    },
    {
      "x": 1,
      "y": 2,
      "z": -1,
      "name": "Plant_Vine_Rug"
    },
    {
      "x": 1,
      "y": 0,
      "z": 0,
      "name": "Soil_Pathway"
    },
    {
      "x": 1,
      "y": 1,
      "z": 0,
      "name": "Soil_Pathway"
    },
    {
      "x": 1,
      "y": 2,
      "z": 0,
      "name": "Plant_Bush_Arid_Sharp"
    },
    {
      "x": 1,
      "y": 0,
      "z": 1,
      "name": "Soil_Pathway"
    },
    {
      "x": 1,
      "y": 1,
      "z": 1,
      "name": "Soil_Pathway"
    },
    {
      "x": 1,
      "y": 2,
      "z": 1,
      "name": "Deco_Scarak_Eggsacks"
    },
    {
      "x": 1,
      "y": 0,
      "z": 2,
      "name": "Soil_Pathway"
    },
    {
      "x": 1,
      "y": 1,
      "z": 2,
      "name": "Soil_Pathway"
    },
    {
      "x": 1,
      "y": 0,
      "z": 3,
      "name": "Soil_Pathway"
    },
    {
      "x": 1,
      "y": 1,
      "z": 3,
      "name": "Ore_Thorium_Mud_Cracked"
    },
    {
      "x": 1,
      "y": 2,
      "z": 3,
      "name": "Plant_Vine_Rug"
    },
    {
      "x": 1,
      "y": 0,
      "z": 4,
      "name": "Soil_Pathway"
    },
    {
      "x": 1,
      "y": 1,
      "z": 4,
      "name": "Soil_Dirt_Half"
    },
    {
      "x": 1,
      "y": 0,
      "z": 5,
      "name": "Soil_Dirt_Stairs"
    },
    {
      "x": 2,
      "y": 0,
      "z": -4,
      "name": "Soil_Dirt_Half",
      "rotation": 6
    },
    {
      "x": 2,
      "y": 0,
      "z": -3,
      "name": "Soil_Pathway"
    },
    {
      "x": 2,
      "y": 1,
      "z": -3,
      "name": "Soil_Pathway_Half"
    },
    {
      "x": 2,
      "y": 0,
      "z": -2,
      "name": "Soil_Pathway"
    },
    {
      "x": 2,
      "y": 1,
      "z": -2,
      "name": "*Soil_Dirt_Half_State_Definitions_Block"
    },
    {
      "x": 2,
      "y": 0,
      "z": -1,
      "name": "Soil_Pathway"
    },
    {
      "x": 2,
      "y": 1,
      "z": -1,
      "name": "Ore_Thorium_Mud_Cracked"
    },
    {
      "x": 2,
      "y": 0,
      "z": 0,
      "name": "Soil_Pathway"
    },
    {
      "x": 2,
      "y": 1,
      "z": 0,
      "name": "Soil_Pathway"
    },
    {
      "x": 2,
      "y": 2,
      "z": 0,
      "name": "Plant_Leaves_Jungle_Floor"
    },
    {
      "x": 2,
      "y": 0,
      "z": 1,
      "name": "Soil_Pathway"
    },
    {
      "x": 2,
      "y": 1,
      "z": 1,
      "name": "Soil_Pathway"
    },
    {
      "x": 2,
      "y": 2,
      "z": 1,
      "name": "Plant_Bush_Arid_Sharp"
    },
    {
      "x": 2,
      "y": 0,
      "z": 2,
      "name": "Soil_Pathway"
    },
    {
      "x": 2,
      "y": 1,
      "z": 2,
      "name": "Soil_Pathway"
    },
    {
      "x": 2,
      "y": 2,
      "z": 2,
      "name": "Plant_Leaves_Jungle_Floor"
    },
    {
      "x": 2,
      "y": 0,
      "z": 3,
      "name": "Soil_Pathway"
    },
    {
      "x": 2,
      "y": 1,
      "z": 3,
      "name": "Ore_Thorium_Mud_Cracked"
    },
    {
      "x": 2,
      "y": 0,
      "z": 4,
      "name": "Soil_Pathway"
    },
    {
      "x": 2,
      "y": 1,
      "z": 4,
      "name": "Soil_Dirt_Stairs"
    },
    {
      "x": 2,
      "y": 0,
      "z": 5,
      "name": "Soil_Pathway_Half",
      "rotation": 4
    },
    {
      "x": 3,
      "y": 0,
      "z": -3,
      "name": "Soil_Pathway_Half",
      "rotation": 5
    },
    {
      "x": 3,
      "y": 0,
      "z": -2,
      "name": "Soil_Dirt_Stairs",
      "rotation": 1
    },
    {
      "x": 3,
      "y": 0,
      "z": -1,
      "name": "Soil_Pathway"
    },
    {
      "x": 3,
      "y": 1,
      "z": -1,
      "name": "Soil_Dirt_Stairs",
      "rotation": 2
    },
    {
      "x": 3,
      "y": 0,
      "z": 0,
      "name": "Soil_Pathway"
    },
    {
      "x": 3,
      "y": 1,
      "z": 0,
      "name": "Ore_Thorium_Mud_Cracked"
    },
    {
      "x": 3,
      "y": 0,
      "z": 1,
      "name": "Soil_Pathway"
    },
    {
      "x": 3,
      "y": 1,
      "z": 1,
      "name": "Ore_Thorium_Mud_Cracked"
    },
    {
      "x": 3,
      "y": 2,
      "z": 1,
      "name": "Plant_Leaves_Jungle_Floor"
    },
    {
      "x": 3,
      "y": 0,
      "z": 2,
      "name": "Soil_Pathway"
    },
    {
      "x": 3,
      "y": 1,
      "z": 2,
      "name": "Ore_Thorium_Mud_Cracked"
    },
    {
      "x": 3,
      "y": 2,
      "z": 2,
      "name": "Plant_Leaves_Jungle_Floor"
    },
    {
      "x": 3,
      "y": 0,
      "z": 3,
      "name": "Soil_Pathway"
    },
    {
      "x": 3,
      "y": 1,
      "z": 3,
      "name": "Soil_Dirt_Stairs"
    },
    {
      "x": 3,
      "y": 0,
      "z": 4,
      "name": "Soil_Pathway"
    },
    {
      "x": 3,
      "y": 1,
      "z": 4,
      "name": "Soil_Dirt_Half"
    },
    {
      "x": 3,
      "y": 0,
      "z": 5,
      "name": "Soil_Pathway_Half",
      "rotation": 4
    },
    {
      "x": 4,
      "y": 0,
      "z": -1,
      "name": "Soil_Dirt_Stairs",
      "rotation": 2
    },
    {
      "x": 4,
      "y": 0,
      "z": 0,
      "name": "Soil_Pathway"
    },
    {
      "x": 4,
      "y": 1,
      "z": 0,
      "name": "Soil_Pathway_Half"
    },
    {
      "x": 4,
      "y": 0,
      "z": 1,
      "name": "Soil_Pathway"
    },
    {
      "x": 4,
      "y": 1,
      "z": 1,
      "name": "*Soil_Dirt_Half_State_Definitions_Block"
    },
    {
      "x": 4,
      "y": 0,
      "z": 2,
      "name": "Soil_Pathway"
    },
    {
      "x": 4,
      "y": 1,
      "z": 2,
      "name": "Soil_Dirt_Stairs",
      "rotation": 1
    },
    {
      "x": 4,
      "y": 0,
      "z": 3,
      "name": "Soil_Dirt_Stairs",
      "rotation": 1
    },
    {
      "x": 4,
      "y": 0,
      "z": 4,
      "name": "Soil_Pathway_Half",
      "rotation": 5
    },
    {
      "x": 5,
      "y": 0,
      "z": 0,
      "name": "Soil_Pathway_Half",
      "rotation": 5
    },
    {
      "x": 5,
      "y": 0,
      "z": 1,
      "name": "Soil_Pathway_Half",
      "rotation": 5
    },
    {
      "x": 5,
      "y": 0,
      "z": 2,
      "name": "Soil_Pathway_Half",
      "rotation": 5
    }
  ],
  "fluids": [
    {
      "x": -4,
      "y": 0,
      "z": -1,
      "name": "Empty",
      "level": 0
    },
    {
      "x": -4,
      "y": 0,
      "z": 0,
      "name": "Empty",
      "level": 0
    },
    {
      "x": -4,
      "y": 0,
      "z": 1,
      "name": "Empty",
      "level": 0
    },
    {
      "x": -4,
      "y": 0,
      "z": 2,
      "name": "Empty",
      "level": 0
    },
    {
      "x": -3,
      "y": 0,
      "z": -2,
      "name": "Empty",
      "level": 0
    },
    {
      "x": -3,
      "y": 0,
      "z": -1,
      "name": "Empty",
      "level": 0
    },
    {
      "x": -3,
      "y": 1,
      "z": -1,
      "name": "Empty",
      "level": 0
    },
    {
      "x": -3,
      "y": 0,
      "z": 0,
      "name": "Empty",
      "level": 0
    },
    {
      "x": -3,
      "y": 1,
      "z": 0,
      "name": "Empty",
      "level": 0
    },
    {
      "x": -3,
      "y": 0,
      "z": 1,
      "name": "Empty",
      "level": 0
    },
    {
      "x": -3,
      "y": 1,
      "z": 1,
      "name": "Empty",
      "level": 0
    },
    {
      "x": -3,
      "y": 0,
      "z": 2,
      "name": "Empty",
      "level": 0
    },
    {
      "x": -3,
      "y": 1,
      "z": 2,
      "name": "Empty",
      "level": 0
    },
    {
      "x": -3,
      "y": 0,
      "z": 3,
      "name": "Empty",
      "level": 0
    },
    {
      "x": -3,
      "y": 1,
      "z": 3,
      "name": "Empty",
      "level": 0
    },
    {
      "x": -2,
      "y": 0,
      "z": -3,
      "name": "Empty",
      "level": 0
    },
    {
      "x": -2,
      "y": 0,
      "z": -2,
      "name": "Empty",
      "level": 0
    },
    {
      "x": -2,
      "y": 1,
      "z": -2,
      "name": "Empty",
      "level": 0
    },
    {
      "x": -2,
      "y": 0,
      "z": -1,
      "name": "Empty",
      "level": 0
    },
    {
      "x": -2,
      "y": 1,
      "z": -1,
      "name": "Empty",
      "level": 0
    },
    {
      "x": -2,
      "y": 2,
      "z": -1,
      "name": "Empty",
      "level": 0
    },
    {
      "x": -2,
      "y": 0,
      "z": 0,
      "name": "Empty",
      "level": 0
    },
    {
      "x": -2,
      "y": 1,
      "z": 0,
      "name": "Empty",
      "level": 0
    },
    {
      "x": -2,
      "y": 2,
      "z": 0,
      "name": "Empty",
      "level": 0
    },
    {
      "x": -2,
      "y": 0,
      "z": 1,
      "name": "Empty",
      "level": 0
    },
    {
      "x": -2,
      "y": 1,
      "z": 1,
      "name": "Empty",
      "level": 0
    },
    {
      "x": -2,
      "y": 2,
      "z": 1,
      "name": "Empty",
      "level": 0
    },
    {
      "x": -2,
      "y": 0,
      "z": 2,
      "name": "Empty",
      "level": 0
    },
    {
      "x": -2,
      "y": 1,
      "z": 2,
      "name": "Empty",
      "level": 0
    },
    {
      "x": -2,
      "y": 2,
      "z": 2,
      "name": "Empty",
      "level": 0
    },
    {
      "x": -2,
      "y": 0,
      "z": 3,
      "name": "Empty",
      "level": 0
    },
    {
      "x": -2,
      "y": 1,
      "z": 3,
      "name": "Empty",
      "level": 0
    },
    {
      "x": -2,
      "y": 0,
      "z": 4,
      "name": "Empty",
      "level": 0
    },
    {
      "x": -1,
      "y": 0,
      "z": -3,
      "name": "Empty",
      "level": 0
    },
    {
      "x": -1,
      "y": 0,
      "z": -2,
      "name": "Empty",
      "level": 0
    },
    {
      "x": -1,
      "y": 1,
      "z": -2,
      "name": "Empty",
      "level": 0
    },
    {
      "x": -1,
      "y": 0,
      "z": -1,
      "name": "Empty",
      "level": 0
    },
    {
      "x": -1,
      "y": 1,
      "z": -1,
      "name": "Empty",
      "level": 0
    },
    {
      "x": -1,
      "y": 2,
      "z": -1,
      "name": "Empty",
      "level": 0
    },
    {
      "x": -1,
      "y": 0,
      "z": 0,
      "name": "Empty",
      "level": 0
    },
    {
      "x": -1,
      "y": 1,
      "z": 0,
      "name": "Empty",
      "level": 0
    },
    {
      "x": -1,
      "y": 2,
      "z": 0,
      "name": "Empty",
      "level": 0
    },
    {
      "x": -1,
      "y": 0,
      "z": 1,
      "name": "Empty",
      "level": 0
    },
    {
      "x": -1,
      "y": 1,
      "z": 1,
      "name": "Empty",
      "level": 0
    },
    {
      "x": -1,
      "y": 2,
      "z": 1,
      "name": "Empty",
      "level": 0
    },
    {
      "x": -1,
      "y": 0,
      "z": 2,
      "name": "Empty",
      "level": 0
    },
    {
      "x": -1,
      "y": 1,
      "z": 2,
      "name": "Empty",
      "level": 0
    },
    {
      "x": -1,
      "y": 2,
      "z": 2,
      "name": "Empty",
      "level": 0
    },
    {
      "x": -1,
      "y": 0,
      "z": 3,
      "name": "Empty",
      "level": 0
    },
    {
      "x": -1,
      "y": 1,
      "z": 3,
      "name": "Empty",
      "level": 0
    },
    {
      "x": -1,
      "y": 2,
      "z": 3,
      "name": "Empty",
      "level": 0
    },
    {
      "x": -1,
      "y": 0,
      "z": 4,
      "name": "Empty",
      "level": 0
    },
    {
      "x": -1,
      "y": 1,
      "z": 4,
      "name": "Empty",
      "level": 0
    },
    {
      "x": 0,
      "y": 0,
      "z": -4,
      "name": "Empty",
      "level": 0
    },
    {
      "x": 0,
      "y": 0,
      "z": -3,
      "name": "Empty",
      "level": 0
    },
    {
      "x": 0,
      "y": 1,
      "z": -3,
      "name": "Empty",
      "level": 0
    },
    {
      "x": 0,
      "y": 0,
      "z": -2,
      "name": "Empty",
      "level": 0
    },
    {
      "x": 0,
      "y": 1,
      "z": -2,
      "name": "Empty",
      "level": 0
    },
    {
      "x": 0,
      "y": 2,
      "z": -2,
      "name": "Empty",
      "level": 0
    },
    {
      "x": 0,
      "y": 0,
      "z": -1,
      "name": "Empty",
      "level": 0
    },
    {
      "x": 0,
      "y": 1,
      "z": -1,
      "name": "Empty",
      "level": 0
    },
    {
      "x": 0,
      "y": 2,
      "z": -1,
      "name": "Empty",
      "level": 0
    },
    {
      "x": 0,
      "y": 0,
      "z": 0,
      "name": "Empty",
      "level": 0
    },
    {
      "x": 0,
      "y": 1,
      "z": 0,
      "name": "Empty",
      "level": 0
    },
    {
      "x": 0,
      "y": 2,
      "z": 0,
      "name": "Empty",
      "level": 0
    },
    {
      "x": 0,
      "y": 0,
      "z": 1,
      "name": "Empty",
      "level": 0
    },
    {
      "x": 0,
      "y": 1,
      "z": 1,
      "name": "Empty",
      "level": 0
    },
    {
      "x": 0,
      "y": 0,
      "z": 2,
      "name": "Empty",
      "level": 0
    },
    {
      "x": 0,
      "y": 1,
      "z": 2,
      "name": "Empty",
      "level": 0
    },
    {
      "x": 0,
      "y": 2,
      "z": 2,
      "name": "Empty",
      "level": 0
    },
    {
      "x": 0,
      "y": 0,
      "z": 3,
      "name": "Empty",
      "level": 0
    },
    {
      "x": 0,
      "y": 1,
      "z": 3,
      "name": "Empty",
      "level": 0
    },
    {
      "x": 0,
      "y": 2,
      "z": 3,
      "name": "Empty",
      "level": 0
    },
    {
      "x": 0,
      "y": 0,
      "z": 4,
      "name": "Empty",
      "level": 0
    },
    {
      "x": 0,
      "y": 1,
      "z": 4,
      "name": "Empty",
      "level": 0
    },
    {
      "x": 0,
      "y": 0,
      "z": 5,
      "name": "Empty",
      "level": 0
    },
    {
      "x": 1,
      "y": 0,
      "z": -4,
      "name": "Empty",
      "level": 0
    },
    {
      "x": 1,
      "y": 0,
      "z": -3,
      "name": "Empty",
      "level": 0
    },
    {
      "x": 1,
      "y": 1,
      "z": -3,
      "name": "Empty",
      "level": 0
    },
    {
      "x": 1,
      "y": 0,
      "z": -2,
      "name": "Empty",
      "level": 0
    },
    {
      "x": 1,
      "y": 1,
      "z": -2,
      "name": "Empty",
      "level": 0
    },
    {
      "x": 1,
      "y": 2,
      "z": -2,
      "name": "Empty",
      "level": 0
    },
    {
      "x": 1,
      "y": 0,
      "z": -1,
      "name": "Empty",
      "level": 0
    },
    {
      "x": 1,
      "y": 1,
      "z": -1,
      "name": "Empty",
      "level": 0
    },
    {
      "x": 1,
      "y": 2,
      "z": -1,
      "name": "Empty",
      "level": 0
    },
    {
      "x": 1,
      "y": 0,
      "z": 0,
      "name": "Empty",
      "level": 0
    },
    {
      "x": 1,
      "y": 1,
      "z": 0,
      "name": "Empty",
      "level": 0
    },
    {
      "x": 1,
      "y": 2,
      "z": 0,
      "name": "Empty",
      "level": 0
    },
    {
      "x": 1,
      "y": 0,
      "z": 1,
      "name": "Empty",
      "level": 0
    },
    {
      "x": 1,
      "y": 1,
      "z": 1,
      "name": "Empty",
      "level": 0
    },
    {
      "x": 1,
      "y": 2,
      "z": 1,
      "name": "Empty",
      "level": 0
    },
    {
      "x": 1,
      "y": 0,
      "z": 2,
      "name": "Empty",
      "level": 0
    },
    {
      "x": 1,
      "y": 1,
      "z": 2,
      "name": "Empty",
      "level": 0
    },
    {
      "x": 1,
      "y": 0,
      "z": 3,
      "name": "Empty",
      "level": 0
    },
    {
      "x": 1,
      "y": 1,
      "z": 3,
      "name": "Empty",
      "level": 0
    },
    {
      "x": 1,
      "y": 2,
      "z": 3,
      "name": "Empty",
      "level": 0
    },
    {
      "x": 1,
      "y": 0,
      "z": 4,
      "name": "Empty",
      "level": 0
    },
    {
      "x": 1,
      "y": 1,
      "z": 4,
      "name": "Empty",
      "level": 0
    },
    {
      "x": 1,
      "y": 0,
      "z": 5,
      "name": "Empty",
      "level": 0
    },
    {
      "x": 2,
      "y": 0,
      "z": -4,
      "name": "Empty",
      "level": 0
    },
    {
      "x": 2,
      "y": 0,
      "z": -3,
      "name": "Empty",
      "level": 0
    },
    {
      "x": 2,
      "y": 1,
      "z": -3,
      "name": "Empty",
      "level": 0
    },
    {
      "x": 2,
      "y": 0,
      "z": -2,
      "name": "Empty",
      "level": 0
    },
    {
      "x": 2,
      "y": 1,
      "z": -2,
      "name": "Empty",
      "level": 0
    },
    {
      "x": 2,
      "y": 0,
      "z": -1,
      "name": "Empty",
      "level": 0
    },
    {
      "x": 2,
      "y": 1,
      "z": -1,
      "name": "Empty",
      "level": 0
    },
    {
      "x": 2,
      "y": 0,
      "z": 0,
      "name": "Empty",
      "level": 0
    },
    {
      "x": 2,
      "y": 1,
      "z": 0,
      "name": "Empty",
      "level": 0
    },
    {
      "x": 2,
      "y": 2,
      "z": 0,
      "name": "Empty",
      "level": 0
    },
    {
      "x": 2,
      "y": 0,
      "z": 1,
      "name": "Empty",
      "level": 0
    },
    {
      "x": 2,
      "y": 1,
      "z": 1,
      "name": "Empty",
      "level": 0
    },
    {
      "x": 2,
      "y": 2,
      "z": 1,
      "name": "Empty",
      "level": 0
    },
    {
      "x": 2,
      "y": 0,
      "z": 2,
      "name": "Empty",
      "level": 0
    },
    {
      "x": 2,
      "y": 1,
      "z": 2,
      "name": "Empty",
      "level": 0
    },
    {
      "x": 2,
      "y": 2,
      "z": 2,
      "name": "Empty",
      "level": 0
    },
    {
      "x": 2,
      "y": 0,
      "z": 3,
      "name": "Empty",
      "level": 0
    },
    {
      "x": 2,
      "y": 1,
      "z": 3,
      "name": "Empty",
      "level": 0
    },
    {
      "x": 2,
      "y": 0,
      "z": 4,
      "name": "Empty",
      "level": 0
    },
    {
      "x": 2,
      "y": 1,
      "z": 4,
      "name": "Empty",
      "level": 0
    },
    {
      "x": 2,
      "y": 0,
      "z": 5,
      "name": "Empty",
      "level": 0
    },
    {
      "x": 3,
      "y": 0,
      "z": -3,
      "name": "Empty",
      "level": 0
    },
    {
      "x": 3,
      "y": 0,
      "z": -2,
      "name": "Empty",
      "level": 0
    },
    {
      "x": 3,
      "y": 0,
      "z": -1,
      "name": "Empty",
      "level": 0
    },
    {
      "x": 3,
      "y": 1,
      "z": -1,
      "name": "Empty",
      "level": 0
    },
    {
      "x": 3,
      "y": 0,
      "z": 0,
      "name": "Empty",
      "level": 0
    },
    {
      "x": 3,
      "y": 1,
      "z": 0,
      "name": "Empty",
      "level": 0
    },
    {
      "x": 3,
      "y": 0,
      "z": 1,
      "name": "Empty",
      "level": 0
    },
    {
      "x": 3,
      "y": 1,
      "z": 1,
      "name": "Empty",
      "level": 0
    },
    {
      "x": 3,
      "y": 2,
      "z": 1,
      "name": "Empty",
      "level": 0
    },
    {
      "x": 3,
      "y": 0,
      "z": 2,
      "name": "Empty",
      "level": 0
    },
    {
      "x": 3,
      "y": 1,
      "z": 2,
      "name": "Empty",
      "level": 0
    },
    {
      "x": 3,
      "y": 2,
      "z": 2,
      "name": "Empty",
      "level": 0
    },
    {
      "x": 3,
      "y": 0,
      "z": 3,
      "name": "Empty",
      "level": 0
    },
    {
      "x": 3,
      "y": 1,
      "z": 3,
      "name": "Empty",
      "level": 0
    },
    {
      "x": 3,
      "y": 0,
      "z": 4,
      "name": "Empty",
      "level": 0
    },
    {
      "x": 3,
      "y": 1,
      "z": 4,
      "name": "Empty",
      "level": 0
    },
    {
      "x": 3,
      "y": 0,
      "z": 5,
      "name": "Empty",
      "level": 0
    },
    {
      "x": 4,
      "y": 0,
      "z": -1,
      "name": "Empty",
      "level": 0
    },
    {
      "x": 4,
      "y": 0,
      "z": 0,
      "name": "Empty",
      "level": 0
    },
    {
      "x": 4,
      "y": 1,
      "z": 0,
      "name": "Empty",
      "level": 0
    },
    {
      "x": 4,
      "y": 0,
      "z": 1,
      "name": "Empty",
      "level": 0
    },
    {
      "x": 4,
      "y": 1,
      "z": 1,
      "name": "Empty",
      "level": 0
    },
    {
      "x": 4,
      "y": 0,
      "z": 2,
      "name": "Empty",
      "level": 0
    },
    {
      "x": 4,
      "y": 1,
      "z": 2,
      "name": "Empty",
      "level": 0
    },
    {
      "x": 4,
      "y": 0,
      "z": 3,
      "name": "Empty",
      "level": 0
    },
    {
      "x": 4,
      "y": 0,
      "z": 4,
      "name": "Empty",
      "level": 0
    },
    {
      "x": 5,
      "y": 0,
      "z": 0,
      "name": "Empty",
      "level": 0
    },
    {
      "x": 5,
      "y": 0,
      "z": 1,
      "name": "Empty",
      "level": 0
    },
    {
      "x": 5,
      "y": 0,
      "z": 2,
      "name": "Empty",
      "level": 0
    }
  ]
}