{
  "version": 8,
  "blockIdVersion": 11,
  "anchorX": 5,
  "anchorY": -1,
  "anchorZ": 7,
  "blocks": [
    {
      "x": 0,
      "y": -4,
      "z": 1,
      "name": "Soil_Mud_Dry"
    },
    {
      "x": 0,
      "y": -3,
      "z": 1,
      "name": "Soil_Mud_Dry"
    },
    {
      "x": 0,
      "y": -2,
      "z": 1,
      "name": "Soil_Mud_Dry"
    },
    {
      "x": 0,
      "y": -4,
      "z": 2,
      "name": "Soil_Mud_Dry"
    },
    {
      "x": 0,
      "y": -3,
      "z": 2,
      "name": "Soil_Mud_Dry"
    },
    {
      "x": 0,
      "y": -2,
      "z": 2,
      "name": "Soil_Mud_Dry"
    },
    {
      "x": 0,
      "y": -1,
      "z": 2,
      "name": "Soil_Mud_Dry"
    },
    {
      "x": 0,
      "y": 0,
      "z": 2,
      "name": "Deco_Bone_Ribs_Long",
      "rotation": 5
    },
    {
      "x": 0,
      "y": -5,
      "z": 3,
      "name": "Soil_Mud_Dry"
    },
    {
      "x": 0,
      "y": -4,
      "z": 3,
      "name": "Soil_Mud_Dry"
    },
    {
      "x": 0,
      "y": -3,
      "z": 3,
      "name": "Soil_Mud_Dry"
    },
    {
      "x": 0,
      "y": -2,
      "z": 3,
      "name": "Soil_Mud_Dry"
    },
    {
      "x": 0,
      "y": -5,
      "z": 4,
      "name": "Soil_Mud_Dry"
    },
    {
      "x": 0,
      "y": -4,
      "z": 4,
      "name": "Soil_Mud_Dry"
    },
    {
      "x": 0,
      "y": -3,
      "z": 4,
      "name": "Soil_Mud_Dry"
    },
    {
      "x": 0,
      "y": -3,
      "z": 5,
      "name": "Soil_Mud_Dry"
    },
    {
      "x": 1,
      "y": -4,
      "z": 0,
      "name": "Soil_Mud_Dry"
    },
    {
      "x": 1,
      "y": -3,
      "z": 0,
      "name": "Soil_Mud_Dry"
    },
    {
      "x": 1,
      "y": -2,
      "z": 0,
      "name": "Soil_Mud_Dry"
    },
    {
      "x": 1,
      "y": -5,
      "z": 1,
      "name": "Soil_Mud_Dry"
    },
    {
      "x": 1,
      "y": -4,
      "z": 1,
      "name": "Soil_Mud_Dry"
    },
    {
      "x": 1,
      "y": -3,
      "z": 1,
      "name": "Soil_Mud_Dry"
    },
    {
      "x": 1,
      "y": -2,
      "z": 1,
      "name": "Soil_Mud_Dry"
    },
    {
      "x": 1,
      "y": -1,
      "z": 1,
      "name": "Soil_Mud_Dry"
    },
    {
      "x": 1,
      "y": -5,
      "z": 2,
      "name": "Soil_Mud_Dry"
    },
    {
      "x": 1,
      "y": -4,
      "z": 2,
      "name": "Soil_Mud_Dry"
    },
    {
      "x": 1,
      "y": -3,
      "z": 2,
      "name": "Soil_Mud_Dry"
    },
    {
      "x": 1,
      "y": -2,
      "z": 2,
      "name": "Soil_Mud_Dry"
    },
    {
      "x": 1,
      "y": -1,
      "z": 2,
      "name": "Soil_Mud_Dry"
    },
    {
      "x": 1,
      "y": 0,
      "z": 2,
      "name": "Deco_Bone_Spine",
      "rotation": 1
    },
    {
      "x": 1,
      "y": -6,
      "z": 3,
      "name": "Soil_Mud_Dry"
    },
    {
      "x": 1,
      "y": -5,
      "z": 3,
      "name": "Soil_Mud_Dry"
    },
    {
      "x": 1,
      "y": -4,
      "z": 3,
      "name": "Soil_Mud_Dry"
    },
    {
      "x": 1,
      "y": -3,
      "z": 3,
      "name": "Soil_Mud_Dry"
    },
    {
      "x": 1,
      "y": -2,
      "z": 3,
      "name": "Soil_Mud_Dry"
    },
    {
      "x": 1,
      "y": -1,
      "z": 3,
      "name": "Soil_Mud_Dry"
    },
    {
      "x": 1,
      "y": -6,
      "z": 4,
      "name": "Soil_Mud_Dry"
    },
    {
      "x": 1,
      "y": -5,
      "z": 4,
      "name": "Soil_Mud_Dry"
    },
    {
      "x": 1,
      "y": -4,
      "z": 4,
      "name": "Soil_Mud_Dry"
    },
    {
      "x": 1,
      "y": -3,
      "z": 4,
      "name": "Soil_Mud_Dry"
    },
    {
      "x": 1,
      "y": -2,
      "z": 4,
      "name": "Soil_Mud_Dry"
    },
    {
      "x": 1,
      "y": -1,
      "z": 4,
      "name": "Soil_Mud_Dry"
    },
    {
      "x": 1,
      "y": -5,
      "z": 5,
      "name": "Soil_Mud_Dry"
    },
    {
      "x": 1,
      "y": -4,
      "z": 5,
      "name": "Soil_Mud_Dry"
    },
    {
      "x": 1,
      "y": -3,
      "z": 5,
      "name": "Soil_Mud_Dry"
    },
    {
      "x": 1,
      "y": -2,
      "z": 5,
      "name": "Soil_Mud_Dry"
    },
    {
      "x": 1,
      "y": -5,
      "z": 6,
      "name": "Soil_Mud_Dry"
    },
    {
      "x": 1,
      "y": -4,
      "z": 6,
      "name": "Soil_Mud_Dry"
    },
    {
      "x": 1,
      "y": -3,
      "z": 6,
      "name": "Soil_Mud_Dry"
    },
    {
      "x": 1,
      "y": -2,
      "z": 6,
      "name": "Soil_Mud_Dry"
    },
    {
      "x": 2,
      "y": -4,
      "z": -1,
      "name": "Soil_Mud_Dry"
    },
    {
      "x": 2,
      "y": -3,
      "z": -1,
      "name": "Soil_Mud_Dry"
    },
    {
      "x": 2,
      "y": -5,
      "z": 0,
      "name": "Soil_Mud_Dry"
    },
    {
      "x": 2,
      "y": -4,
      "z": 0,
      "name": "Soil_Mud_Dry"
    },
    {
      "x": 2,
      "y": -3,
      "z": 0,
      "name": "Soil_Mud_Dry"
    },
    {
      "x": 2,
      "y": -2,
      "z": 0,
      "name": "Soil_Mud_Dry"
    },
    {
      "x": 2,
      "y": -1,
      "z": 0,
      "name": "Soil_Mud_Dry"
    },
    {
      "x": 2,
      "y": -5,
      "z": 1,
      "name": "Soil_Mud_Dry"
    },
    {
      "x": 2,
      "y": -4,
      "z": 1,
      "name": "Soil_Mud_Dry"
    },
    {
      "x": 2,
      "y": -3,
      "z": 1,
      "name": "Soil_Mud_Dry"
    },
    {
      "x": 2,
      "y": -2,
      "z": 1,
      "name": "Soil_Mud_Dry"
    },
    {
      "x": 2,
      "y": -1,
      "z": 1,
      "name": "Soil_Mud_Dry"
    },
    {
      "x": 2,
      "y": 0,
      "z": 1,
      "name": "Deco_Bone_Ribs",
      "rotation": 2
    },
    {
      "x": 2,
      "y": -6,
      "z": 2,
      "name": "Soil_Mud_Dry"
    },
    {
      "x": 2,
      "y": -5,
      "z": 2,
      "name": "Soil_Mud_Dry"
    },
    {
      "x": 2,
      "y": -4,
      "z": 2,
      "name": "Soil_Mud_Dry"
    },
    {
      "x": 2,
      "y": -3,
      "z": 2,
      "name": "Soil_Mud_Dry"
    },
    {
      "x": 2,
      "y": -2,
      "z": 2,
      "name": "Soil_Mud_Dry"
    },
    {
      "x": 2,
      "y": -1,
      "z": 2,
      "name": "Soil_Mud_Dry"
    },
    {
      "x": 2,
      "y": 0,
      "z": 2,
      "name": "Deco_Bone_Spine",
      "rotation": 1
    },
    {
      "x": 2,
      "y": -7,
      "z": 3,
      "name": "Soil_Mud_Dry"
    },
    {
      "x": 2,
      "y": -6,
      "z": 3,
      "name": "Soil_Mud_Dry"
    },
    {
      "x": 2,
      "y": -5,
      "z": 3,
      "name": "Soil_Mud_Dry"
    },
    {
      "x": 2,
      "y": -4,
      "z": 3,
      "name": "Soil_Mud_Dry"
    },
    {
      "x": 2,
      "y": -3,
      "z": 3,
      "name": "Soil_Mud_Dry"
    },
    {
      "x": 2,
      "y": -2,
      "z": 3,
      "name": "Soil_Mud_Dry"
    },
    {
      "x": 2,
      "y": -1,
      "z": 3,
      "name": "Soil_Mud_Dry"
    },
    {
      "x": 2,
      "y": 0,
      "z": 3,
      "name": "Deco_Bone_Ribs"
    },
    {
      "x": 2,
      "y": -7,
      "z": 4,
      "name": "Soil_Mud_Dry"
    },
    {
      "x": 2,
      "y": -6,
      "z": 4,
      "name": "Soil_Mud_Dry"
    },
    {
      "x": 2,
      "y": -5,
      "z": 4,
      "name": "Soil_Mud_Dry"
    },
    {
      "x": 2,
      "y": -4,
      "z": 4,
      "name": "Soil_Mud_Dry"
    },
    {
      "x": 2,
      "y": -3,
      "z": 4,
      "name": "Soil_Mud_Dry"
    },
    {
      "x": 2,
      "y": -2,
      "z": 4,
      "name": "Soil_Mud_Dry"
    },
    {
      "x": 2,
      "y": -1,
      "z": 4,
      "name": "Soil_Dirt"
    },
    {
      "x": 2,
      "y": -7,
      "z": 5,
      "name": "Soil_Mud_Dry"
    },
    {
      "x": 2,
      "y": -6,
      "z": 5,
      "name": "Soil_Mud_Dry"
    },
    {
      "x": 2,
      "y": -5,
      "z": 5,
      "name": "Soil_Mud_Dry"
    },
    {
      "x": 2,
      "y": -4,
      "z": 5,
      "name": "Soil_Mud_Dry"
    },
    {
      "x": 2,
      "y": -3,
      "z": 5,
      "name": "Soil_Dirt"
    },
    {
      "x": 2,
      "y": -2,
      "z": 5,
      "name": "Soil_Dirt"
    },
    {
      "x": 2,
      "y": -6,
      "z": 6,
      "name": "Soil_Mud_Dry"
    },
    {
      "x": 2,
      "y": -5,
      "z": 6,
      "name": "Soil_Mud_Dry"
    },
    {
      "x": 2,
      "y": -4,
      "z": 6,
      "name": "Soil_Mud_Dry"
    },
    {
      "x": 2,
      "y": -3,
      "z": 6,
      "name": "Soil_Mud_Dry"
    },
    {
      "x": 2,
      "y": -2,
      "z": 6,
      "name": "Soil_Dirt"
    },
    {
      "x": 2,
      "y": -5,
      "z": 7,
      "name": "Soil_Mud_Dry"
    },
    {
      "x": 2,
      "y": -4,
      "z": 7,
      "name": "Soil_Mud_Dry"
    },
    {
      "x": 2,
      "y": -3,
      "z": 7,
      "name": "Soil_Mud_Dry"
    },
    {
      "x": 2,
      "y": -2,
      "z": 7,
      "name": "Soil_Mud_Dry"
    },
    {
      "x": 2,
      "y": -4,
      "z": 8,
      "name": "Soil_Mud_Dry"
    },
    {
      "x": 2,
      "y": -3,
      "z": 8,
      "name": "Soil_Mud_Dry"
    },
    {
      "x": 3,
      "y": -4,
      "z": -1,
      "name": "Soil_Mud_Dry"
    },
    {
      "x": 3,
      "y": -3,
      "z": -1,
      "name": "Soil_Mud_Dry"
    },
    {
      "x": 3,
      "y": -5,
      "z": 0,
      "name": "Soil_Mud_Dry"
    },
    {
      "x": 3,
      "y": -4,
      "z": 0,
      "name": "Soil_Mud_Dry"
    },
    {
      "x": 3,
      "y": -3,
      "z": 0,
      "name": "Soil_Mud_Dry"
    },
    {
      "x": 3,
      "y": -2,
      "z": 0,
      "name": "Soil_Mud_Dry"
    },
    {
      "x": 3,
      "y": -6,
      "z": 1,
      "name": "Soil_Mud_Dry"
    },
    {
      "x": 3,
      "y": -5,
      "z": 1,
      "name": "Soil_Mud_Dry"
    },
    {
      "x": 3,
      "y": -4,
      "z": 1,
      "name": "Soil_Mud_Dry"
    },
    {
      "x": 3,
      "y": -3,
      "z": 1,
      "name": "Soil_Mud_Dry"
    },
    {
      "x": 3,
      "y": -2,
      "z": 1,
      "name": "Soil_Mud_Dry"
    },
    {
      "x": 3,
      "y": -1,
      "z": 1,
      "name": "Soil_Mud_Dry"
    },
    {
      "x": 3,
      "y": 0,
      "z": 1,
      "name": "Deco_Bone_Ribs_Long",
      "rotation": 4
    },
    {
      "x": 3,
      "y": -7,
      "z": 2,
      "name": "Soil_Mud_Dry"
    },
    {
      "x": 3,
      "y": -6,
      "z": 2,
      "name": "Soil_Mud_Dry"
    },
    {
      "x": 3,
      "y": -5,
      "z": 2,
      "name": "Soil_Mud_Dry"
    },
    {
      "x": 3,
      "y": -4,
      "z": 2,
      "name": "Soil_Mud_Dry"
    },
    {
      "x": 3,
      "y": -3,
      "z": 2,
      "name": "Soil_Mud_Dry"
    },
    {
      "x": 3,
      "y": -2,
      "z": 2,
      "name": "Soil_Mud_Dry"
    },
    {
      "x": 3,
      "y": -1,
      "z": 2,
      "name": "Soil_Mud_Dry"
    },
    {
      "x": 3,
      "y": 0,
      "z": 2,
      "name": "Deco_Bone_Spine",
      "rotation": 1
    },
    {
      "x": 3,
      "y": -7,
      "z": 3,
      "name": "Soil_Mud_Dry"
    },
    {
      "x": 3,
      "y": -6,
      "z": 3,
      "name": "Soil_Mud_Dry"
    },
    {
      "x": 3,
      "y": -5,
      "z": 3,
      "name": "Soil_Mud_Dry"
    },
    {
      "x": 3,
      "y": -4,
      "z": 3,
      "name": "Soil_Mud_Dry"
    },
    {
      "x": 3,
      "y": -3,
      "z": 3,
      "name": "Soil_Mud_Dry"
    },
    {
      "x": 3,
      "y": -2,
      "z": 3,
      "name": "Soil_Mud_Dry"
    },
    {
      "x": 3,
      "y": -1,
      "z": 3,
      "name": "Soil_Mud_Dry"
    },
    {
      "x": 3,
      "y": 0,
      "z": 3,
      "name": "Deco_Bone_Ribs_Long",
      "rotation": 4
    },
    {
      "x": 3,
      "y": -7,
      "z": 4,
      "name": "Soil_Mud_Dry"
    },
    {
      "x": 3,
      "y": -6,
      "z": 4,
      "name": "Soil_Mud_Dry"
    },
    {
      "x": 3,
      "y": -5,
      "z": 4,
      "name": "Soil_Mud_Dry"
    },
    {
      "x": 3,
      "y": -4,
      "z": 4,
      "name": "Soil_Mud_Dry"
    },
    {
      "x": 3,
      "y": -3,
      "z": 4,
      "name": "Soil_Mud_Dry"
    },
    {
      "x": 3,
      "y": -2,
      "z": 4,
      "name": "Soil_Mud_Dry"
    },
    {
      "x": 3,
      "y": -1,
      "z": 4,
      "name": "Soil_Mud_Dry"
    },
    {
      "x": 3,
      "y": -8,
      "z": 5,
      "name": "Soil_Mud_Dry"
    },
    {
      "x": 3,
      "y": -7,
      "z": 5,
      "name": "Soil_Mud_Dry"
    },
    {
      "x": 3,
      "y": -6,
      "z": 5,
      "name": "Soil_Mud_Dry"
    },
    {
      "x": 3,
      "y": -5,
      "z": 5,
      "name": "Soil_Mud_Dry"
    },
    {
      "x": 3,
      "y": -4,
      "z": 5,
      "name": "Soil_Mud_Dry"
    },
    {
      "x": 3,
      "y": -3,
      "z": 5,
      "name": "Soil_Mud_Dry"
    },
    {
      "x": 3,
      "y": -2,
      "z": 5,
      "name": "Soil_Mud_Dry"
    },
    {
      "x": 3,
      "y": -1,
      "z": 5,
      "name": "Soil_Mud_Dry"
    },
    {
      "x": 3,
      "y": -7,
      "z": 6,
      "name": "Soil_Mud_Dry"
    },
    {
      "x": 3,
      "y": -6,
      "z": 6,
      "name": "Soil_Mud_Dry"
    },
    {
      "x": 3,
      "y": -5,
      "z": 6,
      "name": "Soil_Mud_Dry"
    },
    {
      "x": 3,
      "y": -4,
      "z": 6,
      "name": "Soil_Mud_Dry"
    },
    {
      "x": 3,
      "y": -3,
      "z": 6,
      "name": "Soil_Mud_Dry"
    },
    {
      "x": 3,
      "y": -2,
      "z": 6,
      "name": "Soil_Mud_Dry"
    },
    {
      "x": 3,
      "y": -1,
      "z": 6,
      "name": "Soil_Mud_Dry"
    },
    {
      "x": 3,
      "y": 0,
      "z": 6,
      "name": "Deco_Bone_Pile"
    },
    {
      "x": 3,
      "y": -7,
      "z": 7,
      "name": "Soil_Mud_Dry"
    },
    {
      "x": 3,
      "y": -6,
      "z": 7,
      "name": "Soil_Mud_Dry"
    },
    {
      "x": 3,
      "y": -5,
      "z": 7,
      "name": "Soil_Mud_Dry"
    },
    {
      "x": 3,
      "y": -4,
      "z": 7,
      "name": "Soil_Mud_Dry"
    },
    {
      "x": 3,
      "y": -3,
      "z": 7,
      "name": "Soil_Mud_Dry"
    },
    {
      "x": 3,
      "y": -2,
      "z": 7,
      "name": "Soil_Mud_Dry"
    },
    {
      "x": 3,
      "y": -1,
      "z": 7,
      "name": "Soil_Mud_Dry"
    },
    {
      "x": 3,
      "y": -6,
      "z": 8,
      "name": "Soil_Mud_Dry"
    },
    {
      "x": 3,
      "y": -5,
      "z": 8,
      "name": "Soil_Mud_Dry"
    },
    {
      "x": 3,
      "y": -4,
      "z": 8,
      "name": "Soil_Mud_Dry"
    },
    {
      "x": 3,
      "y": -3,
      "z": 8,
      "name": "Soil_Mud_Dry"
    },
    {
      "x": 3,
      "y": -2,
      "z": 8,
      "name": "Soil_Mud_Dry"
    },
    {
      "x": 3,
      "y": -4,
      "z": 9,
      "name": "Soil_Mud_Dry"
    },
    {
      "x": 3,
      "y": -3,
      "z": 9,
      "name": "Soil_Mud_Dry"
    },
    {
      "x": 3,
      "y": -2,
      "z": 9,
      "name": "Soil_Dirt"
    },
    {
      "x": 4,
      "y": -4,
      "z": -1,
      "name": "Soil_Mud_Dry"
    },
    {
      "x": 4,
      "y": -3,
      "z": -1,
      "name": "Soil_Mud_Dry"
    },
    {
      "x": 4,
      "y": -6,
      "z": 0,
      "name": "Soil_Mud_Dry"
    },
    {
      "x": 4,
      "y": -5,
      "z": 0,
      "name": "Soil_Mud_Dry"
    },
    {
      "x": 4,
      "y": -4,
      "z": 0,
      "name": "Soil_Mud_Dry"
    },
    {
      "x": 4,
      "y": -3,
      "z": 0,
      "name": "Soil_Mud_Dry"
    },
    {
      "x": 4,
      "y": -2,
      "z": 0,
      "name": "Soil_Mud_Dry"
    },
    {
      "x": 4,
      "y": 0,
      "z": 0,
      "name": "Deco_Bone_Ribs",
      "rotation": 2
    },
    {
      "x": 4,
      "y": -7,
      "z": 1,
      "name": "Soil_Mud_Dry"
    },
    {
      "x": 4,
      "y": -6,
      "z": 1,
      "name": "Soil_Mud_Dry"
    },
    {
      "x": 4,
      "y": -5,
      "z": 1,
      "name": "Soil_Mud_Dry"
    },
    {
      "x": 4,
      "y": -4,
      "z": 1,
      "name": "Soil_Mud_Dry"
    },
    {
      "x": 4,
      "y": -3,
      "z": 1,
      "name": "Soil_Mud_Dry"
    },
    {
      "x": 4,
      "y": -2,
      "z": 1,
      "name": "Soil_Mud_Dry"
    },
    {
      "x": 4,
      "y": -1,
      "z": 1,
      "name": "Soil_Mud_Dry"
    },
    {
      "x": 4,
      "y": 0,
      "z": 1,
      "name": "Deco_Bone_Ribs_Long",
      "rotation": 4
    },
    {
      "x": 4,
      "y": -7,
      "z": 2,
      "name": "Soil_Mud_Dry"
    },
    {
      "x": 4,
      "y": -6,
      "z": 2,
      "name": "Soil_Mud_Dry"
    },
    {
      "x": 4,
      "y": -5,
      "z": 2,
      "name": "Soil_Mud_Dry"
    },
    {
      "x": 4,
      "y": -4,
      "z": 2,
      "name": "Soil_Mud_Dry"
    },
    {
      "x": 4,
      "y": -3,
      "z": 2,
      "name": "Soil_Mud_Dry"
    },
    {
      "x": 4,
      "y": -2,
      "z": 2,
      "name": "Soil_Mud_Dry"
    },
    {
      "x": 4,
      "y": -1,
      "z": 2,
      "name": "Soil_Mud_Dry"
    },
    {
      "x": 4,
      "y": 0,
      "z": 2,
      "name": "Deco_Bone_Spine",
      "rotation": 1
    },
    {
      "x": 4,
      "y": -7,
      "z": 3,
      "name": "Soil_Mud_Dry"
    },
    {
      "x": 4,
      "y": -6,
      "z": 3,
      "name": "Soil_Mud_Dry"
    },
    {
      "x": 4,
      "y": -5,
      "z": 3,
      "name": "Soil_Mud_Dry"
    },
    {
      "x": 4,
      "y": -4,
      "z": 3,
      "name": "Soil_Mud_Dry"
    },
    {
      "x": 4,
      "y": -3,
      "z": 3,
      "name": "Soil_Mud_Dry"
    },
    {
      "x": 4,
      "y": -2,
      "z": 3,
      "name": "Soil_Mud_Dry"
    },
    {
      "x": 4,
      "y": -1,
      "z": 3,
      "name": "Soil_Mud_Dry"
    },
    {
      "x": 4,
      "y": -8,
      "z": 4,
      "name": "Soil_Mud_Dry"
    },
    {
      "x": 4,
      "y": -7,
      "z": 4,
      "name": "Soil_Mud_Dry"
    },
    {
      "x": 4,
      "y": -6,
      "z": 4,
      "name": "Soil_Mud_Dry"
    },
    {
      "x": 4,
      "y": -5,
      "z": 4,
      "name": "Soil_Mud_Dry"
    },
    {
      "x": 4,
      "y": -4,
      "z": 4,
      "name": "Soil_Mud_Dry"
    },
    {
      "x": 4,
      "y": -3,
      "z": 4,
      "name": "Soil_Mud_Dry"
    },
    {
      "x": 4,
      "y": -2,
      "z": 4,
      "name": "Soil_Mud_Dry"
    },
    {
      "x": 4,
      "y": -1,
      "z": 4,
      "name": "Soil_Dirt"
    },
    {
      "x": 4,
      "y": -8,
      "z": 5,
      "name": "Soil_Mud_Dry"
    },
    {
      "x": 4,
      "y": -7,
      "z": 5,
      "name": "Soil_Mud_Dry"
    },
    {
      "x": 4,
      "y": -6,
      "z": 5,
      "name": "Soil_Mud_Dry"
    },
    {
      "x": 4,
      "y": -5,
      "z": 5,
      "name": "Soil_Mud_Dry"
    },
    {
      "x": 4,
      "y": -4,
      "z": 5,
      "name": "Soil_Mud_Dry"
    },
    {
      "x": 4,
      "y": -3,
      "z": 5,
      "name": "Soil_Mud_Dry"
    },
    {
      "x": 4,
      "y": -2,
      "z": 5,
      "name": "Soil_Mud_Dry"
    },
    {
      "x": 4,
      "y": -1,
      "z": 5,
      "name": "Soil_Mud_Dry"
    },
    {
      "x": 4,
      "y": -8,
      "z": 6,
      "name": "Soil_Mud_Dry"
    },
    {
      "x": 4,
      "y": -7,
      "z": 6,
      "name": "Soil_Mud_Dry"
    },
    {
      "x": 4,
      "y": -6,
      "z": 6,
      "name": "Soil_Mud_Dry"
    },
    {
      "x": 4,
      "y": -5,
      "z": 6,
      "name": "Soil_Mud_Dry"
    },
    {
      "x": 4,
      "y": -4,
      "z": 6,
      "name": "Soil_Mud_Dry"
    },
    {
      "x": 4,
      "y": -3,
      "z": 6,
      "name": "Soil_Mud_Dry"
    },
    {
      "x": 4,
      "y": -2,
      "z": 6,
      "name": "Soil_Mud_Dry"
    },
    {
      "x": 4,
      "y": -1,
      "z": 6,
      "name": "Soil_Mud_Dry"
    },
    {
      "x": 4,
      "y": -8,
      "z": 7,
      "name": "Soil_Mud_Dry"
    },
    {
      "x": 4,
      "y": -7,
      "z": 7,
      "name": "Soil_Mud_Dry"
    },
    {
      "x": 4,
      "y": -6,
      "z": 7,
      "name": "Soil_Mud_Dry"
    },
    {
      "x": 4,
      "y": -5,
      "z": 7,
      "name": "Soil_Mud_Dry"
    },
    {
      "x": 4,
      "y": -4,
      "z": 7,
      "name": "Soil_Mud_Dry"
    },
    {
      "x": 4,
      "y": -3,
      "z": 7,
      "name": "Soil_Mud_Dry"
    },
    {
      "x": 4,
      "y": -2,
      "z": 7,
      "name": "Soil_Mud_Dry"
    },
    {
      "x": 4,
      "y": -1,
      "z": 7,
      "name": "Soil_Mud_Dry"
    },
    {
      "x": 4,
      "y": -8,
      "z": 8,
      "name": "Soil_Mud_Dry"
    },
    {
      "x": 4,
      "y": -7,
      "z": 8,
      "name": "Soil_Mud_Dry"
    },
    {
      "x": 4,
      "y": -6,
      "z": 8,
      "name": "Soil_Mud_Dry"
    },
    {
      "x": 4,
      "y": -5,
      "z": 8,
      "name": "Soil_Mud_Dry"
    },
    {
      "x": 4,
      "y": -4,
      "z": 8,
      "name": "Soil_Mud_Dry"
    },
    {
      "x": 4,
      "y": -3,
      "z": 8,
      "name": "Soil_Mud_Dry"
    },
    {
      "x": 4,
      "y": -2,
      "z": 8,
      "name": "Soil_Mud_Dry"
    },
    {
      "x": 4,
      "y": -1,
      "z": 8,
      "name": "Soil_Mud_Dry"
    },
    {
      "x": 4,
      "y": -7,
      "z": 9,
      "name": "Soil_Mud_Dry"
    },
    {
      "x": 4,
      "y": -6,
      "z": 9,
      "name": "Soil_Mud_Dry"
    },
    {
      "x": 4,
      "y": -5,
      "z": 9,
      "name": "Soil_Mud_Dry"
    },
    {
      "x": 4,
      "y": -4,
      "z": 9,
      "name": "Soil_Mud_Dry"
    },
    {
      "x": 4,
      "y": -3,
      "z": 9,
      "name": "Soil_Mud_Dry"
    },
    {
      "x": 4,
      "y": -2,
      "z": 9,
      "name": "Soil_Mud_Dry"
    },
    {
      "x": 4,
      "y": -1,
      "z": 9,
      "name": "Soil_Mud_Dry"
    },
    {
      "x": 4,
      "y": -5,
      "z": 10,
      "name": "Soil_Mud_Dry"
    },
    {
      "x": 4,
      "y": -4,
      "z": 10,
      "name": "Soil_Mud_Dry"
    },
    {
      "x": 4,
      "y": -3,
      "z": 10,
      "name": "Soil_Mud_Dry"
    },
    {
      "x": 4,
      "y": -2,
      "z": 10,
      "name": "Soil_Mud_Dry"
    },
    {
      "x": 4,
      "y": -1,
      "z": 10,
      "name": "Soil_Mud_Dry"
    },
    {
      "x": 4,
      "y": 0,
      "z": 10,
      "name": "Deco_Bone_Pile"
    },
    {
      "x": 4,
      "y": -5,
      "z": 11,
      "name": "Soil_Mud_Dry"
    },
    {
      "x": 4,
      "y": -4,
      "z": 11,
      "name": "Soil_Mud_Dry"
    },
    {
      "x": 4,
      "y": -3,
      "z": 11,
      "name": "Soil_Mud_Dry"
    },
    {
      "x": 4,
      "y": -2,
      "z": 11,
      "name": "Soil_Mud_Dry"
    },
    {
      "x": 5,
      "y": -4,
      "z": -1,
      "name": "Soil_Mud_Dry"
    },
    {
      "x": 5,
      "y": -3,
      "z": -1,
      "name": "Soil_Dirt"
    },
    {
      "x": 5,
      "y": -2,
      "z": -1,
      "name": "Soil_Mud_Dry"
    },
    {
      "x": 5,
      "y": -6,
      "z": 0,
      "name": "Soil_Mud_Dry"
    },
    {
      "x": 5,
      "y": -5,
      "z": 0,
      "name": "Soil_Mud_Dry"
    },
    {
      "x": 5,
      "y": -4,
      "z": 0,
      "name": "Soil_Mud_Dry"
    },
    {
      "x": 5,
      "y": -3,
      "z": 0,
      "name": "Soil_Dirt"
    },
    {
      "x": 5,
      "y": -2,
      "z": 0,
      "name": "Soil_Mud_Dry"
    },
    {
      "x": 5,
      "y": -1,
      "z": 0,
      "name": "Soil_Mud_Dry"
    },
    {
      "x": 5,
      "y": -7,
      "z": 1,
      "name": "Soil_Mud_Dry"
    },
    {
      "x": 5,
      "y": -6,
      "z": 1,
      "name": "Soil_Mud_Dry"
    },
    {
      "x": 5,
      "y": -5,
      "z": 1,
      "name": "Soil_Mud_Dry"
    },
    {
      "x": 5,
      "y": -4,
      "z": 1,
      "name": "Soil_Mud_Dry"
    },
    {
      "x": 5,
      "y": -3,
      "z": 1,
      "name": "Soil_Mud_Dry"
    },
    {
      "x": 5,
      "y": -2,
      "z": 1,
      "name": "Soil_Mud_Dry"
    },
    {
      "x": 5,
      "y": -1,
      "z": 1,
      "name": "Soil_Mud_Dry"
    },
    {
      "x": 5,
      "y": 0,
      "z": 1,
      "name": "Deco_Bone_Ribs",
      "rotation": 2
    },
    {
      "x": 5,
      "y": -7,
      "z": 2,
      "name": "Soil_Mud_Dry"
    },
    {
      "x": 5,
      "y": -6,
      "z": 2,
      "name": "Soil_Mud_Dry"
    },
    {
      "x": 5,
      "y": -5,
      "z": 2,
      "name": "Soil_Mud_Dry"
    },
    {
      "x": 5,
      "y": -4,
      "z": 2,
      "name": "Soil_Mud_Dry"
    },
    {
      "x": 5,
      "y": -3,
      "z": 2,
      "name": "Soil_Mud_Dry"
    },
    {
      "x": 5,
      "y": -2,
      "z": 2,
      "name": "Soil_Mud_Dry"
    },
    {
      "x": 5,
      "y": -1,
      "z": 2,
      "name": "Soil_Mud_Dry"
    },
    {
      "x": 5,
      "y": 0,
      "z": 2,
      "name": "Deco_Bone_Ribs_Long",
      "rotation": 4
    },
    {
      "x": 5,
      "y": -8,
      "z": 3,
      "name": "Soil_Mud_Dry"
    },
    {
      "x": 5,
      "y": -7,
      "z": 3,
      "name": "Soil_Mud_Dry"
    },
    {
      "x": 5,
      "y": -6,
      "z": 3,
      "name": "Soil_Mud_Dry"
    },
    {
      "x": 5,
      "y": -5,
      "z": 3,
      "name": "Soil_Mud_Dry"
    },
    {
      "x": 5,
      "y": -4,
      "z": 3,
      "name": "Soil_Mud_Dry"
    },
    {
      "x": 5,
      "y": -3,
      "z": 3,
      "name": "Soil_Mud_Dry"
    },
    {
      "x": 5,
      "y": -2,
      "z": 3,
      "name": "Soil_Mud_Dry"
    },
    {
      "x": 5,
      "y": -1,
      "z": 3,
      "name": "Soil_Mud_Dry"
    },
    {
      "x": 5,
      "y": 0,
      "z": 3,
      "name": "Deco_Bone_Spine",
      "rotation": 1
    },
    {
      "x": 5,
      "y": -8,
      "z": 4,
      "name": "Soil_Mud_Dry"
    },
    {
      "x": 5,
      "y": -7,
      "z": 4,
      "name": "Soil_Mud_Dry"
    },
    {
      "x": 5,
      "y": -6,
      "z": 4,
      "name": "Soil_Mud_Dry"
    },
    {
      "x": 5,
      "y": -5,
      "z": 4,
      "name": "Soil_Mud_Dry"
    },
    {
      "x": 5,
      "y": -4,
      "z": 4,
      "name": "Soil_Mud_Dry"
    },
    {
      "x": 5,
      "y": -3,
      "z": 4,
      "name": "Soil_Mud_Dry"
    },
    {
      "x": 5,
      "y": -2,
      "z": 4,
      "name": "Soil_Mud_Dry"
    },
    {
      "x": 5,
      "y": -1,
      "z": 4,
      "name": "Soil_Dirt"
    },
    {
      "x": 5,
      "y": 0,
      "z": 4,
      "name": "Deco_Bone_Ribs_Long",
      "rotation": 4
    },
    {
      "x": 5,
      "y": -8,
      "z": 5,
      "name": "Soil_Mud_Dry"
    },
    {
      "x": 5,
      "y": -7,
      "z": 5,
      "name": "Soil_Mud_Dry"
    },
    {
      "x": 5,
      "y": -6,
      "z": 5,
      "name": "Soil_Mud_Dry"
    },
    {
      "x": 5,
      "y": -5,
      "z": 5,
      "name": "Soil_Mud_Dry"
    },
    {
      "x": 5,
      "y": -4,
      "z": 5,
      "name": "Soil_Mud_Dry"
    },
    {
      "x": 5,
      "y": -3,
      "z": 5,
      "name": "Soil_Mud_Dry"
    },
    {
      "x": 5,
      "y": -2,
      "z": 5,
      "name": "Soil_Mud_Dry"
    },
    {
      "x": 5,
      "y": -1,
      "z": 5,
      "name": "Soil_Mud_Dry"
    },
    {
      "x": 5,
      "y": -8,
      "z": 6,
      "name": "Soil_Mud_Dry"
    },
    {
      "x": 5,
      "y": -7,
      "z": 6,
      "name": "Soil_Mud_Dry"
    },
    {
      "x": 5,
      "y": -6,
      "z": 6,
      "name": "Soil_Mud_Dry"
    },
    {
      "x": 5,
      "y": -5,
      "z": 6,
      "name": "Soil_Mud_Dry"
    },
    {
      "x": 5,
      "y": -4,
      "z": 6,
      "name": "Soil_Mud_Dry"
    },
    {
      "x": 5,
      "y": -3,
      "z": 6,
      "name": "Soil_Mud_Dry"
    },
    {
      "x": 5,
      "y": -2,
      "z": 6,
      "name": "Soil_Mud_Dry"
    },
    {
      "x": 5,
      "y": -1,
      "z": 6,
      "name": "Soil_Mud_Dry"
    },
    {
      "x": 5,
      "y": 0,
      "z": 6,
      "name": "Deco_Bone_Ribs",
      "rotation": 3
    },
    {
      "x": 5,
      "y": -8,
      "z": 7,
      "name": "Soil_Mud_Dry"
    },
    {
      "x": 5,
      "y": -7,
      "z": 7,
      "name": "Soil_Mud_Dry"
    },
    {
      "x": 5,
      "y": -6,
      "z": 7,
      "name": "Soil_Mud_Dry"
    },
    {
      "x": 5,
      "y": -5,
      "z": 7,
      "name": "Soil_Mud_Dry"
    },
    {
      "x": 5,
      "y": -4,
      "z": 7,
      "name": "Soil_Mud_Dry"
    },
    {
      "x": 5,
      "y": -3,
      "z": 7,
      "name": "Soil_Mud_Dry"
    },
    {
      "x": 5,
      "y": -2,
      "z": 7,
      "name": "Soil_Mud_Dry"
    },
    {
      "x": 5,
      "y": -1,
      "z": 7,
      "name": "Soil_Mud_Dry"
    },
    {
      "x": 5,
      "y": -8,
      "z": 8,
      "name": "Soil_Mud_Dry"
    },
    {
      "x": 5,
      "y": -7,
      "z": 8,
      "name": "Soil_Mud_Dry"
    },
    {
      "x": 5,
      "y": -6,
      "z": 8,
      "name": "Soil_Mud_Dry"
    },
    {
      "x": 5,
      "y": -5,
      "z": 8,
      "name": "Soil_Mud_Dry"
    },
    {
      "x": 5,
      "y": -4,
      "z": 8,
      "name": "Soil_Mud_Dry"
    },
    {
      "x": 5,
      "y": -3,
      "z": 8,
      "name": "Soil_Mud_Dry"
    },
    {
      "x": 5,
      "y": -2,
      "z": 8,
      "name": "Soil_Mud_Dry"
    },
    {
      "x": 5,
      "y": -1,
      "z": 8,
      "name": "Soil_Mud_Dry"
    },
    {
      "x": 5,
      "y": 0,
      "z": 8,
      "name": "Deco_Bone_Ribs",
      "rotation": 3
    },
    {
      "x": 5,
      "y": -7,
      "z": 9,
      "name": "Soil_Mud_Dry"
    },
    {
      "x": 5,
      "y": -6,
      "z": 9,
      "name": "Soil_Mud_Dry"
    },
    {
      "x": 5,
      "y": -5,
      "z": 9,
      "name": "Soil_Mud_Dry"
    },
    {
      "x": 5,
      "y": -4,
      "z": 9,
      "name": "Soil_Mud_Dry"
    },
    {
      "x": 5,
      "y": -3,
      "z": 9,
      "name": "Soil_Mud_Dry"
    },
    {
      "x": 5,
      "y": -2,
      "z": 9,
      "name": "Soil_Dirt"
    },
    {
      "x": 5,
      "y": -1,
      "z": 9,
      "name": "Soil_Mud_Dry"
    },
    {
      "x": 5,
      "y": 0,
      "z": 9,
      "name": "Deco_Bone_Ribs",
      "rotation": 3
    },
    {
      "x": 5,
      "y": -5,
      "z": 10,
      "name": "Soil_Mud_Dry"
    },
    {
      "x": 5,
      "y": -4,
      "z": 10,
      "name": "Soil_Mud_Dry"
    },
    {
      "x": 5,
      "y": -3,
      "z": 10,
      "name": "Soil_Mud_Dry"
    },
    {
      "x": 5,
      "y": -2,
      "z": 10,
      "name": "Soil_Mud_Dry"
    },
    {
      "x": 5,
      "y": -1,
      "z": 10,
      "name": "Soil_Dirt"
    },
    {
      "x": 5,
      "y": -5,
      "z": 11,
      "name": "Soil_Mud_Dry"
    },
    {
      "x": 5,
      "y": -4,
      "z": 11,
      "name": "Soil_Mud_Dry"
    },
    {
      "x": 5,
      "y": -3,
      "z": 11,
      "name": "Soil_Mud_Dry"
    },
    {
      "x": 5,
      "y": -2,
      "z": 11,
      "name": "Soil_Mud_Dry"
    },
    {
      "x": 5,
      "y": -1,
      "z": 11,
      "name": "Soil_Mud_Dry"
    },
    {
      "x": 5,
      "y": -5,
      "z": 12,
      "name": "Soil_Mud_Dry"
    },
    {
      "x": 5,
      "y": -4,
      "z": 12,
      "name": "Soil_Mud_Dry"
    },
    {
      "x": 5,
      "y": -3,
      "z": 12,
      "name": "Soil_Mud_Dry"
    },
    {
      "x": 5,
      "y": -2,
      "z": 12,
      "name": "Soil_Dirt"
    },
    {
      "x": 6,
      "y": -4,
      "z": -1,
      "name": "Soil_Mud_Dry"
    },
    {
      "x": 6,
      "y": -3,
      "z": -1,
      "name": "Soil_Mud_Dry"
    },
    {
      "x": 6,
      "y": -2,
      "z": -1,
      "name": "Soil_Mud_Dry"
    },
    {
      "x": 6,
      "y": -6,
      "z": 0,
      "name": "Soil_Mud_Dry"
    },
    {
      "x": 6,
      "y": -5,
      "z": 0,
      "name": "Soil_Mud_Dry"
    },
    {
      "x": 6,
      "y": -4,
      "z": 0,
      "name": "Soil_Mud_Dry"
    },
    {
      "x": 6,
      "y": -3,
      "z": 0,
      "name": "Soil_Mud_Dry"
    },
    {
      "x": 6,
      "y": -2,
      "z": 0,
      "name": "Soil_Dirt"
    },
    {
      "x": 6,
      "y": -1,
      "z": 0,
      "name": "Soil_Mud_Dry"
    },
    {
      "x": 6,
      "y": -7,
      "z": 1,
      "name": "Soil_Mud_Dry"
    },
    {
      "x": 6,
      "y": -6,
      "z": 1,
      "name": "Soil_Mud_Dry"
    },
    {
      "x": 6,
      "y": -5,
      "z": 1,
      "name": "Soil_Mud_Dry"
    },
    {
      "x": 6,
      "y": -4,
      "z": 1,
      "name": "Soil_Mud_Dry"
    },
    {
      "x": 6,
      "y": -3,
      "z": 1,
      "name": "Soil_Dirt"
    },
    {
      "x": 6,
      "y": -2,
      "z": 1,
      "name": "Soil_Dirt"
    },
    {
      "x": 6,
      "y": -1,
      "z": 1,
      "name": "Soil_Dirt"
    },
    {
      "x": 6,
      "y": -7,
      "z": 2,
      "name": "Soil_Mud_Dry"
    },
    {
      "x": 6,
      "y": -6,
      "z": 2,
      "name": "Soil_Mud_Dry"
    },
    {
      "x": 6,
      "y": -5,
      "z": 2,
      "name": "Soil_Mud_Dry"
    },
    {
      "x": 6,
      "y": -4,
      "z": 2,
      "name": "Soil_Mud_Dry"
    },
    {
      "x": 6,
      "y": -3,
      "z": 2,
      "name": "Soil_Mud_Dry"
    },
    {
      "x": 6,
      "y": -2,
      "z": 2,
      "name": "Soil_Mud_Dry"
    },
    {
      "x": 6,
      "y": -1,
      "z": 2,
      "name": "Soil_Mud_Dry"
    },
    {
      "x": 6,
      "y": 0,
      "z": 2,
      "name": "Deco_Bone_Ribs_Long",
      "rotation": 4
    },
    {
      "x": 6,
      "y": -7,
      "z": 3,
      "name": "Soil_Mud_Dry"
    },
    {
      "x": 6,
      "y": -6,
      "z": 3,
      "name": "Soil_Mud_Dry"
    },
    {
      "x": 6,
      "y": -5,
      "z": 3,
      "name": "Soil_Mud_Dry"
    },
    {
      "x": 6,
      "y": -4,
      "z": 3,
      "name": "Soil_Mud_Dry"
    },
    {
      "x": 6,
      "y": -3,
      "z": 3,
      "name": "Soil_Mud_Dry"
    },
    {
      "x": 6,
      "y": -2,
      "z": 3,
      "name": "Soil_Mud_Dry"
    },
    {
      "x": 6,
      "y": -1,
      "z": 3,
      "name": "Soil_Mud_Dry"
    },
    {
      "x": 6,
      "y": 0,
      "z": 3,
      "name": "Deco_Bone_Spine",
      "rotation": 1
    },
    {
      "x": 6,
      "y": -7,
      "z": 4,
      "name": "Soil_Mud_Dry"
    },
    {
      "x": 6,
      "y": -6,
      "z": 4,
      "name": "Soil_Mud_Dry"
    },
    {
      "x": 6,
      "y": -5,
      "z": 4,
      "name": "Soil_Mud_Dry"
    },
    {
      "x": 6,
      "y": -4,
      "z": 4,
      "name": "Soil_Mud_Dry"
    },
    {
      "x": 6,
      "y": -3,
      "z": 4,
      "name": "Soil_Mud_Dry"
    },
    {
      "x": 6,
      "y": -2,
      "z": 4,
      "name": "Soil_Mud_Dry"
    },
    {
      "x": 6,
      "y": -1,
      "z": 4,
      "name": "Soil_Mud_Dry"
    },
    {
      "x": 6,
      "y": 0,
      "z": 4,
      "name": "Deco_Bone_Ribs_Long",
      "rotation": 4
    },
    {
      "x": 6,
      "y": -8,
      "z": 5,
      "name": "Soil_Mud_Dry"
    },
    {
      "x": 6,
      "y": -7,
      "z": 5,
      "name": "Soil_Mud_Dry"
    },
    {
      "x": 6,
      "y": -6,
      "z": 5,
      "name": "Soil_Mud_Dry"
    },
    {
      "x": 6,
      "y": -5,
      "z": 5,
      "name": "Soil_Mud_Dry"
    },
    {
      "x": 6,
      "y": -4,
      "z": 5,
      "name": "Soil_Mud_Dry"
    },
    {
      "x": 6,
      "y": -3,
      "z": 5,
      "name": "Soil_Mud_Dry"
    },
    {
      "x": 6,
      "y": -2,
      "z": 5,
      "name": "Soil_Mud_Dry"
    },
    {
      "x": 6,
      "y": -1,
      "z": 5,
      "name": "Soil_Mud_Dry"
    },
    {
      "x": 6,
      "y": 0,
      "z": 5,
      "name": "Deco_Bone_Ribs"
    },
    {
      "x": 6,
      "y": -8,
      "z": 6,
      "name": "Soil_Mud_Dry"
    },
    {
      "x": 6,
      "y": -7,
      "z": 6,
      "name": "Soil_Mud_Dry"
    },
    {
      "x": 6,
      "y": -6,
      "z": 6,
      "name": "Soil_Mud_Dry"
    },
    {
      "x": 6,
      "y": -5,
      "z": 6,
      "name": "Soil_Mud_Dry"
    },
    {
      "x": 6,
      "y": -4,
      "z": 6,
      "name": "Soil_Mud_Dry"
    },
    {
      "x": 6,
      "y": -3,
      "z": 6,
      "name": "Soil_Mud_Dry"
    },
    {
      "x": 6,
      "y": -2,
      "z": 6,
      "name": "Soil_Mud_Dry"
    },
    {
      "x": 6,
      "y": -1,
      "z": 6,
      "name": "Soil_Mud_Dry"
    },
    {
      "x": 6,
      "y": 0,
      "z": 6,
      "name": "Deco_Bone_Ribs_Long",
      "rotation": 5
    },
    {
      "x": 6,
      "y": -8,
      "z": 7,
      "name": "Soil_Mud_Dry"
    },
    {
      "x": 6,
      "y": -7,
      "z": 7,
      "name": "Soil_Mud_Dry"
    },
    {
      "x": 6,
      "y": -6,
      "z": 7,
      "name": "Soil_Mud_Dry"
    },
    {
      "x": 6,
      "y": -5,
      "z": 7,
      "name": "Soil_Mud_Dry"
    },
    {
      "x": 6,
      "y": -4,
      "z": 7,
      "name": "Soil_Mud_Dry"
    },
    {
      "x": 6,
      "y": -3,
      "z": 7,
      "name": "Soil_Mud_Dry"
    },
    {
      "x": 6,
      "y": -2,
      "z": 7,
      "name": "Soil_Mud_Dry"
    },
    {
      "x": 6,
      "y": -1,
      "z": 7,
      "name": "Soil_Mud_Dry"
    },
    {
      "x": 6,
      "y": 0,
      "z": 7,
      "name": "Deco_Bone_Ribs",
      "rotation": 3
    },
    {
      "x": 6,
      "y": -8,
      "z": 8,
      "name": "Soil_Mud_Dry"
    },
    {
      "x": 6,
      "y": -7,
      "z": 8,
      "name": "Soil_Mud_Dry"
    },
    {
      "x": 6,
      "y": -6,
      "z": 8,
      "name": "Soil_Mud_Dry"
    },
    {
      "x": 6,
      "y": -5,
      "z": 8,
      "name": "Soil_Mud_Dry"
    },
    {
      "x": 6,
      "y": -4,
      "z": 8,
      "name": "Soil_Mud_Dry"
    },
    {
      "x": 6,
      "y": -3,
      "z": 8,
      "name": "Soil_Mud_Dry"
    },
    {
      "x": 6,
      "y": -2,
      "z": 8,
      "name": "Soil_Mud_Dry"
    },
    {
      "x": 6,
      "y": -1,
      "z": 8,
      "name": "Soil_Mud_Dry"
    },
    {
      "x": 6,
      "y": 0,
      "z": 8,
      "name": "Deco_Bone_Ribs_Long",
      "rotation": 5
    },
    {
      "x": 6,
      "y": -8,
      "z": 9,
      "name": "Soil_Mud_Dry"
    },
    {
      "x": 6,
      "y": -7,
      "z": 9,
      "name": "Soil_Mud_Dry"
    },
    {
      "x": 6,
      "y": -6,
      "z": 9,
      "name": "Soil_Mud_Dry"
    },
    {
      "x": 6,
      "y": -5,
      "z": 9,
      "name": "Soil_Mud_Dry"
    },
    {
      "x": 6,
      "y": -4,
      "z": 9,
      "name": "Soil_Mud_Dry"
    },
    {
      "x": 6,
      "y": -3,
      "z": 9,
      "name": "Soil_Mud_Dry"
    },
    {
      "x": 6,
      "y": -2,
      "z": 9,
      "name": "Soil_Mud_Dry"
    },
    {
      "x": 6,
      "y": -1,
      "z": 9,
      "name": "Soil_Mud_Dry"
    },
    {
      "x": 6,
      "y": 0,
      "z": 9,
      "name": "Deco_Bone_Ribs_Long",
      "rotation": 5
    },
    {
      "x": 6,
      "y": -7,
      "z": 10,
      "name": "Soil_Mud_Dry"
    },
    {
      "x": 6,
      "y": -6,
      "z": 10,
      "name": "Soil_Mud_Dry"
    },
    {
      "x": 6,
      "y": -4,
      "z": 10,
      "name": "Soil_Mud_Dry"
    },
    {
      "x": 6,
      "y": -3,
      "z": 10,
      "name": "Soil_Mud_Dry"
    },
    {
      "x": 6,
      "y": -2,
      "z": 10,
      "name": "Soil_Mud_Dry"
    },
    {
      "x": 6,
      "y": -1,
      "z": 10,
      "name": "Soil_Mud_Dry"
    },
    {
      "x": 6,
      "y": 0,
      "z": 10,
      "name": "Deco_Bone_Ribs_Long",
      "rotation": 5
    },
    {
      "x": 6,
      "y": -6,
      "z": 11,
      "name": "Soil_Mud_Dry"
    },
    {
      "x": 6,
      "y": -5,
      "z": 11,
      "name": "Soil_Mud_Dry"
    },
    {
      "x": 6,
      "y": -4,
      "z": 11,
      "name": "Soil_Mud_Dry"
    },
    {
      "x": 6,
      "y": -3,
      "z": 11,
      "name": "Soil_Mud_Dry"
    },
    {
      "x": 6,
      "y": -2,
      "z": 11,
      "name": "Soil_Mud_Dry"
    },
    {
      "x": 6,
      "y": -1,
      "z": 11,
      "name": "Soil_Mud_Dry"
    },
    {
      "x": 6,
      "y": 0,
      "z": 11,
      "name": "Deco_Bone_Ribs",
      "rotation": 3
    },
    {
      "x": 6,
      "y": -5,
      "z": 12,
      "name": "Soil_Mud_Dry"
    },
    {
      "x": 6,
      "y": -4,
      "z": 12,
      "name": "Soil_Mud_Dry"
    },
    {
      "x": 6,
      "y": -3,
      "z": 12,
      "name": "Soil_Mud_Dry"
    },
    {
      "x": 6,
      "y": -2,
      "z": 12,
      "name": "Soil_Mud_Dry"
    },
    {
      "x": 6,
      "y": -1,
      "z": 12,
      "name": "Soil_Mud_Dry"
    },
    {
      "x": 6,
      "y": -4,
      "z": 13,
      "name": "Soil_Mud_Dry"
    },
    {
      "x": 6,
      "y": -3,
      "z": 13,
      "name": "Soil_Mud_Dry"
    },
    {
      "x": 6,
      "y": -2,
      "z": 13,
      "name": "Soil_Mud_Dry"
    },
    {
      "x": 7,
      "y": -3,
      "z": -1,
      "name": "Soil_Mud_Dry"
    },
    {
      "x": 7,
      "y": -5,
      "z": 0,
      "name": "Soil_Mud_Dry"
    },
    {
      "x": 7,
      "y": -4,
      "z": 0,
      "name": "Soil_Mud_Dry"
    },
    {
      "x": 7,
      "y": -3,
      "z": 0,
      "name": "Soil_Mud_Dry"
    },
    {
      "x": 7,
      "y": -2,
      "z": 0,
      "name": "Soil_Mud_Dry"
    },
    {
      "x": 7,
      "y": -6,
      "z": 1,
      "name": "Soil_Mud_Dry"
    },
    {
      "x": 7,
      "y": -5,
      "z": 1,
      "name": "Soil_Mud_Dry"
    },
    {
      "x": 7,
      "y": -4,
      "z": 1,
      "name": "Soil_Mud_Dry"
    },
    {
      "x": 7,
      "y": -3,
      "z": 1,
      "name": "Soil_Mud_Dry"
    },
    {
      "x": 7,
      "y": -2,
      "z": 1,
      "name": "Soil_Mud_Dry"
    },
    {
      "x": 7,
      "y": -1,
      "z": 1,
      "name": "Soil_Mud_Dry"
    },
    {
      "x": 7,
      "y": -7,
      "z": 2,
      "name": "Soil_Mud_Dry"
    },
    {
      "x": 7,
      "y": -6,
      "z": 2,
      "name": "Soil_Mud_Dry"
    },
    {
      "x": 7,
      "y": -5,
      "z": 2,
      "name": "Soil_Mud_Dry"
    },
    {
      "x": 7,
      "y": -4,
      "z": 2,
      "name": "Soil_Mud_Dry"
    },
    {
      "x": 7,
      "y": -3,
      "z": 2,
      "name": "Soil_Mud_Dry"
    },
    {
      "x": 7,
      "y": -2,
      "z": 2,
      "name": "Soil_Mud_Dry"
    },
    {
      "x": 7,
      "y": -1,
      "z": 2,
      "name": "Soil_Mud_Dry"
    },
    {
      "x": 7,
      "y": -7,
      "z": 3,
      "name": "Soil_Mud_Dry"
    },
    {
      "x": 7,
      "y": -6,
      "z": 3,
      "name": "Soil_Mud_Dry"
    },
    {
      "x": 7,
      "y": -5,
      "z": 3,
      "name": "Soil_Mud_Dry"
    },
    {
      "x": 7,
      "y": -4,
      "z": 3,
      "name": "Soil_Mud_Dry"
    },
    {
      "x": 7,
      "y": -3,
      "z": 3,
      "name": "Soil_Mud_Dry"
    },
    {
      "x": 7,
      "y": -2,
      "z": 3,
      "name": "Soil_Mud_Dry"
    },
    {
      "x": 7,
      "y": -1,
      "z": 3,
      "name": "Soil_Mud_Dry"
    },
    {
      "x": 7,
      "y": -6,
      "z": 4,
      "name": "Soil_Mud_Dry"
    },
    {
      "x": 7,
      "y": -5,
      "z": 4,
      "name": "Soil_Mud_Dry"
    },
    {
      "x": 7,
      "y": -4,
      "z": 4,
      "name": "Soil_Mud_Dry"
    },
    {
      "x": 7,
      "y": -3,
      "z": 4,
      "name": "Soil_Mud_Dry"
    },
    {
      "x": 7,
      "y": -2,
      "z": 4,
      "name": "Soil_Mud_Dry"
    },
    {
      "x": 7,
      "y": -1,
      "z": 4,
      "name": "Soil_Mud_Dry"
    },
    {
      "x": 7,
      "y": 0,
      "z": 4,
      "name": "Deco_Bone_Spine"
    },
    {
      "x": 7,
      "y": -7,
      "z": 5,
      "name": "Soil_Mud_Dry"
    },
    {
      "x": 7,
      "y": -6,
      "z": 5,
      "name": "Soil_Mud_Dry"
    },
    {
      "x": 7,
      "y": -5,
      "z": 5,
      "name": "Soil_Mud_Dry"
    },
    {
      "x": 7,
      "y": -4,
      "z": 5,
      "name": "Soil_Mud_Dry"
    },
    {
      "x": 7,
      "y": -3,
      "z": 5,
      "name": "Soil_Mud_Dry"
    },
    {
      "x": 7,
      "y": -2,
      "z": 5,
      "name": "Soil_Mud_Dry"
    },
    {
      "x": 7,
      "y": -1,
      "z": 5,
      "name": "Soil_Mud_Dry"
    },
    {
      "x": 7,
      "y": 0,
      "z": 5,
      "name": "Deco_Bone_Spine"
    },
    {
      "x": 7,
      "y": -8,
      "z": 6,
      "name": "Soil_Mud_Dry"
    },
    {
      "x": 7,
      "y": -7,
      "z": 6,
      "name": "Soil_Mud_Dry"
    },
    {
      "x": 7,
      "y": -6,
      "z": 6,
      "name": "Soil_Mud_Dry"
    },
    {
      "x": 7,
      "y": -5,
      "z": 6,
      "name": "Soil_Mud_Dry"
    },
    {
      "x": 7,
      "y": -4,
      "z": 6,
      "name": "Soil_Mud_Dry"
    },
    {
      "x": 7,
      "y": -3,
      "z": 6,
      "name": "Soil_Mud_Dry"
    },
    {
      "x": 7,
      "y": -2,
      "z": 6,
      "name": "Soil_Mud_Dry"
    },
    {
      "x": 7,
      "y": -1,
      "z": 6,
      "name": "Soil_Mud_Dry"
    },
    {
      "x": 7,
      "y": 0,
      "z": 6,
      "name": "Deco_Bone_Spine"
    },
    {
      "x": 7,
      "y": -8,
      "z": 7,
      "name": "Soil_Mud_Dry"
    },
    {
      "x": 7,
      "y": -7,
      "z": 7,
      "name": "Soil_Mud_Dry"
    },
    {
      "x": 7,
      "y": -6,
      "z": 7,
      "name": "Soil_Mud_Dry"
    },
    {
      "x": 7,
      "y": -5,
      "z": 7,
      "name": "Soil_Mud_Dry"
    },
    {
      "x": 7,
      "y": -4,
      "z": 7,
      "name": "Soil_Mud_Dry"
    },
    {
      "x": 7,
      "y": -3,
      "z": 7,
      "name": "Soil_Mud_Dry"
    },
    {
      "x": 7,
      "y": -2,
      "z": 7,
      "name": "Soil_Mud_Dry"
    },
    {
      "x": 7,
      "y": -1,
      "z": 7,
      "name": "Soil_Mud_Dry"
    },
    {
      "x": 7,
      "y": 0,
      "z": 7,
      "name": "Deco_Bone_Ribs_Long",
      "rotation": 5
    },
    {
      "x": 7,
      "y": -8,
      "z": 8,
      "name": "Soil_Mud_Dry"
    },
    {
      "x": 7,
      "y": -7,
      "z": 8,
      "name": "Soil_Mud_Dry"
    },
    {
      "x": 7,
      "y": -6,
      "z": 8,
      "name": "Soil_Mud_Dry"
    },
    {
      "x": 7,
      "y": -5,
      "z": 8,
      "name": "Soil_Mud_Dry"
    },
    {
      "x": 7,
      "y": -4,
      "z": 8,
      "name": "Soil_Mud_Dry"
    },
    {
      "x": 7,
      "y": -3,
      "z": 8,
      "name": "Soil_Mud_Dry"
    },
    {
      "x": 7,
      "y": -2,
      "z": 8,
      "name": "Soil_Mud_Dry"
    },
    {
      "x": 7,
      "y": -1,
      "z": 8,
      "name": "Soil_Mud_Dry"
    },
    {
      "x": 7,
      "y": 0,
      "z": 8,
      "name": "Deco_Bone_Ribs_Long",
      "rotation": 5
    },
    {
      "x": 7,
      "y": -8,
      "z": 9,
      "name": "Soil_Mud_Dry"
    },
    {
      "x": 7,
      "y": -7,
      "z": 9,
      "name": "Soil_Mud_Dry"
    },
    {
      "x": 7,
      "y": -6,
      "z": 9,
      "name": "Soil_Mud_Dry"
    },
    {
      "x": 7,
      "y": -5,
      "z": 9,
      "name": "Soil_Mud_Dry"
    },
    {
      "x": 7,
      "y": -4,
      "z": 9,
      "name": "Soil_Mud_Dry"
    },
    {
      "x": 7,
      "y": -3,
      "z": 9,
      "name": "Soil_Mud_Dry"
    },
    {
      "x": 7,
      "y": -2,
      "z": 9,
      "name": "Soil_Mud_Dry"
    },
    {
      "x": 7,
      "y": -1,
      "z": 9,
      "name": "Soil_Mud_Dry"
    },
    {
      "x": 7,
      "y": 0,
      "z": 9,
      "name": "Deco_Bone_Ribs_Long",
      "rotation": 5
    },
    {
      "x": 7,
      "y": -7,
      "z": 10,
      "name": "Soil_Mud_Dry"
    },
    {
      "x": 7,
      "y": -6,
      "z": 10,
      "name": "Soil_Mud_Dry"
    },
    {
      "x": 7,
      "y": -5,
      "z": 10,
      "name": "Soil_Mud_Dry"
    },
    {
      "x": 7,
      "y": -4,
      "z": 10,
      "name": "Soil_Mud_Dry"
    },
    {
      "x": 7,
      "y": -3,
      "z": 10,
      "name": "Soil_Mud_Dry"
    },
    {
      "x": 7,
      "y": -2,
      "z": 10,
      "name": "Soil_Mud_Dry"
    },
    {
      "x": 7,
      "y": -1,
      "z": 10,
      "name": "Soil_Mud_Dry"
    },
    {
      "x": 7,
      "y": 0,
      "z": 10,
      "name": "Deco_Bone_Ribs_Long",
      "rotation": 5
    },
    {
      "x": 7,
      "y": -7,
      "z": 11,
      "name": "Soil_Mud_Dry"
    },
    {
      "x": 7,
      "y": -6,
      "z": 11,
      "name": "Soil_Mud_Dry"
    },
    {
      "x": 7,
      "y": -5,
      "z": 11,
      "name": "Soil_Mud_Dry"
    },
    {
      "x": 7,
      "y": -4,
      "z": 11,
      "name": "Soil_Mud_Dry"
    },
    {
      "x": 7,
      "y": -3,
      "z": 11,
      "name": "Soil_Mud_Dry"
    },
    {
      "x": 7,
      "y": -2,
      "z": 11,
      "name": "Soil_Mud_Dry"
    },
    {
      "x": 7,
      "y": -1,
      "z": 11,
      "name": "Soil_Mud_Dry"
    },
    {
      "x": 7,
      "y": 0,
      "z": 11,
      "name": "Deco_Bone_Ribs_Long",
      "rotation": 5
    },
    {
      "x": 7,
      "y": -6,
      "z": 12,
      "name": "Soil_Mud_Dry"
    },
    {
      "x": 7,
      "y": -5,
      "z": 12,
      "name": "Soil_Mud_Dry"
    },
    {
      "x": 7,
      "y": -4,
      "z": 12,
      "name": "Soil_Mud_Dry"
    },
    {
      "x": 7,
      "y": -3,
      "z": 12,
      "name": "Soil_Mud_Dry"
    },
    {
      "x": 7,
      "y": -2,
      "z": 12,
      "name": "Soil_Mud_Dry"
    },
    {
      "x": 7,
      "y": -1,
      "z": 12,
      "name": "Soil_Mud_Dry"
    },
    {
      "x": 7,
      "y": 0,
      "z": 12,
      "name": "Deco_Bone_Ribs",
      "rotation": 3
    },
    {
      "x": 7,
      "y": -5,
      "z": 13,
      "name": "Soil_Mud_Dry"
    },
    {
      "x": 7,
      "y": -4,
      "z": 13,
      "name": "Soil_Mud_Dry"
    },
    {
      "x": 7,
      "y": -3,
      "z": 13,
      "name": "Soil_Mud_Dry"
    },
    {
      "x": 7,
      "y": -2,
      "z": 13,
      "name": "Soil_Mud_Dry"
    },
    {
      "x": 7,
      "y": -1,
      "z": 13,
      "name": "Soil_Mud_Dry"
    },
    {
      "x": 7,
      "y": -3,
      "z": 14,
      "name": "Soil_Mud_Dry"
    },
    {
      "x": 7,
      "y": -2,
      "z": 14,
      "name": "Soil_Mud_Dry"
    },
    {
      "x": 8,
      "y": -4,
      "z": 0,
      "name": "Soil_Mud_Dry"
    },
    {
      "x": 8,
      "y": -3,
      "z": 0,
      "name": "Soil_Mud_Dry"
    },
    {
      "x": 8,
      "y": -2,
      "z": 0,
      "name": "Soil_Mud_Dry"
    },
    {
      "x": 8,
      "y": -5,
      "z": 1,
      "name": "Soil_Mud_Dry"
    },
    {
      "x": 8,
      "y": -4,
      "z": 1,
      "name": "Soil_Mud_Dry"
    },
    {
      "x": 8,
      "y": -3,
      "z": 1,
      "name": "Soil_Mud_Dry"
    },
    {
      "x": 8,
      "y": -2,
      "z": 1,
      "name": "Soil_Mud_Dry"
    },
    {
      "x": 8,
      "y": -6,
      "z": 2,
      "name": "Soil_Mud_Dry"
    },
    {
      "x": 8,
      "y": -5,
      "z": 2,
      "name": "Soil_Mud_Dry"
    },
    {
      "x": 8,
      "y": -4,
      "z": 2,
      "name": "Soil_Mud_Dry"
    },
    {
      "x": 8,
      "y": -3,
      "z": 2,
      "name": "Soil_Mud_Dry"
    },
    {
      "x": 8,
      "y": -2,
      "z": 2,
      "name": "Soil_Mud_Dry"
    },
    {
      "x": 8,
      "y": -1,
      "z": 2,
      "name": "Soil_Mud_Dry"
    },
    {
      "x": 8,
      "y": -6,
      "z": 3,
      "name": "Soil_Mud_Dry"
    },
    {
      "x": 8,
      "y": -5,
      "z": 3,
      "name": "Soil_Mud_Dry"
    },
    {
      "x": 8,
      "y": -4,
      "z": 3,
      "name": "Soil_Mud_Dry"
    },
    {
      "x": 8,
      "y": -3,
      "z": 3,
      "name": "Soil_Mud_Dry"
    },
    {
      "x": 8,
      "y": -2,
      "z": 3,
      "name": "Soil_Mud_Dry"
    },
    {
      "x": 8,
      "y": -1,
      "z": 3,
      "name": "Soil_Mud_Dry"
    },
    {
      "x": 8,
      "y": -6,
      "z": 4,
      "name": "Soil_Mud_Dry"
    },
    {
      "x": 8,
      "y": -5,
      "z": 4,
      "name": "Soil_Mud_Dry"
    },
    {
      "x": 8,
      "y": -4,
      "z": 4,
      "name": "Soil_Mud_Dry"
    },
    {
      "x": 8,
      "y": -3,
      "z": 4,
      "name": "Soil_Mud_Dry"
    },
    {
      "x": 8,
      "y": -2,
      "z": 4,
      "name": "Soil_Mud_Dry"
    },
    {
      "x": 8,
      "y": -1,
      "z": 4,
      "name": "Soil_Mud_Dry"
    },
    {
      "x": 8,
      "y": 0,
      "z": 4,
      "name": "Deco_Bone_Ribs_Long",
      "rotation": 5
    },
    {
      "x": 8,
      "y": -7,
      "z": 5,
      "name": "Soil_Mud_Dry"
    },
    {
      "x": 8,
      "y": -6,
      "z": 5,
      "name": "Soil_Mud_Dry"
    },
    {
      "x": 8,
      "y": -5,
      "z": 5,
      "name": "Soil_Mud_Dry"
    },
    {
      "x": 8,
      "y": -4,
      "z": 5,
      "name": "Soil_Mud_Dry"
    },
    {
      "x": 8,
      "y": -3,
      "z": 5,
      "name": "Soil_Mud_Dry"
    },
    {
      "x": 8,
      "y": -2,
      "z": 5,
      "name": "Soil_Mud_Dry"
    },
    {
      "x": 8,
      "y": -1,
      "z": 5,
      "name": "Soil_Mud_Dry"
    },
    {
      "x": 8,
      "y": 0,
      "z": 5,
      "name": "Deco_Bone_Ribs_Long",
      "rotation": 5
    },
    {
      "x": 8,
      "y": -7,
      "z": 6,
      "name": "Soil_Mud_Dry"
    },
    {
      "x": 8,
      "y": -6,
      "z": 6,
      "name": "Soil_Mud_Dry"
    },
    {
      "x": 8,
      "y": -5,
      "z": 6,
      "name": "Soil_Mud_Dry"
    },
    {
      "x": 8,
      "y": -4,
      "z": 6,
      "name": "Soil_Mud_Dry"
    },
    {
      "x": 8,
      "y": -3,
      "z": 6,
      "name": "Soil_Mud_Dry"
    },
    {
      "x": 8,
      "y": -2,
      "z": 6,
      "name": "Soil_Mud_Dry"
    },
    {
      "x": 8,
      "y": -1,
      "z": 6,
      "name": "Soil_Mud_Dry"
    },
    {
      "x": 8,
      "y": 0,
      "z": 6,
      "name": "Deco_Bone_Ribs_Long",
      "rotation": 5
    },
    {
      "x": 8,
      "y": -8,
      "z": 7,
      "name": "Soil_Mud_Dry"
    },
    {
      "x": 8,
      "y": -7,
      "z": 7,
      "name": "Soil_Mud_Dry"
    },
    {
      "x": 8,
      "y": -6,
      "z": 7,
      "name": "Soil_Mud_Dry"
    },
    {
      "x": 8,
      "y": -5,
      "z": 7,
      "name": "Soil_Mud_Dry"
    },
    {
      "x": 8,
      "y": -4,
      "z": 7,
      "name": "Soil_Mud_Dry"
    },
    {
      "x": 8,
      "y": -3,
      "z": 7,
      "name": "Soil_Mud_Dry"
    },
    {
      "x": 8,
      "y": -2,
      "z": 7,
      "name": "Soil_Mud_Dry"
    },
    {
      "x": 8,
      "y": -1,
      "z": 7,
      "name": "Soil_Mud_Dry"
    },
    {
      "x": 8,
      "y": 0,
      "z": 7,
      "name": "Deco_Bone_Spine"
    },
    {
      "x": 8,
      "y": -8,
      "z": 8,
      "name": "Soil_Mud_Dry"
    },
    {
      "x": 8,
      "y": -7,
      "z": 8,
      "name": "Soil_Mud_Dry"
    },
    {
      "x": 8,
      "y": -6,
      "z": 8,
      "name": "Soil_Mud_Dry"
    },
    {
      "x": 8,
      "y": -5,
      "z": 8,
      "name": "Soil_Mud_Dry"
    },
    {
      "x": 8,
      "y": -4,
      "z": 8,
      "name": "Soil_Mud_Dry"
    },
    {
      "x": 8,
      "y": -3,
      "z": 8,
      "name": "Soil_Mud_Dry"
    },
    {
      "x": 8,
      "y": -2,
      "z": 8,
      "name": "Soil_Mud_Dry"
    },
    {
      "x": 8,
      "y": -1,
      "z": 8,
      "name": "Soil_Mud_Dry"
    },
    {
      "x": 8,
      "y": 0,
      "z": 8,
      "name": "Deco_Bone_Spine"
    },
    {
      "x": 8,
      "y": -7,
      "z": 9,
      "name": "Soil_Mud_Dry"
    },
    {
      "x": 8,
      "y": -6,
      "z": 9,
      "name": "Soil_Mud_Dry"
    },
    {
      "x": 8,
      "y": -5,
      "z": 9,
      "name": "Soil_Mud_Dry"
    },
    {
      "x": 8,
      "y": -4,
      "z": 9,
      "name": "Soil_Mud_Dry"
    },
    {
      "x": 8,
      "y": -3,
      "z": 9,
      "name": "Soil_Mud_Dry"
    },
    {
      "x": 8,
      "y": -2,
      "z": 9,
      "name": "Soil_Mud_Dry"
    },
    {
      "x": 8,
      "y": -1,
      "z": 9,
      "name": "Soil_Mud_Dry"
    },
    {
      "x": 8,
      "y": 0,
      "z": 9,
      "name": "Deco_Bone_Spine"
    },
    {
      "x": 8,
      "y": -7,
      "z": 10,
      "name": "Soil_Mud_Dry"
    },
    {
      "x": 8,
      "y": -6,
      "z": 10,
      "name": "Soil_Mud_Dry"
    },
    {
      "x": 8,
      "y": -5,
      "z": 10,
      "name": "Soil_Mud_Dry"
    },
    {
      "x": 8,
      "y": -4,
      "z": 10,
      "name": "Soil_Mud_Dry"
    },
    {
      "x": 8,
      "y": -3,
      "z": 10,
      "name": "Soil_Mud_Dry"
    },
    {
      "x": 8,
      "y": -2,
      "z": 10,
      "name": "Soil_Mud_Dry"
    },
    {
      "x": 8,
      "y": -1,
      "z": 10,
      "name": "Soil_Mud_Dry"
    },
    {
      "x": 8,
      "y": 0,
      "z": 10,
      "name": "Deco_Bone_Spine"
    },
    {
      "x": 8,
      "y": -7,
      "z": 11,
      "name": "Soil_Mud_Dry"
    },
    {
      "x": 8,
      "y": -6,
      "z": 11,
      "name": "Soil_Mud_Dry"
    },
    {
      "x": 8,
      "y": -5,
      "z": 11,
      "name": "Soil_Mud_Dry"
    },
    {
      "x": 8,
      "y": -4,
      "z": 11,
      "name": "Soil_Mud_Dry"
    },
    {
      "x": 8,
      "y": -3,
      "z": 11,
      "name": "Soil_Mud_Dry"
    },
    {
      "x": 8,
      "y": -2,
      "z": 11,
      "name": "Soil_Mud_Dry"
    },
    {
      "x": 8,
      "y": -1,
      "z": 11,
      "name": "Soil_Mud_Dry"
    },
    {
      "x": 8,
      "y": 0,
      "z": 11,
      "name": "Deco_Bone_Spine"
    },
    {
      "x": 8,
      "y": -5,
      "z": 12,
      "name": "Soil_Mud_Dry"
    },
    {
      "x": 8,
      "y": -4,
      "z": 12,
      "name": "Soil_Mud_Dry"
    },
    {
      "x": 8,
      "y": -3,
      "z": 12,
      "name": "Soil_Mud_Dry"
    },
    {
      "x": 8,
      "y": -2,
      "z": 12,
      "name": "Soil_Mud_Dry"
    },
    {
      "x": 8,
      "y": -1,
      "z": 12,
      "name": "Soil_Mud_Dry"
    },
    {
      "x": 8,
      "y": 0,
      "z": 12,
      "name": "Deco_Bone_Spine"
    },
    {
      "x": 8,
      "y": -5,
      "z": 13,
      "name": "Soil_Mud_Dry"
    },
    {
      "x": 8,
      "y": -4,
      "z": 13,
      "name": "Soil_Mud_Dry"
    },
    {
      "x": 8,
      "y": -3,
      "z": 13,
      "name": "Soil_Mud_Dry"
    },
    {
      "x": 8,
      "y": -2,
      "z": 13,
      "name": "Soil_Mud_Dry"
    },
    {
      "x": 8,
      "y": -1,
      "z": 13,
      "name": "Soil_Mud_Dry"
    },
    {
      "x": 8,
      "y": 0,
      "z": 13,
      "name": "Deco_Bone_Spine"
    },
    {
      "x": 8,
      "y": -4,
      "z": 14,
      "name": "Soil_Mud_Dry"
    },
    {
      "x": 8,
      "y": -3,
      "z": 14,
      "name": "Soil_Mud_Dry"
    },
    {
      "x": 8,
      "y": -2,
      "z": 14,
      "name": "Soil_Mud_Dry"
    },
    {
      "x": 9,
      "y": -4,
      "z": 1,
      "name": "Soil_Mud_Dry"
    },
    {
      "x": 9,
      "y": -3,
      "z": 1,
      "name": "Soil_Mud_Dry"
    },
    {
      "x": 9,
      "y": -5,
      "z": 2,
      "name": "Soil_Mud_Dry"
    },
    {
      "x": 9,
      "y": -4,
      "z": 2,
      "name": "Soil_Mud_Dry"
    },
    {
      "x": 9,
      "y": -3,
      "z": 2,
      "name": "Soil_Dirt"
    },
    {
      "x": 9,
      "y": -2,
      "z": 2,
      "name": "Soil_Dirt"
    },
    {
      "x": 9,
      "y": -6,
      "z": 3,
      "name": "Soil_Mud_Dry"
    },
    {
      "x": 9,
      "y": -5,
      "z": 3,
      "name": "Soil_Mud_Dry"
    },
    {
      "x": 9,
      "y": -4,
      "z": 3,
      "name": "Soil_Mud_Dry"
    },
    {
      "x": 9,
      "y": -3,
      "z": 3,
      "name": "Soil_Mud_Dry"
    },
    {
      "x": 9,
      "y": -2,
      "z": 3,
      "name": "Soil_Mud_Dry"
    },
    {
      "x": 9,
      "y": -1,
      "z": 3,
      "name": "Soil_Mud_Dry"
    },
    {
      "x": 9,
      "y": -6,
      "z": 4,
      "name": "Soil_Mud_Dry"
    },
    {
      "x": 9,
      "y": -5,
      "z": 4,
      "name": "Soil_Mud_Dry"
    },
    {
      "x": 9,
      "y": -4,
      "z": 4,
      "name": "Soil_Mud_Dry"
    },
    {
      "x": 9,
      "y": -3,
      "z": 4,
      "name": "Soil_Mud_Dry"
    },
    {
      "x": 9,
      "y": -2,
      "z": 4,
      "name": "Soil_Mud_Dry"
    },
    {
      "x": 9,
      "y": -1,
      "z": 4,
      "name": "Soil_Mud_Dry"
    },
    {
      "x": 9,
      "y": 0,
      "z": 4,
      "name": "Deco_Bone_Ribs",
      "rotation": 1
    },
    {
      "x": 9,
      "y": -7,
      "z": 5,
      "name": "Soil_Mud_Dry"
    },
    {
      "x": 9,
      "y": -6,
      "z": 5,
      "name": "Soil_Mud_Dry"
    },
    {
      "x": 9,
      "y": -5,
      "z": 5,
      "name": "Soil_Mud_Dry"
    },
    {
      "x": 9,
      "y": -4,
      "z": 5,
      "name": "Soil_Mud_Dry"
    },
    {
      "x": 9,
      "y": -3,
      "z": 5,
      "name": "Soil_Mud_Dry"
    },
    {
      "x": 9,
      "y": -2,
      "z": 5,
      "name": "Soil_Dirt"
    },
    {
      "x": 9,
      "y": -1,
      "z": 5,
      "name": "Soil_Mud_Dry"
    },
    {
      "x": 9,
      "y": 0,
      "z": 5,
      "name": "Deco_Bone_Ribs",
      "rotation": 1
    },
    {
      "x": 9,
      "y": -7,
      "z": 6,
      "name": "Soil_Mud_Dry"
    },
    {
      "x": 9,
      "y": -6,
      "z": 6,
      "name": "Soil_Mud_Dry"
    },
    {
      "x": 9,
      "y": -5,
      "z": 6,
      "name": "Soil_Mud_Dry"
    },
    {
      "x": 9,
      "y": -4,
      "z": 6,
      "name": "Soil_Mud_Dry"
    },
    {
      "x": 9,
      "y": -3,
      "z": 6,
      "name": "Soil_Mud_Dry"
    },
    {
      "x": 9,
      "y": -2,
      "z": 6,
      "name": "Soil_Mud_Dry"
    },
    {
      "x": 9,
      "y": -1,
      "z": 6,
      "name": "Soil_Mud_Dry"
    },
    {
      "x": 9,
      "y": -7,
      "z": 7,
      "name": "Soil_Mud_Dry"
    },
    {
      "x": 9,
      "y": -6,
      "z": 7,
      "name": "Soil_Mud_Dry"
    },
    {
      "x": 9,
      "y": -5,
      "z": 7,
      "name": "Soil_Mud_Dry"
    },
    {
      "x": 9,
      "y": -4,
      "z": 7,
      "name": "Soil_Mud_Dry"
    },
    {
      "x": 9,
      "y": -3,
      "z": 7,
      "name": "Soil_Mud_Dry"
    },
    {
      "x": 9,
      "y": -2,
      "z": 7,
      "name": "Soil_Mud_Dry"
    },
    {
      "x": 9,
      "y": -1,
      "z": 7,
      "name": "Soil_Mud_Dry"
    },
    {
      "x": 9,
      "y": 0,
      "z": 7,
      "name": "Deco_Bone_Ribs_Long",
      "rotation": 5
    },
    {
      "x": 9,
      "y": -7,
      "z": 8,
      "name": "Soil_Mud_Dry"
    },
    {
      "x": 9,
      "y": -6,
      "z": 8,
      "name": "Soil_Mud_Dry"
    },
    {
      "x": 9,
      "y": -5,
      "z": 8,
      "name": "Soil_Mud_Dry"
    },
    {
      "x": 9,
      "y": -4,
      "z": 8,
      "name": "Soil_Mud_Dry"
    },
    {
      "x": 9,
      "y": -3,
      "z": 8,
      "name": "Soil_Mud_Dry"
    },
    {
      "x": 9,
      "y": -2,
      "z": 8,
      "name": "Soil_Mud_Dry"
    },
    {
      "x": 9,
      "y": -1,
      "z": 8,
      "name": "Soil_Mud_Dry"
    },
    {
      "x": 9,
      "y": 0,
      "z": 8,
      "name": "Deco_Bone_Ribs_Long",
      "rotation": 5
    },
    {
      "x": 9,
      "y": -7,
      "z": 9,
      "name": "Soil_Mud_Dry"
    },
    {
      "x": 9,
      "y": -6,
      "z": 9,
      "name": "Soil_Mud_Dry"
    },
    {
      "x": 9,
      "y": -5,
      "z": 9,
      "name": "Soil_Mud_Dry"
    },
    {
      "x": 9,
      "y": -4,
      "z": 9,
      "name": "Soil_Mud_Dry"
    },
    {
      "x": 9,
      "y": -3,
      "z": 9,
      "name": "Soil_Mud_Dry"
    },
    {
      "x": 9,
      "y": -2,
      "z": 9,
      "name": "Soil_Mud_Dry"
    },
    {
      "x": 9,
      "y": -1,
      "z": 9,
      "name": "Soil_Mud_Dry"
    },
    {
      "x": 9,
      "y": 0,
      "z": 9,
      "name": "Deco_Bone_Ribs_Long",
      "rotation": 5
    },
    {
      "x": 9,
      "y": -7,
      "z": 10,
      "name": "Soil_Mud_Dry"
    },
    {
      "x": 9,
      "y": -6,
      "z": 10,
      "name": "Soil_Mud_Dry"
    },
    {
      "x": 9,
      "y": -5,
      "z": 10,
      "name": "Soil_Mud_Dry"
    },
    {
      "x": 9,
      "y": -4,
      "z": 10,
      "name": "Soil_Mud_Dry"
    },
    {
      "x": 9,
      "y": -3,
      "z": 10,
      "name": "Soil_Mud_Dry"
    },
    {
      "x": 9,
      "y": -2,
      "z": 10,
      "name": "Soil_Mud_Dry"
    },
    {
      "x": 9,
      "y": -1,
      "z": 10,
      "name": "Soil_Mud_Dry"
    },
    {
      "x": 9,
      "y": -6,
      "z": 11,
      "name": "Soil_Mud_Dry"
    },
    {
      "x": 9,
      "y": -5,
      "z": 11,
      "name": "Soil_Mud_Dry"
    },
    {
      "x": 9,
      "y": -4,
      "z": 11,
      "name": "Soil_Mud_Dry"
    },
    {
      "x": 9,
      "y": -3,
      "z": 11,
      "name": "Soil_Mud_Dry"
    },
    {
      "x": 9,
      "y": -2,
      "z": 11,
      "name": "Soil_Mud_Dry"
    },
    {
      "x": 9,
      "y": -1,
      "z": 11,
      "name": "Soil_Mud_Dry"
    },
    {
      "x": 9,
      "y": 0,
      "z": 11,
      "name": "Deco_Bone_Ribs_Long",
      "rotation": 5
    },
    {
      "x": 9,
      "y": -5,
      "z": 12,
      "name": "Soil_Mud_Dry"
    },
    {
      "x": 9,
      "y": -4,
      "z": 12,
      "name": "Soil_Mud_Dry"
    },
    {
      "x": 9,
      "y": -3,
      "z": 12,
      "name": "Soil_Mud_Dry"
    },
    {
      "x": 9,
      "y": -2,
      "z": 12,
      "name": "Soil_Mud_Dry"
    },
    {
      "x": 9,
      "y": -1,
      "z": 12,
      "name": "Soil_Mud_Dry"
    },
    {
      "x": 9,
      "y": 0,
      "z": 12,
      "name": "Deco_Bone_Ribs_Long",
      "rotation": 5
    },
    {
      "x": 9,
      "y": -5,
      "z": 13,
      "name": "Soil_Mud_Dry"
    },
    {
      "x": 9,
      "y": -4,
      "z": 13,
      "name": "Soil_Mud_Dry"
    },
    {
      "x": 9,
      "y": -3,
      "z": 13,
      "name": "Soil_Mud_Dry"
    },
    {
      "x": 9,
      "y": -2,
      "z": 13,
      "name": "Soil_Mud_Dry"
    },
    {
      "x": 9,
      "y": -1,
      "z": 13,
      "name": "Soil_Mud_Dry"
    },
    {
      "x": 9,
      "y": -3,
      "z": 14,
      "name": "Soil_Mud_Dry"
    },
    {
      "x": 9,
      "y": -2,
      "z": 14,
      "name": "Soil_Mud_Dry"
    },
    {
      "x": 10,
      "y": -4,
      "z": 2,
      "name": "Soil_Mud_Dry"
    },
    {
      "x": 10,
      "y": -3,
      "z": 2,
      "name": "Soil_Mud_Dry"
    },
    {
      "x": 10,
      "y": -5,
      "z": 3,
      "name": "Soil_Mud_Dry"
    },
    {
      "x": 10,
      "y": -4,
      "z": 3,
      "name": "Soil_Mud_Dry"
    },
    {
      "x": 10,
      "y": -3,
      "z": 3,
      "name": "Soil_Dirt"
    },
    {
      "x": 10,
      "y": -2,
      "z": 3,
      "name": "Soil_Dirt"
    },
    {
      "x": 10,
      "y": -5,
      "z": 4,
      "name": "Soil_Mud_Dry"
    },
    {
      "x": 10,
      "y": -4,
      "z": 4,
      "name": "Soil_Mud_Dry"
    },
    {
      "x": 10,
      "y": -3,
      "z": 4,
      "name": "Soil_Mud_Dry"
    },
    {
      "x": 10,
      "y": -2,
      "z": 4,
      "name": "Soil_Mud_Dry"
    },
    {
      "x": 10,
      "y": -5,
      "z": 5,
      "name": "Soil_Mud_Dry"
    },
    {
      "x": 10,
      "y": -4,
      "z": 5,
      "name": "Soil_Mud_Dry"
    },
    {
      "x": 10,
      "y": -3,
      "z": 5,
      "name": "Soil_Mud_Dry"
    },
    {
      "x": 10,
      "y": -2,
      "z": 5,
      "name": "Soil_Mud_Dry"
    },
    {
      "x": 10,
      "y": -1,
      "z": 5,
      "name": "Soil_Mud_Dry"
    },
    {
      "x": 10,
      "y": -5,
      "z": 6,
      "name": "Soil_Mud_Dry"
    },
    {
      "x": 10,
      "y": -4,
      "z": 6,
      "name": "Soil_Mud_Dry"
    },
    {
      "x": 10,
      "y": -3,
      "z": 6,
      "name": "Soil_Mud_Dry"
    },
    {
      "x": 10,
      "y": -2,
      "z": 6,
      "name": "Soil_Mud_Dry"
    },
    {
      "x": 10,
      "y": -5,
      "z": 7,
      "name": "Soil_Mud_Dry"
    },
    {
      "x": 10,
      "y": -4,
      "z": 7,
      "name": "Soil_Mud_Dry"
    },
    {
      "x": 10,
      "y": -3,
      "z": 7,
      "name": "Soil_Mud_Dry"
    },
    {
      "x": 10,
      "y": -2,
      "z": 7,
      "name": "Soil_Mud_Dry"
    },
    {
      "x": 10,
      "y": -1,
      "z": 7,
      "name": "Soil_Mud_Dry"
    },
    {
      "x": 10,
      "y": 0,
      "z": 7,
      "name": "Deco_Bone_Ribs",
      "rotation": 1
    },
    {
      "x": 10,
      "y": -6,
      "z": 8,
      "name": "Soil_Mud_Dry"
    },
    {
      "x": 10,
      "y": -5,
      "z": 8,
      "name": "Soil_Mud_Dry"
    },
    {
      "x": 10,
      "y": -4,
      "z": 8,
      "name": "Soil_Mud_Dry"
    },
    {
      "x": 10,
      "y": -3,
      "z": 8,
      "name": "Soil_Mud_Dry"
    },
    {
      "x": 10,
      "y": -2,
      "z": 8,
      "name": "Soil_Mud_Dry"
    },
    {
      "x": 10,
      "y": -1,
      "z": 8,
      "name": "Soil_Mud_Dry"
    },
    {
      "x": 10,
      "y": 0,
      "z": 8,
      "name": "Deco_Bone_Ribs_Long",
      "rotation": 5
    },
    {
      "x": 10,
      "y": -6,
      "z": 9,
      "name": "Soil_Mud_Dry"
    },
    {
      "x": 10,
      "y": -5,
      "z": 9,
      "name": "Soil_Mud_Dry"
    },
    {
      "x": 10,
      "y": -4,
      "z": 9,
      "name": "Soil_Mud_Dry"
    },
    {
      "x": 10,
      "y": -3,
      "z": 9,
      "name": "Soil_Mud_Dry"
    },
    {
      "x": 10,
      "y": -2,
      "z": 9,
      "name": "Soil_Mud_Dry"
    },
    {
      "x": 10,
      "y": -1,
      "z": 9,
      "name": "Soil_Mud_Dry"
    },
    {
      "x": 10,
      "y": 0,
      "z": 9,
      "name": "Deco_Bone_Ribs_Long",
      "rotation": 5
    },
    {
      "x": 10,
      "y": -6,
      "z": 10,
      "name": "Soil_Mud_Dry"
    },
    {
      "x": 10,
      "y": -5,
      "z": 10,
      "name": "Soil_Mud_Dry"
    },
    {
      "x": 10,
      "y": -4,
      "z": 10,
      "name": "Soil_Mud_Dry"
    },
    {
      "x": 10,
      "y": -3,
      "z": 10,
      "name": "Soil_Mud_Dry"
    },
    {
      "x": 10,
      "y": -2,
      "z": 10,
      "name": "Soil_Mud_Dry"
    },
    {
      "x": 10,
      "y": -1,
      "z": 10,
      "name": "Soil_Mud_Dry"
    },
    {
      "x": 10,
      "y": -6,
      "z": 11,
      "name": "Soil_Mud_Dry"
    },
    {
      "x": 10,
      "y": -5,
      "z": 11,
      "name": "Soil_Mud_Dry"
    },
    {
      "x": 10,
      "y": -4,
      "z": 11,
      "name": "Soil_Mud_Dry"
    },
    {
      "x": 10,
      "y": -3,
      "z": 11,
      "name": "Soil_Mud_Dry"
    },
    {
      "x": 10,
      "y": -2,
      "z": 11,
      "name": "Soil_Mud_Dry"
    },
    {
      "x": 10,
      "y": -1,
      "z": 11,
      "name": "Soil_Mud_Dry"
    },
    {
      "x": 10,
      "y": -5,
      "z": 12,
      "name": "Soil_Mud_Dry"
    },
    {
      "x": 10,
      "y": -4,
      "z": 12,
      "name": "Soil_Mud_Dry"
    },
    {
      "x": 10,
      "y": -3,
      "z": 12,
      "name": "Soil_Mud_Dry"
    },
    {
      "x": 10,
      "y": -2,
      "z": 12,
      "name": "Soil_Mud_Dry"
    },
    {
      "x": 10,
      "y": -1,
      "z": 12,
      "name": "Soil_Mud_Dry"
    },
    {
      "x": 10,
      "y": 0,
      "z": 12,
      "name": "Deco_Bone_Ribs",
      "rotation": 1
    },
    {
      "x": 10,
      "y": -4,
      "z": 13,
      "name": "Soil_Mud_Dry"
    },
    {
      "x": 10,
      "y": -3,
      "z": 13,
      "name": "Soil_Mud_Dry"
    },
    {
      "x": 10,
      "y": -2,
      "z": 13,
      "name": "Soil_Mud_Dry"
    },
    {
      "x": 11,
      "y": -3,
      "z": 6,
      "name": "Soil_Mud_Dry"
    },
    {
      "x": 11,
      "y": -2,
      "z": 6,
      "name": "Soil_Mud_Dry"
    },
    {
      "x": 11,
      "y": -4,
      "z": 7,
      "name": "Soil_Mud_Dry"
    },
    {
      "x": 11,
      "y": -3,
      "z": 7,
      "name": "Soil_Mud_Dry"
    },
    {
      "x": 11,
      "y": -2,
      "z": 7,
      "name": "Soil_Mud_Dry"
    },
    {
      "x": 11,
      "y": -5,
      "z": 8,
      "name": "Soil_Mud_Dry"
    },
    {
      "x": 11,
      "y": -4,
      "z": 8,
      "name": "Soil_Mud_Dry"
    },
    {
      "x": 11,
      "y": -3,
      "z": 8,
      "name": "Soil_Mud_Dry"
    },
    {
      "x": 11,
      "y": -2,
      "z": 8,
      "name": "Soil_Mud_Dry"
    },
    {
      "x": 11,
      "y": -1,
      "z": 8,
      "name": "Soil_Mud_Dry"
    },
    {
      "x": 11,
      "y": -5,
      "z": 9,
      "name": "Soil_Mud_Dry"
    },
    {
      "x": 11,
      "y": -4,
      "z": 9,
      "name": "Soil_Mud_Dry"
    },
    {
      "x": 11,
      "y": -3,
      "z": 9,
      "name": "Soil_Mud_Dry"
    },
    {
      "x": 11,
      "y": -2,
      "z": 9,
      "name": "Soil_Mud_Dry"
    },
    {
      "x": 11,
      "y": -1,
      "z": 9,
      "name": "Soil_Mud_Dry"
    },
    {
      "x": 11,
      "y": 0,
      "z": 9,
      "name": "Deco_Bone_Ribs",
      "rotation": 1
    },
    {
      "x": 11,
      "y": -4,
      "z": 10,
      "name": "Soil_Mud_Dry"
    },
    {
      "x": 11,
      "y": -3,
      "z": 10,
      "name": "Soil_Mud_Dry"
    },
    {
      "x": 11,
      "y": -2,
      "z": 10,
      "name": "Soil_Dirt"
    },
    {
      "x": 11,
      "y": -1,
      "z": 10,
      "name": "Soil_Dirt"
    },
    {
      "x": 11,
      "y": 0,
      "z": 10,
      "name": "Deco_Bone_Pile"
    },
    {
      "x": 11,
      "y": -4,
      "z": 11,
      "name": "Soil_Mud_Dry"
    },
    {
      "x": 11,
      "y": -3,
      "z": 11,
      "name": "Soil_Mud_Dry"
    },
    {
      "x": 11,
      "y": -2,
      "z": 11,
      "name": "Soil_Mud_Dry"
    },
    {
      "x": 11,
      "y": -3,
      "z": 12,
      "name": "Soil_Mud_Dry"
    },
    {
      "x": 11,
      "y": -2,
      "z": 12,
      "name": "Soil_Mud_Dry"
    },
    {
      "x": 12,
      "y": -4,
      "z": 8,
      "name": "Soil_Mud_Dry"
    },
    {
      "x": 12,
      "y": -3,
      "z": 8,
      "name": "Soil_Mud_Dry"
    },
    {
      "x": 12,
      "y": -2,
      "z": 8,
      "name": "Soil_Mud_Dry"
    },
    {
      "x": 12,
      "y": -3,
      "z": 9,
      "name": "Soil_Mud_Dry"
    },
    {
      "x": 12,
      "y": -2,
      "z": 9,
      "name": "Soil_Mud_Dry"
    },
    {
      "x": 12,
      "y": -1,
      "z": 9,
      "name": "Soil_Mud_Dry"
    },
    {
      "x": 12,
      "y": -3,
      "z": 10,
      "name": "Soil_Mud_Dry"
    },
    {
      "x": 12,
      "y": -2,
      "z": 10,
      "name": "Soil_Mud_Dry"
    }
  ]
}