{
  "version": 8,
  "blockIdVersion": 11,
  "anchorX": 2,
  "anchorY": -1,
  "anchorZ": 2,
  "blocks": [
    {
      "x": -2,
      "y": -2,
      "z": 1,
      "name": "Soil_Mud_Dry"
    },
    {
      "x": -2,
      "y": -3,
      "z": 2,
      "name": "Soil_Mud_Dry"
    },
    {
      "x": -2,
      "y": -2,
      "z": 2,
      "name": "Soil_Mud_Dry"
    },
    {
      "x": -2,
      "y": -1,
      "z": 2,
      "name": "Soil_Mud_Dry"
    },
    {
      "x": -2,
      "y": -2,
      "z": 3,
      "name": "Soil_Mud_Dry"
    },
    {
      "x": -1,
      "y": -2,
      "z": 0,
      "name": "Soil_Mud_Dry"
    },
    {
      "x": -1,
      "y": -3,
      "z": 1,
      "name": "Soil_Mud_Dry"
    },
    {
      "x": -1,
      "y": -2,
      "z": 1,
      "name": "Soil_Mud_Dry"
    },
    {
      "x": -1,
      "y": -1,
      "z": 1,
      "name": "Soil_Mud_Dry"
    },
    {
      "x": -1,
      "y": -4,
      "z": 2,
      "name": "Soil_Mud_Dry"
    },
    {
      "x": -1,
      "y": -3,
      "z": 2,
      "name": "Soil_Mud_Dry"
    },
    {
      "x": -1,
      "y": -2,
      "z": 2,
      "name": "Soil_Mud_Dry"
    },
    {
      "x": -1,
      "y": -1,
      "z": 2,
      "name": "Soil_Mud_Dry"
    },
    {
      "x": -1,
      "y": -3,
      "z": 3,
      "name": "Soil_Mud_Dry"
    },
    {
      "x": -1,
      "y": -2,
      "z": 3,
      "name": "Soil_Mud_Dry"
    },
    {
      "x": -1,
      "y": -1,
      "z": 3,
      "name": "Soil_Mud_Dry"
    },
    {
      "x": -1,
      "y": 0,
      "z": 3,
      "name": "Deco_Bone_Pile"
    },
    {
      "x": -1,
      "y": -2,
      "z": 4,
      "name": "Soil_Mud_Dry"
    },
    {
      "x": 0,
      "y": -2,
      "z": -1,
      "name": "Soil_Mud_Dry"
    },
    {
      "x": 0,
      "y": -3,
      "z": 0,
      "name": "Soil_Mud_Dry"
    },
    {
      "x": 0,
      "y": -2,
      "z": 0,
      "name": "Soil_Mud_Dry"
    },
    {
      "x": 0,
      "y": -1,
      "z": 0,
      "name": "Soil_Mud_Dry"
    },
    {
      "x": 0,
      "y": 0,
      "z": 0,
      "name": "Plant_Leaves_Jungle_Floor",
      "support": 15
    },
    {
      "x": 0,
      "y": -4,
      "z": 1,
      "name": "Soil_Mud_Dry"
    },
    {
      "x": 0,
      "y": -3,
      "z": 1,
      "name": "Soil_Mud_Dry"
    },
    {
      "x": 0,
      "y": -2,
      "z": 1,
      "name": "Soil_Mud_Dry"
    },
    {
      "x": 0,
      "y": -1,
      "z": 1,
      "name": "Soil_Mud_Dry"
    },
    {
      "x": 0,
      "y": -4,
      "z": 2,
      "name": "Soil_Mud_Dry"
    },
    {
      "x": 0,
      "y": -3,
      "z": 2,
      "name": "Soil_Mud_Dry"
    },
    {
      "x": 0,
      "y": -2,
      "z": 2,
      "name": "Soil_Mud_Dry"
    },
    {
      "x": 0,
      "y": -1,
      "z": 2,
      "name": "Soil_Mud_Dry"
    },
    {
      "x": 0,
      "y": 0,
      "z": 2,
      "name": "Deco_Bone_Ribs",
      "rotation": 3
    },
    {
      "x": 0,
      "y": -4,
      "z": 3,
      "name": "Soil_Mud_Dry"
    },
    {
      "x": 0,
      "y": -3,
      "z": 3,
      "name": "Soil_Mud_Dry"
    },
    {
      "x": 0,
      "y": -2,
      "z": 3,
      "name": "Soil_Mud_Dry"
    },
    {
      "x": 0,
      "y": -1,
      "z": 3,
      "name": "Soil_Dirt"
    },
    {
      "x": 0,
      "y": -3,
      "z": 4,
      "name": "Soil_Mud_Dry"
    },
    {
      "x": 0,
      "y": -2,
      "z": 4,
      "name": "Soil_Mud_Dry"
    },
    {
      "x": 1,
      "y": -2,
      "z": -2,
      "name": "Soil_Mud_Dry"
    },
    {
      "x": 1,
      "y": -3,
      "z": -1,
      "name": "Soil_Mud_Dry"
    },
    {
      "x": 1,
      "y": -2,
      "z": -1,
      "name": "Soil_Mud_Dry"
    },
    {
      "x": 1,
      "y": -1,
      "z": -1,
      "name": "Soil_Dirt"
    },
    {
      "x": 1,
      "y": -4,
      "z": 0,
      "name": "Soil_Mud_Dry"
    },
    {
      "x": 1,
      "y": -3,
      "z": 0,
      "name": "Soil_Mud_Dry"
    },
    {
      "x": 1,
      "y": -2,
      "z": 0,
      "name": "Soil_Mud_Dry"
    },
    {
      "x": 1,
      "y": -1,
      "z": 0,
      "name": "Soil_Mud_Dry"
    },
    {
      "x": 1,
      "y": -5,
      "z": 1,
      "name": "Soil_Mud_Dry"
    },
    {
      "x": 1,
      "y": -4,
      "z": 1,
      "name": "Soil_Mud_Dry"
    },
    {
      "x": 1,
      "y": -3,
      "z": 1,
      "name": "Soil_Mud_Dry"
    },
    {
      "x": 1,
      "y": -2,
      "z": 1,
      "name": "Soil_Mud_Dry"
    },
    {
      "x": 1,
      "y": -1,
      "z": 1,
      "name": "Soil_Mud_Dry"
    },
    {
      "x": 1,
      "y": 0,
      "z": 1,
      "name": "Deco_Bone_Ribs",
      "rotation": 3
    },
    {
      "x": 1,
      "y": -5,
      "z": 2,
      "name": "Soil_Mud_Dry"
    },
    {
      "x": 1,
      "y": -4,
      "z": 2,
      "name": "Soil_Mud_Dry"
    },
    {
      "x": 1,
      "y": -3,
      "z": 2,
      "name": "Soil_Mud_Dry"
    },
    {
      "x": 1,
      "y": -2,
      "z": 2,
      "name": "Soil_Mud_Dry"
    },
    {
      "x": 1,
      "y": -1,
      "z": 2,
      "name": "Soil_Mud_Dry"
    },
    {
      "x": 1,
      "y": 0,
      "z": 2,
      "name": "Deco_Bone_Ribs_Long",
      "rotation": 5
    },
    {
      "x": 1,
      "y": -5,
      "z": 3,
      "name": "Soil_Mud_Dry"
    },
    {
      "x": 1,
      "y": -4,
      "z": 3,
      "name": "Soil_Mud_Dry"
    },
    {
      "x": 1,
      "y": -3,
      "z": 3,
      "name": "Soil_Mud_Dry"
    },
    {
      "x": 1,
      "y": -2,
      "z": 3,
      "name": "Soil_Mud_Dry"
    },
    {
      "x": 1,
      "y": -1,
      "z": 3,
      "name": "Soil_Mud_Dry"
    },
    {
      "x": 1,
      "y": -4,
      "z": 4,
      "name": "Soil_Mud_Dry"
    },
    {
      "x": 1,
      "y": -3,
      "z": 4,
      "name": "Soil_Mud_Dry"
    },
    {
      "x": 1,
      "y": -2,
      "z": 4,
      "name": "Soil_Mud_Dry"
    },
    {
      "x": 1,
      "y": -3,
      "z": 5,
      "name": "Soil_Mud_Dry"
    },
    {
      "x": 2,
      "y": -3,
      "z": -2,
      "name": "Soil_Dirt"
    },
    {
      "x": 2,
      "y": -2,
      "z": -2,
      "name": "Soil_Mud_Dry"
    },
    {
      "x": 2,
      "y": -1,
      "z": -2,
      "name": "Soil_Dirt"
    },
    {
      "x": 2,
      "y": -4,
      "z": -1,
      "name": "Soil_Mud_Dry"
    },
    {
      "x": 2,
      "y": -3,
      "z": -1,
      "name": "Soil_Mud_Dry"
    },
    {
      "x": 2,
      "y": -2,
      "z": -1,
      "name": "Soil_Mud_Dry"
    },
    {
      "x": 2,
      "y": -1,
      "z": -1,
      "name": "Soil_Mud_Dry"
    },
    {
      "x": 2,
      "y": -4,
      "z": 0,
      "name": "Soil_Mud_Dry"
    },
    {
      "x": 2,
      "y": -3,
      "z": 0,
      "name": "Soil_Dirt"
    },
    {
      "x": 2,
      "y": -2,
      "z": 0,
      "name": "Soil_Mud_Dry"
    },
    {
      "x": 2,
      "y": -1,
      "z": 0,
      "name": "Soil_Mud_Dry"
    },
    {
      "x": 2,
      "y": 0,
      "z": 0,
      "name": "Deco_Bone_Spine"
    },
    {
      "x": 2,
      "y": -5,
      "z": 1,
      "name": "Soil_Mud_Dry"
    },
    {
      "x": 2,
      "y": -4,
      "z": 1,
      "name": "Soil_Mud_Dry"
    },
    {
      "x": 2,
      "y": -3,
      "z": 1,
      "name": "Soil_Mud_Dry"
    },
    {
      "x": 2,
      "y": -2,
      "z": 1,
      "name": "Soil_Mud_Dry"
    },
    {
      "x": 2,
      "y": -1,
      "z": 1,
      "name": "Soil_Dirt"
    },
    {
      "x": 2,
      "y": 0,
      "z": 1,
      "name": "Deco_Bone_Spine"
    },
    {
      "x": 2,
      "y": -5,
      "z": 2,
      "name": "Soil_Mud_Dry"
    },
    {
      "x": 2,
      "y": -4,
      "z": 2,
      "name": "Soil_Mud_Dry"
    },
    {
      "x": 2,
      "y": -3,
      "z": 2,
      "name": "Soil_Mud_Dry"
    },
    {
      "x": 2,
      "y": -2,
      "z": 2,
      "name": "Soil_Mud_Dry"
    },
    {
      "x": 2,
      "y": -1,
      "z": 2,
      "name": "Soil_Mud_Dry"
    },
    {
      "x": 2,
      "y": 0,
      "z": 2,
      "name": "Deco_Bone_Spine"
    },
    {
      "x": 2,
      "y": -5,
      "z": 3,
      "name": "Soil_Mud_Dry"
    },
    {
      "x": 2,
      "y": -4,
      "z": 3,
      "name": "Soil_Mud_Dry"
    },
    {
      "x": 2,
      "y": -3,
      "z": 3,
      "name": "Soil_Mud_Dry"
    },
    {
      "x": 2,
      "y": -2,
      "z": 3,
      "name": "Soil_Mud_Dry"
    },
    {
      "x": 2,
      "y": -1,
      "z": 3,
      "name": "Soil_Mud_Dry"
    },
    {
      "x": 2,
      "y": 0,
      "z": 3,
      "name": "Deco_Bone_Ribs_Long",
      "rotation": 4
    },
    {
      "x": 2,
      "y": -5,
      "z": 4,
      "name": "Soil_Mud_Dry"
    },
    {
      "x": 2,
      "y": -4,
      "z": 4,
      "name": "Soil_Mud_Dry"
    },
    {
      "x": 2,
      "y": -3,
      "z": 4,
      "name": "Soil_Mud_Dry"
    },
    {
      "x": 2,
      "y": -2,
      "z": 4,
      "name": "Soil_Mud_Dry"
    },
    {
      "x": 2,
      "y": -1,
      "z": 4,
      "name": "Soil_Dirt"
    },
    {
      "x": 2,
      "y": -4,
      "z": 5,
      "name": "Soil_Mud_Dry"
    },
    {
      "x": 2,
      "y": -3,
      "z": 5,
      "name": "Soil_Mud_Dry"
    },
    {
      "x": 2,
      "y": -2,
      "z": 5,
      "name": "Soil_Mud_Dry"
    },
    {
      "x": 2,
      "y": -3,
      "z": 6,
      "name": "Soil_Mud_Dry"
    },
    {
      "x": 3,
      "y": -2,
      "z": -2,
      "name": "Soil_Dirt"
    },
    {
      "x": 3,
      "y": -3,
      "z": -1,
      "name": "Soil_Mud_Dry"
    },
    {
      "x": 3,
      "y": -2,
      "z": -1,
      "name": "Soil_Mud_Dry"
    },
    {
      "x": 3,
      "y": -1,
      "z": -1,
      "name": "Soil_Mud_Dry"
    },
    {
      "x": 3,
      "y": 0,
      "z": -1,
      "name": "Deco_Bone_Pile"
    },
    {
      "x": 3,
      "y": -4,
      "z": 0,
      "name": "Soil_Mud_Dry"
    },
    {
      "x": 3,
      "y": -3,
      "z": 0,
      "name": "Soil_Mud_Dry"
    },
    {
      "x": 3,
      "y": -2,
      "z": 0,
      "name": "Soil_Dirt"
    },
    {
      "x": 3,
      "y": -1,
      "z": 0,
      "name": "Soil_Mud_Dry"
    },
    {
      "x": 3,
      "y": -4,
      "z": 1,
      "name": "Soil_Mud_Dry"
    },
    {
      "x": 3,
      "y": -3,
      "z": 1,
      "name": "Soil_Mud_Dry"
    },
    {
      "x": 3,
      "y": -2,
      "z": 1,
      "name": "Soil_Mud_Dry"
    },
    {
      "x": 3,
      "y": -1,
      "z": 1,
      "name": "Soil_Mud_Dry"
    },
    {
      "x": 3,
      "y": 0,
      "z": 1,
      "name": "Deco_Bone_Ribs_Long",
      "rotation": 5
    },
    {
      "x": 3,
      "y": -5,
      "z": 2,
      "name": "Soil_Mud_Dry"
    },
    {
      "x": 3,
      "y": -4,
      "z": 2,
      "name": "Soil_Mud_Dry"
    },
    {
      "x": 3,
      "y": -3,
      "z": 2,
      "name": "Soil_Mud_Dry"
    },
    {
      "x": 3,
      "y": -2,
      "z": 2,
      "name": "Soil_Mud_Dry"
    },
    {
      "x": 3,
      "y": -1,
      "z": 2,
      "name": "Soil_Mud_Dry"
    },
    {
      "x": 3,
      "y": 0,
      "z": 2,
      "name": "Deco_Bone_Ribs_Long",
      "rotation": 4
    },
    {
      "x": 3,
      "y": -5,
      "z": 3,
      "name": "Soil_Mud_Dry"
    },
    {
      "x": 3,
      "y": -4,
      "z": 3,
      "name": "Soil_Mud_Dry"
    },
    {
      "x": 3,
      "y": -3,
      "z": 3,
      "name": "Soil_Mud_Dry"
    },
    {
      "x": 3,
      "y": -2,
      "z": 3,
      "name": "Soil_Mud_Dry"
    },
    {
      "x": 3,
      "y": -1,
      "z": 3,
      "name": "Soil_Mud_Dry"
    },
    {
      "x": 3,
      "y": 0,
      "z": 3,
      "name": "Deco_Bone_Spine",
      "rotation": 1
    },
    {
      "x": 3,
      "y": -5,
      "z": 4,
      "name": "Soil_Mud_Dry"
    },
    {
      "x": 3,
      "y": -4,
      "z": 4,
      "name": "Soil_Mud_Dry"
    },
    {
      "x": 3,
      "y": -3,
      "z": 4,
      "name": "Soil_Mud_Dry"
    },
    {
      "x": 3,
      "y": -2,
      "z": 4,
      "name": "Soil_Mud_Dry"
    },
    {
      "x": 3,
      "y": -1,
      "z": 4,
      "name": "Soil_Mud_Dry"
    },
    {
      "x": 3,
      "y": 0,
      "z": 4,
      "name": "Deco_Bone_Ribs_Long",
      "rotation": 4
    },
    {
      "x": 3,
      "y": -5,
      "z": 5,
      "name": "Soil_Mud_Dry"
    },
    {
      "x": 3,
      "y": -4,
      "z": 5,
      "name": "Soil_Mud_Dry"
    },
    {
      "x": 3,
      "y": -3,
      "z": 5,
      "name": "Soil_Mud_Dry"
    },
    {
      "x": 3,
      "y": -2,
      "z": 5,
      "name": "Soil_Mud_Dry"
    },
    {
      "x": 3,
      "y": -1,
      "z": 5,
      "name": "Soil_Mud_Dry"
    },
    {
      "x": 3,
      "y": 0,
      "z": 5,
      "name": "Deco_Bone_Ribs"
    },
    {
      "x": 3,
      "y": -4,
      "z": 6,
      "name": "Soil_Mud_Dry"
    },
    {
      "x": 3,
      "y": -3,
      "z": 6,
      "name": "Soil_Mud_Dry"
    },
    {
      "x": 3,
      "y": -2,
      "z": 6,
      "name": "Soil_Mud_Dry"
    },
    {
      "x": 4,
      "y": -2,
      "z": -1,
      "name": "Soil_Mud_Dry"
    },
    {
      "x": 4,
      "y": -3,
      "z": 0,
      "name": "Soil_Mud_Dry"
    },
    {
      "x": 4,
      "y": -2,
      "z": 0,
      "name": "Soil_Mud_Dry"
    },
    {
      "x": 4,
      "y": -1,
      "z": 0,
      "name": "Soil_Mud_Dry"
    },
    {
      "x": 4,
      "y": -4,
      "z": 1,
      "name": "Soil_Mud_Dry"
    },
    {
      "x": 4,
      "y": -3,
      "z": 1,
      "name": "Soil_Mud_Dry"
    },
    {
      "x": 4,
      "y": -2,
      "z": 1,
      "name": "Soil_Mud_Dry"
    },
    {
      "x": 4,
      "y": -1,
      "z": 1,
      "name": "Soil_Mud_Dry"
    },
    {
      "x": 4,
      "y": 0,
      "z": 1,
      "name": "Deco_Bone_Ribs",
      "rotation": 2
    },
    {
      "x": 4,
      "y": -5,
      "z": 2,
      "name": "Soil_Mud_Dry"
    },
    {
      "x": 4,
      "y": -4,
      "z": 2,
      "name": "Soil_Mud_Dry"
    },
    {
      "x": 4,
      "y": -3,
      "z": 2,
      "name": "Soil_Mud_Dry"
    },
    {
      "x": 4,
      "y": -2,
      "z": 2,
      "name": "Soil_Mud_Dry"
    },
    {
      "x": 4,
      "y": -1,
      "z": 2,
      "name": "Soil_Mud_Dry"
    },
    {
      "x": 4,
      "y": 0,
      "z": 2,
      "name": "Deco_Bone_Ribs_Long",
      "rotation": 4
    },
    {
      "x": 4,
      "y": -5,
      "z": 3,
      "name": "Soil_Mud_Dry"
    },
    {
      "x": 4,
      "y": -4,
      "z": 3,
      "name": "Soil_Mud_Dry"
    },
    {
      "x": 4,
      "y": -3,
      "z": 3,
      "name": "Soil_Mud_Dry"
    },
    {
      "x": 4,
      "y": -2,
      "z": 3,
      "name": "Soil_Mud_Dry"
    },
    {
      "x": 4,
      "y": -1,
      "z": 3,
      "name": "Soil_Mud_Dry"
    },
    {
      "x": 4,
      "y": 0,
      "z": 3,
      "name": "Deco_Bone_Spine",
      "rotation": 1
    },
    {
      "x": 4,
      "y": -5,
      "z": 4,
      "name": "Soil_Mud_Dry"
    },
    {
      "x": 4,
      "y": -4,
      "z": 4,
      "name": "Soil_Mud_Dry"
    },
    {
      "x": 4,
      "y": -3,
      "z": 4,
      "name": "Soil_Mud_Dry"
    },
    {
      "x": 4,
      "y": -2,
      "z": 4,
      "name": "Soil_Mud_Dry"
    },
    {
      "x": 4,
      "y": -1,
      "z": 4,
      "name": "Soil_Mud_Dry"
    },
    {
      "x": 4,
      "y": 0,
      "z": 4,
      "name": "Deco_Bone_Ribs_Long",
      "rotation": 4
    },
    {
      "x": 4,
      "y": -4,
      "z": 5,
      "name": "Soil_Mud_Dry"
    },
    {
      "x": 4,
      "y": -3,
      "z": 5,
      "name": "Soil_Mud_Dry"
    },
    {
      "x": 4,
      "y": -2,
      "z": 5,
      "name": "Soil_Mud_Dry"
    },
    {
      "x": 4,
      "y": 0,
      "z": 5,
      "name": "Deco_Bone_Ribs"
    },
    {
      "x": 4,
      "y": -3,
      "z": 6,
      "name": "Soil_Mud_Dry"
    },
    {
      "x": 5,
      "y": -2,
      "z": 0,
      "name": "Soil_Mud_Dry"
    },
    {
      "x": 5,
      "y": -4,
      "z": 1,
      "name": "Soil_Mud_Dry"
    },
    {
      "x": 5,
      "y": -3,
      "z": 1,
      "name": "Soil_Mud_Dry"
    },
    {
      "x": 5,
      "y": -2,
      "z": 1,
      "name": "Soil_Mud_Dry"
    },
    {
      "x": 5,
      "y": -1,
      "z": 1,
      "name": "Soil_Mud_Dry"
    },
    {
      "x": 5,
      "y": -4,
      "z": 2,
      "name": "Soil_Mud_Dry"
    },
    {
      "x": 5,
      "y": -3,
      "z": 2,
      "name": "Soil_Mud_Dry"
    },
    {
      "x": 5,
      "y": -2,
      "z": 2,
      "name": "Soil_Mud_Dry"
    },
    {
      "x": 5,
      "y": -1,
      "z": 2,
      "name": "Soil_Mud_Dry"
    },
    {
      "x": 5,
      "y": 0,
      "z": 2,
      "name": "Deco_Bone_Ribs_Long",
      "rotation": 4
    },
    {
      "x": 5,
      "y": -5,
      "z": 3,
      "name": "Soil_Mud_Dry"
    },
    {
      "x": 5,
      "y": -4,
      "z": 3,
      "name": "Soil_Mud_Dry"
    },
    {
      "x": 5,
      "y": -3,
      "z": 3,
      "name": "Soil_Mud_Dry"
    },
    {
      "x": 5,
      "y": -2,
      "z": 3,
      "name": "Soil_Mud_Dry"
    },
    {
      "x": 5,
      "y": -1,
      "z": 3,
      "name": "Soil_Mud_Dry"
    },
    {
      "x": 5,
      "y": 0,
      "z": 3,
      "name": "Deco_Bone_Spine",
      "rotation": 1
    },
    {
      "x": 5,
      "y": -4,
      "z": 4,
      "name": "Soil_Mud_Dry"
    },
    {
      "x": 5,
      "y": -3,
      "z": 4,
      "name": "Soil_Mud_Dry"
    },
    {
      "x": 5,
      "y": -2,
      "z": 4,
      "name": "Soil_Mud_Dry"
    },
    {
      "x": 5,
      "y": 0,
      "z": 4,
      "name": "Deco_Bone_Ribs"
    },
    {
      "x": 5,
      "y": -3,
      "z": 5,
      "name": "Soil_Mud_Dry"
    },
    {
      "x": 6,
      "y": -2,
      "z": 1,
      "name": "Soil_Mud_Dry"
    },
    {
      "x": 6,
      "y": -3,
      "z": 2,
      "name": "Soil_Mud_Dry"
    },
    {
      "x": 6,
      "y": -2,
      "z": 2,
      "name": "Soil_Mud_Dry"
    },
    {
      "x": 6,
      "y": -1,
      "z": 2,
      "name": "Soil_Mud_Dry"
    },
    {
      "x": 6,
      "y": -2,
      "z": 3,
      "name": "Soil_Mud_Dry"
    }
  ]
}