{
  "version": 8,
  "blockIdVersion": 11,
  "anchorX": 0,
  "anchorY": 0,
  "anchorZ": 0,
  "blocks": [
    {
      "x": -1,
      "y": 21,
      "z": 0,
      "name": "Build_Tube_Green",
      "rotation": 7
    },
    {
      "x": -1,
      "y": 22,
      "z": 0,
      "name": "Build_Tube_Green",
      "rotation": 7
    },
    {
      "x": -1,
      "y": 23,
      "z": 0,
      "name": "Build_Tube_Green",
      "rotation": 7
    },
    {
      "x": -1,
      "y": 24,
      "z": 0,
      "name": "Build_Tube_Green",
      "rotation": 7
    },
    {
      "x": -1,
      "y": 25,
      "z": 0,
      "name": "Build_Tube_Green",
      "rotation": 7
    },
    {
      "x": -1,
      "y": 26,
      "z": 0,
      "name": "Build_Tube_Green",
      "rotation": 7
    },
    {
      "x": -1,
      "y": 27,
      "z": 0,
      "name": "Build_Tube_Green",
      "rotation": 7
    },
    {
      "x": -1,
      "y": 28,
      "z": 0,
      "name": "Build_Tube_Green",
      "rotation": 7
    },
    {
      "x": -1,
      "y": 20,
      "z": 1,
      "name": "Build_Tube_Green",
      "rotation": 7
    },
    {
      "x": -1,
      "y": 21,
      "z": 1,
      "name": "Build_Tube_Lime",
      "rotation": 7
    },
    {
      "x": -1,
      "y": 22,
      "z": 1,
      "name": "Build_Tube_Green",
      "rotation": 7
    },
    {
      "x": -1,
      "y": 23,
      "z": 1,
      "name": "Build_Tube_Green",
      "rotation": 7
    },
    {
      "x": -1,
      "y": 24,
      "z": 1,
      "name": "Build_Tube_Green",
      "rotation": 7
    },
    {
      "x": -1,
      "y": 25,
      "z": 1,
      "name": "Build_Tube_Green",
      "rotation": 7
    },
    {
      "x": -1,
      "y": 26,
      "z": 1,
      "name": "Build_Tube_Green",
      "rotation": 7
    },
    {
      "x": -1,
      "y": 27,
      "z": 1,
      "name": "Build_Tube_Green",
      "rotation": 7
    },
    {
      "x": -1,
      "y": 28,
      "z": 1,
      "name": "Build_Tube_Green",
      "rotation": 7
    },
    {
      "x": 0,
      "y": 20,
      "z": -1,
      "name": "Build_Tube_Lime",
      "rotation": 6
    },
    {
      "x": 0,
      "y": 21,
      "z": -1,
      "name": "Build_Tube_Lime",
      "rotation": 6
    },
    {
      "x": 0,
      "y": 22,
      "z": -1,
      "name": "Build_Tube_Green",
      "rotation": 6
    },
    {
      "x": 0,
      "y": 23,
      "z": -1,
      "name": "Build_Tube_Green",
      "rotation": 6
    },
    {
      "x": 0,
      "y": 24,
      "z": -1,
      "name": "Build_Tube_Green",
      "rotation": 6
    },
    {
      "x": 0,
      "y": 25,
      "z": -1,
      "name": "Build_Tube_Green",
      "rotation": 6
    },
    {
      "x": 0,
      "y": 26,
      "z": -1,
      "name": "Build_Tube_Green",
      "rotation": 6
    },
    {
      "x": 0,
      "y": 27,
      "z": -1,
      "name": "Build_Tube_Green",
      "rotation": 6
    },
    {
      "x": 0,
      "y": 28,
      "z": -1,
      "name": "Build_Tube_Green",
      "rotation": 6
    },
    {
      "x": 0,
      "y": 0,
      "z": 0,
      "name": "Wood_Prehistoric_Trunk_Full"
    },
    {
      "x": 0,
      "y": 1,
      "z": 0,
      "name": "Wood_Prehistoric_Trunk_Full"
    },
    {
      "x": 0,
      "y": 2,
      "z": 0,
      "name": "Wood_Prehistoric_Trunk_Full"
    },
    {
      "x": 0,
      "y": 3,
      "z": 0,
      "name": "Wood_Prehistoric_Trunk_Full"
    },
    {
      "x": 0,
      "y": 4,
      "z": 0,
      "name": "Wood_Prehistoric_Trunk_Full"
    },
    {
      "x": 0,
      "y": 5,
      "z": 0,
      "name": "Wood_Prehistoric_Trunk_Full"
    },
    {
      "x": 0,
      "y": 6,
      "z": 0,
      "name": "Wood_Prehistoric_Trunk_Full"
    },
    {
      "x": 0,
      "y": 7,
      "z": 0,
      "name": "Wood_Prehistoric_Trunk_Full"
    },
    {
      "x": 0,
      "y": 8,
      "z": 0,
      "name": "Wood_Prehistoric_Trunk_Full"
    },
    {
      "x": 0,
      "y": 9,
      "z": 0,
      "name": "Wood_Prehistoric_Trunk_Full"
    },
    {
      "x": 0,
      "y": 10,
      "z": 0,
      "name": "Wood_Prehistoric_Trunk_Full"
    },
    {
      "x": 0,
      "y": 11,
      "z": 0,
      "name": "Wood_Prehistoric_Trunk_Full"
    },
    {
      "x": 0,
      "y": 12,
      "z": 0,
      "name": "Wood_Prehistoric_Trunk_Full"
    },
    {
      "x": 0,
      "y": 13,
      "z": 0,
      "name": "Wood_Prehistoric_Trunk_Full"
    },
    {
      "x": 0,
      "y": 14,
      "z": 0,
      "name": "Wood_Prehistoric_Trunk_Full"
    },
    {
      "x": 0,
      "y": 15,
      "z": 0,
      "name": "Wood_Prehistoric_Trunk_Full"
    },
    {
      "x": 0,
      "y": 16,
      "z": 0,
      "name": "Wood_Prehistoric_Trunk_Full"
    },
    {
      "x": 0,
      "y": 17,
      "z": 0,
      "name": "Wood_Prehistoric_Trunk_Full"
    },
    {
      "x": 0,
      "y": 18,
      "z": 0,
      "name": "Wood_Prehistoric_Trunk_Full"
    },
    {
      "x": 0,
      "y": 19,
      "z": 0,
      "name": "Wood_Prehistoric_Trunk_Full"
    },
    {
      "x": 0,
      "y": 20,
      "z": 0,
      "name": "Wood_Prehistoric_Trunk_Full"
    },
    {
      "x": 0,
      "y": 21,
      "z": 0,
      "name": "Wood_Prehistoric_Trunk_Full"
    },
    {
      "x": 0,
      "y": 22,
      "z": 0,
      "name": "Plant_Leaves_Palm_Oasis"
    },
    {
      "x": 0,
      "y": 23,
      "z": 0,
      "name": "Plant_Leaves_Palm_Oasis"
    },
    {
      "x": 0,
      "y": 24,
      "z": 0,
      "name": "Plant_Leaves_Palm_Oasis"
    },
    {
      "x": 0,
      "y": 25,
      "z": 0,
      "name": "Plant_Leaves_Palm_Oasis"
    },
    {
      "x": 0,
      "y": 26,
      "z": 0,
      "name": "Plant_Leaves_Palm_Oasis"
    },
    {
      "x": 0,
      "y": 27,
      "z": 0,
      "name": "Plant_Leaves_Palm_Oasis"
    },
    {
      "x": 0,
      "y": 28,
      "z": 0,
      "name": "Plant_Leaves_Palm_Oasis"
    },
    {
      "x": 0,
      "y": 29,
      "z": 0,
      "name": "Build_Tube_Green"
    },
    {
      "x": 0,
      "y": 0,
      "z": 1,
      "name": "Wood_Prehistoric_Trunk_Full"
    },
    {
      "x": 0,
      "y": 1,
      "z": 1,
      "name": "Wood_Prehistoric_Trunk_Full"
    },
    {
      "x": 0,
      "y": 2,
      "z": 1,
      "name": "Wood_Prehistoric_Trunk_Full"
    },
    {
      "x": 0,
      "y": 3,
      "z": 1,
      "name": "Wood_Prehistoric_Trunk_Full"
    },
    {
      "x": 0,
      "y": 4,
      "z": 1,
      "name": "Wood_Prehistoric_Trunk_Full"
    },
    {
      "x": 0,
      "y": 5,
      "z": 1,
      "name": "Wood_Prehistoric_Trunk_Full"
    },
    {
      "x": 0,
      "y": 6,
      "z": 1,
      "name": "Wood_Prehistoric_Trunk_Full"
    },
    {
      "x": 0,
      "y": 7,
      "z": 1,
      "name": "Wood_Prehistoric_Trunk_Full"
    },
    {
      "x": 0,
      "y": 8,
      "z": 1,
      "name": "Wood_Prehistoric_Trunk_Full"
    },
    {
      "x": 0,
      "y": 9,
      "z": 1,
      "name": "Wood_Prehistoric_Trunk_Full"
    },
    {
      "x": 0,
      "y": 10,
      "z": 1,
      "name": "Wood_Prehistoric_Trunk_Full"
    },
    {
      "x": 0,
      "y": 11,
      "z": 1,
      "name": "Wood_Prehistoric_Trunk_Full"
    },
    {
      "x": 0,
      "y": 12,
      "z": 1,
      "name": "Wood_Prehistoric_Trunk_Full"
    },
    {
      "x": 0,
      "y": 13,
      "z": 1,
      "name": "Wood_Prehistoric_Trunk_Full"
    },
    {
      "x": 0,
      "y": 14,
      "z": 1,
      "name": "Wood_Prehistoric_Trunk_Full"
    },
    {
      "x": 0,
      "y": 15,
      "z": 1,
      "name": "Wood_Prehistoric_Trunk_Full"
    },
    {
      "x": 0,
      "y": 16,
      "z": 1,
      "name": "Wood_Prehistoric_Trunk_Full"
    },
    {
      "x": 0,
      "y": 17,
      "z": 1,
      "name": "Wood_Prehistoric_Trunk_Full"
    },
    {
      "x": 0,
      "y": 18,
      "z": 1,
      "name": "Wood_Prehistoric_Trunk_Full"
    },
    {
      "x": 0,
      "y": 19,
      "z": 1,
      "name": "Wood_Prehistoric_Trunk_Full"
    },
    {
      "x": 0,
      "y": 20,
      "z": 1,
      "name": "Wood_Prehistoric_Trunk_Full"
    },
    {
      "x": 0,
      "y": 21,
      "z": 1,
      "name": "Wood_Prehistoric_Trunk_Full"
    },
    {
      "x": 0,
      "y": 22,
      "z": 1,
      "name": "Plant_Leaves_Palm_Oasis"
    },
    {
      "x": 0,
      "y": 23,
      "z": 1,
      "name": "Plant_Leaves_Palm_Oasis"
    },
    {
      "x": 0,
      "y": 24,
      "z": 1,
      "name": "Plant_Leaves_Palm_Oasis"
    },
    {
      "x": 0,
      "y": 25,
      "z": 1,
      "name": "Plant_Leaves_Palm_Oasis"
    },
    {
      "x": 0,
      "y": 26,
      "z": 1,
      "name": "Plant_Leaves_Palm_Oasis"
    },
    {
      "x": 0,
      "y": 27,
      "z": 1,
      "name": "Plant_Leaves_Palm_Oasis"
    },
    {
      "x": 0,
      "y": 28,
      "z": 1,
      "name": "Plant_Leaves_Palm_Oasis"
    },
    {
      "x": 0,
      "y": 29,
      "z": 1,
      "name": "Build_Tube_Green"
    },
    {
      "x": 0,
      "y": 20,
      "z": 2,
      "name": "Build_Tube_Lime",
      "rotation": 4
    },
    {
      "x": 0,
      "y": 21,
      "z": 2,
      "name": "Build_Tube_Green",
      "rotation": 4
    },
    {
      "x": 0,
      "y": 22,
      "z": 2,
      "name": "Build_Tube_Green",
      "rotation": 4
    },
    {
      "x": 0,
      "y": 23,
      "z": 2,
      "name": "Build_Tube_Green",
      "rotation": 4
    },
    {
      "x": 0,
      "y": 24,
      "z": 2,
      "name": "Build_Tube_Green",
      "rotation": 4
    },
    {
      "x": 0,
      "y": 25,
      "z": 2,
      "name": "Build_Tube_Green",
      "rotation": 4
    },
    {
      "x": 0,
      "y": 26,
      "z": 2,
      "name": "Build_Tube_Green",
      "rotation": 4
    },
    {
      "x": 0,
      "y": 27,
      "z": 2,
      "name": "Build_Tube_Green",
      "rotation": 4
    },
    {
      "x": 0,
      "y": 28,
      "z": 2,
      "name": "Build_Tube_Green",
      "rotation": 4
    },
    {
      "x": 1,
      "y": 19,
      "z": -1,
      "name": "Build_Tube_Lime",
      "rotation": 6
    },
    {
      "x": 1,
      "y": 21,
      "z": -1,
      "name": "Build_Tube_Green",
      "rotation": 6
    },
    {
      "x": 1,
      "y": 22,
      "z": -1,
      "name": "Build_Tube_Green",
      "rotation": 6
    },
    {
      "x": 1,
      "y": 23,
      "z": -1,
      "name": "Build_Tube_Green",
      "rotation": 6
    },
    {
      "x": 1,
      "y": 24,
      "z": -1,
      "name": "Build_Tube_Green",
      "rotation": 6
    },
    {
      "x": 1,
      "y": 25,
      "z": -1,
      "name": "Build_Tube_Green",
      "rotation": 6
    },
    {
      "x": 1,
      "y": 26,
      "z": -1,
      "name": "Build_Tube_Green",
      "rotation": 6
    },
    {
      "x": 1,
      "y": 27,
      "z": -1,
      "name": "Build_Tube_Green",
      "rotation": 6
    },
    {
      "x": 1,
      "y": 28,
      "z": -1,
      "name": "Build_Tube_Green",
      "rotation": 6
    },
    {
      "x": 1,
      "y": 0,
      "z": 0,
      "name": "Wood_Prehistoric_Trunk_Full"
    },
    {
      "x": 1,
      "y": 1,
      "z": 0,
      "name": "Wood_Prehistoric_Trunk_Full"
    },
    {
      "x": 1,
      "y": 2,
      "z": 0,
      "name": "Wood_Prehistoric_Trunk_Full"
    },
    {
      "x": 1,
      "y": 3,
      "z": 0,
      "name": "Wood_Prehistoric_Trunk_Full"
    },
    {
      "x": 1,
      "y": 4,
      "z": 0,
      "name": "Wood_Prehistoric_Trunk_Full"
    },
    {
      "x": 1,
      "y": 5,
      "z": 0,
      "name": "Wood_Prehistoric_Trunk_Full"
    },
    {
      "x": 1,
      "y": 6,
      "z": 0,
      "name": "Wood_Prehistoric_Trunk_Full"
    },
    {
      "x": 1,
      "y": 7,
      "z": 0,
      "name": "Wood_Prehistoric_Trunk_Full"
    },
    {
      "x": 1,
      "y": 8,
      "z": 0,
      "name": "Wood_Prehistoric_Trunk_Full"
    },
    {
      "x": 1,
      "y": 9,
      "z": 0,
      "name": "Wood_Prehistoric_Trunk_Full"
    },
    {
      "x": 1,
      "y": 10,
      "z": 0,
      "name": "Wood_Prehistoric_Trunk_Full"
    },
    {
      "x": 1,
      "y": 11,
      "z": 0,
      "name": "Wood_Prehistoric_Trunk_Full"
    },
    {
      "x": 1,
      "y": 12,
      "z": 0,
      "name": "Wood_Prehistoric_Trunk_Full"
    },
    {
      "x": 1,
      "y": 13,
      "z": 0,
      "name": "Wood_Prehistoric_Trunk_Full"
    },
    {
      "x": 1,
      "y": 14,
      "z": 0,
      "name": "Wood_Prehistoric_Trunk_Full"
    },
    {
      "x": 1,
      "y": 15,
      "z": 0,
      "name": "Wood_Prehistoric_Trunk_Full"
    },
    {
      "x": 1,
      "y": 16,
      "z": 0,
      "name": "Wood_Prehistoric_Trunk_Full"
    },
    {
      "x": 1,
      "y": 17,
      "z": 0,
      "name": "Wood_Prehistoric_Trunk_Full"
    },
    {
      "x": 1,
      "y": 18,
      "z": 0,
      "name": "Wood_Prehistoric_Trunk_Full"
    },
    {
      "x": 1,
      "y": 19,
      "z": 0,
      "name": "Wood_Prehistoric_Trunk_Full"
    },
    {
      "x": 1,
      "y": 20,
      "z": 0,
      "name": "Wood_Prehistoric_Trunk_Full"
    },
    {
      "x": 1,
      "y": 21,
      "z": 0,
      "name": "Wood_Prehistoric_Trunk_Full"
    },
    {
      "x": 1,
      "y": 22,
      "z": 0,
      "name": "Plant_Leaves_Palm_Oasis"
    },
    {
      "x": 1,
      "y": 23,
      "z": 0,
      "name": "Plant_Leaves_Palm_Oasis"
    },
    {
      "x": 1,
      "y": 24,
      "z": 0,
      "name": "Plant_Leaves_Palm_Oasis"
    },
    {
      "x": 1,
      "y": 25,
      "z": 0,
      "name": "Plant_Leaves_Palm_Oasis"
    },
    {
      "x": 1,
      "y": 26,
      "z": 0,
      "name": "Plant_Leaves_Palm_Oasis"
    },
    {
      "x": 1,
      "y": 27,
      "z": 0,
      "name": "Plant_Leaves_Palm_Oasis"
    },
    {
      "x": 1,
      "y": 28,
      "z": 0,
      "name": "Plant_Leaves_Palm_Oasis"
    },
    {
      "x": 1,
      "y": 29,
      "z": 0,
      "name": "Build_Tube_Green"
    },
    {
      "x": 1,
      "y": 0,
      "z": 1,
      "name": "Wood_Prehistoric_Trunk_Full"
    },
    {
      "x": 1,
      "y": 1,
      "z": 1,
      "name": "Wood_Prehistoric_Trunk_Full"
    },
    {
      "x": 1,
      "y": 2,
      "z": 1,
      "name": "Wood_Prehistoric_Trunk_Full"
    },
    {
      "x": 1,
      "y": 3,
      "z": 1,
      "name": "Wood_Prehistoric_Trunk_Full"
    },
    {
      "x": 1,
      "y": 4,
      "z": 1,
      "name": "Wood_Prehistoric_Trunk_Full"
    },
    {
      "x": 1,
      "y": 5,
      "z": 1,
      "name": "Wood_Prehistoric_Trunk_Full"
    },
    {
      "x": 1,
      "y": 6,
      "z": 1,
      "name": "Wood_Prehistoric_Trunk_Full"
    },
    {
      "x": 1,
      "y": 7,
      "z": 1,
      "name": "Wood_Prehistoric_Trunk_Full"
    },
    {
      "x": 1,
      "y": 8,
      "z": 1,
      "name": "Wood_Prehistoric_Trunk_Full"
    },
    {
      "x": 1,
      "y": 9,
      "z": 1,
      "name": "Wood_Prehistoric_Trunk_Full"
    },
    {
      "x": 1,
      "y": 10,
      "z": 1,
      "name": "Wood_Prehistoric_Trunk_Full"
    },
    {
      "x": 1,
      "y": 11,
      "z": 1,
      "name": "Wood_Prehistoric_Trunk_Full"
    },
    {
      "x": 1,
      "y": 12,
      "z": 1,
      "name": "Wood_Prehistoric_Trunk_Full"
    },
    {
      "x": 1,
      "y": 13,
      "z": 1,
      "name": "Wood_Prehistoric_Trunk_Full"
    },
    {
      "x": 1,
      "y": 14,
      "z": 1,
      "name": "Wood_Prehistoric_Trunk_Full"
    },
    {
      "x": 1,
      "y": 15,
      "z": 1,
      "name": "Wood_Prehistoric_Trunk_Full"
    },
    {
      "x": 1,
      "y": 16,
      "z": 1,
      "name": "Wood_Prehistoric_Trunk_Full"
    },
    {
      "x": 1,
      "y": 17,
      "z": 1,
      "name": "Wood_Prehistoric_Trunk_Full"
    },
    {
      "x": 1,
      "y": 18,
      "z": 1,
      "name": "Wood_Prehistoric_Trunk_Full"
    },
    {
      "x": 1,
      "y": 19,
      "z": 1,
      "name": "Wood_Prehistoric_Trunk_Full"
    },
    {
      "x": 1,
      "y": 20,
      "z": 1,
      "name": "Wood_Prehistoric_Trunk_Full"
    },
    {
      "x": 1,
      "y": 21,
      "z": 1,
      "name": "Wood_Prehistoric_Trunk_Full"
    },
    {
      "x": 1,
      "y": 22,
      "z": 1,
      "name": "Plant_Leaves_Palm_Oasis"
    },
    {
      "x": 1,
      "y": 23,
      "z": 1,
      "name": "Plant_Leaves_Palm_Oasis"
    },
    {
      "x": 1,
      "y": 24,
      "z": 1,
      "name": "Plant_Leaves_Palm_Oasis"
    },
    {
      "x": 1,
      "y": 25,
      "z": 1,
      "name": "Plant_Leaves_Palm_Oasis"
    },
    {
      "x": 1,
      "y": 26,
      "z": 1,
      "name": "Plant_Leaves_Palm_Oasis"
    },
    {
      "x": 1,
      "y": 27,
      "z": 1,
      "name": "Plant_Leaves_Palm_Oasis"
    },
    {
      "x": 1,
      "y": 28,
      "z": 1,
      "name": "Plant_Leaves_Palm_Oasis"
    },
    {
      "x": 1,
      "y": 29,
      "z": 1,
      "name": "Build_Tube_Green"
    },
    {
      "x": 1,
      "y": 19,
      "z": 2,
      "name": "Build_Tube_Lime",
      "rotation": 4
    },
    {
      "x": 1,
      "y": 21,
      "z": 2,
      "name": "Build_Tube_Lime",
      "rotation": 4
    },
    {
      "x": 1,
      "y": 22,
      "z": 2,
      "name": "Build_Tube_Green",
      "rotation": 4
    },
    {
      "x": 1,
      "y": 23,
      "z": 2,
      "name": "Build_Tube_Green",
      "rotation": 4
    },
    {
      "x": 1,
      "y": 24,
      "z": 2,
      "name": "Build_Tube_Green",
      "rotation": 4
    },
    {
      "x": 1,
      "y": 25,
      "z": 2,
      "name": "Build_Tube_Green",
      "rotation": 4
    },
    {
      "x": 1,
      "y": 26,
      "z": 2,
      "name": "Build_Tube_Green",
      "rotation": 4
    },
    {
      "x": 1,
      "y": 27,
      "z": 2,
      "name": "Build_Tube_Green",
      "rotation": 4
    },
    {
      "x": 1,
      "y": 28,
      "z": 2,
      "name": "Build_Tube_Green",
      "rotation": 4
    },
    {
      "x": 2,
      "y": 21,
      "z": 0,
      "name": "Build_Tube_Green",
      "rotation": 5
    },
    {
      "x": 2,
      "y": 22,
      "z": 0,
      "name": "Build_Tube_Green",
      "rotation": 5
    },
    {
      "x": 2,
      "y": 23,
      "z": 0,
      "name": "Build_Tube_Green",
      "rotation": 5
    },
    {
      "x": 2,
      "y": 24,
      "z": 0,
      "name": "Build_Tube_Green",
      "rotation": 5
    },
    {
      "x": 2,
      "y": 25,
      "z": 0,
      "name": "Build_Tube_Green",
      "rotation": 5
    },
    {
      "x": 2,
      "y": 26,
      "z": 0,
      "name": "Build_Tube_Green",
      "rotation": 5
    },
    {
      "x": 2,
      "y": 27,
      "z": 0,
      "name": "Build_Tube_Green",
      "rotation": 5
    },
    {
      "x": 2,
      "y": 28,
      "z": 0,
      "name": "Build_Tube_Green",
      "rotation": 5
    },
    {
      "x": 2,
      "y": 20,
      "z": 1,
      "name": "Build_Tube_Green",
      "rotation": 5
    },
    {
      "x": 2,
      "y": 21,
      "z": 1,
      "name": "Build_Tube_Lime",
      "rotation": 5
    },
    {
      "x": 2,
      "y": 22,
      "z": 1,
      "name": "Build_Tube_Green",
      "rotation": 5
    },
    {
      "x": 2,
      "y": 23,
      "z": 1,
      "name": "Build_Tube_Green",
      "rotation": 5
    },
    {
      "x": 2,
      "y": 24,
      "z": 1,
      "name": "Build_Tube_Green",
      "rotation": 5
    },
    {
      "x": 2,
      "y": 25,
      "z": 1,
      "name": "Build_Tube_Green",
      "rotation": 5
    },
    {
      "x": 2,
      "y": 26,
      "z": 1,
      "name": "Build_Tube_Green",
      "rotation": 5
    },
    {
      "x": 2,
      "y": 27,
      "z": 1,
      "name": "Build_Tube_Green",
      "rotation": 5
    },
    {
      "x": 2,
      "y": 28,
      "z": 1,
      "name": "Build_Tube_Green",
      "rotation": 5
    }
  ],
  "fluids": [
    {
      "x": -1,
      "y": 21,
      "z": 0,
      "name": "Empty",
      "level": 0
    },
    {
      "x": -1,
      "y": 22,
      "z": 0,
      "name": "Empty",
      "level": 0
    },
    {
      "x": -1,
      "y": 23,
      "z": 0,
      "name": "Empty",
      "level": 0
    },
    {
      "x": -1,
      "y": 24,
      "z": 0,
      "name": "Empty",
      "level": 0
    },
    {
      "x": -1,
      "y": 25,
      "z": 0,
      "name": "Empty",
      "level": 0
    },
    {
      "x": -1,
      "y": 26,
      "z": 0,
      "name": "Empty",
      "level": 0
    },
    {
      "x": -1,
      "y": 27,
      "z": 0,
      "name": "Empty",
      "level": 0
    },
    {
      "x": -1,
      "y": 28,
      "z": 0,
      "name": "Empty",
      "level": 0
    },
    {
      "x": -1,
      "y": 20,
      "z": 1,
      "name": "Empty",
      "level": 0
    },
    {
      "x": -1,
      "y": 21,
      "z": 1,
      "name": "Empty",
      "level": 0
    },
    {
      "x": -1,
      "y": 22,
      "z": 1,
      "name": "Empty",
      "level": 0
    },
    {
      "x": -1,
      "y": 23,
      "z": 1,
      "name": "Empty",
      "level": 0
    },
    {
      "x": -1,
      "y": 24,
      "z": 1,
      "name": "Empty",
      "level": 0
    },
    {
      "x": -1,
      "y": 25,
      "z": 1,
      "name": "Empty",
      "level": 0
    },
    {
      "x": -1,
      "y": 26,
      "z": 1,
      "name": "Empty",
      "level": 0
    },
    {
      "x": -1,
      "y": 27,
      "z": 1,
      "name": "Empty",
      "level": 0
    },
    {
      "x": -1,
      "y": 28,
      "z": 1,
      "name": "Empty",
      "level": 0
    },
    {
      "x": 0,
      "y": 20,
      "z": -1,
      "name": "Empty",
      "level": 0
    },
    {
      "x": 0,
      "y": 21,
      "z": -1,
      "name": "Empty",
      "level": 0
    },
    {
      "x": 0,
      "y": 22,
      "z": -1,
      "name": "Empty",
      "level": 0
    },
    {
      "x": 0,
      "y": 23,
      "z": -1,
      "name": "Empty",
      "level": 0
    },
    {
      "x": 0,
      "y": 24,
      "z": -1,
      "name": "Empty",
      "level": 0
    },
    {
      "x": 0,
      "y": 25,
      "z": -1,
      "name": "Empty",
      "level": 0
    },
    {
      "x": 0,
      "y": 26,
      "z": -1,
      "name": "Empty",
      "level": 0
    },
    {
      "x": 0,
      "y": 27,
      "z": -1,
      "name": "Empty",
      "level": 0
    },
    {
      "x": 0,
      "y": 28,
      "z": -1,
      "name": "Empty",
      "level": 0
    },
    {
      "x": 0,
      "y": 0,
      "z": 0,
      "name": "Empty",
      "level": 0
    },
    {
      "x": 0,
      "y": 1,
      "z": 0,
      "name": "Empty",
      "level": 0
    },
    {
      "x": 0,
      "y": 2,
      "z": 0,
      "name": "Empty",
      "level": 0
    },
    {
      "x": 0,
      "y": 3,
      "z": 0,
      "name": "Empty",
      "level": 0
    },
    {
      "x": 0,
      "y": 4,
      "z": 0,
      "name": "Empty",
      "level": 0
    },
    {
      "x": 0,
      "y": 5,
      "z": 0,
      "name": "Empty",
      "level": 0
    },
    {
      "x": 0,
      "y": 6,
      "z": 0,
      "name": "Empty",
      "level": 0
    },
    {
      "x": 0,
      "y": 7,
      "z": 0,
      "name": "Empty",
      "level": 0
    },
    {
      "x": 0,
      "y": 8,
      "z": 0,
      "name": "Empty",
      "level": 0
    },
    {
      "x": 0,
      "y": 9,
      "z": 0,
      "name": "Empty",
      "level": 0
    },
    {
      "x": 0,
      "y": 10,
      "z": 0,
      "name": "Empty",
      "level": 0
    },
    {
      "x": 0,
      "y": 11,
      "z": 0,
      "name": "Empty",
      "level": 0
    },
    {
      "x": 0,
      "y": 12,
      "z": 0,
      "name": "Empty",
      "level": 0
    },
    {
      "x": 0,
      "y": 13,
      "z": 0,
      "name": "Empty",
      "level": 0
    },
    {
      "x": 0,
      "y": 14,
      "z": 0,
      "name": "Empty",
      "level": 0
    },
    {
      "x": 0,
      "y": 15,
      "z": 0,
      "name": "Empty",
      "level": 0
    },
    {
      "x": 0,
      "y": 16,
      "z": 0,
      "name": "Empty",
      "level": 0
    },
    {
      "x": 0,
      "y": 17,
      "z": 0,
      "name": "Empty",
      "level": 0
    },
    {
      "x": 0,
      "y": 18,
      "z": 0,
      "name": "Empty",
      "level": 0
    },
    {
      "x": 0,
      "y": 19,
      "z": 0,
      "name": "Empty",
      "level": 0
    },
    {
      "x": 0,
      "y": 20,
      "z": 0,
      "name": "Empty",
      "level": 0
    },
    {
      "x": 0,
      "y": 21,
      "z": 0,
      "name": "Empty",
      "level": 0
    },
    {
      "x": 0,
      "y": 22,
      "z": 0,
      "name": "Empty",
      "level": 0
    },
    {
      "x": 0,
      "y": 23,
      "z": 0,
      "name": "Empty",
      "level": 0
    },
    {
      "x": 0,
      "y": 24,
      "z": 0,
      "name": "Empty",
      "level": 0
    },
    {
      "x": 0,
      "y": 25,
      "z": 0,
      "name": "Empty",
      "level": 0
    },
    {
      "x": 0,
      "y": 26,
      "z": 0,
      "name": "Empty",
      "level": 0
    },
    {
      "x": 0,
      "y": 27,
      "z": 0,
      "name": "Empty",
      "level": 0
    },
    {
      "x": 0,
      "y": 28,
      "z": 0,
      "name": "Empty",
      "level": 0
    },
    {
      "x": 0,
      "y": 29,
      "z": 0,
      "name": "Empty",
      "level": 0
    },
    {
      "x": 0,
      "y": 0,
      "z": 1,
      "name": "Empty",
      "level": 0
    },
    {
      "x": 0,
      "y": 1,
      "z": 1,
      "name": "Empty",
      "level": 0
    },
    {
      "x": 0,
      "y": 2,
      "z": 1,
      "name": "Empty",
      "level": 0
    },
    {
      "x": 0,
      "y": 3,
      "z": 1,
      "name": "Empty",
      "level": 0
    },
    {
      "x": 0,
      "y": 4,
      "z": 1,
      "name": "Empty",
      "level": 0
    },
    {
      "x": 0,
      "y": 5,
      "z": 1,
      "name": "Empty",
      "level": 0
    },
    {
      "x": 0,
      "y": 6,
      "z": 1,
      "name": "Empty",
      "level": 0
    },
    {
      "x": 0,
      "y": 7,
      "z": 1,
      "name": "Empty",
      "level": 0
    },
    {
      "x": 0,
      "y": 8,
      "z": 1,
      "name": "Empty",
      "level": 0
    },
    {
      "x": 0,
      "y": 9,
      "z": 1,
      "name": "Empty",
      "level": 0
    },
    {
      "x": 0,
      "y": 10,
      "z": 1,
      "name": "Empty",
      "level": 0
    },
    {
      "x": 0,
      "y": 11,
      "z": 1,
      "name": "Empty",
      "level": 0
    },
    {
      "x": 0,
      "y": 12,
      "z": 1,
      "name": "Empty",
      "level": 0
    },
    {
      "x": 0,
      "y": 13,
      "z": 1,
      "name": "Empty",
      "level": 0
    },
    {
      "x": 0,
      "y": 14,
      "z": 1,
      "name": "Empty",
      "level": 0
    },
    {
      "x": 0,
      "y": 15,
      "z": 1,
      "name": "Empty",
      "level": 0
    },
    {
      "x": 0,
      "y": 16,
      "z": 1,
      "name": "Empty",
      "level": 0
    },
    {
      "x": 0,
      "y": 17,
      "z": 1,
      "name": "Empty",
      "level": 0
    },
    {
      "x": 0,
      "y": 18,
      "z": 1,
      "name": "Empty",
      "level": 0
    },
    {
      "x": 0,
      "y": 19,
      "z": 1,
      "name": "Empty",
      "level": 0
    },
    {
      "x": 0,
      "y": 20,
      "z": 1,
      "name": "Empty",
      "level": 0
    },
    {
      "x": 0,
      "y": 21,
      "z": 1,
      "name": "Empty",
      "level": 0
    },
    {
      "x": 0,
      "y": 22,
      "z": 1,
      "name": "Empty",
      "level": 0
    },
    {
      "x": 0,
      "y": 23,
      "z": 1,
      "name": "Empty",
      "level": 0
    },
    {
      "x": 0,
      "y": 24,
      "z": 1,
      "name": "Empty",
      "level": 0
    },
    {
      "x": 0,
      "y": 25,
      "z": 1,
      "name": "Empty",
      "level": 0
    },
    {
      "x": 0,
      "y": 26,
      "z": 1,
      "name": "Empty",
      "level": 0
    },
    {
      "x": 0,
      "y": 27,
      "z": 1,
      "name": "Empty",
      "level": 0
    },
    {
      "x": 0,
      "y": 28,
      "z": 1,
      "name": "Empty",
      "level": 0
    },
    {
      "x": 0,
      "y": 29,
      "z": 1,
      "name": "Empty",
      "level": 0
    },
    {
      "x": 0,
      "y": 20,
      "z": 2,
      "name": "Empty",
      "level": 0
    },
    {
      "x": 0,
      "y": 21,
      "z": 2,
      "name": "Empty",
      "level": 0
    },
    {
      "x": 0,
      "y": 22,
      "z": 2,
      "name": "Empty",
      "level": 0
    },
    {
      "x": 0,
      "y": 23,
      "z": 2,
      "name": "Empty",
      "level": 0
    },
    {
      "x": 0,
      "y": 24,
      "z": 2,
      "name": "Empty",
      "level": 0
    },
    {
      "x": 0,
      "y": 25,
      "z": 2,
      "name": "Empty",
      "level": 0
    },
    {
      "x": 0,
      "y": 26,
      "z": 2,
      "name": "Empty",
      "level": 0
    },
    {
      "x": 0,
      "y": 27,
      "z": 2,
      "name": "Empty",
      "level": 0
    },
    {
      "x": 0,
      "y": 28,
      "z": 2,
      "name": "Empty",
      "level": 0
    },
    {
      "x": 1,
      "y": 19,
      "z": -1,
      "name": "Empty",
      "level": 0
    },
    {
      "x": 1,
      "y": 21,
      "z": -1,
      "name": "Empty",
      "level": 0
    },
    {
      "x": 1,
      "y": 22,
      "z": -1,
      "name": "Empty",
      "level": 0
    },
    {
      "x": 1,
      "y": 23,
      "z": -1,
      "name": "Empty",
      "level": 0
    },
    {
      "x": 1,
      "y": 24,
      "z": -1,
      "name": "Empty",
      "level": 0
    },
    {
      "x": 1,
      "y": 25,
      "z": -1,
      "name": "Empty",
      "level": 0
    },
    {
      "x": 1,
      "y": 26,
      "z": -1,
      "name": "Empty",
      "level": 0
    },
    {
      "x": 1,
      "y": 27,
      "z": -1,
      "name": "Empty",
      "level": 0
    },
    {
      "x": 1,
      "y": 28,
      "z": -1,
      "name": "Empty",
      "level": 0
    },
    {
      "x": 1,
      "y": 0,
      "z": 0,
      "name": "Empty",
      "level": 0
    },
    {
      "x": 1,
      "y": 1,
      "z": 0,
      "name": "Empty",
      "level": 0
    },
    {
      "x": 1,
      "y": 2,
      "z": 0,
      "name": "Empty",
      "level": 0
    },
    {
      "x": 1,
      "y": 3,
      "z": 0,
      "name": "Empty",
      "level": 0
    },
    {
      "x": 1,
      "y": 4,
      "z": 0,
      "name": "Empty",
      "level": 0
    },
    {
      "x": 1,
      "y": 5,
      "z": 0,
      "name": "Empty",
      "level": 0
    },
    {
      "x": 1,
      "y": 6,
      "z": 0,
      "name": "Empty",
      "level": 0
    },
    {
      "x": 1,
      "y": 7,
      "z": 0,
      "name": "Empty",
      "level": 0
    },
    {
      "x": 1,
      "y": 8,
      "z": 0,
      "name": "Empty",
      "level": 0
    },
    {
      "x": 1,
      "y": 9,
      "z": 0,
      "name": "Empty",
      "level": 0
    },
    {
      "x": 1,
      "y": 10,
      "z": 0,
      "name": "Empty",
      "level": 0
    },
    {
      "x": 1,
      "y": 11,
      "z": 0,
      "name": "Empty",
      "level": 0
    },
    {
      "x": 1,
      "y": 12,
      "z": 0,
      "name": "Empty",
      "level": 0
    },
    {
      "x": 1,
      "y": 13,
      "z": 0,
      "name": "Empty",
      "level": 0
    },
    {
      "x": 1,
      "y": 14,
      "z": 0,
      "name": "Empty",
      "level": 0
    },
    {
      "x": 1,
      "y": 15,
      "z": 0,
      "name": "Empty",
      "level": 0
    },
    {
      "x": 1,
      "y": 16,
      "z": 0,
      "name": "Empty",
      "level": 0
    },
    {
      "x": 1,
      "y": 17,
      "z": 0,
      "name": "Empty",
      "level": 0
    },
    {
      "x": 1,
      "y": 18,
      "z": 0,
      "name": "Empty",
      "level": 0
    },
    {
      "x": 1,
      "y": 19,
      "z": 0,
      "name": "Empty",
      "level": 0
    },
    {
      "x": 1,
      "y": 20,
      "z": 0,
      "name": "Empty",
      "level": 0
    },
    {
      "x": 1,
      "y": 21,
      "z": 0,
      "name": "Empty",
      "level": 0
    },
    {
      "x": 1,
      "y": 22,
      "z": 0,
      "name": "Empty",
      "level": 0
    },
    {
      "x": 1,
      "y": 23,
      "z": 0,
      "name": "Empty",
      "level": 0
    },
    {
      "x": 1,
      "y": 24,
      "z": 0,
      "name": "Empty",
      "level": 0
    },
    {
      "x": 1,
      "y": 25,
      "z": 0,
      "name": "Empty",
      "level": 0
    },
    {
      "x": 1,
      "y": 26,
      "z": 0,
      "name": "Empty",
      "level": 0
    },
    {
      "x": 1,
      "y": 27,
      "z": 0,
      "name": "Empty",
      "level": 0
    },
    {
      "x": 1,
      "y": 28,
      "z": 0,
      "name": "Empty",
      "level": 0
    },
    {
      "x": 1,
      "y": 29,
      "z": 0,
      "name": "Empty",
      "level": 0
    },
    {
      "x": 1,
      "y": 0,
      "z": 1,
      "name": "Empty",
      "level": 0
    },
    {
      "x": 1,
      "y": 1,
      "z": 1,
      "name": "Empty",
      "level": 0
    },
    {
      "x": 1,
      "y": 2,
      "z": 1,
      "name": "Empty",
      "level": 0
    },
    {
      "x": 1,
      "y": 3,
      "z": 1,
      "name": "Empty",
      "level": 0
    },
    {
      "x": 1,
      "y": 4,
      "z": 1,
      "name": "Empty",
      "level": 0
    },
    {
      "x": 1,
      "y": 5,
      "z": 1,
      "name": "Empty",
      "level": 0
    },
    {
      "x": 1,
      "y": 6,
      "z": 1,
      "name": "Empty",
      "level": 0
    },
    {
      "x": 1,
      "y": 7,
      "z": 1,
      "name": "Empty",
      "level": 0
    },
    {
      "x": 1,
      "y": 8,
      "z": 1,
      "name": "Empty",
      "level": 0
    },
    {
      "x": 1,
      "y": 9,
      "z": 1,
      "name": "Empty",
      "level": 0
    },
    {
      "x": 1,
      "y": 10,
      "z": 1,
      "name": "Empty",
      "level": 0
    },
    {
      "x": 1,
      "y": 11,
      "z": 1,
      "name": "Empty",
      "level": 0
    },
    {
      "x": 1,
      "y": 12,
      "z": 1,
      "name": "Empty",
      "level": 0
    },
    {
      "x": 1,
      "y": 13,
      "z": 1,
      "name": "Empty",
      "level": 0
    },
    {
      "x": 1,
      "y": 14,
      "z": 1,
      "name": "Empty",
      "level": 0
    },
    {
      "x": 1,
      "y": 15,
      "z": 1,
      "name": "Empty",
      "level": 0
    },
    {
      "x": 1,
      "y": 16,
      "z": 1,
      "name": "Empty",
      "level": 0
    },
    {
      "x": 1,
      "y": 17,
      "z": 1,
      "name": "Empty",
      "level": 0
    },
    {
      "x": 1,
      "y": 18,
      "z": 1,
      "name": "Empty",
      "level": 0
    },
    {
      "x": 1,
      "y": 19,
      "z": 1,
      "name": "Empty",
      "level": 0
    },
    {
      "x": 1,
      "y": 20,
      "z": 1,
      "name": "Empty",
      "level": 0
    },
    {
      "x": 1,
      "y": 21,
      "z": 1,
      "name": "Empty",
      "level": 0
    },
    {
      "x": 1,
      "y": 22,
      "z": 1,
      "name": "Empty",
      "level": 0
    },
    {
      "x": 1,
      "y": 23,
      "z": 1,
      "name": "Empty",
      "level": 0
    },
    {
      "x": 1,
      "y": 24,
      "z": 1,
      "name": "Empty",
      "level": 0
    },
    {
      "x": 1,
      "y": 25,
      "z": 1,
      "name": "Empty",
      "level": 0
    },
    {
      "x": 1,
      "y": 26,
      "z": 1,
      "name": "Empty",
      "level": 0
    },
    {
      "x": 1,
      "y": 27,
      "z": 1,
      "name": "Empty",
      "level": 0
    },
    {
      "x": 1,
      "y": 28,
      "z": 1,
      "name": "Empty",
      "level": 0
    },
    {
      "x": 1,
      "y": 29,
      "z": 1,
      "name": "Empty",
      "level": 0
    },
    {
      "x": 1,
      "y": 19,
      "z": 2,
      "name": "Empty",
      "level": 0
    },
    {
      "x": 1,
      "y": 21,
      "z": 2,
      "name": "Empty",
      "level": 0
    },
    {
      "x": 1,
      "y": 22,
      "z": 2,
      "name": "Empty",
      "level": 0
    },
    {
      "x": 1,
      "y": 23,
      "z": 2,
      "name": "Empty",
      "level": 0
    },
    {
      "x": 1,
      "y": 24,
      "z": 2,
      "name": "Empty",
      "level": 0
    },
    {
      "x": 1,
      "y": 25,
      "z": 2,
      "name": "Empty",
      "level": 0
    },
    {
      "x": 1,
      "y": 26,
      "z": 2,
      "name": "Empty",
      "level": 0
    },
    {
      "x": 1,
      "y": 27,
      "z": 2,
      "name": "Empty",
      "level": 0
    },
    {
      "x": 1,
      "y": 28,
      "z": 2,
      "name": "Empty",
      "level": 0
    },
    {
      "x": 2,
      "y": 21,
      "z": 0,
      "name": "Empty",
      "level": 0
    },
    {
      "x": 2,
      "y": 22,
      "z": 0,
      "name": "Empty",
      "level": 0
    },
    {
      "x": 2,
      "y": 23,
      "z": 0,
      "name": "Empty",
      "level": 0
    },
    {
      "x": 2,
      "y": 24,
      "z": 0,
      "name": "Empty",
      "level": 0
    },
    {
      "x": 2,
      "y": 25,
      "z": 0,
      "name": "Empty",
      "level": 0
    },
    {
      "x": 2,
      "y": 26,
      "z": 0,
      "name": "Empty",
      "level": 0
    },
    {
      "x": 2,
      "y": 27,
      "z": 0,
      "name": "Empty",
      "level": 0
    },
    {
      "x": 2,
      "y": 28,
      "z": 0,
      "name": "Empty",
      "level": 0
    },
    {
      "x": 2,
      "y": 20,
      "z": 1,
      "name": "Empty",
      "level": 0
    },
    {
      "x": 2,
      "y": 21,
      "z": 1,
      "name": "Empty",
      "level": 0
    },
    {
      "x": 2,
      "y": 22,
      "z": 1,
      "name": "Empty",
      "level": 0
    },
    {
      "x": 2,
      "y": 23,
      "z": 1,
      "name": "Empty",
      "level": 0
    },
    {
      "x": 2,
      "y": 24,
      "z": 1,
      "name": "Empty",
      "level": 0
    },
    {
      "x": 2,
      "y": 25,
      "z": 1,
      "name": "Empty",
      "level": 0
    },
    {
      "x": 2,
      "y": 26,
      "z": 1,
      "name": "Empty",
      "level": 0
    },
    {
      "x": 2,
      "y": 27,
      "z": 1,
      "name": "Empty",
      "level": 0
    },
    {
      "x": 2,
      "y": 28,
      "z": 1,
      "name": "Empty",
      "level": 0
    }
  ]
}