{
  "version": 8,
  "blockIdVersion": 11,
  "anchorX": 1,
  "anchorY": 22,
  "anchorZ": 2,
  "blocks": [
    {
      "x": -32,
      "y": 70,
      "z": 2,
      "name": "Plant_Leaves_Jungle_Max_Support"
    },
    {
      "x": -32,
      "y": 69,
      "z": 3,
      "name": "Plant_Leaves_Jungle_Max_Support"
    },
    {
      "x": -32,
      "y": 70,
      "z": 3,
      "name": "Plant_Leaves_Jungle_Max_Support"
    },
    {
      "x": -31,
      "y": 71,
      "z": -4,
      "name": "Plant_Leaves_Jungle_Max_Support"
    },
    {
      "x": -31,
      "y": 72,
      "z": -4,
      "name": "Plant_Leaves_Jungle_Max_Support"
    },
    {
      "x": -31,
      "y": 73,
      "z": -4,
      "name": "Plant_Leaves_Jungle_Max_Support"
    },
    {
      "x": -31,
      "y": 72,
      "z": -3,
      "name": "Plant_Leaves_Jungle_Max_Support"
    },
    {
      "x": -31,
      "y": 71,
      "z": 0,
      "name": "Plant_Leaves_Jungle_Max_Support"
    },
    {
      "x": -31,
      "y": 69,
      "z": 1,
      "name": "Plant_Leaves_Jungle_Max_Support"
    },
    {
      "x": -31,
      "y": 70,
      "z": 1,
      "name": "Plant_Leaves_Jungle_Max_Support"
    },
    {
      "x": -31,
      "y": 68,
      "z": 2,
      "name": "Plant_Leaves_Jungle_Max_Support"
    },
    {
      "x": -31,
      "y": 69,
      "z": 2,
      "name": "Plant_Leaves_Jungle_Max_Support"
    },
    {
      "x": -31,
      "y": 70,
      "z": 2,
      "name": "Plant_Leaves_Jungle_Max_Support"
    },
    {
      "x": -31,
      "y": 71,
      "z": 2,
      "name": "Plant_Leaves_Jungle_Max_Support"
    },
    {
      "x": -31,
      "y": 72,
      "z": 2,
      "name": "Plant_Leaves_Jungle_Max_Support"
    },
    {
      "x": -31,
      "y": 68,
      "z": 3,
      "name": "Plant_Leaves_Jungle_Max_Support"
    },
    {
      "x": -31,
      "y": 70,
      "z": 3,
      "name": "Plant_Leaves_Jungle_Max_Support"
    },
    {
      "x": -31,
      "y": 71,
      "z": 3,
      "name": "Plant_Leaves_Jungle_Max_Support"
    },
    {
      "x": -31,
      "y": 69,
      "z": 4,
      "name": "Plant_Leaves_Jungle_Max_Support"
    },
    {
      "x": -31,
      "y": 70,
      "z": 4,
      "name": "Plant_Leaves_Jungle_Max_Support"
    },
    {
      "x": -31,
      "y": 71,
      "z": 4,
      "name": "Plant_Leaves_Jungle_Max_Support"
    },
    {
      "x": -30,
      "y": 65,
      "z": -11,
      "name": "Plant_Leaves_Jungle_Max_Support"
    },
    {
      "x": -30,
      "y": 64,
      "z": -10,
      "name": "Plant_Leaves_Jungle_Max_Support"
    },
    {
      "x": -30,
      "y": 66,
      "z": -10,
      "name": "Plant_Leaves_Jungle_Max_Support"
    },
    {
      "x": -30,
      "y": 65,
      "z": -9,
      "name": "Plant_Leaves_Jungle_Max_Support"
    },
    {
      "x": -30,
      "y": 71,
      "z": -5,
      "name": "Plant_Leaves_Jungle_Max_Support"
    },
    {
      "x": -30,
      "y": 70,
      "z": -4,
      "name": "Plant_Leaves_Jungle_Max_Support"
    },
    {
      "x": -30,
      "y": 71,
      "z": -4,
      "name": "Plant_Leaves_Jungle_Max_Support"
    },
    {
      "x": -30,
      "y": 74,
      "z": -4,
      "name": "Plant_Leaves_Jungle_Max_Support"
    },
    {
      "x": -30,
      "y": 70,
      "z": -3,
      "name": "Plant_Leaves_Jungle_Max_Support"
    },
    {
      "x": -30,
      "y": 73,
      "z": -3,
      "name": "Plant_Leaves_Jungle_Max_Support"
    },
    {
      "x": -30,
      "y": 69,
      "z": -2,
      "name": "Plant_Leaves_Jungle_Max_Support",
      "support": 15
    },
    {
      "x": -30,
      "y": 70,
      "z": -2,
      "name": "Plant_Leaves_Jungle_Max_Support"
    },
    {
      "x": -30,
      "y": 71,
      "z": -2,
      "name": "Plant_Leaves_Jungle_Max_Support"
    },
    {
      "x": -30,
      "y": 72,
      "z": -2,
      "name": "Plant_Leaves_Jungle_Max_Support"
    },
    {
      "x": -30,
      "y": 74,
      "z": -2,
      "name": "Plant_Leaves_Jungle_Max_Support"
    },
    {
      "x": -30,
      "y": 69,
      "z": -1,
      "name": "Plant_Leaves_Jungle_Max_Support"
    },
    {
      "x": -30,
      "y": 68,
      "z": 0,
      "name": "Plant_Leaves_Jungle_Max_Support"
    },
    {
      "x": -30,
      "y": 69,
      "z": 0,
      "name": "Plant_Leaves_Jungle_Max_Support"
    },
    {
      "x": -30,
      "y": 71,
      "z": 0,
      "name": "Plant_Leaves_Jungle_Max_Support"
    },
    {
      "x": -30,
      "y": 72,
      "z": 0,
      "name": "Plant_Leaves_Jungle_Max_Support"
    },
    {
      "x": -30,
      "y": 67,
      "z": 1,
      "name": "Plant_Leaves_Jungle_Max_Support"
    },
    {
      "x": -30,
      "y": 69,
      "z": 1,
      "name": "Plant_Leaves_Jungle_Max_Support"
    },
    {
      "x": -30,
      "y": 70,
      "z": 1,
      "name": "Plant_Leaves_Jungle_Max_Support"
    },
    {
      "x": -30,
      "y": 73,
      "z": 1,
      "name": "Plant_Leaves_Jungle_Max_Support"
    },
    {
      "x": -30,
      "y": 67,
      "z": 2,
      "name": "Plant_Leaves_Jungle_Max_Support"
    },
    {
      "x": -30,
      "y": 68,
      "z": 2,
      "name": "Plant_Leaves_Jungle_Max_Support"
    },
    {
      "x": -30,
      "y": 69,
      "z": 2,
      "name": "Plant_Leaves_Jungle_Max_Support"
    },
    {
      "x": -30,
      "y": 70,
      "z": 2,
      "name": "Plant_Leaves_Jungle_Max_Support"
    },
    {
      "x": -30,
      "y": 72,
      "z": 2,
      "name": "Plant_Leaves_Jungle_Max_Support"
    },
    {
      "x": -30,
      "y": 73,
      "z": 2,
      "name": "Plant_Leaves_Jungle_Max_Support"
    },
    {
      "x": -30,
      "y": 68,
      "z": 3,
      "name": "Plant_Leaves_Jungle_Max_Support"
    },
    {
      "x": -30,
      "y": 70,
      "z": 3,
      "name": "Plant_Leaves_Jungle_Max_Support"
    },
    {
      "x": -30,
      "y": 71,
      "z": 3,
      "name": "Plant_Leaves_Jungle_Max_Support"
    },
    {
      "x": -30,
      "y": 72,
      "z": 3,
      "name": "Plant_Leaves_Jungle_Max_Support"
    },
    {
      "x": -30,
      "y": 73,
      "z": 3,
      "name": "Plant_Leaves_Jungle_Max_Support"
    },
    {
      "x": -30,
      "y": 70,
      "z": 4,
      "name": "Plant_Leaves_Jungle_Max_Support"
    },
    {
      "x": -30,
      "y": 71,
      "z": 4,
      "name": "Plant_Leaves_Jungle_Max_Support"
    },
    {
      "x": -30,
      "y": 72,
      "z": 4,
      "name": "Plant_Leaves_Jungle_Max_Support"
    },
    {
      "x": -30,
      "y": 69,
      "z": 5,
      "name": "Plant_Leaves_Jungle_Max_Support"
    },
    {
      "x": -29,
      "y": 64,
      "z": -14,
      "name": "Plant_Leaves_Jungle_Max_Support"
    },
    {
      "x": -29,
      "y": 64,
      "z": -13,
      "name": "Plant_Leaves_Jungle_Max_Support"
    },
    {
      "x": -29,
      "y": 65,
      "z": -12,
      "name": "Plant_Leaves_Jungle_Max_Support"
    },
    {
      "x": -29,
      "y": 66,
      "z": -12,
      "name": "Plant_Leaves_Jungle_Max_Support"
    },
    {
      "x": -29,
      "y": 67,
      "z": -12,
      "name": "Plant_Leaves_Jungle_Max_Support"
    },
    {
      "x": -29,
      "y": 68,
      "z": -12,
      "name": "Plant_Leaves_Jungle_Max_Support"
    },
    {
      "x": -29,
      "y": 64,
      "z": -11,
      "name": "Plant_Leaves_Jungle_Max_Support"
    },
    {
      "x": -29,
      "y": 65,
      "z": -11,
      "name": "Plant_Leaves_Jungle_Max_Support"
    },
    {
      "x": -29,
      "y": 66,
      "z": -11,
      "name": "Plant_Leaves_Jungle_Max_Support"
    },
    {
      "x": -29,
      "y": 67,
      "z": -11,
      "name": "Plant_Leaves_Jungle_Max_Support"
    },
    {
      "x": -29,
      "y": 68,
      "z": -11,
      "name": "Plant_Leaves_Jungle_Max_Support"
    },
    {
      "x": -29,
      "y": 63,
      "z": -10,
      "name": "Plant_Leaves_Jungle_Max_Support"
    },
    {
      "x": -29,
      "y": 64,
      "z": -10,
      "name": "Plant_Leaves_Jungle_Max_Support"
    },
    {
      "x": -29,
      "y": 65,
      "z": -10,
      "name": "Plant_Leaves_Jungle_Max_Support"
    },
    {
      "x": -29,
      "y": 66,
      "z": -10,
      "name": "Plant_Leaves_Jungle_Max_Support"
    },
    {
      "x": -29,
      "y": 67,
      "z": -10,
      "name": "Plant_Leaves_Jungle_Max_Support"
    },
    {
      "x": -29,
      "y": 63,
      "z": -9,
      "name": "Plant_Leaves_Jungle_Max_Support",
      "support": 15
    },
    {
      "x": -29,
      "y": 64,
      "z": -9,
      "name": "Plant_Leaves_Jungle_Max_Support"
    },
    {
      "x": -29,
      "y": 65,
      "z": -9,
      "name": "Plant_Leaves_Jungle_Max_Support"
    },
    {
      "x": -29,
      "y": 66,
      "z": -9,
      "name": "Plant_Leaves_Jungle_Max_Support"
    },
    {
      "x": -29,
      "y": 61,
      "z": -8,
      "name": "Plant_Leaves_Jungle_Max_Support",
      "support": 15
    },
    {
      "x": -29,
      "y": 62,
      "z": -8,
      "name": "Plant_Leaves_Jungle_Max_Support",
      "support": 15
    },
    {
      "x": -29,
      "y": 63,
      "z": -8,
      "name": "Plant_Leaves_Jungle_Max_Support",
      "support": 15
    },
    {
      "x": -29,
      "y": 64,
      "z": -8,
      "name": "Plant_Leaves_Jungle_Max_Support",
      "support": 15
    },
    {
      "x": -29,
      "y": 65,
      "z": -8,
      "name": "Plant_Leaves_Jungle_Max_Support"
    },
    {
      "x": -29,
      "y": 66,
      "z": -8,
      "name": "Plant_Leaves_Jungle_Max_Support"
    },
    {
      "x": -29,
      "y": 65,
      "z": -7,
      "name": "Plant_Leaves_Jungle_Max_Support"
    },
    {
      "x": -29,
      "y": 71,
      "z": -6,
      "name": "Plant_Leaves_Jungle_Max_Support"
    },
    {
      "x": -29,
      "y": 72,
      "z": -6,
      "name": "Plant_Leaves_Jungle_Max_Support"
    },
    {
      "x": -29,
      "y": 70,
      "z": -5,
      "name": "Plant_Leaves_Jungle_Max_Support"
    },
    {
      "x": -29,
      "y": 73,
      "z": -5,
      "name": "Plant_Leaves_Jungle_Max_Support"
    },
    {
      "x": -29,
      "y": 69,
      "z": -4,
      "name": "Plant_Leaves_Jungle_Max_Support"
    },
    {
      "x": -29,
      "y": 70,
      "z": -4,
      "name": "Plant_Leaves_Jungle_Max_Support"
    },
    {
      "x": -29,
      "y": 72,
      "z": -4,
      "name": "Plant_Leaves_Jungle_Max_Support"
    },
    {
      "x": -29,
      "y": 73,
      "z": -4,
      "name": "Plant_Leaves_Jungle_Max_Support"
    },
    {
      "x": -29,
      "y": 74,
      "z": -4,
      "name": "Plant_Leaves_Jungle_Max_Support"
    },
    {
      "x": -29,
      "y": 75,
      "z": -4,
      "name": "Plant_Leaves_Jungle_Max_Support"
    },
    {
      "x": -29,
      "y": 69,
      "z": -3,
      "name": "Plant_Leaves_Jungle_Max_Support",
      "support": 15
    },
    {
      "x": -29,
      "y": 70,
      "z": -3,
      "name": "Plant_Leaves_Jungle_Max_Support"
    },
    {
      "x": -29,
      "y": 71,
      "z": -3,
      "name": "Plant_Leaves_Jungle_Max_Support"
    },
    {
      "x": -29,
      "y": 74,
      "z": -3,
      "name": "Plant_Leaves_Jungle_Max_Support"
    },
    {
      "x": -29,
      "y": 66,
      "z": -2,
      "name": "Plant_Leaves_Jungle_Max_Support",
      "support": 15
    },
    {
      "x": -29,
      "y": 67,
      "z": -2,
      "name": "Plant_Leaves_Jungle_Max_Support",
      "support": 15
    },
    {
      "x": -29,
      "y": 68,
      "z": -2,
      "name": "Plant_Leaves_Jungle_Max_Support",
      "support": 15
    },
    {
      "x": -29,
      "y": 69,
      "z": -2,
      "name": "Plant_Leaves_Jungle_Max_Support",
      "support": 15
    },
    {
      "x": -29,
      "y": 70,
      "z": -2,
      "name": "Plant_Leaves_Jungle_Max_Support"
    },
    {
      "x": -29,
      "y": 71,
      "z": -2,
      "name": "Plant_Leaves_Jungle_Max_Support"
    },
    {
      "x": -29,
      "y": 75,
      "z": -2,
      "name": "Plant_Leaves_Jungle_Max_Support"
    },
    {
      "x": -29,
      "y": 68,
      "z": -1,
      "name": "Plant_Leaves_Jungle_Max_Support",
      "support": 15
    },
    {
      "x": -29,
      "y": 69,
      "z": -1,
      "name": "Plant_Leaves_Jungle_Max_Support"
    },
    {
      "x": -29,
      "y": 70,
      "z": -1,
      "name": "Plant_Leaves_Jungle_Max_Support"
    },
    {
      "x": -29,
      "y": 71,
      "z": -1,
      "name": "Plant_Leaves_Jungle_Max_Support"
    },
    {
      "x": -29,
      "y": 72,
      "z": -1,
      "name": "Plant_Leaves_Jungle_Max_Support"
    },
    {
      "x": -29,
      "y": 73,
      "z": -1,
      "name": "Plant_Leaves_Jungle_Max_Support"
    },
    {
      "x": -29,
      "y": 74,
      "z": -1,
      "name": "Plant_Leaves_Jungle_Max_Support"
    },
    {
      "x": -29,
      "y": 70,
      "z": 0,
      "name": "Plant_Leaves_Jungle_Max_Support"
    },
    {
      "x": -29,
      "y": 72,
      "z": 0,
      "name": "Plant_Leaves_Jungle_Max_Support"
    },
    {
      "x": -29,
      "y": 73,
      "z": 0,
      "name": "Plant_Leaves_Jungle_Max_Support"
    },
    {
      "x": -29,
      "y": 70,
      "z": 1,
      "name": "Plant_Leaves_Jungle_Max_Support"
    },
    {
      "x": -29,
      "y": 71,
      "z": 1,
      "name": "Plant_Leaves_Jungle_Max_Support"
    },
    {
      "x": -29,
      "y": 72,
      "z": 1,
      "name": "Plant_Leaves_Jungle_Max_Support"
    },
    {
      "x": -29,
      "y": 73,
      "z": 1,
      "name": "Plant_Leaves_Jungle_Max_Support"
    },
    {
      "x": -29,
      "y": 74,
      "z": 1,
      "name": "Plant_Leaves_Jungle_Max_Support"
    },
    {
      "x": -29,
      "y": 68,
      "z": 2,
      "name": "Plant_Leaves_Jungle_Max_Support"
    },
    {
      "x": -29,
      "y": 69,
      "z": 2,
      "name": "Plant_Leaves_Jungle_Max_Support"
    },
    {
      "x": -29,
      "y": 70,
      "z": 2,
      "name": "Plant_Leaves_Jungle_Max_Support"
    },
    {
      "x": -29,
      "y": 71,
      "z": 2,
      "name": "Plant_Leaves_Jungle_Max_Support"
    },
    {
      "x": -29,
      "y": 72,
      "z": 2,
      "name": "Plant_Leaves_Jungle_Max_Support"
    },
    {
      "x": -29,
      "y": 67,
      "z": 3,
      "name": "Plant_Leaves_Jungle_Max_Support"
    },
    {
      "x": -29,
      "y": 68,
      "z": 3,
      "name": "Plant_Leaves_Jungle_Max_Support"
    },
    {
      "x": -29,
      "y": 69,
      "z": 3,
      "name": "Plant_Leaves_Jungle_Max_Support"
    },
    {
      "x": -29,
      "y": 71,
      "z": 3,
      "name": "Plant_Leaves_Jungle_Max_Support"
    },
    {
      "x": -29,
      "y": 73,
      "z": 3,
      "name": "Plant_Leaves_Jungle_Max_Support"
    },
    {
      "x": -29,
      "y": 67,
      "z": 4,
      "name": "Plant_Leaves_Jungle_Max_Support",
      "support": 15
    },
    {
      "x": -29,
      "y": 68,
      "z": 4,
      "name": "Plant_Leaves_Jungle_Max_Support",
      "support": 15
    },
    {
      "x": -29,
      "y": 69,
      "z": 4,
      "name": "Plant_Leaves_Jungle_Max_Support"
    },
    {
      "x": -29,
      "y": 71,
      "z": 4,
      "name": "Plant_Leaves_Jungle_Max_Support"
    },
    {
      "x": -29,
      "y": 69,
      "z": 5,
      "name": "Plant_Leaves_Jungle_Max_Support"
    },
    {
      "x": -29,
      "y": 70,
      "z": 5,
      "name": "Plant_Leaves_Jungle_Max_Support"
    },
    {
      "x": -29,
      "y": 71,
      "z": 5,
      "name": "Plant_Leaves_Jungle_Max_Support"
    },
    {
      "x": -28,
      "y": 65,
      "z": -18,
      "name": "Plant_Leaves_Jungle_Max_Support"
    },
    {
      "x": -28,
      "y": 66,
      "z": -18,
      "name": "Plant_Leaves_Jungle_Max_Support"
    },
    {
      "x": -28,
      "y": 65,
      "z": -17,
      "name": "Plant_Leaves_Jungle_Max_Support"
    },
    {
      "x": -28,
      "y": 66,
      "z": -17,
      "name": "Plant_Leaves_Jungle_Max_Support"
    },
    {
      "x": -28,
      "y": 63,
      "z": -16,
      "name": "Plant_Leaves_Jungle_Max_Support"
    },
    {
      "x": -28,
      "y": 65,
      "z": -16,
      "name": "Plant_Leaves_Jungle_Max_Support"
    },
    {
      "x": -28,
      "y": 63,
      "z": -15,
      "name": "Plant_Leaves_Jungle_Max_Support"
    },
    {
      "x": -28,
      "y": 64,
      "z": -15,
      "name": "Plant_Leaves_Jungle_Max_Support"
    },
    {
      "x": -28,
      "y": 60,
      "z": -14,
      "name": "Plant_Leaves_Jungle_Max_Support"
    },
    {
      "x": -28,
      "y": 61,
      "z": -14,
      "name": "Plant_Leaves_Jungle_Max_Support"
    },
    {
      "x": -28,
      "y": 62,
      "z": -14,
      "name": "Plant_Leaves_Jungle_Max_Support"
    },
    {
      "x": -28,
      "y": 62,
      "z": -13,
      "name": "Plant_Leaves_Jungle_Max_Support"
    },
    {
      "x": -28,
      "y": 63,
      "z": -13,
      "name": "Plant_Leaves_Jungle_Max_Support"
    },
    {
      "x": -28,
      "y": 65,
      "z": -13,
      "name": "Plant_Leaves_Jungle_Max_Support"
    },
    {
      "x": -28,
      "y": 66,
      "z": -13,
      "name": "Plant_Leaves_Jungle_Max_Support"
    },
    {
      "x": -28,
      "y": 63,
      "z": -12,
      "name": "Plant_Leaves_Jungle_Max_Support"
    },
    {
      "x": -28,
      "y": 64,
      "z": -12,
      "name": "Plant_Leaves_Jungle_Max_Support"
    },
    {
      "x": -28,
      "y": 65,
      "z": -12,
      "name": "Plant_Leaves_Jungle_Max_Support"
    },
    {
      "x": -28,
      "y": 66,
      "z": -12,
      "name": "Plant_Leaves_Jungle_Max_Support"
    },
    {
      "x": -28,
      "y": 67,
      "z": -12,
      "name": "Plant_Leaves_Jungle_Max_Support"
    },
    {
      "x": -28,
      "y": 68,
      "z": -12,
      "name": "Plant_Leaves_Jungle_Max_Support"
    },
    {
      "x": -28,
      "y": 63,
      "z": -11,
      "name": "Plant_Leaves_Jungle_Max_Support"
    },
    {
      "x": -28,
      "y": 65,
      "z": -11,
      "name": "Plant_Leaves_Jungle_Max_Support"
    },
    {
      "x": -28,
      "y": 66,
      "z": -11,
      "name": "Plant_Leaves_Jungle_Max_Support"
    },
    {
      "x": -28,
      "y": 67,
      "z": -11,
      "name": "Plant_Leaves_Jungle_Max_Support"
    },
    {
      "x": -28,
      "y": 68,
      "z": -11,
      "name": "Plant_Leaves_Jungle_Max_Support"
    },
    {
      "x": -28,
      "y": 69,
      "z": -11,
      "name": "Plant_Leaves_Jungle_Max_Support"
    },
    {
      "x": -28,
      "y": 65,
      "z": -10,
      "name": "Plant_Leaves_Jungle_Max_Support"
    },
    {
      "x": -28,
      "y": 66,
      "z": -10,
      "name": "Plant_Leaves_Jungle_Max_Support"
    },
    {
      "x": -28,
      "y": 67,
      "z": -10,
      "name": "Plant_Leaves_Jungle_Max_Support"
    },
    {
      "x": -28,
      "y": 68,
      "z": -10,
      "name": "Plant_Leaves_Jungle_Max_Support"
    },
    {
      "x": -28,
      "y": 69,
      "z": -10,
      "name": "Plant_Leaves_Jungle_Max_Support"
    },
    {
      "x": -28,
      "y": 64,
      "z": -9,
      "name": "Plant_Leaves_Jungle_Max_Support"
    },
    {
      "x": -28,
      "y": 65,
      "z": -9,
      "name": "Plant_Leaves_Jungle_Max_Support"
    },
    {
      "x": -28,
      "y": 66,
      "z": -9,
      "name": "Plant_Leaves_Jungle_Max_Support"
    },
    {
      "x": -28,
      "y": 67,
      "z": -9,
      "name": "Plant_Leaves_Jungle_Max_Support"
    },
    {
      "x": -28,
      "y": 68,
      "z": -9,
      "name": "Plant_Leaves_Jungle_Max_Support"
    },
    {
      "x": -28,
      "y": 63,
      "z": -8,
      "name": "Plant_Leaves_Jungle_Max_Support"
    },
    {
      "x": -28,
      "y": 64,
      "z": -8,
      "name": "Plant_Leaves_Jungle_Max_Support"
    },
    {
      "x": -28,
      "y": 66,
      "z": -8,
      "name": "Plant_Leaves_Jungle_Max_Support"
    },
    {
      "x": -28,
      "y": 64,
      "z": -7,
      "name": "Plant_Leaves_Jungle_Max_Support"
    },
    {
      "x": -28,
      "y": 65,
      "z": -7,
      "name": "Plant_Leaves_Jungle_Max_Support"
    },
    {
      "x": -28,
      "y": 66,
      "z": -7,
      "name": "Plant_Leaves_Jungle_Max_Support"
    },
    {
      "x": -28,
      "y": 65,
      "z": -6,
      "name": "Plant_Leaves_Jungle_Max_Support"
    },
    {
      "x": -28,
      "y": 71,
      "z": -6,
      "name": "Plant_Leaves_Jungle_Max_Support"
    },
    {
      "x": -28,
      "y": 72,
      "z": -6,
      "name": "Plant_Leaves_Jungle_Max_Support"
    },
    {
      "x": -28,
      "y": 73,
      "z": -6,
      "name": "Plant_Leaves_Jungle_Max_Support"
    },
    {
      "x": -28,
      "y": 70,
      "z": -5,
      "name": "Plant_Leaves_Jungle_Max_Support"
    },
    {
      "x": -28,
      "y": 73,
      "z": -5,
      "name": "Plant_Leaves_Jungle_Max_Support"
    },
    {
      "x": -28,
      "y": 74,
      "z": -5,
      "name": "Plant_Leaves_Jungle_Max_Support"
    },
    {
      "x": -28,
      "y": 69,
      "z": -4,
      "name": "Plant_Leaves_Jungle_Max_Support"
    },
    {
      "x": -28,
      "y": 70,
      "z": -4,
      "name": "Plant_Leaves_Jungle_Max_Support"
    },
    {
      "x": -28,
      "y": 71,
      "z": -4,
      "name": "Plant_Leaves_Jungle_Max_Support"
    },
    {
      "x": -28,
      "y": 72,
      "z": -4,
      "name": "Plant_Leaves_Jungle_Max_Support"
    },
    {
      "x": -28,
      "y": 75,
      "z": -4,
      "name": "Plant_Leaves_Jungle_Max_Support"
    },
    {
      "x": -28,
      "y": 69,
      "z": -3,
      "name": "Plant_Leaves_Jungle_Max_Support"
    },
    {
      "x": -28,
      "y": 70,
      "z": -3,
      "name": "Plant_Leaves_Jungle_Max_Support"
    },
    {
      "x": -28,
      "y": 72,
      "z": -3,
      "name": "Plant_Leaves_Jungle_Max_Support"
    },
    {
      "x": -28,
      "y": 73,
      "z": -3,
      "name": "Plant_Leaves_Jungle_Max_Support"
    },
    {
      "x": -28,
      "y": 74,
      "z": -3,
      "name": "Plant_Leaves_Jungle_Max_Support"
    },
    {
      "x": -28,
      "y": 69,
      "z": -2,
      "name": "Plant_Leaves_Jungle_Max_Support"
    },
    {
      "x": -28,
      "y": 70,
      "z": -2,
      "name": "Plant_Leaves_Jungle_Max_Support"
    },
    {
      "x": -28,
      "y": 71,
      "z": -2,
      "name": "Plant_Leaves_Jungle_Max_Support"
    },
    {
      "x": -28,
      "y": 72,
      "z": -2,
      "name": "Plant_Leaves_Jungle_Max_Support"
    },
    {
      "x": -28,
      "y": 73,
      "z": -2,
      "name": "Plant_Leaves_Jungle_Max_Support"
    },
    {
      "x": -28,
      "y": 74,
      "z": -2,
      "name": "Plant_Leaves_Jungle_Max_Support"
    },
    {
      "x": -28,
      "y": 75,
      "z": -2,
      "name": "Plant_Leaves_Jungle_Max_Support"
    },
    {
      "x": -28,
      "y": 69,
      "z": -1,
      "name": "Plant_Leaves_Jungle_Max_Support"
    },
    {
      "x": -28,
      "y": 70,
      "z": -1,
      "name": "Plant_Leaves_Jungle_Max_Support"
    },
    {
      "x": -28,
      "y": 71,
      "z": -1,
      "name": "Plant_Leaves_Jungle_Max_Support"
    },
    {
      "x": -28,
      "y": 72,
      "z": -1,
      "name": "Plant_Leaves_Jungle_Max_Support"
    },
    {
      "x": -28,
      "y": 73,
      "z": -1,
      "name": "Plant_Leaves_Jungle_Max_Support"
    },
    {
      "x": -28,
      "y": 74,
      "z": -1,
      "name": "Plant_Leaves_Jungle_Max_Support"
    },
    {
      "x": -28,
      "y": 69,
      "z": 0,
      "name": "Plant_Leaves_Jungle_Max_Support"
    },
    {
      "x": -28,
      "y": 70,
      "z": 0,
      "name": "Plant_Leaves_Jungle_Max_Support"
    },
    {
      "x": -28,
      "y": 71,
      "z": 0,
      "name": "Plant_Leaves_Jungle_Max_Support"
    },
    {
      "x": -28,
      "y": 72,
      "z": 0,
      "name": "Plant_Leaves_Jungle_Max_Support"
    },
    {
      "x": -28,
      "y": 73,
      "z": 0,
      "name": "Plant_Leaves_Jungle_Max_Support"
    },
    {
      "x": -28,
      "y": 74,
      "z": 0,
      "name": "Plant_Leaves_Jungle_Max_Support"
    },
    {
      "x": -28,
      "y": 75,
      "z": 0,
      "name": "Plant_Leaves_Jungle_Max_Support"
    },
    {
      "x": -28,
      "y": 69,
      "z": 1,
      "name": "Plant_Leaves_Jungle_Max_Support"
    },
    {
      "x": -28,
      "y": 70,
      "z": 1,
      "name": "Plant_Leaves_Jungle_Max_Support"
    },
    {
      "x": -28,
      "y": 71,
      "z": 1,
      "name": "Plant_Leaves_Jungle_Max_Support"
    },
    {
      "x": -28,
      "y": 72,
      "z": 1,
      "name": "Plant_Leaves_Jungle_Max_Support"
    },
    {
      "x": -28,
      "y": 74,
      "z": 1,
      "name": "Plant_Leaves_Jungle_Max_Support"
    },
    {
      "x": -28,
      "y": 75,
      "z": 1,
      "name": "Plant_Leaves_Jungle_Max_Support"
    },
    {
      "x": -28,
      "y": 67,
      "z": 2,
      "name": "Plant_Leaves_Jungle_Max_Support"
    },
    {
      "x": -28,
      "y": 68,
      "z": 2,
      "name": "Plant_Leaves_Jungle_Max_Support"
    },
    {
      "x": -28,
      "y": 69,
      "z": 2,
      "name": "Plant_Leaves_Jungle_Max_Support"
    },
    {
      "x": -28,
      "y": 70,
      "z": 2,
      "name": "Plant_Leaves_Jungle_Max_Support"
    },
    {
      "x": -28,
      "y": 71,
      "z": 2,
      "name": "Plant_Leaves_Jungle_Max_Support"
    },
    {
      "x": -28,
      "y": 72,
      "z": 2,
      "name": "Plant_Leaves_Jungle_Max_Support"
    },
    {
      "x": -28,
      "y": 74,
      "z": 2,
      "name": "Plant_Leaves_Jungle_Max_Support"
    },
    {
      "x": -28,
      "y": 64,
      "z": 3,
      "name": "Plant_Leaves_Jungle_Max_Support",
      "support": 15
    },
    {
      "x": -28,
      "y": 65,
      "z": 3,
      "name": "Plant_Leaves_Jungle_Max_Support",
      "support": 15
    },
    {
      "x": -28,
      "y": 66,
      "z": 3,
      "name": "Plant_Leaves_Jungle_Max_Support",
      "support": 15
    },
    {
      "x": -28,
      "y": 67,
      "z": 3,
      "name": "Plant_Leaves_Jungle_Max_Support"
    },
    {
      "x": -28,
      "y": 68,
      "z": 3,
      "name": "Plant_Leaves_Jungle_Max_Support"
    },
    {
      "x": -28,
      "y": 69,
      "z": 3,
      "name": "Plant_Leaves_Jungle_Max_Support"
    },
    {
      "x": -28,
      "y": 70,
      "z": 3,
      "name": "Plant_Leaves_Jungle_Max_Support"
    },
    {
      "x": -28,
      "y": 71,
      "z": 3,
      "name": "Plant_Leaves_Jungle_Max_Support"
    },
    {
      "x": -28,
      "y": 73,
      "z": 3,
      "name": "Plant_Leaves_Jungle_Max_Support"
    },
    {
      "x": -28,
      "y": 69,
      "z": 4,
      "name": "Plant_Leaves_Jungle_Max_Support"
    },
    {
      "x": -28,
      "y": 70,
      "z": 4,
      "name": "Plant_Leaves_Jungle_Max_Support"
    },
    {
      "x": -28,
      "y": 72,
      "z": 4,
      "name": "Plant_Leaves_Jungle_Max_Support"
    },
    {
      "x": -28,
      "y": 70,
      "z": 5,
      "name": "Plant_Leaves_Jungle_Max_Support"
    },
    {
      "x": -27,
      "y": 65,
      "z": -18,
      "name": "Plant_Leaves_Jungle_Max_Support"
    },
    {
      "x": -27,
      "y": 68,
      "z": -18,
      "name": "Plant_Leaves_Jungle_Max_Support"
    },
    {
      "x": -27,
      "y": 60,
      "z": -17,
      "name": "Plant_Leaves_Jungle_Max_Support",
      "support": 15
    },
    {
      "x": -27,
      "y": 61,
      "z": -17,
      "name": "Plant_Leaves_Jungle_Max_Support",
      "support": 15
    },
    {
      "x": -27,
      "y": 62,
      "z": -17,
      "name": "Plant_Leaves_Jungle_Max_Support",
      "support": 15
    },
    {
      "x": -27,
      "y": 64,
      "z": -17,
      "name": "Plant_Leaves_Jungle_Max_Support"
    },
    {
      "x": -27,
      "y": 65,
      "z": -17,
      "name": "Plant_Leaves_Jungle_Max_Support"
    },
    {
      "x": -27,
      "y": 66,
      "z": -17,
      "name": "Plant_Leaves_Jungle_Max_Support"
    },
    {
      "x": -27,
      "y": 67,
      "z": -17,
      "name": "Plant_Leaves_Jungle_Max_Support"
    },
    {
      "x": -27,
      "y": 68,
      "z": -17,
      "name": "Plant_Leaves_Jungle_Max_Support"
    },
    {
      "x": -27,
      "y": 58,
      "z": -16,
      "name": "Plant_Leaves_Jungle_Max_Support",
      "support": 15
    },
    {
      "x": -27,
      "y": 59,
      "z": -16,
      "name": "Plant_Leaves_Jungle_Max_Support",
      "support": 15
    },
    {
      "x": -27,
      "y": 60,
      "z": -16,
      "name": "Plant_Leaves_Jungle_Max_Support",
      "support": 15
    },
    {
      "x": -27,
      "y": 62,
      "z": -16,
      "name": "Plant_Leaves_Jungle_Max_Support"
    },
    {
      "x": -27,
      "y": 63,
      "z": -16,
      "name": "Plant_Leaves_Jungle_Max_Support"
    },
    {
      "x": -27,
      "y": 64,
      "z": -16,
      "name": "Plant_Leaves_Jungle_Max_Support"
    },
    {
      "x": -27,
      "y": 67,
      "z": -16,
      "name": "Plant_Leaves_Jungle_Max_Support"
    },
    {
      "x": -27,
      "y": 68,
      "z": -16,
      "name": "Plant_Leaves_Jungle_Max_Support"
    },
    {
      "x": -27,
      "y": 60,
      "z": -15,
      "name": "Plant_Leaves_Jungle_Max_Support"
    },
    {
      "x": -27,
      "y": 61,
      "z": -15,
      "name": "Plant_Leaves_Jungle_Max_Support"
    },
    {
      "x": -27,
      "y": 62,
      "z": -15,
      "name": "Plant_Leaves_Jungle_Max_Support"
    },
    {
      "x": -27,
      "y": 63,
      "z": -15,
      "name": "Plant_Leaves_Jungle_Max_Support"
    },
    {
      "x": -27,
      "y": 64,
      "z": -15,
      "name": "Plant_Leaves_Jungle_Max_Support"
    },
    {
      "x": -27,
      "y": 65,
      "z": -15,
      "name": "Plant_Leaves_Jungle_Max_Support"
    },
    {
      "x": -27,
      "y": 61,
      "z": -14,
      "name": "Plant_Leaves_Jungle_Max_Support"
    },
    {
      "x": -27,
      "y": 62,
      "z": -14,
      "name": "Plant_Leaves_Jungle_Max_Support"
    },
    {
      "x": -27,
      "y": 63,
      "z": -14,
      "name": "Plant_Leaves_Jungle_Max_Support"
    },
    {
      "x": -27,
      "y": 64,
      "z": -14,
      "name": "Plant_Leaves_Jungle_Max_Support"
    },
    {
      "x": -27,
      "y": 65,
      "z": -14,
      "name": "Plant_Leaves_Jungle_Max_Support"
    },
    {
      "x": -27,
      "y": 66,
      "z": -14,
      "name": "Plant_Leaves_Jungle_Max_Support"
    },
    {
      "x": -27,
      "y": 68,
      "z": -14,
      "name": "Plant_Leaves_Jungle_Max_Support"
    },
    {
      "x": -27,
      "y": 60,
      "z": -13,
      "name": "Plant_Leaves_Jungle_Max_Support"
    },
    {
      "x": -27,
      "y": 61,
      "z": -13,
      "name": "Plant_Leaves_Jungle_Max_Support"
    },
    {
      "x": -27,
      "y": 62,
      "z": -13,
      "name": "Plant_Leaves_Jungle_Max_Support"
    },
    {
      "x": -27,
      "y": 63,
      "z": -13,
      "name": "Plant_Leaves_Jungle_Max_Support"
    },
    {
      "x": -27,
      "y": 64,
      "z": -13,
      "name": "Plant_Leaves_Jungle_Max_Support"
    },
    {
      "x": -27,
      "y": 65,
      "z": -13,
      "name": "Plant_Leaves_Jungle_Max_Support"
    },
    {
      "x": -27,
      "y": 66,
      "z": -13,
      "name": "Plant_Leaves_Jungle_Max_Support"
    },
    {
      "x": -27,
      "y": 67,
      "z": -13,
      "name": "Plant_Leaves_Jungle_Max_Support"
    },
    {
      "x": -27,
      "y": 69,
      "z": -13,
      "name": "Plant_Leaves_Jungle_Max_Support"
    },
    {
      "x": -27,
      "y": 61,
      "z": -12,
      "name": "Plant_Leaves_Jungle_Max_Support"
    },
    {
      "x": -27,
      "y": 62,
      "z": -12,
      "name": "Plant_Leaves_Jungle_Max_Support"
    },
    {
      "x": -27,
      "y": 63,
      "z": -12,
      "name": "Plant_Leaves_Jungle_Max_Support"
    },
    {
      "x": -27,
      "y": 64,
      "z": -12,
      "name": "Plant_Leaves_Jungle_Max_Support"
    },
    {
      "x": -27,
      "y": 65,
      "z": -12,
      "name": "Plant_Leaves_Jungle_Max_Support"
    },
    {
      "x": -27,
      "y": 66,
      "z": -12,
      "name": "Plant_Leaves_Jungle_Max_Support"
    },
    {
      "x": -27,
      "y": 69,
      "z": -12,
      "name": "Plant_Leaves_Jungle_Max_Support"
    },
    {
      "x": -27,
      "y": 63,
      "z": -11,
      "name": "Plant_Leaves_Jungle_Max_Support"
    },
    {
      "x": -27,
      "y": 64,
      "z": -11,
      "name": "Plant_Leaves_Jungle_Max_Support"
    },
    {
      "x": -27,
      "y": 65,
      "z": -11,
      "name": "Plant_Leaves_Jungle_Max_Support"
    },
    {
      "x": -27,
      "y": 66,
      "z": -11,
      "name": "Plant_Leaves_Jungle_Max_Support"
    },
    {
      "x": -27,
      "y": 71,
      "z": -11,
      "name": "Plant_Leaves_Jungle_Max_Support"
    },
    {
      "x": -27,
      "y": 63,
      "z": -10,
      "name": "Plant_Leaves_Jungle_Max_Support"
    },
    {
      "x": -27,
      "y": 64,
      "z": -10,
      "name": "Plant_Leaves_Jungle_Max_Support"
    },
    {
      "x": -27,
      "y": 65,
      "z": -10,
      "name": "Plant_Leaves_Jungle_Max_Support"
    },
    {
      "x": -27,
      "y": 66,
      "z": -10,
      "name": "Plant_Leaves_Jungle_Max_Support"
    },
    {
      "x": -27,
      "y": 67,
      "z": -10,
      "name": "Plant_Leaves_Jungle_Max_Support"
    },
    {
      "x": -27,
      "y": 68,
      "z": -10,
      "name": "Plant_Leaves_Jungle_Max_Support"
    },
    {
      "x": -27,
      "y": 70,
      "z": -10,
      "name": "Plant_Leaves_Jungle_Max_Support"
    },
    {
      "x": -27,
      "y": 63,
      "z": -9,
      "name": "Plant_Leaves_Jungle_Max_Support"
    },
    {
      "x": -27,
      "y": 65,
      "z": -9,
      "name": "Plant_Leaves_Jungle_Max_Support"
    },
    {
      "x": -27,
      "y": 66,
      "z": -9,
      "name": "Plant_Leaves_Jungle_Max_Support"
    },
    {
      "x": -27,
      "y": 68,
      "z": -9,
      "name": "Plant_Leaves_Jungle_Max_Support"
    },
    {
      "x": -27,
      "y": 69,
      "z": -9,
      "name": "Plant_Leaves_Jungle_Max_Support"
    },
    {
      "x": -27,
      "y": 65,
      "z": -8,
      "name": "Plant_Leaves_Jungle_Max_Support"
    },
    {
      "x": -27,
      "y": 66,
      "z": -8,
      "name": "Plant_Leaves_Jungle_Max_Support"
    },
    {
      "x": -27,
      "y": 67,
      "z": -8,
      "name": "Plant_Leaves_Jungle_Max_Support"
    },
    {
      "x": -27,
      "y": 63,
      "z": -7,
      "name": "Plant_Leaves_Jungle_Max_Support"
    },
    {
      "x": -27,
      "y": 64,
      "z": -7,
      "name": "Plant_Leaves_Jungle_Max_Support"
    },
    {
      "x": -27,
      "y": 66,
      "z": -7,
      "name": "Plant_Leaves_Jungle_Max_Support"
    },
    {
      "x": -27,
      "y": 67,
      "z": -7,
      "name": "Plant_Leaves_Jungle_Max_Support"
    },
    {
      "x": -27,
      "y": 64,
      "z": -6,
      "name": "Plant_Leaves_Jungle_Max_Support"
    },
    {
      "x": -27,
      "y": 65,
      "z": -6,
      "name": "Plant_Leaves_Jungle_Max_Support"
    },
    {
      "x": -27,
      "y": 66,
      "z": -6,
      "name": "Plant_Leaves_Jungle_Max_Support"
    },
    {
      "x": -27,
      "y": 72,
      "z": -6,
      "name": "Plant_Leaves_Jungle_Max_Support"
    },
    {
      "x": -27,
      "y": 70,
      "z": -5,
      "name": "Plant_Leaves_Jungle_Max_Support"
    },
    {
      "x": -27,
      "y": 71,
      "z": -5,
      "name": "Plant_Leaves_Jungle_Max_Support"
    },
    {
      "x": -27,
      "y": 72,
      "z": -5,
      "name": "Plant_Leaves_Jungle_Max_Support"
    },
    {
      "x": -27,
      "y": 69,
      "z": -4,
      "name": "Plant_Leaves_Jungle_Max_Support"
    },
    {
      "x": -27,
      "y": 71,
      "z": -4,
      "name": "Plant_Leaves_Jungle_Max_Support"
    },
    {
      "x": -27,
      "y": 72,
      "z": -4,
      "name": "Plant_Leaves_Jungle_Max_Support"
    },
    {
      "x": -27,
      "y": 73,
      "z": -4,
      "name": "Plant_Leaves_Jungle_Max_Support"
    },
    {
      "x": -27,
      "y": 75,
      "z": -4,
      "name": "Plant_Leaves_Jungle_Max_Support"
    },
    {
      "x": -27,
      "y": 68,
      "z": -3,
      "name": "Plant_Leaves_Jungle_Max_Support"
    },
    {
      "x": -27,
      "y": 70,
      "z": -3,
      "name": "Plant_Leaves_Jungle_Max_Support"
    },
    {
      "x": -27,
      "y": 71,
      "z": -3,
      "name": "Plant_Leaves_Jungle_Max_Support"
    },
    {
      "x": -27,
      "y": 72,
      "z": -3,
      "name": "Plant_Leaves_Jungle_Max_Support"
    },
    {
      "x": -27,
      "y": 73,
      "z": -3,
      "name": "Plant_Leaves_Jungle_Max_Support"
    },
    {
      "x": -27,
      "y": 74,
      "z": -3,
      "name": "Plant_Leaves_Jungle_Max_Support"
    },
    {
      "x": -27,
      "y": 68,
      "z": -2,
      "name": "Plant_Leaves_Jungle_Max_Support"
    },
    {
      "x": -27,
      "y": 69,
      "z": -2,
      "name": "Plant_Leaves_Jungle_Max_Support"
    },
    {
      "x": -27,
      "y": 70,
      "z": -2,
      "name": "Plant_Leaves_Jungle_Max_Support"
    },
    {
      "x": -27,
      "y": 71,
      "z": -2,
      "name": "Plant_Leaves_Jungle_Max_Support"
    },
    {
      "x": -27,
      "y": 72,
      "z": -2,
      "name": "Plant_Leaves_Jungle_Max_Support"
    },
    {
      "x": -27,
      "y": 73,
      "z": -2,
      "name": "Plant_Leaves_Jungle_Max_Support"
    },
    {
      "x": -27,
      "y": 74,
      "z": -2,
      "name": "Plant_Leaves_Jungle_Max_Support"
    },
    {
      "x": -27,
      "y": 75,
      "z": -2,
      "name": "Plant_Leaves_Jungle_Max_Support"
    },
    {
      "x": -27,
      "y": 68,
      "z": -1,
      "name": "Plant_Leaves_Jungle_Max_Support"
    },
    {
      "x": -27,
      "y": 69,
      "z": -1,
      "name": "Plant_Leaves_Jungle_Max_Support"
    },
    {
      "x": -27,
      "y": 70,
      "z": -1,
      "name": "Plant_Leaves_Jungle_Max_Support"
    },
    {
      "x": -27,
      "y": 71,
      "z": -1,
      "name": "Plant_Leaves_Jungle_Max_Support"
    },
    {
      "x": -27,
      "y": 72,
      "z": -1,
      "name": "Plant_Leaves_Jungle_Max_Support"
    },
    {
      "x": -27,
      "y": 73,
      "z": -1,
      "name": "Plant_Leaves_Jungle_Max_Support"
    },
    {
      "x": -27,
      "y": 74,
      "z": -1,
      "name": "Plant_Leaves_Jungle_Max_Support"
    },
    {
      "x": -27,
      "y": 76,
      "z": -1,
      "name": "Plant_Leaves_Jungle_Max_Support"
    },
    {
      "x": -27,
      "y": 69,
      "z": 0,
      "name": "Plant_Leaves_Jungle_Max_Support"
    },
    {
      "x": -27,
      "y": 70,
      "z": 0,
      "name": "Plant_Leaves_Jungle_Max_Support"
    },
    {
      "x": -27,
      "y": 71,
      "z": 0,
      "name": "Plant_Leaves_Jungle_Max_Support"
    },
    {
      "x": -27,
      "y": 72,
      "z": 0,
      "name": "Plant_Leaves_Jungle_Max_Support"
    },
    {
      "x": -27,
      "y": 73,
      "z": 0,
      "name": "Plant_Leaves_Jungle_Max_Support"
    },
    {
      "x": -27,
      "y": 74,
      "z": 0,
      "name": "Plant_Leaves_Jungle_Max_Support"
    },
    {
      "x": -27,
      "y": 76,
      "z": 0,
      "name": "Plant_Leaves_Jungle_Max_Support"
    },
    {
      "x": -27,
      "y": 66,
      "z": 1,
      "name": "Plant_Leaves_Jungle_Max_Support"
    },
    {
      "x": -27,
      "y": 69,
      "z": 1,
      "name": "Plant_Leaves_Jungle_Max_Support"
    },
    {
      "x": -27,
      "y": 70,
      "z": 1,
      "name": "Plant_Leaves_Jungle_Max_Support"
    },
    {
      "x": -27,
      "y": 71,
      "z": 1,
      "name": "Plant_Leaves_Jungle_Max_Support"
    },
    {
      "x": -27,
      "y": 72,
      "z": 1,
      "name": "Plant_Leaves_Jungle_Max_Support"
    },
    {
      "x": -27,
      "y": 73,
      "z": 1,
      "name": "Plant_Leaves_Jungle_Max_Support"
    },
    {
      "x": -27,
      "y": 75,
      "z": 1,
      "name": "Plant_Leaves_Jungle_Max_Support"
    },
    {
      "x": -27,
      "y": 76,
      "z": 1,
      "name": "Plant_Leaves_Jungle_Max_Support"
    },
    {
      "x": -27,
      "y": 66,
      "z": 2,
      "name": "Plant_Leaves_Jungle_Max_Support"
    },
    {
      "x": -27,
      "y": 67,
      "z": 2,
      "name": "Plant_Leaves_Jungle_Max_Support"
    },
    {
      "x": -27,
      "y": 68,
      "z": 2,
      "name": "Plant_Leaves_Jungle_Max_Support"
    },
    {
      "x": -27,
      "y": 69,
      "z": 2,
      "name": "Plant_Leaves_Jungle_Max_Support"
    },
    {
      "x": -27,
      "y": 70,
      "z": 2,
      "name": "Plant_Leaves_Jungle_Max_Support"
    },
    {
      "x": -27,
      "y": 71,
      "z": 2,
      "name": "Plant_Leaves_Jungle_Max_Support"
    },
    {
      "x": -27,
      "y": 72,
      "z": 2,
      "name": "Plant_Leaves_Jungle_Max_Support"
    },
    {
      "x": -27,
      "y": 74,
      "z": 2,
      "name": "Plant_Leaves_Jungle_Max_Support"
    },
    {
      "x": -27,
      "y": 75,
      "z": 2,
      "name": "Plant_Leaves_Jungle_Max_Support"
    },
    {
      "x": -27,
      "y": 66,
      "z": 3,
      "name": "Plant_Leaves_Jungle_Max_Support"
    },
    {
      "x": -27,
      "y": 67,
      "z": 3,
      "name": "Plant_Leaves_Jungle_Max_Support"
    },
    {
      "x": -27,
      "y": 68,
      "z": 3,
      "name": "Plant_Leaves_Jungle_Max_Support"
    },
    {
      "x": -27,
      "y": 70,
      "z": 3,
      "name": "Plant_Leaves_Jungle_Max_Support"
    },
    {
      "x": -27,
      "y": 72,
      "z": 3,
      "name": "Plant_Leaves_Jungle_Max_Support"
    },
    {
      "x": -27,
      "y": 73,
      "z": 3,
      "name": "Plant_Leaves_Jungle_Max_Support"
    },
    {
      "x": -27,
      "y": 66,
      "z": 4,
      "name": "Plant_Leaves_Jungle_Max_Support",
      "support": 15
    },
    {
      "x": -27,
      "y": 67,
      "z": 4,
      "name": "Plant_Leaves_Jungle_Max_Support"
    },
    {
      "x": -27,
      "y": 68,
      "z": 4,
      "name": "Plant_Leaves_Jungle_Max_Support"
    },
    {
      "x": -27,
      "y": 69,
      "z": 4,
      "name": "Plant_Leaves_Jungle_Max_Support"
    },
    {
      "x": -27,
      "y": 68,
      "z": 5,
      "name": "Plant_Leaves_Jungle_Max_Support",
      "support": 15
    },
    {
      "x": -27,
      "y": 69,
      "z": 5,
      "name": "Plant_Leaves_Jungle_Max_Support"
    },
    {
      "x": -26,
      "y": 64,
      "z": -19,
      "name": "Plant_Leaves_Jungle_Max_Support"
    },
    {
      "x": -26,
      "y": 65,
      "z": -19,
      "name": "Plant_Leaves_Jungle_Max_Support"
    },
    {
      "x": -26,
      "y": 66,
      "z": -19,
      "name": "Plant_Leaves_Jungle_Max_Support"
    },
    {
      "x": -26,
      "y": 59,
      "z": -18,
      "name": "Plant_Leaves_Jungle_Max_Support"
    },
    {
      "x": -26,
      "y": 60,
      "z": -18,
      "name": "Plant_Leaves_Jungle_Max_Support",
      "support": 15
    },
    {
      "x": -26,
      "y": 63,
      "z": -18,
      "name": "Plant_Leaves_Jungle_Max_Support"
    },
    {
      "x": -26,
      "y": 64,
      "z": -18,
      "name": "Plant_Leaves_Jungle_Max_Support"
    },
    {
      "x": -26,
      "y": 67,
      "z": -18,
      "name": "Plant_Leaves_Jungle_Max_Support"
    },
    {
      "x": -26,
      "y": 68,
      "z": -18,
      "name": "Plant_Leaves_Jungle_Max_Support"
    },
    {
      "x": -26,
      "y": 59,
      "z": -17,
      "name": "Plant_Leaves_Jungle_Max_Support"
    },
    {
      "x": -26,
      "y": 60,
      "z": -17,
      "name": "Plant_Leaves_Jungle_Max_Support",
      "support": 15
    },
    {
      "x": -26,
      "y": 61,
      "z": -17,
      "name": "Plant_Leaves_Jungle_Max_Support"
    },
    {
      "x": -26,
      "y": 62,
      "z": -17,
      "name": "Plant_Leaves_Jungle_Max_Support"
    },
    {
      "x": -26,
      "y": 63,
      "z": -17,
      "name": "Plant_Leaves_Jungle_Max_Support"
    },
    {
      "x": -26,
      "y": 64,
      "z": -17,
      "name": "Plant_Leaves_Jungle_Max_Support"
    },
    {
      "x": -26,
      "y": 65,
      "z": -17,
      "name": "Plant_Leaves_Jungle_Max_Support"
    },
    {
      "x": -26,
      "y": 68,
      "z": -17,
      "name": "Plant_Leaves_Jungle_Max_Support"
    },
    {
      "x": -26,
      "y": 59,
      "z": -16,
      "name": "Plant_Leaves_Jungle_Max_Support"
    },
    {
      "x": -26,
      "y": 60,
      "z": -16,
      "name": "Plant_Leaves_Jungle_Max_Support",
      "support": 15
    },
    {
      "x": -26,
      "y": 61,
      "z": -16,
      "name": "Plant_Leaves_Jungle_Max_Support"
    },
    {
      "x": -26,
      "y": 62,
      "z": -16,
      "name": "Plant_Leaves_Jungle_Max_Support"
    },
    {
      "x": -26,
      "y": 63,
      "z": -16,
      "name": "Plant_Leaves_Jungle_Max_Support"
    },
    {
      "x": -26,
      "y": 65,
      "z": -16,
      "name": "Plant_Leaves_Jungle_Max_Support"
    },
    {
      "x": -26,
      "y": 66,
      "z": -16,
      "name": "Plant_Leaves_Jungle_Max_Support"
    },
    {
      "x": -26,
      "y": 68,
      "z": -16,
      "name": "Plant_Leaves_Jungle_Max_Support"
    },
    {
      "x": -26,
      "y": 69,
      "z": -16,
      "name": "Plant_Leaves_Jungle_Max_Support"
    },
    {
      "x": -26,
      "y": 59,
      "z": -15,
      "name": "Plant_Leaves_Jungle_Max_Support"
    },
    {
      "x": -26,
      "y": 60,
      "z": -15,
      "name": "Plant_Leaves_Jungle_Max_Support"
    },
    {
      "x": -26,
      "y": 61,
      "z": -15,
      "name": "Plant_Leaves_Jungle_Max_Support"
    },
    {
      "x": -26,
      "y": 62,
      "z": -15,
      "name": "Plant_Leaves_Jungle_Max_Support"
    },
    {
      "x": -26,
      "y": 63,
      "z": -15,
      "name": "Plant_Leaves_Jungle_Max_Support"
    },
    {
      "x": -26,
      "y": 64,
      "z": -15,
      "name": "Plant_Leaves_Jungle_Max_Support"
    },
    {
      "x": -26,
      "y": 65,
      "z": -15,
      "name": "Plant_Leaves_Jungle_Max_Support"
    },
    {
      "x": -26,
      "y": 66,
      "z": -15,
      "name": "Plant_Leaves_Jungle_Max_Support"
    },
    {
      "x": -26,
      "y": 67,
      "z": -15,
      "name": "Plant_Leaves_Jungle_Max_Support"
    },
    {
      "x": -26,
      "y": 60,
      "z": -14,
      "name": "Plant_Leaves_Jungle_Max_Support"
    },
    {
      "x": -26,
      "y": 61,
      "z": -14,
      "name": "Plant_Leaves_Jungle_Max_Support"
    },
    {
      "x": -26,
      "y": 62,
      "z": -14,
      "name": "Plant_Leaves_Jungle_Max_Support"
    },
    {
      "x": -26,
      "y": 63,
      "z": -14,
      "name": "Plant_Leaves_Jungle_Max_Support"
    },
    {
      "x": -26,
      "y": 64,
      "z": -14,
      "name": "Plant_Leaves_Jungle_Max_Support"
    },
    {
      "x": -26,
      "y": 65,
      "z": -14,
      "name": "Plant_Leaves_Jungle_Max_Support"
    },
    {
      "x": -26,
      "y": 66,
      "z": -14,
      "name": "Plant_Leaves_Jungle_Max_Support"
    },
    {
      "x": -26,
      "y": 67,
      "z": -14,
      "name": "Plant_Leaves_Jungle_Max_Support"
    },
    {
      "x": -26,
      "y": 68,
      "z": -14,
      "name": "Plant_Leaves_Jungle_Max_Support"
    },
    {
      "x": -26,
      "y": 59,
      "z": -13,
      "name": "Plant_Leaves_Jungle_Max_Support"
    },
    {
      "x": -26,
      "y": 62,
      "z": -13,
      "name": "Plant_Leaves_Jungle_Max_Support"
    },
    {
      "x": -26,
      "y": 63,
      "z": -13,
      "name": "Plant_Leaves_Jungle_Max_Support"
    },
    {
      "x": -26,
      "y": 64,
      "z": -13,
      "name": "Plant_Leaves_Jungle_Max_Support"
    },
    {
      "x": -26,
      "y": 66,
      "z": -13,
      "name": "Plant_Leaves_Jungle_Max_Support"
    },
    {
      "x": -26,
      "y": 67,
      "z": -13,
      "name": "Plant_Leaves_Jungle_Max_Support"
    },
    {
      "x": -26,
      "y": 68,
      "z": -13,
      "name": "Plant_Leaves_Jungle_Max_Support"
    },
    {
      "x": -26,
      "y": 70,
      "z": -13,
      "name": "Plant_Leaves_Jungle_Max_Support"
    },
    {
      "x": -26,
      "y": 60,
      "z": -12,
      "name": "Plant_Leaves_Jungle_Max_Support"
    },
    {
      "x": -26,
      "y": 61,
      "z": -12,
      "name": "Plant_Leaves_Jungle_Max_Support"
    },
    {
      "x": -26,
      "y": 64,
      "z": -12,
      "name": "Plant_Leaves_Jungle_Max_Support"
    },
    {
      "x": -26,
      "y": 65,
      "z": -12,
      "name": "Plant_Leaves_Jungle_Max_Support"
    },
    {
      "x": -26,
      "y": 66,
      "z": -12,
      "name": "Plant_Leaves_Jungle_Max_Support"
    },
    {
      "x": -26,
      "y": 67,
      "z": -12,
      "name": "Plant_Leaves_Jungle_Max_Support"
    },
    {
      "x": -26,
      "y": 69,
      "z": -12,
      "name": "Plant_Leaves_Jungle_Max_Support"
    },
    {
      "x": -26,
      "y": 70,
      "z": -12,
      "name": "Plant_Leaves_Jungle_Max_Support"
    },
    {
      "x": -26,
      "y": 71,
      "z": -12,
      "name": "Plant_Leaves_Jungle_Max_Support"
    },
    {
      "x": -26,
      "y": 72,
      "z": -12,
      "name": "Plant_Leaves_Jungle_Max_Support"
    },
    {
      "x": -26,
      "y": 73,
      "z": -12,
      "name": "Plant_Leaves_Jungle_Max_Support"
    },
    {
      "x": -26,
      "y": 65,
      "z": -11,
      "name": "Plant_Leaves_Jungle_Max_Support"
    },
    {
      "x": -26,
      "y": 67,
      "z": -11,
      "name": "Plant_Leaves_Jungle_Max_Support"
    },
    {
      "x": -26,
      "y": 68,
      "z": -11,
      "name": "Plant_Leaves_Jungle_Max_Support"
    },
    {
      "x": -26,
      "y": 70,
      "z": -11,
      "name": "Plant_Leaves_Jungle_Max_Support"
    },
    {
      "x": -26,
      "y": 72,
      "z": -11,
      "name": "Plant_Leaves_Jungle_Max_Support"
    },
    {
      "x": -26,
      "y": 64,
      "z": -10,
      "name": "Plant_Leaves_Jungle_Max_Support"
    },
    {
      "x": -26,
      "y": 65,
      "z": -10,
      "name": "Plant_Leaves_Jungle_Max_Support"
    },
    {
      "x": -26,
      "y": 66,
      "z": -10,
      "name": "Plant_Leaves_Jungle_Max_Support"
    },
    {
      "x": -26,
      "y": 68,
      "z": -10,
      "name": "Plant_Leaves_Jungle_Max_Support"
    },
    {
      "x": -26,
      "y": 69,
      "z": -10,
      "name": "Plant_Leaves_Jungle_Max_Support"
    },
    {
      "x": -26,
      "y": 70,
      "z": -10,
      "name": "Plant_Leaves_Jungle_Max_Support"
    },
    {
      "x": -26,
      "y": 71,
      "z": -10,
      "name": "Plant_Leaves_Jungle_Max_Support"
    },
    {
      "x": -26,
      "y": 72,
      "z": -10,
      "name": "Plant_Leaves_Jungle_Max_Support"
    },
    {
      "x": -26,
      "y": 73,
      "z": -10,
      "name": "Plant_Leaves_Jungle_Max_Support"
    },
    {
      "x": -26,
      "y": 64,
      "z": -9,
      "name": "Plant_Leaves_Jungle_Max_Support"
    },
    {
      "x": -26,
      "y": 65,
      "z": -9,
      "name": "Plant_Leaves_Jungle_Max_Support"
    },
    {
      "x": -26,
      "y": 66,
      "z": -9,
      "name": "Plant_Leaves_Jungle_Max_Support"
    },
    {
      "x": -26,
      "y": 67,
      "z": -9,
      "name": "Plant_Leaves_Jungle_Max_Support"
    },
    {
      "x": -26,
      "y": 68,
      "z": -9,
      "name": "Plant_Leaves_Jungle_Max_Support"
    },
    {
      "x": -26,
      "y": 69,
      "z": -9,
      "name": "Plant_Leaves_Jungle_Max_Support"
    },
    {
      "x": -26,
      "y": 71,
      "z": -9,
      "name": "Plant_Leaves_Jungle_Max_Support"
    },
    {
      "x": -26,
      "y": 63,
      "z": -8,
      "name": "Plant_Leaves_Jungle_Max_Support"
    },
    {
      "x": -26,
      "y": 64,
      "z": -8,
      "name": "Plant_Leaves_Jungle_Max_Support"
    },
    {
      "x": -26,
      "y": 65,
      "z": -8,
      "name": "Plant_Leaves_Jungle_Max_Support"
    },
    {
      "x": -26,
      "y": 67,
      "z": -8,
      "name": "Plant_Leaves_Jungle_Max_Support"
    },
    {
      "x": -26,
      "y": 64,
      "z": -7,
      "name": "Plant_Leaves_Jungle_Max_Support"
    },
    {
      "x": -26,
      "y": 65,
      "z": -7,
      "name": "Plant_Leaves_Jungle_Max_Support"
    },
    {
      "x": -26,
      "y": 65,
      "z": -6,
      "name": "Plant_Leaves_Jungle_Max_Support"
    },
    {
      "x": -26,
      "y": 71,
      "z": -5,
      "name": "Plant_Leaves_Jungle_Max_Support"
    },
    {
      "x": -26,
      "y": 72,
      "z": -5,
      "name": "Plant_Leaves_Jungle_Max_Support"
    },
    {
      "x": -26,
      "y": 73,
      "z": -5,
      "name": "Plant_Leaves_Jungle_Max_Support"
    },
    {
      "x": -26,
      "y": 69,
      "z": -4,
      "name": "Plant_Leaves_Jungle_Max_Support"
    },
    {
      "x": -26,
      "y": 70,
      "z": -4,
      "name": "Plant_Leaves_Jungle_Max_Support"
    },
    {
      "x": -26,
      "y": 71,
      "z": -4,
      "name": "Plant_Leaves_Jungle_Max_Support"
    },
    {
      "x": -26,
      "y": 72,
      "z": -4,
      "name": "Plant_Leaves_Jungle_Max_Support"
    },
    {
      "x": -26,
      "y": 73,
      "z": -4,
      "name": "Plant_Leaves_Jungle_Max_Support"
    },
    {
      "x": -26,
      "y": 74,
      "z": -4,
      "name": "Plant_Leaves_Jungle_Max_Support"
    },
    {
      "x": -26,
      "y": 68,
      "z": -3,
      "name": "Plant_Leaves_Jungle_Max_Support"
    },
    {
      "x": -26,
      "y": 70,
      "z": -3,
      "name": "Plant_Leaves_Jungle_Max_Support"
    },
    {
      "x": -26,
      "y": 71,
      "z": -3,
      "name": "Plant_Leaves_Jungle_Max_Support"
    },
    {
      "x": -26,
      "y": 72,
      "z": -3,
      "name": "Plant_Leaves_Jungle_Max_Support"
    },
    {
      "x": -26,
      "y": 73,
      "z": -3,
      "name": "Plant_Leaves_Jungle_Max_Support"
    },
    {
      "x": -26,
      "y": 74,
      "z": -3,
      "name": "Plant_Leaves_Jungle_Max_Support"
    },
    {
      "x": -26,
      "y": 68,
      "z": -2,
      "name": "Plant_Leaves_Jungle_Max_Support"
    },
    {
      "x": -26,
      "y": 69,
      "z": -2,
      "name": "Plant_Leaves_Jungle_Max_Support"
    },
    {
      "x": -26,
      "y": 70,
      "z": -2,
      "name": "Plant_Leaves_Jungle_Max_Support"
    },
    {
      "x": -26,
      "y": 71,
      "z": -2,
      "name": "Plant_Leaves_Jungle_Max_Support"
    },
    {
      "x": -26,
      "y": 72,
      "z": -2,
      "name": "Plant_Leaves_Jungle_Max_Support"
    },
    {
      "x": -26,
      "y": 73,
      "z": -2,
      "name": "Plant_Leaves_Jungle_Max_Support"
    },
    {
      "x": -26,
      "y": 74,
      "z": -2,
      "name": "Plant_Leaves_Jungle_Max_Support"
    },
    {
      "x": -26,
      "y": 75,
      "z": -2,
      "name": "Plant_Leaves_Jungle_Max_Support"
    },
    {
      "x": -26,
      "y": 69,
      "z": -1,
      "name": "Plant_Leaves_Jungle_Max_Support"
    },
    {
      "x": -26,
      "y": 70,
      "z": -1,
      "name": "Plant_Leaves_Jungle_Max_Support"
    },
    {
      "x": -26,
      "y": 71,
      "z": -1,
      "name": "Plant_Leaves_Jungle_Max_Support"
    },
    {
      "x": -26,
      "y": 72,
      "z": -1,
      "name": "Plant_Leaves_Jungle_Max_Support"
    },
    {
      "x": -26,
      "y": 73,
      "z": -1,
      "name": "Plant_Leaves_Jungle_Max_Support"
    },
    {
      "x": -26,
      "y": 74,
      "z": -1,
      "name": "Plant_Leaves_Jungle_Max_Support"
    },
    {
      "x": -26,
      "y": 75,
      "z": -1,
      "name": "Plant_Leaves_Jungle_Max_Support"
    },
    {
      "x": -26,
      "y": 68,
      "z": 0,
      "name": "Plant_Leaves_Jungle_Max_Support"
    },
    {
      "x": -26,
      "y": 69,
      "z": 0,
      "name": "Plant_Leaves_Jungle_Max_Support"
    },
    {
      "x": -26,
      "y": 70,
      "z": 0,
      "name": "Plant_Leaves_Jungle_Max_Support"
    },
    {
      "x": -26,
      "y": 71,
      "z": 0,
      "name": "Plant_Leaves_Jungle_Max_Support"
    },
    {
      "x": -26,
      "y": 72,
      "z": 0,
      "name": "Plant_Leaves_Jungle_Max_Support"
    },
    {
      "x": -26,
      "y": 73,
      "z": 0,
      "name": "Plant_Leaves_Jungle_Max_Support"
    },
    {
      "x": -26,
      "y": 74,
      "z": 0,
      "name": "Plant_Leaves_Jungle_Max_Support"
    },
    {
      "x": -26,
      "y": 75,
      "z": 0,
      "name": "Plant_Leaves_Jungle_Max_Support"
    },
    {
      "x": -26,
      "y": 76,
      "z": 0,
      "name": "Plant_Leaves_Jungle_Max_Support"
    },
    {
      "x": -26,
      "y": 68,
      "z": 1,
      "name": "Plant_Leaves_Jungle_Max_Support"
    },
    {
      "x": -26,
      "y": 69,
      "z": 1,
      "name": "Plant_Leaves_Jungle_Max_Support"
    },
    {
      "x": -26,
      "y": 70,
      "z": 1,
      "name": "Plant_Leaves_Jungle_Max_Support"
    },
    {
      "x": -26,
      "y": 71,
      "z": 1,
      "name": "Plant_Leaves_Jungle_Max_Support"
    },
    {
      "x": -26,
      "y": 72,
      "z": 1,
      "name": "Plant_Leaves_Jungle_Max_Support"
    },
    {
      "x": -26,
      "y": 74,
      "z": 1,
      "name": "Plant_Leaves_Jungle_Max_Support"
    },
    {
      "x": -26,
      "y": 75,
      "z": 1,
      "name": "Plant_Leaves_Jungle_Max_Support"
    },
    {
      "x": -26,
      "y": 76,
      "z": 1,
      "name": "Plant_Leaves_Jungle_Max_Support"
    },
    {
      "x": -26,
      "y": 68,
      "z": 2,
      "name": "Plant_Leaves_Jungle_Max_Support"
    },
    {
      "x": -26,
      "y": 69,
      "z": 2,
      "name": "Plant_Leaves_Jungle_Max_Support"
    },
    {
      "x": -26,
      "y": 70,
      "z": 2,
      "name": "Plant_Leaves_Jungle_Max_Support"
    },
    {
      "x": -26,
      "y": 71,
      "z": 2,
      "name": "Plant_Leaves_Jungle_Max_Support"
    },
    {
      "x": -26,
      "y": 72,
      "z": 2,
      "name": "Plant_Leaves_Jungle_Max_Support"
    },
    {
      "x": -26,
      "y": 73,
      "z": 2,
      "name": "Plant_Leaves_Jungle_Max_Support"
    },
    {
      "x": -26,
      "y": 74,
      "z": 2,
      "name": "Plant_Leaves_Jungle_Max_Support"
    },
    {
      "x": -26,
      "y": 66,
      "z": 3,
      "name": "Plant_Leaves_Jungle_Max_Support"
    },
    {
      "x": -26,
      "y": 67,
      "z": 3,
      "name": "Plant_Leaves_Jungle_Max_Support"
    },
    {
      "x": -26,
      "y": 68,
      "z": 3,
      "name": "Plant_Leaves_Jungle_Max_Support"
    },
    {
      "x": -26,
      "y": 69,
      "z": 3,
      "name": "Plant_Leaves_Jungle_Max_Support"
    },
    {
      "x": -26,
      "y": 70,
      "z": 3,
      "name": "Plant_Leaves_Jungle_Max_Support"
    },
    {
      "x": -26,
      "y": 71,
      "z": 3,
      "name": "Plant_Leaves_Jungle_Max_Support"
    },
    {
      "x": -26,
      "y": 72,
      "z": 3,
      "name": "Plant_Leaves_Jungle_Max_Support"
    },
    {
      "x": -26,
      "y": 73,
      "z": 3,
      "name": "Plant_Leaves_Jungle_Max_Support"
    },
    {
      "x": -26,
      "y": 67,
      "z": 4,
      "name": "Plant_Leaves_Jungle_Max_Support"
    },
    {
      "x": -26,
      "y": 68,
      "z": 4,
      "name": "Plant_Leaves_Jungle_Max_Support"
    },
    {
      "x": -26,
      "y": 69,
      "z": 4,
      "name": "Plant_Leaves_Jungle_Max_Support"
    },
    {
      "x": -26,
      "y": 70,
      "z": 4,
      "name": "Plant_Leaves_Jungle_Max_Support"
    },
    {
      "x": -26,
      "y": 71,
      "z": 4,
      "name": "Plant_Leaves_Jungle_Max_Support"
    },
    {
      "x": -26,
      "y": 68,
      "z": 5,
      "name": "Plant_Leaves_Jungle_Max_Support"
    },
    {
      "x": -26,
      "y": 69,
      "z": 5,
      "name": "Plant_Leaves_Jungle_Max_Support"
    },
    {
      "x": -26,
      "y": 70,
      "z": 5,
      "name": "Plant_Leaves_Jungle_Max_Support"
    },
    {
      "x": -25,
      "y": 66,
      "z": -20,
      "name": "Plant_Leaves_Jungle_Max_Support"
    },
    {
      "x": -25,
      "y": 67,
      "z": -20,
      "name": "Plant_Leaves_Jungle_Max_Support"
    },
    {
      "x": -25,
      "y": 59,
      "z": -19,
      "name": "Plant_Leaves_Jungle_Max_Support"
    },
    {
      "x": -25,
      "y": 60,
      "z": -19,
      "name": "Plant_Leaves_Jungle_Max_Support"
    },
    {
      "x": -25,
      "y": 61,
      "z": -19,
      "name": "Plant_Leaves_Jungle_Max_Support"
    },
    {
      "x": -25,
      "y": 62,
      "z": -19,
      "name": "Plant_Leaves_Jungle_Max_Support"
    },
    {
      "x": -25,
      "y": 64,
      "z": -19,
      "name": "Plant_Leaves_Jungle_Max_Support"
    },
    {
      "x": -25,
      "y": 66,
      "z": -19,
      "name": "Plant_Leaves_Jungle_Max_Support"
    },
    {
      "x": -25,
      "y": 67,
      "z": -19,
      "name": "Plant_Leaves_Jungle_Max_Support"
    },
    {
      "x": -25,
      "y": 68,
      "z": -19,
      "name": "Plant_Leaves_Jungle_Max_Support"
    },
    {
      "x": -25,
      "y": 60,
      "z": -18,
      "name": "Plant_Leaves_Jungle_Max_Support"
    },
    {
      "x": -25,
      "y": 61,
      "z": -18,
      "name": "Plant_Leaves_Jungle_Max_Support"
    },
    {
      "x": -25,
      "y": 62,
      "z": -18,
      "name": "Plant_Leaves_Jungle_Max_Support"
    },
    {
      "x": -25,
      "y": 63,
      "z": -18,
      "name": "Plant_Leaves_Jungle_Max_Support"
    },
    {
      "x": -25,
      "y": 64,
      "z": -18,
      "name": "Plant_Leaves_Jungle_Max_Support"
    },
    {
      "x": -25,
      "y": 65,
      "z": -18,
      "name": "Plant_Leaves_Jungle_Max_Support"
    },
    {
      "x": -25,
      "y": 66,
      "z": -18,
      "name": "Plant_Leaves_Jungle_Max_Support"
    },
    {
      "x": -25,
      "y": 67,
      "z": -18,
      "name": "Plant_Leaves_Jungle_Max_Support"
    },
    {
      "x": -25,
      "y": 69,
      "z": -18,
      "name": "Plant_Leaves_Jungle_Max_Support"
    },
    {
      "x": -25,
      "y": 58,
      "z": -17,
      "name": "Plant_Leaves_Jungle_Max_Support"
    },
    {
      "x": -25,
      "y": 59,
      "z": -17,
      "name": "Plant_Leaves_Jungle_Max_Support"
    },
    {
      "x": -25,
      "y": 60,
      "z": -17,
      "name": "Plant_Leaves_Jungle_Max_Support"
    },
    {
      "x": -25,
      "y": 61,
      "z": -17,
      "name": "Plant_Leaves_Jungle_Max_Support"
    },
    {
      "x": -25,
      "y": 62,
      "z": -17,
      "name": "Plant_Leaves_Jungle_Max_Support"
    },
    {
      "x": -25,
      "y": 63,
      "z": -17,
      "name": "Plant_Leaves_Jungle_Max_Support"
    },
    {
      "x": -25,
      "y": 64,
      "z": -17,
      "name": "Plant_Leaves_Jungle_Max_Support"
    },
    {
      "x": -25,
      "y": 65,
      "z": -17,
      "name": "Plant_Leaves_Jungle_Max_Support"
    },
    {
      "x": -25,
      "y": 66,
      "z": -17,
      "name": "Plant_Leaves_Jungle_Max_Support"
    },
    {
      "x": -25,
      "y": 67,
      "z": -17,
      "name": "Plant_Leaves_Jungle_Max_Support"
    },
    {
      "x": -25,
      "y": 68,
      "z": -17,
      "name": "Plant_Leaves_Jungle_Max_Support"
    },
    {
      "x": -25,
      "y": 58,
      "z": -16,
      "name": "Plant_Leaves_Jungle_Max_Support"
    },
    {
      "x": -25,
      "y": 59,
      "z": -16,
      "name": "Plant_Leaves_Jungle_Max_Support"
    },
    {
      "x": -25,
      "y": 61,
      "z": -16,
      "name": "Plant_Leaves_Jungle_Max_Support"
    },
    {
      "x": -25,
      "y": 62,
      "z": -16,
      "name": "Plant_Leaves_Jungle_Max_Support"
    },
    {
      "x": -25,
      "y": 63,
      "z": -16,
      "name": "Plant_Leaves_Jungle_Max_Support"
    },
    {
      "x": -25,
      "y": 64,
      "z": -16,
      "name": "Plant_Leaves_Jungle_Max_Support"
    },
    {
      "x": -25,
      "y": 65,
      "z": -16,
      "name": "Plant_Leaves_Jungle_Max_Support"
    },
    {
      "x": -25,
      "y": 66,
      "z": -16,
      "name": "Plant_Leaves_Jungle_Max_Support"
    },
    {
      "x": -25,
      "y": 67,
      "z": -16,
      "name": "Plant_Leaves_Jungle_Max_Support"
    },
    {
      "x": -25,
      "y": 69,
      "z": -16,
      "name": "Plant_Leaves_Jungle_Max_Support"
    },
    {
      "x": -25,
      "y": 59,
      "z": -15,
      "name": "Plant_Leaves_Jungle_Max_Support"
    },
    {
      "x": -25,
      "y": 60,
      "z": -15,
      "name": "Plant_Leaves_Jungle_Max_Support"
    },
    {
      "x": -25,
      "y": 61,
      "z": -15,
      "name": "Plant_Leaves_Jungle_Max_Support"
    },
    {
      "x": -25,
      "y": 62,
      "z": -15,
      "name": "Plant_Leaves_Jungle_Max_Support"
    },
    {
      "x": -25,
      "y": 63,
      "z": -15,
      "name": "Plant_Leaves_Jungle_Max_Support"
    },
    {
      "x": -25,
      "y": 64,
      "z": -15,
      "name": "Plant_Leaves_Jungle_Max_Support"
    },
    {
      "x": -25,
      "y": 65,
      "z": -15,
      "name": "Plant_Leaves_Jungle_Max_Support"
    },
    {
      "x": -25,
      "y": 66,
      "z": -15,
      "name": "Plant_Leaves_Jungle_Max_Support"
    },
    {
      "x": -25,
      "y": 68,
      "z": -15,
      "name": "Plant_Leaves_Jungle_Max_Support"
    },
    {
      "x": -25,
      "y": 59,
      "z": -14,
      "name": "Plant_Leaves_Jungle_Max_Support"
    },
    {
      "x": -25,
      "y": 62,
      "z": -14,
      "name": "Plant_Leaves_Jungle_Max_Support"
    },
    {
      "x": -25,
      "y": 63,
      "z": -14,
      "name": "Plant_Leaves_Jungle_Max_Support"
    },
    {
      "x": -25,
      "y": 64,
      "z": -14,
      "name": "Plant_Leaves_Jungle_Max_Support"
    },
    {
      "x": -25,
      "y": 65,
      "z": -14,
      "name": "Plant_Leaves_Jungle_Max_Support"
    },
    {
      "x": -25,
      "y": 67,
      "z": -14,
      "name": "Plant_Leaves_Jungle_Max_Support"
    },
    {
      "x": -25,
      "y": 68,
      "z": -14,
      "name": "Plant_Leaves_Jungle_Max_Support"
    },
    {
      "x": -25,
      "y": 69,
      "z": -14,
      "name": "Plant_Leaves_Jungle_Max_Support"
    },
    {
      "x": -25,
      "y": 71,
      "z": -14,
      "name": "Plant_Leaves_Jungle_Max_Support"
    },
    {
      "x": -25,
      "y": 72,
      "z": -14,
      "name": "Plant_Leaves_Jungle_Max_Support"
    },
    {
      "x": -25,
      "y": 63,
      "z": -13,
      "name": "Plant_Leaves_Jungle_Max_Support"
    },
    {
      "x": -25,
      "y": 64,
      "z": -13,
      "name": "Plant_Leaves_Jungle_Max_Support"
    },
    {
      "x": -25,
      "y": 65,
      "z": -13,
      "name": "Plant_Leaves_Jungle_Max_Support"
    },
    {
      "x": -25,
      "y": 66,
      "z": -13,
      "name": "Plant_Leaves_Jungle_Max_Support"
    },
    {
      "x": -25,
      "y": 67,
      "z": -13,
      "name": "Plant_Leaves_Jungle_Max_Support"
    },
    {
      "x": -25,
      "y": 68,
      "z": -13,
      "name": "Plant_Leaves_Jungle_Max_Support"
    },
    {
      "x": -25,
      "y": 69,
      "z": -13,
      "name": "Plant_Leaves_Jungle_Max_Support"
    },
    {
      "x": -25,
      "y": 70,
      "z": -13,
      "name": "Plant_Leaves_Jungle_Max_Support"
    },
    {
      "x": -25,
      "y": 72,
      "z": -13,
      "name": "Plant_Leaves_Jungle_Max_Support"
    },
    {
      "x": -25,
      "y": 61,
      "z": -12,
      "name": "Plant_Leaves_Jungle_Max_Support"
    },
    {
      "x": -25,
      "y": 63,
      "z": -12,
      "name": "Plant_Leaves_Jungle_Max_Support"
    },
    {
      "x": -25,
      "y": 64,
      "z": -12,
      "name": "Plant_Leaves_Jungle_Max_Support"
    },
    {
      "x": -25,
      "y": 65,
      "z": -12,
      "name": "Plant_Leaves_Jungle_Max_Support"
    },
    {
      "x": -25,
      "y": 66,
      "z": -12,
      "name": "Plant_Leaves_Jungle_Max_Support"
    },
    {
      "x": -25,
      "y": 67,
      "z": -12,
      "name": "Plant_Leaves_Jungle_Max_Support"
    },
    {
      "x": -25,
      "y": 68,
      "z": -12,
      "name": "Plant_Leaves_Jungle_Max_Support"
    },
    {
      "x": -25,
      "y": 69,
      "z": -12,
      "name": "Plant_Leaves_Jungle_Max_Support"
    },
    {
      "x": -25,
      "y": 70,
      "z": -12,
      "name": "Plant_Leaves_Jungle_Max_Support"
    },
    {
      "x": -25,
      "y": 71,
      "z": -12,
      "name": "Plant_Leaves_Jungle_Max_Support"
    },
    {
      "x": -25,
      "y": 73,
      "z": -12,
      "name": "Plant_Leaves_Jungle_Max_Support"
    },
    {
      "x": -25,
      "y": 64,
      "z": -11,
      "name": "Plant_Leaves_Jungle_Max_Support"
    },
    {
      "x": -25,
      "y": 65,
      "z": -11,
      "name": "Plant_Leaves_Jungle_Max_Support"
    },
    {
      "x": -25,
      "y": 66,
      "z": -11,
      "name": "Plant_Leaves_Jungle_Max_Support"
    },
    {
      "x": -25,
      "y": 67,
      "z": -11,
      "name": "Plant_Leaves_Jungle_Max_Support"
    },
    {
      "x": -25,
      "y": 68,
      "z": -11,
      "name": "Plant_Leaves_Jungle_Max_Support"
    },
    {
      "x": -25,
      "y": 69,
      "z": -11,
      "name": "Plant_Leaves_Jungle_Max_Support"
    },
    {
      "x": -25,
      "y": 70,
      "z": -11,
      "name": "Plant_Leaves_Jungle_Max_Support"
    },
    {
      "x": -25,
      "y": 71,
      "z": -11,
      "name": "Plant_Leaves_Jungle_Max_Support"
    },
    {
      "x": -25,
      "y": 72,
      "z": -11,
      "name": "Plant_Leaves_Jungle_Max_Support"
    },
    {
      "x": -25,
      "y": 64,
      "z": -10,
      "name": "Plant_Leaves_Jungle_Max_Support"
    },
    {
      "x": -25,
      "y": 66,
      "z": -10,
      "name": "Plant_Leaves_Jungle_Max_Support"
    },
    {
      "x": -25,
      "y": 67,
      "z": -10,
      "name": "Plant_Leaves_Jungle_Max_Support"
    },
    {
      "x": -25,
      "y": 68,
      "z": -10,
      "name": "Plant_Leaves_Jungle_Max_Support"
    },
    {
      "x": -25,
      "y": 69,
      "z": -10,
      "name": "Plant_Leaves_Jungle_Max_Support"
    },
    {
      "x": -25,
      "y": 70,
      "z": -10,
      "name": "Plant_Leaves_Jungle_Max_Support"
    },
    {
      "x": -25,
      "y": 71,
      "z": -10,
      "name": "Plant_Leaves_Jungle_Max_Support"
    },
    {
      "x": -25,
      "y": 73,
      "z": -10,
      "name": "Plant_Leaves_Jungle_Max_Support"
    },
    {
      "x": -25,
      "y": 74,
      "z": -10,
      "name": "Plant_Leaves_Jungle_Max_Support"
    },
    {
      "x": -25,
      "y": 63,
      "z": -9,
      "name": "Plant_Leaves_Jungle_Max_Support"
    },
    {
      "x": -25,
      "y": 64,
      "z": -9,
      "name": "Plant_Leaves_Jungle_Max_Support"
    },
    {
      "x": -25,
      "y": 65,
      "z": -9,
      "name": "Plant_Leaves_Jungle_Max_Support"
    },
    {
      "x": -25,
      "y": 66,
      "z": -9,
      "name": "Plant_Leaves_Jungle_Max_Support"
    },
    {
      "x": -25,
      "y": 67,
      "z": -9,
      "name": "Plant_Leaves_Jungle_Max_Support"
    },
    {
      "x": -25,
      "y": 68,
      "z": -9,
      "name": "Plant_Leaves_Jungle_Max_Support"
    },
    {
      "x": -25,
      "y": 69,
      "z": -9,
      "name": "Plant_Leaves_Jungle_Max_Support"
    },
    {
      "x": -25,
      "y": 72,
      "z": -9,
      "name": "Plant_Leaves_Jungle_Max_Support"
    },
    {
      "x": -25,
      "y": 73,
      "z": -9,
      "name": "Plant_Leaves_Jungle_Max_Support"
    },
    {
      "x": -25,
      "y": 63,
      "z": -8,
      "name": "Plant_Leaves_Jungle_Max_Support"
    },
    {
      "x": -25,
      "y": 64,
      "z": -8,
      "name": "Plant_Leaves_Jungle_Max_Support"
    },
    {
      "x": -25,
      "y": 65,
      "z": -8,
      "name": "Plant_Leaves_Jungle_Max_Support"
    },
    {
      "x": -25,
      "y": 66,
      "z": -8,
      "name": "Plant_Leaves_Jungle_Max_Support"
    },
    {
      "x": -25,
      "y": 67,
      "z": -8,
      "name": "Plant_Leaves_Jungle_Max_Support"
    },
    {
      "x": -25,
      "y": 68,
      "z": -8,
      "name": "Plant_Leaves_Jungle_Max_Support"
    },
    {
      "x": -25,
      "y": 71,
      "z": -8,
      "name": "Plant_Leaves_Jungle_Max_Support"
    },
    {
      "x": -25,
      "y": 63,
      "z": -7,
      "name": "Plant_Leaves_Jungle_Max_Support"
    },
    {
      "x": -25,
      "y": 64,
      "z": -7,
      "name": "Plant_Leaves_Jungle_Max_Support"
    },
    {
      "x": -25,
      "y": 65,
      "z": -7,
      "name": "Plant_Leaves_Jungle_Max_Support"
    },
    {
      "x": -25,
      "y": 66,
      "z": -7,
      "name": "Plant_Leaves_Jungle_Max_Support"
    },
    {
      "x": -25,
      "y": 67,
      "z": -7,
      "name": "Plant_Leaves_Jungle_Max_Support"
    },
    {
      "x": -25,
      "y": 63,
      "z": -6,
      "name": "Plant_Leaves_Jungle_Max_Support"
    },
    {
      "x": -25,
      "y": 64,
      "z": -6,
      "name": "Plant_Leaves_Jungle_Max_Support"
    },
    {
      "x": -25,
      "y": 65,
      "z": -6,
      "name": "Plant_Leaves_Jungle_Max_Support"
    },
    {
      "x": -25,
      "y": 66,
      "z": -6,
      "name": "Plant_Leaves_Jungle_Max_Support"
    },
    {
      "x": -25,
      "y": 72,
      "z": -6,
      "name": "Plant_Leaves_Jungle_Max_Support"
    },
    {
      "x": -25,
      "y": 70,
      "z": -5,
      "name": "Plant_Leaves_Jungle_Max_Support"
    },
    {
      "x": -25,
      "y": 71,
      "z": -5,
      "name": "Plant_Leaves_Jungle_Max_Support"
    },
    {
      "x": -25,
      "y": 72,
      "z": -5,
      "name": "Plant_Leaves_Jungle_Max_Support"
    },
    {
      "x": -25,
      "y": 73,
      "z": -5,
      "name": "Plant_Leaves_Jungle_Max_Support"
    },
    {
      "x": -25,
      "y": 68,
      "z": -4,
      "name": "Plant_Leaves_Jungle_Max_Support"
    },
    {
      "x": -25,
      "y": 69,
      "z": -4,
      "name": "Plant_Leaves_Jungle_Max_Support"
    },
    {
      "x": -25,
      "y": 70,
      "z": -4,
      "name": "Plant_Leaves_Jungle_Max_Support"
    },
    {
      "x": -25,
      "y": 71,
      "z": -4,
      "name": "Plant_Leaves_Jungle_Max_Support"
    },
    {
      "x": -25,
      "y": 72,
      "z": -4,
      "name": "Plant_Leaves_Jungle_Max_Support"
    },
    {
      "x": -25,
      "y": 73,
      "z": -4,
      "name": "Plant_Leaves_Jungle_Max_Support"
    },
    {
      "x": -25,
      "y": 68,
      "z": -3,
      "name": "Plant_Leaves_Jungle_Max_Support"
    },
    {
      "x": -25,
      "y": 69,
      "z": -3,
      "name": "Plant_Leaves_Jungle_Max_Support"
    },
    {
      "x": -25,
      "y": 71,
      "z": -3,
      "name": "Plant_Leaves_Jungle_Max_Support"
    },
    {
      "x": -25,
      "y": 72,
      "z": -3,
      "name": "Plant_Leaves_Jungle_Max_Support"
    },
    {
      "x": -25,
      "y": 73,
      "z": -3,
      "name": "Plant_Leaves_Jungle_Max_Support"
    },
    {
      "x": -25,
      "y": 74,
      "z": -3,
      "name": "Plant_Leaves_Jungle_Max_Support"
    },
    {
      "x": -25,
      "y": 68,
      "z": -2,
      "name": "Plant_Leaves_Jungle_Max_Support"
    },
    {
      "x": -25,
      "y": 69,
      "z": -2,
      "name": "Plant_Leaves_Jungle_Max_Support"
    },
    {
      "x": -25,
      "y": 70,
      "z": -2,
      "name": "Plant_Leaves_Jungle_Max_Support"
    },
    {
      "x": -25,
      "y": 71,
      "z": -2,
      "name": "Plant_Leaves_Jungle_Max_Support"
    },
    {
      "x": -25,
      "y": 72,
      "z": -2,
      "name": "Plant_Leaves_Jungle_Max_Support"
    },
    {
      "x": -25,
      "y": 73,
      "z": -2,
      "name": "Plant_Leaves_Jungle_Max_Support"
    },
    {
      "x": -25,
      "y": 74,
      "z": -2,
      "name": "Plant_Leaves_Jungle_Max_Support"
    },
    {
      "x": -25,
      "y": 68,
      "z": -1,
      "name": "Plant_Leaves_Jungle_Max_Support"
    },
    {
      "x": -25,
      "y": 69,
      "z": -1,
      "name": "Plant_Leaves_Jungle_Max_Support"
    },
    {
      "x": -25,
      "y": 70,
      "z": -1,
      "name": "Plant_Leaves_Jungle_Max_Support"
    },
    {
      "x": -25,
      "y": 71,
      "z": -1,
      "name": "Plant_Leaves_Jungle_Max_Support"
    },
    {
      "x": -25,
      "y": 72,
      "z": -1,
      "name": "Plant_Leaves_Jungle_Max_Support"
    },
    {
      "x": -25,
      "y": 73,
      "z": -1,
      "name": "Plant_Leaves_Jungle_Max_Support"
    },
    {
      "x": -25,
      "y": 74,
      "z": -1,
      "name": "Plant_Leaves_Jungle_Max_Support"
    },
    {
      "x": -25,
      "y": 75,
      "z": -1,
      "name": "Plant_Leaves_Jungle_Max_Support"
    },
    {
      "x": -25,
      "y": 68,
      "z": 0,
      "name": "Plant_Leaves_Jungle_Max_Support"
    },
    {
      "x": -25,
      "y": 69,
      "z": 0,
      "name": "Plant_Leaves_Jungle_Max_Support"
    },
    {
      "x": -25,
      "y": 70,
      "z": 0,
      "name": "Plant_Leaves_Jungle_Max_Support"
    },
    {
      "x": -25,
      "y": 71,
      "z": 0,
      "name": "Plant_Leaves_Jungle_Max_Support"
    },
    {
      "x": -25,
      "y": 72,
      "z": 0,
      "name": "Plant_Leaves_Jungle_Max_Support"
    },
    {
      "x": -25,
      "y": 73,
      "z": 0,
      "name": "Plant_Leaves_Jungle_Max_Support"
    },
    {
      "x": -25,
      "y": 74,
      "z": 0,
      "name": "Plant_Leaves_Jungle_Max_Support"
    },
    {
      "x": -25,
      "y": 75,
      "z": 0,
      "name": "Plant_Leaves_Jungle_Max_Support"
    },
    {
      "x": -25,
      "y": 76,
      "z": 0,
      "name": "Plant_Leaves_Jungle_Max_Support"
    },
    {
      "x": -25,
      "y": 68,
      "z": 1,
      "name": "Plant_Leaves_Jungle_Max_Support"
    },
    {
      "x": -25,
      "y": 69,
      "z": 1,
      "name": "Plant_Leaves_Jungle_Max_Support"
    },
    {
      "x": -25,
      "y": 70,
      "z": 1,
      "name": "Plant_Leaves_Jungle_Max_Support"
    },
    {
      "x": -25,
      "y": 71,
      "z": 1,
      "name": "Plant_Leaves_Jungle_Max_Support"
    },
    {
      "x": -25,
      "y": 72,
      "z": 1,
      "name": "Plant_Leaves_Jungle_Max_Support"
    },
    {
      "x": -25,
      "y": 73,
      "z": 1,
      "name": "Plant_Leaves_Jungle_Max_Support"
    },
    {
      "x": -25,
      "y": 74,
      "z": 1,
      "name": "Plant_Leaves_Jungle_Max_Support"
    },
    {
      "x": -25,
      "y": 75,
      "z": 1,
      "name": "Plant_Leaves_Jungle_Max_Support"
    },
    {
      "x": -25,
      "y": 66,
      "z": 2,
      "name": "Plant_Leaves_Jungle_Max_Support"
    },
    {
      "x": -25,
      "y": 68,
      "z": 2,
      "name": "Plant_Leaves_Jungle_Max_Support"
    },
    {
      "x": -25,
      "y": 69,
      "z": 2,
      "name": "Plant_Leaves_Jungle_Max_Support"
    },
    {
      "x": -25,
      "y": 70,
      "z": 2,
      "name": "Plant_Leaves_Jungle_Max_Support"
    },
    {
      "x": -25,
      "y": 71,
      "z": 2,
      "name": "Plant_Leaves_Jungle_Max_Support"
    },
    {
      "x": -25,
      "y": 72,
      "z": 2,
      "name": "Plant_Leaves_Jungle_Max_Support"
    },
    {
      "x": -25,
      "y": 75,
      "z": 2,
      "name": "Plant_Leaves_Jungle_Max_Support"
    },
    {
      "x": -25,
      "y": 66,
      "z": 3,
      "name": "Plant_Leaves_Jungle_Max_Support"
    },
    {
      "x": -25,
      "y": 67,
      "z": 3,
      "name": "Plant_Leaves_Jungle_Max_Support"
    },
    {
      "x": -25,
      "y": 68,
      "z": 3,
      "name": "Plant_Leaves_Jungle_Max_Support"
    },
    {
      "x": -25,
      "y": 69,
      "z": 3,
      "name": "Plant_Leaves_Jungle_Max_Support"
    },
    {
      "x": -25,
      "y": 70,
      "z": 3,
      "name": "Plant_Leaves_Jungle_Max_Support"
    },
    {
      "x": -25,
      "y": 71,
      "z": 3,
      "name": "Plant_Leaves_Jungle_Max_Support"
    },
    {
      "x": -25,
      "y": 72,
      "z": 3,
      "name": "Plant_Leaves_Jungle_Max_Support"
    },
    {
      "x": -25,
      "y": 73,
      "z": 3,
      "name": "Plant_Leaves_Jungle_Max_Support"
    },
    {
      "x": -25,
      "y": 68,
      "z": 4,
      "name": "Plant_Leaves_Jungle_Max_Support"
    },
    {
      "x": -25,
      "y": 69,
      "z": 5,
      "name": "Plant_Leaves_Jungle_Max_Support"
    },
    {
      "x": -25,
      "y": 78,
      "z": 9,
      "name": "Plant_Leaves_Jungle_Max_Support"
    },
    {
      "x": -25,
      "y": 77,
      "z": 10,
      "name": "Plant_Leaves_Jungle_Max_Support"
    },
    {
      "x": -25,
      "y": 79,
      "z": 10,
      "name": "Plant_Leaves_Jungle_Max_Support"
    },
    {
      "x": -25,
      "y": 81,
      "z": 10,
      "name": "Plant_Leaves_Jungle_Max_Support"
    },
    {
      "x": -25,
      "y": 79,
      "z": 11,
      "name": "Plant_Leaves_Jungle_Max_Support"
    },
    {
      "x": -25,
      "y": 80,
      "z": 12,
      "name": "Plant_Leaves_Jungle_Max_Support"
    },
    {
      "x": -25,
      "y": 81,
      "z": 12,
      "name": "Plant_Leaves_Jungle_Max_Support"
    },
    {
      "x": -24,
      "y": 67,
      "z": -20,
      "name": "Plant_Leaves_Jungle_Max_Support"
    },
    {
      "x": -24,
      "y": 61,
      "z": -19,
      "name": "Plant_Leaves_Jungle_Max_Support"
    },
    {
      "x": -24,
      "y": 62,
      "z": -19,
      "name": "Plant_Leaves_Jungle_Max_Support"
    },
    {
      "x": -24,
      "y": 63,
      "z": -19,
      "name": "Plant_Leaves_Jungle_Max_Support"
    },
    {
      "x": -24,
      "y": 64,
      "z": -19,
      "name": "Plant_Leaves_Jungle_Max_Support"
    },
    {
      "x": -24,
      "y": 65,
      "z": -19,
      "name": "Plant_Leaves_Jungle_Max_Support"
    },
    {
      "x": -24,
      "y": 67,
      "z": -19,
      "name": "Plant_Leaves_Jungle_Max_Support"
    },
    {
      "x": -24,
      "y": 60,
      "z": -18,
      "name": "Plant_Leaves_Jungle_Max_Support"
    },
    {
      "x": -24,
      "y": 61,
      "z": -18,
      "name": "Plant_Leaves_Jungle_Max_Support"
    },
    {
      "x": -24,
      "y": 62,
      "z": -18,
      "name": "Plant_Leaves_Jungle_Max_Support"
    },
    {
      "x": -24,
      "y": 63,
      "z": -18,
      "name": "Plant_Leaves_Jungle_Max_Support"
    },
    {
      "x": -24,
      "y": 64,
      "z": -18,
      "name": "Plant_Leaves_Jungle_Max_Support"
    },
    {
      "x": -24,
      "y": 65,
      "z": -18,
      "name": "Plant_Leaves_Jungle_Max_Support"
    },
    {
      "x": -24,
      "y": 66,
      "z": -18,
      "name": "Plant_Leaves_Jungle_Max_Support"
    },
    {
      "x": -24,
      "y": 69,
      "z": -18,
      "name": "Plant_Leaves_Jungle_Max_Support"
    },
    {
      "x": -24,
      "y": 58,
      "z": -17,
      "name": "Plant_Leaves_Jungle_Max_Support"
    },
    {
      "x": -24,
      "y": 59,
      "z": -17,
      "name": "Plant_Leaves_Jungle_Max_Support"
    },
    {
      "x": -24,
      "y": 60,
      "z": -17,
      "name": "Plant_Leaves_Jungle_Max_Support"
    },
    {
      "x": -24,
      "y": 61,
      "z": -17,
      "name": "Plant_Leaves_Jungle_Max_Support"
    },
    {
      "x": -24,
      "y": 62,
      "z": -17,
      "name": "Plant_Leaves_Jungle_Max_Support"
    },
    {
      "x": -24,
      "y": 63,
      "z": -17,
      "name": "Plant_Leaves_Jungle_Max_Support"
    },
    {
      "x": -24,
      "y": 64,
      "z": -17,
      "name": "Plant_Leaves_Jungle_Max_Support"
    },
    {
      "x": -24,
      "y": 65,
      "z": -17,
      "name": "Plant_Leaves_Jungle_Max_Support"
    },
    {
      "x": -24,
      "y": 66,
      "z": -17,
      "name": "Plant_Leaves_Jungle_Max_Support"
    },
    {
      "x": -24,
      "y": 69,
      "z": -17,
      "name": "Plant_Leaves_Jungle_Max_Support"
    },
    {
      "x": -24,
      "y": 59,
      "z": -16,
      "name": "Plant_Leaves_Jungle_Max_Support"
    },
    {
      "x": -24,
      "y": 60,
      "z": -16,
      "name": "Plant_Leaves_Jungle_Max_Support"
    },
    {
      "x": -24,
      "y": 61,
      "z": -16,
      "name": "Plant_Leaves_Jungle_Max_Support"
    },
    {
      "x": -24,
      "y": 62,
      "z": -16,
      "name": "Plant_Leaves_Jungle_Max_Support"
    },
    {
      "x": -24,
      "y": 63,
      "z": -16,
      "name": "Plant_Leaves_Jungle_Max_Support"
    },
    {
      "x": -24,
      "y": 64,
      "z": -16,
      "name": "Plant_Leaves_Jungle_Max_Support"
    },
    {
      "x": -24,
      "y": 65,
      "z": -16,
      "name": "Plant_Leaves_Jungle_Max_Support"
    },
    {
      "x": -24,
      "y": 66,
      "z": -16,
      "name": "Plant_Leaves_Jungle_Max_Support"
    },
    {
      "x": -24,
      "y": 67,
      "z": -16,
      "name": "Plant_Leaves_Jungle_Max_Support"
    },
    {
      "x": -24,
      "y": 60,
      "z": -15,
      "name": "Plant_Leaves_Jungle_Max_Support"
    },
    {
      "x": -24,
      "y": 61,
      "z": -15,
      "name": "Plant_Leaves_Jungle_Max_Support"
    },
    {
      "x": -24,
      "y": 62,
      "z": -15,
      "name": "Plant_Leaves_Jungle_Max_Support"
    },
    {
      "x": -24,
      "y": 63,
      "z": -15,
      "name": "Plant_Leaves_Jungle_Max_Support"
    },
    {
      "x": -24,
      "y": 64,
      "z": -15,
      "name": "Plant_Leaves_Jungle_Max_Support"
    },
    {
      "x": -24,
      "y": 66,
      "z": -15,
      "name": "Plant_Leaves_Jungle_Max_Support"
    },
    {
      "x": -24,
      "y": 67,
      "z": -15,
      "name": "Plant_Leaves_Jungle_Max_Support"
    },
    {
      "x": -24,
      "y": 68,
      "z": -15,
      "name": "Plant_Leaves_Jungle_Max_Support"
    },
    {
      "x": -24,
      "y": 70,
      "z": -15,
      "name": "Plant_Leaves_Jungle_Max_Support"
    },
    {
      "x": -24,
      "y": 60,
      "z": -14,
      "name": "Plant_Leaves_Jungle_Max_Support"
    },
    {
      "x": -24,
      "y": 61,
      "z": -14,
      "name": "Plant_Leaves_Jungle_Max_Support"
    },
    {
      "x": -24,
      "y": 62,
      "z": -14,
      "name": "Plant_Leaves_Jungle_Max_Support"
    },
    {
      "x": -24,
      "y": 63,
      "z": -14,
      "name": "Plant_Leaves_Jungle_Max_Support"
    },
    {
      "x": -24,
      "y": 66,
      "z": -14,
      "name": "Plant_Leaves_Jungle_Max_Support"
    },
    {
      "x": -24,
      "y": 68,
      "z": -14,
      "name": "Plant_Leaves_Jungle_Max_Support"
    },
    {
      "x": -24,
      "y": 69,
      "z": -14,
      "name": "Plant_Leaves_Jungle_Max_Support"
    },
    {
      "x": -24,
      "y": 70,
      "z": -14,
      "name": "Plant_Leaves_Jungle_Max_Support"
    },
    {
      "x": -24,
      "y": 71,
      "z": -14,
      "name": "Plant_Leaves_Jungle_Max_Support"
    },
    {
      "x": -24,
      "y": 72,
      "z": -14,
      "name": "Plant_Leaves_Jungle_Max_Support"
    },
    {
      "x": -24,
      "y": 61,
      "z": -13,
      "name": "Plant_Leaves_Jungle_Max_Support"
    },
    {
      "x": -24,
      "y": 66,
      "z": -13,
      "name": "Plant_Leaves_Jungle_Max_Support"
    },
    {
      "x": -24,
      "y": 67,
      "z": -13,
      "name": "Plant_Leaves_Jungle_Max_Support"
    },
    {
      "x": -24,
      "y": 68,
      "z": -13,
      "name": "Plant_Leaves_Jungle_Max_Support"
    },
    {
      "x": -24,
      "y": 69,
      "z": -13,
      "name": "Plant_Leaves_Jungle_Max_Support"
    },
    {
      "x": -24,
      "y": 71,
      "z": -13,
      "name": "Plant_Leaves_Jungle_Max_Support"
    },
    {
      "x": -24,
      "y": 72,
      "z": -13,
      "name": "Plant_Leaves_Jungle_Max_Support"
    },
    {
      "x": -24,
      "y": 73,
      "z": -13,
      "name": "Plant_Leaves_Jungle_Max_Support"
    },
    {
      "x": -24,
      "y": 66,
      "z": -12,
      "name": "Plant_Leaves_Jungle_Max_Support"
    },
    {
      "x": -24,
      "y": 67,
      "z": -12,
      "name": "Plant_Leaves_Jungle_Max_Support"
    },
    {
      "x": -24,
      "y": 68,
      "z": -12,
      "name": "Plant_Leaves_Jungle_Max_Support"
    },
    {
      "x": -24,
      "y": 69,
      "z": -12,
      "name": "Plant_Leaves_Jungle_Max_Support"
    },
    {
      "x": -24,
      "y": 70,
      "z": -12,
      "name": "Plant_Leaves_Jungle_Max_Support"
    },
    {
      "x": -24,
      "y": 71,
      "z": -12,
      "name": "Plant_Leaves_Jungle_Max_Support"
    },
    {
      "x": -24,
      "y": 72,
      "z": -12,
      "name": "Plant_Leaves_Jungle_Max_Support"
    },
    {
      "x": -24,
      "y": 74,
      "z": -12,
      "name": "Plant_Leaves_Jungle_Max_Support"
    },
    {
      "x": -24,
      "y": 65,
      "z": -11,
      "name": "Plant_Leaves_Jungle_Max_Support"
    },
    {
      "x": -24,
      "y": 66,
      "z": -11,
      "name": "Plant_Leaves_Jungle_Max_Support"
    },
    {
      "x": -24,
      "y": 67,
      "z": -11,
      "name": "Plant_Leaves_Jungle_Max_Support"
    },
    {
      "x": -24,
      "y": 68,
      "z": -11,
      "name": "Plant_Leaves_Jungle_Max_Support"
    },
    {
      "x": -24,
      "y": 69,
      "z": -11,
      "name": "Plant_Leaves_Jungle_Max_Support"
    },
    {
      "x": -24,
      "y": 71,
      "z": -11,
      "name": "Plant_Leaves_Jungle_Max_Support"
    },
    {
      "x": -24,
      "y": 65,
      "z": -10,
      "name": "Plant_Leaves_Jungle_Max_Support"
    },
    {
      "x": -24,
      "y": 66,
      "z": -10,
      "name": "Plant_Leaves_Jungle_Max_Support"
    },
    {
      "x": -24,
      "y": 67,
      "z": -10,
      "name": "Plant_Leaves_Jungle_Max_Support"
    },
    {
      "x": -24,
      "y": 68,
      "z": -10,
      "name": "Plant_Leaves_Jungle_Max_Support"
    },
    {
      "x": -24,
      "y": 69,
      "z": -10,
      "name": "Plant_Leaves_Jungle_Max_Support"
    },
    {
      "x": -24,
      "y": 70,
      "z": -10,
      "name": "Plant_Leaves_Jungle_Max_Support"
    },
    {
      "x": -24,
      "y": 72,
      "z": -10,
      "name": "Plant_Leaves_Jungle_Max_Support"
    },
    {
      "x": -24,
      "y": 73,
      "z": -10,
      "name": "Plant_Leaves_Jungle_Max_Support"
    },
    {
      "x": -24,
      "y": 63,
      "z": -9,
      "name": "Plant_Leaves_Jungle_Max_Support"
    },
    {
      "x": -24,
      "y": 64,
      "z": -9,
      "name": "Plant_Leaves_Jungle_Max_Support"
    },
    {
      "x": -24,
      "y": 65,
      "z": -9,
      "name": "Plant_Leaves_Jungle_Max_Support"
    },
    {
      "x": -24,
      "y": 66,
      "z": -9,
      "name": "Plant_Leaves_Jungle_Max_Support"
    },
    {
      "x": -24,
      "y": 67,
      "z": -9,
      "name": "Plant_Leaves_Jungle_Max_Support"
    },
    {
      "x": -24,
      "y": 68,
      "z": -9,
      "name": "Plant_Leaves_Jungle_Max_Support"
    },
    {
      "x": -24,
      "y": 72,
      "z": -9,
      "name": "Plant_Leaves_Jungle_Max_Support"
    },
    {
      "x": -24,
      "y": 62,
      "z": -8,
      "name": "Plant_Leaves_Jungle_Max_Support"
    },
    {
      "x": -24,
      "y": 63,
      "z": -8,
      "name": "Plant_Leaves_Jungle_Max_Support"
    },
    {
      "x": -24,
      "y": 64,
      "z": -8,
      "name": "Plant_Leaves_Jungle_Max_Support"
    },
    {
      "x": -24,
      "y": 65,
      "z": -8,
      "name": "Plant_Leaves_Jungle_Max_Support"
    },
    {
      "x": -24,
      "y": 66,
      "z": -8,
      "name": "Plant_Leaves_Jungle_Max_Support"
    },
    {
      "x": -24,
      "y": 67,
      "z": -8,
      "name": "Plant_Leaves_Jungle_Max_Support"
    },
    {
      "x": -24,
      "y": 70,
      "z": -8,
      "name": "Plant_Leaves_Jungle_Max_Support"
    },
    {
      "x": -24,
      "y": 71,
      "z": -8,
      "name": "Plant_Leaves_Jungle_Max_Support"
    },
    {
      "x": -24,
      "y": 62,
      "z": -7,
      "name": "Plant_Leaves_Jungle_Max_Support"
    },
    {
      "x": -24,
      "y": 63,
      "z": -7,
      "name": "Plant_Leaves_Jungle_Max_Support"
    },
    {
      "x": -24,
      "y": 64,
      "z": -7,
      "name": "Plant_Leaves_Jungle_Max_Support"
    },
    {
      "x": -24,
      "y": 65,
      "z": -7,
      "name": "Plant_Leaves_Jungle_Max_Support"
    },
    {
      "x": -24,
      "y": 61,
      "z": -6,
      "name": "Plant_Leaves_Jungle_Max_Support"
    },
    {
      "x": -24,
      "y": 64,
      "z": -6,
      "name": "Plant_Leaves_Jungle_Max_Support"
    },
    {
      "x": -24,
      "y": 65,
      "z": -6,
      "name": "Plant_Leaves_Jungle_Max_Support"
    },
    {
      "x": -24,
      "y": 71,
      "z": -6,
      "name": "Plant_Leaves_Jungle_Max_Support"
    },
    {
      "x": -24,
      "y": 62,
      "z": -5,
      "name": "Plant_Leaves_Jungle_Max_Support"
    },
    {
      "x": -24,
      "y": 64,
      "z": -5,
      "name": "Plant_Leaves_Jungle_Max_Support"
    },
    {
      "x": -24,
      "y": 69,
      "z": -5,
      "name": "Plant_Leaves_Jungle_Max_Support"
    },
    {
      "x": -24,
      "y": 71,
      "z": -5,
      "name": "Plant_Leaves_Jungle_Max_Support"
    },
    {
      "x": -24,
      "y": 72,
      "z": -5,
      "name": "Plant_Leaves_Jungle_Max_Support"
    },
    {
      "x": -24,
      "y": 73,
      "z": -5,
      "name": "Plant_Leaves_Jungle_Max_Support"
    },
    {
      "x": -24,
      "y": 63,
      "z": -4,
      "name": "Plant_Leaves_Jungle_Max_Support"
    },
    {
      "x": -24,
      "y": 68,
      "z": -4,
      "name": "Plant_Leaves_Jungle_Max_Support"
    },
    {
      "x": -24,
      "y": 69,
      "z": -4,
      "name": "Plant_Leaves_Jungle_Max_Support"
    },
    {
      "x": -24,
      "y": 70,
      "z": -4,
      "name": "Plant_Leaves_Jungle_Max_Support"
    },
    {
      "x": -24,
      "y": 74,
      "z": -4,
      "name": "Plant_Leaves_Jungle_Max_Support"
    },
    {
      "x": -24,
      "y": 68,
      "z": -3,
      "name": "Plant_Leaves_Jungle_Max_Support"
    },
    {
      "x": -24,
      "y": 69,
      "z": -3,
      "name": "Plant_Leaves_Jungle_Max_Support"
    },
    {
      "x": -24,
      "y": 70,
      "z": -3,
      "name": "Plant_Leaves_Jungle_Max_Support"
    },
    {
      "x": -24,
      "y": 71,
      "z": -3,
      "name": "Plant_Leaves_Jungle_Max_Support"
    },
    {
      "x": -24,
      "y": 73,
      "z": -3,
      "name": "Plant_Leaves_Jungle_Max_Support"
    },
    {
      "x": -24,
      "y": 68,
      "z": -2,
      "name": "Plant_Leaves_Jungle_Max_Support"
    },
    {
      "x": -24,
      "y": 69,
      "z": -2,
      "name": "Plant_Leaves_Jungle_Max_Support"
    },
    {
      "x": -24,
      "y": 70,
      "z": -2,
      "name": "Plant_Leaves_Jungle_Max_Support"
    },
    {
      "x": -24,
      "y": 71,
      "z": -2,
      "name": "Plant_Leaves_Jungle_Max_Support"
    },
    {
      "x": -24,
      "y": 72,
      "z": -2,
      "name": "Plant_Leaves_Jungle_Max_Support"
    },
    {
      "x": -24,
      "y": 73,
      "z": -2,
      "name": "Plant_Leaves_Jungle_Max_Support"
    },
    {
      "x": -24,
      "y": 74,
      "z": -2,
      "name": "Plant_Leaves_Jungle_Max_Support"
    },
    {
      "x": -24,
      "y": 67,
      "z": -1,
      "name": "Plant_Leaves_Jungle_Max_Support"
    },
    {
      "x": -24,
      "y": 68,
      "z": -1,
      "name": "Plant_Leaves_Jungle_Max_Support"
    },
    {
      "x": -24,
      "y": 69,
      "z": -1,
      "name": "Plant_Leaves_Jungle_Max_Support"
    },
    {
      "x": -24,
      "y": 70,
      "z": -1,
      "name": "Plant_Leaves_Jungle_Max_Support"
    },
    {
      "x": -24,
      "y": 71,
      "z": -1,
      "name": "Plant_Leaves_Jungle_Max_Support"
    },
    {
      "x": -24,
      "y": 72,
      "z": -1,
      "name": "Plant_Leaves_Jungle_Max_Support"
    },
    {
      "x": -24,
      "y": 67,
      "z": 0,
      "name": "Wood_Jungle_Trunk_Full"
    },
    {
      "x": -24,
      "y": 68,
      "z": 0,
      "name": "Plant_Leaves_Jungle_Max_Support"
    },
    {
      "x": -24,
      "y": 69,
      "z": 0,
      "name": "Plant_Leaves_Jungle_Max_Support"
    },
    {
      "x": -24,
      "y": 70,
      "z": 0,
      "name": "Plant_Leaves_Jungle_Max_Support"
    },
    {
      "x": -24,
      "y": 71,
      "z": 0,
      "name": "Plant_Leaves_Jungle_Max_Support"
    },
    {
      "x": -24,
      "y": 72,
      "z": 0,
      "name": "Plant_Leaves_Jungle_Max_Support"
    },
    {
      "x": -24,
      "y": 73,
      "z": 0,
      "name": "Plant_Leaves_Jungle_Max_Support"
    },
    {
      "x": -24,
      "y": 74,
      "z": 0,
      "name": "Plant_Leaves_Jungle_Max_Support"
    },
    {
      "x": -24,
      "y": 67,
      "z": 1,
      "name": "Wood_Jungle_Trunk_Full"
    },
    {
      "x": -24,
      "y": 68,
      "z": 1,
      "name": "Plant_Leaves_Jungle_Max_Support"
    },
    {
      "x": -24,
      "y": 69,
      "z": 1,
      "name": "Plant_Leaves_Jungle_Max_Support"
    },
    {
      "x": -24,
      "y": 72,
      "z": 1,
      "name": "Plant_Leaves_Jungle_Max_Support"
    },
    {
      "x": -24,
      "y": 73,
      "z": 1,
      "name": "Plant_Leaves_Jungle_Max_Support"
    },
    {
      "x": -24,
      "y": 75,
      "z": 1,
      "name": "Plant_Leaves_Jungle_Max_Support"
    },
    {
      "x": -24,
      "y": 68,
      "z": 2,
      "name": "Plant_Leaves_Jungle_Max_Support"
    },
    {
      "x": -24,
      "y": 69,
      "z": 2,
      "name": "Plant_Leaves_Jungle_Max_Support"
    },
    {
      "x": -24,
      "y": 70,
      "z": 2,
      "name": "Plant_Leaves_Jungle_Max_Support"
    },
    {
      "x": -24,
      "y": 71,
      "z": 2,
      "name": "Plant_Leaves_Jungle_Max_Support"
    },
    {
      "x": -24,
      "y": 72,
      "z": 2,
      "name": "Plant_Leaves_Jungle_Max_Support"
    },
    {
      "x": -24,
      "y": 73,
      "z": 2,
      "name": "Plant_Leaves_Jungle_Max_Support"
    },
    {
      "x": -24,
      "y": 74,
      "z": 2,
      "name": "Plant_Leaves_Jungle_Max_Support"
    },
    {
      "x": -24,
      "y": 68,
      "z": 3,
      "name": "Plant_Leaves_Jungle_Max_Support"
    },
    {
      "x": -24,
      "y": 69,
      "z": 3,
      "name": "Plant_Leaves_Jungle_Max_Support"
    },
    {
      "x": -24,
      "y": 70,
      "z": 3,
      "name": "Plant_Leaves_Jungle_Max_Support"
    },
    {
      "x": -24,
      "y": 71,
      "z": 3,
      "name": "Plant_Leaves_Jungle_Max_Support"
    },
    {
      "x": -24,
      "y": 72,
      "z": 3,
      "name": "Plant_Leaves_Jungle_Max_Support"
    },
    {
      "x": -24,
      "y": 69,
      "z": 4,
      "name": "Plant_Leaves_Jungle_Max_Support"
    },
    {
      "x": -24,
      "y": 70,
      "z": 4,
      "name": "Plant_Leaves_Jungle_Max_Support"
    },
    {
      "x": -24,
      "y": 78,
      "z": 8,
      "name": "Plant_Leaves_Jungle_Max_Support"
    },
    {
      "x": -24,
      "y": 77,
      "z": 9,
      "name": "Plant_Leaves_Jungle_Max_Support"
    },
    {
      "x": -24,
      "y": 81,
      "z": 9,
      "name": "Plant_Leaves_Jungle_Max_Support"
    },
    {
      "x": -24,
      "y": 77,
      "z": 10,
      "name": "Plant_Leaves_Jungle_Max_Support"
    },
    {
      "x": -24,
      "y": 79,
      "z": 10,
      "name": "Plant_Leaves_Jungle_Max_Support"
    },
    {
      "x": -24,
      "y": 80,
      "z": 10,
      "name": "Plant_Leaves_Jungle_Max_Support"
    },
    {
      "x": -24,
      "y": 82,
      "z": 10,
      "name": "Plant_Leaves_Jungle_Max_Support"
    },
    {
      "x": -24,
      "y": 78,
      "z": 11,
      "name": "Plant_Leaves_Jungle_Max_Support"
    },
    {
      "x": -24,
      "y": 79,
      "z": 11,
      "name": "Plant_Leaves_Jungle_Max_Support"
    },
    {
      "x": -24,
      "y": 82,
      "z": 11,
      "name": "Plant_Leaves_Jungle_Max_Support"
    },
    {
      "x": -24,
      "y": 78,
      "z": 12,
      "name": "Plant_Leaves_Jungle_Max_Support"
    },
    {
      "x": -24,
      "y": 79,
      "z": 12,
      "name": "Plant_Leaves_Jungle_Max_Support"
    },
    {
      "x": -24,
      "y": 82,
      "z": 12,
      "name": "Plant_Leaves_Jungle_Max_Support"
    },
    {
      "x": -24,
      "y": 77,
      "z": 13,
      "name": "Plant_Leaves_Jungle_Max_Support"
    },
    {
      "x": -24,
      "y": 79,
      "z": 13,
      "name": "Plant_Leaves_Jungle_Max_Support"
    },
    {
      "x": -24,
      "y": 81,
      "z": 13,
      "name": "Plant_Leaves_Jungle_Max_Support"
    },
    {
      "x": -23,
      "y": 62,
      "z": -19,
      "name": "Plant_Leaves_Jungle_Max_Support"
    },
    {
      "x": -23,
      "y": 70,
      "z": -19,
      "name": "Plant_Leaves_Jungle_Max_Support"
    },
    {
      "x": -23,
      "y": 71,
      "z": -19,
      "name": "Plant_Leaves_Jungle_Max_Support"
    },
    {
      "x": -23,
      "y": 60,
      "z": -18,
      "name": "Plant_Leaves_Jungle_Max_Support"
    },
    {
      "x": -23,
      "y": 61,
      "z": -18,
      "name": "Plant_Leaves_Jungle_Max_Support"
    },
