{
  "version": 8,
  "blockIdVersion": 11,
  "anchorX": 1,
  "anchorY": 17,
  "anchorZ": -7,
  "blocks": [
    {
      "x": -25,
      "y": 58,
      "z": 20,
      "name": "Plant_Leaves_Beech_Max_Support"
    },
    {
      "x": -25,
      "y": 56,
      "z": 21,
      "name": "Plant_Leaves_Beech_Max_Support"
    },
    {
      "x": -25,
      "y": 57,
      "z": 21,
      "name": "Plant_Leaves_Beech_Max_Support"
    },
    {
      "x": -25,
      "y": 58,
      "z": 21,
      "name": "Plant_Leaves_Beech_Max_Support"
    },
    {
      "x": -25,
      "y": 59,
      "z": 21,
      "name": "Plant_Leaves_Beech_Max_Support"
    },
    {
      "x": -24,
      "y": 57,
      "z": 8,
      "name": "Plant_Leaves_Beech_Max_Support"
    },
    {
      "x": -24,
      "y": 56,
      "z": 9,
      "name": "Plant_Leaves_Beech_Max_Support"
    },
    {
      "x": -24,
      "y": 57,
      "z": 9,
      "name": "Plant_Leaves_Beech_Max_Support"
    },
    {
      "x": -24,
      "y": 61,
      "z": 9,
      "name": "Plant_Leaves_Beech_Max_Support"
    },
    {
      "x": -24,
      "y": 57,
      "z": 10,
      "name": "Plant_Leaves_Beech_Max_Support"
    },
    {
      "x": -24,
      "y": 57,
      "z": 17,
      "name": "Plant_Leaves_Beech_Max_Support"
    },
    {
      "x": -24,
      "y": 57,
      "z": 19,
      "name": "Plant_Leaves_Beech_Max_Support"
    },
    {
      "x": -24,
      "y": 58,
      "z": 19,
      "name": "Plant_Leaves_Beech_Max_Support"
    },
    {
      "x": -24,
      "y": 60,
      "z": 19,
      "name": "Plant_Leaves_Beech_Max_Support"
    },
    {
      "x": -24,
      "y": 57,
      "z": 20,
      "name": "Plant_Leaves_Beech_Max_Support"
    },
    {
      "x": -24,
      "y": 58,
      "z": 20,
      "name": "Plant_Leaves_Beech_Max_Support"
    },
    {
      "x": -24,
      "y": 59,
      "z": 20,
      "name": "Plant_Leaves_Beech_Max_Support"
    },
    {
      "x": -24,
      "y": 60,
      "z": 20,
      "name": "Plant_Leaves_Beech_Max_Support"
    },
    {
      "x": -24,
      "y": 57,
      "z": 21,
      "name": "Plant_Leaves_Beech_Max_Support"
    },
    {
      "x": -24,
      "y": 58,
      "z": 21,
      "name": "Plant_Leaves_Beech_Max_Support"
    },
    {
      "x": -24,
      "y": 59,
      "z": 21,
      "name": "Plant_Leaves_Beech_Max_Support"
    },
    {
      "x": -24,
      "y": 60,
      "z": 21,
      "name": "Plant_Leaves_Beech_Max_Support"
    },
    {
      "x": -24,
      "y": 61,
      "z": 21,
      "name": "Plant_Leaves_Beech_Max_Support"
    },
    {
      "x": -24,
      "y": 56,
      "z": 22,
      "name": "Plant_Leaves_Beech_Max_Support"
    },
    {
      "x": -24,
      "y": 57,
      "z": 22,
      "name": "Plant_Leaves_Beech_Max_Support"
    },
    {
      "x": -24,
      "y": 58,
      "z": 22,
      "name": "Plant_Leaves_Beech_Max_Support"
    },
    {
      "x": -24,
      "y": 59,
      "z": 22,
      "name": "Plant_Leaves_Beech_Max_Support"
    },
    {
      "x": -24,
      "y": 58,
      "z": 23,
      "name": "Plant_Leaves_Beech_Max_Support"
    },
    {
      "x": -23,
      "y": 56,
      "z": 4,
      "name": "Plant_Leaves_Beech_Max_Support"
    },
    {
      "x": -23,
      "y": 55,
      "z": 5,
      "name": "Plant_Leaves_Beech_Max_Support"
    },
    {
      "x": -23,
      "y": 56,
      "z": 5,
      "name": "Plant_Leaves_Beech_Max_Support"
    },
    {
      "x": -23,
      "y": 56,
      "z": 6,
      "name": "Plant_Leaves_Beech_Max_Support"
    },
    {
      "x": -23,
      "y": 57,
      "z": 6,
      "name": "Plant_Leaves_Beech_Max_Support"
    },
    {
      "x": -23,
      "y": 56,
      "z": 7,
      "name": "Plant_Leaves_Beech_Max_Support"
    },
    {
      "x": -23,
      "y": 57,
      "z": 7,
      "name": "Plant_Leaves_Beech_Max_Support"
    },
    {
      "x": -23,
      "y": 60,
      "z": 7,
      "name": "Plant_Leaves_Beech_Max_Support"
    },
    {
      "x": -23,
      "y": 55,
      "z": 9,
      "name": "Plant_Leaves_Beech_Max_Support"
    },
    {
      "x": -23,
      "y": 56,
      "z": 9,
      "name": "Plant_Leaves_Beech_Max_Support"
    },
    {
      "x": -23,
      "y": 57,
      "z": 9,
      "name": "Plant_Leaves_Beech_Max_Support"
    },
    {
      "x": -23,
      "y": 59,
      "z": 9,
      "name": "Plant_Leaves_Beech_Max_Support"
    },
    {
      "x": -23,
      "y": 61,
      "z": 9,
      "name": "Plant_Leaves_Beech_Max_Support"
    },
    {
      "x": -23,
      "y": 62,
      "z": 9,
      "name": "Plant_Leaves_Beech_Max_Support"
    },
    {
      "x": -23,
      "y": 57,
      "z": 10,
      "name": "Plant_Leaves_Beech_Max_Support"
    },
    {
      "x": -23,
      "y": 60,
      "z": 10,
      "name": "Plant_Leaves_Beech_Max_Support"
    },
    {
      "x": -23,
      "y": 57,
      "z": 11,
      "name": "Plant_Leaves_Beech_Max_Support"
    },
    {
      "x": -23,
      "y": 60,
      "z": 11,
      "name": "Plant_Leaves_Beech_Max_Support"
    },
    {
      "x": -23,
      "y": 57,
      "z": 15,
      "name": "Plant_Leaves_Beech_Max_Support"
    },
    {
      "x": -23,
      "y": 57,
      "z": 16,
      "name": "Plant_Leaves_Beech_Max_Support"
    },
    {
      "x": -23,
      "y": 58,
      "z": 16,
      "name": "Plant_Leaves_Beech_Max_Support"
    },
    {
      "x": -23,
      "y": 57,
      "z": 17,
      "name": "Plant_Leaves_Beech_Max_Support"
    },
    {
      "x": -23,
      "y": 57,
      "z": 18,
      "name": "Plant_Leaves_Beech_Max_Support"
    },
    {
      "x": -23,
      "y": 58,
      "z": 18,
      "name": "Plant_Leaves_Beech_Max_Support"
    },
    {
      "x": -23,
      "y": 59,
      "z": 18,
      "name": "Plant_Leaves_Beech_Max_Support"
    },
    {
      "x": -23,
      "y": 60,
      "z": 18,
      "name": "Plant_Leaves_Beech_Max_Support"
    },
    {
      "x": -23,
      "y": 56,
      "z": 19,
      "name": "Plant_Leaves_Beech_Max_Support"
    },
    {
      "x": -23,
      "y": 57,
      "z": 19,
      "name": "Plant_Leaves_Beech_Max_Support"
    },
    {
      "x": -23,
      "y": 58,
      "z": 19,
      "name": "Plant_Leaves_Beech_Max_Support"
    },
    {
      "x": -23,
      "y": 59,
      "z": 19,
      "name": "Plant_Leaves_Beech_Max_Support"
    },
    {
      "x": -23,
      "y": 60,
      "z": 19,
      "name": "Plant_Leaves_Beech_Max_Support"
    },
    {
      "x": -23,
      "y": 55,
      "z": 20,
      "name": "Plant_Leaves_Beech_Max_Support"
    },
    {
      "x": -23,
      "y": 57,
      "z": 20,
      "name": "Plant_Leaves_Beech_Max_Support"
    },
    {
      "x": -23,
      "y": 59,
      "z": 20,
      "name": "Plant_Leaves_Beech_Max_Support"
    },
    {
      "x": -23,
      "y": 62,
      "z": 20,
      "name": "Plant_Leaves_Beech_Max_Support"
    },
    {
      "x": -23,
      "y": 55,
      "z": 21,
      "name": "Plant_Leaves_Beech_Max_Support"
    },
    {
      "x": -23,
      "y": 56,
      "z": 21,
      "name": "Plant_Leaves_Beech_Max_Support"
    },
    {
      "x": -23,
      "y": 57,
      "z": 21,
      "name": "Plant_Leaves_Beech_Max_Support"
    },
    {
      "x": -23,
      "y": 58,
      "z": 21,
      "name": "Plant_Leaves_Beech_Max_Support"
    },
    {
      "x": -23,
      "y": 59,
      "z": 21,
      "name": "Plant_Leaves_Beech_Max_Support"
    },
    {
      "x": -23,
      "y": 60,
      "z": 21,
      "name": "Plant_Leaves_Beech_Max_Support"
    },
    {
      "x": -23,
      "y": 61,
      "z": 21,
      "name": "Plant_Leaves_Beech_Max_Support"
    },
    {
      "x": -23,
      "y": 56,
      "z": 22,
      "name": "Plant_Leaves_Beech_Max_Support"
    },
    {
      "x": -23,
      "y": 57,
      "z": 22,
      "name": "Plant_Leaves_Beech_Max_Support"
    },
    {
      "x": -23,
      "y": 58,
      "z": 22,
      "name": "Plant_Leaves_Beech_Max_Support"
    },
    {
      "x": -23,
      "y": 59,
      "z": 22,
      "name": "Plant_Leaves_Beech_Max_Support"
    },
    {
      "x": -23,
      "y": 60,
      "z": 22,
      "name": "Plant_Leaves_Beech_Max_Support"
    },
    {
      "x": -23,
      "y": 61,
      "z": 22,
      "name": "Plant_Leaves_Beech_Max_Support"
    },
    {
      "x": -23,
      "y": 56,
      "z": 23,
      "name": "Plant_Leaves_Beech_Max_Support"
    },
    {
      "x": -23,
      "y": 57,
      "z": 23,
      "name": "Plant_Leaves_Beech_Max_Support"
    },
    {
      "x": -23,
      "y": 58,
      "z": 23,
      "name": "Plant_Leaves_Beech_Max_Support"
    },
    {
      "x": -23,
      "y": 59,
      "z": 23,
      "name": "Plant_Leaves_Beech_Max_Support"
    },
    {
      "x": -23,
      "y": 60,
      "z": 23,
      "name": "Plant_Leaves_Beech_Max_Support"
    },
    {
      "x": -22,
      "y": 57,
      "z": 4,
      "name": "Plant_Leaves_Beech_Max_Support"
    },
    {
      "x": -22,
      "y": 55,
      "z": 5,
      "name": "Plant_Leaves_Beech_Max_Support"
    },
    {
      "x": -22,
      "y": 56,
      "z": 5,
      "name": "Plant_Leaves_Beech_Max_Support"
    },
    {
      "x": -22,
      "y": 57,
      "z": 5,
      "name": "Plant_Leaves_Beech_Max_Support"
    },
    {
      "x": -22,
      "y": 56,
      "z": 6,
      "name": "Plant_Leaves_Beech_Max_Support"
    },
    {
      "x": -22,
      "y": 57,
      "z": 6,
      "name": "Plant_Leaves_Beech_Max_Support"
    },
    {
      "x": -22,
      "y": 58,
      "z": 6,
      "name": "Plant_Leaves_Beech_Max_Support"
    },
    {
      "x": -22,
      "y": 55,
      "z": 7,
      "name": "Plant_Leaves_Beech_Max_Support"
    },
    {
      "x": -22,
      "y": 57,
      "z": 7,
      "name": "Plant_Leaves_Beech_Max_Support"
    },
    {
      "x": -22,
      "y": 58,
      "z": 7,
      "name": "Plant_Leaves_Beech_Max_Support"
    },
    {
      "x": -22,
      "y": 59,
      "z": 7,
      "name": "Plant_Leaves_Beech_Max_Support"
    },
    {
      "x": -22,
      "y": 60,
      "z": 7,
      "name": "Plant_Leaves_Beech_Max_Support"
    },
    {
      "x": -22,
      "y": 56,
      "z": 8,
      "name": "Plant_Leaves_Beech_Max_Support"
    },
    {
      "x": -22,
      "y": 57,
      "z": 8,
      "name": "Plant_Leaves_Beech_Max_Support"
    },
    {
      "x": -22,
      "y": 58,
      "z": 8,
      "name": "Plant_Leaves_Beech_Max_Support"
    },
    {
      "x": -22,
      "y": 59,
      "z": 8,
      "name": "Plant_Leaves_Beech_Max_Support"
    },
    {
      "x": -22,
      "y": 60,
      "z": 8,
      "name": "Plant_Leaves_Beech_Max_Support"
    },
    {
      "x": -22,
      "y": 62,
      "z": 8,
      "name": "Plant_Leaves_Beech_Max_Support"
    },
    {
      "x": -22,
      "y": 55,
      "z": 9,
      "name": "Plant_Leaves_Beech_Max_Support"
    },
    {
      "x": -22,
      "y": 56,
      "z": 9,
      "name": "Plant_Leaves_Beech_Max_Support"
    },
    {
      "x": -22,
      "y": 57,
      "z": 9,
      "name": "Plant_Leaves_Beech_Max_Support"
    },
    {
      "x": -22,
      "y": 58,
      "z": 9,
      "name": "Plant_Leaves_Beech_Max_Support"
    },
    {
      "x": -22,
      "y": 59,
      "z": 9,
      "name": "Plant_Leaves_Beech_Max_Support"
    },
    {
      "x": -22,
      "y": 60,
      "z": 9,
      "name": "Plant_Leaves_Beech_Max_Support"
    },
    {
      "x": -22,
      "y": 62,
      "z": 9,
      "name": "Plant_Leaves_Beech_Max_Support"
    },
    {
      "x": -22,
      "y": 55,
      "z": 10,
      "name": "Plant_Leaves_Beech_Max_Support"
    },
    {
      "x": -22,
      "y": 56,
      "z": 10,
      "name": "Plant_Leaves_Beech_Max_Support"
    },
    {
      "x": -22,
      "y": 57,
      "z": 10,
      "name": "Plant_Leaves_Beech_Max_Support"
    },
    {
      "x": -22,
      "y": 58,
      "z": 10,
      "name": "Plant_Leaves_Beech_Max_Support"
    },
    {
      "x": -22,
      "y": 60,
      "z": 10,
      "name": "Plant_Leaves_Beech_Max_Support"
    },
    {
      "x": -22,
      "y": 61,
      "z": 10,
      "name": "Plant_Leaves_Beech_Max_Support"
    },
    {
      "x": -22,
      "y": 56,
      "z": 11,
      "name": "Plant_Leaves_Beech_Max_Support"
    },
    {
      "x": -22,
      "y": 57,
      "z": 11,
      "name": "Plant_Leaves_Beech_Max_Support"
    },
    {
      "x": -22,
      "y": 58,
      "z": 11,
      "name": "Plant_Leaves_Beech_Max_Support"
    },
    {
      "x": -22,
      "y": 61,
      "z": 11,
      "name": "Plant_Leaves_Beech_Max_Support"
    },
    {
      "x": -22,
      "y": 56,
      "z": 12,
      "name": "Plant_Leaves_Beech_Max_Support"
    },
    {
      "x": -22,
      "y": 57,
      "z": 12,
      "name": "Plant_Leaves_Beech_Max_Support"
    },
    {
      "x": -22,
      "y": 58,
      "z": 12,
      "name": "Plant_Leaves_Beech_Max_Support"
    },
    {
      "x": -22,
      "y": 57,
      "z": 14,
      "name": "Plant_Leaves_Beech_Max_Support"
    },
    {
      "x": -22,
      "y": 58,
      "z": 14,
      "name": "Plant_Leaves_Beech_Max_Support"
    },
    {
      "x": -22,
      "y": 58,
      "z": 15,
      "name": "Plant_Leaves_Beech_Max_Support"
    },
    {
      "x": -22,
      "y": 55,
      "z": 16,
      "name": "Plant_Leaves_Beech_Max_Support"
    },
    {
      "x": -22,
      "y": 56,
      "z": 16,
      "name": "Plant_Leaves_Beech_Max_Support"
    },
    {
      "x": -22,
      "y": 57,
      "z": 16,
      "name": "Plant_Leaves_Beech_Max_Support"
    },
    {
      "x": -22,
      "y": 58,
      "z": 16,
      "name": "Plant_Leaves_Beech_Max_Support"
    },
    {
      "x": -22,
      "y": 59,
      "z": 16,
      "name": "Plant_Leaves_Beech_Max_Support"
    },
    {
      "x": -22,
      "y": 55,
      "z": 17,
      "name": "Plant_Leaves_Beech_Max_Support"
    },
    {
      "x": -22,
      "y": 56,
      "z": 17,
      "name": "Plant_Leaves_Beech_Max_Support"
    },
    {
      "x": -22,
      "y": 57,
      "z": 17,
      "name": "Plant_Leaves_Beech_Max_Support"
    },
    {
      "x": -22,
      "y": 58,
      "z": 17,
      "name": "Plant_Leaves_Beech_Max_Support"
    },
    {
      "x": -22,
      "y": 59,
      "z": 17,
      "name": "Plant_Leaves_Beech_Max_Support"
    },
    {
      "x": -22,
      "y": 57,
      "z": 18,
      "name": "Plant_Leaves_Beech_Max_Support"
    },
    {
      "x": -22,
      "y": 58,
      "z": 18,
      "name": "Plant_Leaves_Beech_Max_Support"
    },
    {
      "x": -22,
      "y": 59,
      "z": 18,
      "name": "Plant_Leaves_Beech_Max_Support"
    },
    {
      "x": -22,
      "y": 60,
      "z": 18,
      "name": "Plant_Leaves_Beech_Max_Support"
    },
    {
      "x": -22,
      "y": 55,
      "z": 19,
      "name": "Plant_Leaves_Beech_Max_Support"
    },
    {
      "x": -22,
      "y": 57,
      "z": 19,
      "name": "Plant_Leaves_Beech_Max_Support"
    },
    {
      "x": -22,
      "y": 58,
      "z": 19,
      "name": "Plant_Leaves_Beech_Max_Support"
    },
    {
      "x": -22,
      "y": 59,
      "z": 19,
      "name": "Plant_Leaves_Beech_Max_Support"
    },
    {
      "x": -22,
      "y": 60,
      "z": 19,
      "name": "Plant_Leaves_Beech_Max_Support"
    },
    {
      "x": -22,
      "y": 61,
      "z": 19,
      "name": "Plant_Leaves_Beech_Max_Support"
    },
    {
      "x": -22,
      "y": 56,
      "z": 20,
      "name": "Plant_Leaves_Beech_Max_Support"
    },
    {
      "x": -22,
      "y": 57,
      "z": 20,
      "name": "Plant_Leaves_Beech_Max_Support"
    },
    {
      "x": -22,
      "y": 58,
      "z": 20,
      "name": "Plant_Leaves_Beech_Max_Support"
    },
    {
      "x": -22,
      "y": 59,
      "z": 20,
      "name": "Plant_Leaves_Beech_Max_Support"
    },
    {
      "x": -22,
      "y": 60,
      "z": 20,
      "name": "Plant_Leaves_Beech_Max_Support"
    },
    {
      "x": -22,
      "y": 61,
      "z": 20,
      "name": "Plant_Leaves_Beech_Max_Support"
    },
    {
      "x": -22,
      "y": 62,
      "z": 20,
      "name": "Plant_Leaves_Beech_Max_Support"
    },
    {
      "x": -22,
      "y": 55,
      "z": 21,
      "name": "Plant_Leaves_Beech_Max_Support"
    },
    {
      "x": -22,
      "y": 56,
      "z": 21,
      "name": "Plant_Leaves_Beech_Max_Support"
    },
    {
      "x": -22,
      "y": 57,
      "z": 21,
      "name": "Plant_Leaves_Beech_Max_Support"
    },
    {
      "x": -22,
      "y": 58,
      "z": 21,
      "name": "Plant_Leaves_Beech_Max_Support"
    },
    {
      "x": -22,
      "y": 59,
      "z": 21,
      "name": "Plant_Leaves_Beech_Max_Support"
    },
    {
      "x": -22,
      "y": 60,
      "z": 21,
      "name": "Plant_Leaves_Beech_Max_Support"
    },
    {
      "x": -22,
      "y": 61,
      "z": 21,
      "name": "Plant_Leaves_Beech_Max_Support"
    },
    {
      "x": -22,
      "y": 57,
      "z": 22,
      "name": "Plant_Leaves_Beech_Max_Support"
    },
    {
      "x": -22,
      "y": 58,
      "z": 22,
      "name": "Plant_Leaves_Beech_Max_Support"
    },
    {
      "x": -22,
      "y": 59,
      "z": 22,
      "name": "Plant_Leaves_Beech_Max_Support"
    },
    {
      "x": -22,
      "y": 60,
      "z": 22,
      "name": "Plant_Leaves_Beech_Max_Support"
    },
    {
      "x": -22,
      "y": 61,
      "z": 22,
      "name": "Plant_Leaves_Beech_Max_Support"
    },
    {
      "x": -22,
      "y": 57,
      "z": 23,
      "name": "Plant_Leaves_Beech_Max_Support"
    },
    {
      "x": -22,
      "y": 59,
      "z": 23,
      "name": "Plant_Leaves_Beech_Max_Support"
    },
    {
      "x": -22,
      "y": 60,
      "z": 23,
      "name": "Plant_Leaves_Beech_Max_Support"
    },
    {
      "x": -22,
      "y": 61,
      "z": 23,
      "name": "Plant_Leaves_Beech_Max_Support"
    },
    {
      "x": -22,
      "y": 58,
      "z": 24,
      "name": "Plant_Leaves_Beech_Max_Support"
    },
    {
      "x": -21,
      "y": 57,
      "z": 3,
      "name": "Plant_Leaves_Beech_Max_Support"
    },
    {
      "x": -21,
      "y": 55,
      "z": 4,
      "name": "Plant_Leaves_Beech_Max_Support"
    },
    {
      "x": -21,
      "y": 56,
      "z": 4,
      "name": "Plant_Leaves_Beech_Max_Support"
    },
    {
      "x": -21,
      "y": 57,
      "z": 4,
      "name": "Plant_Leaves_Beech_Max_Support"
    },
    {
      "x": -21,
      "y": 55,
      "z": 5,
      "name": "Plant_Leaves_Beech_Max_Support"
    },
    {
      "x": -21,
      "y": 56,
      "z": 5,
      "name": "Plant_Leaves_Beech_Max_Support"
    },
    {
      "x": -21,
      "y": 57,
      "z": 5,
      "name": "Plant_Leaves_Beech_Max_Support"
    },
    {
      "x": -21,
      "y": 58,
      "z": 5,
      "name": "Plant_Leaves_Beech_Max_Support"
    },
    {
      "x": -21,
      "y": 55,
      "z": 6,
      "name": "Plant_Leaves_Beech_Max_Support"
    },
    {
      "x": -21,
      "y": 56,
      "z": 6,
      "name": "Plant_Leaves_Beech_Max_Support"
    },
    {
      "x": -21,
      "y": 57,
      "z": 6,
      "name": "Plant_Leaves_Beech_Max_Support"
    },
    {
      "x": -21,
      "y": 58,
      "z": 6,
      "name": "Plant_Leaves_Beech_Max_Support"
    },
    {
      "x": -21,
      "y": 59,
      "z": 6,
      "name": "Plant_Leaves_Beech_Max_Support"
    },
    {
      "x": -21,
      "y": 60,
      "z": 6,
      "name": "Plant_Leaves_Beech_Max_Support"
    },
    {
      "x": -21,
      "y": 61,
      "z": 6,
      "name": "Plant_Leaves_Beech_Max_Support"
    },
    {
      "x": -21,
      "y": 56,
      "z": 7,
      "name": "Plant_Leaves_Beech_Max_Support"
    },
    {
      "x": -21,
      "y": 57,
      "z": 7,
      "name": "Plant_Leaves_Beech_Max_Support"
    },
    {
      "x": -21,
      "y": 58,
      "z": 7,
      "name": "Plant_Leaves_Beech_Max_Support"
    },
    {
      "x": -21,
      "y": 59,
      "z": 7,
      "name": "Plant_Leaves_Beech_Max_Support"
    },
    {
      "x": -21,
      "y": 60,
      "z": 7,
      "name": "Plant_Leaves_Beech_Max_Support"
    },
    {
      "x": -21,
      "y": 61,
      "z": 7,
      "name": "Plant_Leaves_Beech_Max_Support"
    },
    {
      "x": -21,
      "y": 62,
      "z": 7,
      "name": "Plant_Leaves_Beech_Max_Support"
    },
    {
      "x": -21,
      "y": 55,
      "z": 8,
      "name": "Plant_Leaves_Beech_Max_Support"
    },
    {
      "x": -21,
      "y": 56,
      "z": 8,
      "name": "Plant_Leaves_Beech_Max_Support"
    },
    {
      "x": -21,
      "y": 57,
      "z": 8,
      "name": "Plant_Leaves_Beech_Max_Support"
    },
    {
      "x": -21,
      "y": 58,
      "z": 8,
      "name": "Plant_Leaves_Beech_Max_Support"
    },
    {
      "x": -21,
      "y": 59,
      "z": 8,
      "name": "Plant_Leaves_Beech_Max_Support"
    },
    {
      "x": -21,
      "y": 60,
      "z": 8,
      "name": "Plant_Leaves_Beech_Max_Support"
    },
    {
      "x": -21,
      "y": 55,
      "z": 9,
      "name": "Plant_Leaves_Beech_Max_Support"
    },
    {
      "x": -21,
      "y": 56,
      "z": 9,
      "name": "Plant_Leaves_Beech_Max_Support"
    },
    {
      "x": -21,
      "y": 58,
      "z": 9,
      "name": "Plant_Leaves_Beech_Max_Support"
    },
    {
      "x": -21,
      "y": 59,
      "z": 9,
      "name": "Plant_Leaves_Beech_Max_Support"
    },
    {
      "x": -21,
      "y": 61,
      "z": 9,
      "name": "Plant_Leaves_Beech_Max_Support"
    },
    {
      "x": -21,
      "y": 56,
      "z": 10,
      "name": "Plant_Leaves_Beech_Max_Support"
    },
    {
      "x": -21,
      "y": 57,
      "z": 10,
      "name": "Plant_Leaves_Beech_Max_Support"
    },
    {
      "x": -21,
      "y": 58,
      "z": 10,
      "name": "Plant_Leaves_Beech_Max_Support"
    },
    {
      "x": -21,
      "y": 59,
      "z": 10,
      "name": "Plant_Leaves_Beech_Max_Support"
    },
    {
      "x": -21,
      "y": 60,
      "z": 10,
      "name": "Plant_Leaves_Beech_Max_Support"
    },
    {
      "x": -21,
      "y": 61,
      "z": 10,
      "name": "Plant_Leaves_Beech_Max_Support"
    },
    {
      "x": -21,
      "y": 58,
      "z": 11,
      "name": "Plant_Leaves_Beech_Max_Support"
    },
    {
      "x": -21,
      "y": 55,
      "z": 12,
      "name": "Plant_Leaves_Beech_Max_Support"
    },
    {
      "x": -21,
      "y": 56,
      "z": 12,
      "name": "Plant_Leaves_Beech_Max_Support"
    },
    {
      "x": -21,
      "y": 57,
      "z": 12,
      "name": "Plant_Leaves_Beech_Max_Support"
    },
    {
      "x": -21,
      "y": 58,
      "z": 12,
      "name": "Plant_Leaves_Beech_Max_Support"
    },
    {
      "x": -21,
      "y": 59,
      "z": 12,
      "name": "Plant_Leaves_Beech_Max_Support"
    },
    {
      "x": -21,
      "y": 58,
      "z": 13,
      "name": "Plant_Leaves_Beech_Max_Support"
    },
    {
      "x": -21,
      "y": 56,
      "z": 14,
      "name": "Plant_Leaves_Beech_Max_Support"
    },
    {
      "x": -21,
      "y": 58,
      "z": 14,
      "name": "Plant_Leaves_Beech_Max_Support"
    },
    {
      "x": -21,
      "y": 59,
      "z": 14,
      "name": "Plant_Leaves_Beech_Max_Support"
    },
    {
      "x": -21,
      "y": 56,
      "z": 15,
      "name": "Plant_Leaves_Beech_Max_Support"
    },
    {
      "x": -21,
      "y": 57,
      "z": 15,
      "name": "Plant_Leaves_Beech_Max_Support"
    },
    {
      "x": -21,
      "y": 58,
      "z": 15,
      "name": "Plant_Leaves_Beech_Max_Support"
    },
    {
      "x": -21,
      "y": 59,
      "z": 15,
      "name": "Plant_Leaves_Beech_Max_Support"
    },
    {
      "x": -21,
      "y": 57,
      "z": 16,
      "name": "Plant_Leaves_Beech_Max_Support"
    },
    {
      "x": -21,
      "y": 58,
      "z": 16,
      "name": "Plant_Leaves_Beech_Max_Support"
    },
    {
      "x": -21,
      "y": 56,
      "z": 17,
      "name": "Plant_Leaves_Beech_Max_Support"
    },
    {
      "x": -21,
      "y": 57,
      "z": 17,
      "name": "Plant_Leaves_Beech_Max_Support"
    },
    {
      "x": -21,
      "y": 58,
      "z": 17,
      "name": "Plant_Leaves_Beech_Max_Support"
    },
    {
      "x": -21,
      "y": 59,
      "z": 17,
      "name": "Plant_Leaves_Beech_Max_Support"
    },
    {
      "x": -21,
      "y": 55,
      "z": 18,
      "name": "Plant_Leaves_Beech_Max_Support"
    },
    {
      "x": -21,
      "y": 56,
      "z": 18,
      "name": "Plant_Leaves_Beech_Max_Support"
    },
    {
      "x": -21,
      "y": 57,
      "z": 18,
      "name": "Plant_Leaves_Beech_Max_Support"
    },
    {
      "x": -21,
      "y": 58,
      "z": 18,
      "name": "Plant_Leaves_Beech_Max_Support"
    },
    {
      "x": -21,
      "y": 59,
      "z": 18,
      "name": "Plant_Leaves_Beech_Max_Support"
    },
    {
      "x": -21,
      "y": 60,
      "z": 18,
      "name": "Plant_Leaves_Beech_Max_Support"
    },
    {
      "x": -21,
      "y": 56,
      "z": 19,
      "name": "Plant_Leaves_Beech_Max_Support"
    },
    {
      "x": -21,
      "y": 57,
      "z": 19,
      "name": "Plant_Leaves_Beech_Max_Support"
    },
    {
      "x": -21,
      "y": 58,
      "z": 19,
      "name": "Plant_Leaves_Beech_Max_Support"
    },
    {
      "x": -21,
      "y": 59,
      "z": 19,
      "name": "Plant_Leaves_Beech_Max_Support"
    },
    {
      "x": -21,
      "y": 60,
      "z": 19,
      "name": "Plant_Leaves_Beech_Max_Support"
    },
    {
      "x": -21,
      "y": 55,
      "z": 20,
      "name": "Plant_Leaves_Beech_Max_Support"
    },
    {
      "x": -21,
      "y": 56,
      "z": 20,
      "name": "Plant_Leaves_Beech_Max_Support"
    },
    {
      "x": -21,
      "y": 57,
      "z": 20,
      "name": "Plant_Leaves_Beech_Max_Support"
    },
    {
      "x": -21,
      "y": 58,
      "z": 20,
      "name": "Plant_Leaves_Beech_Max_Support"
    },
    {
      "x": -21,
      "y": 59,
      "z": 20,
      "name": "Plant_Leaves_Beech_Max_Support"
    },
    {
      "x": -21,
      "y": 60,
      "z": 20,
      "name": "Plant_Leaves_Beech_Max_Support"
    },
    {
      "x": -21,
      "y": 55,
      "z": 21,
      "name": "Plant_Leaves_Beech_Max_Support"
    },
    {
      "x": -21,
      "y": 56,
      "z": 21,
      "name": "Plant_Leaves_Beech_Max_Support"
    },
    {
      "x": -21,
      "y": 57,
      "z": 21,
      "name": "Plant_Leaves_Beech_Max_Support"
    },
    {
      "x": -21,
      "y": 58,
      "z": 21,
      "name": "Plant_Leaves_Beech_Max_Support"
    },
    {
      "x": -21,
      "y": 59,
      "z": 21,
      "name": "Plant_Leaves_Beech_Max_Support"
    },
    {
      "x": -21,
      "y": 60,
      "z": 21,
      "name": "Plant_Leaves_Beech_Max_Support"
    },
    {
      "x": -21,
      "y": 56,
      "z": 22,
      "name": "Plant_Leaves_Beech_Max_Support"
    },
    {
      "x": -21,
      "y": 57,
      "z": 22,
      "name": "Plant_Leaves_Beech_Max_Support"
    },
    {
      "x": -21,
      "y": 58,
      "z": 22,
      "name": "Plant_Leaves_Beech_Max_Support"
    },
    {
      "x": -21,
      "y": 59,
      "z": 22,
      "name": "Plant_Leaves_Beech_Max_Support"
    },
    {
      "x": -21,
      "y": 60,
      "z": 22,
      "name": "Plant_Leaves_Beech_Max_Support"
    },
    {
      "x": -21,
      "y": 61,
      "z": 22,
      "name": "Plant_Leaves_Beech_Max_Support"
    },
    {
      "x": -21,
      "y": 56,
      "z": 23,
      "name": "Plant_Leaves_Beech_Max_Support"
    },
    {
      "x": -21,
      "y": 57,
      "z": 23,
      "name": "Plant_Leaves_Beech_Max_Support"
    },
    {
      "x": -21,
      "y": 58,
      "z": 23,
      "name": "Plant_Leaves_Beech_Max_Support"
    },
    {
      "x": -21,
      "y": 58,
      "z": 24,
      "name": "Plant_Leaves_Beech_Max_Support"
    },
    {
      "x": -21,
      "y": 59,
      "z": 24,
      "name": "Plant_Leaves_Beech_Max_Support"
    },
    {
      "x": -21,
      "y": 57,
      "z": 25,
      "name": "Plant_Leaves_Beech_Max_Support"
    },
    {
      "x": -20,
      "y": 55,
      "z": 2,
      "name": "Plant_Leaves_Beech_Max_Support"
    },
    {
      "x": -20,
      "y": 54,
      "z": 3,
      "name": "Plant_Leaves_Beech_Max_Support"
    },
    {
      "x": -20,
      "y": 56,
      "z": 3,
      "name": "Plant_Leaves_Beech_Max_Support"
    },
    {
      "x": -20,
      "y": 55,
      "z": 4,
      "name": "Plant_Leaves_Beech_Max_Support"
    },
    {
      "x": -20,
      "y": 56,
      "z": 4,
      "name": "Plant_Leaves_Beech_Max_Support"
    },
    {
      "x": -20,
      "y": 57,
      "z": 4,
      "name": "Plant_Leaves_Beech_Max_Support"
    },
    {
      "x": -20,
      "y": 54,
      "z": 5,
      "name": "Plant_Leaves_Beech_Max_Support"
    },
    {
      "x": -20,
      "y": 55,
      "z": 5,
      "name": "Plant_Leaves_Beech_Max_Support"
    },
    {
      "x": -20,
      "y": 56,
      "z": 5,
      "name": "Plant_Leaves_Beech_Max_Support"
    },
    {
      "x": -20,
      "y": 58,
      "z": 5,
      "name": "Plant_Leaves_Beech_Max_Support"
    },
    {
      "x": -20,
      "y": 60,
      "z": 5,
      "name": "Plant_Leaves_Beech_Max_Support"
    },
    {
      "x": -20,
      "y": 55,
      "z": 6,
      "name": "Plant_Leaves_Beech_Max_Support"
    },
    {
      "x": -20,
      "y": 56,
      "z": 6,
      "name": "Plant_Leaves_Beech_Max_Support"
    },
    {
      "x": -20,
      "y": 57,
      "z": 6,
      "name": "Plant_Leaves_Beech_Max_Support"
    },
    {
      "x": -20,
      "y": 58,
      "z": 6,
      "name": "Plant_Leaves_Beech_Max_Support"
    },
    {
      "x": -20,
      "y": 59,
      "z": 6,
      "name": "Plant_Leaves_Beech_Max_Support"
    },
    {
      "x": -20,
      "y": 60,
      "z": 6,
      "name": "Plant_Leaves_Beech_Max_Support"
    },
    {
      "x": -20,
      "y": 55,
      "z": 7,
      "name": "Plant_Leaves_Beech_Max_Support"
    },
    {
      "x": -20,
      "y": 56,
      "z": 7,
      "name": "Plant_Leaves_Beech_Max_Support"
    },
    {
      "x": -20,
      "y": 57,
      "z": 7,
      "name": "Plant_Leaves_Beech_Max_Support"
    },
    {
      "x": -20,
      "y": 58,
      "z": 7,
      "name": "Plant_Leaves_Beech_Max_Support"
    },
    {
      "x": -20,
      "y": 60,
      "z": 7,
      "name": "Plant_Leaves_Beech_Max_Support"
    },
    {
      "x": -20,
      "y": 61,
      "z": 7,
      "name": "Plant_Leaves_Beech_Max_Support"
    },
    {
      "x": -20,
      "y": 56,
      "z": 8,
      "name": "Plant_Leaves_Beech_Max_Support"
    },
    {
      "x": -20,
      "y": 57,
      "z": 8,
      "name": "Plant_Leaves_Beech_Max_Support"
    },
    {
      "x": -20,
      "y": 58,
      "z": 8,
      "name": "Plant_Leaves_Beech_Max_Support"
    },
    {
      "x": -20,
      "y": 59,
      "z": 8,
      "name": "Plant_Leaves_Beech_Max_Support"
    },
    {
      "x": -20,
      "y": 60,
      "z": 8,
      "name": "Plant_Leaves_Beech_Max_Support"
    },
    {
      "x": -20,
      "y": 61,
      "z": 8,
      "name": "Plant_Leaves_Beech_Max_Support"
    },
    {
      "x": -20,
      "y": 56,
      "z": 9,
      "name": "Wood_Gumboab_Trunk_Full"
    },
    {
      "x": -20,
      "y": 57,
      "z": 9,
      "name": "Plant_Leaves_Beech_Max_Support"
    },
    {
      "x": -20,
      "y": 58,
      "z": 9,
      "name": "Plant_Leaves_Beech_Max_Support"
    },
    {
      "x": -20,
      "y": 59,
      "z": 9,
      "name": "Plant_Leaves_Beech_Max_Support"
    },
    {
      "x": -20,
      "y": 60,
      "z": 9,
      "name": "Plant_Leaves_Beech_Max_Support"
    },
    {
      "x": -20,
      "y": 61,
      "z": 9,
      "name": "Plant_Leaves_Beech_Max_Support"
    },
    {
      "x": -20,
      "y": 62,
      "z": 9,
      "name": "Plant_Leaves_Beech_Max_Support"
    },
    {
      "x": -20,
      "y": 55,
      "z": 10,
      "name": "Plant_Leaves_Beech_Max_Support"
    },
    {
      "x": -20,
      "y": 56,
      "z": 10,
      "name": "Plant_Leaves_Beech_Max_Support"
    },
    {
      "x": -20,
      "y": 57,
      "z": 10,
      "name": "Plant_Leaves_Beech_Max_Support"
    },
    {
      "x": -20,
      "y": 59,
      "z": 10,
      "name": "Plant_Leaves_Beech_Max_Support"
    },
    {
      "x": -20,
      "y": 60,
      "z": 10,
      "name": "Plant_Leaves_Beech_Max_Support"
    },
    {
      "x": -20,
      "y": 61,
      "z": 10,
      "name": "Plant_Leaves_Beech_Max_Support"
    },
    {
      "x": -20,
      "y": 55,
      "z": 11,
      "name": "Plant_Leaves_Beech_Max_Support"
    },
    {
      "x": -20,
      "y": 56,
      "z": 11,
      "name": "Plant_Leaves_Beech_Max_Support"
    },
    {
      "x": -20,
      "y": 57,
      "z": 11,
      "name": "Plant_Leaves_Beech_Max_Support"
    },
    {
      "x": -20,
      "y": 58,
      "z": 11,
      "name": "Plant_Leaves_Beech_Max_Support"
    },
    {
      "x": -20,
      "y": 59,
      "z": 11,
      "name": "Plant_Leaves_Beech_Max_Support"
    },
    {
      "x": -20,
      "y": 60,
      "z": 11,
      "name": "Plant_Leaves_Beech_Max_Support"
    },
    {
      "x": -20,
      "y": 55,
      "z": 12,
      "name": "Plant_Leaves_Beech_Max_Support"
    },
    {
      "x": -20,
      "y": 56,
      "z": 12,
      "name": "Plant_Leaves_Beech_Max_Support"
    },
    {
      "x": -20,
      "y": 57,
      "z": 12,
      "name": "Plant_Leaves_Beech_Max_Support"
    },
    {
      "x": -20,
      "y": 58,
      "z": 12,
      "name": "Plant_Leaves_Beech_Max_Support"
    },
    {
      "x": -20,
      "y": 59,
      "z": 12,
      "name": "Plant_Leaves_Beech_Max_Support"
    },
    {
      "x": -20,
      "y": 60,
      "z": 12,
      "name": "Plant_Leaves_Beech_Max_Support"
    },
    {
      "x": -20,
      "y": 55,
      "z": 13,
      "name": "Plant_Leaves_Beech_Max_Support"
    },
    {
      "x": -20,
      "y": 56,
      "z": 13,
      "name": "Plant_Leaves_Beech_Max_Support"
    },
    {
      "x": -20,
      "y": 57,
      "z": 13,
      "name": "Plant_Leaves_Beech_Max_Support"
    },
    {
      "x": -20,
      "y": 58,
      "z": 13,
      "name": "Plant_Leaves_Beech_Max_Support"
    },
    {
      "x": -20,
      "y": 59,
      "z": 13,
      "name": "Plant_Leaves_Beech_Max_Support"
    },
    {
      "x": -20,
      "y": 56,
      "z": 14,
      "name": "Plant_Leaves_Beech_Max_Support"
    },
    {
      "x": -20,
      "y": 57,
      "z": 14,
      "name": "Plant_Leaves_Beech_Max_Support"
    },
    {
      "x": -20,
      "y": 58,
      "z": 14,
      "name": "Plant_Leaves_Beech_Max_Support"
    },
    {
      "x": -20,
      "y": 56,
      "z": 15,
      "name": "Plant_Leaves_Beech_Max_Support"
    },
    {
      "x": -20,
      "y": 57,
      "z": 15,
      "name": "Plant_Leaves_Beech_Max_Support"
    },
    {
      "x": -20,
      "y": 58,
      "z": 15,
      "name": "Plant_Leaves_Beech_Max_Support"
    },
    {
      "x": -20,
      "y": 59,
      "z": 15,
      "name": "Plant_Leaves_Beech_Max_Support"
    },
    {
      "x": -20,
      "y": 55,
      "z": 16,
      "name": "Plant_Leaves_Beech_Max_Support"
    },
    {
      "x": -20,
      "y": 56,
      "z": 16,
      "name": "Plant_Leaves_Beech_Max_Support"
    },
    {
      "x": -20,
      "y": 57,
      "z": 16,
      "name": "Plant_Leaves_Beech_Max_Support"
    },
    {
      "x": -20,
      "y": 58,
      "z": 16,
      "name": "Plant_Leaves_Beech_Max_Support"
    },
    {
      "x": -20,
      "y": 60,
      "z": 16,
      "name": "Plant_Leaves_Beech_Max_Support"
    },
    {
      "x": -20,
      "y": 61,
      "z": 16,
      "name": "Plant_Leaves_Beech_Max_Support"
    },
    {
      "x": -20,
      "y": 55,
      "z": 17,
      "name": "Plant_Leaves_Beech_Max_Support"
    },
    {
      "x": -20,
      "y": 56,
      "z": 17,
      "name": "Plant_Leaves_Beech_Max_Support"
    },
    {
      "x": -20,
      "y": 57,
      "z": 17,
      "name": "Plant_Leaves_Beech_Max_Support"
    },
    {
      "x": -20,
      "y": 58,
      "z": 17,
      "name": "Plant_Leaves_Beech_Max_Support"
    },
    {
      "x": -20,
      "y": 59,
      "z": 17,
      "name": "Plant_Leaves_Beech_Max_Support"
    },
    {
      "x": -20,
      "y": 60,
      "z": 17,
      "name": "Plant_Leaves_Beech_Max_Support"
    },
    {
      "x": -20,
      "y": 55,
      "z": 18,
      "name": "Plant_Leaves_Beech_Max_Support"
    },
    {
      "x": -20,
      "y": 56,
      "z": 18,
      "name": "Plant_Leaves_Beech_Max_Support"
    },
    {
      "x": -20,
      "y": 57,
      "z": 18,
      "name": "Plant_Leaves_Beech_Max_Support"
    },
    {
      "x": -20,
      "y": 58,
      "z": 18,
      "name": "Plant_Leaves_Beech_Max_Support"
    },
    {
      "x": -20,
      "y": 59,
      "z": 18,
      "name": "Plant_Leaves_Beech_Max_Support"
    },
    {
      "x": -20,
      "y": 55,
      "z": 19,
      "name": "Plant_Leaves_Beech_Max_Support"
    },
    {
      "x": -20,
      "y": 56,
      "z": 19,
      "name": "Plant_Leaves_Beech_Max_Support"
    },
    {
      "x": -20,
      "y": 57,
      "z": 19,
      "name": "Plant_Leaves_Beech_Max_Support"
    },
    {
      "x": -20,
      "y": 58,
      "z": 19,
      "name": "Plant_Leaves_Beech_Max_Support"
    },
    {
      "x": -20,
      "y": 59,
      "z": 19,
      "name": "Plant_Leaves_Beech_Max_Support"
    },
    {
      "x": -20,
      "y": 55,
      "z": 20,
      "name": "Plant_Leaves_Beech_Max_Support"
    },
    {
      "x": -20,
      "y": 56,
      "z": 20,
      "name": "Plant_Leaves_Beech_Max_Support"
    },
    {
      "x": -20,
      "y": 57,
      "z": 20,
      "name": "Plant_Leaves_Beech_Max_Support"
    },
    {
      "x": -20,
      "y": 58,
      "z": 20,
      "name": "Plant_Leaves_Beech_Max_Support"
    },
    {
      "x": -20,
      "y": 59,
      "z": 20,
      "name": "Plant_Leaves_Beech_Max_Support"
    },
    {
      "x": -20,
      "y": 60,
      "z": 20,
      "name": "Plant_Leaves_Beech_Max_Support"
    },
    {
      "x": -20,
      "y": 61,
      "z": 20,
      "name": "Plant_Leaves_Beech_Max_Support"
    },
    {
      "x": -20,
      "y": 54,
      "z": 21,
      "name": "Plant_Leaves_Beech_Max_Support"
    },
    {
      "x": -20,
      "y": 55,
      "z": 21,
      "name": "Plant_Leaves_Beech_Max_Support"
    },
    {
      "x": -20,
      "y": 56,
      "z": 21,
      "name": "Plant_Leaves_Beech_Max_Support"
    },
    {
      "x": -20,
      "y": 57,
      "z": 21,
      "name": "Plant_Leaves_Beech_Max_Support"
    },
    {
      "x": -20,
      "y": 58,
      "z": 21,
      "name": "Plant_Leaves_Beech_Max_Support"
    },
    {
      "x": -20,
      "y": 59,
      "z": 21,
      "name": "Plant_Leaves_Beech_Max_Support"
    },
    {
      "x": -20,
      "y": 61,
      "z": 21,
      "name": "Plant_Leaves_Beech_Max_Support"
    },
    {
      "x": -20,
      "y": 56,
      "z": 22,
      "name": "Plant_Leaves_Beech_Max_Support"
    },
    {
      "x": -20,
      "y": 57,
      "z": 22,
      "name": "Plant_Leaves_Beech_Max_Support"
    },
    {
      "x": -20,
      "y": 58,
      "z": 22,
      "name": "Plant_Leaves_Beech_Max_Support"
    },
    {
      "x": -20,
      "y": 59,
      "z": 22,
      "name": "Plant_Leaves_Beech_Max_Support"
    },
    {
      "x": -20,
      "y": 60,
      "z": 22,
      "name": "Plant_Leaves_Beech_Max_Support"
    },
    {
      "x": -20,
      "y": 56,
      "z": 23,
      "name": "Plant_Leaves_Beech_Max_Support"
    },
    {
      "x": -20,
      "y": 57,
      "z": 23,
      "name": "Plant_Leaves_Beech_Max_Support"
    },
    {
      "x": -20,
      "y": 58,
      "z": 23,
      "name": "Plant_Leaves_Beech_Max_Support"
    },
    {
      "x": -20,
      "y": 59,
      "z": 23,
      "name": "Plant_Leaves_Beech_Max_Support"
    },
    {
      "x": -20,
      "y": 60,
      "z": 23,
      "name": "Plant_Leaves_Beech_Max_Support"
    },
    {
      "x": -20,
      "y": 57,
      "z": 24,
      "name": "Plant_Leaves_Beech_Max_Support"
    },
    {
      "x": -20,
      "y": 58,
      "z": 24,
      "name": "Plant_Leaves_Beech_Max_Support"
    },
    {
      "x": -19,
      "y": 54,
      "z": 4,
      "name": "Plant_Leaves_Beech_Max_Support"
    },
    {
      "x": -19,
      "y": 55,
      "z": 4,
      "name": "Plant_Leaves_Beech_Max_Support"
    },
    {
      "x": -19,
      "y": 56,
      "z": 4,
      "name": "Plant_Leaves_Beech_Max_Support"
    },
    {
      "x": -19,
      "y": 55,
      "z": 5,
      "name": "Plant_Leaves_Beech_Max_Support"
    },
    {
      "x": -19,
      "y": 56,
      "z": 5,
      "name": "Plant_Leaves_Beech_Max_Support"
    },
    {
      "x": -19,
      "y": 57,
      "z": 5,
      "name": "Plant_Leaves_Beech_Max_Support"
    },
    {
      "x": -19,
      "y": 58,
      "z": 5,
      "name": "Plant_Leaves_Beech_Max_Support"
    },
    {
      "x": -19,
      "y": 59,
      "z": 5,
      "name": "Plant_Leaves_Beech_Max_Support"
    },
    {
      "x": -19,
      "y": 55,
      "z": 6,
      "name": "Plant_Leaves_Beech_Max_Support"
    },
    {
      "x": -19,
      "y": 56,
      "z": 6,
      "name": "Plant_Leaves_Beech_Max_Support"
    },
    {
      "x": -19,
      "y": 57,
      "z": 6,
      "name": "Plant_Leaves_Beech_Max_Support"
    },
    {
      "x": -19,
      "y": 58,
      "z": 6,
      "name": "Plant_Leaves_Beech_Max_Support"
    },
    {
      "x": -19,
      "y": 59,
      "z": 6,
      "name": "Plant_Leaves_Beech_Max_Support"
    },
    {
      "x": -19,
      "y": 61,
      "z": 6,
      "name": "Plant_Leaves_Beech_Max_Support"
    },
    {
      "x": -19,
      "y": 55,
      "z": 7,
      "name": "Plant_Leaves_Beech_Max_Support"
    },
    {
      "x": -19,
      "y": 56,
      "z": 7,
      "name": "Plant_Leaves_Beech_Max_Support"
    },
    {
      "x": -19,
      "y": 57,
      "z": 7,
      "name": "Plant_Leaves_Beech_Max_Support"
    },
    {
      "x": -19,
      "y": 58,
      "z": 7,
      "name": "Plant_Leaves_Beech_Max_Support"
    },
    {
      "x": -19,
      "y": 59,
      "z": 7,
      "name": "Plant_Leaves_Beech_Max_Support"
    },
    {
      "x": -19,
      "y": 60,
      "z": 7,
      "name": "Plant_Leaves_Beech_Max_Support"
    },
    {
      "x": -19,
      "y": 61,
      "z": 7,
      "name": "Plant_Leaves_Beech_Max_Support"
    },
    {
      "x": -19,
      "y": 62,
      "z": 7,
      "name": "Plant_Leaves_Beech_Max_Support"
    },
    {
      "x": -19,
      "y": 56,
      "z": 8,
      "name": "Plant_Leaves_Beech_Max_Support"
    },
    {
      "x": -19,
      "y": 57,
      "z": 8,
      "name": "Plant_Leaves_Beech_Max_Support"
    },
    {
      "x": -19,
      "y": 58,
      "z": 8,
      "name": "Plant_Leaves_Beech_Max_Support"
    },
    {
      "x": -19,
      "y": 59,
      "z": 8,
      "name": "Plant_Leaves_Beech_Max_Support"
    },
    {
      "x": -19,
      "y": 60,
      "z": 8,
      "name": "Plant_Leaves_Beech_Max_Support"
    },
    {
      "x": -19,
      "y": 62,
      "z": 8,
      "name": "Plant_Leaves_Beech_Max_Support"
    },
    {
      "x": -19,
      "y": 56,
      "z": 9,
      "name": "Wood_Gumboab_Trunk_Full"
    },
    {
      "x": -19,
      "y": 57,
      "z": 9,
      "name": "Plant_Leaves_Beech_Max_Support"
    },
    {
      "x": -19,
      "y": 58,
      "z": 9,
      "name": "Plant_Leaves_Beech_Max_Support"
    },
    {
      "x": -19,
      "y": 59,
      "z": 9,
      "name": "Plant_Leaves_Beech_Max_Support"
    },
    {
      "x": -19,
      "y": 60,
      "z": 9,
      "name": "Plant_Leaves_Beech_Max_Support"
    },
    {
      "x": -19,
      "y": 56,
      "z": 10,
      "name": "Plant_Leaves_Beech_Max_Support"
    },
    {
      "x": -19,
      "y": 57,
      "z": 10,
      "name": "Plant_Leaves_Beech_Max_Support"
    },
    {
      "x": -19,
      "y": 58,
      "z": 10,
      "name": "Plant_Leaves_Beech_Max_Support"
    },
    {
      "x": -19,
      "y": 59,
      "z": 10,
      "name": "Plant_Leaves_Beech_Max_Support"
    },
    {
      "x": -19,
      "y": 60,
      "z": 10,
      "name": "Plant_Leaves_Beech_Max_Support"
    },
    {
      "x": -19,
      "y": 56,
      "z": 11,
      "name": "Plant_Leaves_Beech_Max_Support"
    },
    {
      "x": -19,
      "y": 57,
      "z": 11,
      "name": "Plant_Leaves_Beech_Max_Support"
    },
    {
      "x": -19,
      "y": 58,
      "z": 11,
      "name": "Plant_Leaves_Beech_Max_Support"
    },
    {
      "x": -19,
      "y": 59,
      "z": 11,
      "name": "Plant_Leaves_Beech_Max_Support"
    },
    {
      "x": -19,
      "y": 60,
      "z": 11,
      "name": "Plant_Leaves_Beech_Max_Support"
    },
    {
      "x": -19,
      "y": 56,
      "z": 12,
      "name": "Plant_Leaves_Beech_Max_Support"
    },
    {
      "x": -19,
      "y": 57,
      "z": 12,
      "name": "Plant_Leaves_Beech_Max_Support"
    },
    {
      "x": -19,
      "y": 58,
      "z": 12,
      "name": "Plant_Leaves_Beech_Max_Support"
    },
    {
      "x": -19,
      "y": 59,
      "z": 12,
      "name": "Plant_Leaves_Beech_Max_Support"
    },
    {
      "x": -19,
      "y": 56,
      "z": 13,
      "name": "Plant_Leaves_Beech_Max_Support"
    },
    {
      "x": -19,
      "y": 57,
      "z": 13,
      "name": "Plant_Leaves_Beech_Max_Support"
    },
    {
      "x": -19,
      "y": 58,
      "z": 13,
      "name": "Plant_Leaves_Beech_Max_Support"
    },
    {
      "x": -19,
      "y": 59,
      "z": 13,
      "name": "Plant_Leaves_Beech_Max_Support"
    },
    {
      "x": -19,
      "y": 56,
      "z": 14,
      "name": "Plant_Leaves_Beech_Max_Support"
    },
    {
      "x": -19,
      "y": 57,
      "z": 14,
      "name": "Plant_Leaves_Beech_Max_Support"
    },
    {
      "x": -19,
      "y": 58,
      "z": 14,
      "name": "Plant_Leaves_Beech_Max_Support"
    },
    {
      "x": -19,
      "y": 59,
      "z": 14,
      "name": "Plant_Leaves_Beech_Max_Support"
    },
    {
      "x": -19,
      "y": 55,
      "z": 15,
      "name": "Plant_Leaves_Beech_Max_Support"
    },
    {
      "x": -19,
      "y": 56,
      "z": 15,
      "name": "Plant_Leaves_Beech_Max_Support"
    },
    {
      "x": -19,
      "y": 57,
      "z": 15,
      "name": "Plant_Leaves_Beech_Max_Support"
    },
    {
      "x": -19,
      "y": 58,
      "z": 15,
      "name": "Plant_Leaves_Beech_Max_Support"
    },
    {
      "x": -19,
      "y": 59,
      "z": 15,
      "name": "Plant_Leaves_Beech_Max_Support"
    },
    {
      "x": -19,
      "y": 61,
      "z": 15,
      "name": "Plant_Leaves_Beech_Max_Support"
    },
    {
      "x": -19,
      "y": 54,
      "z": 16,
      "name": "Plant_Leaves_Beech_Max_Support"
    },
    {
      "x": -19,
      "y": 55,
      "z": 16,
      "name": "Wood_Gumboab_Trunk_Full"
    },
    {
      "x": -19,
      "y": 56,
      "z": 16,
      "name": "Plant_Leaves_Beech_Max_Support"
    },
    {
      "x": -19,
      "y": 57,
      "z": 16,
      "name": "Plant_Leaves_Beech_Max_Support"
    },
    {
      "x": -19,
      "y": 58,
      "z": 16,
      "name": "Plant_Leaves_Beech_Max_Support"
    },
    {
      "x": -19,
      "y": 59,
      "z": 16,
      "name": "Plant_Leaves_Beech_Max_Support"
    },
    {
      "x": -19,
      "y": 55,
      "z": 17,
      "name": "Wood_Gumboab_Trunk_Full"
    },
    {
      "x": -19,
      "y": 56,
      "z": 17,
      "name": "Wood_Gumboab_Trunk_Full"
    },
    {
      "x": -19,
      "y": 57,
      "z": 17,
      "name": "Plant_Leaves_Beech_Max_Support"
    },
    {
      "x": -19,
      "y": 58,
      "z": 17,
      "name": "Plant_Leaves_Beech_Max_Support"
    },
    {
      "x": -19,
      "y": 59,
      "z": 17,
      "name": "Plant_Leaves_Beech_Max_Support"
    },
    {
      "x": -19,
      "y": 55,
      "z": 18,
      "name": "Wood_Gumboab_Trunk_Full"
    },
    {
      "x": -19,
      "y": 56,
      "z": 18,
      "name": "Plant_Leaves_Beech_Max_Support"
    },
    {
      "x": -19,
      "y": 57,
      "z": 18,
      "name": "Plant_Leaves_Beech_Max_Support"
    },
    {
      "x": -19,
      "y": 58,
      "z": 18,
      "name": "Plant_Leaves_Beech_Max_Support"
    },
    {
      "x": -19,
      "y": 59,
      "z": 18,
      "name": "Plant_Leaves_Beech_Max_Support"
    },
    {
      "x": -19,
      "y": 60,
      "z": 18,
      "name": "Plant_Leaves_Beech_Max_Support"
    },
    {
      "x": -19,
      "y": 54,
      "z": 19,
      "name": "Wood_Gumboab_Roots"
    },
    {
      "x": -19,
      "y": 55,
      "z": 19,
      "name": "Plant_Leaves_Beech_Max_Support"
    },
    {
      "x": -19,
      "y": 56,
      "z": 19,
      "name": "Plant_Leaves_Beech_Max_Support"
    },
    {
      "x": -19,
      "y": 57,
      "z": 19,
      "name": "Plant_Leaves_Beech_Max_Support"
    },
    {
      "x": -19,
      "y": 58,
      "z": 19,
      "name": "Plant_Leaves_Beech_Max_Support"
    },
    {
      "x": -19,
      "y": 54,
      "z": 20,
      "name": "Plant_Leaves_Beech_Max_Support"
    },
    {
      "x": -19,
      "y": 55,
      "z": 20,
      "name": "Plant_Leaves_Beech_Max_Support"
    },
    {
      "x": -19,
      "y": 57,
      "z": 20,
      "name": "Plant_Leaves_Beech_Max_Support"
    },
    {
      "x": -19,
      "y": 58,
      "z": 20,
      "name": "Plant_Leaves_Beech_Max_Support"
    },
    {
      "x": -19,
      "y": 59,
      "z": 20,
      "name": "Plant_Leaves_Beech_Max_Support"
    },
    {
      "x": -19,
      "y": 60,
      "z": 20,
      "name": "Plant_Leaves_Beech_Max_Support"
    },
    {
      "x": -19,
      "y": 55,
      "z": 21,
      "name": "Plant_Leaves_Beech_Max_Support"
    },
    {
      "x": -19,
      "y": 56,
      "z": 21,
      "name": "Plant_Leaves_Beech_Max_Support"
    },
    {
      "x": -19,
      "y": 57,
      "z": 21,
      "name": "Plant_Leaves_Beech_Max_Support"
    },
    {
      "x": -19,
      "y": 58,
      "z": 21,
      "name": "Plant_Leaves_Beech_Max_Support"
    },
    {
      "x": -19,
      "y": 59,
      "z": 21,
      "name": "Plant_Leaves_Beech_Max_Support"
    },
    {
      "x": -19,
      "y": 54,
      "z": 22,
      "name": "Plant_Leaves_Beech_Max_Support"
    },
    {
      "x": -19,
      "y": 55,
      "z": 22,
      "name": "Plant_Leaves_Beech_Max_Support"
    },
    {
      "x": -19,
      "y": 56,
      "z": 22,
      "name": "Plant_Leaves_Beech_Max_Support"
    },
    {
      "x": -19,
      "y": 57,
      "z": 22,
      "name": "Plant_Leaves_Beech_Max_Support"
    },
    {
      "x": -19,
      "y": 58,
      "z": 22,
      "name": "Plant_Leaves_Beech_Max_Support"
    },
    {
      "x": -19,
      "y": 55,
      "z": 23,
      "name": "Plant_Leaves_Beech_Max_Support"
    },
    {
      "x": -19,
      "y": 56,
      "z": 23,
      "name": "Plant_Leaves_Beech_Max_Support"
    },
    {
      "x": -19,
      "y": 57,
      "z": 23,
      "name": "Plant_Leaves_Beech_Max_Support"
    },
    {
      "x": -19,
      "y": 58,
      "z": 23,
      "name": "Plant_Leaves_Beech_Max_Support"
    },
    {
      "x": -19,
      "y": 59,
      "z": 23,
      "name": "Plant_Leaves_Beech_Max_Support"
    },
    {
      "x": -18,
      "y": 3,
      "z": -9,
      "name": "Wood_Gumboab_Trunk_Full"
    },
    {
      "x": -18,
      "y": 2,
      "z": -8,
      "name": "Wood_Gumboab_Trunk_Full"
    },
    {
      "x": -18,
      "y": 3,
      "z": -8,
      "name": "Wood_Gumboab_Trunk_Full"
    },
    {
      "x": -18,
      "y": 1,
      "z": -7,
      "name": "Wood_Gumboab_Trunk_Full"
    },
    {
      "x": -18,
      "y": 2,
      "z": -7,
      "name": "Wood_Gumboab_Trunk_Full"
    },
    {
      "x": -18,
      "y": -1,
      "z": -6,
      "name": "Wood_Gumboab_Roots"
    },
    {
      "x": -18,
      "y": 0,
      "z": -6,
      "name": "Wood_Gumboab_Trunk_Full"
    },
    {
      "x": -18,
      "y": 1,
      "z": -6,
      "name": "Wood_Gumboab_Trunk_Full"
    },
    {
      "x": -18,
      "y": -1,
      "z": -5,
      "name": "Wood_Gumboab_Roots"
    },
    {
      "x": -18,
      "y": 0,
      "z": -5,
      "name": "Wood_Gumboab_Trunk_Full"
    },
    {
      "x": -18,
      "y": 56,
      "z": 3,
      "name": "Plant_Leaves_Beech_Max_Support"
    },
    {
      "x": -18,
      "y": 55,
      "z": 4,
      "name": "Plant_Leaves_Beech_Max_Support"
    },
    {
      "x": -18,
      "y": 56,
      "z": 5,
      "name": "Plant_Leaves_Beech_Max_Support"
    },
    {
      "x": -18,
      "y": 57,
      "z": 5,
      "name": "Plant_Leaves_Beech_Max_Support"
    },
    {
      "x": -18,
      "y": 58,
      "z": 5,
      "name": "Plant_Leaves_Beech_Max_Support"
    },
    {
      "x": -18,
      "y": 55,
      "z": 6,
      "name": "Plant_Leaves_Beech_Max_Support"
    },
    {
      "x": -18,
      "y": 56,
      "z": 6,
      "name": "Plant_Leaves_Beech_Max_Support"
    },
    {
      "x": -18,
      "y": 57,
      "z": 6,
      "name": "Plant_Leaves_Beech_Max_Support"
    },
    {
      "x": -18,
      "y": 58,
      "z": 6,
      "name": "Plant_Leaves_Beech_Max_Support"
    },
    {
      "x": -18,
      "y": 59,
      "z": 6,
      "name": "Plant_Leaves_Beech_Max_Support"
    },
    {
      "x": -18,
      "y": 60,
      "z": 6,
      "name": "Plant_Leaves_Beech_Max_Support"
    },
    {
      "x": -18,
      "y": 55,
      "z": 7,
      "name": "Plant_Leaves_Beech_Max_Support"
    },
    {
      "x": -18,
      "y": 56,
      "z": 7,
      "name": "Plant_Leaves_Beech_Max_Support"
    },
    {
      "x": -18,
      "y": 57,
      "z": 7,
      "name": "Plant_Leaves_Beech_Max_Support"
    },
    {
      "x": -18,
      "y": 58,
      "z": 7,
      "name": "Plant_Leaves_Beech_Max_Support"
    },
    {
      "x": -18,
      "y": 59,
      "z": 7,
      "name": "Plant_Leaves_Beech_Max_Support"
    },
    {
      "x": -18,
      "y": 60,
      "z": 7,
      "name": "Plant_Leaves_Beech_Max_Support"
    },
    {
      "x": -18,
      "y": 61,
      "z": 7,
      "name": "Plant_Leaves_Beech_Max_Support"
    },
    {
      "x": -18,
      "y": 62,
      "z": 7,
      "name": "Plant_Leaves_Beech_Max_Support"
    },
    {
      "x": -18,
      "y": 56,
      "z": 8,
      "name": "Plant_Leaves_Beech_Max_Support"
    },
    {
      "x": -18,
      "y": 57,
      "z": 8,
      "name": "Plant_Leaves_Beech_Max_Support"
    },
    {
      "x": -18,
      "y": 59,
      "z": 8,
      "name": "Plant_Leaves_Beech_Max_Support"
    },
    {
      "x": -18,
      "y": 60,
      "z": 8,
      "name": "Plant_Leaves_Beech_Max_Support"
    },
    {
      "x": -18,
      "y": 61,
      "z": 8,
      "name": "Plant_Leaves_Beech_Max_Support"
    },
    {
      "x": -18,
      "y": 55,
      "z": 9,
      "name": "Wood_Gumboab_Roots"
    },
    {
      "x": -18,
      "y": 56,
      "z": 9,
      "name": "Wood_Gumboab_Trunk_Full"
    },
    {
      "x": -18,
      "y": 57,
      "z": 9,
      "name": "Plant_Leaves_Beech_Max_Support"
    },
    {
      "x": -18,
      "y": 58,
      "z": 9,
      "name": "Plant_Leaves_Beech_Max_Support"
    },
    {
      "x": -18,
      "y": 60,
      "z": 9,
      "name": "Plant_Leaves_Beech_Max_Support"
    },
    {
      "x": -18,
      "y": 56,
      "z": 10,
      "name": "Plant_Leaves_Beech_Max_Support"
    },
    {
      "x": -18,
      "y": 57,
      "z": 10,
      "name": "Plant_Leaves_Beech_Max_Support"
    },
    {
      "x": -18,
      "y": 58,
      "z": 10,
      "name": "Plant_Leaves_Beech_Max_Support"
    },
    {
      "x": -18,
      "y": 59,
      "z": 10,
      "name": "Plant_Leaves_Beech_Max_Support"
    },
    {
      "x": -18,
      "y": 56,
      "z": 11,
      "name": "Plant_Leaves_Beech_Max_Support"
    },
    {
      "x": -18,
      "y": 57,
      "z": 11,
      "name": "Plant_Leaves_Beech_Max_Support"
    },
    {
      "x": -18,
      "y": 58,
      "z": 11,
      "name": "Plant_Leaves_Beech_Max_Support"
    },
    {
      "x": -18,
      "y": 55,
      "z": 12,
      "name": "Plant_Leaves_Beech_Max_Support"
    },
    {
      "x": -18,
      "y": 57,
      "z": 12,
      "name": "Plant_Leaves_Beech_Max_Support"
    },
    {
      "x": -18,
      "y": 58,
      "z": 12,
      "name": "Plant_Leaves_Beech_Max_Support"
    },
    {
      "x": -18,
      "y": 59,
      "z": 12,
      "name": "Plant_Leaves_Beech_Max_Support"
    },
    {
      "x": -18,
      "y": 55,
      "z": 13,
      "name": "Plant_Leaves_Beech_Max_Support"
    },
    {
      "x": -18,
      "y": 56,
      "z": 13,
      "name": "Plant_Leaves_Beech_Max_Support"
    },
    {
      "x": -18,
      "y": 57,
      "z": 13,
      "name": "Plant_Leaves_Beech_Max_Support"
    },
    {
      "x": -18,
      "y": 58,
      "z": 13,
      "name": "Plant_Leaves_Beech_Max_Support"
    },
    {
      "x": -18,
      "y": 59,
      "z": 13,
      "name": "Plant_Leaves_Beech_Max_Support"
    },
    {
      "x": -18,
      "y": 60,
      "z": 13,
      "name": "Plant_Leaves_Beech_Max_Support"
    },
    {
      "x": -18,
      "y": 55,
      "z": 14,
      "name": "Plant_Leaves_Beech_Max_Support"
    },
    {
      "x": -18,
      "y": 56,
      "z": 14,
      "name": "Plant_Leaves_Beech_Max_Support"
    },
    {
      "x": -18,
      "y": 57,
      "z": 14,
      "name": "Plant_Leaves_Beech_Max_Support"
    },
    {
      "x": -18,
      "y": 58,
      "z": 14,
      "name": "Plant_Leaves_Beech_Max_Support"
    },
    {
      "x": -18,
      "y": 59,
      "z": 14,
      "name": "Plant_Leaves_Beech_Max_Support"
    },
    {
      "x": -18,
      "y": 54,
      "z": 15,
      "name": "Plant_Leaves_Beech_Max_Support"
    },
    {
      "x": -18,
      "y": 55,
      "z": 15,
      "name": "Wood_Gumboab_Trunk_Full"
    },
    {
      "x": -18,
      "y": 56,
      "z": 15,
      "name": "Plant_Leaves_Beech_Max_Support"
    },
    {
      "x": -18,
      "y": 57,
      "z": 15,
      "name": "Plant_Leaves_Beech_Max_Support"
    },
    {
      "x": -18,
      "y": 58,
      "z": 15,
      "name": "Plant_Leaves_Beech_Max_Support"
    },
    {
      "x": -18,
      "y": 59,
      "z": 15,
      "name": "Plant_Leaves_Beech_Max_Support"
    },
    {
      "x": -18,
      "y": 60,
      "z": 15,
      "name": "Plant_Leaves_Beech_Max_Support"
    },
    {
      "x": -18,
      "y": 55,
      "z": 16,
      "name": "Wood_Gumboab_Trunk_Full"
    },
    {
      "x": -18,
      "y": 56,
      "z": 16,
      "name": "Plant_Leaves_Beech_Max_Support"
    },
    {
      "x": -18,
      "y": 57,
      "z": 16,
      "name": "Plant_Leaves_Beech_Max_Support"
    },
    {
      "x": -18,
      "y": 58,
      "z": 16,
      "name": "Plant_Leaves_Beech_Max_Support"
    },
    {
      "x": -18,
      "y": 59,
      "z": 16,
      "name": "Plant_Leaves_Beech_Max_Support"
    },
    {
      "x": -18,
      "y": 60,
      "z": 16,
      "name": "Plant_Leaves_Beech_Max_Support"
    },
    {
      "x": -18,
      "y": 61,
      "z": 16,
      "name": "Plant_Leaves_Beech_Max_Support"
    },
    {
      "x": -18,
      "y": 65,
      "z": 16,
      "name": "Plant_Leaves_Beech_Max_Support"
    },
    {
      "x": -18,
      "y": 54,
      "z": 17,
      "name": "Plant_Leaves_Beech_Max_Support"
    },
    {
      "x": -18,
      "y": 55,
      "z": 17,
      "name": "Wood_Gumboab_Trunk_Full"
    },
    {
      "x": -18,
      "y": 56,
      "z": 17,
      "name": "Plant_Leaves_Beech_Max_Support"
    },
    {
      "x": -18,
      "y": 57,
      "z": 17,
      "name": "Plant_Leaves_Beech_Max_Support"
    },
    {
      "x": -18,
      "y": 58,
      "z": 17,
      "name": "Plant_Leaves_Beech_Max_Support"
    },
    {
      "x": -18,
      "y": 59,
      "z": 17,
      "name": "Plant_Leaves_Beech_Max_Support"
    },
    {
      "x": -18,
      "y": 64,
      "z": 17,
      "name": "Plant_Leaves_Beech_Max_Support"
    },
    {
      "x": -18,
      "y": 56,
      "z": 18,
      "name": "Plant_Leaves_Beech_Max_Support"
    },
    {
      "x": -18,
      "y": 57,
      "z": 18,
      "name": "Plant_Leaves_Beech_Max_Support"
    },
    {
      "x": -18,
      "y": 58,
      "z": 18,
      "name": "Plant_Leaves_Beech_Max_Support"
    },
    {
      "x": -18,
      "y": 59,
      "z": 18,
      "name": "Plant_Leaves_Beech_Max_Support"
    },
    {
      "x": -18,
      "y": 65,
      "z": 18,
      "name": "Plant_Leaves_Beech_Max_Support"
    },
    {
      "x": -18,
      "y": 66,
      "z": 18,
      "name": "Plant_Leaves_Beech_Max_Support"
    },
    {
      "x": -18,
      "y": 56,
      "z": 19,
      "name": "Plant_Leaves_Beech_Max_Support"
    },
    {
      "x": -18,
      "y": 58,
      "z": 19,
      "name": "Plant_Leaves_Beech_Max_Support"
    },
    {
      "x": -18,
      "y": 59,
      "z": 19,
      "name": "Plant_Leaves_Beech_Max_Support"
    },
    {
      "x": -18,
      "y": 60,
      "z": 19,
      "name": "Plant_Leaves_Beech_Max_Support"
    },
    {
      "x": -18,
      "y": 55,
      "z": 20,
      "name": "Plant_Leaves_Beech_Max_Support"
    },
    {
      "x": -18,
      "y": 56,
      "z": 20,
      "name": "Plant_Leaves_Beech_Max_Support"
    },
    {
      "x": -18,
      "y": 57,
      "z": 20,
      "name": "Plant_Leaves_Beech_Max_Support"
    },
    {
      "x": -18,
      "y": 58,
      "z": 20,
      "name": "Plant_Leaves_Beech_Max_Support"
    },
    {
      "x": -18,
      "y": 59,
      "z": 20,
      "name": "Plant_Leaves_Beech_Max_Support"
    },
    {
      "x": -18,
      "y": 60,
      "z": 20,
      "name": "Plant_Leaves_Beech_Max_Support"
    },
    {
      "x": -18,
      "y": 66,
      "z": 20,
      "name": "Plant_Leaves_Beech_Max_Support"
    },
    {
      "x": -18,
      "y": 54,
      "z": 21,
      "name": "Plant_Leaves_Beech_Max_Support"
    },
    {
      "x": -18,
      "y": 55,
      "z": 21,
      "name": "Plant_Leaves_Beech_Max_Support"
    },
    {
      "x": -18,
      "y": 56,
      "z": 21,
      "name": "Plant_Leaves_Beech_Max_Support"
    },
    {
      "x": -18,
      "y": 57,
      "z": 21,
      "name": "Plant_Leaves_Beech_Max_Support"
    },
    {
      "x": -18,
      "y": 58,
      "z": 21,
      "name": "Plant_Leaves_Beech_Max_Support"
    },
    {
      "x": -18,
      "y": 55,
      "z": 22,
      "name": "Plant_Leaves_Beech_Max_Support"
    },
    {
      "x": -18,
      "y": 56,
      "z": 22,
      "name": "Plant_Leaves_Beech_Max_Support"
    },
    {
      "x": -18,
      "y": 57,
      "z": 22,
      "name": "Plant_Leaves_Beech_Max_Support"
    },
    {
      "x": -18,
      "y": 58,
      "z": 22,
      "name": "Plant_Leaves_Beech_Max_Support"
    },
    {
      "x": -18,
      "y": 59,
      "z": 22,
      "name": "Plant_Leaves_Beech_Max_Support"
    },
    {
      "x": -18,
      "y": 56,
      "z": 23,
      "name": "Plant_Leaves_Beech_Max_Support"
    },
    {
      "x": -17,
      "y": 43,
      "z": -15,
      "name": "Plant_Leaves_Beech_Max_Support"
    },
    {
      "x": -17,
      "y": 42,
      "z": -14,
      "name": "Plant_Leaves_Beech_Max_Support"
    },
    {
      "x": -17,
      "y": 41,
      "z": -13,
      "name": "Plant_Leaves_Beech_Max_Support"
    },
    {
      "x": -17,
      "y": 42,
      "z": -13,
      "name": "Plant_Leaves_Beech_Max_Support"
    },
    {
      "x": -17,
      "y": 4,
      "z": -10,
      "name": "Wood_Gumboab_Trunk_Full"
    },
    {
      "x": -17,
      "y": 5,
      "z": -10,
      "name": "Wood_Gumboab_Trunk_Full"
    },
    {
      "x": -17,
      "y": 6,
      "z": -10,
      "name": "Wood_Gumboab_Trunk_Full"
    },
    {
      "x": -17,
      "y": 3,
      "z": -9,
      "name": "Wood_Gumboab_Trunk_Full"
    },
    {
      "x": -17,
      "y": 4,
      "z": -9,
      "name": "Wood_Gumboab_Trunk_Full"
    },
    {
      "x": -17,
      "y": 2,
      "z": -8,
      "name": "Wood_Gumboab_Trunk_Full"
    },
    {
      "x": -17,
      "y": 3,
      "z": -8,
      "name": "Wood_Gumboab_Trunk_Full"
    },
    {
      "x": -17,
      "y": 2,
      "z": -7,
      "name": "Wood_Gumboab_Trunk_Full"
    },
    {
      "x": -17,
      "y": 55,
      "z": 3,
      "name": "Plant_Leaves_Beech_Max_Support"
    },
    {
      "x": -17,
      "y": 56,
      "z": 3,
      "name": "Plant_Leaves_Beech_Max_Support"
    },
    {
      "x": -17,
      "y": 54,
      "z": 4,
      "name": "Plant_Leaves_Beech_Max_Support"
    },
    {
      "x": -17,
      "y": 55,
      "z": 4,
      "name": "Plant_Leaves_Beech_Max_Support"
    },
    {
      "x": -17,
      "y": 56,
      "z": 4,
      "name": "Plant_Leaves_Beech_Max_Support"
    },
    {
      "x": -17,
      "y": 57,
      "z": 4,
      "name": "Plant_Leaves_Beech_Max_Support"
    },
    {
      "x": -17,
      "y": 58,
      "z": 4,
      "name": "Plant_Leaves_Beech_Max_Support"
    },
    {
      "x": -17,
      "y": 54,
      "z": 5,
      "name": "Plant_Leaves_Beech_Max_Support"
    },
    {
      "x": -17,
      "y": 55,
      "z": 5,
      "name": "Plant_Leaves_Beech_Max_Support"
    },
    {
      "x": -17,
      "y": 56,
      "z": 5,
      "name": "Plant_Leaves_Beech_Max_Support"
    },
    {
      "x": -17,
      "y": 57,
      "z": 5,
      "name": "Plant_Leaves_Beech_Max_Support"
    },
    {
      "x": -17,
      "y": 58,
      "z": 5,
      "name": "Plant_Leaves_Beech_Max_Support"
    },
    {
      "x": -17,
      "y": 54,
      "z": 6,
      "name": "Plant_Leaves_Beech_Max_Support"
    },
    {
      "x": -17,
      "y": 55,
      "z": 6,
      "name": "Plant_Leaves_Beech_Max_Support"
    },
    {
      "x": -17,
      "y": 56,
      "z": 6,
      "name": "Plant_Leaves_Beech_Max_Support"
    },
    {
      "x": -17,
      "y": 57,
      "z": 6,
      "name": "Plant_Leaves_Beech_Max_Support"
    },
    {
      "x": -17,
      "y": 58,
      "z": 6,
      "name": "Plant_Leaves_Beech_Max_Support"
    },
    {
      "x": -17,
      "y": 55,
      "z": 7,
      "name": "Plant_Leaves_Beech_Max_Support"
    },
    {
      "x": -17,
      "y": 56,
      "z": 7,
      "name": "Plant_Leaves_Beech_Max_Support"
    },
    {
      "x": -17,
      "y": 57,
      "z": 7,
      "name": "Plant_Leaves_Beech_Max_Support"
    },
    {
      "x": -17,
      "y": 58,
      "z": 7,
      "name": "Plant_Leaves_Beech_Max_Support"
    },
    {
      "x": -17,
      "y": 59,
      "z": 7,
      "name": "Plant_Leaves_Beech_Max_Support"
    },
    {
      "x": -17,
      "y": 60,
      "z": 7,
      "name": "Plant_Leaves_Beech_Max_Support"
    },
    {
      "x": -17,
      "y": 55,
      "z": 8,
      "name": "Plant_Leaves_Beech_Max_Support"
    },
    {
      "x": -17,
      "y": 56,
      "z": 8,
      "name": "Plant_Leaves_Beech_Max_Support"
    },
    {
      "x": -17,
      "y": 57,
      "z": 8,
      "name": "Plant_Leaves_Beech_Max_Support"
    },
    {
      "x": -17,
      "y": 58,
      "z": 8,
      "name": "Plant_Leaves_Beech_Max_Support"
    },
    {
      "x": -17,
      "y": 59,
      "z": 8,
      "name": "Plant_Leaves_Beech_Max_Support"
    },
    {
      "x": -17,
      "y": 60,
      "z": 8,
      "name": "Plant_Leaves_Beech_Max_Support"
    },
    {
      "x": -17,
      "y": 56,
      "z": 9,
      "name": "Wood_Gumboab_Trunk_Full"
    },
    {
      "x": -17,
      "y": 57,
      "z": 9,
      "name": "Plant_Leaves_Beech_Max_Support"
    },
    {
      "x": -17,
      "y": 58,
      "z": 9,
      "name": "Plant_Leaves_Beech_Max_Support"
    },
    {
      "x": -17,
      "y": 59,
      "z": 9,
      "name": "Plant_Leaves_Beech_Max_Support"
    },
    {
      "x": -17,
      "y": 60,
      "z": 9,
      "name": "Plant_Leaves_Beech_Max_Support"
    },
    {
      "x": -17,
      "y": 56,
      "z": 10,
      "name": "Plant_Leaves_Beech_Max_Support"
    },
    {
      "x": -17,
      "y": 57,
      "z": 10,
      "name": "Plant_Leaves_Beech_Max_Support"
    },
    {
      "x": -17,
      "y": 58,
      "z": 10,
      "name": "Plant_Leaves_Beech_Max_Support"
    },
    {
      "x": -17,
      "y": 59,
      "z": 10,
      "name": "Plant_Leaves_Beech_Max_Support"
    },
    {
      "x": -17,
      "y": 60,
      "z": 10,
      "name": "Plant_Leaves_Beech_Max_Support"
    },
    {
      "x": -17,
      "y": 57,
      "z": 11,
      "name": "Plant_Leaves_Beech_Max_Support"
    },
    {
      "x": -17,
      "y": 58,
      "z": 11,
      "name": "Plant_Leaves_Beech_Max_Support"
    },
    {
      "x": -17,
      "y": 59,
      "z": 11,
      "name": "Plant_Leaves_Beech_Max_Support"
    },
    {
      "x": -17,
      "y": 56,
      "z": 12,
      "name": "Plant_Leaves_Beech_Max_Support"
    },
    {
      "x": -17,
      "y": 57,
      "z": 12,
      "name": "Plant_Leaves_Beech_Max_Support"
    },
    {
      "x": -17,
      "y": 58,
      "z": 12,
      "name": "Plant_Leaves_Beech_Max_Support"
    },
    {
      "x": -17,
      "y": 59,
      "z": 12,
      "name": "Plant_Leaves_Beech_Max_Support"
    },
    {
      "x": -17,
      "y": 60,
      "z": 12,
      "name": "Plant_Leaves_Beech_Max_Support"
    },
    {
      "x": -17,
      "y": 55,
      "z": 13,
      "name": "Plant_Leaves_Beech_Max_Support"
    },
    {
      "x": -17,
      "y": 56,
      "z": 13,
      "name": "Plant_Leaves_Beech_Max_Support"
    },
    {
      "x": -17,
      "y": 57,
      "z": 13,
      "name": "Plant_Leaves_Beech_Max_Support"
    },
    {
      "x": -17,
      "y": 58,
      "z": 13,
      "name": "Plant_Leaves_Beech_Max_Support"
    },
    {
      "x": -17,
      "y": 59,
      "z": 13,
      "name": "Plant_Leaves_Beech_Max_Support"
    },
    {
      "x": -17,
      "y": 60,
      "z": 13,
      "name": "Plant_Leaves_Beech_Max_Support"
    },
    {
      "x": -17,
      "y": 56,
      "z": 14,
      "name": "Plant_Leaves_Beech_Max_Support"
    },
    {
      "x": -17,
      "y": 57,
      "z": 14,
      "name": "Plant_Leaves_Beech_Max_Support"
    },
    {
      "x": -17,
      "y": 58,
      "z": 14,
      "name": "Plant_Leaves_Beech_Max_Support"
    },
    {
      "x": -17,
      "y": 60,
      "z": 14,
      "name": "Plant_Leaves_Beech_Max_Support"
    },
    {
      "x": -17,
      "y": 55,
      "z": 15,
      "name": "Plant_Leaves_Beech_Max_Support"
    },
    {
      "x": -17,
      "y": 56,
      "z": 15,
      "name": "Wood_Gumboab_Trunk_Full"
    },
    {
      "x": -17,
      "y": 57,
      "z": 15,
      "name": "Plant_Leaves_Beech_Max_Support"
    },
    {
      "x": -17,
      "y": 58,
      "z": 15,
      "name": "Plant_Leaves_Beech_Max_Support"
    },
    {
      "x": -17,
      "y": 59,
      "z": 15,
      "name": "Plant_Leaves_Beech_Max_Support"
    },
    {
      "x": -17,
      "y": 54,
      "z": 16,
      "name": "Plant_Leaves_Beech_Max_Support"
    },
    {
      "x": -17,
      "y": 55,
      "z": 16,
      "name": "Plant_Leaves_Beech_Max_Support"
    },
    {
      "x": -17,
      "y": 56,
      "z": 16,
      "name": "Plant_Leaves_Beech_Max_Support"
    },
    {
      "x": -17,
      "y": 57,
      "z": 16,
      "name": "Plant_Leaves_Beech_Max_Support"
    },
    {
      "x": -17,
      "y": 59,
      "z": 16,
      "name": "Plant_Leaves_Beech_Max_Support"
    },
    {
      "x": -17,
      "y": 64,
      "z": 16,
      "name": "Plant_Leaves_Beech_Max_Support"
    },
    {
      "x": -17,
      "y": 66,
      "z": 16,
      "name": "Plant_Leaves_Beech_Max_Support"
    },
    {
      "x": -17,
      "y": 55,
      "z": 17,
      "name": "Plant_Leaves_Beech_Max_Support"
    },
    {
      "x": -17,
      "y": 56,
      "z": 17,
      "name": "Plant_Leaves_Beech_Max_Support"
    },
    {
      "x": -17,
      "y": 57,
      "z": 17,
      "name": "Plant_Leaves_Beech_Max_Support"
    },
    {
      "x": -17,
      "y": 58,
      "z": 17,
      "name": "Plant_Leaves_Beech_Max_Support"
    },
    {
      "x": -17,
      "y": 59,
      "z": 17,
      "name": "Plant_Leaves_Beech_Max_Support"
    },
    {
      "x": -17,
      "y": 65,
      "z": 17,
      "name": "Plant_Leaves_Beech_Max_Support"
    },
    {
      "x": -17,
      "y": 66,
      "z": 17,
      "name": "Plant_Leaves_Beech_Max_Support"
    },
    {
      "x": -17,
      "y": 55,
      "z": 18,
      "name": "Plant_Leaves_Beech_Max_Support"
    },
    {
      "x": -17,
      "y": 56,
      "z": 18,
      "name": "Plant_Leaves_Beech_Max_Support"
    },
    {
      "x": -17,
      "y": 57,
      "z": 18,
      "name": "Plant_Leaves_Beech_Max_Support"
    },
    {
      "x": -17,
      "y": 58,
      "z": 18,
      "name": "Plant_Leaves_Beech_Max_Support"
    },
    {
      "x": -17,
      "y": 59,
      "z": 18,
      "name": "Plant_Leaves_Beech_Max_Support"
    },
    {
      "x": -17,
      "y": 64,
      "z": 18,
      "name": "Plant_Leaves_Beech_Max_Support"
    },
    {
      "x": -17,
      "y": 65,
      "z": 18,
      "name": "Plant_Leaves_Beech_Max_Support"
    },
    {
      "x": -17,
      "y": 66,
      "z": 18,
      "name": "Plant_Leaves_Beech_Max_Support"
    },
    {
      "x": -17,
      "y": 67,
      "z": 18,
      "name": "Plant_Leaves_Beech_Max_Support"
    },
    {
      "x": -17,
      "y": 56,
      "z": 19,
      "name": "Plant_Leaves_Beech_Max_Support"
    },
    {
      "x": -17,
      "y": 58,
      "z": 19,
      "name": "Plant_Leaves_Beech_Max_Support"
    },
    {
      "x": -17,
      "y": 59,
      "z": 19,
      "name": "Plant_Leaves_Beech_Max_Support"
    },
    {
      "x": -17,
      "y": 60,
      "z": 19,
      "name": "Plant_Leaves_Beech_Max_Support"
    },
    {
      "x": -17,
      "y": 65,
      "z": 19,
      "name": "Plant_Leaves_Beech_Max_Support"
    },
    {
      "x": -17,
      "y": 66,
      "z": 19,
      "name": "Plant_Leaves_Beech_Max_Support"
    },
    {
      "x": -17,
      "y": 67,
      "z": 19,
      "name": "Plant_Leaves_Beech_Max_Support"
    },
    {
      "x": -17,
      "y": 68,
      "z": 19,
      "name": "Plant_Leaves_Beech_Max_Support"
    },
    {
      "x": -17,
      "y": 55,
      "z": 20,
      "name": "Plant_Leaves_Beech_Max_Support"
    },
    {
      "x": -17,
      "y": 56,
      "z": 20,
      "name": "Plant_Leaves_Beech_Max_Support"
    },
    {
      "x": -17,
      "y": 57,
      "z": 20,
      "name": "Plant_Leaves_Beech_Max_Support"
    },
    {
      "x": -17,
      "y": 58,
      "z": 20,
      "name": "Plant_Leaves_Beech_Max_Support"
    },
    {
      "x": -17,
      "y": 59,
      "z": 20,
      "name": "Plant_Leaves_Beech_Max_Support"
    },
    {
      "x": -17,
      "y": 60,
      "z": 20,
      "name": "Plant_Leaves_Beech_Max_Support"
    },
    {
      "x": -17,
      "y": 64,
      "z": 20,
      "name": "Plant_Leaves_Beech_Max_Support",
      "support": 15
    },
    {
      "x": -17,
      "y": 65,
      "z": 20,
      "name": "Plant_Leaves_Beech_Max_Support",
      "support": 15
    },
    {
      "x": -17,
      "y": 66,
      "z": 20,
      "name": "Plant_Leaves_Beech_Max_Support"
    },
    {
      "x": -17,
      "y": 67,
      "z": 20,
      "name": "Plant_Leaves_Beech_Max_Support"
    },
    {
      "x": -17,
      "y": 55,
      "z": 21,
      "name": "Plant_Leaves_Beech_Max_Support"
    },
    {
      "x": -17,
      "y": 56,
      "z": 21,
      "name": "Plant_Leaves_Beech_Max_Support"
    },
    {
      "x": -17,
      "y": 57,
      "z": 21,
      "name": "Plant_Leaves_Beech_Max_Support"
    },
    {
      "x": -17,
      "y": 59,
      "z": 21,
      "name": "Plant_Leaves_Beech_Max_Support"
    },
    {
      "x": -17,
      "y": 64,
      "z": 21,
      "name": "Plant_Leaves_Beech_Max_Support",
      "support": 15
    },
    {
      "x": -17,
      "y": 65,
      "z": 21,
      "name": "Plant_Leaves_Beech_Max_Support",
      "support": 15
    },
    {
      "x": -17,
      "y": 66,
      "z": 21,
      "name": "Plant_Leaves_Beech_Max_Support"
    },
    {
      "x": -17,
      "y": 67,
      "z": 21,
      "name": "Plant_Leaves_Beech_Max_Support"
    },
    {
      "x": -16,
      "y": 43,
      "z": -16,
      "name": "Plant_Leaves_Beech_Max_Support"
    },
    {
      "x": -16,
      "y": 44,
      "z": -16,
      "name": "Plant_Leaves_Beech_Max_Support"
    },
    {
      "x": -16,
      "y": 42,
      "z": -15,
      "name": "Plant_Leaves_Beech_Max_Support"
    },
    {
      "x": -16,
      "y": 43,
      "z": -15,
      "name": "Plant_Leaves_Beech_Max_Support"
    },
    {
      "x": -16,
      "y": 44,
      "z": -15,
      "name": "Plant_Leaves_Beech_Max_Support"
    },
    {
      "x": -16,
      "y": 41,
      "z": -14,
      "name": "Plant_Leaves_Beech_Max_Support"
    },
    {
      "x": -16,
      "y": 43,
      "z": -14,
      "name": "Plant_Leaves_Beech_Max_Support"
    },
    {
      "x": -16,
      "y": 44,
      "z": -14,
      "name": "Plant_Leaves_Beech_Max_Support"
    },
    {
      "x": -16,
      "y": 45,
      "z": -14,
      "name": "Plant_Leaves_Beech_Max_Support"
    },
    {
      "x": -16,
      "y": 41,
      "z": -13,
      "name": "Plant_Leaves_Beech_Max_Support"
    },
    {
      "x": -16,
      "y": 43,
      "z": -13,
      "name": "Plant_Leaves_Beech_Max_Support"
    },
    {
      "x": -16,
      "y": 44,
      "z": -13,
      "name": "Plant_Leaves_Beech_Max_Support"
    },
    {
      "x": -16,
      "y": 45,
      "z": -13,
      "name": "Plant_Leaves_Beech_Max_Support"
    },
    {
      "x": -16,
      "y": 64,
      "z": -13,
      "name": "Plant_Leaves_Beech_Max_Support"
    },
    {
      "x": -16,
      "y": 41,
      "z": -12,
      "name": "Plant_Leaves_Beech_Max_Support"
    },
    {
      "x": -16,
      "y": 43,
      "z": -12,
      "name": "Plant_Leaves_Beech_Max_Support"
    },
    {
      "x": -16,
      "y": 44,
      "z": -12,
      "name": "Plant_Leaves_Beech_Max_Support"
    },
    {
      "x": -16,
      "y": 63,
      "z": -12,
      "name": "Plant_Leaves_Beech_Max_Support"
    },
    {
      "x": -16,
      "y": 64,
      "z": -12,
      "name": "Plant_Leaves_Beech_Max_Support"
    },
    {
      "x": -16,
      "y": 65,
      "z": -12,
      "name": "Plant_Leaves_Beech_Max_Support"
    },
    {
      "x": -16,
      "y": 6,
      "z": -11,
      "name": "Wood_Gumboab_Trunk_Full"
    },
    {
      "x": -16,
      "y": 7,
      "z": -11,
      "name": "Wood_Gumboab_Trunk_Full"
    },
    {
      "x": -16,
      "y": 42,
      "z": -11,
      "name": "Plant_Leaves_Beech_Max_Support"
    },
    {
      "x": -16,
      "y": 43,
      "z": -11,
      "name": "Plant_Leaves_Beech_Max_Support"
    },
    {
      "x": -16,
      "y": 44,
      "z": -11,
      "name": "Plant_Leaves_Beech_Max_Support"
    },
    {
      "x": -16,
      "y": 4,
      "z": -10,
      "name": "Wood_Gumboab_Trunk_Full"
    },
    {
      "x": -16,
      "y": 5,
      "z": -10,
      "name": "Wood_Gumboab_Trunk_Full"
    },
    {
      "x": -16,
      "y": 6,
      "z": -10,
      "name": "Wood_Gumboab_Trunk_Full"
    },
    {
      "x": -16,
      "y": 7,
      "z": -10,
      "name": "Wood_Gumboab_Trunk_Full"
    },
    {
      "x": -16,
      "y": 42,
      "z": -10,
      "name": "Plant_Leaves_Beech_Max_Support"
    },
    {
      "x": -16,
      "y": 43,
      "z": -9,
      "name": "Plant_Leaves_Beech_Max_Support"
    },
    {
      "x": -16,
      "y": 44,
      "z": -9,
      "name": "Plant_Leaves_Beech_Max_Support"
    },
    {
      "x": -16,
      "y": 59,
      "z": 2,
      "name": "Plant_Leaves_Beech_Max_Support"
    },
    {
      "x": -16,
      "y": 56,
      "z": 3,
      "name": "Plant_Leaves_Beech_Max_Support"
    },
    {
      "x": -16,
      "y": 58,
      "z": 3,
      "name": "Plant_Leaves_Beech_Max_Support"
    },
    {
      "x": -16,
      "y": 59,
      "z": 3,
      "name": "Plant_Leaves_Beech_Max_Support"
    },
    {
      "x": -16,
      "y": 55,
      "z": 4,
      "name": "Plant_Leaves_Beech_Max_Support"
    },
    {
      "x": -16,
      "y": 56,
      "z": 4,
      "name": "Plant_Leaves_Beech_Max_Support"
    },
    {
      "x": -16,
      "y": 57,
      "z": 4,
      "name": "Plant_Leaves_Beech_Max_Support"
    },
    {
      "x": -16,
      "y": 59,
      "z": 4,
      "name": "Plant_Leaves_Beech_Max_Support"
    },
    {
      "x": -16,
      "y": 54,
      "z": 5,
      "name": "Plant_Leaves_Beech_Max_Support"
    },
    {
      "x": -16,
      "y": 55,
      "z": 5,
      "name": "Plant_Leaves_Beech_Max_Support"
    },
    {
      "x": -16,
      "y": 56,
      "z": 5,
      "name": "Plant_Leaves_Beech_Max_Support"
    },
    {
      "x": -16,
      "y": 57,
      "z": 5,
      "name": "Plant_Leaves_Beech_Max_Support"
    },
    {
      "x": -16,
      "y": 58,
      "z": 5,
      "name": "Plant_Leaves_Beech_Max_Support"
    },
    {
      "x": -16,
      "y": 59,
      "z": 5,
      "name": "Plant_Leaves_Beech_Max_Support"
    },
    {
      "x": -16,
      "y": 55,
      "z": 6,
      "name": "Plant_Leaves_Beech_Max_Support"
    },
    {
      "x": -16,
      "y": 56,
      "z": 6,
      "name": "Plant_Leaves_Beech_Max_Support"
    },
    {
      "x": -16,
      "y": 57,
      "z": 6,
      "name": "Plant_Leaves_Beech_Max_Support"
    },
    {
      "x": -16,
      "y": 58,
      "z": 6,
      "name": "Plant_Leaves_Beech_Max_Support"
    },
    {
      "x": -16,
      "y": 59,
      "z": 6,
      "name": "Plant_Leaves_Beech_Max_Support"
    },
    {
      "x": -16,
      "y": 55,
      "z": 7,
      "name": "Plant_Leaves_Beech_Max_Support"
    },
    {
      "x": -16,
      "y": 56,
      "z": 7,
      "name": "Plant_Leaves_Beech_Max_Support"
    },
    {
      "x": -16,
      "y": 57,
      "z": 7,
      "name": "Plant_Leaves_Beech_Max_Support"
    },
    {
      "x": -16,
      "y": 58,
      "z": 7,
      "name": "Plant_Leaves_Beech_Max_Support"
    },
    {
      "x": -16,
      "y": 59,
      "z": 7,
      "name": "Plant_Leaves_Beech_Max_Support"
    },
    {
      "x": -16,
      "y": 60,
      "z": 7,
      "name": "Plant_Leaves_Beech_Max_Support"
    },
    {
      "x": -16,
      "y": 55,
      "z": 8,
      "name": "Plant_Leaves_Beech_Max_Support"
    },
    {
      "x": -16,
      "y": 56,
      "z": 8,
      "name": "Wood_Gumboab_Trunk_Full"
    },
    {
      "x": -16,
      "y": 57,
      "z": 8,
      "name": "Plant_Leaves_Beech_Max_Support"
    },
    {
      "x": -16,
      "y": 58,
      "z": 8,
      "name": "Plant_Leaves_Beech_Max_Support"
    },
    {
      "x": -16,
      "y": 59,
      "z": 8,
      "name": "Plant_Leaves_Beech_Max_Support"
    },
    {
      "x": -16,
      "y": 60,
      "z": 8,
      "name": "Plant_Leaves_Beech_Max_Support"
    },
    {
      "x": -16,
      "y": 61,
      "z": 8,
      "name": "Plant_Leaves_Beech_Max_Support"
    },
    {
      "x": -16,
      "y": 55,
      "z": 9,
      "name": "Plant_Leaves_Beech_Max_Support"
    },
    {
      "x": -16,
      "y": 56,
      "z": 9,
      "name": "Wood_Gumboab_Trunk_Full"
    },
    {
      "x": -16,
      "y": 57,
      "z": 9,
      "name": "Plant_Leaves_Beech_Max_Support"
    },
    {
      "x": -16,
      "y": 58,
      "z": 9,
      "name": "Plant_Leaves_Beech_Max_Support"
    },
    {
      "x": -16,
      "y": 59,
      "z": 9,
      "name": "Plant_Leaves_Beech_Max_Support"
    },
    {
      "x": -16,
      "y": 60,
      "z": 9,
      "name": "Plant_Leaves_Beech_Max_Support"
    },
    {
      "x": -16,
      "y": 56,
      "z": 10,
      "name": "Plant_Leaves_Beech_Max_Support"
    },
    {
      "x": -16,
      "y": 59,
      "z": 10,
      "name": "Plant_Leaves_Beech_Max_Support"
    },
    {
      "x": -16,
      "y": 58,
      "z": 11,
      "name": "Plant_Leaves_Beech_Max_Support"
    },
    {
      "x": -16,
      "y": 57,
      "z": 12,
      "name": "Plant_Leaves_Beech_Max_Support"
    },
    {
      "x": -16,
      "y": 58,
      "z": 12,
      "name": "Plant_Leaves_Beech_Max_Support"
    },
    {
      "x": -16,
      "y": 59,
      "z": 12,
      "name": "Plant_Leaves_Beech_Max_Support"
    },
    {
      "x": -16,
      "y": 56,
      "z": 13,
      "name": "Plant_Leaves_Beech_Max_Support"
    },
    {
      "x": -16,
      "y": 57,
      "z": 13,
      "name": "Plant_Leaves_Beech_Max_Support"
    },
    {
      "x": -16,
      "y": 58,
      "z": 13,
      "name": "Plant_Leaves_Beech_Max_Support"
    },
    {
      "x": -16,
      "y": 59,
      "z": 13,
      "name": "Plant_Leaves_Beech_Max_Support"
    },
    {
      "x": -16,
      "y": 60,
      "z": 13,
      "name": "Plant_Leaves_Beech_Max_Support"
    },
    {
      "x": -16,
      "y": 54,
      "z": 14,
      "name": "Wood_Gumboab_Roots"
    },
    {
      "x": -16,
      "y": 55,
      "z": 14,
      "name": "Plant_Leaves_Beech_Max_Support"
    },
    {
      "x": -16,
      "y": 56,
      "z": 14,
      "name": "Plant_Leaves_Beech_Max_Support"
    },
    {
      "x": -16,
      "y": 57,
      "z": 14,
      "name": "Plant_Leaves_Beech_Max_Support"
    },
    {
      "x": -16,
      "y": 58,
      "z": 14,
      "name": "Plant_Leaves_Beech_Max_Support"
    },
    {
      "x": -16,
      "y": 59,
      "z": 14,
      "name": "Plant_Leaves_Beech_Max_Support"
    },
    {
      "x": -16,
      "y": 54,
      "z": 15,
      "name": "Plant_Leaves_Beech_Max_Support"
    },
    {
      "x": -16,
      "y": 55,
      "z": 15,
      "name": "Plant_Leaves_Beech_Max_Support"
    },
    {
      "x": -16,
      "y": 56,
      "z": 15,
      "name": "Plant_Leaves_Beech_Max_Support"
    },
    {
      "x": -16,
      "y": 57,
      "z": 15,
      "name": "Plant_Leaves_Beech_Max_Support"
    },
    {
      "x": -16,
      "y": 58,
      "z": 15,
      "name": "Plant_Leaves_Beech_Max_Support"
    },
    {
      "x": -16,
      "y": 64,
      "z": 15,
      "name": "Plant_Leaves_Beech_Max_Support"
    },
    {
      "x": -16,
      "y": 66,
      "z": 15,
      "name": "Plant_Leaves_Beech_Max_Support"
    },
    {
      "x": -16,
      "y": 53,
      "z": 16,
      "name": "Plant_Leaves_Beech_Max_Support"
    },
    {
      "x": -16,
      "y": 54,
      "z": 16,
      "name": "Plant_Leaves_Beech_Max_Support"
    },
    {
      "x": -16,
      "y": 56,
      "z": 16,
      "name": "Plant_Leaves_Beech_Max_Support"
    },
    {
      "x": -16,
      "y": 57,
      "z": 16,
      "name": "Plant_Leaves_Beech_Max_Support"
    },
    {
      "x": -16,
      "y": 58,
      "z": 16,
      "name": "Plant_Leaves_Beech_Max_Support"
    },
    {
      "x": -16,
      "y": 63,
      "z": 16,
      "name": "Plant_Leaves_Beech_Max_Support"
    },
    {
      "x": -16,
      "y": 64,
      "z": 16,
      "name": "Plant_Leaves_Beech_Max_Support"
    },
    {
      "x": -16,
      "y": 65,
      "z": 16,
      "name": "Plant_Leaves_Beech_Max_Support"
    },
    {
      "x": -16,
      "y": 66,
      "z": 16,
      "name": "Plant_Leaves_Beech_Max_Support"
    },
    {
      "x": -16,
      "y": 67,
      "z": 16,
      "name": "Plant_Leaves_Beech_Max_Support"
    },
    {
      "x": -16,
      "y": 54,
      "z": 17,
      "name": "Plant_Leaves_Beech_Max_Support"
    },
    {
      "x": -16,
      "y": 55,
      "z": 17,
      "name": "Plant_Leaves_Beech_Max_Support"
    },
    {
      "x": -16,
      "y": 56,
      "z": 17,
      "name": "Plant_Leaves_Beech_Max_Support"
    },
    {
      "x": -16,
      "y": 57,
      "z": 17,
      "name": "Plant_Leaves_Beech_Max_Support"
    },
    {
      "x": -16,
      "y": 58,
      "z": 17,
      "name": "Plant_Leaves_Beech_Max_Support"
    },
    {
      "x": -16,
      "y": 63,
      "z": 17,
      "name": "Plant_Leaves_Beech_Max_Support"
    },
    {
      "x": -16,
      "y": 65,
      "z": 17,
      "name": "Plant_Leaves_Beech_Max_Support"
    },
    {
      "x": -16,
      "y": 66,
      "z": 17,
      "name": "Plant_Leaves_Beech_Max_Support"
    },
    {
      "x": -16,
      "y": 67,
      "z": 17,
      "name": "Plant_Leaves_Beech_Max_Support"
    },
    {
      "x": -16,
      "y": 55,
      "z": 18,
      "name": "Plant_Leaves_Beech_Max_Support"
    },
    {
      "x": -16,
      "y": 56,
      "z": 18,
      "name": "Plant_Leaves_Beech_Max_Support"
    },
    {
      "x": -16,
      "y": 59,
      "z": 18,
      "name": "Plant_Leaves_Beech_Max_Support"
    },
    {
      "x": -16,
      "y": 63,
      "z": 18,
      "name": "Plant_Leaves_Beech_Max_Support"
    },
    {
      "x": -16,
      "y": 64,
      "z": 18,
      "name": "Plant_Leaves_Beech_Max_Support"
    },
    {
      "x": -16,
      "y": 65,
      "z": 18,
      "name": "Plant_Leaves_Beech_Max_Support"
    },
    {
      "x": -16,
      "y": 66,
      "z": 18,
      "name": "Plant_Leaves_Beech_Max_Support"
    },
    {
      "x": -16,
      "y": 67,
      "z": 18,
      "name": "Plant_Leaves_Beech_Max_Support"
    },
    {
      "x": -16,
      "y": 68,
      "z": 18,
      "name": "Plant_Leaves_Beech_Max_Support"
    },
    {
      "x": -16,
      "y": 55,
      "z": 19,
      "name": "Plant_Leaves_Beech_Max_Support"
    },
    {
      "x": -16,
      "y": 56,
      "z": 19,
      "name": "Plant_Leaves_Beech_Max_Support"
    },
    {
      "x": -16,
      "y": 57,
      "z": 19,
      "name": "Plant_Leaves_Beech_Max_Support"
    },
    {
      "x": -16,
      "y": 58,
      "z": 19,
      "name": "Plant_Leaves_Beech_Max_Support"
    },
    {
      "x": -16,
      "y": 60,
      "z": 19,
      "name": "Plant_Leaves_Beech_Max_Support"
    },
    {
      "x": -16,
      "y": 64,
      "z": 19,
      "name": "Plant_Leaves_Beech_Max_Support"
    },
    {
      "x": -16,
      "y": 66,
      "z": 19,
      "name": "Plant_Leaves_Beech_Max_Support"
    },
    {
      "x": -16,
      "y": 67,
      "z": 19,
      "name": "Plant_Leaves_Beech_Max_Support"
    },
    {
      "x": -16,
      "y": 68,
      "z": 19,
      "name": "Plant_Leaves_Beech_Max_Support"
    },
    {
      "x": -16,
      "y": 55,
      "z": 20,
      "name": "Plant_Leaves_Beech_Max_Support"
    },
    {
      "x": -16,
      "y": 56,
      "z": 20,
      "name": "Plant_Leaves_Beech_Max_Support"
    },
    {
      "x": -16,
      "y": 57,
      "z": 20,
      "name": "Plant_Leaves_Beech_Max_Support"
    },
    {
      "x": -16,
      "y": 58,
      "z": 20,
      "name": "Plant_Leaves_Beech_Max_Support"
    },
    {
      "x": -16,
      "y": 59,
      "z": 20,
      "name": "Plant_Leaves_Beech_Max_Support"
    },
    {
      "x": -16,
      "y": 60,
      "z": 20,
      "name": "Plant_Leaves_Beech_Max_Support"
    },
    {
      "x": -16,
      "y": 64,
      "z": 20,
      "name": "Plant_Leaves_Beech_Max_Support"
    },
    {
      "x": -16,
      "y": 66,
      "z": 20,
      "name": "Plant_Leaves_Beech_Max_Support"
    },
    {
      "x": -16,
      "y": 67,
      "z": 20,
      "name": "Plant_Leaves_Beech_Max_Support"
    },
    {
      "x": -16,
      "y": 68,
      "z": 20,
      "name": "Plant_Leaves_Beech_Max_Support"
    },
    {
      "x": -16,
      "y": 57,
      "z": 21,
      "name": "Plant_Leaves_Beech_Max_Support"
    },
    {
      "x": -16,
      "y": 58,
      "z": 21,
      "name": "Plant_Leaves_Beech_Max_Support"
    },
    {
      "x": -16,
      "y": 59,
      "z": 21,
      "name": "Plant_Leaves_Beech_Max_Support"
    },
    {
      "x": -16,
      "y": 64,
      "z": 21,
      "name": "Plant_Leaves_Beech_Max_Support"
    },
    {
      "x": -16,
      "y": 65,
      "z": 21,
      "name": "Plant_Leaves_Beech_Max_Support"
    },
    {
      "x": -16,
      "y": 66,
      "z": 21,
      "name": "Plant_Leaves_Beech_Max_Support"
    },
    {
      "x": -16,
      "y": 67,
      "z": 21,
      "name": "Plant_Leaves_Beech_Max_Support"
    },
    {
      "x": -16,
      "y": 68,
      "z": 21,
      "name": "Plant_Leaves_Beech_Max_Support"
    },
    {
      "x": -16,
      "y": 55,
      "z": 22,
      "name": "Plant_Leaves_Beech_Max_Support"
    },
    {
      "x": -16,
      "y": 56,
      "z": 22,
      "name": "Plant_Leaves_Beech_Max_Support"
    },
    {
      "x": -16,
      "y": 65,
      "z": 22,
      "name": "Plant_Leaves_Beech_Max_Support"
    },
    {
      "x": -16,
      "y": 67,
      "z": 22,
      "name": "Plant_Leaves_Beech_Max_Support"
    },
    {
      "x": -15,
      "y": 44,
      "z": -17,
      "name": "Plant_Leaves_Beech_Max_Support"
    },
    {
      "x": -15,
      "y": 42,
      "z": -16,
      "name": "Plant_Leaves_Beech_Max_Support"
    },
    {
      "x": -15,
      "y": 43,
      "z": -16,
      "name": "Plant_Leaves_Beech_Max_Support"
    },
    {
      "x": -15,
      "y": 44,
      "z": -16,
      "name": "Plant_Leaves_Beech_Max_Support"
    },
    {
      "x": -15,
      "y": 42,
      "z": -15,
      "name": "Plant_Leaves_Beech_Max_Support"
    },
    {
      "x": -15,
      "y": 43,
      "z": -15,
      "name": "Plant_Leaves_Beech_Max_Support"
    },
    {
      "x": -15,
      "y": 44,
      "z": -15,
      "name": "Plant_Leaves_Beech_Max_Support"
    },
    {
      "x": -15,
      "y": 45,
      "z": -15,
      "name": "Plant_Leaves_Beech_Max_Support"
    },
    {
      "x": -15,
      "y": 41,
      "z": -14,
      "name": "Plant_Leaves_Beech_Max_Support"
    },
    {
      "x": -15,
      "y": 42,
      "z": -14,
      "name": "Plant_Leaves_Beech_Max_Support"
    },
    {
      "x": -15,
      "y": 43,
      "z": -14,
      "name": "Plant_Leaves_Beech_Max_Support"
    },
    {
      "x": -15,
      "y": 44,
      "z": -14,
      "name": "Plant_Leaves_Beech_Max_Support"
    },
    {
      "x": -15,
      "y": 45,
      "z": -14,
      "name": "Plant_Leaves_Beech_Max_Support"
    },
    {
      "x": -15,
      "y": 46,
      "z": -14,
      "name": "Plant_Leaves_Beech_Max_Support"
    },
    {
      "x": -15,
      "y": 64,
      "z": -14,
      "name": "Plant_Leaves_Beech_Max_Support"
    },
    {
      "x": -15,
      "y": 41,
      "z": -13,
      "name": "Plant_Leaves_Beech_Max_Support"
    },
    {
      "x": -15,
      "y": 42,
      "z": -13,
      "name": "Plant_Leaves_Beech_Max_Support"
    },
    {
      "x": -15,
      "y": 43,
      "z": -13,
      "name": "Plant_Leaves_Beech_Max_Support"
    },
    {
      "x": -15,
      "y": 44,
      "z": -13,
      "name": "Plant_Leaves_Beech_Max_Support"
    },
    {
      "x": -15,
      "y": 45,
      "z": -13,
      "name": "Plant_Leaves_Beech_Max_Support"
    },
    {
      "x": -15,
      "y": 46,
      "z": -13,
      "name": "Plant_Leaves_Beech_Max_Support"
    },
    {
      "x": -15,
      "y": 65,
      "z": -13,
      "name": "Plant_Leaves_Beech_Max_Support"
    },
    {
      "x": -15,
      "y": 43,
      "z": -12,
      "name": "Plant_Leaves_Beech_Max_Support"
    },
    {
      "x": -15,
      "y": 44,
      "z": -12,
      "name": "Plant_Leaves_Beech_Max_Support"
    },
    {
      "x": -15,
      "y": 45,
      "z": -12,
      "name": "Plant_Leaves_Beech_Max_Support"
    },
    {
      "x": -15,
      "y": 46,
      "z": -12,
      "name": "Plant_Leaves_Beech_Max_Support"
    },
    {
      "x": -15,
      "y": 62,
      "z": -12,
      "name": "Plant_Leaves_Beech_Max_Support"
    },
    {
      "x": -15,
      "y": 63,
      "z": -12,
      "name": "Plant_Leaves_Beech_Max_Support"
    },
    {
      "x": -15,
      "y": 64,
      "z": -12,
      "name": "Plant_Leaves_Beech_Max_Support"
    },
    {
      "x": -15,
      "y": 65,
      "z": -12,
      "name": "Plant_Leaves_Beech_Max_Support"
    },
    {
      "x": -15,
      "y": 6,
      "z": -11,
      "name": "Wood_Gumboab_Trunk_Full"
    },
    {
      "x": -15,
      "y": 7,
      "z": -11,
      "name": "Wood_Gumboab_Trunk_Full"
    },
    {
      "x": -15,
      "y": 8,
      "z": -11,
      "name": "Wood_Gumboab_Trunk_Full"
    },
    {
      "x": -15,
      "y": 42,
      "z": -11,
      "name": "Plant_Leaves_Beech_Max_Support"
    },
    {
      "x": -15,
      "y": 43,
      "z": -11,
      "name": "Plant_Leaves_Beech_Max_Support"
    },
    {
      "x": -15,
      "y": 44,
      "z": -11,
      "name": "Plant_Leaves_Beech_Max_Support"
    },
    {
      "x": -15,
      "y": 45,
      "z": -11,
      "name": "Plant_Leaves_Beech_Max_Support"
    },
    {
      "x": -15,
      "y": 46,
      "z": -11,
      "name": "Plant_Leaves_Beech_Max_Support"
    },
    {
      "x": -15,
      "y": 6,
      "z": -10,
      "name": "Wood_Gumboab_Trunk_Full"
    },
    {
      "x": -15,
      "y": 7,
      "z": -10,
      "name": "Wood_Gumboab_Trunk_Full"
    },
    {
      "x": -15,
      "y": 8,
      "z": -10,
      "name": "Wood_Gumboab_Trunk_Full"
    },
    {
      "x": -15,
      "y": 42,
      "z": -10,
      "name": "Plant_Leaves_Beech_Max_Support"
    },
    {
      "x": -15,
      "y": 43,
      "z": -10,
      "name": "Plant_Leaves_Beech_Max_Support"
    },
    {
      "x": -15,
      "y": 44,
      "z": -10,
      "name": "Plant_Leaves_Beech_Max_Support"
    },
    {
      "x": -15,
      "y": 45,
      "z": -10,
      "name": "Plant_Leaves_Beech_Max_Support"
    },
    {
      "x": -15,
      "y": 63,
      "z": -10,
      "name": "Plant_Leaves_Beech_Max_Support"
    },
    {
      "x": -15,
      "y": 64,
      "z": -10,
      "name": "Plant_Leaves_Beech_Max_Support"
    },
    {
      "x": -15,
      "y": 44,
      "z": -9,
      "name": "Plant_Leaves_Beech_Max_Support"
    },
    {
      "x": -15,
      "y": 63,
      "z": -9,
      "name": "Plant_Leaves_Beech_Max_Support"
    },
    {
      "x": -15,
      "y": 43,
      "z": -8,
      "name": "Plant_Leaves_Beech_Max_Support"
    },
    {
      "x": -15,
      "y": 44,
      "z": -8,
      "name": "Plant_Leaves_Beech_Max_Support"
    },
    {
      "x": -15,
      "y": 60,
      "z": -8,
      "name": "Plant_Leaves_Beech_Max_Support"
    },
    {
      "x": -15,
      "y": 61,
      "z": -8,
      "name": "Plant_Leaves_Beech_Max_Support"
    },
    {
      "x": -15,
      "y": 62,
      "z": -8,
      "name": "Plant_Leaves_Beech_Max_Support"
    },
    {
      "x": -15,
      "y": 61,
      "z": -7,
      "name": "Plant_Leaves_Beech_Max_Support"
    },
    {
      "x": -15,
      "y": 59,
      "z": 1,
      "name": "Plant_Leaves_Beech_Max_Support"
    },
    {
      "x": -15,
      "y": 57,
      "z": 2,
      "name": "Plant_Leaves_Beech_Max_Support"
    },
    {
      "x": -15,
      "y": 57,
      "z": 3,
      "name": "Plant_Leaves_Beech_Max_Support"
    },
    {
      "x": -15,
      "y": 58,
      "z": 3,
      "name": "Plant_Leaves_Beech_Max_Support"
    },
    {
      "x": -15,
      "y": 56,
      "z": 4,
      "name": "Plant_Leaves_Beech_Max_Support"
    },
    {
      "x": -15,
      "y": 57,
      "z": 4,
      "name": "Plant_Leaves_Beech_Max_Support"
    },
    {
      "x": -15,
      "y": 58,
      "z": 4,
      "name": "Plant_Leaves_Beech_Max_Support"
    },
    {
      "x": -15,
      "y": 59,
      "z": 4,
      "name": "Plant_Leaves_Beech_Max_Support"
    },
    {
      "x": -15,
      "y": 55,
      "z": 5,
      "name": "Plant_Leaves_Beech_Max_Support"
    },
    {
      "x": -15,
      "y": 56,
      "z": 5,
      "name": "Plant_Leaves_Beech_Max_Support"
    },
    {
      "x": -15,
      "y": 57,
      "z": 5,
      "name": "Plant_Leaves_Beech_Max_Support"
    },
    {
      "x": -15,
      "y": 58,
      "z": 5,
      "name": "Plant_Leaves_Beech_Max_Support"
    },
    {
      "x": -15,
      "y": 59,
      "z": 5,
      "name": "Plant_Leaves_Beech_Max_Support"
    },
    {
      "x": -15,
      "y": 55,
      "z": 6,
      "name": "Plant_Leaves_Beech_Max_Support"
    },
    {
      "x": -15,
      "y": 56,
      "z": 6,
      "name": "Plant_Leaves_Beech_Max_Support"
    },
    {
      "x": -15,
      "y": 57,
      "z": 6,
      "name": "Plant_Leaves_Beech_Max_Support"
    },
    {
      "x": -15,
      "y": 58,
      "z": 6,
      "name": "Plant_Leaves_Beech_Max_Support"
    },
    {
      "x": -15,
      "y": 59,
      "z": 6,
      "name": "Plant_Leaves_Beech_Max_Support"
    },
    {
      "x": -15,
      "y": 60,
      "z": 6,
      "name": "Plant_Leaves_Beech_Max_Support"
    },
    {
      "x": -15,
      "y": 55,
      "z": 7,
      "name": "Plant_Leaves_Beech_Max_Support"
    },
    {
      "x": -15,
      "y": 56,
      "z": 7,
      "name": "Wood_Gumboab_Trunk_Full"
    },
    {
      "x": -15,
      "y": 57,
      "z": 7,
      "name": "Plant_Leaves_Beech_Max_Support"
    },
    {
      "x": -15,
      "y": 58,
      "z": 7,
      "name": "Plant_Leaves_Beech_Max_Support"
    },
    {
      "x": -15,
      "y": 59,
      "z": 7,
      "name": "Plant_Leaves_Beech_Max_Support"
    },
    {
      "x": -15,
      "y": 61,
      "z": 7,
      "name": "Plant_Leaves_Beech_Max_Support"
    },
    {
      "x": -15,
      "y": 54,
      "z": 8,
      "name": "Plant_Leaves_Beech_Max_Support"
    },
    {
      "x": -15,
      "y": 55,
      "z": 8,
      "name": "Wood_Gumboab_Trunk_Full"
    },
    {
