{
  "version": 8,
  "blockIdVersion": 11,
  "anchorX": -10,
  "anchorY": 21,
  "anchorZ": 0,
  "blocks": [
    {
      "x": -24,
      "y": 8,
      "z": -5,
      "name": "Wood_Gumboab_Trunk_Full"
    },
    {
      "x": -24,
      "y": 9,
      "z": -5,
      "name": "Wood_Gumboab_Trunk_Full"
    },
    {
      "x": -24,
      "y": 10,
      "z": -5,
      "name": "Wood_Gumboab_Trunk_Full"
    },
    {
      "x": -24,
      "y": 11,
      "z": -5,
      "name": "Wood_Gumboab_Trunk_Full"
    },
    {
      "x": -24,
      "y": 7,
      "z": -4,
      "name": "Wood_Gumboab_Trunk_Full"
    },
    {
      "x": -24,
      "y": 8,
      "z": -4,
      "name": "Wood_Gumboab_Trunk_Full"
    },
    {
      "x": -24,
      "y": 9,
      "z": -4,
      "name": "Wood_Gumboab_Trunk_Full"
    },
    {
      "x": -24,
      "y": 10,
      "z": -4,
      "name": "Wood_Gumboab_Trunk_Full"
    },
    {
      "x": -24,
      "y": 11,
      "z": -4,
      "name": "Wood_Gumboab_Trunk_Full"
    },
    {
      "x": -24,
      "y": 12,
      "z": -4,
      "name": "Wood_Gumboab_Trunk_Full"
    },
    {
      "x": -23,
      "y": 7,
      "z": -5,
      "name": "Wood_Gumboab_Trunk_Full"
    },
    {
      "x": -23,
      "y": 8,
      "z": -5,
      "name": "Wood_Gumboab_Trunk_Full"
    },
    {
      "x": -23,
      "y": 9,
      "z": -5,
      "name": "Wood_Gumboab_Trunk_Full"
    },
    {
      "x": -23,
      "y": 10,
      "z": -5,
      "name": "Wood_Gumboab_Trunk_Full"
    },
    {
      "x": -23,
      "y": 11,
      "z": -5,
      "name": "Wood_Gumboab_Trunk_Full"
    },
    {
      "x": -23,
      "y": 12,
      "z": -5,
      "name": "Wood_Gumboab_Trunk_Full"
    },
    {
      "x": -23,
      "y": 13,
      "z": -5,
      "name": "Wood_Gumboab_Trunk_Full"
    },
    {
      "x": -23,
      "y": 6,
      "z": -4,
      "name": "Wood_Gumboab_Trunk_Full"
    },
    {
      "x": -23,
      "y": 7,
      "z": -4,
      "name": "Wood_Gumboab_Trunk_Full"
    },
    {
      "x": -23,
      "y": 8,
      "z": -4,
      "name": "Wood_Gumboab_Trunk_Full"
    },
    {
      "x": -23,
      "y": 9,
      "z": -4,
      "name": "Wood_Gumboab_Trunk_Full"
    },
    {
      "x": -23,
      "y": 10,
      "z": -4,
      "name": "Wood_Gumboab_Trunk_Full"
    },
    {
      "x": -23,
      "y": 11,
      "z": -4,
      "name": "Wood_Gumboab_Trunk_Full"
    },
    {
      "x": -23,
      "y": 12,
      "z": -4,
      "name": "Wood_Gumboab_Trunk_Full"
    },
    {
      "x": -23,
      "y": 13,
      "z": -4,
      "name": "Wood_Gumboab_Trunk_Full"
    },
    {
      "x": -23,
      "y": 9,
      "z": 3,
      "name": "Wood_Gumboab_Roots"
    },
    {
      "x": -23,
      "y": 10,
      "z": 3,
      "name": "Wood_Gumboab_Trunk_Full"
    },
    {
      "x": -23,
      "y": 11,
      "z": 3,
      "name": "Wood_Gumboab_Trunk_Full"
    },
    {
      "x": -22,
      "y": 6,
      "z": -5,
      "name": "Wood_Gumboab_Trunk_Full"
    },
    {
      "x": -22,
      "y": 11,
      "z": -5,
      "name": "Wood_Gumboab_Trunk_Full"
    },
    {
      "x": -22,
      "y": 12,
      "z": -5,
      "name": "Wood_Gumboab_Trunk_Full"
    },
    {
      "x": -22,
      "y": 13,
      "z": -5,
      "name": "Wood_Gumboab_Trunk_Full"
    },
    {
      "x": -22,
      "y": 14,
      "z": -5,
      "name": "Wood_Gumboab_Trunk_Full"
    },
    {
      "x": -22,
      "y": 4,
      "z": -4,
      "name": "Wood_Gumboab_Roots"
    },
    {
      "x": -22,
      "y": 5,
      "z": -4,
      "name": "Wood_Gumboab_Trunk_Full"
    },
    {
      "x": -22,
      "y": 6,
      "z": -4,
      "name": "Wood_Gumboab_Trunk_Full"
    },
    {
      "x": -22,
      "y": 7,
      "z": -4,
      "name": "Wood_Gumboab_Trunk_Full"
    },
    {
      "x": -22,
      "y": 11,
      "z": -4,
      "name": "Wood_Gumboab_Trunk_Full"
    },
    {
      "x": -22,
      "y": 12,
      "z": -4,
      "name": "Wood_Gumboab_Trunk_Full"
    },
    {
      "x": -22,
      "y": 13,
      "z": -4,
      "name": "Wood_Gumboab_Trunk_Full"
    },
    {
      "x": -22,
      "y": 14,
      "z": -4,
      "name": "Wood_Gumboab_Trunk_Full"
    },
    {
      "x": -22,
      "y": 12,
      "z": 2,
      "name": "Wood_Gumboab_Trunk_Full"
    },
    {
      "x": -22,
      "y": 13,
      "z": 2,
      "name": "Wood_Gumboab_Trunk_Full"
    },
    {
      "x": -22,
      "y": 9,
      "z": 3,
      "name": "Wood_Gumboab_Roots"
    },
    {
      "x": -22,
      "y": 10,
      "z": 3,
      "name": "Wood_Gumboab_Trunk_Full"
    },
    {
      "x": -22,
      "y": 11,
      "z": 3,
      "name": "Wood_Gumboab_Trunk_Full"
    },
    {
      "x": -22,
      "y": 12,
      "z": 3,
      "name": "Wood_Gumboab_Trunk_Full"
    },
    {
      "x": -22,
      "y": 13,
      "z": 3,
      "name": "Wood_Gumboab_Trunk_Full"
    },
    {
      "x": -22,
      "y": 46,
      "z": 6,
      "name": "Plant_Leaves_Beech_Max_Support",
      "support": 15
    },
    {
      "x": -22,
      "y": 4,
      "z": 7,
      "name": "Wood_Gumboab_Roots"
    },
    {
      "x": -22,
      "y": 5,
      "z": 7,
      "name": "Wood_Gumboab_Trunk_Full"
    },
    {
      "x": -22,
      "y": 6,
      "z": 7,
      "name": "Wood_Gumboab_Trunk_Full"
    },
    {
      "x": -22,
      "y": 7,
      "z": 7,
      "name": "Wood_Gumboab_Trunk_Full"
    },
    {
      "x": -22,
      "y": 8,
      "z": 7,
      "name": "Wood_Gumboab_Trunk_Full"
    },
    {
      "x": -22,
      "y": 9,
      "z": 7,
      "name": "Wood_Gumboab_Trunk_Full"
    },
    {
      "x": -22,
      "y": 47,
      "z": 7,
      "name": "Plant_Leaves_Beech_Max_Support",
      "support": 15
    },
    {
      "x": -22,
      "y": 4,
      "z": 8,
      "name": "Wood_Gumboab_Roots"
    },
    {
      "x": -22,
      "y": 5,
      "z": 8,
      "name": "Wood_Gumboab_Trunk_Full"
    },
    {
      "x": -22,
      "y": 6,
      "z": 8,
      "name": "Wood_Gumboab_Trunk_Full"
    },
    {
      "x": -22,
      "y": 7,
      "z": 8,
      "name": "Wood_Gumboab_Trunk_Full"
    },
    {
      "x": -22,
      "y": 8,
      "z": 8,
      "name": "Wood_Gumboab_Trunk_Full"
    },
    {
      "x": -22,
      "y": 9,
      "z": 8,
      "name": "Wood_Gumboab_Trunk_Full"
    },
    {
      "x": -22,
      "y": 46,
      "z": 8,
      "name": "Plant_Leaves_Beech_Max_Support",
      "support": 15
    },
    {
      "x": -22,
      "y": 47,
      "z": 8,
      "name": "Plant_Leaves_Beech_Max_Support",
      "support": 15
    },
    {
      "x": -22,
      "y": 46,
      "z": 10,
      "name": "Plant_Leaves_Beech_Max_Support",
      "support": 15
    },
    {
      "x": -22,
      "y": 49,
      "z": 10,
      "name": "Plant_Leaves_Beech_Max_Support"
    },
    {
      "x": -22,
      "y": 50,
      "z": 10,
      "name": "Plant_Leaves_Beech_Max_Support"
    },
    {
      "x": -21,
      "y": 8,
      "z": -9,
      "name": "Wood_Gumboab_Trunk_Full"
    },
    {
      "x": -21,
      "y": 9,
      "z": -9,
      "name": "Wood_Gumboab_Trunk_Full"
    },
    {
      "x": -21,
      "y": 10,
      "z": -9,
      "name": "Wood_Gumboab_Trunk_Full"
    },
    {
      "x": -21,
      "y": 6,
      "z": -8,
      "name": "Wood_Gumboab_Trunk_Full"
    },
    {
      "x": -21,
      "y": 7,
      "z": -8,
      "name": "Wood_Gumboab_Trunk_Full"
    },
    {
      "x": -21,
      "y": 8,
      "z": -8,
      "name": "Wood_Gumboab_Trunk_Full"
    },
    {
      "x": -21,
      "y": 9,
      "z": -8,
      "name": "Wood_Gumboab_Trunk_Full"
    },
    {
      "x": -21,
      "y": 10,
      "z": -8,
      "name": "Wood_Gumboab_Trunk_Full"
    },
    {
      "x": -21,
      "y": 11,
      "z": -8,
      "name": "Wood_Gumboab_Trunk_Full"
    },
    {
      "x": -21,
      "y": 6,
      "z": -7,
      "name": "Wood_Gumboab_Trunk_Full"
    },
    {
      "x": -21,
      "y": 7,
      "z": -7,
      "name": "Wood_Gumboab_Trunk_Full"
    },
    {
      "x": -21,
      "y": 12,
      "z": -5,
      "name": "Wood_Gumboab_Trunk_Full"
    },
    {
      "x": -21,
      "y": 13,
      "z": -5,
      "name": "Wood_Gumboab_Trunk_Full"
    },
    {
      "x": -21,
      "y": 14,
      "z": -5,
      "name": "Wood_Gumboab_Trunk_Full"
    },
    {
      "x": -21,
      "y": 15,
      "z": -5,
      "name": "Wood_Gumboab_Trunk_Full"
    },
    {
      "x": -21,
      "y": 13,
      "z": -4,
      "name": "Wood_Gumboab_Trunk_Full"
    },
    {
      "x": -21,
      "y": 14,
      "z": -4,
      "name": "Wood_Gumboab_Trunk_Full"
    },
    {
      "x": -21,
      "y": 15,
      "z": -4,
      "name": "Wood_Gumboab_Trunk_Full"
    },
    {
      "x": -21,
      "y": 70,
      "z": 0,
      "name": "Plant_Leaves_Beech_Max_Support",
      "support": 15
    },
    {
      "x": -21,
      "y": 13,
      "z": 2,
      "name": "Wood_Gumboab_Trunk_Full"
    },
    {
      "x": -21,
      "y": 14,
      "z": 2,
      "name": "Wood_Gumboab_Trunk_Full"
    },
    {
      "x": -21,
      "y": 12,
      "z": 3,
      "name": "Wood_Gumboab_Trunk_Full"
    },
    {
      "x": -21,
      "y": 13,
      "z": 3,
      "name": "Wood_Gumboab_Trunk_Full"
    },
    {
      "x": -21,
      "y": 48,
      "z": 4,
      "name": "Plant_Leaves_Beech_Max_Support"
    },
    {
      "x": -21,
      "y": 49,
      "z": 4,
      "name": "Plant_Leaves_Beech_Max_Support"
    },
    {
      "x": -21,
      "y": 47,
      "z": 5,
      "name": "Plant_Leaves_Beech_Max_Support",
      "support": 15
    },
    {
      "x": -21,
      "y": 48,
      "z": 5,
      "name": "Plant_Leaves_Beech_Max_Support"
    },
    {
      "x": -21,
      "y": 49,
      "z": 5,
      "name": "Plant_Leaves_Beech_Max_Support"
    },
    {
      "x": -21,
      "y": 46,
      "z": 6,
      "name": "Plant_Leaves_Beech_Max_Support",
      "support": 15
    },
    {
      "x": -21,
      "y": 47,
      "z": 6,
      "name": "Plant_Leaves_Beech_Max_Support",
      "support": 15
    },
    {
      "x": -21,
      "y": 48,
      "z": 6,
      "name": "Plant_Leaves_Beech_Max_Support"
    },
    {
      "x": -21,
      "y": 49,
      "z": 6,
      "name": "Plant_Leaves_Beech_Max_Support"
    },
    {
      "x": -21,
      "y": 5,
      "z": 7,
      "name": "Wood_Gumboab_Trunk_Full"
    },
    {
      "x": -21,
      "y": 6,
      "z": 7,
      "name": "Wood_Gumboab_Trunk_Full"
    },
    {
      "x": -21,
      "y": 8,
      "z": 7,
      "name": "Wood_Gumboab_Trunk_Full"
    },
    {
      "x": -21,
      "y": 9,
      "z": 7,
      "name": "Wood_Gumboab_Trunk_Full"
    },
    {
      "x": -21,
      "y": 10,
      "z": 7,
      "name": "Wood_Gumboab_Trunk_Full"
    },
    {
      "x": -21,
      "y": 47,
      "z": 7,
      "name": "Plant_Leaves_Beech_Max_Support",
      "support": 15
    },
    {
      "x": -21,
      "y": 50,
      "z": 7,
      "name": "Plant_Leaves_Beech_Max_Support"
    },
    {
      "x": -21,
      "y": 5,
      "z": 8,
      "name": "Wood_Gumboab_Trunk_Full"
    },
    {
      "x": -21,
      "y": 6,
      "z": 8,
      "name": "Wood_Gumboab_Trunk_Full"
    },
    {
      "x": -21,
      "y": 7,
      "z": 8,
      "name": "Wood_Gumboab_Trunk_Full"
    },
    {
      "x": -21,
      "y": 8,
      "z": 8,
      "name": "Wood_Gumboab_Trunk_Full"
    },
    {
      "x": -21,
      "y": 9,
      "z": 8,
      "name": "Wood_Gumboab_Trunk_Full"
    },
    {
      "x": -21,
      "y": 10,
      "z": 8,
      "name": "Wood_Gumboab_Trunk_Full"
    },
    {
      "x": -21,
      "y": 47,
      "z": 8,
      "name": "Plant_Leaves_Beech_Max_Support",
      "support": 15
    },
    {
      "x": -21,
      "y": 48,
      "z": 8,
      "name": "Plant_Leaves_Beech_Max_Support"
    },
    {
      "x": -21,
      "y": 49,
      "z": 8,
      "name": "Plant_Leaves_Beech_Max_Support"
    },
    {
      "x": -21,
      "y": 48,
      "z": 9,
      "name": "Plant_Leaves_Beech_Max_Support"
    },
    {
      "x": -21,
      "y": 46,
      "z": 10,
      "name": "Plant_Leaves_Beech_Max_Support",
      "support": 15
    },
    {
      "x": -21,
      "y": 47,
      "z": 10,
      "name": "Plant_Leaves_Beech_Max_Support"
    },
    {
      "x": -21,
      "y": 48,
      "z": 10,
      "name": "Plant_Leaves_Beech_Max_Support"
    },
    {
      "x": -21,
      "y": 50,
      "z": 10,
      "name": "Plant_Leaves_Beech_Max_Support"
    },
    {
      "x": -21,
      "y": 46,
      "z": 11,
      "name": "Plant_Leaves_Beech_Max_Support",
      "support": 15
    },
    {
      "x": -21,
      "y": 47,
      "z": 11,
      "name": "Plant_Leaves_Beech_Max_Support",
      "support": 15
    },
    {
      "x": -21,
      "y": 49,
      "z": 11,
      "name": "Plant_Leaves_Beech_Max_Support"
    },
    {
      "x": -21,
      "y": 50,
      "z": 11,
      "name": "Plant_Leaves_Beech_Max_Support"
    },
    {
      "x": -20,
      "y": 8,
      "z": -9,
      "name": "Wood_Gumboab_Trunk_Full"
    },
    {
      "x": -20,
      "y": 9,
      "z": -9,
      "name": "Wood_Gumboab_Trunk_Full"
    },
    {
      "x": -20,
      "y": 10,
      "z": -9,
      "name": "Wood_Gumboab_Trunk_Full"
    },
    {
      "x": -20,
      "y": 11,
      "z": -9,
      "name": "Wood_Gumboab_Trunk_Full"
    },
    {
      "x": -20,
      "y": 12,
      "z": -9,
      "name": "Wood_Gumboab_Trunk_Full"
    },
    {
      "x": -20,
      "y": 6,
      "z": -8,
      "name": "Wood_Gumboab_Trunk_Full"
    },
    {
      "x": -20,
      "y": 7,
      "z": -8,
      "name": "Wood_Gumboab_Trunk_Full"
    },
    {
      "x": -20,
      "y": 8,
      "z": -8,
      "name": "Wood_Gumboab_Trunk_Full"
    },
    {
      "x": -20,
      "y": 9,
      "z": -8,
      "name": "Wood_Gumboab_Trunk_Full"
    },
    {
      "x": -20,
      "y": 10,
      "z": -8,
      "name": "Wood_Gumboab_Trunk_Full"
    },
    {
      "x": -20,
      "y": 11,
      "z": -8,
      "name": "Wood_Gumboab_Trunk_Full"
    },
    {
      "x": -20,
      "y": 12,
      "z": -8,
      "name": "Wood_Gumboab_Trunk_Full"
    },
    {
      "x": -20,
      "y": 13,
      "z": -8,
      "name": "Wood_Gumboab_Trunk_Full"
    },
    {
      "x": -20,
      "y": 5,
      "z": -7,
      "name": "Wood_Gumboab_Trunk_Full"
    },
    {
      "x": -20,
      "y": 6,
      "z": -7,
      "name": "Wood_Gumboab_Trunk_Full"
    },
    {
      "x": -20,
      "y": 7,
      "z": -7,
      "name": "Wood_Gumboab_Trunk_Full"
    },
    {
      "x": -20,
      "y": 8,
      "z": -7,
      "name": "Wood_Gumboab_Trunk_Full"
    },
    {
      "x": -20,
      "y": 12,
      "z": -7,
      "name": "Wood_Gumboab_Trunk_Full"
    },
    {
      "x": -20,
      "y": 13,
      "z": -7,
      "name": "Wood_Gumboab_Trunk_Full"
    },
    {
      "x": -20,
      "y": 14,
      "z": -7,
      "name": "Wood_Gumboab_Trunk_Full"
    },
    {
      "x": -20,
      "y": 5,
      "z": -6,
      "name": "Wood_Gumboab_Trunk_Full"
    },
    {
      "x": -20,
      "y": 14,
      "z": -6,
      "name": "Wood_Gumboab_Trunk_Full"
    },
    {
      "x": -20,
      "y": 15,
      "z": -6,
      "name": "Wood_Gumboab_Trunk_Full"
    },
    {
      "x": -20,
      "y": 13,
      "z": -5,
      "name": "Wood_Gumboab_Trunk_Full"
    },
    {
      "x": -20,
      "y": 14,
      "z": -5,
      "name": "Wood_Gumboab_Trunk_Full"
    },
    {
      "x": -20,
      "y": 15,
      "z": -5,
      "name": "Wood_Gumboab_Trunk_Full"
    },
    {
      "x": -20,
      "y": 16,
      "z": -5,
      "name": "Wood_Gumboab_Trunk_Full"
    },
    {
      "x": -20,
      "y": 13,
      "z": -4,
      "name": "Wood_Gumboab_Trunk_Full"
    },
    {
      "x": -20,
      "y": 14,
      "z": -4,
      "name": "Wood_Gumboab_Trunk_Full"
    },
    {
      "x": -20,
      "y": 15,
      "z": -4,
      "name": "Wood_Gumboab_Trunk_Full"
    },
    {
      "x": -20,
      "y": 16,
      "z": -4,
      "name": "Wood_Gumboab_Trunk_Full"
    },
    {
      "x": -20,
      "y": 70,
      "z": -2,
      "name": "Plant_Leaves_Beech_Max_Support",
      "support": 15
    },
    {
      "x": -20,
      "y": 71,
      "z": -2,
      "name": "Plant_Leaves_Beech_Max_Support",
      "support": 15
    },
    {
      "x": -20,
      "y": 73,
      "z": -2,
      "name": "Plant_Leaves_Beech_Max_Support",
      "support": 15
    },
    {
      "x": -20,
      "y": 74,
      "z": -2,
      "name": "Plant_Leaves_Beech_Max_Support"
    },
    {
      "x": -20,
      "y": 76,
      "z": -2,
      "name": "Plant_Leaves_Beech_Max_Support"
    },
    {
      "x": -20,
      "y": 72,
      "z": -1,
      "name": "Plant_Leaves_Beech_Max_Support",
      "support": 15
    },
    {
      "x": -20,
      "y": 74,
      "z": -1,
      "name": "Plant_Leaves_Beech_Max_Support"
    },
    {
      "x": -20,
      "y": 70,
      "z": 0,
      "name": "Plant_Leaves_Beech_Max_Support",
      "support": 15
    },
    {
      "x": -20,
      "y": 72,
      "z": 0,
      "name": "Plant_Leaves_Beech_Max_Support",
      "support": 15
    },
    {
      "x": -20,
      "y": 73,
      "z": 0,
      "name": "Plant_Leaves_Beech_Max_Support",
      "support": 15
    },
    {
      "x": -20,
      "y": 74,
      "z": 0,
      "name": "Plant_Leaves_Beech_Max_Support"
    },
    {
      "x": -20,
      "y": 75,
      "z": 0,
      "name": "Plant_Leaves_Beech_Max_Support"
    },
    {
      "x": -20,
      "y": 13,
      "z": 1,
      "name": "Wood_Gumboab_Trunk_Full"
    },
    {
      "x": -20,
      "y": 14,
      "z": 1,
      "name": "Wood_Gumboab_Trunk_Full"
    },
    {
      "x": -20,
      "y": 13,
      "z": 2,
      "name": "Wood_Gumboab_Trunk_Full"
    },
    {
      "x": -20,
      "y": 14,
      "z": 2,
      "name": "Wood_Gumboab_Trunk_Full"
    },
    {
      "x": -20,
      "y": 48,
      "z": 3,
      "name": "Plant_Leaves_Beech_Max_Support"
    },
    {
      "x": -20,
      "y": 50,
      "z": 3,
      "name": "Plant_Leaves_Beech_Max_Support"
    },
    {
      "x": -20,
      "y": 47,
      "z": 4,
      "name": "Plant_Leaves_Beech_Max_Support"
    },
    {
      "x": -20,
      "y": 51,
      "z": 4,
      "name": "Plant_Leaves_Beech_Max_Support"
    },
    {
      "x": -20,
      "y": 46,
      "z": 5,
      "name": "Plant_Leaves_Beech_Max_Support",
      "support": 15
    },
    {
      "x": -20,
      "y": 47,
      "z": 5,
      "name": "Plant_Leaves_Beech_Max_Support"
    },
    {
      "x": -20,
      "y": 50,
      "z": 5,
      "name": "Plant_Leaves_Beech_Max_Support"
    },
    {
      "x": -20,
      "y": 47,
      "z": 6,
      "name": "Plant_Leaves_Beech_Max_Support",
      "support": 15
    },
    {
      "x": -20,
      "y": 48,
      "z": 6,
      "name": "Plant_Leaves_Beech_Max_Support"
    },
    {
      "x": -20,
      "y": 49,
      "z": 6,
      "name": "Plant_Leaves_Beech_Max_Support"
    },
    {
      "x": -20,
      "y": 50,
      "z": 6,
      "name": "Plant_Leaves_Beech_Max_Support"
    },
    {
      "x": -20,
      "y": 9,
      "z": 7,
      "name": "Wood_Gumboab_Trunk_Full"
    },
    {
      "x": -20,
      "y": 10,
      "z": 7,
      "name": "Wood_Gumboab_Trunk_Full"
    },
    {
      "x": -20,
      "y": 11,
      "z": 7,
      "name": "Wood_Gumboab_Trunk_Full"
    },
    {
      "x": -20,
      "y": 47,
      "z": 7,
      "name": "Plant_Leaves_Beech_Max_Support",
      "support": 15
    },
    {
      "x": -20,
      "y": 48,
      "z": 7,
      "name": "Plant_Leaves_Beech_Max_Support"
    },
    {
      "x": -20,
      "y": 49,
      "z": 7,
      "name": "Plant_Leaves_Beech_Max_Support"
    },
    {
      "x": -20,
      "y": 51,
      "z": 7,
      "name": "Plant_Leaves_Beech_Max_Support"
    },
    {
      "x": -20,
      "y": 9,
      "z": 8,
      "name": "Wood_Gumboab_Trunk_Full"
    },
    {
      "x": -20,
      "y": 10,
      "z": 8,
      "name": "Wood_Gumboab_Trunk_Full"
    },
    {
      "x": -20,
      "y": 11,
      "z": 8,
      "name": "Wood_Gumboab_Trunk_Full"
    },
    {
      "x": -20,
      "y": 47,
      "z": 8,
      "name": "Plant_Leaves_Beech_Max_Support"
    },
    {
      "x": -20,
      "y": 48,
      "z": 8,
      "name": "Plant_Leaves_Beech_Max_Support"
    },
    {
      "x": -20,
      "y": 49,
      "z": 8,
      "name": "Plant_Leaves_Beech_Max_Support"
    },
    {
      "x": -20,
      "y": 52,
      "z": 8,
      "name": "Plant_Leaves_Beech_Max_Support"
    },
    {
      "x": -20,
      "y": 46,
      "z": 9,
      "name": "Plant_Leaves_Beech_Max_Support"
    },
    {
      "x": -20,
      "y": 47,
      "z": 9,
      "name": "Plant_Leaves_Beech_Max_Support"
    },
    {
      "x": -20,
      "y": 50,
      "z": 9,
      "name": "Plant_Leaves_Beech_Max_Support"
    },
    {
      "x": -20,
      "y": 52,
      "z": 9,
      "name": "Plant_Leaves_Beech_Max_Support"
    },
    {
      "x": -20,
      "y": 46,
      "z": 10,
      "name": "Plant_Leaves_Beech_Max_Support"
    },
    {
      "x": -20,
      "y": 48,
      "z": 10,
      "name": "Plant_Leaves_Beech_Max_Support"
    },
    {
      "x": -20,
      "y": 49,
      "z": 10,
      "name": "Plant_Leaves_Beech_Max_Support"
    },
    {
      "x": -20,
      "y": 50,
      "z": 10,
      "name": "Plant_Leaves_Beech_Max_Support"
    },
    {
      "x": -20,
      "y": 52,
      "z": 10,
      "name": "Plant_Leaves_Beech_Max_Support"
    },
    {
      "x": -20,
      "y": 47,
      "z": 11,
      "name": "Plant_Leaves_Beech_Max_Support"
    },
    {
      "x": -20,
      "y": 49,
      "z": 11,
      "name": "Plant_Leaves_Beech_Max_Support"
    },
    {
      "x": -20,
      "y": 50,
      "z": 11,
      "name": "Plant_Leaves_Beech_Max_Support"
    },
    {
      "x": -20,
      "y": 48,
      "z": 12,
      "name": "Plant_Leaves_Beech_Max_Support"
    },
    {
      "x": -20,
      "y": 49,
      "z": 12,
      "name": "Plant_Leaves_Beech_Max_Support"
    },
    {
      "x": -20,
      "y": 50,
      "z": 12,
      "name": "Plant_Leaves_Beech_Max_Support"
    },
    {
      "x": -19,
      "y": 10,
      "z": -9,
      "name": "Wood_Gumboab_Trunk_Full"
    },
    {
      "x": -19,
      "y": 11,
      "z": -9,
      "name": "Wood_Gumboab_Trunk_Full"
    },
    {
      "x": -19,
      "y": 12,
      "z": -9,
      "name": "Wood_Gumboab_Trunk_Full"
    },
    {
      "x": -19,
      "y": 13,
      "z": -9,
      "name": "Wood_Gumboab_Trunk_Full"
    },
    {
      "x": -19,
      "y": 10,
      "z": -8,
      "name": "Wood_Gumboab_Trunk_Full"
    },
    {
      "x": -19,
      "y": 11,
      "z": -8,
      "name": "Wood_Gumboab_Trunk_Full"
    },
    {
      "x": -19,
      "y": 12,
      "z": -8,
      "name": "Wood_Gumboab_Trunk_Full"
    },
    {
      "x": -19,
      "y": 13,
      "z": -8,
      "name": "Wood_Gumboab_Trunk_Full"
    },
    {
      "x": -19,
      "y": 14,
      "z": -8,
      "name": "Wood_Gumboab_Trunk_Full"
    },
    {
      "x": -19,
      "y": 5,
      "z": -7,
      "name": "Wood_Gumboab_Trunk_Full"
    },
    {
      "x": -19,
      "y": 6,
      "z": -7,
      "name": "Wood_Gumboab_Trunk_Full"
    },
    {
      "x": -19,
      "y": 12,
      "z": -7,
      "name": "Wood_Gumboab_Trunk_Full"
    },
    {
      "x": -19,
      "y": 13,
      "z": -7,
      "name": "Wood_Gumboab_Trunk_Full"
    },
    {
      "x": -19,
      "y": 14,
      "z": -7,
      "name": "Wood_Gumboab_Trunk_Full"
    },
    {
      "x": -19,
      "y": 15,
      "z": -7,
      "name": "Wood_Gumboab_Trunk_Full"
    },
    {
      "x": -19,
      "y": 3,
      "z": -6,
      "name": "Wood_Gumboab_Roots"
    },
    {
      "x": -19,
      "y": 4,
      "z": -6,
      "name": "Wood_Gumboab_Trunk_Full"
    },
    {
      "x": -19,
      "y": 5,
      "z": -6,
      "name": "Wood_Gumboab_Trunk_Full"
    },
    {
      "x": -19,
      "y": 13,
      "z": -6,
      "name": "Wood_Gumboab_Trunk_Full"
    },
    {
      "x": -19,
      "y": 14,
      "z": -6,
      "name": "Wood_Gumboab_Trunk_Full"
    },
    {
      "x": -19,
      "y": 15,
      "z": -6,
      "name": "Wood_Gumboab_Trunk_Full"
    },
    {
      "x": -19,
      "y": 16,
      "z": -6,
      "name": "Wood_Gumboab_Trunk_Full"
    },
    {
      "x": -19,
      "y": 72,
      "z": -6,
      "name": "Plant_Leaves_Beech_Max_Support",
      "support": 15
    },
    {
      "x": -19,
      "y": 14,
      "z": -5,
      "name": "Wood_Gumboab_Trunk_Full"
    },
    {
      "x": -19,
      "y": 15,
      "z": -5,
      "name": "Wood_Gumboab_Trunk_Full"
    },
    {
      "x": -19,
      "y": 16,
      "z": -5,
      "name": "Wood_Gumboab_Trunk_Full"
    },
    {
      "x": -19,
      "y": 17,
      "z": -5,
      "name": "Wood_Gumboab_Trunk_Full"
    },
    {
      "x": -19,
      "y": 72,
      "z": -5,
      "name": "Plant_Leaves_Beech_Max_Support",
      "support": 15
    },
    {
      "x": -19,
      "y": 73,
      "z": -5,
      "name": "Plant_Leaves_Beech_Max_Support"
    },
    {
      "x": -19,
      "y": 74,
      "z": -5,
      "name": "Plant_Leaves_Beech_Max_Support"
    },
    {
      "x": -19,
      "y": 14,
      "z": -4,
      "name": "Wood_Gumboab_Trunk_Full"
    },
    {
      "x": -19,
      "y": 15,
      "z": -4,
      "name": "Wood_Gumboab_Trunk_Full"
    },
    {
      "x": -19,
      "y": 16,
      "z": -4,
      "name": "Wood_Gumboab_Trunk_Full"
    },
    {
      "x": -19,
      "y": 17,
      "z": -4,
      "name": "Wood_Gumboab_Trunk_Full"
    },
    {
      "x": -19,
      "y": 72,
      "z": -4,
      "name": "Plant_Leaves_Beech_Max_Support",
      "support": 15
    },
    {
      "x": -19,
      "y": 74,
      "z": -4,
      "name": "Plant_Leaves_Beech_Max_Support"
    },
    {
      "x": -19,
      "y": 75,
      "z": -4,
      "name": "Plant_Leaves_Beech_Max_Support"
    },
    {
      "x": -19,
      "y": 15,
      "z": -3,
      "name": "Wood_Gumboab_Trunk_Full"
    },
    {
      "x": -19,
      "y": 16,
      "z": -3,
      "name": "Wood_Gumboab_Trunk_Full"
    },
    {
      "x": -19,
      "y": 73,
      "z": -3,
      "name": "Plant_Leaves_Beech_Max_Support",
      "support": 15
    },
    {
      "x": -19,
      "y": 74,
      "z": -3,
      "name": "Plant_Leaves_Beech_Max_Support"
    },
    {
      "x": -19,
      "y": 75,
      "z": -3,
      "name": "Plant_Leaves_Beech_Max_Support"
    },
    {
      "x": -19,
      "y": 76,
      "z": -3,
      "name": "Plant_Leaves_Beech_Max_Support"
    },
    {
      "x": -19,
      "y": 70,
      "z": -2,
      "name": "Plant_Leaves_Beech_Max_Support",
      "support": 15
    },
    {
      "x": -19,
      "y": 71,
      "z": -2,
      "name": "Plant_Leaves_Beech_Max_Support",
      "support": 15
    },
    {
      "x": -19,
      "y": 72,
      "z": -2,
      "name": "Plant_Leaves_Beech_Max_Support",
      "support": 15
    },
    {
      "x": -19,
      "y": 73,
      "z": -2,
      "name": "Plant_Leaves_Beech_Max_Support"
    },
    {
      "x": -19,
      "y": 74,
      "z": -2,
      "name": "Plant_Leaves_Beech_Max_Support"
    },
    {
      "x": -19,
      "y": 72,
      "z": -1,
      "name": "Plant_Leaves_Beech_Max_Support",
      "support": 15
    },
    {
      "x": -19,
      "y": 73,
      "z": -1,
      "name": "Plant_Leaves_Beech_Max_Support",
      "support": 15
    },
    {
      "x": -19,
      "y": 74,
      "z": -1,
      "name": "Plant_Leaves_Beech_Max_Support"
    },
    {
      "x": -19,
      "y": 70,
      "z": 0,
      "name": "Plant_Leaves_Beech_Max_Support",
      "support": 15
    },
    {
      "x": -19,
      "y": 71,
      "z": 0,
      "name": "Plant_Leaves_Beech_Max_Support",
      "support": 15
    },
    {
      "x": -19,
      "y": 72,
      "z": 0,
      "name": "Plant_Leaves_Beech_Max_Support",
      "support": 15
    },
    {
      "x": -19,
      "y": 73,
      "z": 0,
      "name": "Plant_Leaves_Beech_Max_Support"
    },
    {
      "x": -19,
      "y": 74,
      "z": 0,
      "name": "Plant_Leaves_Beech_Max_Support"
    },
    {
      "x": -19,
      "y": 13,
      "z": 1,
      "name": "Wood_Gumboab_Trunk_Full"
    },
    {
      "x": -19,
      "y": 14,
      "z": 1,
      "name": "Wood_Gumboab_Trunk_Full"
    },
    {
      "x": -19,
      "y": 15,
      "z": 1,
      "name": "Wood_Gumboab_Trunk_Full"
    },
    {
      "x": -19,
      "y": 71,
      "z": 1,
      "name": "Plant_Leaves_Beech_Max_Support",
      "support": 15
    },
    {
      "x": -19,
      "y": 72,
      "z": 1,
      "name": "Plant_Leaves_Beech_Max_Support",
      "support": 15
    },
    {
      "x": -19,
      "y": 73,
      "z": 1,
      "name": "Plant_Leaves_Beech_Max_Support",
      "support": 15
    },
    {
      "x": -19,
      "y": 74,
      "z": 1,
      "name": "Plant_Leaves_Beech_Max_Support"
    },
    {
      "x": -19,
      "y": 14,
      "z": 2,
      "name": "Wood_Gumboab_Trunk_Full"
    },
    {
      "x": -19,
      "y": 49,
      "z": 2,
      "name": "Plant_Leaves_Beech_Max_Support"
    },
    {
      "x": -19,
      "y": 50,
      "z": 2,
      "name": "Plant_Leaves_Beech_Max_Support"
    },
    {
      "x": -19,
      "y": 6,
      "z": 3,
      "name": "Wood_Gumboab_Roots"
    },
    {
      "x": -19,
      "y": 7,
      "z": 3,
      "name": "Wood_Gumboab_Trunk_Full"
    },
    {
      "x": -19,
      "y": 8,
      "z": 3,
      "name": "Wood_Gumboab_Trunk_Full"
    },
    {
      "x": -19,
      "y": 47,
      "z": 3,
      "name": "Plant_Leaves_Beech_Max_Support",
      "support": 15
    },
    {
      "x": -19,
      "y": 50,
      "z": 3,
      "name": "Plant_Leaves_Beech_Max_Support"
    },
    {
      "x": -19,
      "y": 7,
      "z": 4,
      "name": "Wood_Gumboab_Roots"
    },
    {
      "x": -19,
      "y": 8,
      "z": 4,
      "name": "Wood_Gumboab_Trunk_Full"
    },
    {
      "x": -19,
      "y": 46,
      "z": 4,
      "name": "Plant_Leaves_Beech_Max_Support"
    },
    {
      "x": -19,
      "y": 47,
      "z": 4,
      "name": "Plant_Leaves_Beech_Max_Support"
    },
    {
      "x": -19,
      "y": 48,
      "z": 4,
      "name": "Plant_Leaves_Beech_Max_Support"
    },
    {
      "x": -19,
      "y": 50,
      "z": 4,
      "name": "Plant_Leaves_Beech_Max_Support"
    },
    {
      "x": -19,
      "y": 52,
      "z": 4,
      "name": "Plant_Leaves_Beech_Max_Support"
    },
    {
      "x": -19,
      "y": 46,
      "z": 5,
      "name": "Plant_Leaves_Beech_Max_Support"
    },
    {
      "x": -19,
      "y": 48,
      "z": 5,
      "name": "Plant_Leaves_Beech_Max_Support"
    },
    {
      "x": -19,
      "y": 50,
      "z": 5,
      "name": "Plant_Leaves_Beech_Max_Support"
    },
    {
      "x": -19,
      "y": 52,
      "z": 5,
      "name": "Plant_Leaves_Beech_Max_Support"
    },
    {
      "x": -19,
      "y": 46,
      "z": 6,
      "name": "Plant_Leaves_Beech_Max_Support"
    },
    {
      "x": -19,
      "y": 47,
      "z": 6,
      "name": "Plant_Leaves_Beech_Max_Support"
    },
    {
      "x": -19,
      "y": 48,
      "z": 6,
      "name": "Plant_Leaves_Beech_Max_Support"
    },
    {
      "x": -19,
      "y": 49,
      "z": 6,
      "name": "Plant_Leaves_Beech_Max_Support"
    },
    {
      "x": -19,
      "y": 50,
      "z": 6,
      "name": "Plant_Leaves_Beech_Max_Support"
    },
    {
      "x": -19,
      "y": 51,
      "z": 6,
      "name": "Plant_Leaves_Beech_Max_Support"
    },
    {
      "x": -19,
      "y": 10,
      "z": 7,
      "name": "Wood_Gumboab_Trunk_Full"
    },
    {
      "x": -19,
      "y": 11,
      "z": 7,
      "name": "Wood_Gumboab_Trunk_Full"
    },
    {
      "x": -19,
      "y": 46,
      "z": 7,
      "name": "Plant_Leaves_Beech_Max_Support"
    },
    {
      "x": -19,
      "y": 47,
      "z": 7,
      "name": "Plant_Leaves_Beech_Max_Support",
      "support": 15
    },
    {
      "x": -19,
      "y": 50,
      "z": 7,
      "name": "Plant_Leaves_Beech_Max_Support"
    },
    {
      "x": -19,
      "y": 51,
      "z": 7,
      "name": "Plant_Leaves_Beech_Max_Support"
    },
    {
      "x": -19,
      "y": 10,
      "z": 8,
      "name": "Wood_Gumboab_Trunk_Full"
    },
    {
      "x": -19,
      "y": 11,
      "z": 8,
      "name": "Wood_Gumboab_Trunk_Full"
    },
    {
      "x": -19,
      "y": 46,
      "z": 8,
      "name": "Plant_Leaves_Beech_Max_Support"
    },
    {
      "x": -19,
      "y": 47,
      "z": 8,
      "name": "Plant_Leaves_Beech_Max_Support"
    },
    {
      "x": -19,
      "y": 48,
      "z": 8,
      "name": "Plant_Leaves_Beech_Max_Support"
    },
    {
      "x": -19,
      "y": 49,
      "z": 8,
      "name": "Plant_Leaves_Beech_Max_Support"
    },
    {
      "x": -19,
      "y": 50,
      "z": 8,
      "name": "Plant_Leaves_Beech_Max_Support"
    },
    {
      "x": -19,
      "y": 51,
      "z": 8,
      "name": "Plant_Leaves_Beech_Max_Support"
    },
    {
      "x": -19,
      "y": 47,
      "z": 9,
      "name": "Plant_Leaves_Beech_Max_Support"
    },
    {
      "x": -19,
      "y": 48,
      "z": 9,
      "name": "Plant_Leaves_Beech_Max_Support"
    },
    {
      "x": -19,
      "y": 49,
      "z": 9,
      "name": "Plant_Leaves_Beech_Max_Support"
    },
    {
      "x": -19,
      "y": 50,
      "z": 9,
      "name": "Plant_Leaves_Beech_Max_Support"
    },
    {
      "x": -19,
      "y": 51,
      "z": 9,
      "name": "Plant_Leaves_Beech_Max_Support"
    },
    {
      "x": -19,
      "y": 46,
      "z": 10,
      "name": "Plant_Leaves_Beech_Max_Support"
    },
    {
      "x": -19,
      "y": 47,
      "z": 10,
      "name": "Plant_Leaves_Beech_Max_Support"
    },
    {
      "x": -19,
      "y": 48,
      "z": 10,
      "name": "Plant_Leaves_Beech_Max_Support"
    },
    {
      "x": -19,
      "y": 51,
      "z": 10,
      "name": "Plant_Leaves_Beech_Max_Support"
    },
    {
      "x": -19,
      "y": 52,
      "z": 10,
      "name": "Plant_Leaves_Beech_Max_Support"
    },
    {
      "x": -19,
      "y": 48,
      "z": 11,
      "name": "Plant_Leaves_Beech_Max_Support"
    },
    {
      "x": -19,
      "y": 49,
      "z": 11,
      "name": "Plant_Leaves_Beech_Max_Support"
    },
    {
      "x": -19,
      "y": 51,
      "z": 11,
      "name": "Plant_Leaves_Beech_Max_Support"
    },
    {
      "x": -19,
      "y": 48,
      "z": 12,
      "name": "Plant_Leaves_Beech_Max_Support"
    },
    {
      "x": -19,
      "y": 49,
      "z": 12,
      "name": "Plant_Leaves_Beech_Max_Support"
    },
    {
      "x": -18,
      "y": 3,
      "z": -13,
      "name": "Wood_Gumboab_Roots"
    },
    {
      "x": -18,
      "y": 4,
      "z": -13,
      "name": "Wood_Gumboab_Trunk_Full"
    },
    {
      "x": -18,
      "y": 5,
      "z": -13,
      "name": "Wood_Gumboab_Trunk_Full"
    },
    {
      "x": -18,
      "y": 4,
      "z": -12,
      "name": "Wood_Gumboab_Trunk_Full"
    },
    {
      "x": -18,
      "y": 5,
      "z": -12,
      "name": "Wood_Gumboab_Trunk_Full"
    },
    {
      "x": -18,
      "y": 6,
      "z": -12,
      "name": "Wood_Gumboab_Trunk_Full"
    },
    {
      "x": -18,
      "y": 5,
      "z": -11,
      "name": "Wood_Gumboab_Trunk_Full"
    },
    {
      "x": -18,
      "y": 6,
      "z": -11,
      "name": "Wood_Gumboab_Trunk_Full"
    },
    {
      "x": -18,
      "y": 7,
      "z": -11,
      "name": "Wood_Gumboab_Trunk_Full"
    },
    {
      "x": -18,
      "y": 8,
      "z": -11,
      "name": "Wood_Gumboab_Trunk_Full"
    },
    {
      "x": -18,
      "y": 6,
      "z": -10,
      "name": "Wood_Gumboab_Trunk_Full"
    },
    {
      "x": -18,
      "y": 7,
      "z": -10,
      "name": "Wood_Gumboab_Trunk_Full"
    },
    {
      "x": -18,
      "y": 8,
      "z": -10,
      "name": "Wood_Gumboab_Trunk_Full"
    },
    {
      "x": -18,
      "y": 9,
      "z": -10,
      "name": "Wood_Gumboab_Trunk_Full"
    },
    {
      "x": -18,
      "y": 70,
      "z": -8,
      "name": "Plant_Leaves_Beech_Max_Support",
      "support": 15
    },
    {
      "x": -18,
      "y": 71,
      "z": -8,
      "name": "Plant_Leaves_Beech_Max_Support",
      "support": 15
    },
    {
      "x": -18,
      "y": 13,
      "z": -7,
      "name": "Wood_Gumboab_Trunk_Full"
    },
    {
      "x": -18,
      "y": 14,
      "z": -7,
      "name": "Wood_Gumboab_Trunk_Full"
    },
    {
      "x": -18,
      "y": 15,
      "z": -7,
      "name": "Wood_Gumboab_Trunk_Full"
    },
    {
      "x": -18,
      "y": 71,
      "z": -7,
      "name": "Plant_Leaves_Beech_Max_Support",
      "support": 15
    },
    {
      "x": -18,
      "y": 3,
      "z": -6,
      "name": "Wood_Gumboab_Roots"
    },
    {
      "x": -18,
      "y": 4,
      "z": -6,
      "name": "Wood_Gumboab_Trunk_Full"
    },
    {
      "x": -18,
      "y": 5,
      "z": -6,
      "name": "Wood_Gumboab_Trunk_Full"
    },
    {
      "x": -18,
      "y": 14,
      "z": -6,
      "name": "Wood_Gumboab_Trunk_Full"
    },
    {
      "x": -18,
      "y": 15,
      "z": -6,
      "name": "Wood_Gumboab_Trunk_Full"
    },
    {
      "x": -18,
      "y": 16,
      "z": -6,
      "name": "Wood_Gumboab_Trunk_Full"
    },
    {
      "x": -18,
      "y": 71,
      "z": -6,
      "name": "Plant_Leaves_Beech_Max_Support",
      "support": 15
    },
    {
      "x": -18,
      "y": 72,
      "z": -6,
      "name": "Plant_Leaves_Beech_Max_Support",
      "support": 15
    },
    {
      "x": -18,
      "y": 73,
      "z": -6,
      "name": "Plant_Leaves_Beech_Max_Support"
    },
    {
      "x": -18,
      "y": 74,
      "z": -6,
      "name": "Plant_Leaves_Beech_Max_Support"
    },
    {
      "x": -18,
      "y": 14,
      "z": -5,
      "name": "Wood_Gumboab_Trunk_Full"
    },
    {
      "x": -18,
      "y": 15,
      "z": -5,
      "name": "Wood_Gumboab_Trunk_Full"
    },
    {
      "x": -18,
      "y": 16,
      "z": -5,
      "name": "Wood_Gumboab_Trunk_Full"
    },
    {
      "x": -18,
      "y": 17,
      "z": -5,
      "name": "Wood_Gumboab_Trunk_Full"
    },
    {
      "x": -18,
      "y": 18,
      "z": -5,
      "name": "Plant_Moss_Rug_Yellow",
      "support": 15
    },
    {
      "x": -18,
      "y": 71,
      "z": -5,
      "name": "Plant_Leaves_Beech_Max_Support",
      "support": 15
    },
    {
      "x": -18,
      "y": 72,
      "z": -5,
      "name": "Plant_Leaves_Beech_Max_Support"
    },
    {
      "x": -18,
      "y": 73,
      "z": -5,
      "name": "Plant_Leaves_Beech_Max_Support"
    },
    {
      "x": -18,
      "y": 74,
      "z": -5,
      "name": "Plant_Leaves_Beech_Max_Support"
    },
    {
      "x": -18,
      "y": 76,
      "z": -5,
      "name": "Plant_Leaves_Beech_Max_Support"
    },
    {
      "x": -18,
      "y": 15,
      "z": -4,
      "name": "Wood_Gumboab_Trunk_Full"
    },
    {
      "x": -18,
      "y": 16,
      "z": -4,
      "name": "Wood_Gumboab_Trunk_Full"
    },
    {
      "x": -18,
      "y": 17,
      "z": -4,
      "name": "Wood_Gumboab_Trunk_Full"
    },
    {
      "x": -18,
      "y": 71,
      "z": -4,
      "name": "Plant_Leaves_Beech_Max_Support",
      "support": 15
    },
    {
      "x": -18,
      "y": 72,
      "z": -4,
      "name": "Plant_Leaves_Beech_Max_Support"
    },
    {
      "x": -18,
      "y": 73,
      "z": -4,
      "name": "Plant_Leaves_Beech_Max_Support"
    },
    {
      "x": -18,
      "y": 74,
      "z": -4,
      "name": "Plant_Leaves_Beech_Max_Support"
    },
    {
      "x": -18,
      "y": 75,
      "z": -4,
      "name": "Plant_Leaves_Beech_Max_Support"
    },
    {
      "x": -18,
      "y": 15,
      "z": -3,
      "name": "Wood_Gumboab_Trunk_Full"
    },
    {
      "x": -18,
      "y": 16,
      "z": -3,
      "name": "Wood_Gumboab_Trunk_Full"
    },
    {
      "x": -18,
      "y": 17,
      "z": -3,
      "name": "Wood_Gumboab_Trunk_Full"
    },
    {
      "x": -18,
      "y": 71,
      "z": -3,
      "name": "Plant_Leaves_Beech_Max_Support",
      "support": 15
    },
    {
      "x": -18,
      "y": 72,
      "z": -3,
      "name": "Plant_Leaves_Beech_Max_Support"
    },
    {
      "x": -18,
      "y": 73,
      "z": -3,
      "name": "Plant_Leaves_Beech_Max_Support"
    },
    {
      "x": -18,
      "y": 74,
      "z": -3,
      "name": "Plant_Leaves_Beech_Max_Support"
    },
    {
      "x": -18,
      "y": 75,
      "z": -3,
      "name": "Plant_Leaves_Beech_Max_Support"
    },
    {
      "x": -18,
      "y": 77,
      "z": -3,
      "name": "Plant_Leaves_Beech_Max_Support"
    },
    {
      "x": -18,
      "y": 70,
      "z": -2,
      "name": "Plant_Leaves_Beech_Max_Support",
      "support": 15
    },
    {
      "x": -18,
      "y": 71,
      "z": -2,
      "name": "Plant_Leaves_Beech_Max_Support",
      "support": 15
    },
    {
      "x": -18,
      "y": 72,
      "z": -2,
      "name": "Plant_Leaves_Beech_Max_Support"
    },
    {
      "x": -18,
      "y": 73,
      "z": -2,
      "name": "Plant_Leaves_Beech_Max_Support"
    },
    {
      "x": -18,
      "y": 74,
      "z": -2,
      "name": "Plant_Leaves_Beech_Max_Support"
    },
    {
      "x": -18,
      "y": 75,
      "z": -2,
      "name": "Plant_Leaves_Beech_Max_Support"
    },
    {
      "x": -18,
      "y": 77,
      "z": -2,
      "name": "Plant_Leaves_Beech_Max_Support"
    },
    {
      "x": -18,
      "y": 71,
      "z": -1,
      "name": "Plant_Leaves_Beech_Max_Support",
      "support": 15
    },
    {
      "x": -18,
      "y": 72,
      "z": -1,
      "name": "Plant_Leaves_Beech_Max_Support",
      "support": 15
    },
    {
      "x": -18,
      "y": 73,
      "z": -1,
      "name": "Plant_Leaves_Beech_Max_Support"
    },
    {
      "x": -18,
      "y": 74,
      "z": -1,
      "name": "Plant_Leaves_Beech_Max_Support"
    },
    {
      "x": -18,
      "y": 77,
      "z": -1,
      "name": "Plant_Leaves_Beech_Max_Support"
    },
    {
      "x": -18,
      "y": 14,
      "z": 0,
      "name": "Wood_Gumboab_Trunk_Full"
    },
    {
      "x": -18,
      "y": 71,
      "z": 0,
      "name": "Plant_Leaves_Beech_Max_Support",
      "support": 15
    },
    {
      "x": -18,
      "y": 72,
      "z": 0,
      "name": "Plant_Leaves_Beech_Max_Support"
    },
    {
      "x": -18,
      "y": 75,
      "z": 0,
      "name": "Plant_Leaves_Beech_Max_Support"
    },
    {
      "x": -18,
      "y": 13,
      "z": 1,
      "name": "Wood_Gumboab_Trunk_Full"
    },
    {
      "x": -18,
      "y": 14,
      "z": 1,
      "name": "Wood_Gumboab_Trunk_Full"
    },
    {
      "x": -18,
      "y": 15,
      "z": 1,
      "name": "Wood_Gumboab_Trunk_Full"
    },
    {
      "x": -18,
      "y": 70,
      "z": 1,
      "name": "Plant_Leaves_Beech_Max_Support",
      "support": 15
    },
    {
      "x": -18,
      "y": 71,
      "z": 1,
      "name": "Plant_Leaves_Beech_Max_Support",
      "support": 15
    },
    {
      "x": -18,
      "y": 72,
      "z": 1,
      "name": "Plant_Leaves_Beech_Max_Support",
      "support": 15
    },
    {
      "x": -18,
      "y": 73,
      "z": 1,
      "name": "Plant_Leaves_Beech_Max_Support"
    },
    {
      "x": -18,
      "y": 74,
      "z": 1,
      "name": "Plant_Leaves_Beech_Max_Support"
    },
    {
      "x": -18,
      "y": 49,
      "z": 2,
      "name": "Plant_Leaves_Beech_Max_Support"
    },
    {
      "x": -18,
      "y": 72,
      "z": 2,
      "name": "Plant_Leaves_Beech_Max_Support",
      "support": 15
    },
    {
      "x": -18,
      "y": 73,
      "z": 2,
      "name": "Plant_Leaves_Beech_Max_Support"
    },
    {
      "x": -18,
      "y": 74,
      "z": 2,
      "name": "Plant_Leaves_Beech_Max_Support"
    },
    {
      "x": -18,
      "y": 8,
      "z": 3,
      "name": "Wood_Gumboab_Trunk_Full"
    },
    {
      "x": -18,
      "y": 9,
      "z": 3,
      "name": "Wood_Gumboab_Trunk_Full"
    },
    {
      "x": -18,
      "y": 47,
      "z": 3,
      "name": "Plant_Leaves_Beech_Max_Support"
    },
    {
      "x": -18,
      "y": 48,
      "z": 3,
      "name": "Plant_Leaves_Beech_Max_Support"
    },
    {
      "x": -18,
      "y": 49,
      "z": 3,
      "name": "Plant_Leaves_Beech_Max_Support"
    },
    {
      "x": -18,
      "y": 50,
      "z": 3,
      "name": "Plant_Leaves_Beech_Max_Support"
    },
    {
      "x": -18,
      "y": 8,
      "z": 4,
      "name": "Wood_Gumboab_Trunk_Full"
    },
    {
      "x": -18,
      "y": 9,
      "z": 4,
      "name": "Wood_Gumboab_Trunk_Full"
    },
    {
      "x": -18,
      "y": 10,
      "z": 4,
      "name": "Wood_Gumboab_Trunk_Full"
    },
    {
      "x": -18,
      "y": 11,
      "z": 4,
      "name": "Wood_Gumboab_Trunk_Full"
    },
    {
      "x": -18,
      "y": 12,
      "z": 4,
      "name": "Wood_Gumboab_Trunk_Full"
    },
    {
      "x": -18,
      "y": 46,
      "z": 4,
      "name": "Plant_Leaves_Beech_Max_Support",
      "support": 15
    },
    {
      "x": -18,
      "y": 47,
      "z": 4,
      "name": "Plant_Leaves_Beech_Max_Support"
    },
    {
      "x": -18,
      "y": 49,
      "z": 4,
      "name": "Plant_Leaves_Beech_Max_Support"
    },
    {
      "x": -18,
      "y": 50,
      "z": 4,
      "name": "Plant_Leaves_Beech_Max_Support"
    },
    {
      "x": -18,
      "y": 52,
      "z": 4,
      "name": "Plant_Leaves_Beech_Max_Support"
    },
    {
      "x": -18,
      "y": 47,
      "z": 5,
      "name": "Plant_Leaves_Beech_Max_Support"
    },
    {
      "x": -18,
      "y": 48,
      "z": 5,
      "name": "Plant_Leaves_Beech_Max_Support"
    },
    {
      "x": -18,
      "y": 49,
      "z": 5,
      "name": "Plant_Leaves_Beech_Max_Support"
    },
    {
      "x": -18,
      "y": 50,
      "z": 5,
      "name": "Plant_Leaves_Beech_Max_Support"
    },
    {
      "x": -18,
      "y": 52,
      "z": 5,
      "name": "Plant_Leaves_Beech_Max_Support"
    },
    {
      "x": -18,
      "y": 46,
      "z": 6,
      "name": "Plant_Leaves_Beech_Max_Support"
    },
    {
      "x": -18,
      "y": 47,
      "z": 6,
      "name": "Plant_Leaves_Beech_Max_Support"
    },
    {
      "x": -18,
      "y": 48,
      "z": 6,
      "name": "Plant_Leaves_Beech_Max_Support"
    },
    {
      "x": -18,
      "y": 49,
      "z": 6,
      "name": "Plant_Leaves_Beech_Max_Support"
    },
    {
      "x": -18,
      "y": 50,
      "z": 6,
      "name": "Plant_Leaves_Beech_Max_Support"
    },
    {
      "x": -18,
      "y": 52,
      "z": 6,
      "name": "Plant_Leaves_Beech_Max_Support"
    },
    {
      "x": -18,
      "y": 10,
      "z": 7,
      "name": "Wood_Gumboab_Trunk_Full"
    },
    {
      "x": -18,
      "y": 11,
      "z": 7,
      "name": "Wood_Gumboab_Trunk_Full"
    },
    {
      "x": -18,
      "y": 12,
      "z": 7,
      "name": "Wood_Gumboab_Trunk_Full"
    },
    {
      "x": -18,
      "y": 45,
      "z": 7,
      "name": "Plant_Leaves_Beech_Max_Support"
    },
    {
      "x": -18,
      "y": 47,
      "z": 7,
      "name": "Wood_Gumboab_Trunk_Full"
    },
    {
      "x": -18,
      "y": 48,
      "z": 7,
      "name": "Plant_Leaves_Beech_Max_Support"
    },
    {
      "x": -18,
      "y": 49,
      "z": 7,
      "name": "Plant_Leaves_Beech_Max_Support"
    },
    {
      "x": -18,
      "y": 51,
      "z": 7,
      "name": "Plant_Leaves_Beech_Max_Support"
    },
    {
      "x": -18,
      "y": 10,
      "z": 8,
      "name": "Wood_Gumboab_Trunk_Full"
    },
    {
      "x": -18,
      "y": 11,
      "z": 8,
      "name": "Wood_Gumboab_Trunk_Full"
    },
    {
      "x": -18,
      "y": 12,
      "z": 8,
      "name": "Wood_Gumboab_Trunk_Full"
    },
    {
      "x": -18,
      "y": 13,
      "z": 8,
      "name": "Plant_Moss_Rug_Yellow",
      "support": 15
    },
    {
      "x": -18,
      "y": 46,
      "z": 8,
      "name": "Plant_Leaves_Beech_Max_Support"
    },
    {
      "x": -18,
      "y": 47,
      "z": 8,
      "name": "Wood_Gumboab_Trunk_Full"
    },
    {
      "x": -18,
      "y": 48,
      "z": 8,
      "name": "Wood_Gumboab_Trunk_Full"
    },
    {
      "x": -18,
      "y": 49,
      "z": 8,
      "name": "Plant_Leaves_Beech_Max_Support"
    },
    {
      "x": -18,
      "y": 50,
      "z": 8,
      "name": "Plant_Leaves_Beech_Max_Support"
    },
    {
      "x": -18,
      "y": 51,
      "z": 8,
      "name": "Plant_Leaves_Beech_Max_Support"
    },
    {
      "x": -18,
      "y": 46,
      "z": 9,
      "name": "Plant_Leaves_Beech_Max_Support"
    },
    {
      "x": -18,
      "y": 47,
      "z": 9,
      "name": "Plant_Leaves_Beech_Max_Support"
    },
    {
      "x": -18,
      "y": 48,
      "z": 9,
      "name": "Plant_Leaves_Beech_Max_Support"
    },
    {
      "x": -18,
      "y": 49,
      "z": 9,
      "name": "Plant_Leaves_Beech_Max_Support"
    },
    {
      "x": -18,
      "y": 50,
      "z": 9,
      "name": "Plant_Leaves_Beech_Max_Support"
    },
    {
      "x": -18,
      "y": 51,
      "z": 9,
      "name": "Plant_Leaves_Beech_Max_Support"
    },
    {
      "x": -18,
      "y": 46,
      "z": 10,
      "name": "Plant_Leaves_Beech_Max_Support"
    },
    {
      "x": -18,
      "y": 47,
      "z": 10,
      "name": "Plant_Leaves_Beech_Max_Support"
    },
    {
      "x": -18,
      "y": 48,
      "z": 10,
      "name": "Plant_Leaves_Beech_Max_Support"
    },
    {
      "x": -18,
      "y": 49,
      "z": 10,
      "name": "Plant_Leaves_Beech_Max_Support"
    },
    {
      "x": -18,
      "y": 50,
      "z": 10,
      "name": "Plant_Leaves_Beech_Max_Support"
    },
    {
      "x": -18,
      "y": 51,
      "z": 10,
      "name": "Plant_Leaves_Beech_Max_Support"
    },
    {
      "x": -18,
      "y": 52,
      "z": 10,
      "name": "Plant_Leaves_Beech_Max_Support"
    },
    {
      "x": -18,
      "y": 46,
      "z": 11,
      "name": "Plant_Leaves_Beech_Max_Support"
    },
    {
      "x": -18,
      "y": 47,
      "z": 11,
      "name": "Plant_Leaves_Beech_Max_Support"
    },
    {
      "x": -18,
      "y": 48,
      "z": 11,
      "name": "Plant_Leaves_Beech_Max_Support"
    },
    {
      "x": -18,
      "y": 49,
      "z": 11,
      "name": "Plant_Leaves_Beech_Max_Support"
    },
    {
      "x": -18,
      "y": 50,
      "z": 11,
      "name": "Plant_Leaves_Beech_Max_Support"
    },
    {
      "x": -18,
      "y": 51,
      "z": 11,
      "name": "Plant_Leaves_Beech_Max_Support"
    },
    {
      "x": -18,
      "y": 47,
      "z": 12,
      "name": "Plant_Leaves_Beech_Max_Support"
    },
    {
      "x": -18,
      "y": 48,
      "z": 12,
      "name": "Plant_Leaves_Beech_Max_Support"
    },
    {
      "x": -18,
      "y": 47,
      "z": 13,
      "name": "Plant_Leaves_Beech_Max_Support",
      "support": 15
    },
    {
      "x": -18,
      "y": 48,
      "z": 13,
      "name": "Plant_Leaves_Beech_Max_Support"
    },
    {
      "x": -17,
      "y": 3,
      "z": -14,
      "name": "Wood_Gumboab_Roots"
    },
    {
      "x": -17,
      "y": 4,
      "z": -14,
      "name": "Wood_Gumboab_Trunk_Full"
    },
    {
      "x": -17,
      "y": 3,
      "z": -13,
      "name": "Wood_Gumboab_Roots"
    },
    {
      "x": -17,
      "y": 4,
      "z": -13,
      "name": "Wood_Gumboab_Trunk_Full"
    },
    {
      "x": -17,
      "y": 5,
      "z": -13,
      "name": "Wood_Gumboab_Trunk_Full"
    },
    {
      "x": -17,
      "y": 4,
      "z": -12,
      "name": "Wood_Gumboab_Trunk_Full"
    },
    {
      "x": -17,
      "y": 5,
      "z": -12,
      "name": "Wood_Gumboab_Trunk_Full"
    },
    {
      "x": -17,
      "y": 6,
      "z": -12,
      "name": "Wood_Gumboab_Trunk_Full"
    },
    {
      "x": -17,
      "y": 5,
      "z": -11,
      "name": "Wood_Gumboab_Trunk_Full"
    },
    {
      "x": -17,
      "y": 6,
      "z": -11,
      "name": "Wood_Gumboab_Trunk_Full"
    },
    {
      "x": -17,
      "y": 7,
      "z": -11,
      "name": "Wood_Gumboab_Trunk_Full"
    },
    {
      "x": -17,
      "y": 8,
      "z": -11,
      "name": "Wood_Gumboab_Trunk_Full"
    },
    {
      "x": -17,
      "y": 6,
      "z": -10,
      "name": "Wood_Gumboab_Trunk_Full"
    },
    {
      "x": -17,
      "y": 7,
      "z": -10,
      "name": "Wood_Gumboab_Trunk_Full"
    },
    {
      "x": -17,
      "y": 8,
      "z": -10,
      "name": "Wood_Gumboab_Trunk_Full"
    },
    {
      "x": -17,
      "y": 9,
      "z": -10,
      "name": "Wood_Gumboab_Trunk_Full"
    },
    {
      "x": -17,
      "y": 10,
      "z": -10,
      "name": "Wood_Gumboab_Trunk_Full"
    },
    {
      "x": -17,
      "y": 71,
      "z": -10,
      "name": "Plant_Leaves_Beech_Max_Support",
      "support": 15
    },
    {
      "x": -17,
      "y": 72,
      "z": -10,
      "name": "Plant_Leaves_Beech_Max_Support",
      "support": 15
    },
    {
      "x": -17,
      "y": 9,
      "z": -9,
      "name": "Wood_Gumboab_Trunk_Full"
    },
    {
      "x": -17,
      "y": 10,
      "z": -9,
      "name": "Wood_Gumboab_Trunk_Full"
    },
    {
      "x": -17,
      "y": 72,
      "z": -9,
      "name": "Plant_Leaves_Beech_Max_Support",
      "support": 15
    },
    {
      "x": -17,
      "y": 73,
      "z": -9,
      "name": "Plant_Leaves_Beech_Max_Support"
    },
    {
      "x": -17,
      "y": 74,
      "z": -9,
      "name": "Plant_Leaves_Beech_Max_Support"
    },
    {
      "x": -17,
      "y": 72,
      "z": -8,
      "name": "Plant_Leaves_Beech_Max_Support",
      "support": 15
    },
    {
      "x": -17,
      "y": 74,
      "z": -8,
      "name": "Plant_Leaves_Beech_Max_Support"
    },
    {
      "x": -17,
      "y": 75,
      "z": -8,
      "name": "Plant_Leaves_Beech_Max_Support"
    },
    {
      "x": -17,
      "y": 72,
      "z": -7,
      "name": "Plant_Leaves_Beech_Max_Support",
      "support": 15
    },
    {
      "x": -17,
      "y": 73,
      "z": -7,
      "name": "Plant_Leaves_Beech_Max_Support"
    },
    {
      "x": -17,
      "y": 74,
      "z": -7,
      "name": "Plant_Leaves_Beech_Max_Support"
    },
    {
      "x": -17,
      "y": 75,
      "z": -7,
      "name": "Plant_Leaves_Beech_Max_Support"
    },
    {
      "x": -17,
      "y": 17,
      "z": -6,
      "name": "Plant_Moss_Wall_Yellow",
      "support": 15,
      "rotation": 2
    },
    {
      "x": -17,
      "y": 72,
      "z": -6,
      "name": "Plant_Leaves_Beech_Max_Support",
      "support": 15
    },
    {
      "x": -17,
      "y": 74,
      "z": -6,
      "name": "Plant_Leaves_Beech_Max_Support"
    },
    {
      "x": -17,
      "y": 75,
      "z": -6,
      "name": "Plant_Leaves_Beech_Max_Support"
    },
    {
      "x": -17,
      "y": 76,
      "z": -6,
      "name": "Plant_Leaves_Beech_Max_Support"
    },
    {
      "x": -17,
      "y": 15,
      "z": -5,
      "name": "Wood_Gumboab_Trunk_Full"
    },
    {
      "x": -17,
      "y": 16,
      "z": -5,
      "name": "Wood_Gumboab_Trunk_Full"
    },
    {
      "x": -17,
      "y": 17,
      "z": -5,
      "name": "Wood_Gumboab_Trunk_Full"
    },
    {
      "x": -17,
      "y": 18,
      "z": -5,
      "name": "Plant_Moss_Rug_Yellow",
      "support": 15
    },
    {
      "x": -17,
      "y": 70,
      "z": -5,
      "name": "Plant_Leaves_Beech_Max_Support",
      "support": 15
    },
    {
      "x": -17,
      "y": 71,
      "z": -5,
      "name": "Plant_Leaves_Beech_Max_Support"
    },
    {
      "x": -17,
      "y": 72,
      "z": -5,
      "name": "Plant_Leaves_Beech_Max_Support",
      "support": 15
    },
    {
      "x": -17,
      "y": 74,
      "z": -5,
      "name": "Plant_Leaves_Beech_Max_Support"
    },
    {
      "x": -17,
      "y": 76,
      "z": -5,
      "name": "Plant_Leaves_Beech_Max_Support"
    },
    {
      "x": -17,
      "y": 15,
      "z": -4,
      "name": "Wood_Gumboab_Trunk_Full"
    },
    {
      "x": -17,
      "y": 16,
      "z": -4,
      "name": "Wood_Gumboab_Trunk_Full"
    },
    {
      "x": -17,
      "y": 17,
      "z": -4,
      "name": "Wood_Gumboab_Trunk_Full"
    },
    {
      "x": -17,
      "y": 70,
      "z": -4,
      "name": "Plant_Leaves_Beech_Max_Support",
      "support": 15
    },
    {
      "x": -17,
      "y": 71,
      "z": -4,
      "name": "Plant_Leaves_Beech_Max_Support"
    },
    {
      "x": -17,
      "y": 73,
      "z": -4,
      "name": "Plant_Leaves_Beech_Max_Support"
    },
    {
      "x": -17,
      "y": 74,
      "z": -4,
      "name": "Plant_Leaves_Beech_Max_Support"
    },
    {
      "x": -17,
      "y": 75,
      "z": -4,
      "name": "Plant_Leaves_Beech_Max_Support"
    },
    {
      "x": -17,
      "y": 76,
      "z": -4,
      "name": "Plant_Leaves_Beech_Max_Support"
    },
    {
      "x": -17,
      "y": 15,
      "z": -3,
      "name": "Wood_Gumboab_Trunk_Full"
    },
    {
      "x": -17,
      "y": 16,
      "z": -3,
      "name": "Wood_Gumboab_Trunk_Full"
    },
    {
      "x": -17,
      "y": 17,
      "z": -3,
      "name": "Wood_Gumboab_Trunk_Full"
    },
    {
      "x": -17,
      "y": 70,
      "z": -3,
      "name": "Plant_Leaves_Beech_Max_Support",
      "support": 15
    },
    {
      "x": -17,
      "y": 71,
      "z": -3,
      "name": "Plant_Leaves_Beech_Max_Support"
    },
    {
      "x": -17,
      "y": 72,
      "z": -3,
      "name": "Plant_Leaves_Beech_Max_Support"
    },
    {
      "x": -17,
      "y": 73,
      "z": -3,
      "name": "Plant_Leaves_Beech_Max_Support"
    },
    {
      "x": -17,
      "y": 74,
      "z": -3,
      "name": "Plant_Leaves_Beech_Max_Support"
    },
    {
      "x": -17,
      "y": 75,
      "z": -3,
      "name": "Plant_Leaves_Beech_Max_Support"
    },
    {
      "x": -17,
      "y": 76,
      "z": -3,
      "name": "Plant_Leaves_Beech_Max_Support"
    },
    {
      "x": -17,
      "y": 77,
      "z": -3,
      "name": "Plant_Leaves_Beech_Max_Support"
    },
    {
      "x": -17,
      "y": 14,
      "z": -2,
      "name": "Wood_Gumboab_Trunk_Full"
    },
    {
      "x": -17,
      "y": 15,
      "z": -2,
      "name": "Wood_Gumboab_Trunk_Full"
    },
    {
      "x": -17,
      "y": 16,
      "z": -2,
      "name": "Wood_Gumboab_Trunk_Full"
    },
    {
      "x": -17,
      "y": 17,
      "z": -2,
      "name": "Wood_Gumboab_Trunk_Full"
    },
    {
      "x": -17,
      "y": 70,
      "z": -2,
      "name": "Plant_Leaves_Beech_Max_Support",
      "support": 15
    },
    {
      "x": -17,
      "y": 71,
      "z": -2,
      "name": "Plant_Leaves_Beech_Max_Support",
      "support": 15
    },
    {
      "x": -17,
      "y": 72,
      "z": -2,
      "name": "Plant_Leaves_Beech_Max_Support"
    },
    {
      "x": -17,
      "y": 73,
      "z": -2,
      "name": "Plant_Leaves_Beech_Max_Support"
    },
    {
      "x": -17,
      "y": 74,
      "z": -2,
      "name": "Plant_Leaves_Beech_Max_Support"
    },
    {
      "x": -17,
      "y": 75,
      "z": -2,
      "name": "Plant_Leaves_Beech_Max_Support"
    },
    {
      "x": -17,
      "y": 76,
      "z": -2,
      "name": "Plant_Leaves_Beech_Max_Support"
    },
    {
      "x": -17,
      "y": 77,
      "z": -2,
      "name": "Plant_Leaves_Beech_Max_Support"
    },
    {
      "x": -17,
      "y": 12,
      "z": -1,
      "name": "Wood_Gumboab_Trunk_Full"
    },
    {
      "x": -17,
      "y": 13,
      "z": -1,
      "name": "Wood_Gumboab_Trunk_Full"
    },
    {
      "x": -17,
      "y": 14,
      "z": -1,
      "name": "Wood_Gumboab_Trunk_Full"
    },
    {
      "x": -17,
      "y": 15,
      "z": -1,
      "name": "Wood_Gumboab_Trunk_Full"
    },
    {
      "x": -17,
      "y": 71,
      "z": -1,
      "name": "Plant_Leaves_Beech_Max_Support",
      "support": 15
    },
    {
      "x": -17,
      "y": 72,
      "z": -1,
      "name": "Plant_Leaves_Beech_Max_Support"
    },
    {
      "x": -17,
      "y": 73,
      "z": -1,
      "name": "Plant_Leaves_Beech_Max_Support"
    },
    {
      "x": -17,
      "y": 74,
      "z": -1,
      "name": "Plant_Leaves_Beech_Max_Support"
    },
    {
      "x": -17,
      "y": 75,
      "z": -1,
      "name": "Plant_Leaves_Beech_Max_Support"
    },
    {
      "x": -17,
      "y": 76,
      "z": -1,
      "name": "Plant_Leaves_Beech_Max_Support"
    },
    {
      "x": -17,
      "y": 5,
      "z": 0,
      "name": "Wood_Gumboab_Roots"
    },
    {
      "x": -17,
      "y": 6,
      "z": 0,
      "name": "Wood_Gumboab_Trunk_Full"
    },
    {
      "x": -17,
      "y": 7,
      "z": 0,
      "name": "Wood_Gumboab_Trunk_Full"
    },
    {
      "x": -17,
      "y": 12,
      "z": 0,
      "name": "Wood_Gumboab_Trunk_Full"
    },
    {
      "x": -17,
      "y": 13,
      "z": 0,
      "name": "Wood_Gumboab_Trunk_Full"
    },
    {
      "x": -17,
      "y": 14,
      "z": 0,
      "name": "Wood_Gumboab_Trunk_Full"
    },
    {
      "x": -17,
      "y": 15,
      "z": 0,
      "name": "Wood_Gumboab_Trunk_Full"
    },
    {
      "x": -17,
      "y": 71,
      "z": 0,
      "name": "Plant_Leaves_Beech_Max_Support",
      "support": 15
    },
    {
      "x": -17,
      "y": 72,
      "z": 0,
      "name": "Plant_Leaves_Beech_Max_Support"
    },
    {
      "x": -17,
      "y": 73,
      "z": 0,
      "name": "Plant_Leaves_Beech_Max_Support"
    },
    {
      "x": -17,
      "y": 74,
      "z": 0,
      "name": "Plant_Leaves_Beech_Max_Support"
    },
    {
      "x": -17,
      "y": 75,
      "z": 0,
      "name": "Plant_Leaves_Beech_Max_Support"
    },
    {
      "x": -17,
      "y": 76,
      "z": 0,
      "name": "Plant_Leaves_Beech_Max_Support"
    },
    {
      "x": -17,
      "y": 5,
      "z": 1,
      "name": "Wood_Gumboab_Roots"
    },
    {
      "x": -17,
      "y": 6,
      "z": 1,
      "name": "Wood_Gumboab_Trunk_Full"
    },
    {
      "x": -17,
      "y": 7,
      "z": 1,
      "name": "Wood_Gumboab_Trunk_Full"
    },
    {
      "x": -17,
      "y": 14,
      "z": 1,
      "name": "Wood_Gumboab_Trunk_Full"
    },
    {
      "x": -17,
      "y": 15,
      "z": 1,
      "name": "Wood_Gumboab_Trunk_Full"
    },
    {
      "x": -17,
      "y": 70,
      "z": 1,
      "name": "Plant_Leaves_Beech_Max_Support",
      "support": 15
    },
    {
      "x": -17,
      "y": 71,
      "z": 1,
      "name": "Plant_Leaves_Beech_Max_Support",
      "support": 15
    },
    {
      "x": -17,
      "y": 72,
      "z": 1,
      "name": "Plant_Leaves_Beech_Max_Support"
    },
    {
      "x": -17,
      "y": 73,
      "z": 1,
      "name": "Plant_Leaves_Beech_Max_Support"
    },
    {
      "x": -17,
      "y": 74,
      "z": 1,
      "name": "Plant_Leaves_Beech_Max_Support"
    },
    {
      "x": -17,
      "y": 76,
      "z": 1,
      "name": "Plant_Leaves_Beech_Max_Support"
    },
    {
      "x": -17,
      "y": 49,
      "z": 2,
      "name": "Plant_Leaves_Beech_Max_Support"
    },
    {
      "x": -17,
      "y": 71,
      "z": 2,
      "name": "Plant_Leaves_Beech_Max_Support",
      "support": 15
    },
    {
      "x": -17,
      "y": 72,
      "z": 2,
      "name": "Plant_Leaves_Beech_Max_Support",
      "support": 15
    },
    {
      "x": -17,
      "y": 75,
      "z": 2,
      "name": "Plant_Leaves_Beech_Max_Support"
    },
    {
      "x": -17,
      "y": 46,
      "z": 3,
      "name": "Plant_Leaves_Beech_Max_Support",
      "support": 15
    },
    {
      "x": -17,
      "y": 47,
      "z": 3,
      "name": "Plant_Leaves_Beech_Max_Support"
    },
    {
      "x": -17,
      "y": 49,
      "z": 3,
      "name": "Plant_Leaves_Beech_Max_Support"
    },
    {
      "x": -17,
      "y": 50,
      "z": 3,
      "name": "Plant_Leaves_Beech_Max_Support"
    },
    {
      "x": -17,
      "y": 69,
      "z": 3,
      "name": "Plant_Leaves_Beech_Max_Support",
      "support": 15
    },
    {
      "x": -17,
      "y": 70,
      "z": 3,
      "name": "Plant_Leaves_Beech_Max_Support",
      "support": 15
    },
    {
      "x": -17,
      "y": 72,
      "z": 3,
      "name": "Plant_Leaves_Beech_Max_Support"
    },
    {
      "x": -17,
      "y": 73,
      "z": 3,
      "name": "Plant_Leaves_Beech_Max_Support"
    },
    {
      "x": -17,
      "y": 74,
      "z": 3,
      "name": "Plant_Leaves_Beech_Max_Support"
    },
    {
      "x": -17,
      "y": 75,
      "z": 3,
      "name": "Plant_Leaves_Beech_Max_Support"
    },
    {
      "x": -17,
      "y": 9,
      "z": 4,
      "name": "Wood_Gumboab_Trunk_Full"
    },
    {
      "x": -17,
      "y": 10,
      "z": 4,
      "name": "Wood_Gumboab_Trunk_Full"
    },
    {
      "x": -17,
      "y": 11,
      "z": 4,
      "name": "Wood_Gumboab_Trunk_Full"
    },
    {
      "x": -17,
      "y": 12,
      "z": 4,
      "name": "Wood_Gumboab_Trunk_Full"
    },
    {
      "x": -17,
      "y": 13,
      "z": 4,
      "name": "Wood_Gumboab_Trunk_Full"
    },
    {
      "x": -17,
      "y": 14,
      "z": 4,
      "name": "Wood_Gumboab_Trunk_Full"
    },
    {
      "x": -17,
      "y": 48,
      "z": 4,
      "name": "Plant_Leaves_Beech_Max_Support"
    },
    {
      "x": -17,
      "y": 49,
      "z": 4,
      "name": "Plant_Leaves_Beech_Max_Support"
    },
    {
      "x": -17,
      "y": 51,
      "z": 4,
      "name": "Plant_Leaves_Beech_Max_Support"
    },
    {
      "x": -17,
      "y": 52,
      "z": 4,
      "name": "Plant_Leaves_Beech_Max_Support"
    },
    {
      "x": -17,
      "y": 73,
      "z": 4,
      "name": "Plant_Leaves_Beech_Max_Support"
    },
    {
      "x": -17,
      "y": 74,
      "z": 4,
      "name": "Plant_Leaves_Beech_Max_Support"
    },
    {
      "x": -17,
      "y": 11,
      "z": 5,
      "name": "Wood_Gumboab_Trunk_Full"
    },
    {
      "x": -17,
      "y": 12,
      "z": 5,
      "name": "Wood_Gumboab_Trunk_Full"
    },
    {
      "x": -17,
      "y": 13,
      "z": 5,
      "name": "Wood_Gumboab_Trunk_Full"
    },
    {
      "x": -17,
      "y": 46,
      "z": 5,
      "name": "Plant_Leaves_Beech_Max_Support"
    },
    {
      "x": -17,
      "y": 47,
      "z": 5,
      "name": "Plant_Leaves_Beech_Max_Support"
    },
    {
      "x": -17,
      "y": 48,
      "z": 5,
      "name": "Plant_Leaves_Beech_Max_Support"
    },
    {
      "x": -17,
      "y": 49,
      "z": 5,
      "name": "Plant_Leaves_Beech_Max_Support"
    },
    {
      "x": -17,
      "y": 51,
      "z": 5,
      "name": "Plant_Leaves_Beech_Max_Support"
    },
    {
      "x": -17,
      "y": 52,
      "z": 5,
      "name": "Plant_Leaves_Beech_Max_Support"
    },
    {
      "x": -17,
      "y": 11,
      "z": 6,
      "name": "Wood_Gumboab_Trunk_Full"
    },
    {
      "x": -17,
      "y": 12,
      "z": 6,
      "name": "Wood_Gumboab_Trunk_Full"
    },
    {
      "x": -17,
      "y": 46,
      "z": 6,
      "name": "Plant_Leaves_Beech_Max_Support"
    },
    {
      "x": -17,
      "y": 47,
      "z": 6,
      "name": "Plant_Leaves_Beech_Max_Support"
    },
    {
      "x": -17,
      "y": 48,
      "z": 6,
      "name": "Plant_Leaves_Beech_Max_Support"
    },
    {
      "x": -17,
      "y": 49,
      "z": 6,
      "name": "Plant_Leaves_Beech_Max_Support"
    },
    {
      "x": -17,
      "y": 50,
      "z": 6,
      "name": "Plant_Leaves_Beech_Max_Support"
    },
    {
      "x": -17,
      "y": 51,
      "z": 6,
      "name": "Plant_Leaves_Beech_Max_Support"
    },
    {
      "x": -17,
      "y": 10,
      "z": 7,
      "name": "Wood_Gumboab_Trunk_Full"
    },
    {
      "x": -17,
      "y": 11,
      "z": 7,
      "name": "Wood_Gumboab_Trunk_Full"
    },
    {
      "x": -17,
      "y": 12,
      "z": 7,
      "name": "Wood_Gumboab_Trunk_Full"
    },
    {
      "x": -17,
      "y": 13,
      "z": 7,
      "name": "Plant_Moss_Rug_Yellow",
      "support": 15
    },
    {
      "x": -17,
      "y": 45,
      "z": 7,
      "name": "Plant_Leaves_Beech_Max_Support"
    },
    {
      "x": -17,
      "y": 46,
      "z": 7,
      "name": "Wood_Gumboab_Trunk_Full"
    },
    {
      "x": -17,
      "y": 47,
      "z": 7,
      "name": "Plant_Leaves_Beech_Max_Support"
    },
    {
      "x": -17,
      "y": 48,
      "z": 7,
      "name": "Plant_Leaves_Beech_Max_Support"
    },
    {
      "x": -17,
      "y": 49,
      "z": 7,
      "name": "Plant_Leaves_Beech_Max_Support"
    },
    {
      "x": -17,
      "y": 50,
      "z": 7,
      "name": "Plant_Leaves_Beech_Max_Support"
    },
    {
      "x": -17,
      "y": 51,
      "z": 7,
      "name": "Plant_Leaves_Beech_Max_Support"
    },
    {
      "x": -17,
      "y": 11,
      "z": 8,
      "name": "Wood_Gumboab_Trunk_Full"
    },
    {
      "x": -17,
      "y": 12,
      "z": 8,
      "name": "Wood_Gumboab_Trunk_Full"
    },
    {
      "x": -17,
      "y": 13,
      "z": 8,
      "name": "Plant_Moss_Rug_Yellow",
      "support": 15
    },
    {
      "x": -17,
      "y": 45,
      "z": 8,
      "name": "Wood_Gumboab_Trunk_Full"
    },
    {
      "x": -17,
      "y": 46,
      "z": 8,
      "name": "Wood_Gumboab_Trunk_Full"
    },
    {
      "x": -17,
      "y": 47,
      "z": 8,
      "name": "Wood_Gumboab_Trunk_Full"
    },
    {
      "x": -17,
      "y": 48,
      "z": 8,
      "name": "Wood_Gumboab_Trunk_Full"
    },
    {
      "x": -17,
      "y": 49,
      "z": 8,
      "name": "Plant_Leaves_Beech_Max_Support"
    },
    {
      "x": -17,
      "y": 50,
      "z": 8,
      "name": "Plant_Leaves_Beech_Max_Support"
    },
    {
      "x": -17,
      "y": 46,
      "z": 9,
      "name": "Plant_Leaves_Beech_Max_Support"
    },
    {
      "x": -17,
      "y": 47,
      "z": 9,
      "name": "Plant_Leaves_Beech_Max_Support"
    },
    {
      "x": -17,
      "y": 48,
      "z": 9,
      "name": "Plant_Leaves_Beech_Max_Support"
    },
    {
      "x": -17,
      "y": 49,
      "z": 9,
      "name": "Plant_Leaves_Beech_Max_Support"
    },
    {
      "x": -17,
      "y": 50,
      "z": 9,
      "name": "Plant_Leaves_Beech_Max_Support"
    },
    {
      "x": -17,
      "y": 51,
      "z": 9,
      "name": "Plant_Leaves_Beech_Max_Support"
    },
    {
      "x": -17,
      "y": 47,
      "z": 10,
      "name": "Plant_Leaves_Beech_Max_Support"
    },
    {
      "x": -17,
      "y": 48,
      "z": 10,
      "name": "Plant_Leaves_Beech_Max_Support"
    },
    {
      "x": -17,
      "y": 49,
      "z": 10,
      "name": "Plant_Leaves_Beech_Max_Support"
    },
    {
      "x": -17,
      "y": 50,
      "z": 10,
      "name": "Plant_Leaves_Beech_Max_Support"
    },
    {
      "x": -17,
      "y": 46,
      "z": 11,
      "name": "Plant_Leaves_Beech_Max_Support"
    },
    {
      "x": -17,
      "y": 47,
      "z": 11,
      "name": "Plant_Leaves_Beech_Max_Support"
    },
    {
      "x": -17,
      "y": 48,
      "z": 11,
      "name": "Plant_Leaves_Beech_Max_Support"
    },
    {
      "x": -17,
      "y": 49,
      "z": 11,
      "name": "Plant_Leaves_Beech_Max_Support"
    },
    {
      "x": -17,
      "y": 50,
      "z": 11,
      "name": "Plant_Leaves_Beech_Max_Support"
    },
    {
      "x": -17,
      "y": 45,
      "z": 12,
      "name": "Plant_Leaves_Beech_Max_Support"
    },
    {
      "x": -17,
      "y": 46,
      "z": 12,
      "name": "Plant_Leaves_Beech_Max_Support"
    },
    {
      "x": -17,
      "y": 47,
      "z": 12,
      "name": "Plant_Leaves_Beech_Max_Support"
    },
    {
      "x": -17,
      "y": 49,
      "z": 12,
      "name": "Plant_Leaves_Beech_Max_Support"
    },
    {
      "x": -17,
      "y": 50,
      "z": 12,
      "name": "Plant_Leaves_Beech_Max_Support"
    },
    {
      "x": -17,
      "y": 52,
      "z": 12,
      "name": "Plant_Leaves_Beech_Max_Support"
    },
    {
      "x": -17,
      "y": 45,
      "z": 13,
      "name": "Plant_Leaves_Beech_Max_Support"
    },
    {
      "x": -17,
      "y": 47,
      "z": 13,
      "name": "Plant_Leaves_Beech_Max_Support"
    },
    {
      "x": -17,
      "y": 48,
      "z": 13,
      "name": "Plant_Leaves_Beech_Max_Support"
    },
    {
      "x": -17,
      "y": 49,
      "z": 13,
      "name": "Plant_Leaves_Beech_Max_Support"
    },
    {
      "x": -17,
      "y": 51,
      "z": 13,
      "name": "Plant_Leaves_Beech_Max_Support"
    },
    {
      "x": -17,
      "y": 47,
      "z": 14,
      "name": "Plant_Leaves_Beech_Max_Support"
    },
    {
      "x": -17,
      "y": 49,
      "z": 14,
      "name": "Plant_Leaves_Beech_Max_Support"
    },
    {
      "x": -17,
      "y": 50,
      "z": 14,
      "name": "Plant_Leaves_Beech_Max_Support"
    },
    {
      "x": -17,
      "y": 50,
      "z": 15,
      "name": "Plant_Leaves_Beech_Max_Support"
    },
    {
      "x": -17,
      "y": 49,
      "z": 17,
      "name": "Plant_Leaves_Beech_Max_Support"
    },
    {
      "x": -17,
      "y": 50,
      "z": 18,
      "name": "Plant_Leaves_Beech_Max_Support"
    },
    {
      "x": -16,
      "y": 10,
      "z": -11,
      "name": "Wood_Gumboab_Trunk_Full"
    },
    {
      "x": -16,
      "y": 8,
      "z": -10,
      "name": "Wood_Gumboab_Trunk_Full"
    },
    {
      "x": -16,
      "y": 9,
      "z": -10,
      "name": "Wood_Gumboab_Trunk_Full"
    },
    {
      "x": -16,
      "y": 10,
      "z": -10,
      "name": "Wood_Gumboab_Trunk_Full"
    },
    {
      "x": -16,
      "y": 11,
      "z": -10,
      "name": "Wood_Gumboab_Trunk_Full"
    },
    {
      "x": -16,
      "y": 72,
      "z": -10,
      "name": "Plant_Leaves_Beech_Max_Support",
      "support": 15
    },
    {
      "x": -16,
      "y": 73,
      "z": -10,
      "name": "Plant_Leaves_Beech_Max_Support",
      "support": 15
    },
    {
      "x": -16,
      "y": 74,
      "z": -10,
      "name": "Plant_Leaves_Beech_Max_Support"
    },
    {
      "x": -16,
      "y": 75,
      "z": -10,
      "name": "Plant_Leaves_Beech_Max_Support"
    },
    {
      "x": -16,
      "y": 9,
      "z": -9,
      "name": "Wood_Gumboab_Trunk_Full"
    },
    {
      "x": -16,
      "y": 10,
      "z": -9,
      "name": "Wood_Gumboab_Trunk_Full"
    },
    {
      "x": -16,
      "y": 11,
      "z": -9,
      "name": "Wood_Gumboab_Trunk_Full"
    },
    {
      "x": -16,
      "y": 71,
      "z": -9,
      "name": "Plant_Leaves_Beech_Max_Support",
      "support": 15
    },
    {
      "x": -16,
      "y": 73,
      "z": -9,
      "name": "Plant_Leaves_Beech_Max_Support"
    },
    {
      "x": -16,
      "y": 74,
      "z": -9,
      "name": "Plant_Leaves_Beech_Max_Support"
    },
    {
      "x": -16,
      "y": 70,
      "z": -8,
      "name": "Plant_Leaves_Beech_Max_Support",
      "support": 15
    },
    {
      "x": -16,
      "y": 71,
      "z": -8,
      "name": "Plant_Leaves_Beech_Max_Support",
      "support": 15
    },
    {
      "x": -16,
      "y": 72,
      "z": -8,
      "name": "Plant_Leaves_Beech_Max_Support"
    },
    {
      "x": -16,
      "y": 73,
      "z": -8,
      "name": "Plant_Leaves_Beech_Max_Support"
    },
    {
      "x": -16,
      "y": 74,
      "z": -8,
      "name": "Plant_Leaves_Beech_Max_Support"
    },
    {
      "x": -16,
      "y": 75,
      "z": -8,
      "name": "Plant_Leaves_Beech_Max_Support"
    },
    {
      "x": -16,
      "y": 76,
      "z": -8,
      "name": "Plant_Leaves_Beech_Max_Support"
    },
    {
      "x": -16,
      "y": 71,
      "z": -7,
      "name": "Plant_Leaves_Beech_Max_Support",
      "support": 15
    },
    {
      "x": -16,
      "y": 72,
      "z": -7,
      "name": "Plant_Leaves_Beech_Max_Support"
    },
    {
      "x": -16,
      "y": 73,
      "z": -7,
      "name": "Plant_Leaves_Beech_Max_Support"
    },
    {
      "x": -16,
      "y": 74,
      "z": -7,
      "name": "Plant_Leaves_Beech_Max_Support"
    },
    {
      "x": -16,
      "y": 75,
      "z": -7,
      "name": "Plant_Leaves_Beech_Max_Support"
    },
    {
      "x": -16,
      "y": 72,
      "z": -6,
      "name": "Plant_Leaves_Beech_Max_Support"
    },
    {
      "x": -16,
      "y": 73,
      "z": -6,
      "name": "Plant_Leaves_Beech_Max_Support"
    },
    {
      "x": -16,
      "y": 74,
      "z": -6,
      "name": "Plant_Leaves_Beech_Max_Support"
    },
    {
      "x": -16,
      "y": 75,
      "z": -6,
      "name": "Plant_Leaves_Beech_Max_Support"
    },
    {
      "x": -16,
      "y": 76,
      "z": -6,
      "name": "Plant_Leaves_Beech_Max_Support"
    },
    {
      "x": -16,
      "y": 16,
      "z": -5,
      "name": "Wood_Gumboab_Trunk_Full"
    },
    {
      "x": -16,
      "y": 72,
      "z": -5,
      "name": "Plant_Leaves_Beech_Max_Support"
    },
    {
      "x": -16,
      "y": 73,
      "z": -5,
      "name": "Plant_Leaves_Beech_Max_Support"
    },
    {
      "x": -16,
      "y": 15,
      "z": -4,
      "name": "Wood_Gumboab_Trunk_Full"
    },
    {
      "x": -16,
      "y": 16,
      "z": -4,
      "name": "Wood_Gumboab_Trunk_Full"
    },
    {
      "x": -16,
      "y": 17,
      "z": -4,
      "name": "Wood_Gumboab_Trunk_Full"
    },
    {
      "x": -16,
      "y": 18,
      "z": -4,
      "name": "Wood_Gumboab_Trunk_Full"
    },
    {
      "x": -16,
      "y": 70,
      "z": -4,
      "name": "Plant_Leaves_Beech_Max_Support"
    },
    {
      "x": -16,
      "y": 71,
      "z": -4,
      "name": "Plant_Leaves_Beech_Max_Support"
    },
    {
      "x": -16,
      "y": 72,
      "z": -4,
      "name": "Plant_Leaves_Beech_Max_Support"
    },
    {
      "x": -16,
      "y": 73,
      "z": -4,
      "name": "Plant_Leaves_Beech_Max_Support"
    },
    {
      "x": -16,
      "y": 74,
      "z": -4,
      "name": "Plant_Leaves_Beech_Max_Support"
    },
    {
      "x": -16,
      "y": 75,
      "z": -4,
      "name": "Plant_Leaves_Beech_Max_Support"
    },
    {
      "x": -16,
      "y": 76,
      "z": -4,
      "name": "Plant_Leaves_Beech_Max_Support"
    },
    {
      "x": -16,
      "y": 77,
      "z": -4,
      "name": "Plant_Leaves_Beech_Max_Support"
    },
    {
      "x": -16,
      "y": 15,
      "z": -3,
      "name": "Wood_Gumboab_Trunk_Full"
    },
    {
      "x": -16,
      "y": 16,
      "z": -3,
      "name": "Wood_Gumboab_Trunk_Full"
    },
    {
      "x": -16,
      "y": 17,
      "z": -3,
      "name": "Wood_Gumboab_Trunk_Full"
    },
    {
      "x": -16,
      "y": 18,
      "z": -3,
      "name": "Wood_Gumboab_Trunk_Full"
    },
    {
      "x": -16,
      "y": 70,
      "z": -3,
      "name": "Plant_Leaves_Beech_Max_Support"
    },
    {
      "x": -16,
      "y": 71,
      "z": -3,
      "name": "Plant_Leaves_Beech_Max_Support"
    },
    {
      "x": -16,
      "y": 72,
      "z": -3,
      "name": "Plant_Leaves_Beech_Max_Support"
    },
    {
      "x": -16,
      "y": 73,
      "z": -3,
      "name": "Plant_Leaves_Beech_Max_Support"
    },
    {
      "x": -16,
      "y": 74,
      "z": -3,
      "name": "Plant_Leaves_Beech_Max_Support"
    },
    {
      "x": -16,
      "y": 75,
      "z": -3,
      "name": "Plant_Leaves_Beech_Max_Support"
    },
    {
      "x": -16,
      "y": 77,
      "z": -3,
      "name": "Plant_Leaves_Beech_Max_Support"
    },
    {
      "x": -16,
      "y": 14,
      "z": -2,
      "name": "Wood_Gumboab_Trunk_Full"
    },
    {
      "x": -16,
      "y": 15,
      "z": -2,
      "name": "Wood_Gumboab_Trunk_Full"
    },
    {
      "x": -16,
      "y": 16,
      "z": -2,
      "name": "Wood_Gumboab_Trunk_Full"
    },
    {
      "x": -16,
      "y": 17,
      "z": -2,
      "name": "Wood_Gumboab_Trunk_Full"
    },
    {
      "x": -16,
      "y": 18,
      "z": -2,
      "name": "Wood_Gumboab_Trunk_Full"
    },
    {
      "x": -16,
      "y": 71,
      "z": -2,
      "name": "Plant_Leaves_Beech_Max_Support"
    },
    {
      "x": -16,
      "y": 72,
      "z": -2,
      "name": "Plant_Leaves_Beech_Max_Support"
    },
    {
      "x": -16,
      "y": 73,
      "z": -2,
      "name": "Plant_Leaves_Beech_Max_Support"
    },
    {
      "x": -16,
      "y": 74,
      "z": -2,
      "name": "Plant_Leaves_Beech_Max_Support"
    },
    {
      "x": -16,
      "y": 75,
      "z": -2,
      "name": "Plant_Leaves_Beech_Max_Support"
    },
    {
      "x": -16,
      "y": 76,
      "z": -2,
      "name": "Plant_Leaves_Beech_Max_Support"
    },
    {
      "x": -16,
      "y": 10,
      "z": -1,
      "name": "Wood_Gumboab_Trunk_Full"
    },
    {
      "x": -16,
      "y": 11,
      "z": -1,
      "name": "Wood_Gumboab_Trunk_Full"
    },
    {
      "x": -16,
      "y": 12,
      "z": -1,
      "name": "Wood_Gumboab_Trunk_Full"
    },
    {
      "x": -16,
      "y": 13,
      "z": -1,
      "name": "Wood_Gumboab_Trunk_Full"
    },
    {
      "x": -16,
      "y": 14,
      "z": -1,
      "name": "Wood_Gumboab_Trunk_Full"
    },
    {
      "x": -16,
      "y": 15,
      "z": -1,
      "name": "Wood_Gumboab_Trunk_Full"
    },
    {
      "x": -16,
      "y": 16,
      "z": -1,
      "name": "Wood_Gumboab_Trunk_Full"
    },
    {
      "x": -16,
      "y": 71,
      "z": -1,
      "name": "Plant_Leaves_Beech_Max_Support"
    },
    {
      "x": -16,
      "y": 73,
      "z": -1,
      "name": "Plant_Leaves_Beech_Max_Support"
    },
    {
      "x": -16,
      "y": 74,
      "z": -1,
      "name": "Plant_Leaves_Beech_Max_Support"
    },
    {
      "x": -16,
      "y": 75,
      "z": -1,
      "name": "Plant_Leaves_Beech_Max_Support"
    },
    {
      "x": -16,
      "y": 76,
      "z": -1,
      "name": "Plant_Leaves_Beech_Max_Support"
    },
    {
      "x": -16,
      "y": 77,
      "z": -1,
      "name": "Plant_Leaves_Beech_Max_Support"
    },
    {
      "x": -16,
      "y": 78,
      "z": -1,
      "name": "Plant_Leaves_Beech_Max_Support"
    },
    {
      "x": -16,
      "y": 6,
      "z": 0,
      "name": "Wood_Gumboab_Trunk_Full"
    },
    {
      "x": -16,
      "y": 7,
      "z": 0,
      "name": "Wood_Gumboab_Trunk_Full"
    },
    {
      "x": -16,
      "y": 8,
      "z": 0,
      "name": "Wood_Gumboab_Trunk_Full"
    },
    {
      "x": -16,
      "y": 9,
      "z": 0,
      "name": "Wood_Gumboab_Trunk_Full"
    },
    {
      "x": -16,
      "y": 10,
      "z": 0,
      "name": "Wood_Gumboab_Trunk_Full"
    },
    {
      "x": -16,
      "y": 11,
      "z": 0,
      "name": "Wood_Gumboab_Trunk_Full"
    },
    {
      "x": -16,
      "y": 12,
      "z": 0,
      "name": "Wood_Gumboab_Trunk_Full"
    },
    {
      "x": -16,
      "y": 13,
      "z": 0,
      "name": "Wood_Gumboab_Trunk_Full"
    },
    {
      "x": -16,
      "y": 14,
      "z": 0,
      "name": "Wood_Gumboab_Trunk_Full"
    },
    {
      "x": -16,
      "y": 15,
      "z": 0,
      "name": "Wood_Gumboab_Trunk_Full"
    },
    {
      "x": -16,
      "y": 72,
      "z": 0,
      "name": "Plant_Leaves_Beech_Max_Support"
    },
    {
      "x": -16,
      "y": 73,
      "z": 0,
      "name": "Plant_Leaves_Beech_Max_Support"
    },
    {
      "x": -16,
      "y": 74,
      "z": 0,
      "name": "Plant_Leaves_Beech_Max_Support"
    },
    {
      "x": -16,
      "y": 75,
      "z": 0,
      "name": "Plant_Leaves_Beech_Max_Support"
    },
    {
      "x": -16,
      "y": 76,
      "z": 0,
      "name": "Plant_Leaves_Beech_Max_Support"
    },
    {
      "x": -16,
      "y": 6,
      "z": 1,
      "name": "Wood_Gumboab_Trunk_Full"
    },
    {
      "x": -16,
      "y": 7,
      "z": 1,
      "name": "Wood_Gumboab_Trunk_Full"
    },
    {
      "x": -16,
      "y": 8,
      "z": 1,
      "name": "Wood_Gumboab_Trunk_Full"
    },
    {
      "x": -16,
      "y": 9,
      "z": 1,
      "name": "Wood_Gumboab_Trunk_Full"
    },
    {
      "x": -16,
      "y": 10,
      "z": 1,
      "name": "Wood_Gumboab_Trunk_Full"
    },
    {
      "x": -16,
      "y": 11,
      "z": 1,
      "name": "Wood_Gumboab_Trunk_Full"
    },
    {
      "x": -16,
      "y": 14,
      "z": 1,
      "name": "Wood_Gumboab_Trunk_Full"
    },
    {
      "x": -16,
      "y": 15,
      "z": 1,
      "name": "Wood_Gumboab_Trunk_Full"
    },
    {
      "x": -16,
      "y": 16,
      "z": 1,
      "name": "Wood_Gumboab_Trunk_Full"
    },
    {
      "x": -16,
      "y": 46,
      "z": 1,
      "name": "Plant_Leaves_Beech_Max_Support"
    },
    {
      "x": -16,
      "y": 71,
      "z": 1,
      "name": "Plant_Leaves_Beech_Max_Support"
    },
    {
      "x": -16,
      "y": 72,
      "z": 1,
      "name": "Plant_Leaves_Beech_Max_Support"
    },
    {
      "x": -16,
      "y": 73,
      "z": 1,
      "name": "Plant_Leaves_Beech_Max_Support"
    },
    {
      "x": -16,
      "y": 74,
      "z": 1,
      "name": "Plant_Leaves_Beech_Max_Support"
    },
    {
      "x": -16,
      "y": 75,
      "z": 1,
      "name": "Plant_Leaves_Beech_Max_Support"
    },
    {
      "x": -16,
      "y": 76,
      "z": 1,
      "name": "Plant_Leaves_Beech_Max_Support"
    },
    {
      "x": -16,
      "y": 15,
      "z": 2,
      "name": "Wood_Gumboab_Trunk_Full"
    },
    {
      "x": -16,
      "y": 16,
      "z": 2,
      "name": "Wood_Gumboab_Trunk_Full"
    },
    {
      "x": -16,
      "y": 45,
      "z": 2,
      "name": "Plant_Leaves_Beech_Max_Support"
    },
    {
      "x": -16,
      "y": 46,
      "z": 2,
      "name": "Plant_Leaves_Beech_Max_Support"
    },
    {
      "x": -16,
      "y": 47,
      "z": 2,
      "name": "Plant_Leaves_Beech_Max_Support"
    },
    {
      "x": -16,
      "y": 71,
      "z": 2,
      "name": "Plant_Leaves_Beech_Max_Support"
    },
    {
      "x": -16,
      "y": 72,
      "z": 2,
      "name": "Plant_Leaves_Beech_Max_Support"
    },
    {
      "x": -16,
      "y": 73,
      "z": 2,
      "name": "Plant_Leaves_Beech_Max_Support"
    },
    {
      "x": -16,
      "y": 74,
      "z": 2,
      "name": "Plant_Leaves_Beech_Max_Support"
    },
    {
      "x": -16,
      "y": 75,
      "z": 2,
      "name": "Plant_Leaves_Beech_Max_Support"
    },
    {
      "x": -16,
      "y": 76,
      "z": 2,
      "name": "Plant_Leaves_Beech_Max_Support"
    },
    {
      "x": -16,
      "y": 13,
      "z": 3,
      "name": "Wood_Gumboab_Trunk_Full"
    },
    {
      "x": -16,
      "y": 14,
      "z": 3,
      "name": "Wood_Gumboab_Trunk_Full"
    },
    {
      "x": -16,
      "y": 15,
      "z": 3,
      "name": "Wood_Gumboab_Trunk_Full"
    },
    {
      "x": -16,
      "y": 16,
      "z": 3,
      "name": "Wood_Gumboab_Trunk_Full"
    },
    {
      "x": -16,
      "y": 45,
      "z": 3,
      "name": "Plant_Leaves_Beech_Max_Support"
    },
    {
      "x": -16,
      "y": 46,
      "z": 3,
      "name": "Plant_Leaves_Beech_Max_Support"
    },
    {
      "x": -16,
      "y": 47,
      "z": 3,
      "name": "Plant_Leaves_Beech_Max_Support"
    },
    {
      "x": -16,
      "y": 48,
      "z": 3,
      "name": "Plant_Leaves_Beech_Max_Support"
    },
    {
      "x": -16,
      "y": 50,
      "z": 3,
      "name": "Plant_Leaves_Beech_Max_Support"
    },
    {
      "x": -16,
      "y": 70,
      "z": 3,
      "name": "Plant_Leaves_Beech_Max_Support",
      "support": 15
    },
    {
      "x": -16,
      "y": 71,
      "z": 3,
      "name": "Plant_Leaves_Beech_Max_Support"
    },
    {
      "x": -16,
      "y": 72,
      "z": 3,
      "name": "Plant_Leaves_Beech_Max_Support"
    },
    {
      "x": -16,
      "y": 73,
      "z": 3,
      "name": "Plant_Leaves_Beech_Max_Support"
    },
    {
      "x": -16,
      "y": 74,
      "z": 3,
      "name": "Plant_Leaves_Beech_Max_Support"
    },
    {
      "x": -16,
      "y": 75,
      "z": 3,
      "name": "Plant_Leaves_Beech_Max_Support"
    },
    {
      "x": -16,
      "y": 12,
      "z": 4,
      "name": "Wood_Gumboab_Trunk_Full"
    },
    {
      "x": -16,
      "y": 13,
      "z": 4,
      "name": "Wood_Gumboab_Trunk_Full"
    },
    {
      "x": -16,
      "y": 14,
      "z": 4,
      "name": "Wood_Gumboab_Trunk_Full"
    },
    {
      "x": -16,
      "y": 15,
      "z": 4,
      "name": "Wood_Gumboab_Trunk_Full"
    },
    {
      "x": -16,
      "y": 16,
      "z": 4,
      "name": "Wood_Gumboab_Trunk_Full"
    },
    {
      "x": -16,
      "y": 46,
      "z": 4,
      "name": "Plant_Leaves_Beech_Max_Support"
    },
    {
      "x": -16,
      "y": 47,
      "z": 4,
      "name": "Plant_Leaves_Beech_Max_Support"
    },
    {
      "x": -16,
      "y": 49,
      "z": 4,
      "name": "Plant_Leaves_Beech_Max_Support"
    },
    {
      "x": -16,
      "y": 50,
      "z": 4,
      "name": "Plant_Leaves_Beech_Max_Support"
    },
    {
      "x": -16,
      "y": 71,
      "z": 4,
      "name": "Plant_Leaves_Beech_Max_Support",
      "support": 15
    },
    {
      "x": -16,
      "y": 72,
      "z": 4,
      "name": "Plant_Leaves_Beech_Max_Support",
      "support": 15
    },
    {
      "x": -16,
      "y": 74,
      "z": 4,
      "name": "Plant_Leaves_Beech_Max_Support"
    },
    {
      "x": -16,
      "y": 12,
      "z": 5,
      "name": "Wood_Gumboab_Trunk_Full"
    },
    {
      "x": -16,
      "y": 13,
      "z": 5,
      "name": "Wood_Gumboab_Trunk_Full"
    },
    {
      "x": -16,
      "y": 14,
      "z": 5,
      "name": "Wood_Gumboab_Trunk_Full"
    },
    {
      "x": -16,
      "y": 46,
      "z": 5,
      "name": "Plant_Leaves_Beech_Max_Support"
    },
    {
      "x": -16,
      "y": 47,
      "z": 5,
      "name": "Plant_Leaves_Beech_Max_Support"
    },
    {
      "x": -16,
      "y": 49,
      "z": 5,
      "name": "Plant_Leaves_Beech_Max_Support"
    },
    {
      "x": -16,
      "y": 50,
      "z": 5,
      "name": "Plant_Leaves_Beech_Max_Support"
    },
    {
      "x": -16,
      "y": 73,
      "z": 5,
      "name": "Plant_Leaves_Beech_Max_Support"
    },
    {
      "x": -16,
      "y": 74,
      "z": 5,
      "name": "Plant_Leaves_Beech_Max_Support"
    },
    {
      "x": -16,
      "y": 11,
      "z": 6,
      "name": "Wood_Gumboab_Trunk_Full"
    },
    {
      "x": -16,
      "y": 12,
      "z": 6,
      "name": "Wood_Gumboab_Trunk_Full"
    },
    {
      "x": -16,
      "y": 13,
      "z": 6,
      "name": "Wood_Gumboab_Trunk_Full"
    },
    {
      "x": -16,
      "y": 46,
      "z": 6,
      "name": "Plant_Leaves_Beech_Max_Support"
    },
    {
      "x": -16,
      "y": 47,
      "z": 6,
      "name": "Plant_Leaves_Beech_Max_Support"
    },
    {
      "x": -16,
      "y": 48,
      "z": 6,
      "name": "Plant_Leaves_Beech_Max_Support"
    },
    {
      "x": -16,
      "y": 49,
      "z": 6,
      "name": "Plant_Leaves_Beech_Max_Support"
    },
    {
      "x": -16,
      "y": 50,
      "z": 6,
      "name": "Plant_Leaves_Beech_Max_Support"
    },
    {
      "x": -16,
      "y": 51,
      "z": 6,
      "name": "Plant_Leaves_Beech_Max_Support"
    },
    {
      "x": -16,
      "y": 11,
      "z": 7,
      "name": "Wood_Gumboab_Trunk_Full"
    },
    {
      "x": -16,
      "y": 12,
      "z": 7,
      "name": "Wood_Gumboab_Trunk_Full"
    },
    {
      "x": -16,
      "y": 45,
      "z": 7,
      "name": "Wood_Gumboab_Trunk_Full"
    },
    {
      "x": -16,
      "y": 46,
      "z": 7,
      "name": "Wood_Gumboab_Trunk_Full"
    },
    {
      "x": -16,
      "y": 47,
      "z": 7,
      "name": "Plant_Leaves_Beech_Max_Support"
    },
    {
      "x": -16,
      "y": 48,
      "z": 7,
      "name": "Plant_Leaves_Beech_Max_Support"
    },
    {
      "x": -16,
      "y": 49,
      "z": 7,
      "name": "Plant_Leaves_Beech_Max_Support"
    },
    {
      "x": -16,
      "y": 51,
      "z": 7,
      "name": "Plant_Leaves_Beech_Max_Support"
    },
    {
      "x": -16,
      "y": 12,
      "z": 8,
      "name": "Wood_Gumboab_Trunk_Full"
    },
    {
      "x": -16,
      "y": 45,
      "z": 8,
      "name": "Wood_Gumboab_Trunk_Full"
    },
    {
      "x": -16,
      "y": 46,
      "z": 8,
      "name": "Wood_Gumboab_Trunk_Full"
    },
    {
      "x": -16,
      "y": 48,
      "z": 8,
      "name": "Plant_Leaves_Beech_Max_Support"
    },
    {
      "x": -16,
      "y": 49,
      "z": 8,
      "name": "Plant_Leaves_Beech_Max_Support"
    },
    {
      "x": -16,
      "y": 50,
      "z": 8,
      "name": "Plant_Leaves_Beech_Max_Support"
    },
    {
      "x": -16,
      "y": 51,
      "z": 8,
      "name": "Plant_Leaves_Beech_Max_Support"
    },
    {
      "x": -16,
      "y": 52,
      "z": 8,
      "name": "Plant_Leaves_Beech_Max_Support"
    },
    {
      "x": -16,
      "y": 45,
      "z": 9,
      "name": "Plant_Leaves_Beech_Max_Support"
    },
    {
      "x": -16,
      "y": 47,
      "z": 9,
      "name": "Plant_Leaves_Beech_Max_Support"
    },
    {
      "x": -16,
      "y": 48,
      "z": 9,
      "name": "Plant_Leaves_Beech_Max_Support"
    },
    {
      "x": -16,
      "y": 49,
      "z": 9,
      "name": "Plant_Leaves_Beech_Max_Support"
    },
    {
      "x": -16,
      "y": 52,
      "z": 9,
      "name": "Plant_Leaves_Beech_Max_Support"
    },
    {
      "x": -16,
      "y": 46,
      "z": 10,
      "name": "Plant_Leaves_Beech_Max_Support"
    },
    {
      "x": -16,
      "y": 47,
      "z": 10,
      "name": "Plant_Leaves_Beech_Max_Support"
    },
    {
      "x": -16,
      "y": 48,
      "z": 10,
      "name": "Plant_Leaves_Beech_Max_Support"
    },
    {
      "x": -16,
      "y": 49,
      "z": 10,
      "name": "Plant_Leaves_Beech_Max_Support"
    },
    {
      "x": -16,
      "y": 50,
      "z": 10,
      "name": "Plant_Leaves_Beech_Max_Support"
    },
    {
      "x": -16,
      "y": 51,
      "z": 10,
      "name": "Plant_Leaves_Beech_Max_Support"
    },
    {
      "x": -16,
      "y": 52,
      "z": 10,
      "name": "Plant_Leaves_Beech_Max_Support"
    },
    {
      "x": -16,
      "y": 44,
      "z": 11,
      "name": "Plant_Leaves_Beech_Max_Support"
    },
    {
      "x": -16,
      "y": 46,
      "z": 11,
      "name": "Plant_Leaves_Beech_Max_Support"
    },
    {
      "x": -16,
      "y": 47,
      "z": 11,
      "name": "Plant_Leaves_Beech_Max_Support"
    },
    {
      "x": -16,
      "y": 48,
      "z": 11,
      "name": "Plant_Leaves_Beech_Max_Support"
    },
    {
      "x": -16,
      "y": 49,
      "z": 11,
      "name": "Plant_Leaves_Beech_Max_Support"
    },
    {
      "x": -16,
      "y": 51,
      "z": 11,
      "name": "Plant_Leaves_Beech_Max_Support"
    },
    {
      "x": -16,
      "y": 52,
      "z": 11,
      "name": "Plant_Leaves_Beech_Max_Support"
    },
    {
      "x": -16,
      "y": 43,
      "z": 12,
      "name": "Plant_Leaves_Beech_Max_Support"
    },
    {
      "x": -16,
      "y": 44,
      "z": 12,
      "name": "Plant_Leaves_Beech_Max_Support"
    },
    {
      "x": -16,
      "y": 46,
      "z": 12,
      "name": "Plant_Leaves_Beech_Max_Support"
    },
    {
      "x": -16,
      "y": 47,
      "z": 12,
      "name": "Plant_Leaves_Beech_Max_Support"
    },
    {
      "x": -16,
      "y": 48,
      "z": 12,
      "name": "Plant_Leaves_Beech_Max_Support"
    },
    {
      "x": -16,
      "y": 49,
      "z": 12,
      "name": "Plant_Leaves_Beech_Max_Support"
    },
    {
      "x": -16,
      "y": 51,
      "z": 12,
      "name": "Plant_Leaves_Beech_Max_Support"
    },
    {
      "x": -16,
      "y": 52,
      "z": 12,
      "name": "Plant_Leaves_Beech_Max_Support"
    },
    {
      "x": -16,
      "y": 44,
      "z": 13,
      "name": "Plant_Leaves_Beech_Max_Support"
    },
    {
      "x": -16,
      "y": 45,
      "z": 13,
      "name": "Plant_Leaves_Beech_Max_Support"
    },
    {
      "x": -16,
      "y": 46,
      "z": 13,
      "name": "Plant_Leaves_Beech_Max_Support"
    },
    {
      "x": -16,
      "y": 48,
      "z": 13,
      "name": "Plant_Leaves_Beech_Max_Support"
    },
    {
      "x": -16,
      "y": 49,
      "z": 13,
      "name": "Plant_Leaves_Beech_Max_Support"
    },
    {
      "x": -16,
      "y": 50,
      "z": 13,
      "name": "Plant_Leaves_Beech_Max_Support"
    },
    {
      "x": -16,
      "y": 51,
      "z": 13,
      "name": "Plant_Leaves_Beech_Max_Support"
    },
    {
      "x": -16,
      "y": 52,
      "z": 13,
      "name": "Plant_Leaves_Beech_Max_Support"
    },
    {
      "x": -16,
      "y": 45,
      "z": 14,
      "name": "Plant_Leaves_Beech_Max_Support"
    },
    {
      "x": -16,
      "y": 46,
      "z": 14,
      "name": "Plant_Leaves_Beech_Max_Support"
    },
    {
      "x": -16,
      "y": 48,
      "z": 14,
      "name": "Plant_Leaves_Beech_Max_Support"
    },
    {
      "x": -16,
      "y": 49,
      "z": 14,
      "name": "Plant_Leaves_Beech_Max_Support"
    },
    {
      "x": -16,
      "y": 50,
      "z": 14,
      "name": "Plant_Leaves_Beech_Max_Support"
    },
    {
      "x": -16,
      "y": 51,
      "z": 14,
      "name": "Plant_Leaves_Beech_Max_Support"
    },
    {
      "x": -16,
      "y": 52,
      "z": 14,
      "name": "Plant_Leaves_Beech_Max_Support"
    },
    {
      "x": -16,
      "y": 51,
      "z": 15,
      "name": "Plant_Leaves_Beech_Max_Support"
    },
    {
      "x": -16,
      "y": 52,
      "z": 15,
      "name": "Plant_Leaves_Beech_Max_Support"
    },
    {
      "x": -16,
      "y": 49,
      "z": 16,
      "name": "Plant_Leaves_Beech_Max_Support"
    },
    {
      "x": -16,
      "y": 50,
      "z": 16,
      "name": "Plant_Leaves_Beech_Max_Support"
    },
    {
      "x": -16,
      "y": 51,
      "z": 16,
      "name": "Plant_Leaves_Beech_Max_Support"
    },
    {
      "x": -16,
      "y": 50,
      "z": 17,
      "name": "Plant_Leaves_Beech_Max_Support"
    },
    {
      "x": -16,
      "y": 51,
      "z": 17,
      "name": "Plant_Leaves_Beech_Max_Support"
    },
    {
      "x": -16,
      "y": 50,
      "z": 18,
      "name": "Plant_Leaves_Beech_Max_Support"
    },
    {
      "x": -16,
      "y": 53,
      "z": 19,
      "name": "Plant_Leaves_Beech_Max_Support"
    },
    {
      "x": -16,
      "y": 54,
      "z": 19,
      "name": "Plant_Leaves_Beech_Max_Support"
    },
    {
      "x": -16,
      "y": 53,
      "z": 21,
      "name": "Plant_Leaves_Beech_Max_Support"
    },
    {
      "x": -15,
      "y": 61,
      "z": -13,
      "name": "Plant_Leaves_Beech_Max_Support"
    },
    {
      "x": -15,
      "y": 60,
      "z": -12,
      "name": "Plant_Leaves_Beech_Max_Support"
    },
    {
      "x": -15,
      "y": 61,
      "z": -12,
      "name": "Plant_Leaves_Beech_Max_Support"
    },
    {
      "x": -15,
      "y": 61,
      "z": -11,
      "name": "Plant_Leaves_Beech_Max_Support"
    },
    {
      "x": -15,
      "y": 71,
      "z": -11,
      "name": "Plant_Leaves_Beech_Max_Support",
      "support": 15
    },
    {
      "x": -15,
      "y": 72,
      "z": -11,
      "name": "Plant_Leaves_Beech_Max_Support",
      "support": 15
    },
    {
      "x": -15,
      "y": 73,
      "z": -11,
      "name": "Plant_Leaves_Beech_Max_Support"
    },
    {
      "x": -15,
      "y": 74,
      "z": -11,
      "name": "Plant_Leaves_Beech_Max_Support"
    },
    {
      "x": -15,
      "y": 10,
      "z": -10,
      "name": "Wood_Gumboab_Trunk_Full"
    },
    {
      "x": -15,
      "y": 11,
      "z": -10,
      "name": "Wood_Gumboab_Trunk_Full"
    },
    {
      "x": -15,
      "y": 71,
      "z": -10,
      "name": "Plant_Leaves_Beech_Max_Support",
      "support": 15
    },
    {
      "x": -15,
      "y": 72,
      "z": -10,
      "name": "Plant_Leaves_Beech_Max_Support"
    },
    {
      "x": -15,
      "y": 73,
      "z": -10,
      "name": "Plant_Leaves_Beech_Max_Support",
      "support": 15
    },
    {
      "x": -15,
      "y": 74,
      "z": -10,
      "name": "Plant_Leaves_Beech_Max_Support"
    },
    {
      "x": -15,
      "y": 75,
      "z": -10,
      "name": "Plant_Leaves_Beech_Max_Support"
    },
    {
      "x": -15,
      "y": 10,
      "z": -9,
      "name": "Wood_Gumboab_Trunk_Full"
    },
    {
      "x": -15,
      "y": 11,
      "z": -9,
      "name": "Wood_Gumboab_Trunk_Full"
    },
    {
      "x": -15,
      "y": 12,
      "z": -9,
      "name": "Wood_Gumboab_Trunk_Full"
    },
    {
      "x": -15,
      "y": 13,
      "z": -9,
      "name": "Wood_Gumboab_Trunk_Full"
    },
    {
      "x": -15,
      "y": 72,
      "z": -9,
      "name": "Plant_Leaves_Beech_Max_Support",
      "support": 15
    },
    {
      "x": -15,
      "y": 73,
      "z": -9,
      "name": "Plant_Leaves_Beech_Max_Support"
    },
    {
      "x": -15,
      "y": 74,
      "z": -9,
      "name": "Plant_Leaves_Beech_Max_Support"
    },
    {
      "x": -15,
      "y": 76,
      "z": -9,
      "name": "Plant_Leaves_Beech_Max_Support"
    },
    {
      "x": -15,
      "y": 11,
      "z": -8,
      "name": "Wood_Gumboab_Trunk_Full"
    },
    {
      "x": -15,
      "y": 12,
      "z": -8,
      "name": "Wood_Gumboab_Trunk_Full"
    },
    {
      "x": -15,
      "y": 71,
      "z": -8,
      "name": "Plant_Leaves_Beech_Max_Support"
    },
    {
      "x": -15,
      "y": 72,
      "z": -8,
      "name": "Plant_Leaves_Beech_Max_Support"
    },
    {
