{
  "version": 8,
  "blockIdVersion": 11,
  "anchorX": -5,
  "anchorY": 14,
  "anchorZ": -1,
  "blocks": [
    {
      "x": -19,
      "y": 60,
      "z": 0,
      "name": "Plant_Leaves_Beech_Max_Support"
    },
    {
      "x": -19,
      "y": 59,
      "z": 1,
      "name": "Plant_Leaves_Beech_Max_Support"
    },
    {
      "x": -19,
      "y": 60,
      "z": 1,
      "name": "Plant_Leaves_Beech_Max_Support"
    },
    {
      "x": -19,
      "y": 61,
      "z": 1,
      "name": "Plant_Leaves_Beech_Max_Support"
    },
    {
      "x": -19,
      "y": 61,
      "z": 2,
      "name": "Plant_Leaves_Beech_Max_Support"
    },
    {
      "x": -19,
      "y": 61,
      "z": 3,
      "name": "Plant_Leaves_Beech_Max_Support"
    },
    {
      "x": -18,
      "y": 60,
      "z": -2,
      "name": "Plant_Leaves_Beech_Max_Support"
    },
    {
      "x": -18,
      "y": 59,
      "z": -1,
      "name": "Plant_Leaves_Beech_Max_Support"
    },
    {
      "x": -18,
      "y": 60,
      "z": -1,
      "name": "Plant_Leaves_Beech_Max_Support"
    },
    {
      "x": -18,
      "y": 61,
      "z": -1,
      "name": "Plant_Leaves_Beech_Max_Support"
    },
    {
      "x": -18,
      "y": 59,
      "z": 0,
      "name": "Plant_Leaves_Beech_Max_Support"
    },
    {
      "x": -18,
      "y": 60,
      "z": 0,
      "name": "Plant_Leaves_Beech_Max_Support"
    },
    {
      "x": -18,
      "y": 61,
      "z": 0,
      "name": "Plant_Leaves_Beech_Max_Support"
    },
    {
      "x": -18,
      "y": 60,
      "z": 1,
      "name": "Plant_Leaves_Beech_Max_Support"
    },
    {
      "x": -18,
      "y": 61,
      "z": 1,
      "name": "Plant_Leaves_Beech_Max_Support"
    },
    {
      "x": -18,
      "y": 59,
      "z": 2,
      "name": "Plant_Leaves_Beech_Max_Support"
    },
    {
      "x": -18,
      "y": 61,
      "z": 2,
      "name": "Plant_Leaves_Beech_Max_Support"
    },
    {
      "x": -18,
      "y": 62,
      "z": 2,
      "name": "Plant_Leaves_Beech_Max_Support"
    },
    {
      "x": -18,
      "y": 60,
      "z": 3,
      "name": "Plant_Leaves_Beech_Max_Support"
    },
    {
      "x": -18,
      "y": 62,
      "z": 3,
      "name": "Plant_Leaves_Beech_Max_Support"
    },
    {
      "x": -18,
      "y": 61,
      "z": 4,
      "name": "Plant_Leaves_Beech_Max_Support"
    },
    {
      "x": -18,
      "y": 62,
      "z": 4,
      "name": "Plant_Leaves_Beech_Max_Support"
    },
    {
      "x": -17,
      "y": 59,
      "z": -1,
      "name": "Plant_Leaves_Beech_Max_Support"
    },
    {
      "x": -17,
      "y": 60,
      "z": -1,
      "name": "Plant_Leaves_Beech_Max_Support"
    },
    {
      "x": -17,
      "y": 61,
      "z": -1,
      "name": "Plant_Leaves_Beech_Max_Support"
    },
    {
      "x": -17,
      "y": 63,
      "z": -1,
      "name": "Plant_Leaves_Beech_Max_Support"
    },
    {
      "x": -17,
      "y": 58,
      "z": 0,
      "name": "Plant_Leaves_Beech_Max_Support"
    },
    {
      "x": -17,
      "y": 59,
      "z": 0,
      "name": "Plant_Leaves_Beech_Max_Support"
    },
    {
      "x": -17,
      "y": 60,
      "z": 0,
      "name": "Plant_Leaves_Beech_Max_Support"
    },
    {
      "x": -17,
      "y": 61,
      "z": 0,
      "name": "Plant_Leaves_Beech_Max_Support"
    },
    {
      "x": -17,
      "y": 62,
      "z": 0,
      "name": "Plant_Leaves_Beech_Max_Support"
    },
    {
      "x": -17,
      "y": 59,
      "z": 1,
      "name": "Plant_Leaves_Beech_Max_Support"
    },
    {
      "x": -17,
      "y": 60,
      "z": 1,
      "name": "Plant_Leaves_Beech_Max_Support"
    },
    {
      "x": -17,
      "y": 62,
      "z": 1,
      "name": "Plant_Leaves_Beech_Max_Support"
    },
    {
      "x": -17,
      "y": 61,
      "z": 2,
      "name": "Plant_Leaves_Beech_Max_Support"
    },
    {
      "x": -17,
      "y": 62,
      "z": 2,
      "name": "Plant_Leaves_Beech_Max_Support"
    },
    {
      "x": -17,
      "y": 59,
      "z": 3,
      "name": "Plant_Leaves_Beech_Max_Support"
    },
    {
      "x": -17,
      "y": 62,
      "z": 3,
      "name": "Plant_Leaves_Beech_Max_Support"
    },
    {
      "x": -17,
      "y": 60,
      "z": 4,
      "name": "Plant_Leaves_Beech_Max_Support"
    },
    {
      "x": -17,
      "y": 61,
      "z": 4,
      "name": "Plant_Leaves_Beech_Max_Support"
    },
    {
      "x": -17,
      "y": 32,
      "z": 5,
      "name": "Plant_Leaves_Beech_Max_Support"
    },
    {
      "x": -17,
      "y": 33,
      "z": 5,
      "name": "Plant_Leaves_Beech_Max_Support"
    },
    {
      "x": -17,
      "y": 62,
      "z": 5,
      "name": "Plant_Leaves_Beech_Max_Support"
    },
    {
      "x": -17,
      "y": 63,
      "z": 5,
      "name": "Plant_Leaves_Beech_Max_Support"
    },
    {
      "x": -17,
      "y": 33,
      "z": 6,
      "name": "Plant_Leaves_Beech_Max_Support"
    },
    {
      "x": -17,
      "y": 32,
      "z": 10,
      "name": "Plant_Leaves_Beech_Max_Support"
    },
    {
      "x": -17,
      "y": 32,
      "z": 11,
      "name": "Plant_Leaves_Beech_Max_Support"
    },
    {
      "x": -17,
      "y": 33,
      "z": 11,
      "name": "Plant_Leaves_Beech_Max_Support"
    },
    {
      "x": -17,
      "y": 32,
      "z": 12,
      "name": "Plant_Leaves_Beech_Max_Support"
    },
    {
      "x": -16,
      "y": 4,
      "z": -4,
      "name": "Wood_Gumboab_Roots"
    },
    {
      "x": -16,
      "y": 5,
      "z": -4,
      "name": "Wood_Gumboab_Trunk_Full"
    },
    {
      "x": -16,
      "y": 6,
      "z": -4,
      "name": "Wood_Gumboab_Trunk_Full"
    },
    {
      "x": -16,
      "y": 7,
      "z": -4,
      "name": "Wood_Gumboab_Trunk_Full"
    },
    {
      "x": -16,
      "y": 59,
      "z": -3,
      "name": "Plant_Leaves_Beech_Max_Support"
    },
    {
      "x": -16,
      "y": 61,
      "z": -3,
      "name": "Plant_Leaves_Beech_Max_Support"
    },
    {
      "x": -16,
      "y": 58,
      "z": -2,
      "name": "Plant_Leaves_Beech_Max_Support"
    },
    {
      "x": -16,
      "y": 60,
      "z": -2,
      "name": "Plant_Leaves_Beech_Max_Support"
    },
    {
      "x": -16,
      "y": 61,
      "z": -2,
      "name": "Plant_Leaves_Beech_Max_Support"
    },
    {
      "x": -16,
      "y": 62,
      "z": -2,
      "name": "Plant_Leaves_Beech_Max_Support"
    },
    {
      "x": -16,
      "y": 58,
      "z": -1,
      "name": "Plant_Leaves_Beech_Max_Support"
    },
    {
      "x": -16,
      "y": 59,
      "z": -1,
      "name": "Plant_Leaves_Beech_Max_Support"
    },
    {
      "x": -16,
      "y": 60,
      "z": -1,
      "name": "Plant_Leaves_Beech_Max_Support"
    },
    {
      "x": -16,
      "y": 61,
      "z": -1,
      "name": "Plant_Leaves_Beech_Max_Support"
    },
    {
      "x": -16,
      "y": 62,
      "z": -1,
      "name": "Plant_Leaves_Beech_Max_Support"
    },
    {
      "x": -16,
      "y": 63,
      "z": -1,
      "name": "Plant_Leaves_Beech_Max_Support"
    },
    {
      "x": -16,
      "y": 59,
      "z": 0,
      "name": "Plant_Leaves_Beech_Max_Support"
    },
    {
      "x": -16,
      "y": 60,
      "z": 0,
      "name": "Plant_Leaves_Beech_Max_Support"
    },
    {
      "x": -16,
      "y": 61,
      "z": 0,
      "name": "Plant_Leaves_Beech_Max_Support"
    },
    {
      "x": -16,
      "y": 62,
      "z": 0,
      "name": "Plant_Leaves_Beech_Max_Support"
    },
    {
      "x": -16,
      "y": 63,
      "z": 0,
      "name": "Plant_Leaves_Beech_Max_Support"
    },
    {
      "x": -16,
      "y": 58,
      "z": 1,
      "name": "Plant_Leaves_Beech_Max_Support"
    },
    {
      "x": -16,
      "y": 59,
      "z": 1,
      "name": "Plant_Leaves_Beech_Max_Support"
    },
    {
      "x": -16,
      "y": 60,
      "z": 1,
      "name": "Plant_Leaves_Beech_Max_Support"
    },
    {
      "x": -16,
      "y": 62,
      "z": 1,
      "name": "Plant_Leaves_Beech_Max_Support"
    },
    {
      "x": -16,
      "y": 63,
      "z": 1,
      "name": "Plant_Leaves_Beech_Max_Support"
    },
    {
      "x": -16,
      "y": 64,
      "z": 1,
      "name": "Plant_Leaves_Beech_Max_Support"
    },
    {
      "x": -16,
      "y": 3,
      "z": 2,
      "name": "Wood_Gumboab_Trunk_Full"
    },
    {
      "x": -16,
      "y": 59,
      "z": 2,
      "name": "Plant_Leaves_Beech_Max_Support"
    },
    {
      "x": -16,
      "y": 60,
      "z": 2,
      "name": "Plant_Leaves_Beech_Max_Support"
    },
    {
      "x": -16,
      "y": 61,
      "z": 2,
      "name": "Plant_Leaves_Beech_Max_Support"
    },
    {
      "x": -16,
      "y": 62,
      "z": 2,
      "name": "Plant_Leaves_Beech_Max_Support"
    },
    {
      "x": -16,
      "y": 63,
      "z": 2,
      "name": "Plant_Leaves_Beech_Max_Support"
    },
    {
      "x": -16,
      "y": 59,
      "z": 3,
      "name": "Plant_Leaves_Beech_Max_Support"
    },
    {
      "x": -16,
      "y": 60,
      "z": 3,
      "name": "Plant_Leaves_Beech_Max_Support"
    },
    {
      "x": -16,
      "y": 61,
      "z": 3,
      "name": "Plant_Leaves_Beech_Max_Support"
    },
    {
      "x": -16,
      "y": 63,
      "z": 3,
      "name": "Plant_Leaves_Beech_Max_Support"
    },
    {
      "x": -16,
      "y": 64,
      "z": 3,
      "name": "Plant_Leaves_Beech_Max_Support"
    },
    {
      "x": -16,
      "y": 32,
      "z": 4,
      "name": "Plant_Leaves_Beech_Max_Support"
    },
    {
      "x": -16,
      "y": 34,
      "z": 4,
      "name": "Plant_Leaves_Beech_Max_Support"
    },
    {
      "x": -16,
      "y": 36,
      "z": 4,
      "name": "Plant_Leaves_Beech_Max_Support"
    },
    {
      "x": -16,
      "y": 63,
      "z": 4,
      "name": "Plant_Leaves_Beech_Max_Support"
    },
    {
      "x": -16,
      "y": 31,
      "z": 5,
      "name": "Plant_Leaves_Beech_Max_Support"
    },
    {
      "x": -16,
      "y": 33,
      "z": 5,
      "name": "Plant_Leaves_Beech_Max_Support"
    },
    {
      "x": -16,
      "y": 34,
      "z": 5,
      "name": "Plant_Leaves_Beech_Max_Support"
    },
    {
      "x": -16,
      "y": 35,
      "z": 5,
      "name": "Plant_Leaves_Beech_Max_Support"
    },
    {
      "x": -16,
      "y": 63,
      "z": 5,
      "name": "Plant_Leaves_Beech_Max_Support"
    },
    {
      "x": -16,
      "y": 32,
      "z": 6,
      "name": "Plant_Leaves_Beech_Max_Support"
    },
    {
      "x": -16,
      "y": 33,
      "z": 6,
      "name": "Plant_Leaves_Beech_Max_Support"
    },
    {
      "x": -16,
      "y": 34,
      "z": 6,
      "name": "Plant_Leaves_Beech_Max_Support"
    },
    {
      "x": -16,
      "y": 35,
      "z": 6,
      "name": "Plant_Leaves_Beech_Max_Support"
    },
    {
      "x": -16,
      "y": 36,
      "z": 6,
      "name": "Plant_Leaves_Beech_Max_Support"
    },
    {
      "x": -16,
      "y": 60,
      "z": 6,
      "name": "Plant_Leaves_Beech_Max_Support"
    },
    {
      "x": -16,
      "y": 61,
      "z": 6,
      "name": "Plant_Leaves_Beech_Max_Support"
    },
    {
      "x": -16,
      "y": 33,
      "z": 7,
      "name": "Plant_Leaves_Beech_Max_Support"
    },
    {
      "x": -16,
      "y": 33,
      "z": 8,
      "name": "Plant_Leaves_Beech_Max_Support"
    },
    {
      "x": -16,
      "y": 34,
      "z": 8,
      "name": "Plant_Leaves_Beech_Max_Support"
    },
    {
      "x": -16,
      "y": 35,
      "z": 9,
      "name": "Plant_Leaves_Beech_Max_Support"
    },
    {
      "x": -16,
      "y": 36,
      "z": 9,
      "name": "Plant_Leaves_Beech_Max_Support"
    },
    {
      "x": -16,
      "y": 31,
      "z": 10,
      "name": "Plant_Leaves_Beech_Max_Support"
    },
    {
      "x": -16,
      "y": 33,
      "z": 10,
      "name": "Plant_Leaves_Beech_Max_Support"
    },
    {
      "x": -16,
      "y": 34,
      "z": 10,
      "name": "Plant_Leaves_Beech_Max_Support"
    },
    {
      "x": -16,
      "y": 35,
      "z": 10,
      "name": "Plant_Leaves_Beech_Max_Support"
    },
    {
      "x": -16,
      "y": 31,
      "z": 11,
      "name": "Plant_Leaves_Beech_Max_Support"
    },
    {
      "x": -16,
      "y": 32,
      "z": 11,
      "name": "Plant_Leaves_Beech_Max_Support"
    },
    {
      "x": -16,
      "y": 33,
      "z": 11,
      "name": "Plant_Leaves_Beech_Max_Support"
    },
    {
      "x": -16,
      "y": 33,
      "z": 12,
      "name": "Plant_Leaves_Beech_Max_Support"
    },
    {
      "x": -15,
      "y": 6,
      "z": -5,
      "name": "Wood_Gumboab_Trunk_Full"
    },
    {
      "x": -15,
      "y": 6,
      "z": -4,
      "name": "Wood_Gumboab_Trunk_Full"
    },
    {
      "x": -15,
      "y": 7,
      "z": -4,
      "name": "Wood_Gumboab_Trunk_Full"
    },
    {
      "x": -15,
      "y": 8,
      "z": -4,
      "name": "Wood_Gumboab_Trunk_Full"
    },
    {
      "x": -15,
      "y": 7,
      "z": -3,
      "name": "Wood_Gumboab_Trunk_Full"
    },
    {
      "x": -15,
      "y": 8,
      "z": -3,
      "name": "Wood_Gumboab_Trunk_Full"
    },
    {
      "x": -15,
      "y": 60,
      "z": -3,
      "name": "Plant_Leaves_Beech_Max_Support"
    },
    {
      "x": -15,
      "y": 60,
      "z": -2,
      "name": "Plant_Leaves_Beech_Max_Support"
    },
    {
      "x": -15,
      "y": 61,
      "z": -2,
      "name": "Plant_Leaves_Beech_Max_Support"
    },
    {
      "x": -15,
      "y": 58,
      "z": -1,
      "name": "Plant_Leaves_Beech_Max_Support"
    },
    {
      "x": -15,
      "y": 59,
      "z": -1,
      "name": "Plant_Leaves_Beech_Max_Support"
    },
    {
      "x": -15,
      "y": 60,
      "z": -1,
      "name": "Plant_Leaves_Beech_Max_Support"
    },
    {
      "x": -15,
      "y": 61,
      "z": -1,
      "name": "Plant_Leaves_Beech_Max_Support"
    },
    {
      "x": -15,
      "y": 62,
      "z": -1,
      "name": "Plant_Leaves_Beech_Max_Support"
    },
    {
      "x": -15,
      "y": 63,
      "z": -1,
      "name": "Plant_Leaves_Beech_Max_Support"
    },
    {
      "x": -15,
      "y": 59,
      "z": 0,
      "name": "Plant_Leaves_Beech_Max_Support"
    },
    {
      "x": -15,
      "y": 60,
      "z": 0,
      "name": "Plant_Leaves_Beech_Max_Support"
    },
    {
      "x": -15,
      "y": 61,
      "z": 0,
      "name": "Plant_Leaves_Beech_Max_Support"
    },
    {
      "x": -15,
      "y": 62,
      "z": 0,
      "name": "Plant_Leaves_Beech_Max_Support"
    },
    {
      "x": -15,
      "y": 64,
      "z": 0,
      "name": "Plant_Leaves_Beech_Max_Support"
    },
    {
      "x": -15,
      "y": 2,
      "z": 1,
      "name": "Wood_Gumboab_Roots"
    },
    {
      "x": -15,
      "y": 3,
      "z": 1,
      "name": "Wood_Gumboab_Trunk_Full"
    },
    {
      "x": -15,
      "y": 59,
      "z": 1,
      "name": "Plant_Leaves_Beech_Max_Support"
    },
    {
      "x": -15,
      "y": 60,
      "z": 1,
      "name": "Plant_Leaves_Beech_Max_Support"
    },
    {
      "x": -15,
      "y": 61,
      "z": 1,
      "name": "Plant_Leaves_Beech_Max_Support"
    },
    {
      "x": -15,
      "y": 62,
      "z": 1,
      "name": "Plant_Leaves_Beech_Max_Support"
    },
    {
      "x": -15,
      "y": 63,
      "z": 1,
      "name": "Plant_Leaves_Beech_Max_Support"
    },
    {
      "x": -15,
      "y": 64,
      "z": 1,
      "name": "Plant_Leaves_Beech_Max_Support"
    },
    {
      "x": -15,
      "y": 2,
      "z": 2,
      "name": "Wood_Gumboab_Roots"
    },
    {
      "x": -15,
      "y": 3,
      "z": 2,
      "name": "Wood_Gumboab_Trunk_Full"
    },
    {
      "x": -15,
      "y": 4,
      "z": 2,
      "name": "Wood_Gumboab_Trunk_Full"
    },
    {
      "x": -15,
      "y": 5,
      "z": 2,
      "name": "Wood_Gumboab_Trunk_Full"
    },
    {
      "x": -15,
      "y": 59,
      "z": 2,
      "name": "Plant_Leaves_Beech_Max_Support"
    },
    {
      "x": -15,
      "y": 60,
      "z": 2,
      "name": "Plant_Leaves_Beech_Max_Support"
    },
    {
      "x": -15,
      "y": 61,
      "z": 2,
      "name": "Plant_Leaves_Beech_Max_Support"
    },
    {
      "x": -15,
      "y": 62,
      "z": 2,
      "name": "Plant_Leaves_Beech_Max_Support"
    },
    {
      "x": -15,
      "y": 63,
      "z": 2,
      "name": "Plant_Leaves_Beech_Max_Support"
    },
    {
      "x": -15,
      "y": 4,
      "z": 3,
      "name": "Wood_Gumboab_Trunk_Full"
    },
    {
      "x": -15,
      "y": 5,
      "z": 3,
      "name": "Wood_Gumboab_Trunk_Full"
    },
    {
      "x": -15,
      "y": 32,
      "z": 3,
      "name": "Plant_Leaves_Beech_Max_Support"
    },
    {
      "x": -15,
      "y": 33,
      "z": 3,
      "name": "Plant_Leaves_Beech_Max_Support"
    },
    {
      "x": -15,
      "y": 34,
      "z": 3,
      "name": "Plant_Leaves_Beech_Max_Support"
    },
    {
      "x": -15,
      "y": 36,
      "z": 3,
      "name": "Plant_Leaves_Beech_Max_Support"
    },
    {
      "x": -15,
      "y": 59,
      "z": 3,
      "name": "Plant_Leaves_Beech_Max_Support"
    },
    {
      "x": -15,
      "y": 61,
      "z": 3,
      "name": "Plant_Leaves_Beech_Max_Support"
    },
    {
      "x": -15,
      "y": 62,
      "z": 3,
      "name": "Plant_Leaves_Beech_Max_Support"
    },
    {
      "x": -15,
      "y": 64,
      "z": 3,
      "name": "Plant_Leaves_Beech_Max_Support"
    },
    {
      "x": -15,
      "y": 32,
      "z": 4,
      "name": "Plant_Leaves_Beech_Max_Support"
    },
    {
      "x": -15,
      "y": 33,
      "z": 4,
      "name": "Plant_Leaves_Beech_Max_Support"
    },
    {
      "x": -15,
      "y": 34,
      "z": 4,
      "name": "Plant_Leaves_Beech_Max_Support"
    },
    {
      "x": -15,
      "y": 35,
      "z": 4,
      "name": "Plant_Leaves_Beech_Max_Support"
    },
    {
      "x": -15,
      "y": 36,
      "z": 4,
      "name": "Plant_Leaves_Beech_Max_Support"
    },
    {
      "x": -15,
      "y": 37,
      "z": 4,
      "name": "Plant_Leaves_Beech_Max_Support"
    },
    {
      "x": -15,
      "y": 61,
      "z": 4,
      "name": "Plant_Leaves_Beech_Max_Support"
    },
    {
      "x": -15,
      "y": 63,
      "z": 4,
      "name": "Plant_Leaves_Beech_Max_Support"
    },
    {
      "x": -15,
      "y": 31,
      "z": 5,
      "name": "Plant_Leaves_Beech_Max_Support"
    },
    {
      "x": -15,
      "y": 32,
      "z": 5,
      "name": "Plant_Leaves_Beech_Max_Support"
    },
    {
      "x": -15,
      "y": 33,
      "z": 5,
      "name": "Plant_Leaves_Beech_Max_Support"
    },
    {
      "x": -15,
      "y": 34,
      "z": 5,
      "name": "Plant_Leaves_Beech_Max_Support"
    },
    {
      "x": -15,
      "y": 35,
      "z": 5,
      "name": "Plant_Leaves_Beech_Max_Support"
    },
    {
      "x": -15,
      "y": 37,
      "z": 5,
      "name": "Plant_Leaves_Beech_Max_Support"
    },
    {
      "x": -15,
      "y": 60,
      "z": 5,
      "name": "Plant_Leaves_Beech_Max_Support"
    },
    {
      "x": -15,
      "y": 62,
      "z": 5,
      "name": "Plant_Leaves_Beech_Max_Support"
    },
    {
      "x": -15,
      "y": 63,
      "z": 5,
      "name": "Plant_Leaves_Beech_Max_Support"
    },
    {
      "x": -15,
      "y": 33,
      "z": 6,
      "name": "Plant_Leaves_Beech_Max_Support"
    },
    {
      "x": -15,
      "y": 34,
      "z": 6,
      "name": "Plant_Leaves_Beech_Max_Support"
    },
    {
      "x": -15,
      "y": 36,
      "z": 6,
      "name": "Plant_Leaves_Beech_Max_Support"
    },
    {
      "x": -15,
      "y": 37,
      "z": 6,
      "name": "Plant_Leaves_Beech_Max_Support"
    },
    {
      "x": -15,
      "y": 38,
      "z": 6,
      "name": "Plant_Leaves_Beech_Max_Support"
    },
    {
      "x": -15,
      "y": 59,
      "z": 6,
      "name": "Plant_Leaves_Beech_Max_Support"
    },
    {
      "x": -15,
      "y": 61,
      "z": 6,
      "name": "Plant_Leaves_Beech_Max_Support"
    },
    {
      "x": -15,
      "y": 62,
      "z": 6,
      "name": "Plant_Leaves_Beech_Max_Support"
    },
    {
      "x": -15,
      "y": 32,
      "z": 7,
      "name": "Plant_Leaves_Beech_Max_Support"
    },
    {
      "x": -15,
      "y": 33,
      "z": 7,
      "name": "Plant_Leaves_Beech_Max_Support"
    },
    {
      "x": -15,
      "y": 34,
      "z": 7,
      "name": "Plant_Leaves_Beech_Max_Support"
    },
    {
      "x": -15,
      "y": 35,
      "z": 7,
      "name": "Plant_Leaves_Beech_Max_Support"
    },
    {
      "x": -15,
      "y": 36,
      "z": 7,
      "name": "Plant_Leaves_Beech_Max_Support"
    },
    {
      "x": -15,
      "y": 37,
      "z": 7,
      "name": "Plant_Leaves_Beech_Max_Support"
    },
    {
      "x": -15,
      "y": 61,
      "z": 7,
      "name": "Plant_Leaves_Beech_Max_Support"
    },
    {
      "x": -15,
      "y": 62,
      "z": 7,
      "name": "Plant_Leaves_Beech_Max_Support"
    },
    {
      "x": -15,
      "y": 32,
      "z": 8,
      "name": "Plant_Leaves_Beech_Max_Support"
    },
    {
      "x": -15,
      "y": 33,
      "z": 8,
      "name": "Plant_Leaves_Beech_Max_Support"
    },
    {
      "x": -15,
      "y": 34,
      "z": 8,
      "name": "Plant_Leaves_Beech_Max_Support"
    },
    {
      "x": -15,
      "y": 35,
      "z": 8,
      "name": "Plant_Leaves_Beech_Max_Support"
    },
    {
      "x": -15,
      "y": 36,
      "z": 8,
      "name": "Plant_Leaves_Beech_Max_Support"
    },
    {
      "x": -15,
      "y": 37,
      "z": 8,
      "name": "Plant_Leaves_Beech_Max_Support"
    },
    {
      "x": -15,
      "y": 61,
      "z": 8,
      "name": "Plant_Leaves_Beech_Max_Support"
    },
    {
      "x": -15,
      "y": 32,
      "z": 9,
      "name": "Plant_Leaves_Beech_Max_Support"
    },
    {
      "x": -15,
      "y": 33,
      "z": 9,
      "name": "Plant_Leaves_Beech_Max_Support"
    },
    {
      "x": -15,
      "y": 34,
      "z": 9,
      "name": "Plant_Leaves_Beech_Max_Support"
    },
    {
      "x": -15,
      "y": 35,
      "z": 9,
      "name": "Plant_Leaves_Beech_Max_Support"
    },
    {
      "x": -15,
      "y": 37,
      "z": 9,
      "name": "Plant_Leaves_Beech_Max_Support"
    },
    {
      "x": -15,
      "y": 32,
      "z": 10,
      "name": "Plant_Leaves_Beech_Max_Support"
    },
    {
      "x": -15,
      "y": 33,
      "z": 10,
      "name": "Plant_Leaves_Beech_Max_Support"
    },
    {
      "x": -15,
      "y": 34,
      "z": 10,
      "name": "Plant_Leaves_Beech_Max_Support"
    },
    {
      "x": -15,
      "y": 35,
      "z": 10,
      "name": "Plant_Leaves_Beech_Max_Support"
    },
    {
      "x": -15,
      "y": 36,
      "z": 10,
      "name": "Plant_Leaves_Beech_Max_Support"
    },
    {
      "x": -15,
      "y": 37,
      "z": 10,
      "name": "Plant_Leaves_Beech_Max_Support"
    },
    {
      "x": -15,
      "y": 31,
      "z": 11,
      "name": "Plant_Leaves_Beech_Max_Support"
    },
    {
      "x": -15,
      "y": 32,
      "z": 11,
      "name": "Plant_Leaves_Beech_Max_Support"
    },
    {
      "x": -15,
      "y": 33,
      "z": 11,
      "name": "Plant_Leaves_Beech_Max_Support"
    },
    {
      "x": -15,
      "y": 34,
      "z": 11,
      "name": "Plant_Leaves_Beech_Max_Support"
    },
    {
      "x": -15,
      "y": 32,
      "z": 12,
      "name": "Plant_Leaves_Beech_Max_Support"
    },
    {
      "x": -15,
      "y": 33,
      "z": 12,
      "name": "Plant_Leaves_Beech_Max_Support"
    },
    {
      "x": -14,
      "y": 59,
      "z": -5,
      "name": "Plant_Leaves_Beech_Max_Support"
    },
    {
      "x": -14,
      "y": 60,
      "z": -5,
      "name": "Plant_Leaves_Beech_Max_Support"
    },
    {
      "x": -14,
      "y": 7,
      "z": -4,
      "name": "Wood_Gumboab_Trunk_Full"
    },
    {
      "x": -14,
      "y": 8,
      "z": -4,
      "name": "Wood_Gumboab_Trunk_Full"
    },
    {
      "x": -14,
      "y": 59,
      "z": -4,
      "name": "Plant_Leaves_Beech_Max_Support"
    },
    {
      "x": -14,
      "y": 60,
      "z": -4,
      "name": "Plant_Leaves_Beech_Max_Support"
    },
    {
      "x": -14,
      "y": 7,
      "z": -3,
      "name": "Wood_Gumboab_Trunk_Full"
    },
    {
      "x": -14,
      "y": 8,
      "z": -3,
      "name": "Wood_Gumboab_Trunk_Full"
    },
    {
      "x": -14,
      "y": 9,
      "z": -3,
      "name": "Wood_Gumboab_Trunk_Full"
    },
    {
      "x": -14,
      "y": 59,
      "z": -3,
      "name": "Plant_Leaves_Beech_Max_Support"
    },
    {
      "x": -14,
      "y": 60,
      "z": -3,
      "name": "Plant_Leaves_Beech_Max_Support"
    },
    {
      "x": -14,
      "y": 61,
      "z": -3,
      "name": "Plant_Leaves_Beech_Max_Support"
    },
    {
      "x": -14,
      "y": 7,
      "z": -2,
      "name": "Wood_Gumboab_Trunk_Full"
    },
    {
      "x": -14,
      "y": 8,
      "z": -2,
      "name": "Wood_Gumboab_Trunk_Full"
    },
    {
      "x": -14,
      "y": 9,
      "z": -2,
      "name": "Wood_Gumboab_Trunk_Full"
    },
    {
      "x": -14,
      "y": 10,
      "z": -2,
      "name": "Wood_Gumboab_Trunk_Full"
    },
    {
      "x": -14,
      "y": 61,
      "z": -2,
      "name": "Plant_Leaves_Beech_Max_Support"
    },
    {
      "x": -14,
      "y": 63,
      "z": -2,
      "name": "Plant_Leaves_Beech_Max_Support"
    },
    {
      "x": -14,
      "y": 9,
      "z": -1,
      "name": "Wood_Gumboab_Trunk_Full"
    },
    {
      "x": -14,
      "y": 10,
      "z": -1,
      "name": "Wood_Gumboab_Trunk_Full"
    },
    {
      "x": -14,
      "y": 59,
      "z": -1,
      "name": "Plant_Leaves_Beech_Max_Support"
    },
    {
      "x": -14,
      "y": 60,
      "z": -1,
      "name": "Plant_Leaves_Beech_Max_Support"
    },
    {
      "x": -14,
      "y": 63,
      "z": -1,
      "name": "Plant_Leaves_Beech_Max_Support"
    },
    {
      "x": -14,
      "y": 10,
      "z": 0,
      "name": "Wood_Gumboab_Trunk_Full"
    },
    {
      "x": -14,
      "y": 58,
      "z": 0,
      "name": "Wood_Gumboab_Branch_Corner",
      "support": 15,
      "rotation": 3
    },
    {
      "x": -14,
      "y": 59,
      "z": 0,
      "name": "Wood_Gumboab_Branch_Long",
      "support": 15
    },
    {
      "x": -14,
      "y": 60,
      "z": 0,
      "name": "Plant_Leaves_Beech_Max_Support"
    },
    {
      "x": -14,
      "y": 62,
      "z": 0,
      "name": "Plant_Leaves_Beech_Max_Support"
    },
    {
      "x": -14,
      "y": 65,
      "z": 0,
      "name": "Plant_Leaves_Beech_Max_Support"
    },
    {
      "x": -14,
      "y": 20,
      "z": 1,
      "name": "Plant_Vine_Jungle",
      "support": 15,
      "rotation": 3
    },
    {
      "x": -14,
      "y": 21,
      "z": 1,
      "name": "Plant_Vine_Jungle",
      "support": 15,
      "rotation": 3
    },
    {
      "x": -14,
      "y": 22,
      "z": 1,
      "name": "Plant_Vine_Jungle",
      "support": 15,
      "rotation": 3
    },
    {
      "x": -14,
      "y": 23,
      "z": 1,
      "name": "Plant_Vine_Jungle",
      "support": 15,
      "rotation": 3
    },
    {
      "x": -14,
      "y": 24,
      "z": 1,
      "name": "Plant_Vine_Jungle",
      "support": 15,
      "rotation": 3
    },
    {
      "x": -14,
      "y": 25,
      "z": 1,
      "name": "Plant_Vine_Jungle",
      "support": 15,
      "rotation": 3
    },
    {
      "x": -14,
      "y": 26,
      "z": 1,
      "name": "Plant_Vine_Jungle",
      "support": 15,
      "rotation": 3
    },
    {
      "x": -14,
      "y": 27,
      "z": 1,
      "name": "Plant_Vine_Jungle",
      "support": 15,
      "rotation": 3
    },
    {
      "x": -14,
      "y": 28,
      "z": 1,
      "name": "Plant_Vine_Jungle",
      "support": 15,
      "rotation": 3
    },
    {
      "x": -14,
      "y": 29,
      "z": 1,
      "name": "Plant_Vine_Jungle",
      "support": 15,
      "rotation": 3
    },
    {
      "x": -14,
      "y": 30,
      "z": 1,
      "name": "Plant_Vine_Jungle",
      "support": 15,
      "rotation": 3
    },
    {
      "x": -14,
      "y": 31,
      "z": 1,
      "name": "Plant_Vine_Jungle",
      "support": 15,
      "rotation": 3
    },
    {
      "x": -14,
      "y": 32,
      "z": 1,
      "name": "Plant_Vine_Jungle",
      "support": 15,
      "rotation": 3
    },
    {
      "x": -14,
      "y": 33,
      "z": 1,
      "name": "Plant_Vine_Jungle",
      "support": 15,
      "rotation": 3
    },
    {
      "x": -14,
      "y": 34,
      "z": 1,
      "name": "Plant_Vine_Jungle",
      "support": 15,
      "rotation": 3
    },
    {
      "x": -14,
      "y": 35,
      "z": 1,
      "name": "Plant_Vine_Jungle",
      "support": 15,
      "rotation": 3
    },
    {
      "x": -14,
      "y": 36,
      "z": 1,
      "name": "Plant_Vine_Jungle",
      "support": 15,
      "rotation": 3
    },
    {
      "x": -14,
      "y": 37,
      "z": 1,
      "name": "Plant_Vine_Jungle",
      "support": 15,
      "rotation": 3
    },
    {
      "x": -14,
      "y": 38,
      "z": 1,
      "name": "Plant_Vine_Jungle",
      "support": 15,
      "rotation": 3
    },
    {
      "x": -14,
      "y": 39,
      "z": 1,
      "name": "Plant_Vine_Jungle",
      "support": 15,
      "rotation": 3
    },
    {
      "x": -14,
      "y": 40,
      "z": 1,
      "name": "Plant_Vine_Jungle",
      "support": 15,
      "rotation": 3
    },
    {
      "x": -14,
      "y": 41,
      "z": 1,
      "name": "Plant_Vine_Jungle",
      "support": 15,
      "rotation": 3
    },
    {
      "x": -14,
      "y": 42,
      "z": 1,
      "name": "Plant_Vine_Jungle",
      "support": 15,
      "rotation": 3
    },
    {
      "x": -14,
      "y": 43,
      "z": 1,
      "name": "Plant_Vine_Jungle",
      "support": 15,
      "rotation": 3
    },
    {
      "x": -14,
      "y": 44,
      "z": 1,
      "name": "Plant_Vine_Jungle",
      "support": 15,
      "rotation": 3
    },
    {
      "x": -14,
      "y": 45,
      "z": 1,
      "name": "Plant_Vine_Jungle",
      "support": 15,
      "rotation": 3
    },
    {
      "x": -14,
      "y": 46,
      "z": 1,
      "name": "Plant_Vine_Jungle",
      "support": 15,
      "rotation": 3
    },
    {
      "x": -14,
      "y": 47,
      "z": 1,
      "name": "Plant_Vine_Jungle",
      "support": 15,
      "rotation": 3
    },
    {
      "x": -14,
      "y": 48,
      "z": 1,
      "name": "Plant_Vine_Jungle",
      "support": 15,
      "rotation": 3
    },
    {
      "x": -14,
      "y": 49,
      "z": 1,
      "name": "Plant_Vine_Jungle",
      "support": 15,
      "rotation": 3
    },
    {
      "x": -14,
      "y": 50,
      "z": 1,
      "name": "Plant_Vine_Jungle",
      "support": 15,
      "rotation": 3
    },
    {
      "x": -14,
      "y": 51,
      "z": 1,
      "name": "Plant_Vine_Jungle",
      "support": 15,
      "rotation": 3
    },
    {
      "x": -14,
      "y": 52,
      "z": 1,
      "name": "Plant_Vine_Jungle",
      "support": 15,
      "rotation": 3
    },
    {
      "x": -14,
      "y": 53,
      "z": 1,
      "name": "Plant_Vine_Jungle",
      "support": 15,
      "rotation": 3
    },
    {
      "x": -14,
      "y": 54,
      "z": 1,
      "name": "Plant_Vine_Jungle",
      "support": 15,
      "rotation": 3
    },
    {
      "x": -14,
      "y": 55,
      "z": 1,
      "name": "Plant_Vine_Jungle",
      "support": 15,
      "rotation": 3
    },
    {
      "x": -14,
      "y": 56,
      "z": 1,
      "name": "Plant_Vine_Jungle",
      "support": 15,
      "rotation": 3
    },
    {
      "x": -14,
      "y": 57,
      "z": 1,
      "name": "Plant_Vine_Jungle",
      "support": 15,
      "rotation": 3
    },
    {
      "x": -14,
      "y": 58,
      "z": 1,
      "name": "Plant_Vine_Jungle",
      "support": 15,
      "rotation": 3
    },
    {
      "x": -14,
      "y": 60,
      "z": 1,
      "name": "Plant_Leaves_Beech_Max_Support"
    },
    {
      "x": -14,
      "y": 61,
      "z": 1,
      "name": "Plant_Leaves_Beech_Max_Support"
    },
    {
      "x": -14,
      "y": 62,
      "z": 1,
      "name": "Plant_Leaves_Beech_Max_Support"
    },
    {
      "x": -14,
      "y": 63,
      "z": 1,
      "name": "Plant_Leaves_Beech_Max_Support"
    },
    {
      "x": -14,
      "y": 64,
      "z": 1,
      "name": "Plant_Leaves_Beech_Max_Support"
    },
    {
      "x": -14,
      "y": 65,
      "z": 1,
      "name": "Plant_Leaves_Beech_Max_Support"
    },
    {
      "x": -14,
      "y": 4,
      "z": 2,
      "name": "Wood_Gumboab_Trunk_Full"
    },
    {
      "x": -14,
      "y": 5,
      "z": 2,
      "name": "Wood_Gumboab_Trunk_Full"
    },
    {
      "x": -14,
      "y": 6,
      "z": 2,
      "name": "Wood_Gumboab_Trunk_Full"
    },
    {
      "x": -14,
      "y": 7,
      "z": 2,
      "name": "Wood_Gumboab_Trunk_Full"
    },
    {
      "x": -14,
      "y": 8,
      "z": 2,
      "name": "Wood_Gumboab_Trunk_Full"
    },
    {
      "x": -14,
      "y": 33,
      "z": 2,
      "name": "Plant_Leaves_Beech_Max_Support"
    },
    {
      "x": -14,
      "y": 34,
      "z": 2,
      "name": "Plant_Leaves_Beech_Max_Support"
    },
    {
      "x": -14,
      "y": 35,
      "z": 2,
      "name": "Plant_Leaves_Beech_Max_Support"
    },
    {
      "x": -14,
      "y": 36,
      "z": 2,
      "name": "Plant_Leaves_Beech_Max_Support"
    },
    {
      "x": -14,
      "y": 60,
      "z": 2,
      "name": "Plant_Leaves_Beech_Max_Support"
    },
    {
      "x": -14,
      "y": 61,
      "z": 2,
      "name": "Plant_Leaves_Beech_Max_Support"
    },
    {
      "x": -14,
      "y": 62,
      "z": 2,
      "name": "Plant_Leaves_Beech_Max_Support"
    },
    {
      "x": -14,
      "y": 63,
      "z": 2,
      "name": "Plant_Leaves_Beech_Max_Support"
    },
    {
      "x": -14,
      "y": 64,
      "z": 2,
      "name": "Plant_Leaves_Beech_Max_Support"
    },
    {
      "x": -14,
      "y": 65,
      "z": 2,
      "name": "Plant_Leaves_Beech_Max_Support"
    },
    {
      "x": -14,
      "y": 4,
      "z": 3,
      "name": "Wood_Gumboab_Trunk_Full"
    },
    {
      "x": -14,
      "y": 5,
      "z": 3,
      "name": "Wood_Gumboab_Trunk_Full"
    },
    {
      "x": -14,
      "y": 6,
      "z": 3,
      "name": "Wood_Gumboab_Trunk_Full"
    },
    {
      "x": -14,
      "y": 7,
      "z": 3,
      "name": "Wood_Gumboab_Trunk_Full"
    },
    {
      "x": -14,
      "y": 8,
      "z": 3,
      "name": "Wood_Gumboab_Trunk_Full"
    },
    {
      "x": -14,
      "y": 32,
      "z": 3,
      "name": "Plant_Leaves_Beech_Max_Support"
    },
    {
      "x": -14,
      "y": 33,
      "z": 3,
      "name": "Plant_Leaves_Beech_Max_Support"
    },
    {
      "x": -14,
      "y": 34,
      "z": 3,
      "name": "Plant_Leaves_Beech_Max_Support"
    },
    {
      "x": -14,
      "y": 35,
      "z": 3,
      "name": "Plant_Leaves_Beech_Max_Support"
    },
    {
      "x": -14,
      "y": 36,
      "z": 3,
      "name": "Plant_Leaves_Beech_Max_Support"
    },
    {
      "x": -14,
      "y": 60,
      "z": 3,
      "name": "Plant_Leaves_Beech_Max_Support"
    },
    {
      "x": -14,
      "y": 61,
      "z": 3,
      "name": "Plant_Leaves_Beech_Max_Support"
    },
    {
      "x": -14,
      "y": 62,
      "z": 3,
      "name": "Plant_Leaves_Beech_Max_Support"
    },
    {
      "x": -14,
      "y": 63,
      "z": 3,
      "name": "Plant_Leaves_Beech_Max_Support"
    },
    {
      "x": -14,
      "y": 64,
      "z": 3,
      "name": "Plant_Leaves_Beech_Max_Support"
    },
    {
      "x": -14,
      "y": 32,
      "z": 4,
      "name": "Plant_Leaves_Beech_Max_Support"
    },
    {
      "x": -14,
      "y": 33,
      "z": 4,
      "name": "Plant_Leaves_Beech_Max_Support"
    },
    {
      "x": -14,
      "y": 34,
      "z": 4,
      "name": "Plant_Leaves_Beech_Max_Support"
    },
    {
      "x": -14,
      "y": 36,
      "z": 4,
      "name": "Plant_Leaves_Beech_Max_Support"
    },
    {
      "x": -14,
      "y": 37,
      "z": 4,
      "name": "Plant_Leaves_Beech_Max_Support"
    },
    {
      "x": -14,
      "y": 38,
      "z": 4,
      "name": "Plant_Leaves_Beech_Max_Support"
    },
    {
      "x": -14,
      "y": 60,
      "z": 4,
      "name": "Plant_Leaves_Beech_Max_Support"
    },
    {
      "x": -14,
      "y": 61,
      "z": 4,
      "name": "Plant_Leaves_Beech_Max_Support"
    },
    {
      "x": -14,
      "y": 62,
      "z": 4,
      "name": "Plant_Leaves_Beech_Max_Support"
    },
    {
      "x": -14,
      "y": 63,
      "z": 4,
      "name": "Plant_Leaves_Beech_Max_Support"
    },
    {
      "x": -14,
      "y": 31,
      "z": 5,
      "name": "Plant_Leaves_Beech_Max_Support"
    },
    {
      "x": -14,
      "y": 32,
      "z": 5,
      "name": "Plant_Leaves_Beech_Max_Support"
    },
    {
      "x": -14,
      "y": 33,
      "z": 5,
      "name": "Plant_Leaves_Beech_Max_Support"
    },
    {
      "x": -14,
      "y": 34,
      "z": 5,
      "name": "Plant_Leaves_Beech_Max_Support"
    },
    {
      "x": -14,
      "y": 35,
      "z": 5,
      "name": "Plant_Leaves_Beech_Max_Support"
    },
    {
      "x": -14,
      "y": 38,
      "z": 5,
      "name": "Plant_Leaves_Beech_Max_Support"
    },
    {
      "x": -14,
      "y": 59,
      "z": 5,
      "name": "Plant_Leaves_Beech_Max_Support"
    },
    {
      "x": -14,
      "y": 60,
      "z": 5,
      "name": "Plant_Leaves_Beech_Max_Support"
    },
    {
      "x": -14,
      "y": 61,
      "z": 5,
      "name": "Plant_Leaves_Beech_Max_Support"
    },
    {
      "x": -14,
      "y": 32,
      "z": 6,
      "name": "Plant_Leaves_Beech_Max_Support"
    },
    {
      "x": -14,
      "y": 33,
      "z": 6,
      "name": "Plant_Leaves_Beech_Max_Support"
    },
    {
      "x": -14,
      "y": 34,
      "z": 6,
      "name": "Plant_Leaves_Beech_Max_Support"
    },
    {
      "x": -14,
      "y": 35,
      "z": 6,
      "name": "Plant_Leaves_Beech_Max_Support"
    },
    {
      "x": -14,
      "y": 36,
      "z": 6,
      "name": "Plant_Leaves_Beech_Max_Support"
    },
    {
      "x": -14,
      "y": 37,
      "z": 6,
      "name": "Plant_Leaves_Beech_Max_Support"
    },
    {
      "x": -14,
      "y": 38,
      "z": 6,
      "name": "Plant_Leaves_Beech_Max_Support"
    },
    {
      "x": -14,
      "y": 59,
      "z": 6,
      "name": "Plant_Leaves_Beech_Max_Support"
    },
    {
      "x": -14,
      "y": 60,
      "z": 6,
      "name": "Plant_Leaves_Beech_Max_Support"
    },
    {
      "x": -14,
      "y": 61,
      "z": 6,
      "name": "Plant_Leaves_Beech_Max_Support"
    },
    {
      "x": -14,
      "y": 62,
      "z": 6,
      "name": "Plant_Leaves_Beech_Max_Support"
    },
    {
      "x": -14,
      "y": 31,
      "z": 7,
      "name": "Plant_Leaves_Beech_Max_Support"
    },
    {
      "x": -14,
      "y": 33,
      "z": 7,
      "name": "Plant_Leaves_Beech_Max_Support"
    },
    {
      "x": -14,
      "y": 34,
      "z": 7,
      "name": "Plant_Leaves_Beech_Max_Support"
    },
    {
      "x": -14,
      "y": 35,
      "z": 7,
      "name": "Plant_Leaves_Beech_Max_Support"
    },
    {
      "x": -14,
      "y": 36,
      "z": 7,
      "name": "Plant_Leaves_Beech_Max_Support"
    },
    {
      "x": -14,
      "y": 37,
      "z": 7,
      "name": "Plant_Leaves_Beech_Max_Support"
    },
    {
      "x": -14,
      "y": 38,
      "z": 7,
      "name": "Plant_Leaves_Beech_Max_Support"
    },
    {
      "x": -14,
      "y": 59,
      "z": 7,
      "name": "Plant_Leaves_Beech_Max_Support"
    },
    {
      "x": -14,
      "y": 60,
      "z": 7,
      "name": "Plant_Leaves_Beech_Max_Support"
    },
    {
      "x": -14,
      "y": 61,
      "z": 7,
      "name": "Plant_Leaves_Beech_Max_Support"
    },
    {
      "x": -14,
      "y": 62,
      "z": 7,
      "name": "Plant_Leaves_Beech_Max_Support"
    },
    {
      "x": -14,
      "y": 63,
      "z": 7,
      "name": "Plant_Leaves_Beech_Max_Support"
    },
    {
      "x": -14,
      "y": 64,
      "z": 7,
      "name": "Plant_Leaves_Beech_Max_Support"
    },
    {
      "x": -14,
      "y": 32,
      "z": 8,
      "name": "Plant_Leaves_Beech_Max_Support"
    },
    {
      "x": -14,
      "y": 33,
      "z": 8,
      "name": "Plant_Leaves_Beech_Max_Support"
    },
    {
      "x": -14,
      "y": 34,
      "z": 8,
      "name": "Plant_Leaves_Beech_Max_Support"
    },
    {
      "x": -14,
      "y": 35,
      "z": 8,
      "name": "Plant_Leaves_Beech_Max_Support"
    },
    {
      "x": -14,
      "y": 36,
      "z": 8,
      "name": "Plant_Leaves_Beech_Max_Support"
    },
    {
      "x": -14,
      "y": 37,
      "z": 8,
      "name": "Plant_Leaves_Beech_Max_Support"
    },
    {
      "x": -14,
      "y": 38,
      "z": 8,
      "name": "Plant_Leaves_Beech_Max_Support"
    },
    {
      "x": -14,
      "y": 39,
      "z": 8,
      "name": "Plant_Leaves_Beech_Max_Support"
    },
    {
      "x": -14,
      "y": 59,
      "z": 8,
      "name": "Plant_Leaves_Beech_Max_Support"
    },
    {
      "x": -14,
      "y": 61,
      "z": 8,
      "name": "Plant_Leaves_Beech_Max_Support"
    },
    {
      "x": -14,
      "y": 62,
      "z": 8,
      "name": "Plant_Leaves_Beech_Max_Support"
    },
    {
      "x": -14,
      "y": 33,
      "z": 9,
      "name": "Plant_Leaves_Beech_Max_Support"
    },
    {
      "x": -14,
      "y": 34,
      "z": 9,
      "name": "Plant_Leaves_Beech_Max_Support"
    },
    {
      "x": -14,
      "y": 35,
      "z": 9,
      "name": "Plant_Leaves_Beech_Max_Support"
    },
    {
      "x": -14,
      "y": 36,
      "z": 9,
      "name": "Plant_Leaves_Beech_Max_Support"
    },
    {
      "x": -14,
      "y": 38,
      "z": 9,
      "name": "Plant_Leaves_Beech_Max_Support"
    },
    {
      "x": -14,
      "y": 32,
      "z": 10,
      "name": "Plant_Leaves_Beech_Max_Support"
    },
    {
      "x": -14,
      "y": 33,
      "z": 10,
      "name": "Plant_Leaves_Beech_Max_Support"
    },
    {
      "x": -14,
      "y": 34,
      "z": 10,
      "name": "Plant_Leaves_Beech_Max_Support"
    },
    {
      "x": -14,
      "y": 35,
      "z": 10,
      "name": "Plant_Leaves_Beech_Max_Support"
    },
    {
      "x": -14,
      "y": 36,
      "z": 10,
      "name": "Plant_Leaves_Beech_Max_Support"
    },
    {
      "x": -14,
      "y": 37,
      "z": 10,
      "name": "Plant_Leaves_Beech_Max_Support"
    },
    {
      "x": -14,
      "y": 38,
      "z": 10,
      "name": "Plant_Leaves_Beech_Max_Support"
    },
    {
      "x": -14,
      "y": 31,
      "z": 11,
      "name": "Plant_Leaves_Beech_Max_Support"
    },
    {
      "x": -14,
      "y": 32,
      "z": 11,
      "name": "Plant_Leaves_Beech_Max_Support"
    },
    {
      "x": -14,
      "y": 33,
      "z": 11,
      "name": "Plant_Leaves_Beech_Max_Support"
    },
    {
      "x": -14,
      "y": 34,
      "z": 11,
      "name": "Plant_Leaves_Beech_Max_Support"
    },
    {
      "x": -14,
      "y": 35,
      "z": 11,
      "name": "Plant_Leaves_Beech_Max_Support"
    },
    {
      "x": -14,
      "y": 32,
      "z": 12,
      "name": "Plant_Leaves_Beech_Max_Support"
    },
    {
      "x": -14,
      "y": 33,
      "z": 12,
      "name": "Plant_Leaves_Beech_Max_Support"
    },
    {
      "x": -13,
      "y": 59,
      "z": -6,
      "name": "Plant_Leaves_Beech_Max_Support"
    },
    {
      "x": -13,
      "y": 60,
      "z": -6,
      "name": "Plant_Leaves_Beech_Max_Support"
    },
    {
      "x": -13,
      "y": 59,
      "z": -5,
      "name": "Plant_Leaves_Beech_Max_Support"
    },
    {
      "x": -13,
      "y": 61,
      "z": -5,
      "name": "Plant_Leaves_Beech_Max_Support"
    },
    {
      "x": -13,
      "y": 58,
      "z": -4,
      "name": "Plant_Leaves_Beech_Max_Support"
    },
    {
      "x": -13,
      "y": 59,
      "z": -4,
      "name": "Plant_Leaves_Beech_Max_Support"
    },
    {
      "x": -13,
      "y": 60,
      "z": -4,
      "name": "Plant_Leaves_Beech_Max_Support"
    },
    {
      "x": -13,
      "y": 62,
      "z": -4,
      "name": "Plant_Leaves_Beech_Max_Support"
    },
    {
      "x": -13,
      "y": 7,
      "z": -3,
      "name": "Wood_Gumboab_Trunk_Full"
    },
    {
      "x": -13,
      "y": 8,
      "z": -3,
      "name": "Wood_Gumboab_Trunk_Full"
    },
    {
      "x": -13,
      "y": 9,
      "z": -3,
      "name": "Wood_Gumboab_Trunk_Full"
    },
    {
      "x": -13,
      "y": 59,
      "z": -3,
      "name": "Plant_Leaves_Beech_Max_Support"
    },
    {
      "x": -13,
      "y": 60,
      "z": -3,
      "name": "Plant_Leaves_Beech_Max_Support"
    },
    {
      "x": -13,
      "y": 61,
      "z": -3,
      "name": "Plant_Leaves_Beech_Max_Support"
    },
    {
      "x": -13,
      "y": 62,
      "z": -3,
      "name": "Plant_Leaves_Beech_Max_Support"
    },
    {
      "x": -13,
      "y": 8,
      "z": -2,
      "name": "Wood_Gumboab_Trunk_Full"
    },
    {
      "x": -13,
      "y": 9,
      "z": -2,
      "name": "Wood_Gumboab_Trunk_Full"
    },
    {
      "x": -13,
      "y": 10,
      "z": -2,
      "name": "Wood_Gumboab_Trunk_Full"
    },
    {
      "x": -13,
      "y": 11,
      "z": -2,
      "name": "Wood_Gumboab_Trunk_Full"
    },
    {
      "x": -13,
      "y": 60,
      "z": -2,
      "name": "Plant_Leaves_Beech_Max_Support"
    },
    {
      "x": -13,
      "y": 61,
      "z": -2,
      "name": "Plant_Leaves_Beech_Max_Support"
    },
    {
      "x": -13,
      "y": 63,
      "z": -2,
      "name": "Plant_Leaves_Beech_Max_Support"
    },
    {
      "x": -13,
      "y": 8,
      "z": -1,
      "name": "Wood_Gumboab_Trunk_Full"
    },
    {
      "x": -13,
      "y": 9,
      "z": -1,
      "name": "Wood_Gumboab_Trunk_Full"
    },
    {
      "x": -13,
      "y": 10,
      "z": -1,
      "name": "Wood_Gumboab_Trunk_Full"
    },
    {
      "x": -13,
      "y": 11,
      "z": -1,
      "name": "Wood_Gumboab_Trunk_Full"
    },
    {
      "x": -13,
      "y": 60,
      "z": -1,
      "name": "Plant_Leaves_Beech_Max_Support"
    },
    {
      "x": -13,
      "y": 61,
      "z": -1,
      "name": "Plant_Leaves_Beech_Max_Support"
    },
    {
      "x": -13,
      "y": 62,
      "z": -1,
      "name": "Plant_Leaves_Beech_Max_Support"
    },
    {
      "x": -13,
      "y": 63,
      "z": -1,
      "name": "Plant_Leaves_Beech_Max_Support"
    },
    {
      "x": -13,
      "y": 9,
      "z": 0,
      "name": "Wood_Gumboab_Trunk_Full"
    },
    {
      "x": -13,
      "y": 10,
      "z": 0,
      "name": "Wood_Gumboab_Trunk_Full"
    },
    {
      "x": -13,
      "y": 11,
      "z": 0,
      "name": "Wood_Gumboab_Trunk_Full"
    },
    {
      "x": -13,
      "y": 58,
      "z": 0,
      "name": "Wood_Gumboab_Trunk_Full"
    },
    {
      "x": -13,
      "y": 59,
      "z": 0,
      "name": "Plant_Leaves_Beech_Max_Support"
    },
    {
      "x": -13,
      "y": 61,
      "z": 0,
      "name": "Plant_Leaves_Beech_Max_Support"
    },
    {
      "x": -13,
      "y": 63,
      "z": 0,
      "name": "Plant_Leaves_Beech_Max_Support"
    },
    {
      "x": -13,
      "y": 64,
      "z": 0,
      "name": "Plant_Leaves_Beech_Max_Support"
    },
    {
      "x": -13,
      "y": 65,
      "z": 0,
      "name": "Plant_Leaves_Beech_Max_Support"
    },
    {
      "x": -13,
      "y": 7,
      "z": 1,
      "name": "Wood_Gumboab_Trunk_Full"
    },
    {
      "x": -13,
      "y": 8,
      "z": 1,
      "name": "Wood_Gumboab_Trunk_Full"
    },
    {
      "x": -13,
      "y": 9,
      "z": 1,
      "name": "Wood_Gumboab_Trunk_Full"
    },
    {
      "x": -13,
      "y": 10,
      "z": 1,
      "name": "Wood_Gumboab_Trunk_Full"
    },
    {
      "x": -13,
      "y": 58,
      "z": 1,
      "name": "Wood_Gumboab_Trunk_Full"
    },
    {
      "x": -13,
      "y": 60,
      "z": 1,
      "name": "Plant_Leaves_Beech_Max_Support"
    },
    {
      "x": -13,
      "y": 61,
      "z": 1,
      "name": "Plant_Leaves_Beech_Max_Support"
    },
    {
      "x": -13,
      "y": 62,
      "z": 1,
      "name": "Plant_Leaves_Beech_Max_Support"
    },
    {
      "x": -13,
      "y": 63,
      "z": 1,
      "name": "Plant_Leaves_Beech_Max_Support"
    },
    {
      "x": -13,
      "y": 65,
      "z": 1,
      "name": "Plant_Leaves_Beech_Max_Support"
    },
    {
      "x": -13,
      "y": 6,
      "z": 2,
      "name": "Wood_Gumboab_Trunk_Full"
    },
    {
      "x": -13,
      "y": 7,
      "z": 2,
      "name": "Wood_Gumboab_Trunk_Full"
    },
    {
      "x": -13,
      "y": 8,
      "z": 2,
      "name": "Wood_Gumboab_Trunk_Full"
    },
    {
      "x": -13,
      "y": 9,
      "z": 2,
      "name": "Wood_Gumboab_Trunk_Full"
    },
    {
      "x": -13,
      "y": 32,
      "z": 2,
      "name": "Plant_Leaves_Beech_Max_Support"
    },
    {
      "x": -13,
      "y": 34,
      "z": 2,
      "name": "Plant_Leaves_Beech_Max_Support"
    },
    {
      "x": -13,
      "y": 35,
      "z": 2,
      "name": "Plant_Leaves_Beech_Max_Support"
    },
    {
      "x": -13,
      "y": 36,
      "z": 2,
      "name": "Plant_Leaves_Beech_Max_Support"
    },
    {
      "x": -13,
      "y": 61,
      "z": 2,
      "name": "Plant_Leaves_Beech_Max_Support"
    },
    {
      "x": -13,
      "y": 62,
      "z": 2,
      "name": "Plant_Leaves_Beech_Max_Support"
    },
    {
      "x": -13,
      "y": 63,
      "z": 2,
      "name": "Plant_Leaves_Beech_Max_Support"
    },
    {
      "x": -13,
      "y": 64,
      "z": 2,
      "name": "Plant_Leaves_Beech_Max_Support"
    },
    {
      "x": -13,
      "y": 65,
      "z": 2,
      "name": "Plant_Leaves_Beech_Max_Support"
    },
    {
      "x": -13,
      "y": 6,
      "z": 3,
      "name": "Wood_Gumboab_Trunk_Full"
    },
    {
      "x": -13,
      "y": 7,
      "z": 3,
      "name": "Wood_Gumboab_Trunk_Full"
    },
    {
      "x": -13,
      "y": 8,
      "z": 3,
      "name": "Wood_Gumboab_Trunk_Full"
    },
    {
      "x": -13,
      "y": 31,
      "z": 3,
      "name": "Plant_Leaves_Beech_Max_Support"
    },
    {
      "x": -13,
      "y": 32,
      "z": 3,
      "name": "Plant_Leaves_Beech_Max_Support"
    },
    {
      "x": -13,
      "y": 33,
      "z": 3,
      "name": "Plant_Leaves_Beech_Max_Support"
    },
    {
      "x": -13,
      "y": 34,
      "z": 3,
      "name": "Plant_Leaves_Beech_Max_Support"
    },
    {
      "x": -13,
      "y": 37,
      "z": 3,
      "name": "Plant_Leaves_Beech_Max_Support"
    },
    {
      "x": -13,
      "y": 60,
      "z": 3,
      "name": "Plant_Leaves_Beech_Max_Support"
    },
    {
      "x": -13,
      "y": 61,
      "z": 3,
      "name": "Plant_Leaves_Beech_Max_Support"
    },
    {
      "x": -13,
      "y": 62,
      "z": 3,
      "name": "Plant_Leaves_Beech_Max_Support"
    },
    {
      "x": -13,
      "y": 63,
      "z": 3,
      "name": "Plant_Leaves_Beech_Max_Support"
    },
    {
      "x": -13,
      "y": 64,
      "z": 3,
      "name": "Plant_Leaves_Beech_Max_Support"
    },
    {
      "x": -13,
      "y": 65,
      "z": 3,
      "name": "Plant_Leaves_Beech_Max_Support"
    },
    {
      "x": -13,
      "y": 31,
      "z": 4,
      "name": "Plant_Leaves_Beech_Max_Support"
    },
    {
      "x": -13,
      "y": 33,
      "z": 4,
      "name": "Plant_Leaves_Beech_Max_Support"
    },
    {
      "x": -13,
      "y": 37,
      "z": 4,
      "name": "Plant_Leaves_Beech_Max_Support"
    },
    {
      "x": -13,
      "y": 38,
      "z": 4,
      "name": "Plant_Leaves_Beech_Max_Support"
    },
    {
      "x": -13,
      "y": 61,
      "z": 4,
      "name": "Plant_Leaves_Beech_Max_Support"
    },
    {
      "x": -13,
      "y": 63,
      "z": 4,
      "name": "Plant_Leaves_Beech_Max_Support"
    },
    {
      "x": -13,
      "y": 32,
      "z": 5,
      "name": "Plant_Leaves_Beech_Max_Support"
    },
    {
      "x": -13,
      "y": 33,
      "z": 5,
      "name": "Plant_Leaves_Beech_Max_Support"
    },
    {
      "x": -13,
      "y": 34,
      "z": 5,
      "name": "Plant_Leaves_Beech_Max_Support"
    },
    {
      "x": -13,
      "y": 35,
      "z": 5,
      "name": "Plant_Leaves_Beech_Max_Support"
    },
    {
      "x": -13,
      "y": 36,
      "z": 5,
      "name": "Plant_Leaves_Beech_Max_Support"
    },
    {
      "x": -13,
      "y": 37,
      "z": 5,
      "name": "Plant_Leaves_Beech_Max_Support"
    },
    {
      "x": -13,
      "y": 38,
      "z": 5,
      "name": "Plant_Leaves_Beech_Max_Support"
    },
    {
      "x": -13,
      "y": 39,
      "z": 5,
      "name": "Plant_Leaves_Beech_Max_Support"
    },
    {
      "x": -13,
      "y": 60,
      "z": 5,
      "name": "Plant_Leaves_Beech_Max_Support"
    },
    {
      "x": -13,
      "y": 61,
      "z": 5,
      "name": "Plant_Leaves_Beech_Max_Support"
    },
    {
      "x": -13,
      "y": 63,
      "z": 5,
      "name": "Plant_Leaves_Beech_Max_Support"
    },
    {
      "x": -13,
      "y": 32,
      "z": 6,
      "name": "Plant_Leaves_Beech_Max_Support"
    },
    {
      "x": -13,
      "y": 33,
      "z": 6,
      "name": "Plant_Leaves_Beech_Max_Support"
    },
    {
      "x": -13,
      "y": 34,
      "z": 6,
      "name": "Plant_Leaves_Beech_Max_Support"
    },
    {
      "x": -13,
      "y": 35,
      "z": 6,
      "name": "Plant_Leaves_Beech_Max_Support"
    },
    {
      "x": -13,
      "y": 36,
      "z": 6,
      "name": "Plant_Leaves_Beech_Max_Support"
    },
    {
      "x": -13,
      "y": 37,
      "z": 6,
      "name": "Plant_Leaves_Beech_Max_Support"
    },
    {
      "x": -13,
      "y": 38,
      "z": 6,
      "name": "Plant_Leaves_Beech_Max_Support"
    },
    {
      "x": -13,
      "y": 39,
      "z": 6,
      "name": "Plant_Leaves_Beech_Max_Support"
    },
    {
      "x": -13,
      "y": 40,
      "z": 6,
      "name": "Plant_Leaves_Beech_Max_Support"
    },
    {
      "x": -13,
      "y": 59,
      "z": 6,
      "name": "Plant_Leaves_Beech_Max_Support"
    },
    {
      "x": -13,
      "y": 60,
      "z": 6,
      "name": "Plant_Leaves_Beech_Max_Support"
    },
    {
      "x": -13,
      "y": 61,
      "z": 6,
      "name": "Plant_Leaves_Beech_Max_Support"
    },
    {
      "x": -13,
      "y": 62,
      "z": 6,
      "name": "Plant_Leaves_Beech_Max_Support"
    },
    {
      "x": -13,
      "y": 63,
      "z": 6,
      "name": "Plant_Leaves_Beech_Max_Support"
    },
    {
      "x": -13,
      "y": 32,
      "z": 7,
      "name": "Plant_Leaves_Beech_Max_Support"
    },
    {
      "x": -13,
      "y": 33,
      "z": 7,
      "name": "Plant_Leaves_Beech_Max_Support"
    },
    {
      "x": -13,
      "y": 34,
      "z": 7,
      "name": "Plant_Leaves_Beech_Max_Support"
    },
    {
      "x": -13,
      "y": 35,
      "z": 7,
      "name": "Plant_Leaves_Beech_Max_Support"
    },
    {
      "x": -13,
      "y": 37,
      "z": 7,
      "name": "Plant_Leaves_Beech_Max_Support"
    },
    {
      "x": -13,
      "y": 38,
      "z": 7,
      "name": "Plant_Leaves_Beech_Max_Support"
    },
    {
      "x": -13,
      "y": 40,
      "z": 7,
      "name": "Plant_Leaves_Beech_Max_Support"
    },
    {
      "x": -13,
      "y": 58,
      "z": 7,
      "name": "Plant_Leaves_Beech_Max_Support"
    },
    {
      "x": -13,
      "y": 59,
      "z": 7,
      "name": "Plant_Leaves_Beech_Max_Support"
    },
    {
      "x": -13,
      "y": 60,
      "z": 7,
      "name": "Plant_Leaves_Beech_Max_Support"
    },
    {
      "x": -13,
      "y": 61,
      "z": 7,
      "name": "Plant_Leaves_Beech_Max_Support"
    },
    {
      "x": -13,
      "y": 62,
      "z": 7,
      "name": "Plant_Leaves_Beech_Max_Support"
    },
    {
      "x": -13,
      "y": 63,
      "z": 7,
      "name": "Plant_Leaves_Beech_Max_Support"
    },
    {
      "x": -13,
      "y": 64,
      "z": 7,
      "name": "Plant_Leaves_Beech_Max_Support"
    },
    {
      "x": -13,
      "y": 31,
      "z": 8,
      "name": "Plant_Leaves_Beech_Max_Support"
    },
    {
      "x": -13,
      "y": 32,
      "z": 8,
      "name": "Plant_Leaves_Beech_Max_Support"
    },
    {
      "x": -13,
      "y": 33,
      "z": 8,
      "name": "Wood_Gumboab_Trunk_Full"
    },
    {
      "x": -13,
      "y": 34,
      "z": 8,
      "name": "Plant_Leaves_Beech_Max_Support"
    },
    {
      "x": -13,
      "y": 35,
      "z": 8,
      "name": "Plant_Leaves_Beech_Max_Support"
    },
    {
      "x": -13,
      "y": 36,
      "z": 8,
      "name": "Plant_Leaves_Beech_Max_Support"
    },
    {
      "x": -13,
      "y": 37,
      "z": 8,
      "name": "Plant_Leaves_Beech_Max_Support"
    },
    {
      "x": -13,
      "y": 38,
      "z": 8,
      "name": "Plant_Leaves_Beech_Max_Support"
    },
    {
      "x": -13,
      "y": 39,
      "z": 8,
      "name": "Plant_Leaves_Beech_Max_Support"
    },
    {
      "x": -13,
      "y": 58,
      "z": 8,
      "name": "Plant_Leaves_Beech_Max_Support"
    },
    {
      "x": -13,
      "y": 59,
      "z": 8,
      "name": "Plant_Leaves_Beech_Max_Support"
    },
    {
      "x": -13,
      "y": 60,
      "z": 8,
      "name": "Plant_Leaves_Beech_Max_Support"
    },
    {
      "x": -13,
      "y": 62,
      "z": 8,
      "name": "Plant_Leaves_Beech_Max_Support"
    },
    {
      "x": -13,
      "y": 64,
      "z": 8,
      "name": "Plant_Leaves_Beech_Max_Support"
    },
    {
      "x": -13,
      "y": 32,
      "z": 9,
      "name": "Plant_Leaves_Beech_Max_Support"
    },
    {
      "x": -13,
      "y": 33,
      "z": 9,
      "name": "Plant_Leaves_Beech_Max_Support"
    },
    {
      "x": -13,
      "y": 34,
      "z": 9,
      "name": "Plant_Leaves_Beech_Max_Support"
    },
    {
      "x": -13,
      "y": 35,
      "z": 9,
      "name": "Plant_Leaves_Beech_Max_Support"
    },
    {
      "x": -13,
      "y": 37,
      "z": 9,
      "name": "Plant_Leaves_Beech_Max_Support"
    },
    {
      "x": -13,
      "y": 38,
      "z": 9,
      "name": "Plant_Leaves_Beech_Max_Support"
    },
    {
      "x": -13,
      "y": 59,
      "z": 9,
      "name": "Plant_Leaves_Beech_Max_Support"
    },
    {
      "x": -13,
      "y": 61,
      "z": 9,
      "name": "Plant_Leaves_Beech_Max_Support"
    },
    {
      "x": -13,
      "y": 31,
      "z": 10,
      "name": "Plant_Leaves_Beech_Max_Support"
    },
    {
      "x": -13,
      "y": 32,
      "z": 10,
      "name": "Plant_Leaves_Beech_Max_Support"
    },
    {
      "x": -13,
      "y": 33,
      "z": 10,
      "name": "Plant_Leaves_Beech_Max_Support"
    },
    {
      "x": -13,
      "y": 34,
      "z": 10,
      "name": "Plant_Leaves_Beech_Max_Support"
    },
    {
      "x": -13,
      "y": 35,
      "z": 10,
      "name": "Plant_Leaves_Beech_Max_Support"
    },
    {
      "x": -13,
      "y": 36,
      "z": 10,
      "name": "Plant_Leaves_Beech_Max_Support"
    },
    {
      "x": -13,
      "y": 37,
      "z": 10,
      "name": "Plant_Leaves_Beech_Max_Support"
    },
    {
      "x": -13,
      "y": 38,
      "z": 10,
      "name": "Plant_Leaves_Beech_Max_Support"
    },
    {
      "x": -13,
      "y": 31,
      "z": 11,
      "name": "Plant_Leaves_Beech_Max_Support"
    },
    {
      "x": -13,
      "y": 32,
      "z": 11,
      "name": "Plant_Leaves_Beech_Max_Support"
    },
    {
      "x": -13,
      "y": 33,
      "z": 11,
      "name": "Plant_Leaves_Beech_Max_Support"
    },
    {
      "x": -13,
      "y": 34,
      "z": 11,
      "name": "Plant_Leaves_Beech_Max_Support"
    },
    {
      "x": -13,
      "y": 35,
      "z": 11,
      "name": "Plant_Leaves_Beech_Max_Support"
    },
    {
      "x": -13,
      "y": 36,
      "z": 11,
      "name": "Plant_Leaves_Beech_Max_Support"
    },
    {
      "x": -13,
      "y": 37,
      "z": 11,
      "name": "Plant_Leaves_Beech_Max_Support"
    },
    {
      "x": -13,
      "y": 32,
      "z": 12,
      "name": "Plant_Leaves_Beech_Max_Support"
    },
    {
      "x": -13,
      "y": 35,
      "z": 12,
      "name": "Plant_Leaves_Beech_Max_Support"
    },
    {
      "x": -13,
      "y": 36,
      "z": 12,
      "name": "Plant_Leaves_Beech_Max_Support"
    },
    {
      "x": -13,
      "y": 32,
      "z": 13,
      "name": "Plant_Leaves_Beech_Max_Support"
    },
    {
      "x": -12,
      "y": 9,
      "z": -8,
      "name": "Wood_Gumboab_Trunk_Full"
    },
    {
      "x": -12,
      "y": 10,
      "z": -8,
      "name": "Wood_Gumboab_Trunk_Full"
    },
    {
      "x": -12,
      "y": 9,
      "z": -7,
      "name": "Wood_Gumboab_Trunk_Full"
    },
    {
      "x": -12,
      "y": 10,
      "z": -7,
      "name": "Wood_Gumboab_Trunk_Full"
    },
    {
      "x": -12,
      "y": 11,
      "z": -7,
      "name": "Wood_Gumboab_Trunk_Full"
    },
    {
      "x": -12,
      "y": 10,
      "z": -6,
      "name": "Wood_Gumboab_Trunk_Full"
    },
    {
      "x": -12,
      "y": 11,
      "z": -6,
      "name": "Wood_Gumboab_Trunk_Full"
    },
    {
      "x": -12,
      "y": 12,
      "z": -6,
      "name": "Wood_Gumboab_Trunk_Full"
    },
    {
      "x": -12,
      "y": 58,
      "z": -6,
      "name": "Plant_Leaves_Beech_Max_Support"
    },
    {
      "x": -12,
      "y": 59,
      "z": -6,
      "name": "Plant_Leaves_Beech_Max_Support"
    },
    {
      "x": -12,
      "y": 60,
      "z": -6,
      "name": "Plant_Leaves_Beech_Max_Support"
    },
    {
      "x": -12,
      "y": 61,
      "z": -6,
      "name": "Plant_Leaves_Beech_Max_Support"
    },
    {
      "x": -12,
      "y": 62,
      "z": -6,
      "name": "Plant_Leaves_Beech_Max_Support"
    },
    {
      "x": -12,
      "y": 11,
      "z": -5,
      "name": "Wood_Gumboab_Trunk_Full"
    },
    {
      "x": -12,
      "y": 12,
      "z": -5,
      "name": "Wood_Gumboab_Trunk_Full"
    },
    {
      "x": -12,
      "y": 58,
      "z": -5,
      "name": "Plant_Leaves_Beech_Max_Support"
    },
    {
      "x": -12,
      "y": 60,
      "z": -5,
      "name": "Plant_Leaves_Beech_Max_Support"
    },
    {
      "x": -12,
      "y": 61,
      "z": -5,
      "name": "Plant_Leaves_Beech_Max_Support"
    },
    {
      "x": -12,
      "y": 57,
      "z": -4,
      "name": "Plant_Leaves_Beech_Max_Support"
    },
    {
      "x": -12,
      "y": 58,
      "z": -4,
      "name": "Plant_Leaves_Beech_Max_Support"
    },
    {
      "x": -12,
      "y": 59,
      "z": -4,
      "name": "Plant_Leaves_Beech_Max_Support"
    },
    {
      "x": -12,
      "y": 60,
      "z": -4,
      "name": "Plant_Leaves_Beech_Max_Support"
    },
    {
      "x": -12,
      "y": 62,
      "z": -4,
      "name": "Plant_Leaves_Beech_Max_Support"
    },
    {
      "x": -12,
      "y": 57,
      "z": -3,
      "name": "Plant_Leaves_Beech_Max_Support"
    },
    {
      "x": -12,
      "y": 58,
      "z": -3,
      "name": "Plant_Leaves_Beech_Max_Support"
    },
    {
      "x": -12,
      "y": 59,
      "z": -3,
      "name": "Plant_Leaves_Beech_Max_Support"
    },
    {
      "x": -12,
      "y": 60,
      "z": -3,
      "name": "Plant_Leaves_Beech_Max_Support"
    },
    {
      "x": -12,
      "y": 61,
      "z": -3,
      "name": "Plant_Leaves_Beech_Max_Support"
    },
    {
      "x": -12,
      "y": 63,
      "z": -3,
      "name": "Plant_Leaves_Beech_Max_Support"
    },
    {
      "x": -12,
      "y": 9,
      "z": -2,
      "name": "Wood_Gumboab_Trunk_Full"
    },
    {
      "x": -12,
      "y": 10,
      "z": -2,
      "name": "Wood_Gumboab_Trunk_Full"
    },
    {
      "x": -12,
      "y": 11,
      "z": -2,
      "name": "Wood_Gumboab_Trunk_Full"
    },
    {
      "x": -12,
      "y": 12,
      "z": -2,
      "name": "Wood_Gumboab_Trunk_Full"
    },
    {
      "x": -12,
      "y": 58,
      "z": -2,
      "name": "Plant_Leaves_Beech_Max_Support"
    },
    {
      "x": -12,
      "y": 60,
      "z": -2,
      "name": "Plant_Leaves_Beech_Max_Support"
    },
    {
      "x": -12,
      "y": 61,
      "z": -2,
      "name": "Plant_Leaves_Beech_Max_Support"
    },
    {
      "x": -12,
      "y": 62,
      "z": -2,
      "name": "Plant_Leaves_Beech_Max_Support"
    },
    {
      "x": -12,
      "y": 63,
      "z": -2,
      "name": "Plant_Leaves_Beech_Max_Support"
    },
    {
      "x": -12,
      "y": 9,
      "z": -1,
      "name": "Wood_Gumboab_Trunk_Full"
    },
    {
      "x": -12,
      "y": 10,
      "z": -1,
      "name": "Wood_Gumboab_Trunk_Full"
    },
    {
      "x": -12,
      "y": 11,
      "z": -1,
      "name": "Wood_Gumboab_Trunk_Full"
    },
    {
      "x": -12,
      "y": 12,
      "z": -1,
      "name": "Wood_Gumboab_Trunk_Full"
    },
    {
      "x": -12,
      "y": 59,
      "z": -1,
      "name": "Plant_Leaves_Beech_Max_Support"
    },
    {
      "x": -12,
      "y": 60,
      "z": -1,
      "name": "Plant_Leaves_Beech_Max_Support"
    },
    {
      "x": -12,
      "y": 61,
      "z": -1,
      "name": "Plant_Leaves_Beech_Max_Support"
    },
    {
      "x": -12,
      "y": 62,
      "z": -1,
      "name": "Plant_Leaves_Beech_Max_Support"
    },
    {
      "x": -12,
      "y": 63,
      "z": -1,
      "name": "Plant_Leaves_Beech_Max_Support"
    },
    {
      "x": -12,
      "y": 64,
      "z": -1,
      "name": "Plant_Leaves_Beech_Max_Support"
    },
    {
      "x": -12,
      "y": 65,
      "z": -1,
      "name": "Plant_Leaves_Beech_Max_Support"
    },
    {
      "x": -12,
      "y": 8,
      "z": 0,
      "name": "Wood_Gumboab_Trunk_Full"
    },
    {
      "x": -12,
      "y": 9,
      "z": 0,
      "name": "Wood_Gumboab_Trunk_Full"
    },
    {
      "x": -12,
      "y": 10,
      "z": 0,
      "name": "Wood_Gumboab_Trunk_Full"
    },
    {
      "x": -12,
      "y": 11,
      "z": 0,
      "name": "Wood_Gumboab_Trunk_Full"
    },
    {
      "x": -12,
      "y": 12,
      "z": 0,
      "name": "Wood_Gumboab_Trunk_Full"
    },
    {
      "x": -12,
      "y": 57,
      "z": 0,
      "name": "Wood_Gumboab_Roots"
    },
    {
      "x": -12,
      "y": 58,
      "z": 0,
      "name": "Wood_Gumboab_Trunk_Full"
    },
    {
      "x": -12,
      "y": 59,
      "z": 0,
      "name": "Plant_Leaves_Beech_Max_Support"
    },
    {
      "x": -12,
      "y": 60,
      "z": 0,
      "name": "Plant_Leaves_Beech_Max_Support"
    },
    {
      "x": -12,
      "y": 61,
      "z": 0,
      "name": "Plant_Leaves_Beech_Max_Support"
    },
    {
      "x": -12,
      "y": 62,
      "z": 0,
      "name": "Plant_Leaves_Beech_Max_Support"
    },
    {
      "x": -12,
      "y": 63,
      "z": 0,
      "name": "Plant_Leaves_Beech_Max_Support"
    },
    {
      "x": -12,
      "y": 65,
      "z": 0,
      "name": "Plant_Leaves_Beech_Max_Support"
    },
    {
      "x": -12,
      "y": 8,
      "z": 1,
      "name": "Wood_Gumboab_Trunk_Full"
    },
    {
      "x": -12,
      "y": 9,
      "z": 1,
      "name": "Wood_Gumboab_Trunk_Full"
    },
    {
      "x": -12,
      "y": 10,
      "z": 1,
      "name": "Wood_Gumboab_Trunk_Full"
    },
    {
      "x": -12,
      "y": 11,
      "z": 1,
      "name": "Wood_Gumboab_Trunk_Full"
    },
    {
      "x": -12,
      "y": 58,
      "z": 1,
      "name": "Wood_Gumboab_Trunk_Full"
    },
    {
      "x": -12,
      "y": 59,
      "z": 1,
      "name": "Plant_Leaves_Beech_Max_Support"
    },
    {
      "x": -12,
      "y": 60,
      "z": 1,
      "name": "Plant_Leaves_Beech_Max_Support"
    },
    {
      "x": -12,
      "y": 62,
      "z": 1,
      "name": "Plant_Leaves_Beech_Max_Support"
    },
    {
      "x": -12,
      "y": 63,
      "z": 1,
      "name": "Plant_Leaves_Beech_Max_Support"
    },
    {
      "x": -12,
      "y": 64,
      "z": 1,
      "name": "Plant_Leaves_Beech_Max_Support"
    },
    {
      "x": -12,
      "y": 7,
      "z": 2,
      "name": "Wood_Gumboab_Trunk_Full"
    },
    {
      "x": -12,
      "y": 8,
      "z": 2,
      "name": "Wood_Gumboab_Trunk_Full"
    },
    {
      "x": -12,
      "y": 9,
      "z": 2,
      "name": "Wood_Gumboab_Trunk_Full"
    },
    {
      "x": -12,
      "y": 32,
      "z": 2,
      "name": "Plant_Leaves_Beech_Max_Support"
    },
    {
      "x": -12,
      "y": 33,
      "z": 2,
      "name": "Plant_Leaves_Beech_Max_Support"
    },
    {
      "x": -12,
      "y": 60,
      "z": 2,
      "name": "Plant_Leaves_Beech_Max_Support"
    },
    {
      "x": -12,
      "y": 61,
      "z": 2,
      "name": "Plant_Leaves_Beech_Max_Support"
    },
    {
      "x": -12,
      "y": 62,
      "z": 2,
      "name": "Plant_Leaves_Beech_Max_Support"
    },
    {
      "x": -12,
      "y": 63,
      "z": 2,
      "name": "Plant_Leaves_Beech_Max_Support"
    },
    {
      "x": -12,
      "y": 64,
      "z": 2,
      "name": "Plant_Leaves_Beech_Max_Support"
    },
    {
      "x": -12,
      "y": 65,
      "z": 2,
      "name": "Plant_Leaves_Beech_Max_Support"
    },
    {
      "x": -12,
      "y": 7,
      "z": 3,
      "name": "Wood_Gumboab_Trunk_Full"
    },
    {
      "x": -12,
      "y": 8,
      "z": 3,
      "name": "Wood_Gumboab_Trunk_Full"
    },
    {
      "x": -12,
      "y": 31,
      "z": 3,
      "name": "Plant_Leaves_Beech_Max_Support"
    },
    {
      "x": -12,
      "y": 32,
      "z": 3,
      "name": "Plant_Leaves_Beech_Max_Support"
    },
    {
      "x": -12,
      "y": 33,
      "z": 3,
      "name": "Plant_Leaves_Beech_Max_Support"
    },
    {
      "x": -12,
      "y": 34,
      "z": 3,
      "name": "Plant_Leaves_Beech_Max_Support"
    },
    {
      "x": -12,
      "y": 61,
      "z": 3,
      "name": "Plant_Leaves_Beech_Max_Support"
    },
    {
      "x": -12,
      "y": 62,
      "z": 3,
      "name": "Plant_Leaves_Beech_Max_Support"
    },
    {
      "x": -12,
      "y": 63,
      "z": 3,
      "name": "Plant_Leaves_Beech_Max_Support"
    },
    {
      "x": -12,
      "y": 65,
      "z": 3,
      "name": "Plant_Leaves_Beech_Max_Support"
    },
    {
      "x": -12,
      "y": 32,
      "z": 4,
      "name": "Plant_Leaves_Beech_Max_Support"
    },
    {
      "x": -12,
      "y": 33,
      "z": 4,
      "name": "Plant_Leaves_Beech_Max_Support"
    },
    {
      "x": -12,
      "y": 34,
      "z": 4,
      "name": "Plant_Leaves_Beech_Max_Support"
    },
    {
      "x": -12,
      "y": 35,
      "z": 4,
      "name": "Plant_Leaves_Beech_Max_Support"
    },
    {
      "x": -12,
      "y": 36,
      "z": 4,
      "name": "Plant_Leaves_Beech_Max_Support"
    },
    {
      "x": -12,
      "y": 37,
      "z": 4,
      "name": "Plant_Leaves_Beech_Max_Support"
    },
    {
      "x": -12,
      "y": 38,
      "z": 4,
      "name": "Plant_Leaves_Beech_Max_Support"
    },
    {
      "x": -12,
      "y": 59,
      "z": 4,
      "name": "Plant_Leaves_Beech_Max_Support"
    },
    {
      "x": -12,
      "y": 60,
      "z": 4,
      "name": "Plant_Leaves_Beech_Max_Support"
    },
    {
      "x": -12,
      "y": 61,
      "z": 4,
      "name": "Plant_Leaves_Beech_Max_Support"
    },
    {
      "x": -12,
      "y": 62,
      "z": 4,
      "name": "Plant_Leaves_Beech_Max_Support"
    },
    {
      "x": -12,
      "y": 63,
      "z": 4,
      "name": "Plant_Leaves_Beech_Max_Support"
    },
    {
      "x": -12,
      "y": 64,
      "z": 4,
      "name": "Plant_Leaves_Beech_Max_Support"
    },
    {
      "x": -12,
      "y": 65,
      "z": 4,
      "name": "Plant_Leaves_Beech_Max_Support"
    },
    {
      "x": -12,
      "y": 32,
      "z": 5,
      "name": "Plant_Leaves_Beech_Max_Support"
    },
    {
      "x": -12,
      "y": 33,
      "z": 5,
      "name": "Plant_Leaves_Beech_Max_Support"
    },
    {
      "x": -12,
      "y": 34,
      "z": 5,
      "name": "Plant_Leaves_Beech_Max_Support"
    },
    {
      "x": -12,
      "y": 35,
      "z": 5,
      "name": "Wood_Gumboab_Trunk_Full"
    },
    {
      "x": -12,
      "y": 36,
      "z": 5,
      "name": "Wood_Gumboab_Trunk_Full"
    },
    {
      "x": -12,
      "y": 37,
      "z": 5,
      "name": "Plant_Leaves_Beech_Max_Support"
    },
    {
      "x": -12,
      "y": 38,
      "z": 5,
      "name": "Plant_Leaves_Beech_Max_Support"
    },
    {
      "x": -12,
      "y": 58,
      "z": 5,
      "name": "Plant_Leaves_Beech_Max_Support"
    },
    {
      "x": -12,
      "y": 59,
      "z": 5,
      "name": "Plant_Leaves_Beech_Max_Support"
    },
    {
      "x": -12,
      "y": 60,
      "z": 5,
      "name": "Plant_Leaves_Beech_Max_Support"
    },
    {
      "x": -12,
      "y": 61,
      "z": 5,
      "name": "Plant_Leaves_Beech_Max_Support"
    },
    {
      "x": -12,
      "y": 62,
      "z": 5,
      "name": "Plant_Leaves_Beech_Max_Support"
    },
    {
      "x": -12,
      "y": 63,
      "z": 5,
      "name": "Plant_Leaves_Beech_Max_Support"
    },
    {
      "x": -12,
      "y": 64,
      "z": 5,
      "name": "Plant_Leaves_Beech_Max_Support"
    },
    {
      "x": -12,
      "y": 31,
      "z": 6,
      "name": "Wood_Gumboab_Trunk_Full"
    },
    {
      "x": -12,
      "y": 32,
      "z": 6,
      "name": "Wood_Gumboab_Trunk_Full"
    },
    {
      "x": -12,
      "y": 33,
      "z": 6,
      "name": "Plant_Leaves_Beech_Max_Support"
    },
    {
      "x": -12,
      "y": 34,
      "z": 6,
      "name": "Plant_Leaves_Beech_Max_Support"
    },
    {
      "x": -12,
      "y": 35,
      "z": 6,
      "name": "Plant_Leaves_Beech_Max_Support"
    },
    {
      "x": -12,
      "y": 36,
      "z": 6,
      "name": "Plant_Leaves_Beech_Max_Support"
    },
    {
      "x": -12,
      "y": 37,
      "z": 6,
      "name": "Plant_Leaves_Beech_Max_Support"
    },
    {
      "x": -12,
      "y": 38,
      "z": 6,
      "name": "Plant_Leaves_Beech_Max_Support"
    },
    {
      "x": -12,
      "y": 40,
      "z": 6,
      "name": "Plant_Leaves_Beech_Max_Support"
    },
    {
      "x": -12,
      "y": 57,
      "z": 6,
      "name": "Plant_Leaves_Beech_Max_Support"
    },
    {
      "x": -12,
      "y": 58,
      "z": 6,
      "name": "Wood_Gumboab_Trunk_Full"
    },
    {
      "x": -12,
      "y": 60,
      "z": 6,
      "name": "Plant_Leaves_Beech_Max_Support"
    },
    {
      "x": -12,
      "y": 61,
      "z": 6,
      "name": "Plant_Leaves_Beech_Max_Support"
    },
    {
      "x": -12,
      "y": 62,
      "z": 6,
      "name": "Plant_Leaves_Beech_Max_Support"
    },
    {
      "x": -12,
      "y": 63,
      "z": 6,
      "name": "Plant_Leaves_Beech_Max_Support"
    },
    {
      "x": -12,
      "y": 64,
      "z": 6,
      "name": "Plant_Leaves_Beech_Max_Support"
    },
    {
      "x": -12,
      "y": 31,
      "z": 7,
      "name": "Plant_Leaves_Beech_Max_Support"
    },
    {
      "x": -12,
      "y": 32,
      "z": 7,
      "name": "Wood_Gumboab_Trunk_Full"
    },
    {
      "x": -12,
      "y": 33,
      "z": 7,
      "name": "Plant_Leaves_Beech_Max_Support"
    },
    {
      "x": -12,
      "y": 34,
      "z": 7,
      "name": "Plant_Leaves_Beech_Max_Support"
    },
    {
      "x": -12,
      "y": 35,
      "z": 7,
      "name": "Plant_Leaves_Beech_Max_Support"
    },
    {
      "x": -12,
      "y": 36,
      "z": 7,
      "name": "Plant_Leaves_Beech_Max_Support"
    },
    {
      "x": -12,
      "y": 37,
      "z": 7,
      "name": "Plant_Leaves_Beech_Max_Support"
    },
    {
      "x": -12,
      "y": 38,
      "z": 7,
      "name": "Plant_Leaves_Beech_Max_Support"
    },
    {
      "x": -12,
      "y": 57,
      "z": 7,
      "name": "Plant_Leaves_Beech_Max_Support"
    },
    {
      "x": -12,
      "y": 59,
      "z": 7,
      "name": "Plant_Leaves_Beech_Max_Support"
    },
    {
      "x": -12,
      "y": 60,
      "z": 7,
      "name": "Plant_Leaves_Beech_Max_Support"
    },
    {
      "x": -12,
      "y": 61,
      "z": 7,
      "name": "Plant_Leaves_Beech_Max_Support"
    },
    {
      "x": -12,
      "y": 62,
      "z": 7,
      "name": "Plant_Leaves_Beech_Max_Support"
    },
    {
      "x": -12,
      "y": 63,
      "z": 7,
      "name": "Plant_Leaves_Beech_Max_Support"
    },
    {
      "x": -12,
      "y": 32,
      "z": 8,
      "name": "Plant_Leaves_Beech_Max_Support"
    },
    {
      "x": -12,
      "y": 33,
      "z": 8,
      "name": "Wood_Gumboab_Trunk_Full"
    },
    {
      "x": -12,
      "y": 34,
      "z": 8,
      "name": "Plant_Leaves_Beech_Max_Support"
    },
    {
      "x": -12,
      "y": 35,
      "z": 8,
      "name": "Plant_Leaves_Beech_Max_Support"
    },
    {
      "x": -12,
      "y": 36,
      "z": 8,
      "name": "Plant_Leaves_Beech_Max_Support"
    },
    {
      "x": -12,
      "y": 37,
      "z": 8,
      "name": "Plant_Leaves_Beech_Max_Support"
    },
    {
      "x": -12,
      "y": 38,
      "z": 8,
      "name": "Plant_Leaves_Beech_Max_Support"
    },
    {
      "x": -12,
      "y": 39,
      "z": 8,
      "name": "Plant_Leaves_Beech_Max_Support"
    },
    {
      "x": -12,
      "y": 58,
      "z": 8,
      "name": "Plant_Leaves_Beech_Max_Support"
    },
    {
      "x": -12,
      "y": 60,
      "z": 8,
      "name": "Plant_Leaves_Beech_Max_Support"
    },
    {
      "x": -12,
      "y": 61,
      "z": 8,
      "name": "Plant_Leaves_Beech_Max_Support"
    },
    {
      "x": -12,
      "y": 62,
      "z": 8,
      "name": "Plant_Leaves_Beech_Max_Support"
    },
    {
      "x": -12,
      "y": 63,
      "z": 8,
      "name": "Plant_Leaves_Beech_Max_Support"
    },
    {
      "x": -12,
      "y": 65,
      "z": 8,
      "name": "Plant_Leaves_Beech_Max_Support"
    },
    {
      "x": -12,
      "y": 32,
      "z": 9,
      "name": "Plant_Leaves_Beech_Max_Support"
    },
    {
      "x": -12,
      "y": 33,
      "z": 9,
      "name": "Plant_Leaves_Beech_Max_Support"
    },
    {
      "x": -12,
      "y": 34,
      "z": 9,
      "name": "Plant_Leaves_Beech_Max_Support"
    },
    {
      "x": -12,
      "y": 35,
      "z": 9,
      "name": "Plant_Leaves_Beech_Max_Support"
    },
    {
      "x": -12,
      "y": 36,
      "z": 9,
      "name": "Plant_Leaves_Beech_Max_Support"
    },
    {
      "x": -12,
      "y": 37,
      "z": 9,
      "name": "Plant_Leaves_Beech_Max_Support"
    },
    {
      "x": -12,
      "y": 38,
      "z": 9,
      "name": "Plant_Leaves_Beech_Max_Support"
    },
    {
      "x": -12,
      "y": 39,
      "z": 9,
      "name": "Plant_Leaves_Beech_Max_Support"
    },
    {
      "x": -12,
      "y": 60,
      "z": 9,
      "name": "Plant_Leaves_Beech_Max_Support"
    },
    {
      "x": -12,
      "y": 61,
      "z": 9,
      "name": "Plant_Leaves_Beech_Max_Support"
    },
    {
      "x": -12,
      "y": 62,
      "z": 9,
      "name": "Plant_Leaves_Beech_Max_Support"
    },
    {
      "x": -12,
      "y": 63,
      "z": 9,
      "name": "Plant_Leaves_Beech_Max_Support"
    },
    {
      "x": -12,
      "y": 32,
      "z": 10,
      "name": "Plant_Leaves_Beech_Max_Support"
    },
    {
      "x": -12,
      "y": 33,
      "z": 10,
      "name": "Plant_Leaves_Beech_Max_Support"
    },
    {
      "x": -12,
      "y": 34,
      "z": 10,
      "name": "Plant_Leaves_Beech_Max_Support"
    },
    {
      "x": -12,
      "y": 35,
      "z": 10,
      "name": "Plant_Leaves_Beech_Max_Support"
    },
    {
      "x": -12,
      "y": 36,
      "z": 10,
      "name": "Plant_Leaves_Beech_Max_Support"
    },
    {
      "x": -12,
      "y": 37,
      "z": 10,
      "name": "Plant_Leaves_Beech_Max_Support"
    },
    {
      "x": -12,
      "y": 38,
      "z": 10,
      "name": "Plant_Leaves_Beech_Max_Support"
    },
    {
      "x": -12,
      "y": 39,
      "z": 10,
      "name": "Plant_Leaves_Beech_Max_Support"
    },
    {
      "x": -12,
      "y": 59,
      "z": 10,
      "name": "Plant_Leaves_Beech_Max_Support"
    },
    {
      "x": -12,
      "y": 61,
      "z": 10,
      "name": "Plant_Leaves_Beech_Max_Support"
    },
    {
      "x": -12,
      "y": 31,
      "z": 11,
      "name": "Plant_Leaves_Beech_Max_Support"
    },
    {
      "x": -12,
      "y": 32,
      "z": 11,
      "name": "Plant_Leaves_Beech_Max_Support"
    },
    {
      "x": -12,
      "y": 33,
      "z": 11,
      "name": "Plant_Leaves_Beech_Max_Support"
    },
    {
      "x": -12,
      "y": 34,
      "z": 11,
      "name": "Plant_Leaves_Beech_Max_Support"
    },
    {
      "x": -12,
      "y": 35,
      "z": 11,
      "name": "Plant_Leaves_Beech_Max_Support"
    },
    {
      "x": -12,
      "y": 36,
      "z": 11,
      "name": "Plant_Leaves_Beech_Max_Support"
    },
    {
      "x": -12,
      "y": 37,
      "z": 11,
      "name": "Plant_Leaves_Beech_Max_Support"
    },
    {
      "x": -12,
      "y": 38,
      "z": 11,
      "name": "Plant_Leaves_Beech_Max_Support"
    },
    {
      "x": -12,
      "y": 33,
      "z": 12,
      "name": "Plant_Leaves_Beech_Max_Support"
    },
    {
      "x": -12,
      "y": 34,
      "z": 12,
      "name": "Plant_Leaves_Beech_Max_Support"
    },
    {
      "x": -12,
      "y": 36,
      "z": 12,
      "name": "Plant_Leaves_Beech_Max_Support"
    },
    {
      "x": -12,
      "y": 33,
      "z": 13,
      "name": "Plant_Leaves_Beech_Max_Support"
    },
    {
      "x": -11,
      "y": 6,
      "z": -9,
      "name": "Wood_Gumboab_Roots"
    },
    {
      "x": -11,
      "y": 7,
      "z": -9,
      "name": "Wood_Gumboab_Trunk_Full"
    },
    {
      "x": -11,
      "y": 8,
      "z": -9,
      "name": "Wood_Gumboab_Trunk_Full"
    },
    {
      "x": -11,
      "y": 8,
      "z": -8,
      "name": "Wood_Gumboab_Trunk_Full"
    },
    {
      "x": -11,
      "y": 9,
      "z": -8,
      "name": "Wood_Gumboab_Trunk_Full"
    },
    {
      "x": -11,
      "y": 10,
      "z": -8,
      "name": "Wood_Gumboab_Trunk_Full"
    },
    {
      "x": -11,
      "y": 9,
      "z": -7,
      "name": "Wood_Gumboab_Trunk_Full"
    },
    {
      "x": -11,
      "y": 10,
      "z": -7,
      "name": "Wood_Gumboab_Trunk_Full"
    },
    {
      "x": -11,
      "y": 11,
      "z": -7,
      "name": "Wood_Gumboab_Trunk_Full"
    },
    {
      "x": -11,
      "y": 59,
      "z": -7,
      "name": "Plant_Leaves_Beech_Max_Support"
    },
    {
      "x": -11,
      "y": 61,
      "z": -7,
      "name": "Plant_Leaves_Beech_Max_Support"
    },
    {
      "x": -11,
      "y": 10,
      "z": -6,
      "name": "Wood_Gumboab_Trunk_Full"
    },
    {
      "x": -11,
      "y": 11,
      "z": -6,
      "name": "Wood_Gumboab_Trunk_Full"
    },
    {
      "x": -11,
      "y": 12,
      "z": -6,
      "name": "Wood_Gumboab_Trunk_Full"
    },
    {
      "x": -11,
      "y": 58,
      "z": -6,
      "name": "Plant_Leaves_Beech_Max_Support"
    },
    {
      "x": -11,
      "y": 59,
      "z": -6,
      "name": "Plant_Leaves_Beech_Max_Support"
    },
    {
      "x": -11,
      "y": 62,
      "z": -6,
      "name": "Plant_Leaves_Beech_Max_Support"
    },
    {
      "x": -11,
      "y": 10,
      "z": -5,
      "name": "Wood_Gumboab_Trunk_Full"
    },
    {
      "x": -11,
      "y": 11,
      "z": -5,
      "name": "Wood_Gumboab_Trunk_Full"
    },
    {
      "x": -11,
      "y": 12,
      "z": -5,
      "name": "Wood_Gumboab_Trunk_Full"
    },
    {
      "x": -11,
      "y": 13,
      "z": -5,
      "name": "Wood_Gumboab_Trunk_Full"
    },
    {
      "x": -11,
      "y": 57,
      "z": -5,
      "name": "Plant_Leaves_Beech_Max_Support"
    },
    {
      "x": -11,
      "y": 58,
      "z": -5,
      "name": "Plant_Leaves_Beech_Max_Support"
    },
    {
      "x": -11,
      "y": 59,
      "z": -5,
      "name": "Plant_Leaves_Beech_Max_Support"
    },
    {
      "x": -11,
      "y": 60,
      "z": -5,
      "name": "Plant_Leaves_Beech_Max_Support"
    },
    {
      "x": -11,
      "y": 61,
      "z": -5,
      "name": "Plant_Leaves_Beech_Max_Support"
    },
    {
      "x": -11,
      "y": 63,
      "z": -5,
      "name": "Plant_Leaves_Beech_Max_Support"
    },
    {
      "x": -11,
      "y": 11,
      "z": -4,
      "name": "Wood_Gumboab_Trunk_Full"
    },
    {
      "x": -11,
      "y": 12,
      "z": -4,
      "name": "Wood_Gumboab_Trunk_Full"
    },
    {
      "x": -11,
      "y": 13,
      "z": -4,
      "name": "Wood_Gumboab_Trunk_Full"
    },
    {
      "x": -11,
      "y": 57,
      "z": -4,
      "name": "Plant_Leaves_Beech_Max_Support"
    },
    {
      "x": -11,
      "y": 58,
      "z": -4,
      "name": "Plant_Leaves_Beech_Max_Support"
    },
    {
      "x": -11,
      "y": 59,
      "z": -4,
      "name": "Plant_Leaves_Beech_Max_Support"
    },
    {
      "x": -11,
      "y": 60,
      "z": -4,
      "name": "Plant_Leaves_Beech_Max_Support"
    },
    {
      "x": -11,
      "y": 61,
      "z": -4,
      "name": "Plant_Leaves_Beech_Max_Support"
    },
    {
      "x": -11,
      "y": 62,
      "z": -4,
      "name": "Plant_Leaves_Beech_Max_Support"
    },
    {
      "x": -11,
      "y": 63,
      "z": -4,
      "name": "Plant_Leaves_Beech_Max_Support"
    },
    {
      "x": -11,
      "y": 12,
      "z": -3,
      "name": "Wood_Gumboab_Trunk_Full"
    },
    {
      "x": -11,
      "y": 13,
      "z": -3,
      "name": "Wood_Gumboab_Trunk_Full"
    },
    {
      "x": -11,
      "y": 57,
      "z": -3,
      "name": "Plant_Leaves_Beech_Max_Support"
    },
    {
      "x": -11,
      "y": 59,
      "z": -3,
      "name": "Plant_Leaves_Beech_Max_Support"
    },
    {
      "x": -11,
      "y": 60,
      "z": -3,
      "name": "Plant_Leaves_Beech_Max_Support"
    },
    {
      "x": -11,
      "y": 61,
      "z": -3,
      "name": "Plant_Leaves_Beech_Max_Support"
    },
    {
      "x": -11,
      "y": 62,
      "z": -3,
      "name": "Plant_Leaves_Beech_Max_Support"
    },
    {
      "x": -11,
      "y": 63,
      "z": -3,
      "name": "Plant_Leaves_Beech_Max_Support"
    },
    {
      "x": -11,
      "y": 64,
      "z": -3,
      "name": "Plant_Leaves_Beech_Max_Support"
    },
    {
      "x": -11,
      "y": 10,
      "z": -2,
      "name": "Wood_Gumboab_Trunk_Full"
    },
    {
      "x": -11,
      "y": 11,
      "z": -2,
      "name": "Wood_Gumboab_Trunk_Full"
    },
    {
      "x": -11,
      "y": 12,
      "z": -2,
      "name": "Wood_Gumboab_Trunk_Full"
    },
    {
      "x": -11,
      "y": 13,
      "z": -2,
      "name": "Wood_Gumboab_Trunk_Full"
    },
    {
      "x": -11,
      "y": 58,
      "z": -2,
      "name": "Plant_Leaves_Beech_Max_Support"
    },
    {
      "x": -11,
      "y": 60,
      "z": -2,
      "name": "Plant_Leaves_Beech_Max_Support"
    },
    {
      "x": -11,
      "y": 61,
      "z": -2,
      "name": "Plant_Leaves_Beech_Max_Support"
    },
    {
      "x": -11,
      "y": 62,
      "z": -2,
      "name": "Plant_Leaves_Beech_Max_Support"
    },
    {
      "x": -11,
      "y": 63,
      "z": -2,
      "name": "Plant_Leaves_Beech_Max_Support"
    },
    {
      "x": -11,
      "y": 9,
      "z": -1,
      "name": "Wood_Gumboab_Trunk_Full"
    },
    {
      "x": -11,
      "y": 10,
      "z": -1,
      "name": "Wood_Gumboab_Trunk_Full"
    },
    {
      "x": -11,
      "y": 11,
      "z": -1,
      "name": "Wood_Gumboab_Trunk_Full"
    },
    {
      "x": -11,
      "y": 12,
      "z": -1,
      "name": "Wood_Gumboab_Trunk_Full"
    },
    {
      "x": -11,
      "y": 13,
      "z": -1,
      "name": "Wood_Gumboab_Trunk_Full"
    },
    {
      "x": -11,
      "y": 58,
      "z": -1,
      "name": "Wood_Gumboab_Trunk_Full"
    },
    {
      "x": -11,
      "y": 59,
      "z": -1,
      "name": "Wood_Gumboab_Trunk_Full"
    },
    {
      "x": -11,
      "y": 61,
      "z": -1,
      "name": "Plant_Leaves_Beech_Max_Support"
    },
    {
      "x": -11,
      "y": 62,
      "z": -1,
      "name": "Plant_Leaves_Beech_Max_Support"
    },
    {
      "x": -11,
      "y": 63,
      "z": -1,
      "name": "Plant_Leaves_Beech_Max_Support"
    },
    {
      "x": -11,
      "y": 64,
      "z": -1,
      "name": "Plant_Leaves_Beech_Max_Support"
    },
    {
      "x": -11,
      "y": 65,
      "z": -1,
      "name": "Plant_Leaves_Beech_Max_Support"
    },
    {
      "x": -11,
      "y": 9,
      "z": 0,
      "name": "Wood_Gumboab_Trunk_Full"
    },
    {
      "x": -11,
      "y": 10,
      "z": 0,
      "name": "Wood_Gumboab_Trunk_Full"
    },
    {
      "x": -11,
      "y": 11,
      "z": 0,
      "name": "Wood_Gumboab_Trunk_Full"
    },
    {
      "x": -11,
      "y": 12,
      "z": 0,
      "name": "Wood_Gumboab_Trunk_Full"
    },
    {
      "x": -11,
      "y": 13,
      "z": 0,
      "name": "Wood_Gumboab_Trunk_Full"
    },
    {
      "x": -11,
      "y": 58,
      "z": 0,
      "name": "Wood_Gumboab_Trunk_Full"
    },
    {
      "x": -11,
      "y": 59,
      "z": 0,
      "name": "Wood_Gumboab_Trunk_Full"
    },
    {
      "x": -11,
      "y": 60,
      "z": 0,
      "name": "Plant_Leaves_Beech_Max_Support"
    },
    {
      "x": -11,
      "y": 61,
      "z": 0,
      "name": "Plant_Leaves_Beech_Max_Support"
    },
    {
      "x": -11,
      "y": 62,
      "z": 0,
      "name": "Plant_Leaves_Beech_Max_Support"
    },
    {
      "x": -11,
      "y": 63,
      "z": 0,
      "name": "Plant_Leaves_Beech_Max_Support"
    },
    {
      "x": -11,
      "y": 64,
      "z": 0,
      "name": "Plant_Leaves_Beech_Max_Support"
    },
    {
      "x": -11,
      "y": 65,
      "z": 0,
      "name": "Plant_Leaves_Beech_Max_Support"
    },
    {
      "x": -11,
      "y": 9,
      "z": 1,
      "name": "Wood_Gumboab_Trunk_Full"
    },
    {
      "x": -11,
      "y": 10,
      "z": 1,
      "name": "Wood_Gumboab_Trunk_Full"
    },
    {
      "x": -11,
      "y": 11,
      "z": 1,
      "name": "Wood_Gumboab_Trunk_Full"
    },
    {
      "x": -11,
      "y": 32,
      "z": 1,
      "name": "Plant_Leaves_Beech_Max_Support"
    },
    {
      "x": -11,
      "y": 58,
      "z": 1,
      "name": "Plant_Leaves_Beech_Max_Support"
    },
    {
      "x": -11,
      "y": 59,
      "z": 1,
      "name": "Plant_Leaves_Beech_Max_Support"
    },
    {
      "x": -11,
      "y": 60,
      "z": 1,
      "name": "Plant_Leaves_Beech_Max_Support"
    },
    {
      "x": -11,
      "y": 61,
      "z": 1,
      "name": "Plant_Leaves_Beech_Max_Support"
    },
    {
      "x": -11,
      "y": 62,
      "z": 1,
      "name": "Plant_Leaves_Beech_Max_Support"
    },
    {
      "x": -11,
      "y": 63,
      "z": 1,
      "name": "Plant_Leaves_Beech_Max_Support"
    },
    {
      "x": -11,
      "y": 64,
      "z": 1,
      "name": "Plant_Leaves_Beech_Max_Support"
    },
    {
      "x": -11,
      "y": 31,
      "z": 2,
      "name": "Plant_Leaves_Beech_Max_Support"
    },
    {
      "x": -11,
      "y": 32,
      "z": 2,
      "name": "Plant_Leaves_Beech_Max_Support"
    },
    {
      "x": -11,
      "y": 33,
      "z": 2,
      "name": "Plant_Leaves_Beech_Max_Support"
    },
    {
      "x": -11,
      "y": 34,
      "z": 2,
      "name": "Plant_Leaves_Beech_Max_Support"
    },
    {
      "x": -11,
      "y": 59,
      "z": 2,
      "name": "Plant_Leaves_Beech_Max_Support"
    },
    {
      "x": -11,
      "y": 60,
      "z": 2,
      "name": "Plant_Leaves_Beech_Max_Support"
    },
    {
      "x": -11,
      "y": 61,
      "z": 2,
      "name": "Plant_Leaves_Beech_Max_Support"
    },
    {
      "x": -11,
      "y": 62,
      "z": 2,
      "name": "Plant_Leaves_Beech_Max_Support"
    },
    {
      "x": -11,
      "y": 63,
      "z": 2,
      "name": "Plant_Leaves_Beech_Max_Support"
    },
    {
      "x": -11,
      "y": 30,
      "z": 3,
      "name": "Plant_Leaves_Beech_Max_Support"
    },
    {
      "x": -11,
      "y": 31,
      "z": 3,
      "name": "Plant_Leaves_Beech_Max_Support"
    },
    {
      "x": -11,
      "y": 32,
      "z": 3,
      "name": "Plant_Leaves_Beech_Max_Support"
    },
    {
      "x": -11,
      "y": 33,
      "z": 3,
      "name": "Plant_Leaves_Beech_Max_Support"
    },
    {
      "x": -11,
      "y": 34,
      "z": 3,
      "name": "Plant_Leaves_Beech_Max_Support"
    },
    {
      "x": -11,
      "y": 35,
      "z": 3,
      "name": "Plant_Leaves_Beech_Max_Support"
    },
    {
      "x": -11,
      "y": 59,
      "z": 3,
      "name": "Plant_Leaves_Beech_Max_Support"
    },
    {
      "x": -11,
      "y": 60,
      "z": 3,
      "name": "Plant_Leaves_Beech_Max_Support"
    },
    {
      "x": -11,
      "y": 61,
      "z": 3,
      "name": "Plant_Leaves_Beech_Max_Support"
    },
    {
      "x": -11,
      "y": 62,
      "z": 3,
      "name": "Plant_Leaves_Beech_Max_Support"
    },
    {
      "x": -11,
      "y": 63,
      "z": 3,
      "name": "Plant_Leaves_Beech_Max_Support"
    },
    {
      "x": -11,
      "y": 64,
      "z": 3,
      "name": "Plant_Leaves_Beech_Max_Support"
    },
    {
      "x": -11,
      "y": 65,
      "z": 3,
      "name": "Plant_Leaves_Beech_Max_Support"
    },
    {
      "x": -11,
      "y": 6,
      "z": 4,
      "name": "Wood_Gumboab_Trunk_Full"
    },
    {
      "x": -11,
      "y": 7,
      "z": 4,
      "name": "Wood_Gumboab_Trunk_Full"
    },
    {
      "x": -11,
      "y": 8,
      "z": 4,
      "name": "Wood_Gumboab_Trunk_Full"
    },
    {
      "x": -11,
      "y": 31,
      "z": 4,
      "name": "Plant_Leaves_Beech_Max_Support"
    },
    {
      "x": -11,
      "y": 32,
      "z": 4,
      "name": "Plant_Leaves_Beech_Max_Support"
    },
    {
      "x": -11,
      "y": 33,
      "z": 4,
      "name": "Plant_Leaves_Beech_Max_Support"
    },
    {
      "x": -11,
      "y": 34,
      "z": 4,
      "name": "Plant_Leaves_Beech_Max_Support"
    },
    {
      "x": -11,
      "y": 35,
      "z": 4,
      "name": "Plant_Leaves_Beech_Max_Support"
    },
    {
      "x": -11,
      "y": 37,
      "z": 4,
      "name": "Plant_Leaves_Beech_Max_Support"
    },
    {
      "x": -11,
      "y": 58,
      "z": 4,
      "name": "Plant_Leaves_Beech_Max_Support"
    },
    {
      "x": -11,
      "y": 59,
      "z": 4,
      "name": "Plant_Leaves_Beech_Max_Support"
    },
    {
      "x": -11,
      "y": 61,
      "z": 4,
      "name": "Plant_Leaves_Beech_Max_Support"
    },
    {
      "x": -11,
      "y": 62,
      "z": 4,
      "name": "Plant_Leaves_Beech_Max_Support"
    },
    {
      "x": -11,
      "y": 63,
      "z": 4,
      "name": "Plant_Leaves_Beech_Max_Support"
    },
    {
      "x": -11,
      "y": 64,
      "z": 4,
      "name": "Plant_Leaves_Beech_Max_Support"
    },
    {
      "x": -11,
      "y": 65,
      "z": 4,
      "name": "Plant_Leaves_Beech_Max_Support"
    },
    {
      "x": -11,
      "y": 5,
      "z": 5,
      "name": "Wood_Gumboab_Trunk_Full"
    },
    {
      "x": -11,
      "y": 6,
      "z": 5,
      "name": "Wood_Gumboab_Trunk_Full"
    },
    {
      "x": -11,
      "y": 7,
      "z": 5,
      "name": "Wood_Gumboab_Trunk_Full"
    },
    {
      "x": -11,
      "y": 8,
      "z": 5,
      "name": "Wood_Gumboab_Trunk_Full"
    },
    {
      "x": -11,
      "y": 31,
      "z": 5,
      "name": "Plant_Leaves_Beech_Max_Support"
    },
    {
      "x": -11,
      "y": 32,
      "z": 5,
      "name": "Plant_Leaves_Beech_Max_Support"
    },
    {
      "x": -11,
      "y": 33,
      "z": 5,
      "name": "Plant_Leaves_Beech_Max_Support"
    },
    {
      "x": -11,
      "y": 34,
      "z": 5,
      "name": "Plant_Leaves_Beech_Max_Support"
    },
    {
      "x": -11,
      "y": 35,
      "z": 5,
      "name": "Plant_Leaves_Beech_Max_Support"
    },
    {
      "x": -11,
      "y": 36,
      "z": 5,
      "name": "Plant_Leaves_Beech_Max_Support"
    },
    {
      "x": -11,
      "y": 37,
      "z": 5,
      "name": "Plant_Leaves_Beech_Max_Support"
    },
    {
      "x": -11,
      "y": 39,
      "z": 5,
      "name": "Plant_Leaves_Beech_Max_Support"
    },
    {
      "x": -11,
      "y": 58,
      "z": 5,
      "name": "Plant_Leaves_Beech_Max_Support"
    },
    {
      "x": -11,
      "y": 59,
      "z": 5,
      "name": "Plant_Leaves_Beech_Max_Support"
    },
    {
      "x": -11,
      "y": 61,
      "z": 5,
      "name": "Plant_Leaves_Beech_Max_Support"
    },
    {
      "x": -11,
      "y": 63,
      "z": 5,
      "name": "Plant_Leaves_Beech_Max_Support"
    },
    {
      "x": -11,
      "y": 64,
      "z": 5,
      "name": "Plant_Leaves_Beech_Max_Support"
    },
    {
      "x": -11,
      "y": 4,
      "z": 6,
      "name": "Wood_Gumboab_Trunk_Full"
    },
    {
      "x": -11,
      "y": 5,
      "z": 6,
      "name": "Wood_Gumboab_Trunk_Full"
    },
    {
      "x": -11,
      "y": 6,
      "z": 6,
      "name": "Wood_Gumboab_Trunk_Full"
    },
    {
      "x": -11,
      "y": 7,
      "z": 6,
      "name": "Wood_Gumboab_Trunk_Full"
    },
    {
      "x": -11,
      "y": 31,
      "z": 6,
      "name": "Wood_Gumboab_Trunk_Full"
    },
    {
      "x": -11,
      "y": 32,
      "z": 6,
      "name": "Wood_Gumboab_Trunk_Full"
    },
    {
      "x": -11,
      "y": 33,
      "z": 6,
      "name": "Plant_Leaves_Beech_Max_Support"
    },
    {
      "x": -11,
      "y": 34,
      "z": 6,
      "name": "Plant_Leaves_Beech_Max_Support"
    },
    {
      "x": -11,
      "y": 35,
      "z": 6,
      "name": "Plant_Leaves_Beech_Max_Support"
    },
    {
      "x": -11,
      "y": 36,
      "z": 6,
      "name": "Plant_Leaves_Beech_Max_Support"
    },
    {
      "x": -11,
      "y": 38,
      "z": 6,
      "name": "Plant_Leaves_Beech_Max_Support"
    },
    {
      "x": -11,
      "y": 58,
      "z": 6,
      "name": "Wood_Gumboab_Trunk_Full"
    },
    {
      "x": -11,
      "y": 59,
      "z": 6,
      "name": "Plant_Leaves_Beech_Max_Support"
    },
    {
      "x": -11,
      "y": 60,
      "z": 6,
      "name": "Plant_Leaves_Beech_Max_Support"
    },
    {
      "x": -11,
      "y": 61,
      "z": 6,
      "name": "Plant_Leaves_Beech_Max_Support"
    },
    {
      "x": -11,
      "y": 62,
      "z": 6,
      "name": "Plant_Leaves_Beech_Max_Support"
    },
    {
      "x": -11,
      "y": 63,
      "z": 6,
      "name": "Plant_Leaves_Beech_Max_Support"
    },
    {
      "x": -11,
      "y": 64,
      "z": 6,
      "name": "Plant_Leaves_Beech_Max_Support"
    },
    {
      "x": -11,
      "y": 3,
      "z": 7,
      "name": "Wood_Gumboab_Trunk_Full"
    },
    {
      "x": -11,
      "y": 4,
      "z": 7,
      "name": "Wood_Gumboab_Trunk_Full"
    },
    {
      "x": -11,
      "y": 5,
      "z": 7,
      "name": "Wood_Gumboab_Trunk_Full"
    },
    {
      "x": -11,
      "y": 6,
      "z": 7,
      "name": "Wood_Gumboab_Trunk_Full"
    },
    {
      "x": -11,
      "y": 31,
      "z": 7,
      "name": "Plant_Leaves_Beech_Max_Support"
    },
    {
      "x": -11,
      "y": 32,
      "z": 7,
      "name": "Plant_Leaves_Beech_Max_Support"
    },
    {
      "x": -11,
      "y": 33,
      "z": 7,
      "name": "Plant_Leaves_Beech_Max_Support"
    },
    {
      "x": -11,
      "y": 34,
      "z": 7,
      "name": "Plant_Leaves_Beech_Max_Support"
    },
    {
      "x": -11,
      "y": 35,
      "z": 7,
      "name": "Plant_Leaves_Beech_Max_Support"
    },
    {
      "x": -11,
      "y": 36,
      "z": 7,
      "name": "Plant_Leaves_Beech_Max_Support"
    },
    {
      "x": -11,
      "y": 37,
      "z": 7,
      "name": "Plant_Leaves_Beech_Max_Support"
    },
    {
      "x": -11,
      "y": 38,
      "z": 7,
      "name": "Plant_Leaves_Beech_Max_Support"
    },
    {
      "x": -11,
      "y": 39,
      "z": 7,
      "name": "Plant_Leaves_Beech_Max_Support"
    },
    {
      "x": -11,
      "y": 40,
      "z": 7,
      "name": "Plant_Leaves_Beech_Max_Support"
    },
    {
      "x": -11,
      "y": 57,
      "z": 7,
      "name": "Plant_Leaves_Beech_Max_Support"
    },
    {
      "x": -11,
      "y": 58,
      "z": 7,
      "name": "Plant_Leaves_Beech_Max_Support"
    },
    {
      "x": -11,
      "y": 59,
      "z": 7,
      "name": "Plant_Leaves_Beech_Max_Support"
    },
    {
      "x": -11,
      "y": 60,
      "z": 7,
      "name": "Plant_Leaves_Beech_Max_Support"
    },
    {
      "x": -11,
      "y": 61,
      "z": 7,
      "name": "Plant_Leaves_Beech_Max_Support"
    },
    {
      "x": -11,
      "y": 62,
      "z": 7,
      "name": "Plant_Leaves_Beech_Max_Support"
    },
    {
      "x": -11,
      "y": 63,
      "z": 7,
      "name": "Plant_Leaves_Beech_Max_Support"
    },
    {
      "x": -11,
      "y": 65,
      "z": 7,
      "name": "Plant_Leaves_Beech_Max_Support"
    },
    {
      "x": -11,
      "y": 3,
      "z": 8,
      "name": "Wood_Gumboab_Trunk_Full"
    },
    {
      "x": -11,
      "y": 31,
      "z": 8,
      "name": "Plant_Leaves_Beech_Max_Support"
    },
    {
      "x": -11,
      "y": 32,
      "z": 8,
      "name": "Plant_Leaves_Beech_Max_Support"
    },
    {
      "x": -11,
      "y": 33,
      "z": 8,
      "name": "Plant_Leaves_Beech_Max_Support"
    },
    {
      "x": -11,
      "y": 34,
      "z": 8,
      "name": "Plant_Leaves_Beech_Max_Support"
    },
    {
      "x": -11,
      "y": 35,
      "z": 8,
      "name": "Plant_Leaves_Beech_Max_Support"
