{
  "version": 8,
  "blockIdVersion": 11,
  "anchorX": 3,
  "anchorY": 30,
  "anchorZ": 4,
  "blocks": [
    {
      "x": -37,
      "y": 75,
      "z": 14,
      "name": "Plant_Leaves_Jungle_Max_Support"
    },
    {
      "x": -37,
      "y": 74,
      "z": 15,
      "name": "Plant_Leaves_Jungle_Max_Support"
    },
    {
      "x": -36,
      "y": 75,
      "z": 12,
      "name": "Plant_Leaves_Jungle_Max_Support"
    },
    {
      "x": -36,
      "y": 75,
      "z": 13,
      "name": "Plant_Leaves_Jungle_Max_Support"
    },
    {
      "x": -36,
      "y": 72,
      "z": 14,
      "name": "Plant_Leaves_Jungle_Max_Support"
    },
    {
      "x": -36,
      "y": 73,
      "z": 14,
      "name": "Plant_Leaves_Jungle_Max_Support"
    },
    {
      "x": -36,
      "y": 74,
      "z": 14,
      "name": "Plant_Leaves_Jungle_Max_Support"
    },
    {
      "x": -36,
      "y": 75,
      "z": 14,
      "name": "Plant_Leaves_Jungle_Max_Support"
    },
    {
      "x": -36,
      "y": 73,
      "z": 15,
      "name": "Plant_Leaves_Jungle_Max_Support"
    },
    {
      "x": -36,
      "y": 74,
      "z": 15,
      "name": "Plant_Leaves_Jungle_Max_Support"
    },
    {
      "x": -36,
      "y": 75,
      "z": 15,
      "name": "Plant_Leaves_Jungle_Max_Support"
    },
    {
      "x": -36,
      "y": 76,
      "z": 15,
      "name": "Plant_Leaves_Jungle_Max_Support"
    },
    {
      "x": -36,
      "y": 73,
      "z": 16,
      "name": "Plant_Leaves_Jungle_Max_Support"
    },
    {
      "x": -36,
      "y": 74,
      "z": 16,
      "name": "Plant_Leaves_Jungle_Max_Support"
    },
    {
      "x": -36,
      "y": 74,
      "z": 17,
      "name": "Plant_Leaves_Jungle_Max_Support"
    },
    {
      "x": -35,
      "y": 73,
      "z": 12,
      "name": "Plant_Leaves_Jungle_Max_Support"
    },
    {
      "x": -35,
      "y": 74,
      "z": 12,
      "name": "Plant_Leaves_Jungle_Max_Support"
    },
    {
      "x": -35,
      "y": 75,
      "z": 12,
      "name": "Plant_Leaves_Jungle_Max_Support"
    },
    {
      "x": -35,
      "y": 72,
      "z": 13,
      "name": "Plant_Leaves_Jungle_Max_Support"
    },
    {
      "x": -35,
      "y": 73,
      "z": 13,
      "name": "Plant_Leaves_Jungle_Max_Support"
    },
    {
      "x": -35,
      "y": 74,
      "z": 13,
      "name": "Plant_Leaves_Jungle_Max_Support"
    },
    {
      "x": -35,
      "y": 75,
      "z": 13,
      "name": "Plant_Leaves_Jungle_Max_Support"
    },
    {
      "x": -35,
      "y": 76,
      "z": 13,
      "name": "Plant_Leaves_Jungle_Max_Support"
    },
    {
      "x": -35,
      "y": 72,
      "z": 14,
      "name": "Plant_Leaves_Jungle_Max_Support"
    },
    {
      "x": -35,
      "y": 73,
      "z": 14,
      "name": "Plant_Leaves_Jungle_Max_Support"
    },
    {
      "x": -35,
      "y": 74,
      "z": 14,
      "name": "Plant_Leaves_Jungle_Max_Support"
    },
    {
      "x": -35,
      "y": 75,
      "z": 14,
      "name": "Plant_Leaves_Jungle_Max_Support"
    },
    {
      "x": -35,
      "y": 73,
      "z": 15,
      "name": "Plant_Leaves_Jungle_Max_Support"
    },
    {
      "x": -35,
      "y": 74,
      "z": 15,
      "name": "Plant_Leaves_Jungle_Max_Support"
    },
    {
      "x": -35,
      "y": 75,
      "z": 15,
      "name": "Plant_Leaves_Jungle_Max_Support"
    },
    {
      "x": -35,
      "y": 76,
      "z": 15,
      "name": "Plant_Leaves_Jungle_Max_Support"
    },
    {
      "x": -35,
      "y": 72,
      "z": 16,
      "name": "Plant_Leaves_Jungle_Max_Support"
    },
    {
      "x": -35,
      "y": 73,
      "z": 16,
      "name": "Plant_Leaves_Jungle_Max_Support"
    },
    {
      "x": -35,
      "y": 74,
      "z": 16,
      "name": "Plant_Leaves_Jungle_Max_Support"
    },
    {
      "x": -35,
      "y": 75,
      "z": 16,
      "name": "Plant_Leaves_Jungle_Max_Support"
    },
    {
      "x": -35,
      "y": 76,
      "z": 16,
      "name": "Plant_Leaves_Jungle_Max_Support"
    },
    {
      "x": -35,
      "y": 73,
      "z": 17,
      "name": "Plant_Leaves_Jungle_Max_Support"
    },
    {
      "x": -35,
      "y": 74,
      "z": 18,
      "name": "Plant_Leaves_Jungle_Max_Support"
    },
    {
      "x": -35,
      "y": 75,
      "z": 18,
      "name": "Plant_Leaves_Jungle_Max_Support"
    },
    {
      "x": -35,
      "y": 74,
      "z": 19,
      "name": "Plant_Leaves_Jungle_Max_Support"
    },
    {
      "x": -34,
      "y": 57,
      "z": 6,
      "name": "Plant_Leaves_Jungle_Max_Support"
    },
    {
      "x": -34,
      "y": 58,
      "z": 6,
      "name": "Plant_Leaves_Jungle_Max_Support"
    },
    {
      "x": -34,
      "y": 57,
      "z": 7,
      "name": "Plant_Leaves_Jungle_Max_Support"
    },
    {
      "x": -34,
      "y": 74,
      "z": 11,
      "name": "Plant_Leaves_Jungle_Max_Support"
    },
    {
      "x": -34,
      "y": 75,
      "z": 11,
      "name": "Plant_Leaves_Jungle_Max_Support"
    },
    {
      "x": -34,
      "y": 76,
      "z": 11,
      "name": "Plant_Leaves_Jungle_Max_Support"
    },
    {
      "x": -34,
      "y": 74,
      "z": 12,
      "name": "Plant_Leaves_Jungle_Max_Support"
    },
    {
      "x": -34,
      "y": 75,
      "z": 12,
      "name": "Plant_Leaves_Jungle_Max_Support"
    },
    {
      "x": -34,
      "y": 76,
      "z": 12,
      "name": "Plant_Leaves_Jungle_Max_Support"
    },
    {
      "x": -34,
      "y": 73,
      "z": 13,
      "name": "Plant_Leaves_Jungle_Max_Support"
    },
    {
      "x": -34,
      "y": 74,
      "z": 13,
      "name": "Plant_Leaves_Jungle_Max_Support"
    },
    {
      "x": -34,
      "y": 75,
      "z": 13,
      "name": "Plant_Leaves_Jungle_Max_Support"
    },
    {
      "x": -34,
      "y": 76,
      "z": 13,
      "name": "Plant_Leaves_Jungle_Max_Support"
    },
    {
      "x": -34,
      "y": 73,
      "z": 14,
      "name": "Plant_Leaves_Jungle_Max_Support"
    },
    {
      "x": -34,
      "y": 74,
      "z": 14,
      "name": "Plant_Leaves_Jungle_Max_Support"
    },
    {
      "x": -34,
      "y": 75,
      "z": 14,
      "name": "Plant_Leaves_Jungle_Max_Support"
    },
    {
      "x": -34,
      "y": 76,
      "z": 14,
      "name": "Plant_Leaves_Jungle_Max_Support"
    },
    {
      "x": -34,
      "y": 72,
      "z": 15,
      "name": "Plant_Leaves_Jungle_Max_Support"
    },
    {
      "x": -34,
      "y": 73,
      "z": 15,
      "name": "Plant_Leaves_Jungle_Max_Support"
    },
    {
      "x": -34,
      "y": 74,
      "z": 15,
      "name": "Plant_Leaves_Jungle_Max_Support"
    },
    {
      "x": -34,
      "y": 75,
      "z": 15,
      "name": "Plant_Leaves_Jungle_Max_Support"
    },
    {
      "x": -34,
      "y": 76,
      "z": 15,
      "name": "Plant_Leaves_Jungle_Max_Support"
    },
    {
      "x": -34,
      "y": 77,
      "z": 15,
      "name": "Plant_Leaves_Jungle_Max_Support"
    },
    {
      "x": -34,
      "y": 72,
      "z": 16,
      "name": "Plant_Leaves_Jungle_Max_Support"
    },
    {
      "x": -34,
      "y": 74,
      "z": 16,
      "name": "Plant_Leaves_Jungle_Max_Support"
    },
    {
      "x": -34,
      "y": 72,
      "z": 17,
      "name": "Plant_Leaves_Jungle_Max_Support"
    },
    {
      "x": -34,
      "y": 73,
      "z": 17,
      "name": "Plant_Leaves_Jungle_Max_Support"
    },
    {
      "x": -34,
      "y": 74,
      "z": 17,
      "name": "Plant_Leaves_Jungle_Max_Support"
    },
    {
      "x": -34,
      "y": 75,
      "z": 17,
      "name": "Plant_Leaves_Jungle_Max_Support"
    },
    {
      "x": -34,
      "y": 72,
      "z": 18,
      "name": "Plant_Leaves_Jungle_Max_Support"
    },
    {
      "x": -34,
      "y": 73,
      "z": 18,
      "name": "Plant_Leaves_Jungle_Max_Support"
    },
    {
      "x": -34,
      "y": 74,
      "z": 18,
      "name": "Plant_Leaves_Jungle_Max_Support"
    },
    {
      "x": -34,
      "y": 75,
      "z": 18,
      "name": "Plant_Leaves_Jungle_Max_Support"
    },
    {
      "x": -34,
      "y": 76,
      "z": 18,
      "name": "Plant_Leaves_Jungle_Max_Support"
    },
    {
      "x": -33,
      "y": 53,
      "z": 5,
      "name": "Plant_Leaves_Jungle_Max_Support",
      "support": 15
    },
    {
      "x": -33,
      "y": 54,
      "z": 5,
      "name": "Plant_Leaves_Jungle_Max_Support",
      "support": 15
    },
    {
      "x": -33,
      "y": 55,
      "z": 5,
      "name": "Plant_Leaves_Jungle_Max_Support",
      "support": 15
    },
    {
      "x": -33,
      "y": 56,
      "z": 5,
      "name": "Plant_Leaves_Jungle_Max_Support",
      "support": 15
    },
    {
      "x": -33,
      "y": 58,
      "z": 5,
      "name": "Plant_Leaves_Jungle_Max_Support"
    },
    {
      "x": -33,
      "y": 56,
      "z": 6,
      "name": "Plant_Leaves_Jungle_Max_Support",
      "support": 15
    },
    {
      "x": -33,
      "y": 58,
      "z": 6,
      "name": "Plant_Leaves_Jungle_Max_Support"
    },
    {
      "x": -33,
      "y": 59,
      "z": 6,
      "name": "Plant_Leaves_Jungle_Max_Support"
    },
    {
      "x": -33,
      "y": 56,
      "z": 7,
      "name": "Plant_Leaves_Jungle_Max_Support"
    },
    {
      "x": -33,
      "y": 57,
      "z": 7,
      "name": "Plant_Leaves_Jungle_Max_Support"
    },
    {
      "x": -33,
      "y": 56,
      "z": 8,
      "name": "Plant_Leaves_Jungle_Max_Support"
    },
    {
      "x": -33,
      "y": 57,
      "z": 8,
      "name": "Plant_Leaves_Jungle_Max_Support"
    },
    {
      "x": -33,
      "y": 58,
      "z": 8,
      "name": "Plant_Leaves_Jungle_Max_Support"
    },
    {
      "x": -33,
      "y": 57,
      "z": 9,
      "name": "Plant_Leaves_Jungle_Max_Support"
    },
    {
      "x": -33,
      "y": 58,
      "z": 9,
      "name": "Plant_Leaves_Jungle_Max_Support"
    },
    {
      "x": -33,
      "y": 62,
      "z": 9,
      "name": "Plant_Leaves_Jungle_Max_Support"
    },
    {
      "x": -33,
      "y": 57,
      "z": 10,
      "name": "Plant_Leaves_Jungle_Max_Support"
    },
    {
      "x": -33,
      "y": 58,
      "z": 10,
      "name": "Plant_Leaves_Jungle_Max_Support"
    },
    {
      "x": -33,
      "y": 61,
      "z": 10,
      "name": "Plant_Leaves_Jungle_Max_Support"
    },
    {
      "x": -33,
      "y": 75,
      "z": 10,
      "name": "Plant_Leaves_Jungle_Max_Support"
    },
    {
      "x": -33,
      "y": 56,
      "z": 11,
      "name": "Plant_Leaves_Jungle_Max_Support"
    },
    {
      "x": -33,
      "y": 58,
      "z": 11,
      "name": "Plant_Leaves_Jungle_Max_Support"
    },
    {
      "x": -33,
      "y": 59,
      "z": 11,
      "name": "Plant_Leaves_Jungle_Max_Support"
    },
    {
      "x": -33,
      "y": 60,
      "z": 11,
      "name": "Plant_Leaves_Jungle_Max_Support"
    },
    {
      "x": -33,
      "y": 61,
      "z": 11,
      "name": "Plant_Leaves_Jungle_Max_Support"
    },
    {
      "x": -33,
      "y": 62,
      "z": 11,
      "name": "Plant_Leaves_Jungle_Max_Support"
    },
    {
      "x": -33,
      "y": 74,
      "z": 11,
      "name": "Plant_Leaves_Jungle_Max_Support"
    },
    {
      "x": -33,
      "y": 75,
      "z": 11,
      "name": "Plant_Leaves_Jungle_Max_Support"
    },
    {
      "x": -33,
      "y": 76,
      "z": 11,
      "name": "Plant_Leaves_Jungle_Max_Support"
    },
    {
      "x": -33,
      "y": 57,
      "z": 12,
      "name": "Plant_Leaves_Jungle_Max_Support"
    },
    {
      "x": -33,
      "y": 60,
      "z": 12,
      "name": "Plant_Leaves_Jungle_Max_Support"
    },
    {
      "x": -33,
      "y": 62,
      "z": 12,
      "name": "Plant_Leaves_Jungle_Max_Support"
    },
    {
      "x": -33,
      "y": 75,
      "z": 12,
      "name": "Plant_Leaves_Jungle_Max_Support"
    },
    {
      "x": -33,
      "y": 76,
      "z": 12,
      "name": "Plant_Leaves_Jungle_Max_Support"
    },
    {
      "x": -33,
      "y": 77,
      "z": 12,
      "name": "Plant_Leaves_Jungle_Max_Support"
    },
    {
      "x": -33,
      "y": 74,
      "z": 13,
      "name": "Plant_Leaves_Jungle_Max_Support"
    },
    {
      "x": -33,
      "y": 75,
      "z": 13,
      "name": "Plant_Leaves_Jungle_Max_Support"
    },
    {
      "x": -33,
      "y": 76,
      "z": 13,
      "name": "Plant_Leaves_Jungle_Max_Support"
    },
    {
      "x": -33,
      "y": 73,
      "z": 14,
      "name": "Plant_Leaves_Jungle_Max_Support"
    },
    {
      "x": -33,
      "y": 74,
      "z": 14,
      "name": "Plant_Leaves_Jungle_Max_Support"
    },
    {
      "x": -33,
      "y": 75,
      "z": 14,
      "name": "Plant_Leaves_Jungle_Max_Support"
    },
    {
      "x": -33,
      "y": 76,
      "z": 14,
      "name": "Plant_Leaves_Jungle_Max_Support"
    },
    {
      "x": -33,
      "y": 77,
      "z": 14,
      "name": "Plant_Leaves_Jungle_Max_Support"
    },
    {
      "x": -33,
      "y": 73,
      "z": 15,
      "name": "Plant_Leaves_Jungle_Max_Support"
    },
    {
      "x": -33,
      "y": 75,
      "z": 15,
      "name": "Plant_Leaves_Jungle_Max_Support"
    },
    {
      "x": -33,
      "y": 77,
      "z": 15,
      "name": "Plant_Leaves_Jungle_Max_Support"
    },
    {
      "x": -33,
      "y": 78,
      "z": 15,
      "name": "Plant_Leaves_Jungle_Max_Support"
    },
    {
      "x": -33,
      "y": 72,
      "z": 16,
      "name": "Plant_Leaves_Jungle_Max_Support"
    },
    {
      "x": -33,
      "y": 73,
      "z": 16,
      "name": "Plant_Leaves_Jungle_Max_Support"
    },
    {
      "x": -33,
      "y": 74,
      "z": 16,
      "name": "Plant_Leaves_Jungle_Max_Support"
    },
    {
      "x": -33,
      "y": 75,
      "z": 16,
      "name": "Plant_Leaves_Jungle_Max_Support"
    },
    {
      "x": -33,
      "y": 76,
      "z": 16,
      "name": "Plant_Leaves_Jungle_Max_Support"
    },
    {
      "x": -33,
      "y": 77,
      "z": 16,
      "name": "Plant_Leaves_Jungle_Max_Support"
    },
    {
      "x": -33,
      "y": 73,
      "z": 17,
      "name": "Plant_Leaves_Jungle_Max_Support"
    },
    {
      "x": -33,
      "y": 74,
      "z": 17,
      "name": "Plant_Leaves_Jungle_Max_Support"
    },
    {
      "x": -33,
      "y": 75,
      "z": 17,
      "name": "Plant_Leaves_Jungle_Max_Support"
    },
    {
      "x": -33,
      "y": 76,
      "z": 17,
      "name": "Plant_Leaves_Jungle_Max_Support"
    },
    {
      "x": -33,
      "y": 78,
      "z": 17,
      "name": "Plant_Leaves_Jungle_Max_Support"
    },
    {
      "x": -33,
      "y": 72,
      "z": 18,
      "name": "Plant_Leaves_Jungle_Max_Support"
    },
    {
      "x": -33,
      "y": 73,
      "z": 18,
      "name": "Plant_Leaves_Jungle_Max_Support"
    },
    {
      "x": -33,
      "y": 74,
      "z": 18,
      "name": "Plant_Leaves_Jungle_Max_Support"
    },
    {
      "x": -33,
      "y": 77,
      "z": 18,
      "name": "Plant_Leaves_Jungle_Max_Support"
    },
    {
      "x": -33,
      "y": 74,
      "z": 19,
      "name": "Plant_Leaves_Jungle_Max_Support"
    },
    {
      "x": -33,
      "y": 75,
      "z": 19,
      "name": "Plant_Leaves_Jungle_Max_Support"
    },
    {
      "x": -33,
      "y": 76,
      "z": 19,
      "name": "Plant_Leaves_Jungle_Max_Support"
    },
    {
      "x": -33,
      "y": 73,
      "z": 20,
      "name": "Plant_Leaves_Jungle_Max_Support"
    },
    {
      "x": -33,
      "y": 74,
      "z": 20,
      "name": "Plant_Leaves_Jungle_Max_Support"
    },
    {
      "x": -33,
      "y": 75,
      "z": 20,
      "name": "Plant_Leaves_Jungle_Max_Support"
    },
    {
      "x": -32,
      "y": 57,
      "z": 4,
      "name": "Plant_Leaves_Jungle_Max_Support"
    },
    {
      "x": -32,
      "y": 58,
      "z": 4,
      "name": "Plant_Leaves_Jungle_Max_Support"
    },
    {
      "x": -32,
      "y": 57,
      "z": 5,
      "name": "Plant_Leaves_Jungle_Max_Support"
    },
    {
      "x": -32,
      "y": 59,
      "z": 5,
      "name": "Plant_Leaves_Jungle_Max_Support"
    },
    {
      "x": -32,
      "y": 55,
      "z": 6,
      "name": "Plant_Leaves_Jungle_Max_Support",
      "support": 15
    },
    {
      "x": -32,
      "y": 56,
      "z": 6,
      "name": "Plant_Leaves_Jungle_Max_Support"
    },
    {
      "x": -32,
      "y": 57,
      "z": 6,
      "name": "Plant_Leaves_Jungle_Max_Support"
    },
    {
      "x": -32,
      "y": 58,
      "z": 6,
      "name": "Plant_Leaves_Jungle_Max_Support"
    },
    {
      "x": -32,
      "y": 56,
      "z": 7,
      "name": "Plant_Leaves_Jungle_Max_Support"
    },
    {
      "x": -32,
      "y": 57,
      "z": 7,
      "name": "Plant_Leaves_Jungle_Max_Support"
    },
    {
      "x": -32,
      "y": 58,
      "z": 7,
      "name": "Plant_Leaves_Jungle_Max_Support"
    },
    {
      "x": -32,
      "y": 59,
      "z": 7,
      "name": "Plant_Leaves_Jungle_Max_Support"
    },
    {
      "x": -32,
      "y": 61,
      "z": 7,
      "name": "Plant_Leaves_Jungle_Max_Support"
    },
    {
      "x": -32,
      "y": 55,
      "z": 8,
      "name": "Plant_Leaves_Jungle_Max_Support"
    },
    {
      "x": -32,
      "y": 56,
      "z": 8,
      "name": "Plant_Leaves_Jungle_Max_Support"
    },
    {
      "x": -32,
      "y": 57,
      "z": 8,
      "name": "Plant_Leaves_Jungle_Max_Support"
    },
    {
      "x": -32,
      "y": 58,
      "z": 8,
      "name": "Plant_Leaves_Jungle_Max_Support"
    },
    {
      "x": -32,
      "y": 59,
      "z": 8,
      "name": "Plant_Leaves_Jungle_Max_Support"
    },
    {
      "x": -32,
      "y": 60,
      "z": 8,
      "name": "Plant_Leaves_Jungle_Max_Support"
    },
    {
      "x": -32,
      "y": 61,
      "z": 8,
      "name": "Plant_Leaves_Jungle_Max_Support"
    },
    {
      "x": -32,
      "y": 62,
      "z": 8,
      "name": "Plant_Leaves_Jungle_Max_Support"
    },
    {
      "x": -32,
      "y": 57,
      "z": 9,
      "name": "Plant_Leaves_Jungle_Max_Support"
    },
    {
      "x": -32,
      "y": 58,
      "z": 9,
      "name": "Plant_Leaves_Jungle_Max_Support"
    },
    {
      "x": -32,
      "y": 60,
      "z": 9,
      "name": "Plant_Leaves_Jungle_Max_Support"
    },
    {
      "x": -32,
      "y": 62,
      "z": 9,
      "name": "Plant_Leaves_Jungle_Max_Support"
    },
    {
      "x": -32,
      "y": 55,
      "z": 10,
      "name": "Plant_Leaves_Jungle_Max_Support"
    },
    {
      "x": -32,
      "y": 56,
      "z": 10,
      "name": "Plant_Leaves_Jungle_Max_Support"
    },
    {
      "x": -32,
      "y": 57,
      "z": 10,
      "name": "Plant_Leaves_Jungle_Max_Support"
    },
    {
      "x": -32,
      "y": 58,
      "z": 10,
      "name": "Plant_Leaves_Jungle_Max_Support"
    },
    {
      "x": -32,
      "y": 60,
      "z": 10,
      "name": "Plant_Leaves_Jungle_Max_Support"
    },
    {
      "x": -32,
      "y": 61,
      "z": 10,
      "name": "Plant_Leaves_Jungle_Max_Support"
    },
    {
      "x": -32,
      "y": 63,
      "z": 10,
      "name": "Plant_Leaves_Jungle_Max_Support"
    },
    {
      "x": -32,
      "y": 77,
      "z": 10,
      "name": "Plant_Leaves_Jungle_Max_Support"
    },
    {
      "x": -32,
      "y": 54,
      "z": 11,
      "name": "Plant_Leaves_Jungle_Max_Support"
    },
    {
      "x": -32,
      "y": 55,
      "z": 11,
      "name": "Plant_Leaves_Jungle_Max_Support"
    },
    {
      "x": -32,
      "y": 56,
      "z": 11,
      "name": "Plant_Leaves_Jungle_Max_Support"
    },
    {
      "x": -32,
      "y": 58,
      "z": 11,
      "name": "Plant_Leaves_Jungle_Max_Support"
    },
    {
      "x": -32,
      "y": 59,
      "z": 11,
      "name": "Plant_Leaves_Jungle_Max_Support"
    },
    {
      "x": -32,
      "y": 60,
      "z": 11,
      "name": "Plant_Leaves_Jungle_Max_Support"
    },
    {
      "x": -32,
      "y": 61,
      "z": 11,
      "name": "Plant_Leaves_Jungle_Max_Support"
    },
    {
      "x": -32,
      "y": 62,
      "z": 11,
      "name": "Plant_Leaves_Jungle_Max_Support"
    },
    {
      "x": -32,
      "y": 63,
      "z": 11,
      "name": "Plant_Leaves_Jungle_Max_Support"
    },
    {
      "x": -32,
      "y": 74,
      "z": 11,
      "name": "Plant_Leaves_Jungle_Max_Support"
    },
    {
      "x": -32,
      "y": 75,
      "z": 11,
      "name": "Plant_Leaves_Jungle_Max_Support"
    },
    {
      "x": -32,
      "y": 77,
      "z": 11,
      "name": "Plant_Leaves_Jungle_Max_Support"
    },
    {
      "x": -32,
      "y": 78,
      "z": 11,
      "name": "Plant_Leaves_Jungle_Max_Support"
    },
    {
      "x": -32,
      "y": 52,
      "z": 12,
      "name": "Plant_Leaves_Jungle_Max_Support",
      "support": 15
    },
    {
      "x": -32,
      "y": 53,
      "z": 12,
      "name": "Plant_Leaves_Jungle_Max_Support",
      "support": 15
    },
    {
      "x": -32,
      "y": 54,
      "z": 12,
      "name": "Plant_Leaves_Jungle_Max_Support",
      "support": 15
    },
    {
      "x": -32,
      "y": 55,
      "z": 12,
      "name": "Plant_Leaves_Jungle_Max_Support",
      "support": 15
    },
    {
      "x": -32,
      "y": 56,
      "z": 12,
      "name": "Plant_Leaves_Jungle_Max_Support"
    },
    {
      "x": -32,
      "y": 57,
      "z": 12,
      "name": "Plant_Leaves_Jungle_Max_Support"
    },
    {
      "x": -32,
      "y": 58,
      "z": 12,
      "name": "Plant_Leaves_Jungle_Max_Support"
    },
    {
      "x": -32,
      "y": 59,
      "z": 12,
      "name": "Plant_Leaves_Jungle_Max_Support"
    },
    {
      "x": -32,
      "y": 61,
      "z": 12,
      "name": "Plant_Leaves_Jungle_Max_Support"
    },
    {
      "x": -32,
      "y": 62,
      "z": 12,
      "name": "Plant_Leaves_Jungle_Max_Support"
    },
    {
      "x": -32,
      "y": 63,
      "z": 12,
      "name": "Plant_Leaves_Jungle_Max_Support"
    },
    {
      "x": -32,
      "y": 75,
      "z": 12,
      "name": "Plant_Leaves_Jungle_Max_Support"
    },
    {
      "x": -32,
      "y": 76,
      "z": 12,
      "name": "Plant_Leaves_Jungle_Max_Support"
    },
    {
      "x": -32,
      "y": 77,
      "z": 12,
      "name": "Plant_Leaves_Jungle_Max_Support"
    },
    {
      "x": -32,
      "y": 57,
      "z": 13,
      "name": "Plant_Leaves_Jungle_Max_Support"
    },
    {
      "x": -32,
      "y": 60,
      "z": 13,
      "name": "Plant_Leaves_Jungle_Max_Support"
    },
    {
      "x": -32,
      "y": 62,
      "z": 13,
      "name": "Plant_Leaves_Jungle_Max_Support"
    },
    {
      "x": -32,
      "y": 74,
      "z": 13,
      "name": "Plant_Leaves_Jungle_Max_Support"
    },
    {
      "x": -32,
      "y": 75,
      "z": 13,
      "name": "Plant_Leaves_Jungle_Max_Support"
    },
    {
      "x": -32,
      "y": 76,
      "z": 13,
      "name": "Plant_Leaves_Jungle_Max_Support"
    },
    {
      "x": -32,
      "y": 77,
      "z": 13,
      "name": "Plant_Leaves_Jungle_Max_Support"
    },
    {
      "x": -32,
      "y": 59,
      "z": 14,
      "name": "Plant_Leaves_Jungle_Max_Support"
    },
    {
      "x": -32,
      "y": 74,
      "z": 14,
      "name": "Plant_Leaves_Jungle_Max_Support"
    },
    {
      "x": -32,
      "y": 75,
      "z": 14,
      "name": "Plant_Leaves_Jungle_Max_Support"
    },
    {
      "x": -32,
      "y": 76,
      "z": 14,
      "name": "Plant_Leaves_Jungle_Max_Support"
    },
    {
      "x": -32,
      "y": 78,
      "z": 14,
      "name": "Plant_Leaves_Jungle_Max_Support"
    },
    {
      "x": -32,
      "y": 79,
      "z": 14,
      "name": "Plant_Leaves_Jungle_Max_Support"
    },
    {
      "x": -32,
      "y": 74,
      "z": 15,
      "name": "Plant_Leaves_Jungle_Max_Support"
    },
    {
      "x": -32,
      "y": 75,
      "z": 15,
      "name": "Plant_Leaves_Jungle_Max_Support"
    },
    {
      "x": -32,
      "y": 76,
      "z": 15,
      "name": "Plant_Leaves_Jungle_Max_Support"
    },
    {
      "x": -32,
      "y": 77,
      "z": 15,
      "name": "Plant_Leaves_Jungle_Max_Support"
    },
    {
      "x": -32,
      "y": 78,
      "z": 15,
      "name": "Plant_Leaves_Jungle_Max_Support"
    },
    {
      "x": -32,
      "y": 79,
      "z": 15,
      "name": "Plant_Leaves_Jungle_Max_Support"
    },
    {
      "x": -32,
      "y": 73,
      "z": 16,
      "name": "Plant_Leaves_Jungle_Max_Support"
    },
    {
      "x": -32,
      "y": 74,
      "z": 16,
      "name": "Plant_Leaves_Jungle_Max_Support"
    },
    {
      "x": -32,
      "y": 75,
      "z": 16,
      "name": "Plant_Leaves_Jungle_Max_Support"
    },
    {
      "x": -32,
      "y": 76,
      "z": 16,
      "name": "Plant_Leaves_Jungle_Max_Support"
    },
    {
      "x": -32,
      "y": 77,
      "z": 16,
      "name": "Plant_Leaves_Jungle_Max_Support"
    },
    {
      "x": -32,
      "y": 78,
      "z": 16,
      "name": "Plant_Leaves_Jungle_Max_Support"
    },
    {
      "x": -32,
      "y": 73,
      "z": 17,
      "name": "Plant_Leaves_Jungle_Max_Support"
    },
    {
      "x": -32,
      "y": 74,
      "z": 17,
      "name": "Plant_Leaves_Jungle_Max_Support"
    },
    {
      "x": -32,
      "y": 75,
      "z": 17,
      "name": "Plant_Leaves_Jungle_Max_Support"
    },
    {
      "x": -32,
      "y": 76,
      "z": 17,
      "name": "Plant_Leaves_Jungle_Max_Support"
    },
    {
      "x": -32,
      "y": 77,
      "z": 17,
      "name": "Plant_Leaves_Jungle_Max_Support"
    },
    {
      "x": -32,
      "y": 79,
      "z": 17,
      "name": "Plant_Leaves_Jungle_Max_Support"
    },
    {
      "x": -32,
      "y": 72,
      "z": 18,
      "name": "Plant_Leaves_Jungle_Max_Support"
    },
    {
      "x": -32,
      "y": 73,
      "z": 18,
      "name": "Plant_Leaves_Jungle_Max_Support"
    },
    {
      "x": -32,
      "y": 74,
      "z": 18,
      "name": "Plant_Leaves_Jungle_Max_Support"
    },
    {
      "x": -32,
      "y": 75,
      "z": 18,
      "name": "Plant_Leaves_Jungle_Max_Support"
    },
    {
      "x": -32,
      "y": 76,
      "z": 18,
      "name": "Plant_Leaves_Jungle_Max_Support"
    },
    {
      "x": -32,
      "y": 77,
      "z": 18,
      "name": "Plant_Leaves_Jungle_Max_Support"
    },
    {
      "x": -32,
      "y": 78,
      "z": 18,
      "name": "Plant_Leaves_Jungle_Max_Support"
    },
    {
      "x": -32,
      "y": 72,
      "z": 19,
      "name": "Plant_Leaves_Jungle_Max_Support"
    },
    {
      "x": -32,
      "y": 73,
      "z": 19,
      "name": "Plant_Leaves_Jungle_Max_Support"
    },
    {
      "x": -32,
      "y": 75,
      "z": 19,
      "name": "Plant_Leaves_Jungle_Max_Support"
    },
    {
      "x": -32,
      "y": 76,
      "z": 19,
      "name": "Plant_Leaves_Jungle_Max_Support"
    },
    {
      "x": -32,
      "y": 77,
      "z": 19,
      "name": "Plant_Leaves_Jungle_Max_Support"
    },
    {
      "x": -32,
      "y": 73,
      "z": 20,
      "name": "Plant_Leaves_Jungle_Max_Support"
    },
    {
      "x": -32,
      "y": 74,
      "z": 20,
      "name": "Plant_Leaves_Jungle_Max_Support"
    },
    {
      "x": -32,
      "y": 75,
      "z": 20,
      "name": "Plant_Leaves_Jungle_Max_Support"
    },
    {
      "x": -32,
      "y": 74,
      "z": 21,
      "name": "Plant_Leaves_Jungle_Max_Support"
    },
    {
      "x": -31,
      "y": 57,
      "z": 4,
      "name": "Plant_Leaves_Jungle_Max_Support"
    },
    {
      "x": -31,
      "y": 59,
      "z": 4,
      "name": "Plant_Leaves_Jungle_Max_Support"
    },
    {
      "x": -31,
      "y": 57,
      "z": 5,
      "name": "Plant_Leaves_Jungle_Max_Support"
    },
    {
      "x": -31,
      "y": 58,
      "z": 5,
      "name": "Plant_Leaves_Jungle_Max_Support"
    },
    {
      "x": -31,
      "y": 59,
      "z": 5,
      "name": "Plant_Leaves_Jungle_Max_Support"
    },
    {
      "x": -31,
      "y": 56,
      "z": 6,
      "name": "Plant_Leaves_Jungle_Max_Support"
    },
    {
      "x": -31,
      "y": 57,
      "z": 6,
      "name": "Plant_Leaves_Jungle_Max_Support"
    },
    {
      "x": -31,
      "y": 58,
      "z": 6,
      "name": "Plant_Leaves_Jungle_Max_Support"
    },
    {
      "x": -31,
      "y": 59,
      "z": 6,
      "name": "Plant_Leaves_Jungle_Max_Support"
    },
    {
      "x": -31,
      "y": 55,
      "z": 7,
      "name": "Plant_Leaves_Jungle_Max_Support"
    },
    {
      "x": -31,
      "y": 57,
      "z": 7,
      "name": "Plant_Leaves_Jungle_Max_Support"
    },
    {
      "x": -31,
      "y": 58,
      "z": 7,
      "name": "Plant_Leaves_Jungle_Max_Support"
    },
    {
      "x": -31,
      "y": 59,
      "z": 7,
      "name": "Plant_Leaves_Jungle_Max_Support"
    },
    {
      "x": -31,
      "y": 61,
      "z": 7,
      "name": "Plant_Leaves_Jungle_Max_Support"
    },
    {
      "x": -31,
      "y": 62,
      "z": 7,
      "name": "Plant_Leaves_Jungle_Max_Support"
    },
    {
      "x": -31,
      "y": 56,
      "z": 8,
      "name": "Plant_Leaves_Jungle_Max_Support"
    },
    {
      "x": -31,
      "y": 57,
      "z": 8,
      "name": "Plant_Leaves_Jungle_Max_Support"
    },
    {
      "x": -31,
      "y": 59,
      "z": 8,
      "name": "Plant_Leaves_Jungle_Max_Support"
    },
    {
      "x": -31,
      "y": 61,
      "z": 8,
      "name": "Plant_Leaves_Jungle_Max_Support"
    },
    {
      "x": -31,
      "y": 62,
      "z": 8,
      "name": "Plant_Leaves_Jungle_Max_Support"
    },
    {
      "x": -31,
      "y": 63,
      "z": 8,
      "name": "Plant_Leaves_Jungle_Max_Support"
    },
    {
      "x": -31,
      "y": 55,
      "z": 9,
      "name": "Plant_Leaves_Jungle_Max_Support"
    },
    {
      "x": -31,
      "y": 56,
      "z": 9,
      "name": "Plant_Leaves_Jungle_Max_Support"
    },
    {
      "x": -31,
      "y": 57,
      "z": 9,
      "name": "Plant_Leaves_Jungle_Max_Support"
    },
    {
      "x": -31,
      "y": 58,
      "z": 9,
      "name": "Plant_Leaves_Jungle_Max_Support"
    },
    {
      "x": -31,
      "y": 59,
      "z": 9,
      "name": "Plant_Leaves_Jungle_Max_Support"
    },
    {
      "x": -31,
      "y": 60,
      "z": 9,
      "name": "Plant_Leaves_Jungle_Max_Support"
    },
    {
      "x": -31,
      "y": 61,
      "z": 9,
      "name": "Plant_Leaves_Jungle_Max_Support"
    },
    {
      "x": -31,
      "y": 62,
      "z": 9,
      "name": "Plant_Leaves_Jungle_Max_Support"
    },
    {
      "x": -31,
      "y": 75,
      "z": 9,
      "name": "Plant_Leaves_Jungle_Max_Support"
    },
    {
      "x": -31,
      "y": 55,
      "z": 10,
      "name": "Plant_Leaves_Jungle_Max_Support"
    },
    {
      "x": -31,
      "y": 56,
      "z": 10,
      "name": "Plant_Leaves_Jungle_Max_Support"
    },
    {
      "x": -31,
      "y": 57,
      "z": 10,
      "name": "Plant_Leaves_Jungle_Max_Support"
    },
    {
      "x": -31,
      "y": 58,
      "z": 10,
      "name": "Plant_Leaves_Jungle_Max_Support"
    },
    {
      "x": -31,
      "y": 59,
      "z": 10,
      "name": "Plant_Leaves_Jungle_Max_Support"
    },
    {
      "x": -31,
      "y": 60,
      "z": 10,
      "name": "Plant_Leaves_Jungle_Max_Support"
    },
    {
      "x": -31,
      "y": 61,
      "z": 10,
      "name": "Plant_Leaves_Jungle_Max_Support"
    },
    {
      "x": -31,
      "y": 62,
      "z": 10,
      "name": "Plant_Leaves_Jungle_Max_Support"
    },
    {
      "x": -31,
      "y": 63,
      "z": 10,
      "name": "Plant_Leaves_Jungle_Max_Support"
    },
    {
      "x": -31,
      "y": 74,
      "z": 10,
      "name": "Plant_Leaves_Jungle_Max_Support"
    },
    {
      "x": -31,
      "y": 75,
      "z": 10,
      "name": "Plant_Leaves_Jungle_Max_Support"
    },
    {
      "x": -31,
      "y": 76,
      "z": 10,
      "name": "Plant_Leaves_Jungle_Max_Support"
    },
    {
      "x": -31,
      "y": 53,
      "z": 11,
      "name": "Plant_Leaves_Jungle_Max_Support"
    },
    {
      "x": -31,
      "y": 55,
      "z": 11,
      "name": "Plant_Leaves_Jungle_Max_Support"
    },
    {
      "x": -31,
      "y": 56,
      "z": 11,
      "name": "Plant_Leaves_Jungle_Max_Support"
    },
    {
      "x": -31,
      "y": 57,
      "z": 11,
      "name": "Plant_Leaves_Jungle_Max_Support"
    },
    {
      "x": -31,
      "y": 58,
      "z": 11,
      "name": "Plant_Leaves_Jungle_Max_Support"
    },
    {
      "x": -31,
      "y": 59,
      "z": 11,
      "name": "Plant_Leaves_Jungle_Max_Support"
    },
    {
      "x": -31,
      "y": 60,
      "z": 11,
      "name": "Plant_Leaves_Jungle_Max_Support"
    },
    {
      "x": -31,
      "y": 61,
      "z": 11,
      "name": "Plant_Leaves_Jungle_Max_Support"
    },
    {
      "x": -31,
      "y": 62,
      "z": 11,
      "name": "Plant_Leaves_Jungle_Max_Support"
    },
    {
      "x": -31,
      "y": 74,
      "z": 11,
      "name": "Plant_Leaves_Jungle_Max_Support"
    },
    {
      "x": -31,
      "y": 75,
      "z": 11,
      "name": "Plant_Leaves_Jungle_Max_Support"
    },
    {
      "x": -31,
      "y": 76,
      "z": 11,
      "name": "Plant_Leaves_Jungle_Max_Support"
    },
    {
      "x": -31,
      "y": 77,
      "z": 11,
      "name": "Plant_Leaves_Jungle_Max_Support"
    },
    {
      "x": -31,
      "y": 54,
      "z": 12,
      "name": "Plant_Leaves_Jungle_Max_Support"
    },
    {
      "x": -31,
      "y": 55,
      "z": 12,
      "name": "Plant_Leaves_Jungle_Max_Support"
    },
    {
      "x": -31,
      "y": 56,
      "z": 12,
      "name": "Plant_Leaves_Jungle_Max_Support"
    },
    {
      "x": -31,
      "y": 57,
      "z": 12,
      "name": "Plant_Leaves_Jungle_Max_Support"
    },
    {
      "x": -31,
      "y": 58,
      "z": 12,
      "name": "Plant_Leaves_Jungle_Max_Support"
    },
    {
      "x": -31,
      "y": 59,
      "z": 12,
      "name": "Plant_Leaves_Jungle_Max_Support"
    },
    {
      "x": -31,
      "y": 60,
      "z": 12,
      "name": "Plant_Leaves_Jungle_Max_Support"
    },
    {
      "x": -31,
      "y": 61,
      "z": 12,
      "name": "Plant_Leaves_Jungle_Max_Support"
    },
    {
      "x": -31,
      "y": 62,
      "z": 12,
      "name": "Plant_Leaves_Jungle_Max_Support"
    },
    {
      "x": -31,
      "y": 74,
      "z": 12,
      "name": "Plant_Leaves_Jungle_Max_Support"
    },
    {
      "x": -31,
      "y": 75,
      "z": 12,
      "name": "Plant_Leaves_Jungle_Max_Support"
    },
    {
      "x": -31,
      "y": 76,
      "z": 12,
      "name": "Plant_Leaves_Jungle_Max_Support"
    },
    {
      "x": -31,
      "y": 77,
      "z": 12,
      "name": "Plant_Leaves_Jungle_Max_Support"
    },
    {
      "x": -31,
      "y": 79,
      "z": 12,
      "name": "Plant_Leaves_Jungle_Max_Support"
    },
    {
      "x": -31,
      "y": 55,
      "z": 13,
      "name": "Plant_Leaves_Jungle_Max_Support"
    },
    {
      "x": -31,
      "y": 56,
      "z": 13,
      "name": "Plant_Leaves_Jungle_Max_Support"
    },
    {
      "x": -31,
      "y": 58,
      "z": 13,
      "name": "Plant_Leaves_Jungle_Max_Support"
    },
    {
      "x": -31,
      "y": 59,
      "z": 13,
      "name": "Plant_Leaves_Jungle_Max_Support"
    },
    {
      "x": -31,
      "y": 60,
      "z": 13,
      "name": "Plant_Leaves_Jungle_Max_Support"
    },
    {
      "x": -31,
      "y": 61,
      "z": 13,
      "name": "Plant_Leaves_Jungle_Max_Support"
    },
    {
      "x": -31,
      "y": 62,
      "z": 13,
      "name": "Plant_Leaves_Jungle_Max_Support"
    },
    {
      "x": -31,
      "y": 63,
      "z": 13,
      "name": "Plant_Leaves_Jungle_Max_Support"
    },
    {
      "x": -31,
      "y": 74,
      "z": 13,
      "name": "Plant_Leaves_Jungle_Max_Support"
    },
    {
      "x": -31,
      "y": 75,
      "z": 13,
      "name": "Plant_Leaves_Jungle_Max_Support"
    },
    {
      "x": -31,
      "y": 77,
      "z": 13,
      "name": "Plant_Leaves_Jungle_Max_Support"
    },
    {
      "x": -31,
      "y": 78,
      "z": 13,
      "name": "Plant_Leaves_Jungle_Max_Support"
    },
    {
      "x": -31,
      "y": 58,
      "z": 14,
      "name": "Plant_Leaves_Jungle_Max_Support"
    },
    {
      "x": -31,
      "y": 59,
      "z": 14,
      "name": "Plant_Leaves_Jungle_Max_Support"
    },
    {
      "x": -31,
      "y": 60,
      "z": 14,
      "name": "Plant_Leaves_Jungle_Max_Support"
    },
    {
      "x": -31,
      "y": 75,
      "z": 14,
      "name": "Plant_Leaves_Jungle_Max_Support"
    },
    {
      "x": -31,
      "y": 76,
      "z": 14,
      "name": "Plant_Leaves_Jungle_Max_Support"
    },
    {
      "x": -31,
      "y": 77,
      "z": 14,
      "name": "Plant_Leaves_Jungle_Max_Support"
    },
    {
      "x": -31,
      "y": 78,
      "z": 14,
      "name": "Plant_Leaves_Jungle_Max_Support"
    },
    {
      "x": -31,
      "y": 79,
      "z": 14,
      "name": "Plant_Leaves_Jungle_Max_Support"
    },
    {
      "x": -31,
      "y": 59,
      "z": 15,
      "name": "Plant_Leaves_Jungle_Max_Support"
    },
    {
      "x": -31,
      "y": 60,
      "z": 15,
      "name": "Plant_Leaves_Jungle_Max_Support"
    },
    {
      "x": -31,
      "y": 76,
      "z": 15,
      "name": "Plant_Leaves_Jungle_Max_Support"
    },
    {
      "x": -31,
      "y": 77,
      "z": 15,
      "name": "Plant_Leaves_Jungle_Max_Support"
    },
    {
      "x": -31,
      "y": 78,
      "z": 15,
      "name": "Plant_Leaves_Jungle_Max_Support"
    },
    {
      "x": -31,
      "y": 79,
      "z": 15,
      "name": "Plant_Leaves_Jungle_Max_Support"
    },
    {
      "x": -31,
      "y": 74,
      "z": 16,
      "name": "Plant_Leaves_Jungle_Max_Support"
    },
    {
      "x": -31,
      "y": 75,
      "z": 16,
      "name": "Plant_Leaves_Jungle_Max_Support"
    },
    {
      "x": -31,
      "y": 76,
      "z": 16,
      "name": "Plant_Leaves_Jungle_Max_Support"
    },
    {
      "x": -31,
      "y": 77,
      "z": 16,
      "name": "Plant_Leaves_Jungle_Max_Support"
    },
    {
      "x": -31,
      "y": 78,
      "z": 16,
      "name": "Plant_Leaves_Jungle_Max_Support"
    },
    {
      "x": -31,
      "y": 79,
      "z": 16,
      "name": "Plant_Leaves_Jungle_Max_Support"
    },
    {
      "x": -31,
      "y": 74,
      "z": 17,
      "name": "Plant_Leaves_Jungle_Max_Support"
    },
    {
      "x": -31,
      "y": 75,
      "z": 17,
      "name": "Plant_Leaves_Jungle_Max_Support"
    },
    {
      "x": -31,
      "y": 76,
      "z": 17,
      "name": "Plant_Leaves_Jungle_Max_Support"
    },
    {
      "x": -31,
      "y": 77,
      "z": 17,
      "name": "Plant_Leaves_Jungle_Max_Support"
    },
    {
      "x": -31,
      "y": 78,
      "z": 17,
      "name": "Plant_Leaves_Jungle_Max_Support"
    },
    {
      "x": -31,
      "y": 79,
      "z": 17,
      "name": "Plant_Leaves_Jungle_Max_Support"
    },
    {
      "x": -31,
      "y": 80,
      "z": 17,
      "name": "Plant_Leaves_Jungle_Max_Support"
    },
    {
      "x": -31,
      "y": 72,
      "z": 18,
      "name": "Plant_Leaves_Jungle_Max_Support"
    },
    {
      "x": -31,
      "y": 73,
      "z": 18,
      "name": "Plant_Leaves_Jungle_Max_Support"
    },
    {
      "x": -31,
      "y": 74,
      "z": 18,
      "name": "Plant_Leaves_Jungle_Max_Support"
    },
    {
      "x": -31,
      "y": 75,
      "z": 18,
      "name": "Plant_Leaves_Jungle_Max_Support"
    },
    {
      "x": -31,
      "y": 76,
      "z": 18,
      "name": "Plant_Leaves_Jungle_Max_Support"
    },
    {
      "x": -31,
      "y": 77,
      "z": 18,
      "name": "Plant_Leaves_Jungle_Max_Support"
    },
    {
      "x": -31,
      "y": 78,
      "z": 18,
      "name": "Plant_Leaves_Jungle_Max_Support"
    },
    {
      "x": -31,
      "y": 74,
      "z": 19,
      "name": "Plant_Leaves_Jungle_Max_Support"
    },
    {
      "x": -31,
      "y": 75,
      "z": 19,
      "name": "Plant_Leaves_Jungle_Max_Support"
    },
    {
      "x": -31,
      "y": 76,
      "z": 19,
      "name": "Plant_Leaves_Jungle_Max_Support"
    },
    {
      "x": -31,
      "y": 77,
      "z": 19,
      "name": "Plant_Leaves_Jungle_Max_Support"
    },
    {
      "x": -31,
      "y": 73,
      "z": 20,
      "name": "Plant_Leaves_Jungle_Max_Support"
    },
    {
      "x": -31,
      "y": 74,
      "z": 20,
      "name": "Plant_Leaves_Jungle_Max_Support"
    },
    {
      "x": -31,
      "y": 76,
      "z": 20,
      "name": "Plant_Leaves_Jungle_Max_Support"
    },
    {
      "x": -31,
      "y": 73,
      "z": 21,
      "name": "Plant_Leaves_Jungle_Max_Support"
    },
    {
      "x": -30,
      "y": 59,
      "z": 2,
      "name": "Plant_Leaves_Jungle_Max_Support"
    },
    {
      "x": -30,
      "y": 59,
      "z": 3,
      "name": "Plant_Leaves_Jungle_Max_Support"
    },
    {
      "x": -30,
      "y": 60,
      "z": 3,
      "name": "Plant_Leaves_Jungle_Max_Support"
    },
    {
      "x": -30,
      "y": 57,
      "z": 4,
      "name": "Plant_Leaves_Jungle_Max_Support"
    },
    {
      "x": -30,
      "y": 59,
      "z": 4,
      "name": "Plant_Leaves_Jungle_Max_Support"
    },
    {
      "x": -30,
      "y": 60,
      "z": 4,
      "name": "Plant_Leaves_Jungle_Max_Support"
    },
    {
      "x": -30,
      "y": 57,
      "z": 5,
      "name": "Plant_Leaves_Jungle_Max_Support"
    },
    {
      "x": -30,
      "y": 55,
      "z": 6,
      "name": "Plant_Leaves_Jungle_Max_Support"
    },
    {
      "x": -30,
      "y": 56,
      "z": 6,
      "name": "Plant_Leaves_Jungle_Max_Support"
    },
    {
      "x": -30,
      "y": 57,
      "z": 6,
      "name": "Plant_Leaves_Jungle_Max_Support"
    },
    {
      "x": -30,
      "y": 58,
      "z": 6,
      "name": "Plant_Leaves_Jungle_Max_Support"
    },
    {
      "x": -30,
      "y": 59,
      "z": 6,
      "name": "Plant_Leaves_Jungle_Max_Support"
    },
    {
      "x": -30,
      "y": 62,
      "z": 6,
      "name": "Plant_Leaves_Jungle_Max_Support"
    },
    {
      "x": -30,
      "y": 56,
      "z": 7,
      "name": "Plant_Leaves_Jungle_Max_Support"
    },
    {
      "x": -30,
      "y": 57,
      "z": 7,
      "name": "Plant_Leaves_Jungle_Max_Support"
    },
    {
      "x": -30,
      "y": 58,
      "z": 7,
      "name": "Plant_Leaves_Jungle_Max_Support"
    },
    {
      "x": -30,
      "y": 59,
      "z": 7,
      "name": "Plant_Leaves_Jungle_Max_Support"
    },
    {
      "x": -30,
      "y": 60,
      "z": 7,
      "name": "Plant_Leaves_Jungle_Max_Support"
    },
    {
      "x": -30,
      "y": 61,
      "z": 7,
      "name": "Plant_Leaves_Jungle_Max_Support"
    },
    {
      "x": -30,
      "y": 62,
      "z": 7,
      "name": "Plant_Leaves_Jungle_Max_Support"
    },
    {
      "x": -30,
      "y": 55,
      "z": 8,
      "name": "Plant_Leaves_Jungle_Max_Support"
    },
    {
      "x": -30,
      "y": 56,
      "z": 8,
      "name": "Plant_Leaves_Jungle_Max_Support"
    },
    {
      "x": -30,
      "y": 57,
      "z": 8,
      "name": "Plant_Leaves_Jungle_Max_Support"
    },
    {
      "x": -30,
      "y": 58,
      "z": 8,
      "name": "Plant_Leaves_Jungle_Max_Support"
    },
    {
      "x": -30,
      "y": 59,
      "z": 8,
      "name": "Plant_Leaves_Jungle_Max_Support"
    },
    {
      "x": -30,
      "y": 60,
      "z": 8,
      "name": "Plant_Leaves_Jungle_Max_Support"
    },
    {
      "x": -30,
      "y": 63,
      "z": 8,
      "name": "Plant_Leaves_Jungle_Max_Support"
    },
    {
      "x": -30,
      "y": 54,
      "z": 9,
      "name": "Plant_Leaves_Jungle_Max_Support"
    },
    {
      "x": -30,
      "y": 55,
      "z": 9,
      "name": "Plant_Leaves_Jungle_Max_Support"
    },
    {
      "x": -30,
      "y": 56,
      "z": 9,
      "name": "Plant_Leaves_Jungle_Max_Support"
    },
    {
      "x": -30,
      "y": 57,
      "z": 9,
      "name": "Plant_Leaves_Jungle_Max_Support"
    },
    {
      "x": -30,
      "y": 58,
      "z": 9,
      "name": "Plant_Leaves_Jungle_Max_Support"
    },
    {
      "x": -30,
      "y": 59,
      "z": 9,
      "name": "Plant_Leaves_Jungle_Max_Support"
    },
    {
      "x": -30,
      "y": 60,
      "z": 9,
      "name": "Plant_Leaves_Jungle_Max_Support"
    },
    {
      "x": -30,
      "y": 61,
      "z": 9,
      "name": "Plant_Leaves_Jungle_Max_Support"
    },
    {
      "x": -30,
      "y": 62,
      "z": 9,
      "name": "Plant_Leaves_Jungle_Max_Support"
    },
    {
      "x": -30,
      "y": 53,
      "z": 10,
      "name": "Plant_Leaves_Jungle_Max_Support"
    },
    {
      "x": -30,
      "y": 54,
      "z": 10,
      "name": "Plant_Leaves_Jungle_Max_Support"
    },
    {
      "x": -30,
      "y": 55,
      "z": 10,
      "name": "Plant_Leaves_Jungle_Max_Support"
    },
    {
      "x": -30,
      "y": 56,
      "z": 10,
      "name": "Plant_Leaves_Jungle_Max_Support"
    },
    {
      "x": -30,
      "y": 57,
      "z": 10,
      "name": "Plant_Leaves_Jungle_Max_Support"
    },
    {
      "x": -30,
      "y": 58,
      "z": 10,
      "name": "Plant_Leaves_Jungle_Max_Support"
    },
    {
      "x": -30,
      "y": 59,
      "z": 10,
      "name": "Plant_Leaves_Jungle_Max_Support"
    },
    {
      "x": -30,
      "y": 61,
      "z": 10,
      "name": "Plant_Leaves_Jungle_Max_Support"
    },
    {
      "x": -30,
      "y": 74,
      "z": 10,
      "name": "Plant_Leaves_Jungle_Max_Support"
    },
    {
      "x": -30,
      "y": 75,
      "z": 10,
      "name": "Plant_Leaves_Jungle_Max_Support"
    },
    {
      "x": -30,
      "y": 77,
      "z": 10,
      "name": "Plant_Leaves_Jungle_Max_Support"
    },
    {
      "x": -30,
      "y": 53,
      "z": 11,
      "name": "Plant_Leaves_Jungle_Max_Support"
    },
    {
      "x": -30,
      "y": 54,
      "z": 11,
      "name": "Plant_Leaves_Jungle_Max_Support"
    },
    {
      "x": -30,
      "y": 55,
      "z": 11,
      "name": "Plant_Leaves_Jungle_Max_Support"
    },
    {
      "x": -30,
      "y": 56,
      "z": 11,
      "name": "Plant_Leaves_Jungle_Max_Support"
    },
    {
      "x": -30,
      "y": 57,
      "z": 11,
      "name": "Plant_Leaves_Jungle_Max_Support"
    },
    {
      "x": -30,
      "y": 58,
      "z": 11,
      "name": "Plant_Leaves_Jungle_Max_Support"
    },
    {
      "x": -30,
      "y": 59,
      "z": 11,
      "name": "Plant_Leaves_Jungle_Max_Support"
    },
    {
      "x": -30,
      "y": 60,
      "z": 11,
      "name": "Plant_Leaves_Jungle_Max_Support"
    },
    {
      "x": -30,
      "y": 61,
      "z": 11,
      "name": "Plant_Leaves_Jungle_Max_Support"
    },
    {
      "x": -30,
      "y": 62,
      "z": 11,
      "name": "Plant_Leaves_Jungle_Max_Support"
    },
    {
      "x": -30,
      "y": 63,
      "z": 11,
      "name": "Plant_Leaves_Jungle_Max_Support"
    },
    {
      "x": -30,
      "y": 64,
      "z": 11,
      "name": "Plant_Leaves_Jungle_Max_Support"
    },
    {
      "x": -30,
      "y": 74,
      "z": 11,
      "name": "Plant_Leaves_Jungle_Max_Support"
    },
    {
      "x": -30,
      "y": 75,
      "z": 11,
      "name": "Plant_Leaves_Jungle_Max_Support"
    },
    {
      "x": -30,
      "y": 76,
      "z": 11,
      "name": "Plant_Leaves_Jungle_Max_Support"
    },
    {
      "x": -30,
      "y": 77,
      "z": 11,
      "name": "Plant_Leaves_Jungle_Max_Support"
    },
    {
      "x": -30,
      "y": 78,
      "z": 11,
      "name": "Plant_Leaves_Jungle_Max_Support"
    },
    {
      "x": -30,
      "y": 53,
      "z": 12,
      "name": "Plant_Leaves_Jungle_Max_Support"
    },
    {
      "x": -30,
      "y": 55,
      "z": 12,
      "name": "Plant_Leaves_Jungle_Max_Support"
    },
    {
      "x": -30,
      "y": 56,
      "z": 12,
      "name": "Plant_Leaves_Jungle_Max_Support"
    },
    {
      "x": -30,
      "y": 57,
      "z": 12,
      "name": "Plant_Leaves_Jungle_Max_Support"
    },
    {
      "x": -30,
      "y": 58,
      "z": 12,
      "name": "Plant_Leaves_Jungle_Max_Support"
    },
    {
      "x": -30,
      "y": 59,
      "z": 12,
      "name": "Plant_Leaves_Jungle_Max_Support"
    },
    {
      "x": -30,
      "y": 60,
      "z": 12,
      "name": "Plant_Leaves_Jungle_Max_Support"
    },
    {
      "x": -30,
      "y": 61,
      "z": 12,
      "name": "Plant_Leaves_Jungle_Max_Support"
    },
    {
      "x": -30,
      "y": 74,
      "z": 12,
      "name": "Plant_Leaves_Jungle_Max_Support"
    },
    {
      "x": -30,
      "y": 75,
      "z": 12,
      "name": "Plant_Leaves_Jungle_Max_Support"
    },
    {
      "x": -30,
      "y": 76,
      "z": 12,
      "name": "Plant_Leaves_Jungle_Max_Support"
    },
    {
      "x": -30,
      "y": 77,
      "z": 12,
      "name": "Plant_Leaves_Jungle_Max_Support"
    },
    {
      "x": -30,
      "y": 78,
      "z": 12,
      "name": "Plant_Leaves_Jungle_Max_Support"
    },
    {
      "x": -30,
      "y": 79,
      "z": 12,
      "name": "Plant_Leaves_Jungle_Max_Support"
    },
    {
      "x": -30,
      "y": 54,
      "z": 13,
      "name": "Plant_Leaves_Jungle_Max_Support"
    },
    {
      "x": -30,
      "y": 55,
      "z": 13,
      "name": "Plant_Leaves_Jungle_Max_Support"
    },
    {
      "x": -30,
      "y": 56,
      "z": 13,
      "name": "Plant_Leaves_Jungle_Max_Support"
    },
    {
      "x": -30,
      "y": 57,
      "z": 13,
      "name": "Plant_Leaves_Jungle_Max_Support"
    },
    {
      "x": -30,
      "y": 58,
      "z": 13,
      "name": "Plant_Leaves_Jungle_Max_Support"
    },
    {
      "x": -30,
      "y": 59,
      "z": 13,
      "name": "Plant_Leaves_Jungle_Max_Support"
    },
    {
      "x": -30,
      "y": 60,
      "z": 13,
      "name": "Plant_Leaves_Jungle_Max_Support"
    },
    {
      "x": -30,
      "y": 61,
      "z": 13,
      "name": "Plant_Leaves_Jungle_Max_Support"
    },
    {
      "x": -30,
      "y": 62,
      "z": 13,
      "name": "Plant_Leaves_Jungle_Max_Support"
    },
    {
      "x": -30,
      "y": 75,
      "z": 13,
      "name": "Plant_Leaves_Jungle_Max_Support"
    },
    {
      "x": -30,
      "y": 76,
      "z": 13,
      "name": "Plant_Leaves_Jungle_Max_Support"
    },
    {
      "x": -30,
      "y": 77,
      "z": 13,
      "name": "Plant_Leaves_Jungle_Max_Support"
    },
    {
      "x": -30,
      "y": 78,
      "z": 13,
      "name": "Plant_Leaves_Jungle_Max_Support"
    },
    {
      "x": -30,
      "y": 79,
      "z": 13,
      "name": "Plant_Leaves_Jungle_Max_Support"
    },
    {
      "x": -30,
      "y": 58,
      "z": 14,
      "name": "Plant_Leaves_Jungle_Max_Support"
    },
    {
      "x": -30,
      "y": 76,
      "z": 14,
      "name": "Plant_Leaves_Jungle_Max_Support"
    },
    {
      "x": -30,
      "y": 77,
      "z": 14,
      "name": "Plant_Leaves_Jungle_Max_Support"
    },
    {
      "x": -30,
      "y": 79,
      "z": 14,
      "name": "Plant_Leaves_Jungle_Max_Support"
    },
    {
      "x": -30,
      "y": 60,
      "z": 15,
      "name": "Plant_Leaves_Jungle_Max_Support"
    },
    {
      "x": -30,
      "y": 61,
      "z": 15,
      "name": "Plant_Leaves_Jungle_Max_Support"
    },
    {
      "x": -30,
      "y": 76,
      "z": 15,
      "name": "Plant_Leaves_Jungle_Max_Support"
    },
    {
      "x": -30,
      "y": 77,
      "z": 15,
      "name": "Plant_Leaves_Jungle_Max_Support"
    },
    {
      "x": -30,
      "y": 78,
      "z": 15,
      "name": "Plant_Leaves_Jungle_Max_Support"
    },
    {
      "x": -30,
      "y": 79,
      "z": 15,
      "name": "Plant_Leaves_Jungle_Max_Support"
    },
    {
      "x": -30,
      "y": 60,
      "z": 16,
      "name": "Plant_Leaves_Jungle_Max_Support"
    },
    {
      "x": -30,
      "y": 73,
      "z": 16,
      "name": "Plant_Leaves_Jungle_Max_Support"
    },
    {
      "x": -30,
      "y": 74,
      "z": 16,
      "name": "Plant_Leaves_Jungle_Max_Support"
    },
    {
      "x": -30,
      "y": 75,
      "z": 16,
      "name": "Plant_Leaves_Jungle_Max_Support"
    },
    {
      "x": -30,
      "y": 76,
      "z": 16,
      "name": "Plant_Leaves_Jungle_Max_Support"
    },
    {
      "x": -30,
      "y": 77,
      "z": 16,
      "name": "Plant_Leaves_Jungle_Max_Support"
    },
    {
      "x": -30,
      "y": 78,
      "z": 16,
      "name": "Plant_Leaves_Jungle_Max_Support"
    },
    {
      "x": -30,
      "y": 72,
      "z": 17,
      "name": "Plant_Leaves_Jungle_Max_Support"
    },
    {
      "x": -30,
      "y": 73,
      "z": 17,
      "name": "Plant_Leaves_Jungle_Max_Support"
    },
    {
      "x": -30,
      "y": 75,
      "z": 17,
      "name": "Plant_Leaves_Jungle_Max_Support"
    },
    {
      "x": -30,
      "y": 76,
      "z": 17,
      "name": "Plant_Leaves_Jungle_Max_Support"
    },
    {
      "x": -30,
      "y": 77,
      "z": 17,
      "name": "Plant_Leaves_Jungle_Max_Support"
    },
    {
      "x": -30,
      "y": 78,
      "z": 17,
      "name": "Plant_Leaves_Jungle_Max_Support"
    },
    {
      "x": -30,
      "y": 73,
      "z": 18,
      "name": "Plant_Leaves_Jungle_Max_Support"
    },
    {
      "x": -30,
      "y": 74,
      "z": 18,
      "name": "Plant_Leaves_Jungle_Max_Support"
    },
    {
      "x": -30,
      "y": 75,
      "z": 18,
      "name": "Plant_Leaves_Jungle_Max_Support"
    },
    {
      "x": -30,
      "y": 76,
      "z": 18,
      "name": "Plant_Leaves_Jungle_Max_Support"
    },
    {
      "x": -30,
      "y": 77,
      "z": 18,
      "name": "Plant_Leaves_Jungle_Max_Support"
    },
    {
      "x": -30,
      "y": 78,
      "z": 18,
      "name": "Plant_Leaves_Jungle_Max_Support"
    },
    {
      "x": -30,
      "y": 73,
      "z": 19,
      "name": "Plant_Leaves_Jungle_Max_Support"
    },
    {
      "x": -30,
      "y": 74,
      "z": 19,
      "name": "Plant_Leaves_Jungle_Max_Support"
    },
    {
      "x": -30,
      "y": 75,
      "z": 19,
      "name": "Plant_Leaves_Jungle_Max_Support"
    },
    {
      "x": -30,
      "y": 76,
      "z": 19,
      "name": "Plant_Leaves_Jungle_Max_Support"
    },
    {
      "x": -30,
      "y": 79,
      "z": 19,
      "name": "Plant_Leaves_Jungle_Max_Support"
    },
    {
      "x": -30,
      "y": 73,
      "z": 20,
      "name": "Plant_Leaves_Jungle_Max_Support"
    },
    {
      "x": -30,
      "y": 74,
      "z": 20,
      "name": "Plant_Leaves_Jungle_Max_Support"
    },
    {
      "x": -30,
      "y": 75,
      "z": 20,
      "name": "Plant_Leaves_Jungle_Max_Support"
    },
    {
      "x": -30,
      "y": 76,
      "z": 20,
      "name": "Plant_Leaves_Jungle_Max_Support"
    },
    {
      "x": -30,
      "y": 72,
      "z": 21,
      "name": "Plant_Leaves_Jungle_Max_Support"
    },
    {
      "x": -30,
      "y": 74,
      "z": 21,
      "name": "Plant_Leaves_Jungle_Max_Support"
    },
    {
      "x": -30,
      "y": 75,
      "z": 21,
      "name": "Plant_Leaves_Jungle_Max_Support"
    },
    {
      "x": -30,
      "y": 75,
      "z": 22,
      "name": "Plant_Leaves_Jungle_Max_Support"
    },
    {
      "x": -30,
      "y": 73,
      "z": 24,
      "name": "Plant_Leaves_Jungle_Max_Support"
    },
    {
      "x": -30,
      "y": 74,
      "z": 25,
      "name": "Plant_Leaves_Jungle_Max_Support"
    },
    {
      "x": -29,
      "y": 55,
      "z": 2,
      "name": "Plant_Leaves_Jungle_Max_Support",
      "support": 15
    },
    {
      "x": -29,
      "y": 56,
      "z": 2,
      "name": "Plant_Leaves_Jungle_Max_Support",
      "support": 15
    },
    {
      "x": -29,
      "y": 57,
      "z": 2,
      "name": "Plant_Leaves_Jungle_Max_Support",
      "support": 15
    },
    {
      "x": -29,
      "y": 59,
      "z": 2,
      "name": "Plant_Leaves_Jungle_Max_Support"
    },
    {
      "x": -29,
      "y": 60,
      "z": 2,
      "name": "Plant_Leaves_Jungle_Max_Support"
    },
    {
      "x": -29,
      "y": 57,
      "z": 3,
      "name": "Plant_Leaves_Jungle_Max_Support"
    },
    {
      "x": -29,
      "y": 61,
      "z": 3,
      "name": "Plant_Leaves_Jungle_Max_Support"
    },
    {
      "x": -29,
      "y": 56,
      "z": 4,
      "name": "Plant_Leaves_Jungle_Max_Support"
    },
    {
      "x": -29,
      "y": 57,
      "z": 4,
      "name": "Plant_Leaves_Jungle_Max_Support"
    },
    {
      "x": -29,
      "y": 58,
      "z": 4,
      "name": "Plant_Leaves_Jungle_Max_Support"
    },
    {
      "x": -29,
      "y": 59,
      "z": 4,
      "name": "Plant_Leaves_Jungle_Max_Support"
    },
    {
      "x": -29,
      "y": 60,
      "z": 4,
      "name": "Plant_Leaves_Jungle_Max_Support"
    },
    {
      "x": -29,
      "y": 56,
      "z": 5,
      "name": "Plant_Leaves_Jungle_Max_Support"
    },
    {
      "x": -29,
      "y": 57,
      "z": 5,
      "name": "Plant_Leaves_Jungle_Max_Support"
    },
    {
      "x": -29,
      "y": 58,
      "z": 5,
      "name": "Plant_Leaves_Jungle_Max_Support"
    },
    {
      "x": -29,
      "y": 60,
      "z": 5,
      "name": "Plant_Leaves_Jungle_Max_Support"
    },
    {
      "x": -29,
      "y": 61,
      "z": 5,
      "name": "Plant_Leaves_Jungle_Max_Support"
    },
    {
      "x": -29,
      "y": 55,
      "z": 6,
      "name": "Plant_Leaves_Jungle_Max_Support"
    },
    {
      "x": -29,
      "y": 56,
      "z": 6,
      "name": "Plant_Leaves_Jungle_Max_Support"
    },
    {
      "x": -29,
      "y": 57,
      "z": 6,
      "name": "Plant_Leaves_Jungle_Max_Support"
    },
    {
      "x": -29,
      "y": 58,
      "z": 6,
      "name": "Plant_Leaves_Jungle_Max_Support"
    },
    {
      "x": -29,
      "y": 59,
      "z": 6,
      "name": "Plant_Leaves_Jungle_Max_Support"
    },
    {
      "x": -29,
      "y": 60,
      "z": 6,
      "name": "Plant_Leaves_Jungle_Max_Support"
    },
    {
      "x": -29,
      "y": 61,
      "z": 6,
      "name": "Plant_Leaves_Jungle_Max_Support"
    },
    {
      "x": -29,
      "y": 55,
      "z": 7,
      "name": "Plant_Leaves_Jungle_Max_Support"
    },
    {
      "x": -29,
      "y": 56,
      "z": 7,
      "name": "Plant_Leaves_Jungle_Max_Support"
    },
    {
      "x": -29,
      "y": 57,
      "z": 7,
      "name": "Plant_Leaves_Jungle_Max_Support"
    },
    {
      "x": -29,
      "y": 58,
      "z": 7,
      "name": "Plant_Leaves_Jungle_Max_Support"
    },
    {
      "x": -29,
      "y": 59,
      "z": 7,
      "name": "Plant_Leaves_Jungle_Max_Support"
    },
    {
      "x": -29,
      "y": 60,
      "z": 7,
      "name": "Plant_Leaves_Jungle_Max_Support"
    },
    {
      "x": -29,
      "y": 61,
      "z": 7,
      "name": "Plant_Leaves_Jungle_Max_Support"
    },
    {
      "x": -29,
      "y": 62,
      "z": 7,
      "name": "Plant_Leaves_Jungle_Max_Support"
    },
    {
      "x": -29,
      "y": 63,
      "z": 7,
      "name": "Plant_Leaves_Jungle_Max_Support"
    },
    {
      "x": -29,
      "y": 56,
      "z": 8,
      "name": "Plant_Leaves_Jungle_Max_Support"
    },
    {
      "x": -29,
      "y": 61,
      "z": 8,
      "name": "Plant_Leaves_Jungle_Max_Support"
    },
    {
      "x": -29,
      "y": 63,
      "z": 8,
      "name": "Plant_Leaves_Jungle_Max_Support"
    },
    {
      "x": -29,
      "y": 55,
      "z": 9,
      "name": "Plant_Leaves_Jungle_Max_Support"
    },
    {
      "x": -29,
      "y": 56,
      "z": 9,
      "name": "Plant_Leaves_Jungle_Max_Support"
    },
    {
      "x": -29,
      "y": 59,
      "z": 9,
      "name": "Plant_Leaves_Jungle_Max_Support"
    },
    {
      "x": -29,
      "y": 60,
      "z": 9,
      "name": "Plant_Leaves_Jungle_Max_Support"
    },
    {
      "x": -29,
      "y": 61,
      "z": 9,
      "name": "Plant_Leaves_Jungle_Max_Support"
    },
    {
      "x": -29,
      "y": 62,
      "z": 9,
      "name": "Plant_Leaves_Jungle_Max_Support"
    },
    {
      "x": -29,
      "y": 63,
      "z": 9,
      "name": "Plant_Leaves_Jungle_Max_Support"
    },
    {
      "x": -29,
      "y": 64,
      "z": 9,
      "name": "Plant_Leaves_Jungle_Max_Support"
    },
    {
      "x": -29,
      "y": 75,
      "z": 9,
      "name": "Plant_Leaves_Jungle_Max_Support"
    },
    {
      "x": -29,
      "y": 76,
      "z": 9,
      "name": "Plant_Leaves_Jungle_Max_Support"
    },
    {
      "x": -29,
      "y": 77,
      "z": 9,
      "name": "Plant_Leaves_Jungle_Max_Support"
    },
    {
      "x": -29,
      "y": 54,
      "z": 10,
      "name": "Plant_Leaves_Jungle_Max_Support"
    },
    {
      "x": -29,
      "y": 55,
      "z": 10,
      "name": "Plant_Leaves_Jungle_Max_Support"
    },
    {
      "x": -29,
      "y": 56,
      "z": 10,
      "name": "Plant_Leaves_Jungle_Max_Support"
    },
    {
      "x": -29,
      "y": 57,
      "z": 10,
      "name": "Plant_Leaves_Jungle_Max_Support"
    },
    {
      "x": -29,
      "y": 58,
      "z": 10,
      "name": "Plant_Leaves_Jungle_Max_Support"
    },
    {
      "x": -29,
      "y": 59,
      "z": 10,
      "name": "Plant_Leaves_Jungle_Max_Support"
    },
    {
      "x": -29,
      "y": 60,
      "z": 10,
      "name": "Plant_Leaves_Jungle_Max_Support"
    },
    {
      "x": -29,
      "y": 61,
      "z": 10,
      "name": "Plant_Leaves_Jungle_Max_Support"
    },
    {
      "x": -29,
      "y": 62,
      "z": 10,
      "name": "Plant_Leaves_Jungle_Max_Support"
    },
    {
      "x": -29,
      "y": 63,
      "z": 10,
      "name": "Plant_Leaves_Jungle_Max_Support"
    },
    {
      "x": -29,
      "y": 75,
      "z": 10,
      "name": "Plant_Leaves_Jungle_Max_Support"
    },
    {
      "x": -29,
      "y": 76,
      "z": 10,
      "name": "Plant_Leaves_Jungle_Max_Support"
    },
    {
      "x": -29,
      "y": 77,
      "z": 10,
      "name": "Plant_Leaves_Jungle_Max_Support"
    },
    {
      "x": -29,
      "y": 78,
      "z": 10,
      "name": "Plant_Leaves_Jungle_Max_Support"
    },
    {
      "x": -29,
      "y": 53,
      "z": 11,
      "name": "Plant_Leaves_Jungle_Max_Support"
    },
    {
      "x": -29,
      "y": 54,
      "z": 11,
      "name": "Plant_Leaves_Jungle_Max_Support"
    },
    {
      "x": -29,
      "y": 55,
      "z": 11,
      "name": "Plant_Leaves_Jungle_Max_Support"
    },
    {
      "x": -29,
      "y": 56,
      "z": 11,
      "name": "Plant_Leaves_Jungle_Max_Support"
    },
    {
      "x": -29,
      "y": 57,
      "z": 11,
      "name": "Plant_Leaves_Jungle_Max_Support"
    },
    {
      "x": -29,
      "y": 58,
      "z": 11,
      "name": "Plant_Leaves_Jungle_Max_Support"
    },
    {
      "x": -29,
      "y": 59,
      "z": 11,
      "name": "Plant_Leaves_Jungle_Max_Support"
    },
    {
      "x": -29,
      "y": 60,
      "z": 11,
      "name": "Plant_Leaves_Jungle_Max_Support"
    },
    {
      "x": -29,
      "y": 61,
      "z": 11,
      "name": "Plant_Leaves_Jungle_Max_Support"
    },
    {
      "x": -29,
      "y": 74,
      "z": 11,
      "name": "Plant_Leaves_Jungle_Max_Support"
    },
    {
      "x": -29,
      "y": 75,
      "z": 11,
      "name": "Plant_Leaves_Jungle_Max_Support"
    },
    {
      "x": -29,
      "y": 76,
      "z": 11,
      "name": "Plant_Leaves_Jungle_Max_Support"
    },
    {
      "x": -29,
      "y": 54,
      "z": 12,
      "name": "Plant_Leaves_Jungle_Max_Support"
    },
    {
      "x": -29,
      "y": 55,
      "z": 12,
      "name": "Plant_Leaves_Jungle_Max_Support"
    },
    {
      "x": -29,
      "y": 56,
      "z": 12,
      "name": "Plant_Leaves_Jungle_Max_Support"
    },
    {
      "x": -29,
      "y": 57,
      "z": 12,
      "name": "Plant_Leaves_Jungle_Max_Support"
    },
    {
      "x": -29,
      "y": 58,
      "z": 12,
      "name": "Plant_Leaves_Jungle_Max_Support"
    },
    {
      "x": -29,
      "y": 59,
      "z": 12,
      "name": "Plant_Leaves_Jungle_Max_Support"
    },
    {
      "x": -29,
      "y": 60,
      "z": 12,
      "name": "Plant_Leaves_Jungle_Max_Support"
    },
    {
      "x": -29,
      "y": 61,
      "z": 12,
      "name": "Plant_Leaves_Jungle_Max_Support"
    },
    {
      "x": -29,
      "y": 62,
      "z": 12,
      "name": "Plant_Leaves_Jungle_Max_Support"
    },
    {
      "x": -29,
      "y": 74,
      "z": 12,
      "name": "Plant_Leaves_Jungle_Max_Support"
    },
    {
      "x": -29,
      "y": 75,
      "z": 12,
      "name": "Plant_Leaves_Jungle_Max_Support"
    },
    {
      "x": -29,
      "y": 76,
      "z": 12,
      "name": "Plant_Leaves_Jungle_Max_Support"
    },
    {
      "x": -29,
      "y": 77,
      "z": 12,
      "name": "Plant_Leaves_Jungle_Max_Support"
    },
    {
      "x": -29,
      "y": 78,
      "z": 12,
      "name": "Plant_Leaves_Jungle_Max_Support"
    },
    {
      "x": -29,
      "y": 79,
      "z": 12,
      "name": "Plant_Leaves_Jungle_Max_Support"
    },
    {
      "x": -29,
      "y": 55,
      "z": 13,
      "name": "Plant_Leaves_Jungle_Max_Support"
    },
    {
      "x": -29,
      "y": 56,
      "z": 13,
      "name": "Plant_Leaves_Jungle_Max_Support"
    },
    {
      "x": -29,
      "y": 57,
      "z": 13,
      "name": "Plant_Leaves_Jungle_Max_Support"
    },
    {
      "x": -29,
      "y": 58,
      "z": 13,
      "name": "Plant_Leaves_Jungle_Max_Support"
    },
    {
      "x": -29,
      "y": 59,
      "z": 13,
      "name": "Plant_Leaves_Jungle_Max_Support"
    },
    {
      "x": -29,
      "y": 60,
      "z": 13,
      "name": "Plant_Leaves_Jungle_Max_Support"
    },
    {
      "x": -29,
      "y": 61,
      "z": 13,
      "name": "Plant_Leaves_Jungle_Max_Support"
    },
    {
      "x": -29,
      "y": 62,
      "z": 13,
      "name": "Plant_Leaves_Jungle_Max_Support"
    },
    {
      "x": -29,
      "y": 76,
      "z": 13,
      "name": "Plant_Leaves_Jungle_Max_Support"
    },
    {
      "x": -29,
      "y": 77,
      "z": 13,
      "name": "Plant_Leaves_Jungle_Max_Support"
    },
    {
      "x": -29,
      "y": 78,
      "z": 13,
      "name": "Plant_Leaves_Jungle_Max_Support"
    },
    {
      "x": -29,
      "y": 79,
      "z": 13,
      "name": "Plant_Leaves_Jungle_Max_Support"
    },
    {
      "x": -29,
      "y": 56,
      "z": 14,
      "name": "Plant_Leaves_Jungle_Max_Support"
    },
    {
      "x": -29,
      "y": 57,
      "z": 14,
      "name": "Plant_Leaves_Jungle_Max_Support"
    },
    {
      "x": -29,
      "y": 58,
      "z": 14,
      "name": "Plant_Leaves_Jungle_Max_Support"
    },
    {
      "x": -29,
      "y": 59,
      "z": 14,
      "name": "Plant_Leaves_Jungle_Max_Support"
    },
    {
      "x": -29,
      "y": 60,
      "z": 14,
      "name": "Plant_Leaves_Jungle_Max_Support"
    },
    {
      "x": -29,
      "y": 62,
      "z": 14,
      "name": "Plant_Leaves_Jungle_Max_Support"
    },
    {
      "x": -29,
      "y": 77,
      "z": 14,
      "name": "Plant_Leaves_Jungle_Max_Support"
    },
    {
      "x": -29,
      "y": 78,
      "z": 14,
      "name": "Plant_Leaves_Jungle_Max_Support"
    },
    {
      "x": -29,
      "y": 79,
      "z": 14,
      "name": "Plant_Leaves_Jungle_Max_Support"
    },
    {
      "x": -29,
      "y": 80,
      "z": 14,
      "name": "Plant_Leaves_Jungle_Max_Support"
    },
    {
      "x": -29,
      "y": 58,
      "z": 15,
      "name": "Plant_Leaves_Jungle_Max_Support"
    },
    {
      "x": -29,
      "y": 59,
      "z": 15,
      "name": "Plant_Leaves_Jungle_Max_Support"
    },
    {
      "x": -29,
      "y": 60,
      "z": 15,
      "name": "Plant_Leaves_Jungle_Max_Support"
    },
    {
      "x": -29,
      "y": 61,
      "z": 15,
      "name": "Plant_Leaves_Jungle_Max_Support"
    },
    {
      "x": -29,
      "y": 62,
      "z": 15,
      "name": "Plant_Leaves_Jungle_Max_Support"
    },
    {
      "x": -29,
      "y": 76,
      "z": 15,
      "name": "Plant_Leaves_Jungle_Max_Support"
    },
    {
      "x": -29,
      "y": 77,
      "z": 15,
      "name": "Plant_Leaves_Jungle_Max_Support"
    },
    {
      "x": -29,
      "y": 78,
      "z": 15,
      "name": "Plant_Leaves_Jungle_Max_Support"
    },
    {
      "x": -29,
      "y": 79,
      "z": 15,
      "name": "Plant_Leaves_Jungle_Max_Support"
    },
    {
      "x": -29,
      "y": 80,
      "z": 15,
      "name": "Plant_Leaves_Jungle_Max_Support"
    },
    {
      "x": -29,
      "y": 59,
      "z": 16,
      "name": "Plant_Leaves_Jungle_Max_Support"
    },
    {
      "x": -29,
      "y": 60,
      "z": 16,
      "name": "Plant_Leaves_Jungle_Max_Support"
    },
    {
      "x": -29,
      "y": 72,
      "z": 16,
      "name": "Plant_Leaves_Jungle_Max_Support"
    },
    {
      "x": -29,
      "y": 74,
      "z": 16,
      "name": "Plant_Leaves_Jungle_Max_Support"
    },
    {
      "x": -29,
      "y": 75,
      "z": 16,
      "name": "Plant_Leaves_Jungle_Max_Support"
    },
    {
      "x": -29,
      "y": 76,
      "z": 16,
      "name": "Plant_Leaves_Jungle_Max_Support"
    },
    {
      "x": -29,
      "y": 77,
      "z": 16,
      "name": "Plant_Leaves_Jungle_Max_Support"
    },
    {
      "x": -29,
      "y": 78,
      "z": 16,
      "name": "Plant_Leaves_Jungle_Max_Support"
    },
    {
      "x": -29,
      "y": 79,
      "z": 16,
      "name": "Plant_Leaves_Jungle_Max_Support"
    },
    {
      "x": -29,
      "y": 80,
      "z": 16,
      "name": "Plant_Leaves_Jungle_Max_Support"
    },
    {
      "x": -29,
      "y": 81,
      "z": 16,
      "name": "Plant_Leaves_Jungle_Max_Support"
    },
    {
      "x": -29,
      "y": 71,
      "z": 17,
      "name": "Plant_Leaves_Jungle_Max_Support"
    },
    {
      "x": -29,
      "y": 74,
      "z": 17,
      "name": "Plant_Leaves_Jungle_Max_Support"
    },
    {
      "x": -29,
      "y": 75,
      "z": 17,
      "name": "Plant_Leaves_Jungle_Max_Support"
    },
    {
      "x": -29,
      "y": 76,
      "z": 17,
      "name": "Plant_Leaves_Jungle_Max_Support"
    },
    {
      "x": -29,
      "y": 77,
      "z": 17,
      "name": "Plant_Leaves_Jungle_Max_Support"
    },
    {
      "x": -29,
      "y": 78,
      "z": 17,
      "name": "Plant_Leaves_Jungle_Max_Support"
    },
    {
      "x": -29,
      "y": 79,
      "z": 17,
      "name": "Plant_Leaves_Jungle_Max_Support"
    },
    {
      "x": -29,
      "y": 72,
      "z": 18,
      "name": "Plant_Leaves_Jungle_Max_Support"
    },
    {
      "x": -29,
      "y": 73,
      "z": 18,
      "name": "Plant_Leaves_Jungle_Max_Support"
    },
    {
      "x": -29,
      "y": 74,
      "z": 18,
      "name": "Plant_Leaves_Jungle_Max_Support"
    },
    {
      "x": -29,
      "y": 75,
      "z": 18,
      "name": "Plant_Leaves_Jungle_Max_Support"
    },
    {
      "x": -29,
      "y": 76,
      "z": 18,
      "name": "Plant_Leaves_Jungle_Max_Support"
    },
    {
      "x": -29,
      "y": 77,
      "z": 18,
      "name": "Plant_Leaves_Jungle_Max_Support"
    },
    {
      "x": -29,
      "y": 78,
      "z": 18,
      "name": "Plant_Leaves_Jungle_Max_Support"
    },
    {
      "x": -29,
      "y": 79,
      "z": 18,
      "name": "Plant_Leaves_Jungle_Max_Support"
    },
    {
      "x": -29,
      "y": 81,
      "z": 18,
      "name": "Plant_Leaves_Jungle_Max_Support"
    },
    {
      "x": -29,
      "y": 72,
      "z": 19,
      "name": "Plant_Leaves_Jungle_Max_Support"
    },
    {
      "x": -29,
      "y": 73,
      "z": 19,
      "name": "Plant_Leaves_Jungle_Max_Support"
    },
    {
      "x": -29,
      "y": 74,
      "z": 19,
      "name": "Plant_Leaves_Jungle_Max_Support"
    },
    {
      "x": -29,
      "y": 75,
      "z": 19,
      "name": "Plant_Leaves_Jungle_Max_Support"
    },
    {
      "x": -29,
      "y": 76,
      "z": 19,
      "name": "Plant_Leaves_Jungle_Max_Support"
    },
    {
      "x": -29,
      "y": 78,
      "z": 19,
      "name": "Plant_Leaves_Jungle_Max_Support"
    },
    {
      "x": -29,
      "y": 79,
      "z": 19,
      "name": "Plant_Leaves_Jungle_Max_Support"
    },
    {
      "x": -29,
      "y": 80,
      "z": 19,
      "name": "Plant_Leaves_Jungle_Max_Support"
    },
    {
      "x": -29,
      "y": 73,
      "z": 20,
      "name": "Plant_Leaves_Jungle_Max_Support"
    },
    {
      "x": -29,
      "y": 74,
      "z": 20,
      "name": "Plant_Leaves_Jungle_Max_Support"
    },
    {
      "x": -29,
      "y": 73,
      "z": 21,
      "name": "Plant_Leaves_Jungle_Max_Support"
    },
    {
      "x": -29,
      "y": 74,
      "z": 21,
      "name": "Plant_Leaves_Jungle_Max_Support"
    },
    {
      "x": -29,
      "y": 74,
      "z": 22,
      "name": "Plant_Leaves_Jungle_Max_Support"
    },
    {
      "x": -29,
      "y": 75,
      "z": 23,
      "name": "Plant_Leaves_Jungle_Max_Support"
    },
    {
      "x": -29,
      "y": 72,
      "z": 24,
      "name": "Plant_Leaves_Jungle_Max_Support"
    },
    {
      "x": -29,
      "y": 75,
      "z": 25,
      "name": "Plant_Leaves_Jungle_Max_Support"
    },
    {
      "x": -29,
      "y": 74,
      "z": 26,
      "name": "Plant_Leaves_Jungle_Max_Support"
    },
    {
      "x": -28,
      "y": 58,
      "z": 2,
      "name": "Plant_Leaves_Jungle_Max_Support",
      "support": 15
    },
    {
      "x": -28,
      "y": 59,
      "z": 2,
      "name": "Plant_Leaves_Jungle_Max_Support"
    },
    {
      "x": -28,
      "y": 59,
      "z": 3,
      "name": "Plant_Leaves_Jungle_Max_Support"
    },
    {
      "x": -28,
      "y": 60,
      "z": 3,
      "name": "Plant_Leaves_Jungle_Max_Support"
    },
    {
      "x": -28,
      "y": 59,
      "z": 4,
      "name": "Plant_Leaves_Jungle_Max_Support"
    },
    {
      "x": -28,
      "y": 60,
      "z": 4,
      "name": "Plant_Leaves_Jungle_Max_Support"
    },
    {
      "x": -28,
      "y": 61,
      "z": 4,
      "name": "Plant_Leaves_Jungle_Max_Support"
    },
    {
      "x": -28,
      "y": 56,
      "z": 5,
      "name": "Plant_Leaves_Jungle_Max_Support"
    },
    {
      "x": -28,
      "y": 57,
      "z": 5,
      "name": "Plant_Leaves_Jungle_Max_Support"
    },
    {
      "x": -28,
      "y": 58,
      "z": 5,
      "name": "Plant_Leaves_Jungle_Max_Support"
    },
    {
      "x": -28,
      "y": 59,
      "z": 5,
      "name": "Plant_Leaves_Jungle_Max_Support"
    },
    {
      "x": -28,
      "y": 60,
      "z": 5,
      "name": "Plant_Leaves_Jungle_Max_Support"
    },
    {
      "x": -28,
      "y": 55,
      "z": 6,
      "name": "Plant_Leaves_Jungle_Max_Support"
    },
    {
      "x": -28,
      "y": 56,
      "z": 6,
      "name": "Plant_Leaves_Jungle_Max_Support"
    },
    {
      "x": -28,
      "y": 57,
      "z": 6,
      "name": "Plant_Leaves_Jungle_Max_Support"
    },
    {
      "x": -28,
      "y": 58,
      "z": 6,
      "name": "Plant_Leaves_Jungle_Max_Support"
    },
    {
      "x": -28,
      "y": 60,
      "z": 6,
      "name": "Plant_Leaves_Jungle_Max_Support"
    },
    {
      "x": -28,
      "y": 61,
      "z": 6,
      "name": "Plant_Leaves_Jungle_Max_Support"
    },
    {
      "x": -28,
      "y": 62,
      "z": 6,
      "name": "Plant_Leaves_Jungle_Max_Support"
    },
    {
      "x": -28,
      "y": 55,
      "z": 7,
      "name": "Plant_Leaves_Jungle_Max_Support"
    },
    {
      "x": -28,
      "y": 57,
      "z": 7,
      "name": "Plant_Leaves_Jungle_Max_Support"
    },
    {
      "x": -28,
      "y": 58,
      "z": 7,
      "name": "Plant_Leaves_Jungle_Max_Support"
    },
    {
      "x": -28,
      "y": 59,
      "z": 7,
      "name": "Plant_Leaves_Jungle_Max_Support"
    },
    {
      "x": -28,
      "y": 60,
      "z": 7,
      "name": "Plant_Leaves_Jungle_Max_Support"
    },
    {
      "x": -28,
      "y": 61,
      "z": 7,
      "name": "Plant_Leaves_Jungle_Max_Support"
    },
    {
      "x": -28,
      "y": 62,
      "z": 7,
      "name": "Plant_Leaves_Jungle_Max_Support"
    },
    {
      "x": -28,
      "y": 63,
      "z": 7,
      "name": "Plant_Leaves_Jungle_Max_Support"
    },
    {
      "x": -28,
      "y": 56,
      "z": 8,
      "name": "Plant_Leaves_Jungle_Max_Support"
    },
    {
      "x": -28,
      "y": 59,
      "z": 8,
      "name": "Plant_Leaves_Jungle_Max_Support"
    },
    {
      "x": -28,
      "y": 60,
      "z": 8,
      "name": "Plant_Leaves_Jungle_Max_Support"
    },
    {
      "x": -28,
      "y": 62,
      "z": 8,
      "name": "Plant_Leaves_Jungle_Max_Support"
    },
    {
      "x": -28,
      "y": 63,
      "z": 8,
      "name": "Plant_Leaves_Jungle_Max_Support"
    },
    {
      "x": -28,
      "y": 64,
      "z": 8,
      "name": "Plant_Leaves_Jungle_Max_Support"
    },
    {
      "x": -28,
      "y": 74,
      "z": 8,
      "name": "Plant_Leaves_Jungle_Max_Support"
    },
    {
      "x": -28,
      "y": 54,
      "z": 9,
      "name": "Plant_Leaves_Jungle_Max_Support"
    },
    {
      "x": -28,
      "y": 59,
      "z": 9,
      "name": "Plant_Leaves_Jungle_Max_Support"
    },
    {
      "x": -28,
      "y": 60,
      "z": 9,
      "name": "Plant_Leaves_Jungle_Max_Support"
    },
    {
      "x": -28,
      "y": 61,
      "z": 9,
      "name": "Plant_Leaves_Jungle_Max_Support"
    },
    {
      "x": -28,
      "y": 62,
      "z": 9,
      "name": "Plant_Leaves_Jungle_Max_Support"
    },
    {
      "x": -28,
      "y": 63,
      "z": 9,
      "name": "Plant_Leaves_Jungle_Max_Support"
    },
    {
      "x": -28,
      "y": 64,
      "z": 9,
      "name": "Plant_Leaves_Jungle_Max_Support"
    },
    {
      "x": -28,
      "y": 65,
      "z": 9,
      "name": "Plant_Leaves_Jungle_Max_Support"
    },
    {
      "x": -28,
      "y": 74,
      "z": 9,
      "name": "Plant_Leaves_Jungle_Max_Support"
    },
    {
      "x": -28,
      "y": 77,
      "z": 9,
      "name": "Plant_Leaves_Jungle_Max_Support"
    },
    {
      "x": -28,
      "y": 54,
      "z": 10,
      "name": "Plant_Leaves_Jungle_Max_Support"
    },
    {
      "x": -28,
      "y": 58,
      "z": 10,
      "name": "Plant_Leaves_Jungle_Max_Support"
    },
    {
      "x": -28,
      "y": 59,
      "z": 10,
      "name": "Plant_Leaves_Jungle_Max_Support"
    },
    {
      "x": -28,
      "y": 60,
      "z": 10,
      "name": "Plant_Leaves_Jungle_Max_Support"
    },
    {
      "x": -28,
      "y": 61,
      "z": 10,
      "name": "Plant_Leaves_Jungle_Max_Support"
    },
    {
      "x": -28,
      "y": 62,
      "z": 10,
      "name": "Plant_Leaves_Jungle_Max_Support"
    },
    {
      "x": -28,
      "y": 63,
      "z": 10,
      "name": "Plant_Leaves_Jungle_Max_Support"
    },
    {
      "x": -28,
      "y": 64,
      "z": 10,
      "name": "Plant_Leaves_Jungle_Max_Support"
    },
    {
      "x": -28,
      "y": 74,
      "z": 10,
      "name": "Plant_Leaves_Jungle_Max_Support"
    },
    {
      "x": -28,
      "y": 75,
      "z": 10,
      "name": "Plant_Leaves_Jungle_Max_Support"
    },
    {
      "x": -28,
      "y": 76,
      "z": 10,
      "name": "Plant_Leaves_Jungle_Max_Support"
    },
    {
      "x": -28,
      "y": 78,
      "z": 10,
      "name": "Plant_Leaves_Jungle_Max_Support"
    },
    {
      "x": -28,
      "y": 54,
      "z": 11,
      "name": "Plant_Leaves_Jungle_Max_Support"
    },
    {
      "x": -28,
      "y": 55,
      "z": 11,
      "name": "Plant_Leaves_Jungle_Max_Support"
    },
    {
      "x": -28,
      "y": 56,
      "z": 11,
      "name": "Plant_Leaves_Jungle_Max_Support"
    },
    {
      "x": -28,
      "y": 57,
      "z": 11,
      "name": "Plant_Leaves_Jungle_Max_Support"
    },
    {
      "x": -28,
      "y": 59,
      "z": 11,
      "name": "Plant_Leaves_Jungle_Max_Support"
    },
    {
      "x": -28,
      "y": 60,
      "z": 11,
      "name": "Plant_Leaves_Jungle_Max_Support"
    },
    {
      "x": -28,
      "y": 61,
      "z": 11,
      "name": "Plant_Leaves_Jungle_Max_Support"
    },
    {
      "x": -28,
      "y": 62,
      "z": 11,
      "name": "Plant_Leaves_Jungle_Max_Support"
    },
    {
      "x": -28,
      "y": 75,
      "z": 11,
      "name": "Plant_Leaves_Jungle_Max_Support"
    },
    {
      "x": -28,
      "y": 76,
      "z": 11,
      "name": "Plant_Leaves_Jungle_Max_Support"
    },
    {
      "x": -28,
      "y": 77,
      "z": 11,
      "name": "Plant_Leaves_Jungle_Max_Support"
    },
    {
      "x": -28,
      "y": 78,
      "z": 11,
      "name": "Plant_Leaves_Jungle_Max_Support"
    },
    {
      "x": -28,
      "y": 54,
      "z": 12,
      "name": "Plant_Leaves_Jungle_Max_Support"
    },
    {
      "x": -28,
      "y": 55,
      "z": 12,
      "name": "Plant_Leaves_Jungle_Max_Support"
    },
    {
      "x": -28,
      "y": 56,
      "z": 12,
      "name": "Plant_Leaves_Jungle_Max_Support"
    },
    {
      "x": -28,
      "y": 57,
      "z": 12,
      "name": "Plant_Leaves_Jungle_Max_Support"
    },
    {
      "x": -28,
      "y": 58,
      "z": 12,
      "name": "Plant_Leaves_Jungle_Max_Support"
    },
    {
      "x": -28,
      "y": 59,
      "z": 12,
      "name": "Plant_Leaves_Jungle_Max_Support"
    },
    {
      "x": -28,
      "y": 60,
      "z": 12,
      "name": "Plant_Leaves_Jungle_Max_Support"
    },
    {
      "x": -28,
      "y": 61,
      "z": 12,
      "name": "Plant_Leaves_Jungle_Max_Support"
    },
    {
      "x": -28,
      "y": 63,
      "z": 12,
      "name": "Plant_Leaves_Jungle_Max_Support"
    },
    {
      "x": -28,
      "y": 74,
      "z": 12,
      "name": "Plant_Leaves_Jungle_Max_Support"
    },
    {
      "x": -28,
      "y": 75,
      "z": 12,
      "name": "Plant_Leaves_Jungle_Max_Support"
    },
    {
      "x": -28,
      "y": 76,
      "z": 12,
      "name": "Plant_Leaves_Jungle_Max_Support"
    },
    {
      "x": -28,
      "y": 77,
      "z": 12,
      "name": "Plant_Leaves_Jungle_Max_Support"
    },
    {
      "x": -28,
      "y": 78,
      "z": 12,
      "name": "Plant_Leaves_Jungle_Max_Support"
    },
    {
      "x": -28,
      "y": 54,
      "z": 13,
      "name": "Plant_Leaves_Jungle_Max_Support"
    },
    {
      "x": -28,
      "y": 55,
      "z": 13,
      "name": "Plant_Leaves_Jungle_Max_Support"
    },
    {
      "x": -28,
      "y": 56,
      "z": 13,
      "name": "Plant_Leaves_Jungle_Max_Support"
    },
    {
      "x": -28,
      "y": 57,
      "z": 13,
      "name": "Plant_Leaves_Jungle_Max_Support"
    },
    {
      "x": -28,
      "y": 58,
      "z": 13,
      "name": "Plant_Leaves_Jungle_Max_Support"
    },
    {
      "x": -28,
      "y": 59,
      "z": 13,
      "name": "Plant_Leaves_Jungle_Max_Support"
    },
    {
      "x": -28,
      "y": 60,
      "z": 13,
      "name": "Plant_Leaves_Jungle_Max_Support"
    },
    {
      "x": -28,
      "y": 62,
      "z": 13,
      "name": "Plant_Leaves_Jungle_Max_Support"
    },
    {
      "x": -28,
      "y": 75,
      "z": 13,
      "name": "Plant_Leaves_Jungle_Max_Support"
    },
    {
      "x": -28,
      "y": 76,
      "z": 13,
      "name": "Plant_Leaves_Jungle_Max_Support"
    },
    {
      "x": -28,
      "y": 77,
      "z": 13,
      "name": "Plant_Leaves_Jungle_Max_Support"
    },
    {
      "x": -28,
      "y": 78,
      "z": 13,
      "name": "Plant_Leaves_Jungle_Max_Support"
    },
    {
      "x": -28,
      "y": 79,
      "z": 13,
      "name": "Plant_Leaves_Jungle_Max_Support"
    },
    {
      "x": -28,
      "y": 55,
      "z": 14,
      "name": "Plant_Leaves_Jungle_Max_Support"
    },
    {
      "x": -28,
      "y": 56,
      "z": 14,
      "name": "Plant_Leaves_Jungle_Max_Support"
    },
    {
      "x": -28,
      "y": 57,
      "z": 14,
      "name": "Plant_Leaves_Jungle_Max_Support"
    },
    {
      "x": -28,
      "y": 58,
      "z": 14,
      "name": "Plant_Leaves_Jungle_Max_Support"
    },
    {
      "x": -28,
      "y": 59,
      "z": 14,
      "name": "Plant_Leaves_Jungle_Max_Support"
    },
    {
      "x": -28,
      "y": 60,
      "z": 14,
      "name": "Plant_Leaves_Jungle_Max_Support"
    },
    {
      "x": -28,
      "y": 61,
      "z": 14,
      "name": "Plant_Leaves_Jungle_Max_Support"
    },
    {
      "x": -28,
      "y": 75,
      "z": 14,
      "name": "Plant_Leaves_Jungle_Max_Support"
    },
    {
      "x": -28,
      "y": 76,
      "z": 14,
      "name": "Plant_Leaves_Jungle_Max_Support"
    },
    {
      "x": -28,
      "y": 77,
      "z": 14,
      "name": "Plant_Leaves_Jungle_Max_Support"
    },
    {
      "x": -28,
      "y": 78,
      "z": 14,
      "name": "Plant_Leaves_Jungle_Max_Support"
    },
    {
      "x": -28,
      "y": 56,
      "z": 15,
      "name": "Plant_Leaves_Jungle_Max_Support"
    },
    {
      "x": -28,
      "y": 60,
      "z": 15,
      "name": "Plant_Leaves_Jungle_Max_Support"
    },
    {
      "x": -28,
      "y": 61,
      "z": 15,
      "name": "Plant_Leaves_Jungle_Max_Support"
    },
    {
      "x": -28,
      "y": 72,
      "z": 15,
      "name": "Plant_Leaves_Jungle_Max_Support"
    },
    {
      "x": -28,
      "y": 73,
      "z": 15,
      "name": "Plant_Leaves_Jungle_Max_Support"
    },
    {
      "x": -28,
      "y": 75,
      "z": 15,
      "name": "Plant_Leaves_Jungle_Max_Support"
    },
    {
      "x": -28,
      "y": 76,
      "z": 15,
      "name": "Plant_Leaves_Jungle_Max_Support"
    },
    {
      "x": -28,
      "y": 77,
      "z": 15,
      "name": "Plant_Leaves_Jungle_Max_Support"
    },
    {
      "x": -28,
      "y": 79,
      "z": 15,
      "name": "Plant_Leaves_Jungle_Max_Support"
    },
    {
      "x": -28,
      "y": 60,
      "z": 16,
      "name": "Plant_Leaves_Jungle_Max_Support"
    },
    {
      "x": -28,
      "y": 61,
      "z": 16,
      "name": "Plant_Leaves_Jungle_Max_Support"
    },
    {
      "x": -28,
      "y": 62,
      "z": 16,
      "name": "Plant_Leaves_Jungle_Max_Support"
    },
    {
      "x": -28,
      "y": 71,
      "z": 16,
      "name": "Plant_Leaves_Jungle_Max_Support"
    },
    {
      "x": -28,
      "y": 72,
      "z": 16,
      "name": "Plant_Leaves_Jungle_Max_Support"
    },
    {
      "x": -28,
      "y": 74,
      "z": 16,
      "name": "Plant_Leaves_Jungle_Max_Support"
    },
    {
      "x": -28,
      "y": 75,
      "z": 16,
      "name": "Plant_Leaves_Jungle_Max_Support"
    },
    {
      "x": -28,
      "y": 76,
      "z": 16,
      "name": "Plant_Leaves_Jungle_Max_Support"
    },
    {
      "x": -28,
      "y": 77,
      "z": 16,
      "name": "Plant_Leaves_Jungle_Max_Support"
    },
    {
      "x": -28,
      "y": 78,
      "z": 16,
      "name": "Plant_Leaves_Jungle_Max_Support"
    },
    {
      "x": -28,
      "y": 61,
      "z": 17,
      "name": "Plant_Leaves_Jungle_Max_Support"
    },
    {
      "x": -28,
      "y": 72,
      "z": 17,
      "name": "Plant_Leaves_Jungle_Max_Support"
    },
    {
      "x": -28,
      "y": 73,
      "z": 17,
      "name": "Plant_Leaves_Jungle_Max_Support"
    },
    {
      "x": -28,
      "y": 74,
      "z": 17,
      "name": "Plant_Leaves_Jungle_Max_Support"
    },
    {
      "x": -28,
      "y": 75,
      "z": 17,
      "name": "Plant_Leaves_Jungle_Max_Support"
    },
    {
      "x": -28,
      "y": 76,
      "z": 17,
      "name": "Plant_Leaves_Jungle_Max_Support"
    },
    {
      "x": -28,
      "y": 77,
      "z": 17,
      "name": "Plant_Leaves_Jungle_Max_Support"
    },
    {
      "x": -28,
      "y": 78,
      "z": 17,
      "name": "Plant_Leaves_Jungle_Max_Support"
    },
    {
      "x": -28,
      "y": 71,
      "z": 18,
      "name": "Plant_Leaves_Jungle_Max_Support"
    },
    {
      "x": -28,
      "y": 72,
      "z": 18,
      "name": "Plant_Leaves_Jungle_Max_Support"
    },
    {
      "x": -28,
      "y": 73,
      "z": 18,
      "name": "Plant_Leaves_Jungle_Max_Support"
    },
    {
      "x": -28,
      "y": 75,
      "z": 18,
      "name": "Plant_Leaves_Jungle_Max_Support"
    },
    {
      "x": -28,
      "y": 76,
      "z": 18,
      "name": "Plant_Leaves_Jungle_Max_Support"
    },
    {
      "x": -28,
      "y": 78,
      "z": 18,
      "name": "Plant_Leaves_Jungle_Max_Support"
    },
    {
      "x": -28,
      "y": 79,
      "z": 18,
      "name": "Plant_Leaves_Jungle_Max_Support"
    },
    {
      "x": -28,
      "y": 80,
      "z": 18,
      "name": "Plant_Leaves_Jungle_Max_Support"
    },
    {
      "x": -28,
      "y": 72,
      "z": 19,
      "name": "Plant_Leaves_Jungle_Max_Support"
    },
    {
      "x": -28,
      "y": 73,
      "z": 19,
      "name": "Plant_Leaves_Jungle_Max_Support"
    },
    {
      "x": -28,
      "y": 74,
      "z": 19,
      "name": "Plant_Leaves_Jungle_Max_Support"
    },
    {
      "x": -28,
      "y": 75,
      "z": 19,
      "name": "Plant_Leaves_Jungle_Max_Support"
    },
    {
      "x": -28,
      "y": 76,
      "z": 19,
      "name": "Plant_Leaves_Jungle_Max_Support"
    },
    {
      "x": -28,
      "y": 77,
      "z": 19,
      "name": "Plant_Leaves_Jungle_Max_Support"
    },
    {
      "x": -28,
      "y": 72,
      "z": 20,
      "name": "Plant_Leaves_Jungle_Max_Support"
    },
    {
      "x": -28,
      "y": 73,
      "z": 20,
      "name": "Plant_Leaves_Jungle_Max_Support"
    },
    {
      "x": -28,
      "y": 74,
      "z": 20,
      "name": "Plant_Leaves_Jungle_Max_Support"
    },
    {
      "x": -28,
      "y": 75,
      "z": 20,
      "name": "Plant_Leaves_Jungle_Max_Support"
    },
    {
      "x": -28,
      "y": 76,
      "z": 20,
      "name": "Plant_Leaves_Jungle_Max_Support"
    },
    {
      "x": -28,
      "y": 74,
      "z": 21,
      "name": "Plant_Leaves_Jungle_Max_Support"
    },
    {
      "x": -28,
      "y": 75,
      "z": 21,
      "name": "Plant_Leaves_Jungle_Max_Support"
    },
    {
      "x": -28,
      "y": 73,
      "z": 22,
      "name": "Plant_Leaves_Jungle_Max_Support"
    },
    {
      "x": -28,
      "y": 74,
      "z": 22,
      "name": "Plant_Leaves_Jungle_Max_Support"
    },
    {
      "x": -28,
      "y": 75,
      "z": 22,
      "name": "Plant_Leaves_Jungle_Max_Support"
    },
    {
      "x": -28,
      "y": 72,
      "z": 23,
      "name": "Plant_Leaves_Jungle_Max_Support"
    },
    {
      "x": -28,
      "y": 73,
      "z": 23,
      "name": "Plant_Leaves_Jungle_Max_Support"
    },
    {
      "x": -28,
      "y": 74,
      "z": 23,
      "name": "Plant_Leaves_Jungle_Max_Support"
    },
    {
      "x": -28,
      "y": 75,
      "z": 23,
      "name": "Plant_Leaves_Jungle_Max_Support"
    },
    {
      "x": -28,
      "y": 74,
      "z": 24,
      "name": "Plant_Leaves_Jungle_Max_Support"
    },
    {
      "x": -28,
      "y": 76,
      "z": 24,
      "name": "Plant_Leaves_Jungle_Max_Support"
    },
    {
      "x": -28,
      "y": 76,
      "z": 25,
      "name": "Plant_Leaves_Jungle_Max_Support"
    },
    {
      "x": -28,
      "y": 74,
      "z": 26,
      "name": "Plant_Leaves_Jungle_Max_Support"
    },
    {
      "x": -28,
      "y": 75,
      "z": 26,
      "name": "Plant_Leaves_Jungle_Max_Support"
    },
    {
      "x": -27,
      "y": 58,
      "z": 3,
      "name": "Plant_Leaves_Jungle_Max_Support"
    },
    {
      "x": -27,
      "y": 59,
      "z": 3,
      "name": "Plant_Leaves_Jungle_Max_Support"
    },
    {
      "x": -27,
      "y": 58,
      "z": 4,
      "name": "Plant_Leaves_Jungle_Max_Support"
    },
    {
      "x": -27,
      "y": 59,
      "z": 4,
      "name": "Plant_Leaves_Jungle_Max_Support"
    },
    {
      "x": -27,
      "y": 60,
      "z": 4,
      "name": "Plant_Leaves_Jungle_Max_Support"
    },
    {
      "x": -27,
      "y": 56,
      "z": 5,
      "name": "Plant_Leaves_Jungle_Max_Support"
    },
    {
      "x": -27,
      "y": 57,
      "z": 5,
      "name": "Plant_Leaves_Jungle_Max_Support"
    },
    {
      "x": -27,
      "y": 59,
      "z": 5,
      "name": "Plant_Leaves_Jungle_Max_Support"
    },
    {
      "x": -27,
      "y": 60,
      "z": 5,
      "name": "Plant_Leaves_Jungle_Max_Support"
    },
    {
      "x": -27,
      "y": 61,
      "z": 5,
      "name": "Plant_Leaves_Jungle_Max_Support"
    },
    {
      "x": -27,
      "y": 62,
      "z": 5,
      "name": "Plant_Leaves_Jungle_Max_Support"
    },
    {
      "x": -27,
      "y": 55,
      "z": 6,
      "name": "Plant_Leaves_Jungle_Max_Support"
    },
    {
      "x": -27,
      "y": 57,
      "z": 6,
      "name": "Plant_Leaves_Jungle_Max_Support"
    },
    {
      "x": -27,
      "y": 58,
      "z": 6,
      "name": "Plant_Leaves_Jungle_Max_Support"
    },
    {
      "x": -27,
      "y": 59,
      "z": 6,
      "name": "Plant_Leaves_Jungle_Max_Support"
    },
    {
      "x": -27,
      "y": 60,
      "z": 6,
      "name": "Plant_Leaves_Jungle_Max_Support"
    },
    {
      "x": -27,
      "y": 61,
      "z": 6,
      "name": "Plant_Leaves_Jungle_Max_Support"
    },
    {
      "x": -27,
      "y": 62,
      "z": 6,
      "name": "Plant_Leaves_Jungle_Max_Support"
    },
    {
      "x": -27,
      "y": 56,
      "z": 7,
      "name": "Plant_Leaves_Jungle_Max_Support"
    },
    {
      "x": -27,
      "y": 57,
      "z": 7,
      "name": "Plant_Leaves_Jungle_Max_Support"
    },
    {
      "x": -27,
      "y": 58,
      "z": 7,
      "name": "Plant_Leaves_Jungle_Max_Support"
    },
    {
      "x": -27,
      "y": 59,
      "z": 7,
      "name": "Plant_Leaves_Jungle_Max_Support"
    },
    {
      "x": -27,
      "y": 61,
      "z": 7,
      "name": "Plant_Leaves_Jungle_Max_Support"
    },
    {
      "x": -27,
      "y": 63,
      "z": 7,
      "name": "Plant_Leaves_Jungle_Max_Support"
    },
    {
      "x": -27,
      "y": 64,
      "z": 7,
      "name": "Plant_Leaves_Jungle_Max_Support"
    },
    {
      "x": -27,
      "y": 74,
      "z": 7,
      "name": "Plant_Leaves_Jungle_Max_Support"
    },
    {
      "x": -27,
      "y": 57,
      "z": 8,
      "name": "Plant_Leaves_Jungle_Max_Support"
    },
    {
      "x": -27,
      "y": 58,
      "z": 8,
      "name": "Plant_Leaves_Jungle_Max_Support"
    },
    {
      "x": -27,
      "y": 59,
      "z": 8,
      "name": "Plant_Leaves_Jungle_Max_Support"
    },
    {
      "x": -27,
      "y": 60,
      "z": 8,
      "name": "Plant_Leaves_Jungle_Max_Support"
    },
    {
      "x": -27,
      "y": 62,
      "z": 8,
      "name": "Plant_Leaves_Jungle_Max_Support"
    },
    {
      "x": -27,
      "y": 63,
      "z": 8,
      "name": "Plant_Leaves_Jungle_Max_Support"
    },
    {
      "x": -27,
      "y": 64,
      "z": 8,
      "name": "Plant_Leaves_Jungle_Max_Support"
    },
    {
      "x": -27,
      "y": 65,
      "z": 8,
      "name": "Plant_Leaves_Jungle_Max_Support"
    },
    {
      "x": -27,
      "y": 75,
      "z": 8,
      "name": "Plant_Leaves_Jungle_Max_Support"
    },
    {
      "x": -27,
      "y": 76,
      "z": 8,
      "name": "Plant_Leaves_Jungle_Max_Support"
    },
    {
      "x": -27,
      "y": 55,
      "z": 9,
      "name": "Plant_Leaves_Jungle_Max_Support"
    },
    {
      "x": -27,
      "y": 57,
      "z": 9,
      "name": "Plant_Leaves_Jungle_Max_Support"
    },
    {
      "x": -27,
      "y": 58,
      "z": 9,
      "name": "Plant_Leaves_Jungle_Max_Support"
    },
    {
      "x": -27,
      "y": 59,
      "z": 9,
      "name": "Plant_Leaves_Jungle_Max_Support"
    },
    {
      "x": -27,
      "y": 60,
      "z": 9,
      "name": "Plant_Leaves_Jungle_Max_Support"
    },
    {
      "x": -27,
      "y": 61,
      "z": 9,
      "name": "Plant_Leaves_Jungle_Max_Support"
    },
    {
      "x": -27,
      "y": 62,
      "z": 9,
      "name": "Plant_Leaves_Jungle_Max_Support"
    },
    {
      "x": -27,
      "y": 63,
      "z": 9,
      "name": "Plant_Leaves_Jungle_Max_Support"
    },
    {
      "x": -27,
      "y": 65,
      "z": 9,
      "name": "Plant_Leaves_Jungle_Max_Support"
    },
    {
      "x": -27,
      "y": 72,
      "z": 9,
      "name": "Plant_Leaves_Jungle_Max_Support"
    },
    {
      "x": -27,
      "y": 73,
      "z": 9,
      "name": "Plant_Leaves_Jungle_Max_Support"
    },
    {
      "x": -27,
      "y": 75,
      "z": 9,
      "name": "Plant_Leaves_Jungle_Max_Support"
    },
    {
      "x": -27,
      "y": 76,
      "z": 9,
      "name": "Plant_Leaves_Jungle_Max_Support"
    },
    {
      "x": -27,
      "y": 77,
      "z": 9,
      "name": "Plant_Leaves_Jungle_Max_Support"
    },
    {
      "x": -27,
      "y": 54,
      "z": 10,
      "name": "Plant_Leaves_Jungle_Max_Support"
    },
    {
      "x": -27,
      "y": 57,
      "z": 10,
      "name": "Plant_Leaves_Jungle_Max_Support"
    },
    {
      "x": -27,
      "y": 58,
      "z": 10,
      "name": "Plant_Leaves_Jungle_Max_Support"
    },
    {
      "x": -27,
      "y": 59,
      "z": 10,
      "name": "Plant_Leaves_Jungle_Max_Support"
    },
    {
      "x": -27,
      "y": 60,
      "z": 10,
      "name": "Plant_Leaves_Jungle_Max_Support"
    },
    {
      "x": -27,
      "y": 61,
      "z": 10,
      "name": "Plant_Leaves_Jungle_Max_Support"
    },
    {
      "x": -27,
      "y": 62,
      "z": 10,
      "name": "Plant_Leaves_Jungle_Max_Support"
    },
    {
      "x": -27,
      "y": 63,
      "z": 10,
      "name": "Plant_Leaves_Jungle_Max_Support"
    },
    {
      "x": -27,
      "y": 65,
      "z": 10,
      "name": "Plant_Leaves_Jungle_Max_Support"
    },
    {
      "x": -27,
      "y": 73,
      "z": 10,
      "name": "Plant_Leaves_Jungle_Max_Support"
    },
    {
      "x": -27,
      "y": 74,
      "z": 10,
      "name": "Plant_Leaves_Jungle_Max_Support"
    },
    {
      "x": -27,
      "y": 75,
      "z": 10,
      "name": "Plant_Leaves_Jungle_Max_Support"
    },
    {
      "x": -27,
      "y": 76,
      "z": 10,
      "name": "Plant_Leaves_Jungle_Max_Support"
    },
    {
      "x": -27,
      "y": 77,
      "z": 10,
      "name": "Plant_Leaves_Jungle_Max_Support"
    },
    {
      "x": -27,
      "y": 78,
      "z": 10,
      "name": "Plant_Leaves_Jungle_Max_Support"
    },
    {
      "x": -27,
      "y": 57,
      "z": 11,
      "name": "Plant_Leaves_Jungle_Max_Support"
    },
    {
      "x": -27,
      "y": 58,
      "z": 11,
      "name": "Plant_Leaves_Jungle_Max_Support"
    },
    {
      "x": -27,
      "y": 59,
      "z": 11,
      "name": "Plant_Leaves_Jungle_Max_Support"
    },
    {
      "x": -27,
      "y": 60,
      "z": 11,
      "name": "Plant_Leaves_Jungle_Max_Support"
    },
    {
      "x": -27,
      "y": 63,
      "z": 11,
      "name": "Plant_Leaves_Jungle_Max_Support"
    },
    {
      "x": -27,
      "y": 74,
      "z": 11,
      "name": "Plant_Leaves_Jungle_Max_Support"
    },
    {
      "x": -27,
      "y": 75,
      "z": 11,
      "name": "Plant_Leaves_Jungle_Max_Support"
    },
    {
      "x": -27,
      "y": 76,
      "z": 11,
      "name": "Plant_Leaves_Jungle_Max_Support"
    },
    {
      "x": -27,
      "y": 78,
      "z": 11,
      "name": "Plant_Leaves_Jungle_Max_Support"
    },
    {
      "x": -27,
      "y": 56,
      "z": 12,
      "name": "Plant_Leaves_Jungle_Max_Support"
    },
    {
      "x": -27,
      "y": 57,
      "z": 12,
      "name": "Plant_Leaves_Jungle_Max_Support"
    },
    {
      "x": -27,
      "y": 58,
      "z": 12,
      "name": "Plant_Leaves_Jungle_Max_Support"
    },
    {
      "x": -27,
      "y": 59,
      "z": 12,
      "name": "Plant_Leaves_Jungle_Max_Support"
    },
    {
      "x": -27,
      "y": 60,
      "z": 12,
      "name": "Plant_Leaves_Jungle_Max_Support"
    },
    {
      "x": -27,
      "y": 61,
      "z": 12,
      "name": "Plant_Leaves_Jungle_Max_Support"
    },
    {
      "x": -27,
      "y": 62,
      "z": 12,
      "name": "Plant_Leaves_Jungle_Max_Support"
    },
    {
      "x": -27,
      "y": 63,
      "z": 12,
      "name": "Plant_Leaves_Jungle_Max_Support"
    },
    {
      "x": -27,
      "y": 74,
      "z": 12,
      "name": "Plant_Leaves_Jungle_Max_Support"
    },
    {
      "x": -27,
      "y": 75,
      "z": 12,
      "name": "Plant_Leaves_Jungle_Max_Support"
    },
    {
      "x": -27,
      "y": 76,
      "z": 12,
      "name": "Plant_Leaves_Jungle_Max_Support"
    },
    {
      "x": -27,
      "y": 77,
      "z": 12,
      "name": "Plant_Leaves_Jungle_Max_Support"
    },
    {
      "x": -27,
      "y": 78,
      "z": 12,
      "name": "Plant_Leaves_Jungle_Max_Support"
    },
    {
      "x": -27,
      "y": 55,
      "z": 13,
      "name": "Plant_Leaves_Jungle_Max_Support"
    },
    {
      "x": -27,
      "y": 56,
      "z": 13,
      "name": "Plant_Leaves_Jungle_Max_Support"
    },
    {
      "x": -27,
      "y": 57,
      "z": 13,
      "name": "Plant_Leaves_Jungle_Max_Support"
    },
    {
      "x": -27,
      "y": 58,
      "z": 13,
      "name": "Plant_Leaves_Jungle_Max_Support"
    },
    {
      "x": -27,
      "y": 59,
      "z": 13,
      "name": "Plant_Leaves_Jungle_Max_Support"
    },
    {
      "x": -27,
      "y": 60,
      "z": 13,
      "name": "Plant_Leaves_Jungle_Max_Support"
    },
    {
      "x": -27,
      "y": 61,
      "z": 13,
      "name": "Plant_Leaves_Jungle_Max_Support"
    },
    {
      "x": -27,
      "y": 62,
      "z": 13,
      "name": "Plant_Leaves_Jungle_Max_Support"
    },
    {
