{
  "version": 8,
  "blockIdVersion": 11,
  "anchorX": 2,
  "anchorY": 23,
  "anchorZ": -10,
  "blocks": [
    {
      "x": -25,
      "y": 57,
      "z": 26,
      "name": "Plant_Leaves_Beech_Max_Support"
    },
    {
      "x": -25,
      "y": 56,
      "z": 27,
      "name": "Plant_Leaves_Beech_Max_Support"
    },
    {
      "x": -25,
      "y": 58,
      "z": 27,
      "name": "Plant_Leaves_Beech_Max_Support"
    },
    {
      "x": -25,
      "y": 56,
      "z": 28,
      "name": "Plant_Leaves_Beech_Max_Support"
    },
    {
      "x": -25,
      "y": 57,
      "z": 28,
      "name": "Plant_Leaves_Beech_Max_Support"
    },
    {
      "x": -25,
      "y": 58,
      "z": 28,
      "name": "Plant_Leaves_Beech_Max_Support"
    },
    {
      "x": -24,
      "y": 56,
      "z": -15,
      "name": "Plant_Leaves_Beech_Max_Support"
    },
    {
      "x": -24,
      "y": 58,
      "z": -15,
      "name": "Plant_Leaves_Beech_Max_Support"
    },
    {
      "x": -24,
      "y": 56,
      "z": 24,
      "name": "Plant_Leaves_Beech_Max_Support"
    },
    {
      "x": -24,
      "y": 55,
      "z": 25,
      "name": "Plant_Leaves_Beech_Max_Support"
    },
    {
      "x": -24,
      "y": 56,
      "z": 25,
      "name": "Plant_Leaves_Beech_Max_Support"
    },
    {
      "x": -24,
      "y": 57,
      "z": 25,
      "name": "Plant_Leaves_Beech_Max_Support"
    },
    {
      "x": -24,
      "y": 55,
      "z": 26,
      "name": "Plant_Leaves_Beech_Max_Support"
    },
    {
      "x": -24,
      "y": 56,
      "z": 26,
      "name": "Plant_Leaves_Beech_Max_Support"
    },
    {
      "x": -24,
      "y": 58,
      "z": 26,
      "name": "Plant_Leaves_Beech_Max_Support"
    },
    {
      "x": -24,
      "y": 55,
      "z": 27,
      "name": "Plant_Leaves_Beech_Max_Support"
    },
    {
      "x": -24,
      "y": 56,
      "z": 27,
      "name": "Plant_Leaves_Beech_Max_Support"
    },
    {
      "x": -24,
      "y": 57,
      "z": 27,
      "name": "Plant_Leaves_Beech_Max_Support"
    },
    {
      "x": -24,
      "y": 58,
      "z": 27,
      "name": "Plant_Leaves_Beech_Max_Support"
    },
    {
      "x": -24,
      "y": 57,
      "z": 28,
      "name": "Plant_Leaves_Beech_Max_Support"
    },
    {
      "x": -24,
      "y": 58,
      "z": 28,
      "name": "Plant_Leaves_Beech_Max_Support"
    },
    {
      "x": -24,
      "y": 57,
      "z": 29,
      "name": "Plant_Leaves_Beech_Max_Support"
    },
    {
      "x": -24,
      "y": 58,
      "z": 29,
      "name": "Plant_Leaves_Beech_Max_Support"
    },
    {
      "x": -23,
      "y": 57,
      "z": -19,
      "name": "Plant_Leaves_Beech_Max_Support"
    },
    {
      "x": -23,
      "y": 55,
      "z": -18,
      "name": "Plant_Leaves_Beech_Max_Support",
      "support": 15
    },
    {
      "x": -23,
      "y": 57,
      "z": -17,
      "name": "Plant_Leaves_Beech_Max_Support"
    },
    {
      "x": -23,
      "y": 56,
      "z": -16,
      "name": "Plant_Leaves_Beech_Max_Support"
    },
    {
      "x": -23,
      "y": 58,
      "z": -16,
      "name": "Plant_Leaves_Beech_Max_Support"
    },
    {
      "x": -23,
      "y": 56,
      "z": -15,
      "name": "Plant_Leaves_Beech_Max_Support"
    },
    {
      "x": -23,
      "y": 59,
      "z": -15,
      "name": "Plant_Leaves_Beech_Max_Support"
    },
    {
      "x": -23,
      "y": 60,
      "z": -15,
      "name": "Plant_Leaves_Beech_Max_Support"
    },
    {
      "x": -23,
      "y": 56,
      "z": -14,
      "name": "Plant_Leaves_Beech_Max_Support"
    },
    {
      "x": -23,
      "y": 59,
      "z": -14,
      "name": "Plant_Leaves_Beech_Max_Support"
    },
    {
      "x": -23,
      "y": 60,
      "z": -14,
      "name": "Plant_Leaves_Beech_Max_Support"
    },
    {
      "x": -23,
      "y": 61,
      "z": -14,
      "name": "Plant_Leaves_Beech_Max_Support"
    },
    {
      "x": -23,
      "y": 57,
      "z": -13,
      "name": "Plant_Leaves_Beech_Max_Support"
    },
    {
      "x": -23,
      "y": 59,
      "z": -13,
      "name": "Plant_Leaves_Beech_Max_Support"
    },
    {
      "x": -23,
      "y": 61,
      "z": -13,
      "name": "Plant_Leaves_Beech_Max_Support"
    },
    {
      "x": -23,
      "y": 55,
      "z": -10,
      "name": "Plant_Leaves_Beech_Max_Support"
    },
    {
      "x": -23,
      "y": 57,
      "z": -10,
      "name": "Plant_Leaves_Beech_Max_Support"
    },
    {
      "x": -23,
      "y": 56,
      "z": -9,
      "name": "Plant_Leaves_Beech_Max_Support"
    },
    {
      "x": -23,
      "y": 56,
      "z": 23,
      "name": "Plant_Leaves_Beech_Max_Support"
    },
    {
      "x": -23,
      "y": 57,
      "z": 24,
      "name": "Plant_Leaves_Beech_Max_Support"
    },
    {
      "x": -23,
      "y": 58,
      "z": 24,
      "name": "Plant_Leaves_Beech_Max_Support"
    },
    {
      "x": -23,
      "y": 54,
      "z": 25,
      "name": "Plant_Leaves_Beech_Max_Support"
    },
    {
      "x": -23,
      "y": 55,
      "z": 25,
      "name": "Plant_Leaves_Beech_Max_Support"
    },
    {
      "x": -23,
      "y": 57,
      "z": 25,
      "name": "Plant_Leaves_Beech_Max_Support"
    },
    {
      "x": -23,
      "y": 58,
      "z": 25,
      "name": "Plant_Leaves_Beech_Max_Support"
    },
    {
      "x": -23,
      "y": 54,
      "z": 26,
      "name": "Plant_Leaves_Beech_Max_Support"
    },
    {
      "x": -23,
      "y": 55,
      "z": 26,
      "name": "Plant_Leaves_Beech_Max_Support"
    },
    {
      "x": -23,
      "y": 56,
      "z": 26,
      "name": "Plant_Leaves_Beech_Max_Support"
    },
    {
      "x": -23,
      "y": 59,
      "z": 26,
      "name": "Plant_Leaves_Beech_Max_Support"
    },
    {
      "x": -23,
      "y": 54,
      "z": 27,
      "name": "Plant_Leaves_Beech_Max_Support"
    },
    {
      "x": -23,
      "y": 55,
      "z": 27,
      "name": "Plant_Leaves_Beech_Max_Support"
    },
    {
      "x": -23,
      "y": 56,
      "z": 27,
      "name": "Wood_Gumboab_Trunk_Full"
    },
    {
      "x": -23,
      "y": 57,
      "z": 27,
      "name": "Wood_Gumboab_Trunk_Full"
    },
    {
      "x": -23,
      "y": 58,
      "z": 27,
      "name": "Plant_Leaves_Beech_Max_Support"
    },
    {
      "x": -23,
      "y": 55,
      "z": 28,
      "name": "Plant_Leaves_Beech_Max_Support"
    },
    {
      "x": -23,
      "y": 56,
      "z": 28,
      "name": "Plant_Leaves_Beech_Max_Support"
    },
    {
      "x": -23,
      "y": 57,
      "z": 28,
      "name": "Plant_Leaves_Beech_Max_Support"
    },
    {
      "x": -23,
      "y": 58,
      "z": 28,
      "name": "Plant_Leaves_Beech_Max_Support"
    },
    {
      "x": -23,
      "y": 59,
      "z": 28,
      "name": "Plant_Leaves_Beech_Max_Support"
    },
    {
      "x": -23,
      "y": 60,
      "z": 28,
      "name": "Plant_Leaves_Beech_Max_Support"
    },
    {
      "x": -23,
      "y": 55,
      "z": 29,
      "name": "Plant_Leaves_Beech_Max_Support"
    },
    {
      "x": -23,
      "y": 56,
      "z": 29,
      "name": "Plant_Leaves_Beech_Max_Support"
    },
    {
      "x": -23,
      "y": 57,
      "z": 29,
      "name": "Plant_Leaves_Beech_Max_Support"
    },
    {
      "x": -23,
      "y": 58,
      "z": 29,
      "name": "Plant_Leaves_Beech_Max_Support"
    },
    {
      "x": -23,
      "y": 56,
      "z": 30,
      "name": "Plant_Leaves_Beech_Max_Support"
    },
    {
      "x": -23,
      "y": 57,
      "z": 30,
      "name": "Plant_Leaves_Beech_Max_Support"
    },
    {
      "x": -22,
      "y": 57,
      "z": -20,
      "name": "Plant_Leaves_Beech_Max_Support"
    },
    {
      "x": -22,
      "y": 56,
      "z": -19,
      "name": "Plant_Leaves_Beech_Max_Support"
    },
    {
      "x": -22,
      "y": 57,
      "z": -19,
      "name": "Plant_Leaves_Beech_Max_Support"
    },
    {
      "x": -22,
      "y": 55,
      "z": -18,
      "name": "Plant_Leaves_Beech_Max_Support"
    },
    {
      "x": -22,
      "y": 59,
      "z": -18,
      "name": "Plant_Leaves_Beech_Max_Support"
    },
    {
      "x": -22,
      "y": 56,
      "z": -17,
      "name": "Plant_Leaves_Beech_Max_Support"
    },
    {
      "x": -22,
      "y": 57,
      "z": -17,
      "name": "Plant_Leaves_Beech_Max_Support"
    },
    {
      "x": -22,
      "y": 58,
      "z": -17,
      "name": "Plant_Leaves_Beech_Max_Support"
    },
    {
      "x": -22,
      "y": 55,
      "z": -16,
      "name": "Plant_Leaves_Beech_Max_Support",
      "support": 15
    },
    {
      "x": -22,
      "y": 56,
      "z": -16,
      "name": "Plant_Leaves_Beech_Max_Support"
    },
    {
      "x": -22,
      "y": 57,
      "z": -16,
      "name": "Plant_Leaves_Beech_Max_Support"
    },
    {
      "x": -22,
      "y": 58,
      "z": -16,
      "name": "Plant_Leaves_Beech_Max_Support"
    },
    {
      "x": -22,
      "y": 59,
      "z": -16,
      "name": "Plant_Leaves_Beech_Max_Support"
    },
    {
      "x": -22,
      "y": 60,
      "z": -16,
      "name": "Plant_Leaves_Beech_Max_Support"
    },
    {
      "x": -22,
      "y": 55,
      "z": -15,
      "name": "Plant_Leaves_Beech_Max_Support"
    },
    {
      "x": -22,
      "y": 56,
      "z": -15,
      "name": "Plant_Leaves_Beech_Max_Support"
    },
    {
      "x": -22,
      "y": 57,
      "z": -15,
      "name": "Plant_Leaves_Beech_Max_Support"
    },
    {
      "x": -22,
      "y": 58,
      "z": -15,
      "name": "Plant_Leaves_Beech_Max_Support"
    },
    {
      "x": -22,
      "y": 59,
      "z": -15,
      "name": "Plant_Leaves_Beech_Max_Support"
    },
    {
      "x": -22,
      "y": 60,
      "z": -15,
      "name": "Plant_Leaves_Beech_Max_Support"
    },
    {
      "x": -22,
      "y": 61,
      "z": -15,
      "name": "Plant_Leaves_Beech_Max_Support"
    },
    {
      "x": -22,
      "y": 56,
      "z": -14,
      "name": "Plant_Leaves_Beech_Max_Support"
    },
    {
      "x": -22,
      "y": 57,
      "z": -14,
      "name": "Plant_Leaves_Beech_Max_Support"
    },
    {
      "x": -22,
      "y": 58,
      "z": -14,
      "name": "Plant_Leaves_Beech_Max_Support"
    },
    {
      "x": -22,
      "y": 59,
      "z": -14,
      "name": "Plant_Leaves_Beech_Max_Support"
    },
    {
      "x": -22,
      "y": 61,
      "z": -14,
      "name": "Plant_Leaves_Beech_Max_Support"
    },
    {
      "x": -22,
      "y": 62,
      "z": -14,
      "name": "Plant_Leaves_Beech_Max_Support"
    },
    {
      "x": -22,
      "y": 55,
      "z": -13,
      "name": "Plant_Leaves_Beech_Max_Support"
    },
    {
      "x": -22,
      "y": 56,
      "z": -13,
      "name": "Plant_Leaves_Beech_Max_Support"
    },
    {
      "x": -22,
      "y": 58,
      "z": -13,
      "name": "Plant_Leaves_Beech_Max_Support"
    },
    {
      "x": -22,
      "y": 61,
      "z": -13,
      "name": "Plant_Leaves_Beech_Max_Support"
    },
    {
      "x": -22,
      "y": 62,
      "z": -13,
      "name": "Plant_Leaves_Beech_Max_Support"
    },
    {
      "x": -22,
      "y": 56,
      "z": -12,
      "name": "Plant_Leaves_Beech_Max_Support"
    },
    {
      "x": -22,
      "y": 58,
      "z": -12,
      "name": "Plant_Leaves_Beech_Max_Support"
    },
    {
      "x": -22,
      "y": 59,
      "z": -12,
      "name": "Plant_Leaves_Beech_Max_Support"
    },
    {
      "x": -22,
      "y": 61,
      "z": -12,
      "name": "Plant_Leaves_Beech_Max_Support"
    },
    {
      "x": -22,
      "y": 54,
      "z": -11,
      "name": "Plant_Leaves_Beech_Max_Support"
    },
    {
      "x": -22,
      "y": 56,
      "z": -11,
      "name": "Plant_Leaves_Beech_Max_Support"
    },
    {
      "x": -22,
      "y": 57,
      "z": -11,
      "name": "Plant_Leaves_Beech_Max_Support"
    },
    {
      "x": -22,
      "y": 58,
      "z": -11,
      "name": "Plant_Leaves_Beech_Max_Support"
    },
    {
      "x": -22,
      "y": 53,
      "z": -10,
      "name": "Plant_Leaves_Beech_Max_Support"
    },
    {
      "x": -22,
      "y": 54,
      "z": -10,
      "name": "Plant_Leaves_Beech_Max_Support"
    },
    {
      "x": -22,
      "y": 55,
      "z": -10,
      "name": "Plant_Leaves_Beech_Max_Support"
    },
    {
      "x": -22,
      "y": 56,
      "z": -10,
      "name": "Plant_Leaves_Beech_Max_Support"
    },
    {
      "x": -22,
      "y": 57,
      "z": -10,
      "name": "Plant_Leaves_Beech_Max_Support"
    },
    {
      "x": -22,
      "y": 58,
      "z": -10,
      "name": "Plant_Leaves_Beech_Max_Support"
    },
    {
      "x": -22,
      "y": 54,
      "z": -9,
      "name": "Plant_Leaves_Beech_Max_Support"
    },
    {
      "x": -22,
      "y": 55,
      "z": -9,
      "name": "Plant_Leaves_Beech_Max_Support"
    },
    {
      "x": -22,
      "y": 55,
      "z": 22,
      "name": "Plant_Leaves_Beech_Max_Support"
    },
    {
      "x": -22,
      "y": 54,
      "z": 23,
      "name": "Plant_Leaves_Beech_Max_Support"
    },
    {
      "x": -22,
      "y": 55,
      "z": 23,
      "name": "Plant_Leaves_Beech_Max_Support"
    },
    {
      "x": -22,
      "y": 56,
      "z": 23,
      "name": "Plant_Leaves_Beech_Max_Support"
    },
    {
      "x": -22,
      "y": 57,
      "z": 23,
      "name": "Plant_Leaves_Beech_Max_Support"
    },
    {
      "x": -22,
      "y": 54,
      "z": 24,
      "name": "Plant_Leaves_Beech_Max_Support"
    },
    {
      "x": -22,
      "y": 55,
      "z": 24,
      "name": "Plant_Leaves_Beech_Max_Support"
    },
    {
      "x": -22,
      "y": 56,
      "z": 24,
      "name": "Plant_Leaves_Beech_Max_Support"
    },
    {
      "x": -22,
      "y": 57,
      "z": 24,
      "name": "Plant_Leaves_Beech_Max_Support"
    },
    {
      "x": -22,
      "y": 58,
      "z": 24,
      "name": "Plant_Leaves_Beech_Max_Support"
    },
    {
      "x": -22,
      "y": 54,
      "z": 25,
      "name": "Plant_Leaves_Beech_Max_Support"
    },
    {
      "x": -22,
      "y": 55,
      "z": 25,
      "name": "Plant_Leaves_Beech_Max_Support"
    },
    {
      "x": -22,
      "y": 56,
      "z": 25,
      "name": "Plant_Leaves_Beech_Max_Support"
    },
    {
      "x": -22,
      "y": 58,
      "z": 25,
      "name": "Plant_Leaves_Beech_Max_Support"
    },
    {
      "x": -22,
      "y": 59,
      "z": 25,
      "name": "Plant_Leaves_Beech_Max_Support"
    },
    {
      "x": -22,
      "y": 60,
      "z": 25,
      "name": "Plant_Leaves_Beech_Max_Support"
    },
    {
      "x": -22,
      "y": 61,
      "z": 25,
      "name": "Plant_Leaves_Beech_Max_Support"
    },
    {
      "x": -22,
      "y": 62,
      "z": 25,
      "name": "Plant_Leaves_Beech_Max_Support"
    },
    {
      "x": -22,
      "y": 54,
      "z": 26,
      "name": "Plant_Leaves_Beech_Max_Support"
    },
    {
      "x": -22,
      "y": 55,
      "z": 26,
      "name": "Plant_Leaves_Beech_Max_Support"
    },
    {
      "x": -22,
      "y": 56,
      "z": 26,
      "name": "Plant_Leaves_Beech_Max_Support"
    },
    {
      "x": -22,
      "y": 57,
      "z": 26,
      "name": "Plant_Leaves_Beech_Max_Support"
    },
    {
      "x": -22,
      "y": 58,
      "z": 26,
      "name": "Plant_Leaves_Beech_Max_Support"
    },
    {
      "x": -22,
      "y": 60,
      "z": 26,
      "name": "Plant_Leaves_Beech_Max_Support"
    },
    {
      "x": -22,
      "y": 61,
      "z": 26,
      "name": "Plant_Leaves_Beech_Max_Support"
    },
    {
      "x": -22,
      "y": 62,
      "z": 26,
      "name": "Plant_Leaves_Beech_Max_Support"
    },
    {
      "x": -22,
      "y": 55,
      "z": 27,
      "name": "Plant_Leaves_Beech_Max_Support"
    },
    {
      "x": -22,
      "y": 56,
      "z": 27,
      "name": "Plant_Leaves_Beech_Max_Support"
    },
    {
      "x": -22,
      "y": 57,
      "z": 27,
      "name": "Wood_Gumboab_Trunk_Full"
    },
    {
      "x": -22,
      "y": 59,
      "z": 27,
      "name": "Plant_Leaves_Beech_Max_Support"
    },
    {
      "x": -22,
      "y": 60,
      "z": 27,
      "name": "Plant_Leaves_Beech_Max_Support"
    },
    {
      "x": -22,
      "y": 61,
      "z": 27,
      "name": "Plant_Leaves_Beech_Max_Support"
    },
    {
      "x": -22,
      "y": 55,
      "z": 28,
      "name": "Plant_Leaves_Beech_Max_Support"
    },
    {
      "x": -22,
      "y": 56,
      "z": 28,
      "name": "Wood_Gumboab_Trunk_Full"
    },
    {
      "x": -22,
      "y": 57,
      "z": 28,
      "name": "Wood_Gumboab_Trunk_Full"
    },
    {
      "x": -22,
      "y": 58,
      "z": 28,
      "name": "Plant_Leaves_Beech_Max_Support"
    },
    {
      "x": -22,
      "y": 59,
      "z": 28,
      "name": "Plant_Leaves_Beech_Max_Support"
    },
    {
      "x": -22,
      "y": 55,
      "z": 29,
      "name": "Plant_Leaves_Beech_Max_Support"
    },
    {
      "x": -22,
      "y": 57,
      "z": 29,
      "name": "Plant_Leaves_Beech_Max_Support"
    },
    {
      "x": -22,
      "y": 58,
      "z": 29,
      "name": "Plant_Leaves_Beech_Max_Support"
    },
    {
      "x": -22,
      "y": 56,
      "z": 30,
      "name": "Plant_Leaves_Beech_Max_Support"
    },
    {
      "x": -22,
      "y": 57,
      "z": 30,
      "name": "Plant_Leaves_Beech_Max_Support"
    },
    {
      "x": -22,
      "y": 56,
      "z": 31,
      "name": "Plant_Leaves_Beech_Max_Support"
    },
    {
      "x": -22,
      "y": 57,
      "z": 31,
      "name": "Plant_Leaves_Beech_Max_Support"
    },
    {
      "x": -22,
      "y": 58,
      "z": 31,
      "name": "Plant_Leaves_Beech_Max_Support"
    },
    {
      "x": -21,
      "y": 55,
      "z": -21,
      "name": "Plant_Leaves_Beech_Max_Support",
      "support": 15
    },
    {
      "x": -21,
      "y": 55,
      "z": -20,
      "name": "Plant_Leaves_Beech_Max_Support",
      "support": 15
    },
    {
      "x": -21,
      "y": 58,
      "z": -20,
      "name": "Plant_Leaves_Beech_Max_Support"
    },
    {
      "x": -21,
      "y": 55,
      "z": -19,
      "name": "Plant_Leaves_Beech_Max_Support"
    },
    {
      "x": -21,
      "y": 56,
      "z": -19,
      "name": "Plant_Leaves_Beech_Max_Support"
    },
    {
      "x": -21,
      "y": 57,
      "z": -19,
      "name": "Plant_Leaves_Beech_Max_Support"
    },
    {
      "x": -21,
      "y": 58,
      "z": -19,
      "name": "Plant_Leaves_Beech_Max_Support"
    },
    {
      "x": -21,
      "y": 59,
      "z": -19,
      "name": "Plant_Leaves_Beech_Max_Support"
    },
    {
      "x": -21,
      "y": 56,
      "z": -18,
      "name": "Plant_Leaves_Beech_Max_Support"
    },
    {
      "x": -21,
      "y": 57,
      "z": -18,
      "name": "Plant_Leaves_Beech_Max_Support"
    },
    {
      "x": -21,
      "y": 58,
      "z": -18,
      "name": "Plant_Leaves_Beech_Max_Support"
    },
    {
      "x": -21,
      "y": 55,
      "z": -17,
      "name": "Plant_Leaves_Beech_Max_Support"
    },
    {
      "x": -21,
      "y": 57,
      "z": -17,
      "name": "Plant_Leaves_Beech_Max_Support"
    },
    {
      "x": -21,
      "y": 58,
      "z": -17,
      "name": "Plant_Leaves_Beech_Max_Support"
    },
    {
      "x": -21,
      "y": 59,
      "z": -17,
      "name": "Plant_Leaves_Beech_Max_Support"
    },
    {
      "x": -21,
      "y": 60,
      "z": -17,
      "name": "Plant_Leaves_Beech_Max_Support"
    },
    {
      "x": -21,
      "y": 56,
      "z": -16,
      "name": "Plant_Leaves_Beech_Max_Support"
    },
    {
      "x": -21,
      "y": 57,
      "z": -16,
      "name": "Plant_Leaves_Beech_Max_Support"
    },
    {
      "x": -21,
      "y": 58,
      "z": -16,
      "name": "Plant_Leaves_Beech_Max_Support"
    },
    {
      "x": -21,
      "y": 59,
      "z": -16,
      "name": "Plant_Leaves_Beech_Max_Support"
    },
    {
      "x": -21,
      "y": 61,
      "z": -16,
      "name": "Plant_Leaves_Beech_Max_Support"
    },
    {
      "x": -21,
      "y": 62,
      "z": -16,
      "name": "Plant_Leaves_Beech_Max_Support"
    },
    {
      "x": -21,
      "y": 55,
      "z": -15,
      "name": "Plant_Leaves_Beech_Max_Support"
    },
    {
      "x": -21,
      "y": 56,
      "z": -15,
      "name": "Plant_Leaves_Beech_Max_Support"
    },
    {
      "x": -21,
      "y": 57,
      "z": -15,
      "name": "Plant_Leaves_Beech_Max_Support"
    },
    {
      "x": -21,
      "y": 58,
      "z": -15,
      "name": "Plant_Leaves_Beech_Max_Support"
    },
    {
      "x": -21,
      "y": 59,
      "z": -15,
      "name": "Plant_Leaves_Beech_Max_Support"
    },
    {
      "x": -21,
      "y": 60,
      "z": -15,
      "name": "Plant_Leaves_Beech_Max_Support"
    },
    {
      "x": -21,
      "y": 55,
      "z": -14,
      "name": "Plant_Leaves_Beech_Max_Support"
    },
    {
      "x": -21,
      "y": 56,
      "z": -14,
      "name": "Plant_Leaves_Beech_Max_Support"
    },
    {
      "x": -21,
      "y": 57,
      "z": -14,
      "name": "Plant_Leaves_Beech_Max_Support"
    },
    {
      "x": -21,
      "y": 58,
      "z": -14,
      "name": "Plant_Leaves_Beech_Max_Support"
    },
    {
      "x": -21,
      "y": 59,
      "z": -14,
      "name": "Plant_Leaves_Beech_Max_Support"
    },
    {
      "x": -21,
      "y": 60,
      "z": -14,
      "name": "Plant_Leaves_Beech_Max_Support"
    },
    {
      "x": -21,
      "y": 61,
      "z": -14,
      "name": "Plant_Leaves_Beech_Max_Support"
    },
    {
      "x": -21,
      "y": 63,
      "z": -14,
      "name": "Plant_Leaves_Beech_Max_Support"
    },
    {
      "x": -21,
      "y": 54,
      "z": -13,
      "name": "Plant_Leaves_Beech_Max_Support"
    },
    {
      "x": -21,
      "y": 55,
      "z": -13,
      "name": "Plant_Leaves_Beech_Max_Support"
    },
    {
      "x": -21,
      "y": 56,
      "z": -13,
      "name": "Plant_Leaves_Beech_Max_Support"
    },
    {
      "x": -21,
      "y": 57,
      "z": -13,
      "name": "Plant_Leaves_Beech_Max_Support"
    },
    {
      "x": -21,
      "y": 58,
      "z": -13,
      "name": "Plant_Leaves_Beech_Max_Support"
    },
    {
      "x": -21,
      "y": 59,
      "z": -13,
      "name": "Plant_Leaves_Beech_Max_Support"
    },
    {
      "x": -21,
      "y": 60,
      "z": -13,
      "name": "Plant_Leaves_Beech_Max_Support"
    },
    {
      "x": -21,
      "y": 62,
      "z": -13,
      "name": "Plant_Leaves_Beech_Max_Support"
    },
    {
      "x": -21,
      "y": 55,
      "z": -12,
      "name": "Plant_Leaves_Beech_Max_Support"
    },
    {
      "x": -21,
      "y": 56,
      "z": -12,
      "name": "Plant_Leaves_Beech_Max_Support"
    },
    {
      "x": -21,
      "y": 57,
      "z": -12,
      "name": "Plant_Leaves_Beech_Max_Support"
    },
    {
      "x": -21,
      "y": 58,
      "z": -12,
      "name": "Plant_Leaves_Beech_Max_Support"
    },
    {
      "x": -21,
      "y": 59,
      "z": -12,
      "name": "Plant_Leaves_Beech_Max_Support"
    },
    {
      "x": -21,
      "y": 60,
      "z": -12,
      "name": "Plant_Leaves_Beech_Max_Support"
    },
    {
      "x": -21,
      "y": 61,
      "z": -12,
      "name": "Plant_Leaves_Beech_Max_Support"
    },
    {
      "x": -21,
      "y": 53,
      "z": -11,
      "name": "Plant_Leaves_Beech_Max_Support"
    },
    {
      "x": -21,
      "y": 54,
      "z": -11,
      "name": "Plant_Leaves_Beech_Max_Support"
    },
    {
      "x": -21,
      "y": 55,
      "z": -11,
      "name": "Plant_Leaves_Beech_Max_Support"
    },
    {
      "x": -21,
      "y": 56,
      "z": -11,
      "name": "Plant_Leaves_Beech_Max_Support"
    },
    {
      "x": -21,
      "y": 57,
      "z": -11,
      "name": "Plant_Leaves_Beech_Max_Support"
    },
    {
      "x": -21,
      "y": 58,
      "z": -11,
      "name": "Plant_Leaves_Beech_Max_Support"
    },
    {
      "x": -21,
      "y": 61,
      "z": -11,
      "name": "Plant_Leaves_Beech_Max_Support"
    },
    {
      "x": -21,
      "y": 52,
      "z": -10,
      "name": "Plant_Leaves_Beech_Max_Support"
    },
    {
      "x": -21,
      "y": 53,
      "z": -10,
      "name": "Plant_Leaves_Beech_Max_Support"
    },
    {
      "x": -21,
      "y": 54,
      "z": -10,
      "name": "Plant_Leaves_Beech_Max_Support"
    },
    {
      "x": -21,
      "y": 55,
      "z": -10,
      "name": "Plant_Leaves_Beech_Max_Support"
    },
    {
      "x": -21,
      "y": 56,
      "z": -10,
      "name": "Plant_Leaves_Beech_Max_Support"
    },
    {
      "x": -21,
      "y": 57,
      "z": -10,
      "name": "Plant_Leaves_Beech_Max_Support"
    },
    {
      "x": -21,
      "y": 58,
      "z": -10,
      "name": "Plant_Leaves_Beech_Max_Support"
    },
    {
      "x": -21,
      "y": 53,
      "z": -9,
      "name": "Plant_Leaves_Beech_Max_Support"
    },
    {
      "x": -21,
      "y": 54,
      "z": -9,
      "name": "Plant_Leaves_Beech_Max_Support"
    },
    {
      "x": -21,
      "y": 55,
      "z": -9,
      "name": "Plant_Leaves_Beech_Max_Support"
    },
    {
      "x": -21,
      "y": 56,
      "z": -9,
      "name": "Plant_Leaves_Beech_Max_Support"
    },
    {
      "x": -21,
      "y": 57,
      "z": -9,
      "name": "Plant_Leaves_Beech_Max_Support"
    },
    {
      "x": -21,
      "y": 58,
      "z": -9,
      "name": "Plant_Leaves_Beech_Max_Support"
    },
    {
      "x": -21,
      "y": 55,
      "z": -8,
      "name": "Plant_Leaves_Beech_Max_Support"
    },
    {
      "x": -21,
      "y": 56,
      "z": -8,
      "name": "Plant_Leaves_Beech_Max_Support"
    },
    {
      "x": -21,
      "y": 57,
      "z": -8,
      "name": "Plant_Leaves_Beech_Max_Support"
    },
    {
      "x": -21,
      "y": 55,
      "z": 21,
      "name": "Plant_Leaves_Beech_Max_Support"
    },
    {
      "x": -21,
      "y": 54,
      "z": 22,
      "name": "Plant_Leaves_Beech_Max_Support"
    },
    {
      "x": -21,
      "y": 55,
      "z": 22,
      "name": "Plant_Leaves_Beech_Max_Support"
    },
    {
      "x": -21,
      "y": 53,
      "z": 23,
      "name": "Plant_Leaves_Beech_Max_Support"
    },
    {
      "x": -21,
      "y": 54,
      "z": 23,
      "name": "Plant_Leaves_Beech_Max_Support"
    },
    {
      "x": -21,
      "y": 56,
      "z": 23,
      "name": "Plant_Leaves_Beech_Max_Support"
    },
    {
      "x": -21,
      "y": 57,
      "z": 23,
      "name": "Plant_Leaves_Beech_Max_Support"
    },
    {
      "x": -21,
      "y": 54,
      "z": 24,
      "name": "Plant_Leaves_Beech_Max_Support"
    },
    {
      "x": -21,
      "y": 55,
      "z": 24,
      "name": "Plant_Leaves_Beech_Max_Support"
    },
    {
      "x": -21,
      "y": 56,
      "z": 24,
      "name": "Plant_Leaves_Beech_Max_Support"
    },
    {
      "x": -21,
      "y": 57,
      "z": 24,
      "name": "Plant_Leaves_Beech_Max_Support"
    },
    {
      "x": -21,
      "y": 55,
      "z": 25,
      "name": "Plant_Leaves_Beech_Max_Support"
    },
    {
      "x": -21,
      "y": 56,
      "z": 25,
      "name": "Plant_Leaves_Beech_Max_Support"
    },
    {
      "x": -21,
      "y": 57,
      "z": 25,
      "name": "Plant_Leaves_Beech_Max_Support"
    },
    {
      "x": -21,
      "y": 58,
      "z": 25,
      "name": "Plant_Leaves_Beech_Max_Support"
    },
    {
      "x": -21,
      "y": 60,
      "z": 25,
      "name": "Plant_Leaves_Beech_Max_Support"
    },
    {
      "x": -21,
      "y": 62,
      "z": 25,
      "name": "Plant_Leaves_Beech_Max_Support"
    },
    {
      "x": -21,
      "y": 63,
      "z": 25,
      "name": "Plant_Leaves_Beech_Max_Support"
    },
    {
      "x": -21,
      "y": 54,
      "z": 26,
      "name": "Plant_Leaves_Beech_Max_Support"
    },
    {
      "x": -21,
      "y": 55,
      "z": 26,
      "name": "Plant_Leaves_Beech_Max_Support"
    },
    {
      "x": -21,
      "y": 56,
      "z": 26,
      "name": "Plant_Leaves_Beech_Max_Support"
    },
    {
      "x": -21,
      "y": 57,
      "z": 26,
      "name": "Plant_Leaves_Beech_Max_Support"
    },
    {
      "x": -21,
      "y": 58,
      "z": 26,
      "name": "Plant_Leaves_Beech_Max_Support"
    },
    {
      "x": -21,
      "y": 59,
      "z": 26,
      "name": "Plant_Leaves_Beech_Max_Support"
    },
    {
      "x": -21,
      "y": 63,
      "z": 26,
      "name": "Plant_Leaves_Beech_Max_Support"
    },
    {
      "x": -21,
      "y": 55,
      "z": 27,
      "name": "Plant_Leaves_Beech_Max_Support"
    },
    {
      "x": -21,
      "y": 56,
      "z": 27,
      "name": "Plant_Leaves_Beech_Max_Support"
    },
    {
      "x": -21,
      "y": 57,
      "z": 27,
      "name": "Plant_Leaves_Beech_Max_Support"
    },
    {
      "x": -21,
      "y": 58,
      "z": 27,
      "name": "Plant_Leaves_Beech_Max_Support"
    },
    {
      "x": -21,
      "y": 59,
      "z": 27,
      "name": "Plant_Leaves_Beech_Max_Support"
    },
    {
      "x": -21,
      "y": 61,
      "z": 27,
      "name": "Plant_Leaves_Beech_Max_Support"
    },
    {
      "x": -21,
      "y": 63,
      "z": 27,
      "name": "Plant_Leaves_Beech_Max_Support"
    },
    {
      "x": -21,
      "y": 54,
      "z": 28,
      "name": "Plant_Leaves_Beech_Max_Support"
    },
    {
      "x": -21,
      "y": 55,
      "z": 28,
      "name": "Plant_Leaves_Beech_Max_Support"
    },
    {
      "x": -21,
      "y": 56,
      "z": 28,
      "name": "Wood_Gumboab_Trunk_Full"
    },
    {
      "x": -21,
      "y": 57,
      "z": 28,
      "name": "Plant_Leaves_Beech_Max_Support"
    },
    {
      "x": -21,
      "y": 58,
      "z": 28,
      "name": "Plant_Leaves_Beech_Max_Support"
    },
    {
      "x": -21,
      "y": 59,
      "z": 28,
      "name": "Plant_Leaves_Beech_Max_Support"
    },
    {
      "x": -21,
      "y": 60,
      "z": 28,
      "name": "Plant_Leaves_Beech_Max_Support"
    },
    {
      "x": -21,
      "y": 62,
      "z": 28,
      "name": "Plant_Leaves_Beech_Max_Support"
    },
    {
      "x": -21,
      "y": 54,
      "z": 29,
      "name": "Plant_Leaves_Beech_Max_Support"
    },
    {
      "x": -21,
      "y": 55,
      "z": 29,
      "name": "Plant_Leaves_Beech_Max_Support"
    },
    {
      "x": -21,
      "y": 56,
      "z": 29,
      "name": "Wood_Gumboab_Trunk_Full"
    },
    {
      "x": -21,
      "y": 57,
      "z": 29,
      "name": "Plant_Leaves_Beech_Max_Support"
    },
    {
      "x": -21,
      "y": 58,
      "z": 29,
      "name": "Plant_Leaves_Beech_Max_Support"
    },
    {
      "x": -21,
      "y": 59,
      "z": 29,
      "name": "Plant_Leaves_Beech_Max_Support"
    },
    {
      "x": -21,
      "y": 56,
      "z": 30,
      "name": "Plant_Leaves_Beech_Max_Support"
    },
    {
      "x": -21,
      "y": 57,
      "z": 30,
      "name": "Plant_Leaves_Beech_Max_Support"
    },
    {
      "x": -21,
      "y": 58,
      "z": 30,
      "name": "Plant_Leaves_Beech_Max_Support"
    },
    {
      "x": -21,
      "y": 59,
      "z": 30,
      "name": "Plant_Leaves_Beech_Max_Support"
    },
    {
      "x": -21,
      "y": 55,
      "z": 31,
      "name": "Plant_Leaves_Beech_Max_Support"
    },
    {
      "x": -21,
      "y": 56,
      "z": 31,
      "name": "Plant_Leaves_Beech_Max_Support"
    },
    {
      "x": -21,
      "y": 57,
      "z": 31,
      "name": "Plant_Leaves_Beech_Max_Support"
    },
    {
      "x": -21,
      "y": 58,
      "z": 31,
      "name": "Plant_Leaves_Beech_Max_Support"
    },
    {
      "x": -21,
      "y": 55,
      "z": 32,
      "name": "Plant_Leaves_Beech_Max_Support"
    },
    {
      "x": -21,
      "y": 58,
      "z": 32,
      "name": "Plant_Leaves_Beech_Max_Support"
    },
    {
      "x": -21,
      "y": 55,
      "z": 33,
      "name": "Plant_Leaves_Beech_Max_Support"
    },
    {
      "x": -21,
      "y": 56,
      "z": 33,
      "name": "Plant_Leaves_Beech_Max_Support"
    },
    {
      "x": -21,
      "y": 55,
      "z": 34,
      "name": "Plant_Leaves_Beech_Max_Support"
    },
    {
      "x": -20,
      "y": 57,
      "z": -20,
      "name": "Plant_Leaves_Beech_Max_Support"
    },
    {
      "x": -20,
      "y": 56,
      "z": -19,
      "name": "Plant_Leaves_Beech_Max_Support"
    },
    {
      "x": -20,
      "y": 57,
      "z": -19,
      "name": "Plant_Leaves_Beech_Max_Support"
    },
    {
      "x": -20,
      "y": 58,
      "z": -19,
      "name": "Plant_Leaves_Beech_Max_Support"
    },
    {
      "x": -20,
      "y": 59,
      "z": -19,
      "name": "Plant_Leaves_Beech_Max_Support"
    },
    {
      "x": -20,
      "y": 55,
      "z": -18,
      "name": "Plant_Leaves_Beech_Max_Support"
    },
    {
      "x": -20,
      "y": 56,
      "z": -18,
      "name": "Plant_Leaves_Beech_Max_Support"
    },
    {
      "x": -20,
      "y": 57,
      "z": -18,
      "name": "Plant_Leaves_Beech_Max_Support"
    },
    {
      "x": -20,
      "y": 58,
      "z": -18,
      "name": "Plant_Leaves_Beech_Max_Support"
    },
    {
      "x": -20,
      "y": 59,
      "z": -18,
      "name": "Plant_Leaves_Beech_Max_Support"
    },
    {
      "x": -20,
      "y": 55,
      "z": -17,
      "name": "Plant_Leaves_Beech_Max_Support"
    },
    {
      "x": -20,
      "y": 56,
      "z": -17,
      "name": "Plant_Leaves_Beech_Max_Support"
    },
    {
      "x": -20,
      "y": 57,
      "z": -17,
      "name": "Plant_Leaves_Beech_Max_Support"
    },
    {
      "x": -20,
      "y": 58,
      "z": -17,
      "name": "Plant_Leaves_Beech_Max_Support"
    },
    {
      "x": -20,
      "y": 59,
      "z": -17,
      "name": "Plant_Leaves_Beech_Max_Support"
    },
    {
      "x": -20,
      "y": 60,
      "z": -17,
      "name": "Plant_Leaves_Beech_Max_Support"
    },
    {
      "x": -20,
      "y": 61,
      "z": -17,
      "name": "Plant_Leaves_Beech_Max_Support"
    },
    {
      "x": -20,
      "y": 55,
      "z": -16,
      "name": "Plant_Leaves_Beech_Max_Support"
    },
    {
      "x": -20,
      "y": 56,
      "z": -16,
      "name": "Wood_Gumboab_Trunk_Full"
    },
    {
      "x": -20,
      "y": 57,
      "z": -16,
      "name": "Plant_Leaves_Beech_Max_Support"
    },
    {
      "x": -20,
      "y": 59,
      "z": -16,
      "name": "Plant_Leaves_Beech_Max_Support"
    },
    {
      "x": -20,
      "y": 60,
      "z": -16,
      "name": "Plant_Leaves_Beech_Max_Support"
    },
    {
      "x": -20,
      "y": 61,
      "z": -16,
      "name": "Plant_Leaves_Beech_Max_Support"
    },
    {
      "x": -20,
      "y": 55,
      "z": -15,
      "name": "Plant_Leaves_Beech_Max_Support"
    },
    {
      "x": -20,
      "y": 56,
      "z": -15,
      "name": "Plant_Leaves_Beech_Max_Support"
    },
    {
      "x": -20,
      "y": 57,
      "z": -15,
      "name": "Plant_Leaves_Beech_Max_Support"
    },
    {
      "x": -20,
      "y": 58,
      "z": -15,
      "name": "Plant_Leaves_Beech_Max_Support"
    },
    {
      "x": -20,
      "y": 60,
      "z": -15,
      "name": "Plant_Leaves_Beech_Max_Support"
    },
    {
      "x": -20,
      "y": 61,
      "z": -15,
      "name": "Plant_Leaves_Beech_Max_Support"
    },
    {
      "x": -20,
      "y": 62,
      "z": -15,
      "name": "Plant_Leaves_Beech_Max_Support"
    },
    {
      "x": -20,
      "y": 63,
      "z": -15,
      "name": "Plant_Leaves_Beech_Max_Support"
    },
    {
      "x": -20,
      "y": 54,
      "z": -14,
      "name": "Plant_Leaves_Beech_Max_Support"
    },
    {
      "x": -20,
      "y": 55,
      "z": -14,
      "name": "Plant_Leaves_Beech_Max_Support"
    },
    {
      "x": -20,
      "y": 56,
      "z": -14,
      "name": "Plant_Leaves_Beech_Max_Support"
    },
    {
      "x": -20,
      "y": 57,
      "z": -14,
      "name": "Plant_Leaves_Beech_Max_Support"
    },
    {
      "x": -20,
      "y": 58,
      "z": -14,
      "name": "Plant_Leaves_Beech_Max_Support"
    },
    {
      "x": -20,
      "y": 59,
      "z": -14,
      "name": "Plant_Leaves_Beech_Max_Support"
    },
    {
      "x": -20,
      "y": 60,
      "z": -14,
      "name": "Plant_Leaves_Beech_Max_Support"
    },
    {
      "x": -20,
      "y": 61,
      "z": -14,
      "name": "Plant_Leaves_Beech_Max_Support"
    },
    {
      "x": -20,
      "y": 62,
      "z": -14,
      "name": "Plant_Leaves_Beech_Max_Support"
    },
    {
      "x": -20,
      "y": 54,
      "z": -13,
      "name": "Plant_Leaves_Beech_Max_Support"
    },
    {
      "x": -20,
      "y": 55,
      "z": -13,
      "name": "Plant_Leaves_Beech_Max_Support"
    },
    {
      "x": -20,
      "y": 56,
      "z": -13,
      "name": "Plant_Leaves_Beech_Max_Support"
    },
    {
      "x": -20,
      "y": 57,
      "z": -13,
      "name": "Plant_Leaves_Beech_Max_Support"
    },
    {
      "x": -20,
      "y": 58,
      "z": -13,
      "name": "Plant_Leaves_Beech_Max_Support"
    },
    {
      "x": -20,
      "y": 59,
      "z": -13,
      "name": "Plant_Leaves_Beech_Max_Support"
    },
    {
      "x": -20,
      "y": 60,
      "z": -13,
      "name": "Plant_Leaves_Beech_Max_Support"
    },
    {
      "x": -20,
      "y": 63,
      "z": -13,
      "name": "Plant_Leaves_Beech_Max_Support"
    },
    {
      "x": -20,
      "y": 54,
      "z": -12,
      "name": "Plant_Leaves_Beech_Max_Support"
    },
    {
      "x": -20,
      "y": 55,
      "z": -12,
      "name": "Plant_Leaves_Beech_Max_Support"
    },
    {
      "x": -20,
      "y": 56,
      "z": -12,
      "name": "Plant_Leaves_Beech_Max_Support"
    },
    {
      "x": -20,
      "y": 57,
      "z": -12,
      "name": "Plant_Leaves_Beech_Max_Support"
    },
    {
      "x": -20,
      "y": 58,
      "z": -12,
      "name": "Plant_Leaves_Beech_Max_Support"
    },
    {
      "x": -20,
      "y": 59,
      "z": -12,
      "name": "Plant_Leaves_Beech_Max_Support"
    },
    {
      "x": -20,
      "y": 61,
      "z": -12,
      "name": "Plant_Leaves_Beech_Max_Support"
    },
    {
      "x": -20,
      "y": 52,
      "z": -11,
      "name": "Plant_Leaves_Beech_Max_Support"
    },
    {
      "x": -20,
      "y": 53,
      "z": -11,
      "name": "Plant_Leaves_Beech_Max_Support"
    },
    {
      "x": -20,
      "y": 54,
      "z": -11,
      "name": "Plant_Leaves_Beech_Max_Support"
    },
    {
      "x": -20,
      "y": 55,
      "z": -11,
      "name": "Plant_Leaves_Beech_Max_Support"
    },
    {
      "x": -20,
      "y": 56,
      "z": -11,
      "name": "Plant_Leaves_Beech_Max_Support"
    },
    {
      "x": -20,
      "y": 57,
      "z": -11,
      "name": "Plant_Leaves_Beech_Max_Support"
    },
    {
      "x": -20,
      "y": 58,
      "z": -11,
      "name": "Plant_Leaves_Beech_Max_Support"
    },
    {
      "x": -20,
      "y": 59,
      "z": -11,
      "name": "Plant_Leaves_Beech_Max_Support"
    },
    {
      "x": -20,
      "y": 61,
      "z": -11,
      "name": "Plant_Leaves_Beech_Max_Support"
    },
    {
      "x": -20,
      "y": 52,
      "z": -10,
      "name": "Plant_Leaves_Beech_Max_Support"
    },
    {
      "x": -20,
      "y": 53,
      "z": -10,
      "name": "Plant_Leaves_Beech_Max_Support"
    },
    {
      "x": -20,
      "y": 54,
      "z": -10,
      "name": "Plant_Leaves_Beech_Max_Support"
    },
    {
      "x": -20,
      "y": 55,
      "z": -10,
      "name": "Plant_Leaves_Beech_Max_Support"
    },
    {
      "x": -20,
      "y": 56,
      "z": -10,
      "name": "Plant_Leaves_Beech_Max_Support"
    },
    {
      "x": -20,
      "y": 57,
      "z": -10,
      "name": "Plant_Leaves_Beech_Max_Support"
    },
    {
      "x": -20,
      "y": 58,
      "z": -10,
      "name": "Plant_Leaves_Beech_Max_Support"
    },
    {
      "x": -20,
      "y": 59,
      "z": -10,
      "name": "Plant_Leaves_Beech_Max_Support"
    },
    {
      "x": -20,
      "y": 52,
      "z": -9,
      "name": "Plant_Leaves_Beech_Max_Support"
    },
    {
      "x": -20,
      "y": 53,
      "z": -9,
      "name": "Plant_Leaves_Beech_Max_Support"
    },
    {
      "x": -20,
      "y": 54,
      "z": -9,
      "name": "Plant_Leaves_Beech_Max_Support"
    },
    {
      "x": -20,
      "y": 55,
      "z": -9,
      "name": "Plant_Leaves_Beech_Max_Support"
    },
    {
      "x": -20,
      "y": 56,
      "z": -9,
      "name": "Plant_Leaves_Beech_Max_Support"
    },
    {
      "x": -20,
      "y": 57,
      "z": -9,
      "name": "Plant_Leaves_Beech_Max_Support"
    },
    {
      "x": -20,
      "y": 58,
      "z": -9,
      "name": "Plant_Leaves_Beech_Max_Support"
    },
    {
      "x": -20,
      "y": 60,
      "z": -9,
      "name": "Plant_Leaves_Beech_Max_Support"
    },
    {
      "x": -20,
      "y": 53,
      "z": -8,
      "name": "Plant_Leaves_Beech_Max_Support"
    },
    {
      "x": -20,
      "y": 55,
      "z": -8,
      "name": "Plant_Leaves_Beech_Max_Support"
    },
    {
      "x": -20,
      "y": 56,
      "z": -8,
      "name": "Plant_Leaves_Beech_Max_Support"
    },
    {
      "x": -20,
      "y": 56,
      "z": 5,
      "name": "Plant_Leaves_Beech_Max_Support"
    },
    {
      "x": -20,
      "y": 55,
      "z": 6,
      "name": "Plant_Leaves_Beech_Max_Support"
    },
    {
      "x": -20,
      "y": 56,
      "z": 6,
      "name": "Plant_Leaves_Beech_Max_Support"
    },
    {
      "x": -20,
      "y": 56,
      "z": 7,
      "name": "Plant_Leaves_Beech_Max_Support"
    },
    {
      "x": -20,
      "y": 54,
      "z": 21,
      "name": "Plant_Leaves_Beech_Max_Support"
    },
    {
      "x": -20,
      "y": 55,
      "z": 21,
      "name": "Plant_Leaves_Beech_Max_Support"
    },
    {
      "x": -20,
      "y": 56,
      "z": 21,
      "name": "Plant_Leaves_Beech_Max_Support"
    },
    {
      "x": -20,
      "y": 53,
      "z": 22,
      "name": "Plant_Leaves_Beech_Max_Support"
    },
    {
      "x": -20,
      "y": 54,
      "z": 22,
      "name": "Plant_Leaves_Beech_Max_Support"
    },
    {
      "x": -20,
      "y": 55,
      "z": 22,
      "name": "Plant_Leaves_Beech_Max_Support"
    },
    {
      "x": -20,
      "y": 57,
      "z": 22,
      "name": "Plant_Leaves_Beech_Max_Support"
    },
    {
      "x": -20,
      "y": 53,
      "z": 23,
      "name": "Plant_Leaves_Beech_Max_Support"
    },
    {
      "x": -20,
      "y": 54,
      "z": 23,
      "name": "Plant_Leaves_Beech_Max_Support"
    },
    {
      "x": -20,
      "y": 55,
      "z": 23,
      "name": "Plant_Leaves_Beech_Max_Support"
    },
    {
      "x": -20,
      "y": 56,
      "z": 23,
      "name": "Plant_Leaves_Beech_Max_Support"
    },
    {
      "x": -20,
      "y": 57,
      "z": 23,
      "name": "Plant_Leaves_Beech_Max_Support"
    },
    {
      "x": -20,
      "y": 60,
      "z": 23,
      "name": "Plant_Leaves_Beech_Max_Support"
    },
    {
      "x": -20,
      "y": 61,
      "z": 23,
      "name": "Plant_Leaves_Beech_Max_Support"
    },
    {
      "x": -20,
      "y": 55,
      "z": 24,
      "name": "Plant_Leaves_Beech_Max_Support"
    },
    {
      "x": -20,
      "y": 56,
      "z": 24,
      "name": "Plant_Leaves_Beech_Max_Support"
    },
    {
      "x": -20,
      "y": 57,
      "z": 24,
      "name": "Plant_Leaves_Beech_Max_Support"
    },
    {
      "x": -20,
      "y": 59,
      "z": 24,
      "name": "Plant_Leaves_Beech_Max_Support"
    },
    {
      "x": -20,
      "y": 61,
      "z": 24,
      "name": "Plant_Leaves_Beech_Max_Support"
    },
    {
      "x": -20,
      "y": 62,
      "z": 24,
      "name": "Plant_Leaves_Beech_Max_Support"
    },
    {
      "x": -20,
      "y": 63,
      "z": 24,
      "name": "Plant_Leaves_Beech_Max_Support"
    },
    {
      "x": -20,
      "y": 54,
      "z": 25,
      "name": "Plant_Leaves_Beech_Max_Support"
    },
    {
      "x": -20,
      "y": 55,
      "z": 25,
      "name": "Plant_Leaves_Beech_Max_Support"
    },
    {
      "x": -20,
      "y": 56,
      "z": 25,
      "name": "Plant_Leaves_Beech_Max_Support"
    },
    {
      "x": -20,
      "y": 57,
      "z": 25,
      "name": "Plant_Leaves_Beech_Max_Support"
    },
    {
      "x": -20,
      "y": 58,
      "z": 25,
      "name": "Plant_Leaves_Beech_Max_Support"
    },
    {
      "x": -20,
      "y": 59,
      "z": 25,
      "name": "Plant_Leaves_Beech_Max_Support"
    },
    {
      "x": -20,
      "y": 60,
      "z": 25,
      "name": "Plant_Leaves_Beech_Max_Support"
    },
    {
      "x": -20,
      "y": 61,
      "z": 25,
      "name": "Plant_Leaves_Beech_Max_Support"
    },
    {
      "x": -20,
      "y": 63,
      "z": 25,
      "name": "Plant_Leaves_Beech_Max_Support"
    },
    {
      "x": -20,
      "y": 55,
      "z": 26,
      "name": "Plant_Leaves_Beech_Max_Support"
    },
    {
      "x": -20,
      "y": 56,
      "z": 26,
      "name": "Plant_Leaves_Beech_Max_Support"
    },
    {
      "x": -20,
      "y": 58,
      "z": 26,
      "name": "Plant_Leaves_Beech_Max_Support"
    },
    {
      "x": -20,
      "y": 59,
      "z": 26,
      "name": "Plant_Leaves_Beech_Max_Support"
    },
    {
      "x": -20,
      "y": 60,
      "z": 26,
      "name": "Plant_Leaves_Beech_Max_Support"
    },
    {
      "x": -20,
      "y": 61,
      "z": 26,
      "name": "Plant_Leaves_Beech_Max_Support"
    },
    {
      "x": -20,
      "y": 62,
      "z": 26,
      "name": "Plant_Leaves_Beech_Max_Support"
    },
    {
      "x": -20,
      "y": 63,
      "z": 26,
      "name": "Plant_Leaves_Beech_Max_Support"
    },
    {
      "x": -20,
      "y": 55,
      "z": 27,
      "name": "Plant_Leaves_Beech_Max_Support"
    },
    {
      "x": -20,
      "y": 56,
      "z": 27,
      "name": "Plant_Leaves_Beech_Max_Support"
    },
    {
      "x": -20,
      "y": 57,
      "z": 27,
      "name": "Plant_Leaves_Beech_Max_Support"
    },
    {
      "x": -20,
      "y": 58,
      "z": 27,
      "name": "Plant_Leaves_Beech_Max_Support"
    },
    {
      "x": -20,
      "y": 59,
      "z": 27,
      "name": "Plant_Leaves_Beech_Max_Support"
    },
    {
      "x": -20,
      "y": 60,
      "z": 27,
      "name": "Plant_Leaves_Beech_Max_Support"
    },
    {
      "x": -20,
      "y": 61,
      "z": 27,
      "name": "Plant_Leaves_Beech_Max_Support"
    },
    {
      "x": -20,
      "y": 62,
      "z": 27,
      "name": "Plant_Leaves_Beech_Max_Support"
    },
    {
      "x": -20,
      "y": 63,
      "z": 27,
      "name": "Plant_Leaves_Beech_Max_Support"
    },
    {
      "x": -20,
      "y": 64,
      "z": 27,
      "name": "Plant_Leaves_Beech_Max_Support"
    },
    {
      "x": -20,
      "y": 55,
      "z": 28,
      "name": "Wood_Gumboab_Trunk_Full"
    },
    {
      "x": -20,
      "y": 56,
      "z": 28,
      "name": "Wood_Gumboab_Trunk_Full"
    },
    {
      "x": -20,
      "y": 57,
      "z": 28,
      "name": "Plant_Leaves_Beech_Max_Support"
    },
    {
      "x": -20,
      "y": 58,
      "z": 28,
      "name": "Plant_Leaves_Beech_Max_Support"
    },
    {
      "x": -20,
      "y": 59,
      "z": 28,
      "name": "Plant_Leaves_Beech_Max_Support"
    },
    {
      "x": -20,
      "y": 62,
      "z": 28,
      "name": "Plant_Leaves_Beech_Max_Support"
    },
    {
      "x": -20,
      "y": 63,
      "z": 28,
      "name": "Plant_Leaves_Beech_Max_Support"
    },
    {
      "x": -20,
      "y": 54,
      "z": 29,
      "name": "Plant_Leaves_Beech_Max_Support"
    },
    {
      "x": -20,
      "y": 55,
      "z": 29,
      "name": "Wood_Gumboab_Trunk_Full"
    },
    {
      "x": -20,
      "y": 56,
      "z": 29,
      "name": "Wood_Gumboab_Trunk_Full"
    },
    {
      "x": -20,
      "y": 57,
      "z": 29,
      "name": "Plant_Leaves_Beech_Max_Support"
    },
    {
      "x": -20,
      "y": 58,
      "z": 29,
      "name": "Plant_Leaves_Beech_Max_Support"
    },
    {
      "x": -20,
      "y": 59,
      "z": 29,
      "name": "Plant_Leaves_Beech_Max_Support"
    },
    {
      "x": -20,
      "y": 60,
      "z": 29,
      "name": "Plant_Leaves_Beech_Max_Support"
    },
    {
      "x": -20,
      "y": 61,
      "z": 29,
      "name": "Plant_Leaves_Beech_Max_Support"
    },
    {
      "x": -20,
      "y": 56,
      "z": 30,
      "name": "Plant_Leaves_Beech_Max_Support"
    },
    {
      "x": -20,
      "y": 57,
      "z": 30,
      "name": "Plant_Leaves_Beech_Max_Support"
    },
    {
      "x": -20,
      "y": 58,
      "z": 30,
      "name": "Plant_Leaves_Beech_Max_Support"
    },
    {
      "x": -20,
      "y": 59,
      "z": 30,
      "name": "Plant_Leaves_Beech_Max_Support"
    },
    {
      "x": -20,
      "y": 60,
      "z": 30,
      "name": "Plant_Leaves_Beech_Max_Support"
    },
    {
      "x": -20,
      "y": 55,
      "z": 31,
      "name": "Plant_Leaves_Beech_Max_Support"
    },
    {
      "x": -20,
      "y": 56,
      "z": 31,
      "name": "Plant_Leaves_Beech_Max_Support"
    },
    {
      "x": -20,
      "y": 57,
      "z": 31,
      "name": "Plant_Leaves_Beech_Max_Support"
    },
    {
      "x": -20,
      "y": 58,
      "z": 31,
      "name": "Plant_Leaves_Beech_Max_Support"
    },
    {
      "x": -20,
      "y": 60,
      "z": 31,
      "name": "Plant_Leaves_Beech_Max_Support"
    },
    {
      "x": -20,
      "y": 54,
      "z": 32,
      "name": "Plant_Leaves_Beech_Max_Support"
    },
    {
      "x": -20,
      "y": 55,
      "z": 32,
      "name": "Plant_Leaves_Beech_Max_Support"
    },
    {
      "x": -20,
      "y": 56,
      "z": 32,
      "name": "Plant_Leaves_Beech_Max_Support"
    },
    {
      "x": -20,
      "y": 57,
      "z": 32,
      "name": "Plant_Leaves_Beech_Max_Support"
    },
    {
      "x": -20,
      "y": 58,
      "z": 32,
      "name": "Plant_Leaves_Beech_Max_Support"
    },
    {
      "x": -20,
      "y": 59,
      "z": 32,
      "name": "Plant_Leaves_Beech_Max_Support"
    },
    {
      "x": -20,
      "y": 55,
      "z": 33,
      "name": "Plant_Leaves_Beech_Max_Support"
    },
    {
      "x": -20,
      "y": 56,
      "z": 33,
      "name": "Plant_Leaves_Beech_Max_Support"
    },
    {
      "x": -20,
      "y": 54,
      "z": 34,
      "name": "Plant_Leaves_Beech_Max_Support"
    },
    {
      "x": -20,
      "y": 55,
      "z": 34,
      "name": "Plant_Leaves_Beech_Max_Support"
    },
    {
      "x": -20,
      "y": 55,
      "z": 35,
      "name": "Plant_Leaves_Beech_Max_Support"
    },
    {
      "x": -19,
      "y": 55,
      "z": -21,
      "name": "Plant_Leaves_Beech_Max_Support",
      "support": 15
    },
    {
      "x": -19,
      "y": 57,
      "z": -21,
      "name": "Plant_Leaves_Beech_Max_Support"
    },
    {
      "x": -19,
      "y": 55,
      "z": -20,
      "name": "Plant_Leaves_Beech_Max_Support",
      "support": 15
    },
    {
      "x": -19,
      "y": 58,
      "z": -20,
      "name": "Plant_Leaves_Beech_Max_Support"
    },
    {
      "x": -19,
      "y": 55,
      "z": -19,
      "name": "Plant_Leaves_Beech_Max_Support"
    },
    {
      "x": -19,
      "y": 56,
      "z": -19,
      "name": "Plant_Leaves_Beech_Max_Support"
    },
    {
      "x": -19,
      "y": 57,
      "z": -19,
      "name": "Plant_Leaves_Beech_Max_Support"
    },
    {
      "x": -19,
      "y": 58,
      "z": -19,
      "name": "Plant_Leaves_Beech_Max_Support"
    },
    {
      "x": -19,
      "y": 59,
      "z": -19,
      "name": "Plant_Leaves_Beech_Max_Support"
    },
    {
      "x": -19,
      "y": 56,
      "z": -18,
      "name": "Plant_Leaves_Beech_Max_Support"
    },
    {
      "x": -19,
      "y": 57,
      "z": -18,
      "name": "Plant_Leaves_Beech_Max_Support"
    },
    {
      "x": -19,
      "y": 58,
      "z": -18,
      "name": "Plant_Leaves_Beech_Max_Support"
    },
    {
      "x": -19,
      "y": 60,
      "z": -18,
      "name": "Plant_Leaves_Beech_Max_Support"
    },
    {
      "x": -19,
      "y": 55,
      "z": -17,
      "name": "Plant_Leaves_Beech_Max_Support"
    },
    {
      "x": -19,
      "y": 56,
      "z": -17,
      "name": "Wood_Gumboab_Trunk_Full"
    },
    {
      "x": -19,
      "y": 57,
      "z": -17,
      "name": "Plant_Leaves_Beech_Max_Support"
    },
    {
      "x": -19,
      "y": 58,
      "z": -17,
      "name": "Plant_Leaves_Beech_Max_Support"
    },
    {
      "x": -19,
      "y": 59,
      "z": -17,
      "name": "Plant_Leaves_Beech_Max_Support"
    },
    {
      "x": -19,
      "y": 61,
      "z": -17,
      "name": "Plant_Leaves_Beech_Max_Support"
    },
    {
      "x": -19,
      "y": 55,
      "z": -16,
      "name": "Plant_Leaves_Beech_Max_Support"
    },
    {
      "x": -19,
      "y": 56,
      "z": -16,
      "name": "Wood_Gumboab_Trunk_Full"
    },
    {
      "x": -19,
      "y": 57,
      "z": -16,
      "name": "Wood_Gumboab_Trunk_Full"
    },
    {
      "x": -19,
      "y": 58,
      "z": -16,
      "name": "Plant_Leaves_Beech_Max_Support"
    },
    {
      "x": -19,
      "y": 59,
      "z": -16,
      "name": "Plant_Leaves_Beech_Max_Support"
    },
    {
      "x": -19,
      "y": 60,
      "z": -16,
      "name": "Plant_Leaves_Beech_Max_Support"
    },
    {
      "x": -19,
      "y": 61,
      "z": -16,
      "name": "Plant_Leaves_Beech_Max_Support"
    },
    {
      "x": -19,
      "y": 62,
      "z": -16,
      "name": "Plant_Leaves_Beech_Max_Support"
    },
    {
      "x": -19,
      "y": 56,
      "z": -15,
      "name": "Wood_Gumboab_Trunk_Full"
    },
    {
      "x": -19,
      "y": 57,
      "z": -15,
      "name": "Plant_Leaves_Beech_Max_Support"
    },
    {
      "x": -19,
      "y": 58,
      "z": -15,
      "name": "Plant_Leaves_Beech_Max_Support"
    },
    {
      "x": -19,
      "y": 59,
      "z": -15,
      "name": "Plant_Leaves_Beech_Max_Support"
    },
    {
      "x": -19,
      "y": 60,
      "z": -15,
      "name": "Plant_Leaves_Beech_Max_Support"
    },
    {
      "x": -19,
      "y": 55,
      "z": -14,
      "name": "Plant_Leaves_Beech_Max_Support"
    },
    {
      "x": -19,
      "y": 56,
      "z": -14,
      "name": "Plant_Leaves_Beech_Max_Support"
    },
    {
      "x": -19,
      "y": 57,
      "z": -14,
      "name": "Plant_Leaves_Beech_Max_Support"
    },
    {
      "x": -19,
      "y": 58,
      "z": -14,
      "name": "Plant_Leaves_Beech_Max_Support"
    },
    {
      "x": -19,
      "y": 59,
      "z": -14,
      "name": "Plant_Leaves_Beech_Max_Support"
    },
    {
      "x": -19,
      "y": 60,
      "z": -14,
      "name": "Plant_Leaves_Beech_Max_Support"
    },
    {
      "x": -19,
      "y": 61,
      "z": -14,
      "name": "Plant_Leaves_Beech_Max_Support"
    },
    {
      "x": -19,
      "y": 62,
      "z": -14,
      "name": "Plant_Leaves_Beech_Max_Support"
    },
    {
      "x": -19,
      "y": 56,
      "z": -13,
      "name": "Plant_Leaves_Beech_Max_Support"
    },
    {
      "x": -19,
      "y": 57,
      "z": -13,
      "name": "Plant_Leaves_Beech_Max_Support"
    },
    {
      "x": -19,
      "y": 58,
      "z": -13,
      "name": "Plant_Leaves_Beech_Max_Support"
    },
    {
      "x": -19,
      "y": 59,
      "z": -13,
      "name": "Plant_Leaves_Beech_Max_Support"
    },
    {
      "x": -19,
      "y": 60,
      "z": -13,
      "name": "Plant_Leaves_Beech_Max_Support"
    },
    {
      "x": -19,
      "y": 61,
      "z": -13,
      "name": "Plant_Leaves_Beech_Max_Support"
    },
    {
      "x": -19,
      "y": 62,
      "z": -13,
      "name": "Plant_Leaves_Beech_Max_Support"
    },
    {
      "x": -19,
      "y": 54,
      "z": -12,
      "name": "Plant_Leaves_Beech_Max_Support"
    },
    {
      "x": -19,
      "y": 55,
      "z": -12,
      "name": "Plant_Leaves_Beech_Max_Support"
    },
    {
      "x": -19,
      "y": 56,
      "z": -12,
      "name": "Plant_Leaves_Beech_Max_Support"
    },
    {
      "x": -19,
      "y": 57,
      "z": -12,
      "name": "Plant_Leaves_Beech_Max_Support"
    },
    {
      "x": -19,
      "y": 58,
      "z": -12,
      "name": "Plant_Leaves_Beech_Max_Support"
    },
    {
      "x": -19,
      "y": 59,
      "z": -12,
      "name": "Plant_Leaves_Beech_Max_Support"
    },
    {
      "x": -19,
      "y": 60,
      "z": -12,
      "name": "Plant_Leaves_Beech_Max_Support"
    },
    {
      "x": -19,
      "y": 61,
      "z": -12,
      "name": "Plant_Leaves_Beech_Max_Support"
    },
    {
      "x": -19,
      "y": 62,
      "z": -12,
      "name": "Plant_Leaves_Beech_Max_Support"
    },
    {
      "x": -19,
      "y": 53,
      "z": -11,
      "name": "Plant_Leaves_Beech_Max_Support"
    },
    {
      "x": -19,
      "y": 55,
      "z": -11,
      "name": "Plant_Leaves_Beech_Max_Support"
    },
    {
      "x": -19,
      "y": 56,
      "z": -11,
      "name": "Plant_Leaves_Beech_Max_Support"
    },
    {
      "x": -19,
      "y": 57,
      "z": -11,
      "name": "Plant_Leaves_Beech_Max_Support"
    },
    {
      "x": -19,
      "y": 58,
      "z": -11,
      "name": "Plant_Leaves_Beech_Max_Support"
    },
    {
      "x": -19,
      "y": 59,
      "z": -11,
      "name": "Plant_Leaves_Beech_Max_Support"
    },
    {
      "x": -19,
      "y": 60,
      "z": -11,
      "name": "Plant_Leaves_Beech_Max_Support"
    },
    {
      "x": -19,
      "y": 53,
      "z": -10,
      "name": "Plant_Leaves_Beech_Max_Support"
    },
    {
      "x": -19,
      "y": 55,
      "z": -10,
      "name": "Plant_Leaves_Beech_Max_Support"
    },
    {
      "x": -19,
      "y": 56,
      "z": -10,
      "name": "Plant_Leaves_Beech_Max_Support"
    },
    {
      "x": -19,
      "y": 57,
      "z": -10,
      "name": "Plant_Leaves_Beech_Max_Support"
    },
    {
      "x": -19,
      "y": 58,
      "z": -10,
      "name": "Plant_Leaves_Beech_Max_Support"
    },
    {
      "x": -19,
      "y": 59,
      "z": -10,
      "name": "Plant_Leaves_Beech_Max_Support"
    },
    {
      "x": -19,
      "y": 61,
      "z": -10,
      "name": "Plant_Leaves_Beech_Max_Support"
    },
    {
      "x": -19,
      "y": 53,
      "z": -9,
      "name": "Plant_Leaves_Beech_Max_Support"
    },
    {
      "x": -19,
      "y": 55,
      "z": -9,
      "name": "Plant_Leaves_Beech_Max_Support"
    },
    {
      "x": -19,
      "y": 56,
      "z": -9,
      "name": "Plant_Leaves_Beech_Max_Support"
    },
    {
      "x": -19,
      "y": 57,
      "z": -9,
      "name": "Plant_Leaves_Beech_Max_Support"
    },
    {
      "x": -19,
      "y": 58,
      "z": -9,
      "name": "Plant_Leaves_Beech_Max_Support"
    },
    {
      "x": -19,
      "y": 59,
      "z": -9,
      "name": "Plant_Leaves_Beech_Max_Support"
    },
    {
      "x": -19,
      "y": 61,
      "z": -9,
      "name": "Plant_Leaves_Beech_Max_Support"
    },
    {
      "x": -19,
      "y": 54,
      "z": -8,
      "name": "Plant_Leaves_Beech_Max_Support"
    },
    {
      "x": -19,
      "y": 56,
      "z": -8,
      "name": "Plant_Leaves_Beech_Max_Support"
    },
    {
      "x": -19,
      "y": 57,
      "z": -8,
      "name": "Plant_Leaves_Beech_Max_Support"
    },
    {
      "x": -19,
      "y": 58,
      "z": -8,
      "name": "Plant_Leaves_Beech_Max_Support"
    },
    {
      "x": -19,
      "y": 59,
      "z": -8,
      "name": "Plant_Leaves_Beech_Max_Support"
    },
    {
      "x": -19,
      "y": 56,
      "z": 1,
      "name": "Plant_Leaves_Beech_Max_Support"
    },
    {
      "x": -19,
      "y": 57,
      "z": 2,
      "name": "Plant_Leaves_Beech_Max_Support"
    },
    {
      "x": -19,
      "y": 59,
      "z": 2,
      "name": "Plant_Leaves_Beech_Max_Support"
    },
    {
      "x": -19,
      "y": 60,
      "z": 2,
      "name": "Plant_Leaves_Beech_Max_Support"
    },
    {
      "x": -19,
      "y": 56,
      "z": 3,
      "name": "Plant_Leaves_Beech_Max_Support"
    },
    {
      "x": -19,
      "y": 58,
      "z": 3,
      "name": "Plant_Leaves_Beech_Max_Support"
    },
    {
      "x": -19,
      "y": 59,
      "z": 3,
      "name": "Plant_Leaves_Beech_Max_Support"
    },
    {
      "x": -19,
      "y": 55,
      "z": 4,
      "name": "Plant_Leaves_Beech_Max_Support"
    },
    {
      "x": -19,
      "y": 56,
      "z": 4,
      "name": "Plant_Leaves_Beech_Max_Support"
    },
    {
      "x": -19,
      "y": 58,
      "z": 4,
      "name": "Plant_Leaves_Beech_Max_Support"
    },
    {
      "x": -19,
      "y": 55,
      "z": 5,
      "name": "Plant_Leaves_Beech_Max_Support"
    },
    {
      "x": -19,
      "y": 56,
      "z": 5,
      "name": "Plant_Leaves_Beech_Max_Support"
    },
    {
      "x": -19,
      "y": 54,
      "z": 6,
      "name": "Plant_Leaves_Beech_Max_Support"
    },
    {
      "x": -19,
      "y": 55,
      "z": 6,
      "name": "Plant_Leaves_Beech_Max_Support"
    },
    {
      "x": -19,
      "y": 56,
      "z": 6,
      "name": "Plant_Leaves_Beech_Max_Support"
    },
    {
      "x": -19,
      "y": 57,
      "z": 6,
      "name": "Plant_Leaves_Beech_Max_Support"
    },
    {
      "x": -19,
      "y": 58,
      "z": 6,
      "name": "Plant_Leaves_Beech_Max_Support"
    },
    {
      "x": -19,
      "y": 55,
      "z": 7,
      "name": "Plant_Leaves_Beech_Max_Support"
    },
    {
      "x": -19,
      "y": 56,
      "z": 7,
      "name": "Plant_Leaves_Beech_Max_Support"
    },
    {
      "x": -19,
      "y": 57,
      "z": 7,
      "name": "Plant_Leaves_Beech_Max_Support"
    },
    {
      "x": -19,
      "y": 55,
      "z": 20,
      "name": "Plant_Leaves_Beech_Max_Support"
    },
    {
      "x": -19,
      "y": 54,
      "z": 21,
      "name": "Plant_Leaves_Beech_Max_Support"
    },
    {
      "x": -19,
      "y": 55,
      "z": 21,
      "name": "Plant_Leaves_Beech_Max_Support"
    },
    {
      "x": -19,
      "y": 56,
      "z": 21,
      "name": "Plant_Leaves_Beech_Max_Support"
    },
    {
      "x": -19,
      "y": 55,
      "z": 22,
      "name": "Plant_Leaves_Beech_Max_Support"
    },
    {
      "x": -19,
      "y": 56,
      "z": 22,
      "name": "Plant_Leaves_Beech_Max_Support"
    },
    {
      "x": -19,
      "y": 53,
      "z": 23,
      "name": "Plant_Leaves_Beech_Max_Support"
    },
    {
      "x": -19,
      "y": 55,
      "z": 23,
      "name": "Plant_Leaves_Beech_Max_Support"
    },
    {
      "x": -19,
      "y": 56,
      "z": 23,
      "name": "Plant_Leaves_Beech_Max_Support"
    },
    {
      "x": -19,
      "y": 57,
      "z": 23,
      "name": "Plant_Leaves_Beech_Max_Support"
    },
    {
      "x": -19,
      "y": 58,
      "z": 23,
      "name": "Plant_Leaves_Beech_Max_Support"
    },
    {
      "x": -19,
      "y": 59,
      "z": 23,
      "name": "Plant_Leaves_Beech_Max_Support"
    },
    {
      "x": -19,
      "y": 60,
      "z": 23,
      "name": "Plant_Leaves_Beech_Max_Support"
    },
    {
      "x": -19,
      "y": 54,
      "z": 24,
      "name": "Plant_Leaves_Beech_Max_Support"
    },
    {
      "x": -19,
      "y": 55,
      "z": 24,
      "name": "Plant_Leaves_Beech_Max_Support"
    },
    {
      "x": -19,
      "y": 56,
      "z": 24,
      "name": "Plant_Leaves_Beech_Max_Support"
    },
    {
      "x": -19,
      "y": 57,
      "z": 24,
      "name": "Plant_Leaves_Beech_Max_Support"
    },
    {
      "x": -19,
      "y": 58,
      "z": 24,
      "name": "Plant_Leaves_Beech_Max_Support"
    },
    {
      "x": -19,
      "y": 59,
      "z": 24,
      "name": "Plant_Leaves_Beech_Max_Support"
    },
    {
      "x": -19,
      "y": 60,
      "z": 24,
      "name": "Plant_Leaves_Beech_Max_Support"
    },
    {
      "x": -19,
      "y": 62,
      "z": 24,
      "name": "Plant_Leaves_Beech_Max_Support"
    },
    {
      "x": -19,
      "y": 56,
      "z": 25,
      "name": "Plant_Leaves_Beech_Max_Support"
    },
    {
      "x": -19,
      "y": 57,
      "z": 25,
      "name": "Plant_Leaves_Beech_Max_Support"
    },
    {
      "x": -19,
      "y": 58,
      "z": 25,
      "name": "Plant_Leaves_Beech_Max_Support"
    },
    {
      "x": -19,
      "y": 59,
      "z": 25,
      "name": "Plant_Leaves_Beech_Max_Support"
    },
    {
      "x": -19,
      "y": 60,
      "z": 25,
      "name": "Plant_Leaves_Beech_Max_Support"
    },
    {
      "x": -19,
      "y": 61,
      "z": 25,
      "name": "Plant_Leaves_Beech_Max_Support"
    },
    {
      "x": -19,
      "y": 63,
      "z": 25,
      "name": "Plant_Leaves_Beech_Max_Support"
    },
    {
      "x": -19,
      "y": 64,
      "z": 25,
      "name": "Plant_Leaves_Beech_Max_Support"
    },
    {
      "x": -19,
      "y": 56,
      "z": 26,
      "name": "Plant_Leaves_Beech_Max_Support"
    },
    {
      "x": -19,
      "y": 57,
      "z": 26,
      "name": "Plant_Leaves_Beech_Max_Support"
    },
    {
      "x": -19,
      "y": 59,
      "z": 26,
      "name": "Plant_Leaves_Beech_Max_Support"
    },
    {
      "x": -19,
      "y": 60,
      "z": 26,
      "name": "Plant_Leaves_Beech_Max_Support"
    },
    {
      "x": -19,
      "y": 61,
      "z": 26,
      "name": "Plant_Leaves_Beech_Max_Support"
    },
    {
      "x": -19,
      "y": 62,
      "z": 26,
      "name": "Plant_Leaves_Beech_Max_Support"
    },
    {
      "x": -19,
      "y": 55,
      "z": 27,
      "name": "Plant_Leaves_Beech_Max_Support"
    },
    {
      "x": -19,
      "y": 56,
      "z": 27,
      "name": "Plant_Leaves_Beech_Max_Support"
    },
    {
      "x": -19,
      "y": 57,
      "z": 27,
      "name": "Plant_Leaves_Beech_Max_Support"
    },
    {
      "x": -19,
      "y": 58,
      "z": 27,
      "name": "Plant_Leaves_Beech_Max_Support"
    },
    {
      "x": -19,
      "y": 59,
      "z": 27,
      "name": "Plant_Leaves_Beech_Max_Support"
    },
    {
      "x": -19,
      "y": 60,
      "z": 27,
      "name": "Plant_Leaves_Beech_Max_Support"
    },
    {
      "x": -19,
      "y": 61,
      "z": 27,
      "name": "Plant_Leaves_Beech_Max_Support"
    },
    {
      "x": -19,
      "y": 63,
      "z": 27,
      "name": "Plant_Leaves_Beech_Max_Support"
    },
    {
      "x": -19,
      "y": 54,
      "z": 28,
      "name": "Plant_Leaves_Beech_Max_Support"
    },
    {
      "x": -19,
      "y": 56,
      "z": 28,
      "name": "Plant_Leaves_Beech_Max_Support"
    },
    {
      "x": -19,
      "y": 57,
      "z": 28,
      "name": "Plant_Leaves_Beech_Max_Support"
    },
    {
      "x": -19,
      "y": 58,
      "z": 28,
      "name": "Plant_Leaves_Beech_Max_Support"
    },
    {
      "x": -19,
      "y": 60,
      "z": 28,
      "name": "Plant_Leaves_Beech_Max_Support"
    },
    {
      "x": -19,
      "y": 54,
      "z": 29,
      "name": "Plant_Leaves_Beech_Max_Support"
    },
    {
      "x": -19,
      "y": 55,
      "z": 29,
      "name": "Wood_Gumboab_Trunk_Full"
    },
    {
      "x": -19,
      "y": 56,
      "z": 29,
      "name": "Wood_Gumboab_Trunk_Full"
    },
    {
      "x": -19,
      "y": 57,
      "z": 29,
      "name": "Plant_Leaves_Beech_Max_Support"
    },
    {
      "x": -19,
      "y": 59,
      "z": 29,
      "name": "Plant_Leaves_Beech_Max_Support"
    },
    {
      "x": -19,
      "y": 60,
      "z": 29,
      "name": "Plant_Leaves_Beech_Max_Support"
    },
    {
      "x": -19,
      "y": 61,
      "z": 29,
      "name": "Plant_Leaves_Beech_Max_Support"
    },
    {
      "x": -19,
      "y": 54,
      "z": 30,
      "name": "Plant_Leaves_Beech_Max_Support"
    },
    {
      "x": -19,
      "y": 55,
      "z": 30,
      "name": "Wood_Gumboab_Trunk_Full"
    },
    {
      "x": -19,
      "y": 56,
      "z": 30,
      "name": "Wood_Gumboab_Trunk_Full"
    },
    {
      "x": -19,
      "y": 57,
      "z": 30,
      "name": "Plant_Leaves_Beech_Max_Support"
    },
    {
      "x": -19,
      "y": 58,
      "z": 30,
      "name": "Plant_Leaves_Beech_Max_Support"
    },
    {
      "x": -19,
      "y": 59,
      "z": 30,
      "name": "Plant_Leaves_Beech_Max_Support"
    },
    {
      "x": -19,
      "y": 60,
      "z": 30,
      "name": "Plant_Leaves_Beech_Max_Support"
    },
    {
      "x": -19,
      "y": 61,
      "z": 30,
      "name": "Plant_Leaves_Beech_Max_Support"
    },
    {
      "x": -19,
      "y": 57,
      "z": 31,
      "name": "Plant_Leaves_Beech_Max_Support"
    },
    {
      "x": -19,
      "y": 58,
      "z": 31,
      "name": "Plant_Leaves_Beech_Max_Support"
    },
    {
      "x": -19,
      "y": 60,
      "z": 31,
      "name": "Plant_Leaves_Beech_Max_Support"
    },
    {
      "x": -19,
      "y": 53,
      "z": 32,
      "name": "Plant_Leaves_Beech_Max_Support"
    },
    {
      "x": -19,
      "y": 55,
      "z": 32,
      "name": "Plant_Leaves_Beech_Max_Support"
    },
    {
      "x": -19,
      "y": 56,
      "z": 32,
      "name": "Plant_Leaves_Beech_Max_Support"
    },
    {
      "x": -19,
      "y": 57,
      "z": 32,
      "name": "Plant_Leaves_Beech_Max_Support"
    },
    {
      "x": -19,
      "y": 58,
      "z": 32,
      "name": "Plant_Leaves_Beech_Max_Support"
    },
    {
      "x": -19,
      "y": 59,
      "z": 32,
      "name": "Plant_Leaves_Beech_Max_Support"
    },
    {
      "x": -19,
      "y": 60,
      "z": 32,
      "name": "Plant_Leaves_Beech_Max_Support"
    },
    {
      "x": -19,
      "y": 53,
      "z": 33,
      "name": "Plant_Leaves_Beech_Max_Support"
    },
    {
      "x": -19,
      "y": 54,
      "z": 33,
      "name": "Plant_Leaves_Beech_Max_Support"
    },
    {
      "x": -19,
      "y": 55,
      "z": 33,
      "name": "Plant_Leaves_Beech_Max_Support"
    },
    {
      "x": -19,
      "y": 56,
      "z": 33,
      "name": "Plant_Leaves_Beech_Max_Support"
    },
    {
      "x": -19,
      "y": 57,
      "z": 33,
      "name": "Plant_Leaves_Beech_Max_Support"
    },
    {
      "x": -19,
      "y": 58,
      "z": 33,
      "name": "Plant_Leaves_Beech_Max_Support"
    },
    {
      "x": -19,
      "y": 53,
      "z": 34,
      "name": "Plant_Leaves_Beech_Max_Support"
    },
    {
      "x": -19,
      "y": 54,
      "z": 34,
      "name": "Plant_Leaves_Beech_Max_Support"
    },
    {
      "x": -19,
      "y": 55,
      "z": 34,
      "name": "Plant_Leaves_Beech_Max_Support"
    },
    {
      "x": -19,
      "y": 54,
      "z": 35,
      "name": "Plant_Leaves_Beech_Max_Support"
    },
    {
      "x": -18,
      "y": 51,
      "z": -23,
      "name": "Plant_Leaves_Beech_Max_Support"
    },
    {
      "x": -18,
      "y": 50,
      "z": -22,
      "name": "Plant_Leaves_Beech_Max_Support"
    },
    {
      "x": -18,
      "y": 51,
      "z": -22,
      "name": "Plant_Leaves_Beech_Max_Support"
    },
    {
      "x": -18,
      "y": 52,
      "z": -22,
      "name": "Plant_Leaves_Beech_Max_Support"
    },
    {
      "x": -18,
      "y": 56,
      "z": -21,
      "name": "Plant_Leaves_Beech_Max_Support"
    },
    {
      "x": -18,
      "y": 57,
      "z": -21,
      "name": "Plant_Leaves_Beech_Max_Support"
    },
    {
      "x": -18,
      "y": 58,
      "z": -21,
      "name": "Plant_Leaves_Beech_Max_Support"
    },
    {
      "x": -18,
      "y": 56,
      "z": -20,
      "name": "Plant_Leaves_Beech_Max_Support"
    },
    {
      "x": -18,
      "y": 58,
      "z": -20,
      "name": "Plant_Leaves_Beech_Max_Support"
    },
    {
      "x": -18,
      "y": 59,
      "z": -20,
      "name": "Plant_Leaves_Beech_Max_Support"
    },
    {
      "x": -18,
      "y": 56,
      "z": -19,
      "name": "Plant_Leaves_Beech_Max_Support"
    },
    {
      "x": -18,
      "y": 57,
      "z": -19,
      "name": "Plant_Leaves_Beech_Max_Support"
    },
    {
      "x": -18,
      "y": 58,
      "z": -19,
      "name": "Plant_Leaves_Beech_Max_Support"
    },
    {
      "x": -18,
      "y": 59,
      "z": -19,
      "name": "Plant_Leaves_Beech_Max_Support"
    },
    {
      "x": -18,
      "y": 55,
      "z": -18,
      "name": "Plant_Leaves_Beech_Max_Support"
    },
    {
      "x": -18,
      "y": 56,
      "z": -18,
      "name": "Plant_Leaves_Beech_Max_Support"
    },
    {
      "x": -18,
      "y": 57,
      "z": -18,
      "name": "Plant_Leaves_Beech_Max_Support"
    },
    {
      "x": -18,
      "y": 58,
      "z": -18,
      "name": "Plant_Leaves_Beech_Max_Support"
    },
    {
      "x": -18,
      "y": 59,
      "z": -18,
      "name": "Plant_Leaves_Beech_Max_Support"
    },
    {
      "x": -18,
      "y": 60,
      "z": -18,
      "name": "Plant_Leaves_Beech_Max_Support"
    },
    {
      "x": -18,
      "y": 55,
      "z": -17,
      "name": "Plant_Leaves_Beech_Max_Support"
    },
    {
      "x": -18,
      "y": 56,
      "z": -17,
      "name": "Plant_Leaves_Beech_Max_Support"
    },
    {
      "x": -18,
      "y": 57,
      "z": -17,
      "name": "Plant_Leaves_Beech_Max_Support"
    },
    {
      "x": -18,
      "y": 58,
      "z": -17,
      "name": "Plant_Leaves_Beech_Max_Support"
    },
    {
      "x": -18,
      "y": 59,
      "z": -17,
      "name": "Plant_Leaves_Beech_Max_Support"
    },
    {
      "x": -18,
      "y": 60,
      "z": -17,
      "name": "Plant_Leaves_Beech_Max_Support"
    },
    {
      "x": -18,
      "y": 61,
      "z": -17,
      "name": "Plant_Leaves_Beech_Max_Support"
    },
    {
      "x": -18,
      "y": 55,
      "z": -16,
      "name": "Wood_Gumboab_Trunk_Full"
    },
    {
      "x": -18,
      "y": 56,
      "z": -16,
      "name": "Plant_Leaves_Beech_Max_Support"
    },
    {
      "x": -18,
      "y": 57,
      "z": -16,
      "name": "Wood_Gumboab_Trunk_Full"
    },
    {
      "x": -18,
      "y": 58,
      "z": -16,
      "name": "Plant_Leaves_Beech_Max_Support"
    },
    {
      "x": -18,
      "y": 59,
      "z": -16,
      "name": "Plant_Leaves_Beech_Max_Support"
    },
    {
      "x": -18,
      "y": 60,
      "z": -16,
      "name": "Plant_Leaves_Beech_Max_Support"
    },
    {
      "x": -18,
      "y": 61,
      "z": -16,
      "name": "Plant_Leaves_Beech_Max_Support"
    },
    {
      "x": -18,
      "y": 63,
      "z": -16,
      "name": "Plant_Leaves_Beech_Max_Support"
    },
    {
      "x": -18,
      "y": 55,
      "z": -15,
      "name": "Wood_Gumboab_Trunk_Full"
    },
    {
      "x": -18,
      "y": 56,
      "z": -15,
      "name": "Wood_Gumboab_Trunk_Full"
    },
    {
      "x": -18,
      "y": 57,
      "z": -15,
      "name": "Plant_Leaves_Beech_Max_Support"
    },
    {
      "x": -18,
      "y": 58,
      "z": -15,
      "name": "Plant_Leaves_Beech_Max_Support"
    },
    {
      "x": -18,
      "y": 59,
      "z": -15,
      "name": "Plant_Leaves_Beech_Max_Support"
    },
    {
      "x": -18,
      "y": 60,
      "z": -15,
      "name": "Plant_Leaves_Beech_Max_Support"
    },
    {
      "x": -18,
      "y": 56,
      "z": -14,
      "name": "Plant_Leaves_Beech_Max_Support"
    },
    {
      "x": -18,
      "y": 57,
      "z": -14,
      "name": "Plant_Leaves_Beech_Max_Support"
    },
    {
      "x": -18,
      "y": 58,
      "z": -14,
      "name": "Plant_Leaves_Beech_Max_Support"
    },
    {
      "x": -18,
      "y": 59,
      "z": -14,
      "name": "Plant_Leaves_Beech_Max_Support"
    },
    {
      "x": -18,
      "y": 60,
      "z": -14,
      "name": "Plant_Leaves_Beech_Max_Support"
    },
    {
      "x": -18,
      "y": 61,
      "z": -14,
      "name": "Plant_Leaves_Beech_Max_Support"
    },
    {
      "x": -18,
      "y": 62,
      "z": -14,
      "name": "Plant_Leaves_Beech_Max_Support"
    },
    {
      "x": -18,
      "y": 63,
      "z": -14,
      "name": "Plant_Leaves_Beech_Max_Support"
    },
    {
      "x": -18,
      "y": 55,
      "z": -13,
      "name": "Plant_Leaves_Beech_Max_Support"
    },
    {
      "x": -18,
      "y": 57,
      "z": -13,
      "name": "Plant_Leaves_Beech_Max_Support"
    },
    {
      "x": -18,
      "y": 58,
      "z": -13,
      "name": "Plant_Leaves_Beech_Max_Support"
    },
    {
      "x": -18,
      "y": 59,
      "z": -13,
      "name": "Plant_Leaves_Beech_Max_Support"
    },
    {
      "x": -18,
      "y": 60,
      "z": -13,
      "name": "Plant_Leaves_Beech_Max_Support"
    },
    {
      "x": -18,
      "y": 61,
      "z": -13,
      "name": "Plant_Leaves_Beech_Max_Support"
    },
    {
      "x": -18,
      "y": 62,
      "z": -13,
      "name": "Plant_Leaves_Beech_Max_Support"
    },
    {
      "x": -18,
      "y": 63,
      "z": -13,
      "name": "Plant_Leaves_Beech_Max_Support"
    },
    {
      "x": -18,
      "y": 56,
      "z": -12,
      "name": "Plant_Leaves_Beech_Max_Support"
    },
    {
      "x": -18,
      "y": 57,
      "z": -12,
      "name": "Plant_Leaves_Beech_Max_Support"
    },
    {
      "x": -18,
      "y": 58,
      "z": -12,
      "name": "Plant_Leaves_Beech_Max_Support"
    },
    {
      "x": -18,
      "y": 59,
      "z": -12,
      "name": "Plant_Leaves_Beech_Max_Support"
    },
    {
      "x": -18,
      "y": 60,
      "z": -12,
      "name": "Plant_Leaves_Beech_Max_Support"
    },
    {
      "x": -18,
      "y": 61,
      "z": -12,
      "name": "Plant_Leaves_Beech_Max_Support"
    },
    {
      "x": -18,
      "y": 62,
      "z": -12,
      "name": "Plant_Leaves_Beech_Max_Support"
    },
    {
      "x": -18,
      "y": 55,
      "z": -11,
      "name": "Plant_Leaves_Beech_Max_Support"
    },
    {
      "x": -18,
      "y": 57,
      "z": -11,
      "name": "Plant_Leaves_Beech_Max_Support"
    },
    {
      "x": -18,
      "y": 58,
      "z": -11,
      "name": "Plant_Leaves_Beech_Max_Support"
    },
    {
      "x": -18,
      "y": 59,
      "z": -11,
      "name": "Plant_Leaves_Beech_Max_Support"
    },
    {
      "x": -18,
      "y": 60,
      "z": -11,
      "name": "Plant_Leaves_Beech_Max_Support"
    },
    {
      "x": -18,
      "y": 61,
      "z": -11,
      "name": "Plant_Leaves_Beech_Max_Support"
    },
    {
      "x": -18,
      "y": 62,
      "z": -11,
      "name": "Plant_Leaves_Beech_Max_Support"
    },
    {
      "x": -18,
      "y": 53,
      "z": -10,
      "name": "Plant_Leaves_Beech_Max_Support"
    },
    {
      "x": -18,
      "y": 54,
      "z": -10,
      "name": "Plant_Leaves_Beech_Max_Support"
    },
    {
      "x": -18,
      "y": 55,
      "z": -10,
      "name": "Plant_Leaves_Beech_Max_Support"
    },
    {
      "x": -18,
      "y": 56,
      "z": -10,
      "name": "Plant_Leaves_Beech_Max_Support"
    },
    {
      "x": -18,
      "y": 57,
      "z": -10,
      "name": "Plant_Leaves_Beech_Max_Support"
    },
    {
      "x": -18,
      "y": 58,
      "z": -10,
      "name": "Plant_Leaves_Beech_Max_Support"
    },
    {
      "x": -18,
      "y": 60,
      "z": -10,
      "name": "Plant_Leaves_Beech_Max_Support"
    },
    {
      "x": -18,
      "y": 62,
      "z": -10,
      "name": "Plant_Leaves_Beech_Max_Support"
    },
    {
      "x": -18,
      "y": 56,
      "z": -9,
      "name": "Plant_Leaves_Beech_Max_Support"
    },
    {
      "x": -18,
      "y": 57,
      "z": -9,
      "name": "Plant_Leaves_Beech_Max_Support"
    },
    {
      "x": -18,
      "y": 58,
      "z": -9,
      "name": "Plant_Leaves_Beech_Max_Support"
    },
    {
      "x": -18,
      "y": 59,
      "z": -9,
      "name": "Plant_Leaves_Beech_Max_Support"
    },
    {
      "x": -18,
      "y": 60,
      "z": -9,
      "name": "Plant_Leaves_Beech_Max_Support"
    },
    {
      "x": -18,
      "y": 62,
      "z": -9,
      "name": "Plant_Leaves_Beech_Max_Support"
    },
    {
      "x": -18,
      "y": 56,
      "z": -8,
      "name": "Plant_Leaves_Beech_Max_Support"
    },
    {
      "x": -18,
      "y": 57,
      "z": -8,
      "name": "Plant_Leaves_Beech_Max_Support"
    },
    {
      "x": -18,
      "y": 58,
      "z": -8,
      "name": "Plant_Leaves_Beech_Max_Support"
    },
    {
      "x": -18,
      "y": 60,
      "z": -8,
      "name": "Plant_Leaves_Beech_Max_Support"
    },
    {
      "x": -18,
      "y": 61,
      "z": -8,
      "name": "Plant_Leaves_Beech_Max_Support"
    },
    {
      "x": -18,
      "y": 58,
      "z": -7,
      "name": "Plant_Leaves_Beech_Max_Support"
    },
    {
      "x": -18,
      "y": 59,
      "z": -7,
      "name": "Plant_Leaves_Beech_Max_Support"
    },
    {
      "x": -18,
      "y": 60,
      "z": -7,
      "name": "Plant_Leaves_Beech_Max_Support"
    },
    {
      "x": -18,
      "y": 55,
      "z": 1,
      "name": "Plant_Leaves_Beech_Max_Support"
    },
    {
      "x": -18,
      "y": 56,
      "z": 1,
      "name": "Plant_Leaves_Beech_Max_Support"
    },
    {
      "x": -18,
      "y": 59,
      "z": 1,
      "name": "Plant_Leaves_Beech_Max_Support"
    },
    {
      "x": -18,
      "y": 55,
      "z": 2,
      "name": "Plant_Leaves_Beech_Max_Support"
    },
    {
      "x": -18,
      "y": 56,
      "z": 2,
      "name": "Plant_Leaves_Beech_Max_Support"
    },
    {
      "x": -18,
      "y": 57,
      "z": 2,
      "name": "Plant_Leaves_Beech_Max_Support"
    },
    {
      "x": -18,
      "y": 59,
      "z": 2,
      "name": "Plant_Leaves_Beech_Max_Support"
    },
    {
      "x": -18,
      "y": 60,
      "z": 2,
      "name": "Plant_Leaves_Beech_Max_Support"
    },
    {
      "x": -18,
      "y": 56,
      "z": 3,
      "name": "Plant_Leaves_Beech_Max_Support"
    },
    {
      "x": -18,
      "y": 57,
      "z": 3,
      "name": "Plant_Leaves_Beech_Max_Support"
    },
    {
      "x": -18,
      "y": 58,
      "z": 3,
      "name": "Plant_Leaves_Beech_Max_Support"
    },
    {
      "x": -18,
      "y": 60,
      "z": 3,
      "name": "Plant_Leaves_Beech_Max_Support"
    },
    {
      "x": -18,
      "y": 61,
      "z": 3,
      "name": "Plant_Leaves_Beech_Max_Support"
    },
    {
      "x": -18,
      "y": 54,
      "z": 4,
      "name": "Plant_Leaves_Beech_Max_Support"
    },
    {
      "x": -18,
      "y": 55,
      "z": 4,
      "name": "Plant_Leaves_Beech_Max_Support"
    },
    {
      "x": -18,
      "y": 56,
      "z": 4,
      "name": "Plant_Leaves_Beech_Max_Support"
    },
    {
      "x": -18,
      "y": 57,
      "z": 4,
      "name": "Plant_Leaves_Beech_Max_Support"
    },
    {
      "x": -18,
      "y": 58,
      "z": 4,
      "name": "Plant_Leaves_Beech_Max_Support"
    },
    {
      "x": -18,
      "y": 59,
      "z": 4,
      "name": "Plant_Leaves_Beech_Max_Support"
    },
    {
      "x": -18,
      "y": 60,
      "z": 4,
      "name": "Plant_Leaves_Beech_Max_Support"
    },
    {
      "x": -18,
      "y": 61,
      "z": 4,
      "name": "Plant_Leaves_Beech_Max_Support"
    },
    {
      "x": -18,
      "y": 53,
      "z": 5,
      "name": "Plant_Leaves_Beech_Max_Support"
    },
    {
      "x": -18,
      "y": 54,
      "z": 5,
      "name": "Plant_Leaves_Beech_Max_Support"
    },
    {
      "x": -18,
      "y": 55,
      "z": 5,
      "name": "Plant_Leaves_Beech_Max_Support"
    },
    {
      "x": -18,
      "y": 56,
      "z": 5,
      "name": "Plant_Leaves_Beech_Max_Support"
    },
    {
      "x": -18,
      "y": 57,
      "z": 5,
      "name": "Plant_Leaves_Beech_Max_Support"
    },
    {
      "x": -18,
      "y": 58,
      "z": 5,
      "name": "Plant_Leaves_Beech_Max_Support"
    },
    {
      "x": -18,
      "y": 60,
      "z": 5,
      "name": "Plant_Leaves_Beech_Max_Support"
    },
    {
      "x": -18,
      "y": 54,
      "z": 6,
      "name": "Plant_Leaves_Beech_Max_Support"
    },
    {
      "x": -18,
      "y": 55,
      "z": 6,
      "name": "Plant_Leaves_Beech_Max_Support"
    },
    {
      "x": -18,
      "y": 56,
      "z": 6,
      "name": "Plant_Leaves_Beech_Max_Support"
    },
    {
      "x": -18,
      "y": 57,
      "z": 6,
      "name": "Plant_Leaves_Beech_Max_Support"
    },
    {
      "x": -18,
      "y": 58,
      "z": 6,
      "name": "Plant_Leaves_Beech_Max_Support"
    },
    {
      "x": -18,
      "y": 59,
      "z": 6,
      "name": "Plant_Leaves_Beech_Max_Support"
    },
    {
      "x": -18,
      "y": 60,
      "z": 6,
      "name": "Plant_Leaves_Beech_Max_Support"
    },
    {
      "x": -18,
      "y": 54,
      "z": 7,
      "name": "Plant_Leaves_Beech_Max_Support"
    },
    {
      "x": -18,
      "y": 55,
      "z": 7,
      "name": "Plant_Leaves_Beech_Max_Support"
    },
    {
      "x": -18,
      "y": 56,
      "z": 7,
      "name": "Plant_Leaves_Beech_Max_Support"
    },
    {
      "x": -18,
      "y": 57,
      "z": 7,
      "name": "Plant_Leaves_Beech_Max_Support"
    },
    {
      "x": -18,
      "y": 58,
      "z": 7,
      "name": "Plant_Leaves_Beech_Max_Support"
    },
    {
      "x": -18,
      "y": 59,
      "z": 7,
      "name": "Plant_Leaves_Beech_Max_Support"
    },
    {
      "x": -18,
      "y": 55,
      "z": 8,
      "name": "Plant_Leaves_Beech_Max_Support"
    },
    {
      "x": -18,
      "y": 57,
      "z": 8,
      "name": "Plant_Leaves_Beech_Max_Support"
    },
    {
      "x": -18,
      "y": 61,
      "z": 8,
      "name": "Plant_Leaves_Beech_Max_Support"
    },
    {
      "x": -18,
      "y": 62,
      "z": 8,
      "name": "Plant_Leaves_Beech_Max_Support"
    },
    {
      "x": -18,
      "y": 56,
      "z": 9,
      "name": "Plant_Leaves_Beech_Max_Support"
    },
    {
      "x": -18,
      "y": 57,
      "z": 9,
      "name": "Plant_Leaves_Beech_Max_Support"
    },
    {
      "x": -18,
      "y": 58,
      "z": 9,
      "name": "Plant_Leaves_Beech_Max_Support"
    },
    {
      "x": -18,
      "y": 60,
      "z": 9,
      "name": "Plant_Leaves_Beech_Max_Support"
    },
    {
      "x": -18,
      "y": 61,
      "z": 9,
      "name": "Plant_Leaves_Beech_Max_Support"
    },
    {
      "x": -18,
      "y": 62,
      "z": 9,
      "name": "Plant_Leaves_Beech_Max_Support"
    },
    {
      "x": -18,
      "y": 60,
      "z": 10,
      "name": "Plant_Leaves_Beech_Max_Support"
    },
    {
      "x": -18,
      "y": 62,
      "z": 10,
      "name": "Plant_Leaves_Beech_Max_Support"
    },
    {
      "x": -18,
      "y": 58,
      "z": 15,
      "name": "Plant_Leaves_Beech_Max_Support"
    },
    {
      "x": -18,
      "y": 59,
      "z": 15,
      "name": "Plant_Leaves_Beech_Max_Support"
    },
    {
      "x": -18,
      "y": 57,
      "z": 16,
      "name": "Plant_Leaves_Beech_Max_Support"
    },
    {
      "x": -18,
      "y": 59,
      "z": 16,
      "name": "Plant_Leaves_Beech_Max_Support"
    },
    {
      "x": -18,
      "y": 56,
      "z": 17,
      "name": "Plant_Leaves_Beech_Max_Support"
    },
    {
      "x": -18,
      "y": 58,
      "z": 17,
      "name": "Plant_Leaves_Beech_Max_Support"
    },
    {
      "x": -18,
      "y": 56,
      "z": 18,
      "name": "Plant_Leaves_Beech_Max_Support"
    },
    {
      "x": -18,
      "y": 57,
      "z": 18,
      "name": "Plant_Leaves_Beech_Max_Support"
    },
    {
      "x": -18,
      "y": 55,
      "z": 19,
      "name": "Plant_Leaves_Beech_Max_Support"
    },
    {
      "x": -18,
      "y": 56,
      "z": 19,
      "name": "Plant_Leaves_Beech_Max_Support"
    },
    {
      "x": -18,
      "y": 54,
      "z": 20,
      "name": "Plant_Leaves_Beech_Max_Support"
    },
    {
      "x": -18,
      "y": 55,
      "z": 20,
      "name": "Plant_Leaves_Beech_Max_Support"
    },
    {
      "x": -18,
      "y": 56,
      "z": 20,
      "name": "Plant_Leaves_Beech_Max_Support"
    },
    {
      "x": -18,
      "y": 53,
      "z": 21,
      "name": "Plant_Leaves_Beech_Max_Support"
    },
    {
      "x": -18,
      "y": 54,
      "z": 21,
      "name": "Plant_Leaves_Beech_Max_Support"
    },
    {
      "x": -18,
      "y": 57,
      "z": 21,
      "name": "Plant_Leaves_Beech_Max_Support"
    },
    {
      "x": -18,
      "y": 54,
      "z": 22,
      "name": "Plant_Leaves_Beech_Max_Support"
    },
    {
      "x": -18,
      "y": 55,
      "z": 22,
      "name": "Plant_Leaves_Beech_Max_Support"
    },
    {
      "x": -18,
      "y": 56,
      "z": 22,
      "name": "Plant_Leaves_Beech_Max_Support"
    },
    {
      "x": -18,
      "y": 58,
      "z": 22,
      "name": "Plant_Leaves_Beech_Max_Support"
    },
    {
      "x": -18,
      "y": 55,
      "z": 23,
      "name": "Plant_Leaves_Beech_Max_Support"
    },
    {
      "x": -18,
      "y": 56,
      "z": 23,
      "name": "Plant_Leaves_Beech_Max_Support"
    },
    {
      "x": -18,
      "y": 57,
      "z": 23,
      "name": "Plant_Leaves_Beech_Max_Support"
    },
    {
      "x": -18,
      "y": 58,
      "z": 23,
      "name": "Plant_Leaves_Beech_Max_Support"
    },
    {
      "x": -18,
      "y": 59,
      "z": 23,
      "name": "Plant_Leaves_Beech_Max_Support"
    },
    {
      "x": -18,
      "y": 60,
      "z": 23,
      "name": "Plant_Leaves_Beech_Max_Support"
    },
    {
      "x": -18,
      "y": 61,
      "z": 23,
      "name": "Plant_Leaves_Beech_Max_Support"
    },
    {
      "x": -18,
      "y": 62,
      "z": 23,
      "name": "Plant_Leaves_Beech_Max_Support"
    },
    {
      "x": -18,
      "y": 55,
      "z": 24,
      "name": "Plant_Leaves_Beech_Max_Support"
    },
    {
      "x": -18,
      "y": 56,
      "z": 24,
      "name": "Plant_Leaves_Beech_Max_Support"
    },
    {
      "x": -18,
      "y": 57,
      "z": 24,
      "name": "Plant_Leaves_Beech_Max_Support"
    },
    {
      "x": -18,
      "y": 58,
      "z": 24,
      "name": "Plant_Leaves_Beech_Max_Support"
    },
    {
      "x": -18,
      "y": 59,
      "z": 24,
      "name": "Plant_Leaves_Beech_Max_Support"
    },
    {
      "x": -18,
      "y": 60,
      "z": 24,
      "name": "Plant_Leaves_Beech_Max_Support"
    },
    {
      "x": -18,
      "y": 61,
      "z": 24,
      "name": "Plant_Leaves_Beech_Max_Support"
    },
    {
      "x": -18,
      "y": 62,
      "z": 24,
      "name": "Plant_Leaves_Beech_Max_Support"
    },
    {
      "x": -18,
      "y": 63,
      "z": 24,
      "name": "Plant_Leaves_Beech_Max_Support"
    },
    {
      "x": -18,
      "y": 55,
      "z": 25,
      "name": "Plant_Leaves_Beech_Max_Support"
    },
    {
      "x": -18,
      "y": 56,
      "z": 25,
      "name": "Plant_Leaves_Beech_Max_Support"
    },
    {
      "x": -18,
      "y": 58,
      "z": 25,
      "name": "Plant_Leaves_Beech_Max_Support"
    },
    {
      "x": -18,
      "y": 59,
      "z": 25,
      "name": "Plant_Leaves_Beech_Max_Support"
    },
    {
      "x": -18,
      "y": 60,
      "z": 25,
      "name": "Plant_Leaves_Beech_Max_Support"
    },
    {
      "x": -18,
      "y": 61,
      "z": 25,
      "name": "Plant_Leaves_Beech_Max_Support"
    },
    {
      "x": -18,
      "y": 64,
      "z": 25,
      "name": "Plant_Leaves_Beech_Max_Support"
    },
    {
      "x": -18,
      "y": 56,
      "z": 26,
      "name": "Plant_Leaves_Beech_Max_Support"
    },
    {
      "x": -18,
      "y": 57,
      "z": 26,
      "name": "Plant_Leaves_Beech_Max_Support"
    },
    {
      "x": -18,
      "y": 58,
      "z": 26,
      "name": "Plant_Leaves_Beech_Max_Support"
    },
    {
      "x": -18,
      "y": 59,
      "z": 26,
      "name": "Plant_Leaves_Beech_Max_Support"
    },
    {
      "x": -18,
      "y": 60,
      "z": 26,
      "name": "Plant_Leaves_Beech_Max_Support"
    },
    {
      "x": -18,
      "y": 61,
      "z": 26,
      "name": "Plant_Leaves_Beech_Max_Support"
    },
    {
      "x": -18,
      "y": 62,
      "z": 26,
      "name": "Plant_Leaves_Beech_Max_Support"
    },
    {
      "x": -18,
      "y": 64,
      "z": 26,
      "name": "Plant_Leaves_Beech_Max_Support"
    },
    {
      "x": -18,
      "y": 57,
      "z": 27,
      "name": "Plant_Leaves_Beech_Max_Support"
    },
    {
      "x": -18,
      "y": 58,
      "z": 27,
      "name": "Plant_Leaves_Beech_Max_Support"
    },
    {
      "x": -18,
      "y": 59,
      "z": 27,
      "name": "Plant_Leaves_Beech_Max_Support"
    },
    {
      "x": -18,
      "y": 60,
      "z": 27,
      "name": "Plant_Leaves_Beech_Max_Support"
    },
    {
      "x": -18,
      "y": 61,
      "z": 27,
      "name": "Plant_Leaves_Beech_Max_Support"
    },
    {
      "x": -18,
      "y": 62,
      "z": 27,
      "name": "Plant_Leaves_Beech_Max_Support"
    },
    {
      "x": -18,
      "y": 63,
      "z": 27,
      "name": "Plant_Leaves_Beech_Max_Support"
    },
    {
      "x": -18,
      "y": 64,
      "z": 27,
      "name": "Plant_Leaves_Beech_Max_Support"
    },
    {
      "x": -18,
      "y": 55,
      "z": 28,
      "name": "Plant_Leaves_Beech_Max_Support"
    },
    {
      "x": -18,
      "y": 56,
      "z": 28,
      "name": "Plant_Leaves_Beech_Max_Support"
    },
    {
      "x": -18,
      "y": 57,
      "z": 28,
      "name": "Plant_Leaves_Beech_Max_Support"
    },
    {
      "x": -18,
      "y": 58,
      "z": 28,
      "name": "Plant_Leaves_Beech_Max_Support"
    },
    {
      "x": -18,
      "y": 59,
      "z": 28,
      "name": "Plant_Leaves_Beech_Max_Support"
    },
    {
      "x": -18,
      "y": 61,
      "z": 28,
      "name": "Plant_Leaves_Beech_Max_Support"
    },
    {
      "x": -18,
      "y": 63,
      "z": 28,
      "name": "Plant_Leaves_Beech_Max_Support"
    },
    {
      "x": -18,
      "y": 55,
      "z": 29,
      "name": "Wood_Gumboab_Trunk_Full"
    },
    {
      "x": -18,
      "y": 56,
      "z": 29,
      "name": "Wood_Gumboab_Trunk_Full"
    },
    {
      "x": -18,
      "y": 57,
      "z": 29,
      "name": "Plant_Leaves_Beech_Max_Support"
    },
    {
      "x": -18,
      "y": 58,
      "z": 29,
      "name": "Plant_Leaves_Beech_Max_Support"
    },
    {
      "x": -18,
      "y": 59,
      "z": 29,
      "name": "Plant_Leaves_Beech_Max_Support"
    },
    {
      "x": -18,
      "y": 60,
      "z": 29,
      "name": "Plant_Leaves_Beech_Max_Support"
    },
    {
      "x": -18,
      "y": 61,
      "z": 29,
      "name": "Plant_Leaves_Beech_Max_Support"
    },
    {
      "x": -18,
      "y": 55,
      "z": 30,
      "name": "Wood_Gumboab_Trunk_Full"
    },
    {
      "x": -18,
      "y": 56,
      "z": 30,
      "name": "Wood_Gumboab_Trunk_Full"
    },
    {
      "x": -18,
      "y": 57,
      "z": 30,
      "name": "Plant_Leaves_Beech_Max_Support"
    },
    {
      "x": -18,
      "y": 58,
      "z": 30,
      "name": "Plant_Leaves_Beech_Max_Support"
    },
    {
      "x": -18,
      "y": 60,
      "z": 30,
      "name": "Plant_Leaves_Beech_Max_Support"
    },
    {
      "x": -18,
      "y": 61,
      "z": 30,
      "name": "Plant_Leaves_Beech_Max_Support"
    },
    {
      "x": -18,
      "y": 55,
      "z": 31,
      "name": "Plant_Leaves_Beech_Max_Support"
    },
    {
      "x": -18,
      "y": 56,
      "z": 31,
      "name": "Plant_Leaves_Beech_Max_Support"
    },
    {
      "x": -18,
      "y": 57,
      "z": 31,
      "name": "Plant_Leaves_Beech_Max_Support"
    },
    {
      "x": -18,
      "y": 58,
      "z": 31,
      "name": "Plant_Leaves_Beech_Max_Support"
    },
    {
      "x": -18,
      "y": 59,
      "z": 31,
      "name": "Plant_Leaves_Beech_Max_Support"
    },
    {
      "x": -18,
      "y": 60,
      "z": 31,
      "name": "Plant_Leaves_Beech_Max_Support"
    },
    {
      "x": -18,
      "y": 61,
      "z": 31,
      "name": "Plant_Leaves_Beech_Max_Support"
    },
    {
      "x": -18,
      "y": 54,
      "z": 32,
      "name": "Plant_Leaves_Beech_Max_Support"
    },
    {
      "x": -18,
      "y": 55,
      "z": 32,
      "name": "Plant_Leaves_Beech_Max_Support"
    },
    {
      "x": -18,
      "y": 56,
      "z": 32,
      "name": "Plant_Leaves_Beech_Max_Support"
    },
    {
      "x": -18,
      "y": 57,
      "z": 32,
      "name": "Plant_Leaves_Beech_Max_Support"
    },
    {
      "x": -18,
      "y": 58,
      "z": 32,
      "name": "Plant_Leaves_Beech_Max_Support"
    },
    {
      "x": -18,
      "y": 60,
      "z": 32,
      "name": "Plant_Leaves_Beech_Max_Support"
    },
    {
      "x": -18,
      "y": 61,
      "z": 32,
      "name": "Plant_Leaves_Beech_Max_Support"
    },
    {
      "x": -18,
      "y": 53,
      "z": 33,
      "name": "Plant_Leaves_Beech_Max_Support"
    },
    {
      "x": -18,
      "y": 54,
      "z": 33,
      "name": "Plant_Leaves_Beech_Max_Support"
    },
    {
      "x": -18,
      "y": 56,
      "z": 33,
      "name": "Plant_Leaves_Beech_Max_Support"
    },
    {
      "x": -18,
      "y": 58,
      "z": 33,
      "name": "Plant_Leaves_Beech_Max_Support"
    },
    {
      "x": -18,
      "y": 59,
      "z": 33,
      "name": "Plant_Leaves_Beech_Max_Support"
    },
    {
      "x": -18,
      "y": 60,
      "z": 33,
      "name": "Plant_Leaves_Beech_Max_Support"
    },
    {
      "x": -18,
      "y": 54,
      "z": 34,
      "name": "Plant_Leaves_Beech_Max_Support"
    },
    {
      "x": -18,
      "y": 55,
      "z": 34,
      "name": "Plant_Leaves_Beech_Max_Support"
    },
    {
      "x": -18,
      "y": 56,
      "z": 34,
      "name": "Plant_Leaves_Beech_Max_Support"
    },
    {
      "x": -18,
      "y": 55,
      "z": 35,
      "name": "Plant_Leaves_Beech_Max_Support"
    },
    {
      "x": -17,
      "y": 51,
      "z": -24,
      "name": "Plant_Leaves_Beech_Max_Support"
    },
    {
      "x": -17,
      "y": 51,
      "z": -23,
      "name": "Plant_Leaves_Beech_Max_Support"
    },
    {
      "x": -17,
      "y": 49,
      "z": -22,
      "name": "Plant_Leaves_Beech_Max_Support"
    },
    {
      "x": -17,
      "y": 50,
      "z": -22,
      "name": "Plant_Leaves_Beech_Max_Support"
    },
    {
      "x": -17,
      "y": 51,
      "z": -22,
      "name": "Plant_Leaves_Beech_Max_Support"
    },
    {
      "x": -17,
      "y": 52,
      "z": -22,
      "name": "Plant_Leaves_Beech_Max_Support"
    },
    {
      "x": -17,
      "y": 53,
      "z": -22,
      "name": "Plant_Leaves_Beech_Max_Support"
    },
    {
      "x": -17,
      "y": 50,
      "z": -21,
      "name": "Plant_Leaves_Beech_Max_Support"
    },
    {
      "x": -17,
      "y": 51,
      "z": -21,
      "name": "Plant_Leaves_Beech_Max_Support"
    },
    {
      "x": -17,
      "y": 57,
      "z": -21,
      "name": "Plant_Leaves_Beech_Max_Support"
    },
    {
      "x": -17,
      "y": 56,
      "z": -20,
      "name": "Plant_Leaves_Beech_Max_Support"
    },
    {
      "x": -17,
      "y": 57,
      "z": -20,
      "name": "Plant_Leaves_Beech_Max_Support"
    },
    {
      "x": -17,
      "y": 58,
      "z": -20,
      "name": "Plant_Leaves_Beech_Max_Support"
    },
    {
      "x": -17,
      "y": 55,
      "z": -19,
      "name": "Plant_Leaves_Beech_Max_Support"
    },
    {
      "x": -17,
      "y": 56,
      "z": -19,
      "name": "Plant_Leaves_Beech_Max_Support"
    },
    {
      "x": -17,
      "y": 57,
      "z": -19,
      "name": "Plant_Leaves_Beech_Max_Support"
    },
    {
      "x": -17,
      "y": 58,
      "z": -19,
      "name": "Plant_Leaves_Beech_Max_Support"
    },
    {
      "x": -17,
      "y": 59,
      "z": -19,
      "name": "Plant_Leaves_Beech_Max_Support"
    },
    {
      "x": -17,
      "y": 55,
      "z": -18,
      "name": "Plant_Leaves_Beech_Max_Support"
    },
    {
      "x": -17,
      "y": 56,
      "z": -18,
      "name": "Plant_Leaves_Beech_Max_Support"
    },
    {
      "x": -17,
      "y": 57,
      "z": -18,
      "name": "Plant_Leaves_Beech_Max_Support"
    },
    {
      "x": -17,
      "y": 58,
      "z": -18,
      "name": "Plant_Leaves_Beech_Max_Support"
    },
    {
      "x": -17,
      "y": 61,
      "z": -18,
      "name": "Plant_Leaves_Beech_Max_Support"
    },
    {
      "x": -17,
      "y": 55,
      "z": -17,
      "name": "Plant_Leaves_Beech_Max_Support"
    },
    {
      "x": -17,
      "y": 56,
      "z": -17,
      "name": "Plant_Leaves_Beech_Max_Support"
    },
    {
      "x": -17,
      "y": 57,
      "z": -17,
      "name": "Plant_Leaves_Beech_Max_Support"
    },
    {
      "x": -17,
      "y": 58,
      "z": -17,
      "name": "Plant_Leaves_Beech_Max_Support"
    },
    {
      "x": -17,
      "y": 59,
      "z": -17,
      "name": "Plant_Leaves_Beech_Max_Support"
    },
    {
      "x": -17,
      "y": 60,
      "z": -17,
      "name": "Plant_Leaves_Beech_Max_Support"
    },
    {
      "x": -17,
      "y": 61,
      "z": -17,
      "name": "Plant_Leaves_Beech_Max_Support"
    },
    {
      "x": -17,
      "y": 55,
      "z": -16,
      "name": "Plant_Leaves_Beech_Max_Support"
    },
    {
      "x": -17,
      "y": 56,
      "z": -16,
      "name": "Plant_Leaves_Beech_Max_Support"
    },
    {
      "x": -17,
      "y": 57,
      "z": -16,
      "name": "Plant_Leaves_Beech_Max_Support"
    },
    {
      "x": -17,
      "y": 58,
      "z": -16,
      "name": "Plant_Leaves_Beech_Max_Support"
    },
    {
      "x": -17,
      "y": 59,
      "z": -16,
      "name": "Plant_Leaves_Beech_Max_Support"
    },
    {
      "x": -17,
      "y": 60,
      "z": -16,
      "name": "Plant_Leaves_Beech_Max_Support"
    },
    {
      "x": -17,
      "y": 61,
      "z": -16,
      "name": "Plant_Leaves_Beech_Max_Support"
    },
    {
      "x": -17,
      "y": 55,
      "z": -15,
      "name": "Wood_Gumboab_Trunk_Full"
    },
    {
      "x": -17,
      "y": 56,
      "z": -15,
      "name": "Plant_Leaves_Beech_Max_Support"
    },
    {
