{
  "version": 8,
  "blockIdVersion": 11,
  "anchorX": 0,
  "anchorY": 7,
  "anchorZ": -1,
  "blocks": [
    {
      "x": -11,
      "y": 43,
      "z": -2,
      "name": "Plant_Leaves_Bamboo"
    },
    {
      "x": -11,
      "y": 43,
      "z": -1,
      "name": "Plant_Leaves_Bamboo"
    },
    {
      "x": -11,
      "y": 43,
      "z": 0,
      "name": "Plant_Leaves_Bamboo"
    },
    {
      "x": -10,
      "y": 42,
      "z": -4,
      "name": "Plant_Leaves_Bamboo"
    },
    {
      "x": -10,
      "y": 42,
      "z": -3,
      "name": "Plant_Leaves_Bamboo"
    },
    {
      "x": -10,
      "y": 43,
      "z": -3,
      "name": "Plant_Leaves_Bamboo"
    },
    {
      "x": -10,
      "y": 42,
      "z": -2,
      "name": "Plant_Leaves_Bamboo"
    },
    {
      "x": -10,
      "y": 43,
      "z": -2,
      "name": "Plant_Leaves_Bamboo"
    },
    {
      "x": -10,
      "y": 43,
      "z": -1,
      "name": "Plant_Leaves_Bamboo"
    },
    {
      "x": -10,
      "y": 44,
      "z": -1,
      "name": "Plant_Leaves_Bamboo"
    },
    {
      "x": -10,
      "y": 43,
      "z": 0,
      "name": "Plant_Leaves_Bamboo"
    },
    {
      "x": -10,
      "y": 44,
      "z": 0,
      "name": "Plant_Leaves_Bamboo"
    },
    {
      "x": -10,
      "y": 43,
      "z": 1,
      "name": "Plant_Leaves_Bamboo"
    },
    {
      "x": -10,
      "y": 44,
      "z": 1,
      "name": "Plant_Leaves_Bamboo"
    },
    {
      "x": -10,
      "y": 44,
      "z": 2,
      "name": "Plant_Leaves_Bamboo"
    },
    {
      "x": -10,
      "y": 44,
      "z": 3,
      "name": "Plant_Leaves_Bamboo"
    },
    {
      "x": -10,
      "y": 44,
      "z": 4,
      "name": "Plant_Leaves_Bamboo"
    },
    {
      "x": -9,
      "y": 39,
      "z": -6,
      "name": "Plant_Leaves_Bamboo"
    },
    {
      "x": -9,
      "y": 39,
      "z": -5,
      "name": "Plant_Leaves_Bamboo"
    },
    {
      "x": -9,
      "y": 42,
      "z": -5,
      "name": "Plant_Leaves_Bamboo"
    },
    {
      "x": -9,
      "y": 39,
      "z": -4,
      "name": "Plant_Leaves_Bamboo"
    },
    {
      "x": -9,
      "y": 42,
      "z": -4,
      "name": "Plant_Leaves_Bamboo"
    },
    {
      "x": -9,
      "y": 42,
      "z": -3,
      "name": "Plant_Leaves_Bamboo"
    },
    {
      "x": -9,
      "y": 43,
      "z": -3,
      "name": "Plant_Leaves_Bamboo"
    },
    {
      "x": -9,
      "y": 42,
      "z": -2,
      "name": "Plant_Leaves_Bamboo"
    },
    {
      "x": -9,
      "y": 43,
      "z": -2,
      "name": "Plant_Leaves_Bamboo"
    },
    {
      "x": -9,
      "y": 44,
      "z": -2,
      "name": "Plant_Leaves_Bamboo"
    },
    {
      "x": -9,
      "y": 41,
      "z": -1,
      "name": "Wood_Prehistoric_Branch_Corner",
      "rotation": 3
    },
    {
      "x": -9,
      "y": 42,
      "z": -1,
      "name": "Wood_Prehistoric_Branch_Long"
    },
    {
      "x": -9,
      "y": 43,
      "z": -1,
      "name": "Wood_Prehistoric_Branch_Long"
    },
    {
      "x": -9,
      "y": 44,
      "z": -1,
      "name": "Plant_Leaves_Bamboo"
    },
    {
      "x": -9,
      "y": 45,
      "z": -1,
      "name": "Plant_Leaves_Bamboo"
    },
    {
      "x": -9,
      "y": 43,
      "z": 0,
      "name": "Plant_Leaves_Bamboo"
    },
    {
      "x": -9,
      "y": 44,
      "z": 0,
      "name": "Plant_Leaves_Bamboo"
    },
    {
      "x": -9,
      "y": 43,
      "z": 1,
      "name": "Plant_Leaves_Bamboo"
    },
    {
      "x": -9,
      "y": 44,
      "z": 1,
      "name": "Plant_Leaves_Bamboo"
    },
    {
      "x": -9,
      "y": 44,
      "z": 2,
      "name": "Plant_Leaves_Bamboo"
    },
    {
      "x": -9,
      "y": 44,
      "z": 3,
      "name": "Plant_Leaves_Bamboo"
    },
    {
      "x": -9,
      "y": 45,
      "z": 3,
      "name": "Plant_Leaves_Bamboo"
    },
    {
      "x": -9,
      "y": 42,
      "z": 4,
      "name": "Plant_Leaves_Bamboo"
    },
    {
      "x": -9,
      "y": 44,
      "z": 4,
      "name": "Plant_Leaves_Bamboo"
    },
    {
      "x": -9,
      "y": 42,
      "z": 5,
      "name": "Plant_Leaves_Bamboo"
    },
    {
      "x": -9,
      "y": 44,
      "z": 5,
      "name": "Plant_Leaves_Bamboo"
    },
    {
      "x": -9,
      "y": 42,
      "z": 6,
      "name": "Plant_Leaves_Bamboo"
    },
    {
      "x": -8,
      "y": 39,
      "z": -7,
      "name": "Plant_Leaves_Bamboo"
    },
    {
      "x": -8,
      "y": 39,
      "z": -6,
      "name": "Plant_Leaves_Bamboo"
    },
    {
      "x": -8,
      "y": 42,
      "z": -6,
      "name": "Plant_Leaves_Bamboo"
    },
    {
      "x": -8,
      "y": 39,
      "z": -5,
      "name": "Plant_Leaves_Bamboo"
    },
    {
      "x": -8,
      "y": 40,
      "z": -5,
      "name": "Plant_Leaves_Bamboo"
    },
    {
      "x": -8,
      "y": 42,
      "z": -5,
      "name": "Plant_Leaves_Bamboo"
    },
    {
      "x": -8,
      "y": 39,
      "z": -4,
      "name": "Plant_Leaves_Bamboo"
    },
    {
      "x": -8,
      "y": 42,
      "z": -4,
      "name": "Plant_Leaves_Bamboo"
    },
    {
      "x": -8,
      "y": 43,
      "z": -4,
      "name": "Plant_Leaves_Bamboo"
    },
    {
      "x": -8,
      "y": 39,
      "z": -3,
      "name": "Plant_Leaves_Bamboo"
    },
    {
      "x": -8,
      "y": 42,
      "z": -3,
      "name": "Plant_Leaves_Bamboo"
    },
    {
      "x": -8,
      "y": 43,
      "z": -3,
      "name": "Plant_Leaves_Bamboo"
    },
    {
      "x": -8,
      "y": 42,
      "z": -2,
      "name": "Plant_Leaves_Bamboo"
    },
    {
      "x": -8,
      "y": 43,
      "z": -2,
      "name": "Plant_Leaves_Bamboo"
    },
    {
      "x": -8,
      "y": 44,
      "z": -2,
      "name": "Plant_Leaves_Bamboo"
    },
    {
      "x": -8,
      "y": 41,
      "z": -1,
      "name": "Wood_Prehistoric_Branch_Long",
      "rotation": 5
    },
    {
      "x": -8,
      "y": 43,
      "z": -1,
      "name": "Plant_Leaves_Bamboo"
    },
    {
      "x": -8,
      "y": 44,
      "z": -1,
      "name": "Plant_Leaves_Bamboo"
    },
    {
      "x": -8,
      "y": 42,
      "z": 0,
      "name": "Plant_Leaves_Bamboo"
    },
    {
      "x": -8,
      "y": 43,
      "z": 0,
      "name": "Plant_Leaves_Bamboo"
    },
    {
      "x": -8,
      "y": 44,
      "z": 0,
      "name": "Plant_Leaves_Bamboo"
    },
    {
      "x": -8,
      "y": 45,
      "z": 0,
      "name": "Plant_Leaves_Bamboo"
    },
    {
      "x": -8,
      "y": 41,
      "z": 1,
      "name": "Wood_Prehistoric_Branch_Corner",
      "rotation": 2
    },
    {
      "x": -8,
      "y": 42,
      "z": 1,
      "name": "Wood_Prehistoric_Branch_Corner",
      "rotation": 9
    },
    {
      "x": -8,
      "y": 43,
      "z": 1,
      "name": "Plant_Leaves_Bamboo"
    },
    {
      "x": -8,
      "y": 44,
      "z": 1,
      "name": "Plant_Leaves_Bamboo"
    },
    {
      "x": -8,
      "y": 45,
      "z": 1,
      "name": "Plant_Leaves_Bamboo"
    },
    {
      "x": -8,
      "y": 41,
      "z": 2,
      "name": "Wood_Prehistoric_Branch_Long",
      "rotation": 4
    },
    {
      "x": -8,
      "y": 42,
      "z": 2,
      "name": "Plant_Leaves_Bamboo"
    },
    {
      "x": -8,
      "y": 44,
      "z": 2,
      "name": "Plant_Leaves_Bamboo"
    },
    {
      "x": -8,
      "y": 45,
      "z": 2,
      "name": "Plant_Leaves_Bamboo"
    },
    {
      "x": -8,
      "y": 41,
      "z": 3,
      "name": "Wood_Prehistoric_Branch_Corner"
    },
    {
      "x": -8,
      "y": 42,
      "z": 3,
      "name": "Wood_Prehistoric_Branch_Long"
    },
    {
      "x": -8,
      "y": 43,
      "z": 3,
      "name": "Wood_Prehistoric_Branch_Long"
    },
    {
      "x": -8,
      "y": 44,
      "z": 3,
      "name": "Wood_Prehistoric_Branch_Long"
    },
    {
      "x": -8,
      "y": 45,
      "z": 3,
      "name": "Plant_Leaves_Bamboo"
    },
    {
      "x": -8,
      "y": 42,
      "z": 4,
      "name": "Plant_Leaves_Bamboo"
    },
    {
      "x": -8,
      "y": 43,
      "z": 4,
      "name": "Plant_Leaves_Bamboo"
    },
    {
      "x": -8,
      "y": 44,
      "z": 4,
      "name": "Plant_Leaves_Bamboo"
    },
    {
      "x": -8,
      "y": 45,
      "z": 4,
      "name": "Plant_Leaves_Bamboo"
    },
    {
      "x": -8,
      "y": 42,
      "z": 5,
      "name": "Plant_Leaves_Bamboo"
    },
    {
      "x": -8,
      "y": 43,
      "z": 5,
      "name": "Plant_Leaves_Bamboo"
    },
    {
      "x": -8,
      "y": 44,
      "z": 5,
      "name": "Plant_Leaves_Bamboo"
    },
    {
      "x": -8,
      "y": 42,
      "z": 6,
      "name": "Plant_Leaves_Bamboo"
    },
    {
      "x": -8,
      "y": 43,
      "z": 6,
      "name": "Plant_Leaves_Bamboo"
    },
    {
      "x": -8,
      "y": 42,
      "z": 7,
      "name": "Plant_Leaves_Bamboo"
    },
    {
      "x": -8,
      "y": 42,
      "z": 8,
      "name": "Plant_Leaves_Bamboo"
    },
    {
      "x": -7,
      "y": 43,
      "z": -9,
      "name": "Plant_Leaves_Bamboo"
    },
    {
      "x": -7,
      "y": 43,
      "z": -8,
      "name": "Plant_Leaves_Bamboo"
    },
    {
      "x": -7,
      "y": 39,
      "z": -7,
      "name": "Plant_Leaves_Bamboo"
    },
    {
      "x": -7,
      "y": 43,
      "z": -7,
      "name": "Plant_Leaves_Bamboo"
    },
    {
      "x": -7,
      "y": 39,
      "z": -6,
      "name": "Plant_Leaves_Bamboo"
    },
    {
      "x": -7,
      "y": 40,
      "z": -6,
      "name": "Plant_Leaves_Bamboo"
    },
    {
      "x": -7,
      "y": 42,
      "z": -6,
      "name": "Plant_Leaves_Bamboo"
    },
    {
      "x": -7,
      "y": 38,
      "z": -5,
      "name": "Wood_Prehistoric_Branch_Corner",
      "rotation": 3
    },
    {
      "x": -7,
      "y": 39,
      "z": -5,
      "name": "Wood_Prehistoric_Branch_Long"
    },
    {
      "x": -7,
      "y": 40,
      "z": -5,
      "name": "Plant_Leaves_Bamboo"
    },
    {
      "x": -7,
      "y": 42,
      "z": -5,
      "name": "Plant_Leaves_Bamboo"
    },
    {
      "x": -7,
      "y": 24,
      "z": -4,
      "name": "Plant_Leaves_Bamboo",
      "support": 15,
      "rotation": 1
    },
    {
      "x": -7,
      "y": 39,
      "z": -4,
      "name": "Plant_Leaves_Bamboo"
    },
    {
      "x": -7,
      "y": 40,
      "z": -4,
      "name": "Plant_Leaves_Bamboo"
    },
    {
      "x": -7,
      "y": 42,
      "z": -4,
      "name": "Plant_Leaves_Bamboo"
    },
    {
      "x": -7,
      "y": 43,
      "z": -4,
      "name": "Plant_Leaves_Bamboo"
    },
    {
      "x": -7,
      "y": 24,
      "z": -3,
      "name": "Plant_Leaves_Bamboo",
      "support": 15,
      "rotation": 1
    },
    {
      "x": -7,
      "y": 39,
      "z": -3,
      "name": "Plant_Leaves_Bamboo"
    },
    {
      "x": -7,
      "y": 40,
      "z": -3,
      "name": "Wood_Prehistoric_Branch_Corner",
      "rotation": 3
    },
    {
      "x": -7,
      "y": 41,
      "z": -3,
      "name": "Wood_Prehistoric_Branch_Long"
    },
    {
      "x": -7,
      "y": 42,
      "z": -3,
      "name": "Wood_Prehistoric_Branch_Long"
    },
    {
      "x": -7,
      "y": 43,
      "z": -3,
      "name": "Plant_Leaves_Bamboo"
    },
    {
      "x": -7,
      "y": 44,
      "z": -3,
      "name": "Plant_Leaves_Bamboo"
    },
    {
      "x": -7,
      "y": 24,
      "z": -2,
      "name": "Plant_Leaves_Bamboo",
      "support": 15,
      "rotation": 1
    },
    {
      "x": -7,
      "y": 42,
      "z": -2,
      "name": "Plant_Leaves_Bamboo"
    },
    {
      "x": -7,
      "y": 43,
      "z": -2,
      "name": "Plant_Leaves_Bamboo"
    },
    {
      "x": -7,
      "y": 44,
      "z": -2,
      "name": "Plant_Leaves_Bamboo"
    },
    {
      "x": -7,
      "y": 24,
      "z": -1,
      "name": "Plant_Leaves_Bamboo",
      "support": 15,
      "rotation": 1
    },
    {
      "x": -7,
      "y": 41,
      "z": -1,
      "name": "Wood_Prehistoric_Branch_Long",
      "rotation": 5
    },
    {
      "x": -7,
      "y": 43,
      "z": -1,
      "name": "Plant_Leaves_Bamboo"
    },
    {
      "x": -7,
      "y": 44,
      "z": -1,
      "name": "Plant_Leaves_Bamboo"
    },
    {
      "x": -7,
      "y": 43,
      "z": 0,
      "name": "Plant_Leaves_Bamboo"
    },
    {
      "x": -7,
      "y": 44,
      "z": 0,
      "name": "Plant_Leaves_Bamboo"
    },
    {
      "x": -7,
      "y": 45,
      "z": 0,
      "name": "Plant_Leaves_Bamboo"
    },
    {
      "x": -7,
      "y": 42,
      "z": 1,
      "name": "Wood_Prehistoric_Branch_Long",
      "rotation": 5
    },
    {
      "x": -7,
      "y": 44,
      "z": 1,
      "name": "Plant_Leaves_Bamboo"
    },
    {
      "x": -7,
      "y": 45,
      "z": 1,
      "name": "Plant_Leaves_Bamboo"
    },
    {
      "x": -7,
      "y": 42,
      "z": 2,
      "name": "Plant_Leaves_Bamboo"
    },
    {
      "x": -7,
      "y": 44,
      "z": 2,
      "name": "Plant_Leaves_Bamboo"
    },
    {
      "x": -7,
      "y": 45,
      "z": 2,
      "name": "Plant_Leaves_Bamboo"
    },
    {
      "x": -7,
      "y": 43,
      "z": 3,
      "name": "Plant_Leaves_Bamboo"
    },
    {
      "x": -7,
      "y": 44,
      "z": 3,
      "name": "Plant_Leaves_Bamboo"
    },
    {
      "x": -7,
      "y": 45,
      "z": 3,
      "name": "Plant_Leaves_Bamboo"
    },
    {
      "x": -7,
      "y": 42,
      "z": 4,
      "name": "Plant_Leaves_Bamboo"
    },
    {
      "x": -7,
      "y": 43,
      "z": 4,
      "name": "Plant_Leaves_Bamboo"
    },
    {
      "x": -7,
      "y": 44,
      "z": 4,
      "name": "Plant_Leaves_Bamboo"
    },
    {
      "x": -7,
      "y": 42,
      "z": 5,
      "name": "Plant_Leaves_Bamboo"
    },
    {
      "x": -7,
      "y": 43,
      "z": 5,
      "name": "Plant_Leaves_Bamboo"
    },
    {
      "x": -7,
      "y": 44,
      "z": 5,
      "name": "Plant_Leaves_Bamboo"
    },
    {
      "x": -7,
      "y": 42,
      "z": 6,
      "name": "Plant_Leaves_Bamboo"
    },
    {
      "x": -7,
      "y": 43,
      "z": 6,
      "name": "Plant_Leaves_Bamboo"
    },
    {
      "x": -7,
      "y": 42,
      "z": 7,
      "name": "Plant_Leaves_Bamboo"
    },
    {
      "x": -7,
      "y": 43,
      "z": 7,
      "name": "Plant_Leaves_Bamboo"
    },
    {
      "x": -7,
      "y": 42,
      "z": 8,
      "name": "Plant_Leaves_Bamboo"
    },
    {
      "x": -6,
      "y": 43,
      "z": -10,
      "name": "Plant_Leaves_Bamboo"
    },
    {
      "x": -6,
      "y": 43,
      "z": -9,
      "name": "Plant_Leaves_Bamboo"
    },
    {
      "x": -6,
      "y": 44,
      "z": -9,
      "name": "Plant_Leaves_Bamboo"
    },
    {
      "x": -6,
      "y": 43,
      "z": -8,
      "name": "Plant_Leaves_Bamboo"
    },
    {
      "x": -6,
      "y": 44,
      "z": -8,
      "name": "Plant_Leaves_Bamboo"
    },
    {
      "x": -6,
      "y": 39,
      "z": -7,
      "name": "Plant_Leaves_Bamboo"
    },
    {
      "x": -6,
      "y": 43,
      "z": -7,
      "name": "Plant_Leaves_Bamboo"
    },
    {
      "x": -6,
      "y": 44,
      "z": -7,
      "name": "Plant_Leaves_Bamboo"
    },
    {
      "x": -6,
      "y": 39,
      "z": -6,
      "name": "Plant_Leaves_Bamboo"
    },
    {
      "x": -6,
      "y": 42,
      "z": -6,
      "name": "Plant_Leaves_Bamboo"
    },
    {
      "x": -6,
      "y": 43,
      "z": -6,
      "name": "Plant_Leaves_Bamboo"
    },
    {
      "x": -6,
      "y": 38,
      "z": -5,
      "name": "Wood_Prehistoric_Branch_Long",
      "rotation": 5
    },
    {
      "x": -6,
      "y": 39,
      "z": -5,
      "name": "Plant_Leaves_Bamboo"
    },
    {
      "x": -6,
      "y": 40,
      "z": -5,
      "name": "Plant_Leaves_Bamboo"
    },
    {
      "x": -6,
      "y": 42,
      "z": -5,
      "name": "Plant_Leaves_Bamboo"
    },
    {
      "x": -6,
      "y": 23,
      "z": -4,
      "name": "Plant_Leaves_Bamboo",
      "rotation": 1
    },
    {
      "x": -6,
      "y": 25,
      "z": -4,
      "name": "Plant_Leaves_Bamboo",
      "rotation": 1
    },
    {
      "x": -6,
      "y": 39,
      "z": -4,
      "name": "Plant_Leaves_Bamboo"
    },
    {
      "x": -6,
      "y": 42,
      "z": -4,
      "name": "Plant_Leaves_Bamboo"
    },
    {
      "x": -6,
      "y": 43,
      "z": -4,
      "name": "Plant_Leaves_Bamboo"
    },
    {
      "x": -6,
      "y": 21,
      "z": -3,
      "name": "Wood_Prehistoric_Branch_Corner",
      "rotation": 3
    },
    {
      "x": -6,
      "y": 22,
      "z": -3,
      "name": "Wood_Prehistoric_Branch_Long",
      "rotation": 1
    },
    {
      "x": -6,
      "y": 23,
      "z": -3,
      "name": "Wood_Prehistoric_Branch_Corner",
      "rotation": 34
    },
    {
      "x": -6,
      "y": 24,
      "z": -3,
      "name": "Plant_Leaves_Bamboo",
      "support": 15,
      "rotation": 1
    },
    {
      "x": -6,
      "y": 25,
      "z": -3,
      "name": "Plant_Leaves_Bamboo",
      "rotation": 1
    },
    {
      "x": -6,
      "y": 26,
      "z": -3,
      "name": "Plant_Leaves_Bamboo",
      "rotation": 1
    },
    {
      "x": -6,
      "y": 39,
      "z": -3,
      "name": "Plant_Leaves_Bamboo"
    },
    {
      "x": -6,
      "y": 40,
      "z": -3,
      "name": "Wood_Prehistoric_Branch_Long",
      "rotation": 5
    },
    {
      "x": -6,
      "y": 42,
      "z": -3,
      "name": "Plant_Leaves_Bamboo"
    },
    {
      "x": -6,
      "y": 43,
      "z": -3,
      "name": "Plant_Leaves_Bamboo"
    },
    {
      "x": -6,
      "y": 23,
      "z": -2,
      "name": "Wood_Prehistoric_Branch_Corner"
    },
    {
      "x": -6,
      "y": 24,
      "z": -2,
      "name": "Wood_Prehistoric_Branch_Long",
      "rotation": 1
    },
    {
      "x": -6,
      "y": 25,
      "z": -2,
      "name": "Plant_Leaves_Bamboo",
      "rotation": 1
    },
    {
      "x": -6,
      "y": 26,
      "z": -2,
      "name": "Plant_Leaves_Bamboo",
      "rotation": 1
    },
    {
      "x": -6,
      "y": 27,
      "z": -2,
      "name": "Plant_Leaves_Bamboo",
      "rotation": 1
    },
    {
      "x": -6,
      "y": 42,
      "z": -2,
      "name": "Plant_Leaves_Bamboo"
    },
    {
      "x": -6,
      "y": 43,
      "z": -2,
      "name": "Plant_Leaves_Bamboo"
    },
    {
      "x": -6,
      "y": 44,
      "z": -2,
      "name": "Plant_Leaves_Bamboo"
    },
    {
      "x": -6,
      "y": 24,
      "z": -1,
      "name": "Plant_Leaves_Bamboo",
      "support": 15,
      "rotation": 1
    },
    {
      "x": -6,
      "y": 26,
      "z": -1,
      "name": "Plant_Leaves_Bamboo",
      "rotation": 1
    },
    {
      "x": -6,
      "y": 27,
      "z": -1,
      "name": "Plant_Leaves_Bamboo",
      "rotation": 1
    },
    {
      "x": -6,
      "y": 40,
      "z": -1,
      "name": "Wood_Prehistoric_Branch_Corner",
      "rotation": 2
    },
    {
      "x": -6,
      "y": 41,
      "z": -1,
      "name": "Wood_Prehistoric_Branch_Corner",
      "rotation": 11
    },
    {
      "x": -6,
      "y": 44,
      "z": -1,
      "name": "Plant_Leaves_Bamboo"
    },
    {
      "x": -6,
      "y": 40,
      "z": 0,
      "name": "Wood_Prehistoric_Branch_Long",
      "rotation": 4
    },
    {
      "x": -6,
      "y": 44,
      "z": 0,
      "name": "Plant_Leaves_Bamboo"
    },
    {
      "x": -6,
      "y": 45,
      "z": 0,
      "name": "Plant_Leaves_Bamboo"
    },
    {
      "x": -6,
      "y": 37,
      "z": 1,
      "name": "Wood_Prehistoric_Trunk_Full"
    },
    {
      "x": -6,
      "y": 38,
      "z": 1,
      "name": "Wood_Prehistoric_Trunk_Full"
    },
    {
      "x": -6,
      "y": 39,
      "z": 1,
      "name": "Wood_Prehistoric_Trunk_Full"
    },
    {
      "x": -6,
      "y": 40,
      "z": 1,
      "name": "Wood_Prehistoric_Trunk_Full"
    },
    {
      "x": -6,
      "y": 41,
      "z": 1,
      "name": "Wood_Prehistoric_Trunk_Full"
    },
    {
      "x": -6,
      "y": 42,
      "z": 1,
      "name": "Wood_Prehistoric_Trunk_Full"
    },
    {
      "x": -6,
      "y": 44,
      "z": 1,
      "name": "Plant_Leaves_Bamboo"
    },
    {
      "x": -6,
      "y": 45,
      "z": 1,
      "name": "Plant_Leaves_Bamboo"
    },
    {
      "x": -6,
      "y": 43,
      "z": 2,
      "name": "Plant_Leaves_Bamboo"
    },
    {
      "x": -6,
      "y": 44,
      "z": 2,
      "name": "Plant_Leaves_Bamboo"
    },
    {
      "x": -6,
      "y": 45,
      "z": 2,
      "name": "Plant_Leaves_Bamboo"
    },
    {
      "x": -6,
      "y": 43,
      "z": 3,
      "name": "Plant_Leaves_Bamboo"
    },
    {
      "x": -6,
      "y": 44,
      "z": 3,
      "name": "Plant_Leaves_Bamboo"
    },
    {
      "x": -6,
      "y": 43,
      "z": 4,
      "name": "Plant_Leaves_Bamboo"
    },
    {
      "x": -6,
      "y": 44,
      "z": 4,
      "name": "Plant_Leaves_Bamboo"
    },
    {
      "x": -6,
      "y": 43,
      "z": 5,
      "name": "Plant_Leaves_Bamboo"
    },
    {
      "x": -6,
      "y": 44,
      "z": 5,
      "name": "Plant_Leaves_Bamboo"
    },
    {
      "x": -6,
      "y": 42,
      "z": 6,
      "name": "Plant_Leaves_Bamboo"
    },
    {
      "x": -6,
      "y": 43,
      "z": 6,
      "name": "Plant_Leaves_Bamboo"
    },
    {
      "x": -6,
      "y": 44,
      "z": 6,
      "name": "Plant_Leaves_Bamboo"
    },
    {
      "x": -6,
      "y": 42,
      "z": 7,
      "name": "Plant_Leaves_Bamboo"
    },
    {
      "x": -6,
      "y": 43,
      "z": 7,
      "name": "Plant_Leaves_Bamboo"
    },
    {
      "x": -6,
      "y": 42,
      "z": 8,
      "name": "Plant_Leaves_Bamboo"
    },
    {
      "x": -6,
      "y": 43,
      "z": 8,
      "name": "Plant_Leaves_Bamboo"
    },
    {
      "x": -6,
      "y": 42,
      "z": 9,
      "name": "Plant_Leaves_Bamboo"
    },
    {
      "x": -5,
      "y": 43,
      "z": -11,
      "name": "Plant_Leaves_Bamboo"
    },
    {
      "x": -5,
      "y": 43,
      "z": -10,
      "name": "Plant_Leaves_Bamboo"
    },
    {
      "x": -5,
      "y": 44,
      "z": -10,
      "name": "Plant_Leaves_Bamboo"
    },
    {
      "x": -5,
      "y": 43,
      "z": -9,
      "name": "Plant_Leaves_Bamboo"
    },
    {
      "x": -5,
      "y": 44,
      "z": -9,
      "name": "Plant_Leaves_Bamboo"
    },
    {
      "x": -5,
      "y": 43,
      "z": -8,
      "name": "Plant_Leaves_Bamboo"
    },
    {
      "x": -5,
      "y": 44,
      "z": -8,
      "name": "Plant_Leaves_Bamboo"
    },
    {
      "x": -5,
      "y": 43,
      "z": -7,
      "name": "Plant_Leaves_Bamboo"
    },
    {
      "x": -5,
      "y": 44,
      "z": -7,
      "name": "Plant_Leaves_Bamboo"
    },
    {
      "x": -5,
      "y": 39,
      "z": -6,
      "name": "Plant_Leaves_Bamboo"
    },
    {
      "x": -5,
      "y": 43,
      "z": -6,
      "name": "Plant_Leaves_Bamboo"
    },
    {
      "x": -5,
      "y": 44,
      "z": -6,
      "name": "Plant_Leaves_Bamboo"
    },
    {
      "x": -5,
      "y": 23,
      "z": -5,
      "name": "Plant_Leaves_Bamboo",
      "rotation": 1
    },
    {
      "x": -5,
      "y": 37,
      "z": -5,
      "name": "Wood_Prehistoric_Branch_Corner",
      "rotation": 2
    },
    {
      "x": -5,
      "y": 38,
      "z": -5,
      "name": "Wood_Prehistoric_Branch_Corner",
      "rotation": 11
    },
    {
      "x": -5,
      "y": 39,
      "z": -5,
      "name": "Plant_Leaves_Bamboo"
    },
    {
      "x": -5,
      "y": 42,
      "z": -5,
      "name": "Plant_Leaves_Bamboo"
    },
    {
      "x": -5,
      "y": 43,
      "z": -5,
      "name": "Plant_Leaves_Bamboo"
    },
    {
      "x": -5,
      "y": 48,
      "z": -5,
      "name": "Plant_Leaves_Bamboo"
    },
    {
      "x": -5,
      "y": 23,
      "z": -4,
      "name": "Plant_Leaves_Bamboo",
      "rotation": 1
    },
    {
      "x": -5,
      "y": 24,
      "z": -4,
      "name": "Plant_Leaves_Bamboo",
      "rotation": 1
    },
    {
      "x": -5,
      "y": 34,
      "z": -4,
      "name": "Wood_Prehistoric_Trunk_Full"
    },
    {
      "x": -5,
      "y": 35,
      "z": -4,
      "name": "Plant_Moss_Rug_Yellow"
    },
    {
      "x": -5,
      "y": 37,
      "z": -4,
      "name": "Wood_Prehistoric_Trunk_Full"
    },
    {
      "x": -5,
      "y": 38,
      "z": -4,
      "name": "Wood_Prehistoric_Trunk_Full"
    },
    {
      "x": -5,
      "y": 39,
      "z": -4,
      "name": "Wood_Prehistoric_Trunk_Full"
    },
    {
      "x": -5,
      "y": 42,
      "z": -4,
      "name": "Plant_Leaves_Bamboo"
    },
    {
      "x": -5,
      "y": 48,
      "z": -4,
      "name": "Plant_Leaves_Bamboo"
    },
    {
      "x": -5,
      "y": 4,
      "z": -3,
      "name": "Wood_Prehistoric_Trunk_Full"
    },
    {
      "x": -5,
      "y": 21,
      "z": -3,
      "name": "Wood_Prehistoric_Branch_Long",
      "rotation": 5
    },
    {
      "x": -5,
      "y": 23,
      "z": -3,
      "name": "Plant_Leaves_Bamboo",
      "rotation": 1
    },
    {
      "x": -5,
      "y": 24,
      "z": -3,
      "name": "Plant_Leaves_Bamboo",
      "rotation": 1
    },
    {
      "x": -5,
      "y": 25,
      "z": -3,
      "name": "Plant_Leaves_Bamboo",
      "rotation": 1
    },
    {
      "x": -5,
      "y": 26,
      "z": -3,
      "name": "Plant_Leaves_Bamboo",
      "rotation": 1
    },
    {
      "x": -5,
      "y": 34,
      "z": -3,
      "name": "Wood_Prehistoric_Trunk_Full"
    },
    {
      "x": -5,
      "y": 35,
      "z": -3,
      "name": "Wood_Prehistoric_Trunk_Full"
    },
    {
      "x": -5,
      "y": 36,
      "z": -3,
      "name": "Wood_Prehistoric_Trunk_Full"
    },
    {
      "x": -5,
      "y": 37,
      "z": -3,
      "name": "Wood_Prehistoric_Trunk_Full"
    },
    {
      "x": -5,
      "y": 39,
      "z": -3,
      "name": "Wood_Prehistoric_Branch_Corner"
    },
    {
      "x": -5,
      "y": 40,
      "z": -3,
      "name": "Wood_Prehistoric_Branch_Corner",
      "rotation": 11
    },
    {
      "x": -5,
      "y": 42,
      "z": -3,
      "name": "Plant_Leaves_Bamboo"
    },
    {
      "x": -5,
      "y": 48,
      "z": -3,
      "name": "Plant_Leaves_Bamboo"
    },
    {
      "x": -5,
      "y": 4,
      "z": -2,
      "name": "Wood_Prehistoric_Trunk_Full"
    },
    {
      "x": -5,
      "y": 5,
      "z": -2,
      "name": "Wood_Prehistoric_Trunk_Full"
    },
    {
      "x": -5,
      "y": 26,
      "z": -2,
      "name": "Plant_Leaves_Bamboo",
      "rotation": 1
    },
    {
      "x": -5,
      "y": 27,
      "z": -2,
      "name": "Plant_Leaves_Bamboo",
      "rotation": 1
    },
    {
      "x": -5,
      "y": 25,
      "z": -1,
      "name": "Wood_Prehistoric_Branch_Corner",
      "rotation": 3
    },
    {
      "x": -5,
      "y": 26,
      "z": -1,
      "name": "Wood_Prehistoric_Branch_Long",
      "rotation": 1
    },
    {
      "x": -5,
      "y": 27,
      "z": -1,
      "name": "Plant_Leaves_Bamboo",
      "rotation": 1
    },
    {
      "x": -5,
      "y": 44,
      "z": -1,
      "name": "Plant_Leaves_Bamboo"
    },
    {
      "x": -5,
      "y": 49,
      "z": -1,
      "name": "Plant_Leaves_Bamboo"
    },
    {
      "x": -5,
      "y": 26,
      "z": 0,
      "name": "Plant_Leaves_Bamboo",
      "support": 15,
      "rotation": 1
    },
    {
      "x": -5,
      "y": 44,
      "z": 0,
      "name": "Plant_Leaves_Bamboo"
    },
    {
      "x": -5,
      "y": 48,
      "z": 0,
      "name": "Plant_Leaves_Bamboo"
    },
    {
      "x": -5,
      "y": 49,
      "z": 0,
      "name": "Plant_Leaves_Bamboo"
    },
    {
      "x": -5,
      "y": 4,
      "z": 1,
      "name": "Wood_Prehistoric_Trunk_Full"
    },
    {
      "x": -5,
      "y": 5,
      "z": 1,
      "name": "Wood_Prehistoric_Trunk_Full"
    },
    {
      "x": -5,
      "y": 37,
      "z": 1,
      "name": "Wood_Prehistoric_Trunk_Full"
    },
    {
      "x": -5,
      "y": 44,
      "z": 1,
      "name": "Plant_Leaves_Bamboo"
    },
    {
      "x": -5,
      "y": 48,
      "z": 1,
      "name": "Plant_Leaves_Bamboo"
    },
    {
      "x": -5,
      "y": 49,
      "z": 1,
      "name": "Plant_Leaves_Bamboo"
    },
    {
      "x": -5,
      "y": 4,
      "z": 2,
      "name": "Wood_Prehistoric_Trunk_Full"
    },
    {
      "x": -5,
      "y": 43,
      "z": 2,
      "name": "Plant_Leaves_Bamboo"
    },
    {
      "x": -5,
      "y": 44,
      "z": 2,
      "name": "Plant_Leaves_Bamboo"
    },
    {
      "x": -5,
      "y": 48,
      "z": 2,
      "name": "Plant_Leaves_Bamboo"
    },
    {
      "x": -5,
      "y": 40,
      "z": 3,
      "name": "Wood_Prehistoric_Branch_Corner",
      "rotation": 3
    },
    {
      "x": -5,
      "y": 41,
      "z": 3,
      "name": "Wood_Prehistoric_Branch_Corner",
      "rotation": 8
    },
    {
      "x": -5,
      "y": 44,
      "z": 3,
      "name": "Plant_Leaves_Bamboo"
    },
    {
      "x": -5,
      "y": 41,
      "z": 4,
      "name": "Wood_Prehistoric_Branch_Long",
      "rotation": 4
    },
    {
      "x": -5,
      "y": 43,
      "z": 4,
      "name": "Plant_Leaves_Bamboo"
    },
    {
      "x": -5,
      "y": 44,
      "z": 4,
      "name": "Plant_Leaves_Bamboo"
    },
    {
      "x": -5,
      "y": 41,
      "z": 5,
      "name": "Wood_Prehistoric_Branch_Corner"
    },
    {
      "x": -5,
      "y": 42,
      "z": 5,
      "name": "Wood_Prehistoric_Branch_Long"
    },
    {
      "x": -5,
      "y": 43,
      "z": 5,
      "name": "Wood_Prehistoric_Branch_Long"
    },
    {
      "x": -5,
      "y": 44,
      "z": 5,
      "name": "Plant_Leaves_Bamboo"
    },
    {
      "x": -5,
      "y": 42,
      "z": 6,
      "name": "Plant_Leaves_Bamboo"
    },
    {
      "x": -5,
      "y": 43,
      "z": 6,
      "name": "Plant_Leaves_Bamboo"
    },
    {
      "x": -5,
      "y": 44,
      "z": 6,
      "name": "Plant_Leaves_Bamboo"
    },
    {
      "x": -5,
      "y": 42,
      "z": 7,
      "name": "Plant_Leaves_Bamboo"
    },
    {
      "x": -5,
      "y": 43,
      "z": 7,
      "name": "Plant_Leaves_Bamboo"
    },
    {
      "x": -5,
      "y": 42,
      "z": 8,
      "name": "Plant_Leaves_Bamboo"
    },
    {
      "x": -5,
      "y": 43,
      "z": 8,
      "name": "Plant_Leaves_Bamboo"
    },
    {
      "x": -5,
      "y": 42,
      "z": 9,
      "name": "Plant_Leaves_Bamboo"
    },
    {
      "x": -4,
      "y": 43,
      "z": -12,
      "name": "Plant_Leaves_Bamboo"
    },
    {
      "x": -4,
      "y": 43,
      "z": -11,
      "name": "Plant_Leaves_Bamboo"
    },
    {
      "x": -4,
      "y": 44,
      "z": -11,
      "name": "Plant_Leaves_Bamboo"
    },
    {
      "x": -4,
      "y": 43,
      "z": -10,
      "name": "Plant_Leaves_Bamboo"
    },
    {
      "x": -4,
      "y": 44,
      "z": -10,
      "name": "Plant_Leaves_Bamboo"
    },
    {
      "x": -4,
      "y": 43,
      "z": -9,
      "name": "Plant_Leaves_Bamboo"
    },
    {
      "x": -4,
      "y": 44,
      "z": -9,
      "name": "Plant_Leaves_Bamboo"
    },
    {
      "x": -4,
      "y": 45,
      "z": -9,
      "name": "Plant_Leaves_Bamboo"
    },
    {
      "x": -4,
      "y": 41,
      "z": -8,
      "name": "Wood_Prehistoric_Branch_Corner",
      "rotation": 2
    },
    {
      "x": -4,
      "y": 42,
      "z": -8,
      "name": "Wood_Prehistoric_Branch_Long"
    },
    {
      "x": -4,
      "y": 43,
      "z": -8,
      "name": "Plant_Leaves_Bamboo"
    },
    {
      "x": -4,
      "y": 44,
      "z": -8,
      "name": "Plant_Leaves_Bamboo"
    },
    {
      "x": -4,
      "y": 45,
      "z": -8,
      "name": "Plant_Leaves_Bamboo"
    },
    {
      "x": -4,
      "y": 41,
      "z": -7,
      "name": "Wood_Prehistoric_Branch_Long",
      "rotation": 4
    },
    {
      "x": -4,
      "y": 43,
      "z": -7,
      "name": "Plant_Leaves_Bamboo"
    },
    {
      "x": -4,
      "y": 44,
      "z": -7,
      "name": "Plant_Leaves_Bamboo"
    },
    {
      "x": -4,
      "y": 45,
      "z": -7,
      "name": "Plant_Leaves_Bamboo"
    },
    {
      "x": -4,
      "y": 24,
      "z": -6,
      "name": "Plant_Leaves_Bamboo",
      "rotation": 1
    },
    {
      "x": -4,
      "y": 25,
      "z": -6,
      "name": "Plant_Leaves_Bamboo",
      "rotation": 1
    },
    {
      "x": -4,
      "y": 39,
      "z": -6,
      "name": "Wood_Prehistoric_Branch_Corner",
      "rotation": 3
    },
    {
      "x": -4,
      "y": 40,
      "z": -6,
      "name": "Wood_Prehistoric_Branch_Long"
    },
    {
      "x": -4,
      "y": 41,
      "z": -6,
      "name": "Wood_Prehistoric_Branch_Corner",
      "rotation": 10
    },
    {
      "x": -4,
      "y": 43,
      "z": -6,
      "name": "Plant_Leaves_Bamboo"
    },
    {
      "x": -4,
      "y": 44,
      "z": -6,
      "name": "Plant_Leaves_Bamboo"
    },
    {
      "x": -4,
      "y": 48,
      "z": -6,
      "name": "Plant_Leaves_Bamboo"
    },
    {
      "x": -4,
      "y": 23,
      "z": -5,
      "name": "Plant_Leaves_Bamboo",
      "rotation": 1
    },
    {
      "x": -4,
      "y": 24,
      "z": -5,
      "name": "Plant_Leaves_Bamboo",
      "rotation": 1
    },
    {
      "x": -4,
      "y": 25,
      "z": -5,
      "name": "Plant_Leaves_Bamboo",
      "rotation": 1
    },
    {
      "x": -4,
      "y": 43,
      "z": -5,
      "name": "Plant_Leaves_Bamboo"
    },
    {
      "x": -4,
      "y": 44,
      "z": -5,
      "name": "Plant_Leaves_Bamboo"
    },
    {
      "x": -4,
      "y": 48,
      "z": -5,
      "name": "Plant_Leaves_Bamboo"
    },
    {
      "x": -4,
      "y": 23,
      "z": -4,
      "name": "Plant_Leaves_Bamboo",
      "rotation": 1
    },
    {
      "x": -4,
      "y": 24,
      "z": -4,
      "name": "Plant_Leaves_Bamboo",
      "rotation": 1
    },
    {
      "x": -4,
      "y": 32,
      "z": -4,
      "name": "Wood_Prehistoric_Trunk_Full"
    },
    {
      "x": -4,
      "y": 33,
      "z": -4,
      "name": "Wood_Prehistoric_Trunk_Full"
    },
    {
      "x": -4,
      "y": 34,
      "z": -4,
      "name": "Wood_Prehistoric_Trunk_Full"
    },
    {
      "x": -4,
      "y": 35,
      "z": -4,
      "name": "Plant_Moss_Rug_Yellow"
    },
    {
      "x": -4,
      "y": 48,
      "z": -4,
      "name": "Plant_Leaves_Bamboo"
    },
    {
      "x": -4,
      "y": 4,
      "z": -3,
      "name": "Wood_Prehistoric_Trunk_Full"
    },
    {
      "x": -4,
      "y": 5,
      "z": -3,
      "name": "Wood_Prehistoric_Trunk_Full"
    },
    {
      "x": -4,
      "y": 18,
      "z": -3,
      "name": "Wood_Prehistoric_Trunk_Full",
      "rotation": 1
    },
    {
      "x": -4,
      "y": 19,
      "z": -3,
      "name": "Wood_Prehistoric_Trunk_Full",
      "rotation": 1
    },
    {
      "x": -4,
      "y": 20,
      "z": -3,
      "name": "Wood_Prehistoric_Trunk_Full",
      "rotation": 1
    },
    {
      "x": -4,
      "y": 21,
      "z": -3,
      "name": "Wood_Prehistoric_Trunk_Full",
      "rotation": 1
    },
    {
      "x": -4,
      "y": 22,
      "z": -3,
      "name": "Wood_Prehistoric_Trunk_Full",
      "rotation": 1
    },
    {
      "x": -4,
      "y": 23,
      "z": -3,
      "name": "Wood_Prehistoric_Trunk_Full",
      "rotation": 1
    },
    {
      "x": -4,
      "y": 24,
      "z": -3,
      "name": "Plant_Leaves_Bamboo",
      "rotation": 1
    },
    {
      "x": -4,
      "y": 31,
      "z": -3,
      "name": "Wood_Prehistoric_Trunk_Full"
    },
    {
      "x": -4,
      "y": 32,
      "z": -3,
      "name": "Wood_Prehistoric_Trunk_Full"
    },
    {
      "x": -4,
      "y": 33,
      "z": -3,
      "name": "Wood_Prehistoric_Trunk_Full"
    },
    {
      "x": -4,
      "y": 34,
      "z": -3,
      "name": "Wood_Prehistoric_Trunk_Full"
    },
    {
      "x": -4,
      "y": 35,
      "z": -3,
      "name": "Plant_Moss_Rug_Yellow"
    },
    {
      "x": -4,
      "y": 48,
      "z": -3,
      "name": "Plant_Leaves_Bamboo"
    },
    {
      "x": -4,
      "y": 4,
      "z": -2,
      "name": "Wood_Prehistoric_Trunk_Full"
    },
    {
      "x": -4,
      "y": 5,
      "z": -2,
      "name": "Wood_Prehistoric_Trunk_Full"
    },
    {
      "x": -4,
      "y": 6,
      "z": -2,
      "name": "Wood_Prehistoric_Trunk_Full"
    },
    {
      "x": -4,
      "y": 23,
      "z": -2,
      "name": "Wood_Prehistoric_Branch_Long",
      "rotation": 6
    },
    {
      "x": -4,
      "y": 26,
      "z": -2,
      "name": "Plant_Leaves_Bamboo",
      "rotation": 1
    },
    {
      "x": -4,
      "y": 48,
      "z": -2,
      "name": "Plant_Leaves_Bamboo"
    },
    {
      "x": -4,
      "y": 49,
      "z": -2,
      "name": "Plant_Leaves_Bamboo"
    },
    {
      "x": -4,
      "y": 23,
      "z": -1,
      "name": "Wood_Prehistoric_Branch_Corner"
    },
    {
      "x": -4,
      "y": 24,
      "z": -1,
      "name": "Wood_Prehistoric_Branch_Long",
      "rotation": 1
    },
    {
      "x": -4,
      "y": 25,
      "z": -1,
      "name": "Wood_Prehistoric_Branch_Corner",
      "rotation": 33
    },
    {
      "x": -4,
      "y": 48,
      "z": -1,
      "name": "Plant_Leaves_Bamboo"
    },
    {
      "x": -4,
      "y": 49,
      "z": -1,
      "name": "Plant_Leaves_Bamboo"
    },
    {
      "x": -4,
      "y": 4,
      "z": 0,
      "name": "Wood_Prehistoric_Trunk_Full"
    },
    {
      "x": -4,
      "y": 5,
      "z": 0,
      "name": "Wood_Prehistoric_Trunk_Full"
    },
    {
      "x": -4,
      "y": 6,
      "z": 0,
      "name": "Wood_Prehistoric_Trunk_Full"
    },
    {
      "x": -4,
      "y": 7,
      "z": 0,
      "name": "Wood_Prehistoric_Trunk_Full"
    },
    {
      "x": -4,
      "y": 8,
      "z": 0,
      "name": "Wood_Prehistoric_Trunk_Full"
    },
    {
      "x": -4,
      "y": 43,
      "z": 0,
      "name": "Wood_Prehistoric_Branch_Corner",
      "rotation": 3
    },
    {
      "x": -4,
      "y": 44,
      "z": 0,
      "name": "Wood_Prehistoric_Branch_Long"
    },
    {
      "x": -4,
      "y": 45,
      "z": 0,
      "name": "Wood_Prehistoric_Branch_Long"
    },
    {
      "x": -4,
      "y": 48,
      "z": 0,
      "name": "Plant_Leaves_Bamboo"
    },
    {
      "x": -4,
      "y": 49,
      "z": 0,
      "name": "Plant_Leaves_Bamboo"
    },
    {
      "x": -4,
      "y": 4,
      "z": 1,
      "name": "Wood_Prehistoric_Trunk_Full"
    },
    {
      "x": -4,
      "y": 5,
      "z": 1,
      "name": "Wood_Prehistoric_Trunk_Full"
    },
    {
      "x": -4,
      "y": 6,
      "z": 1,
      "name": "Wood_Prehistoric_Trunk_Full"
    },
    {
      "x": -4,
      "y": 36,
      "z": 1,
      "name": "Wood_Prehistoric_Trunk_Full"
    },
    {
      "x": -4,
      "y": 37,
      "z": 1,
      "name": "Wood_Prehistoric_Trunk_Full"
    },
    {
      "x": -4,
      "y": 38,
      "z": 1,
      "name": "Wood_Prehistoric_Trunk_Full"
    },
    {
      "x": -4,
      "y": 44,
      "z": 1,
      "name": "Plant_Leaves_Bamboo"
    },
    {
      "x": -4,
      "y": 47,
      "z": 1,
      "name": "Plant_Leaves_Bamboo"
    },
    {
      "x": -4,
      "y": 48,
      "z": 1,
      "name": "Plant_Leaves_Bamboo"
    },
    {
      "x": -4,
      "y": 49,
      "z": 1,
      "name": "Plant_Leaves_Bamboo"
    },
    {
      "x": -4,
      "y": 4,
      "z": 2,
      "name": "Wood_Prehistoric_Trunk_Full"
    },
    {
      "x": -4,
      "y": 5,
      "z": 2,
      "name": "Wood_Prehistoric_Trunk_Full"
    },
    {
      "x": -4,
      "y": 34,
      "z": 2,
      "name": "Wood_Prehistoric_Trunk_Full"
    },
    {
      "x": -4,
      "y": 35,
      "z": 2,
      "name": "Wood_Prehistoric_Trunk_Full"
    },
    {
      "x": -4,
      "y": 36,
      "z": 2,
      "name": "Wood_Prehistoric_Trunk_Full"
    },
    {
      "x": -4,
      "y": 37,
      "z": 2,
      "name": "Plant_Moss_Rug_Yellow"
    },
    {
      "x": -4,
      "y": 38,
      "z": 2,
      "name": "Wood_Prehistoric_Trunk_Full"
    },
    {
      "x": -4,
      "y": 43,
      "z": 2,
      "name": "Plant_Leaves_Bamboo"
    },
    {
      "x": -4,
      "y": 44,
      "z": 2,
      "name": "Plant_Leaves_Bamboo"
    },
    {
      "x": -4,
      "y": 47,
      "z": 2,
      "name": "Plant_Leaves_Bamboo"
    },
    {
      "x": -4,
      "y": 48,
      "z": 2,
      "name": "Plant_Leaves_Bamboo"
    },
    {
      "x": -4,
      "y": 49,
      "z": 2,
      "name": "Plant_Leaves_Bamboo"
    },
    {
      "x": -4,
      "y": 38,
      "z": 3,
      "name": "Wood_Prehistoric_Trunk_Full"
    },
    {
      "x": -4,
      "y": 39,
      "z": 3,
      "name": "Wood_Prehistoric_Trunk_Full"
    },
    {
      "x": -4,
      "y": 40,
      "z": 3,
      "name": "Wood_Prehistoric_Trunk_Full"
    },
    {
      "x": -4,
      "y": 43,
      "z": 3,
      "name": "Plant_Leaves_Bamboo"
    },
    {
      "x": -4,
      "y": 47,
      "z": 3,
      "name": "Plant_Leaves_Bamboo"
    },
    {
      "x": -4,
      "y": 48,
      "z": 3,
      "name": "Plant_Leaves_Bamboo"
    },
    {
      "x": -4,
      "y": 43,
      "z": 4,
      "name": "Plant_Leaves_Bamboo"
    },
    {
      "x": -4,
      "y": 44,
      "z": 4,
      "name": "Plant_Leaves_Bamboo"
    },
    {
      "x": -4,
      "y": 43,
      "z": 5,
      "name": "Plant_Leaves_Bamboo"
    },
    {
      "x": -4,
      "y": 44,
      "z": 5,
      "name": "Plant_Leaves_Bamboo"
    },
    {
      "x": -4,
      "y": 43,
      "z": 6,
      "name": "Plant_Leaves_Bamboo"
    },
    {
      "x": -4,
      "y": 44,
      "z": 6,
      "name": "Plant_Leaves_Bamboo"
    },
    {
      "x": -4,
      "y": 42,
      "z": 7,
      "name": "Plant_Leaves_Bamboo"
    },
    {
      "x": -4,
      "y": 43,
      "z": 7,
      "name": "Plant_Leaves_Bamboo"
    },
    {
      "x": -4,
      "y": 42,
      "z": 8,
      "name": "Plant_Leaves_Bamboo"
    },
    {
      "x": -4,
      "y": 43,
      "z": 8,
      "name": "Plant_Leaves_Bamboo"
    },
    {
      "x": -4,
      "y": 42,
      "z": 9,
      "name": "Plant_Leaves_Bamboo"
    },
    {
      "x": -3,
      "y": 43,
      "z": -13,
      "name": "Plant_Leaves_Bamboo"
    },
    {
      "x": -3,
      "y": 43,
      "z": -12,
      "name": "Plant_Leaves_Bamboo"
    },
    {
      "x": -3,
      "y": 43,
      "z": -11,
      "name": "Plant_Leaves_Bamboo"
    },
    {
      "x": -3,
      "y": 44,
      "z": -11,
      "name": "Plant_Leaves_Bamboo"
    },
    {
      "x": -3,
      "y": 43,
      "z": -10,
      "name": "Plant_Leaves_Bamboo"
    },
    {
      "x": -3,
      "y": 44,
      "z": -10,
      "name": "Plant_Leaves_Bamboo"
    },
    {
      "x": -3,
      "y": 42,
      "z": -9,
      "name": "Plant_Leaves_Bamboo"
    },
    {
      "x": -3,
      "y": 43,
      "z": -9,
      "name": "Plant_Leaves_Bamboo"
    },
    {
      "x": -3,
      "y": 44,
      "z": -9,
      "name": "Plant_Leaves_Bamboo"
    },
    {
      "x": -3,
      "y": 45,
      "z": -9,
      "name": "Plant_Leaves_Bamboo"
    },
    {
      "x": -3,
      "y": 42,
      "z": -8,
      "name": "Plant_Leaves_Bamboo"
    },
    {
      "x": -3,
      "y": 43,
      "z": -8,
      "name": "Plant_Leaves_Bamboo"
    },
    {
      "x": -3,
      "y": 44,
      "z": -8,
      "name": "Plant_Leaves_Bamboo"
    },
    {
      "x": -3,
      "y": 45,
      "z": -8,
      "name": "Plant_Leaves_Bamboo"
    },
    {
      "x": -3,
      "y": 24,
      "z": -7,
      "name": "Plant_Leaves_Bamboo",
      "support": 15,
      "rotation": 1
    },
    {
      "x": -3,
      "y": 42,
      "z": -7,
      "name": "Plant_Leaves_Bamboo"
    },
    {
      "x": -3,
      "y": 43,
      "z": -7,
      "name": "Plant_Leaves_Bamboo"
    },
    {
      "x": -3,
      "y": 44,
      "z": -7,
      "name": "Plant_Leaves_Bamboo"
    },
    {
      "x": -3,
      "y": 45,
      "z": -7,
      "name": "Plant_Leaves_Bamboo"
    },
    {
      "x": -3,
      "y": 48,
      "z": -7,
      "name": "Plant_Leaves_Bamboo"
    },
    {
      "x": -3,
      "y": 24,
      "z": -6,
      "name": "Plant_Leaves_Bamboo",
      "rotation": 1
    },
    {
      "x": -3,
      "y": 25,
      "z": -6,
      "name": "Plant_Leaves_Bamboo",
      "rotation": 1
    },
    {
      "x": -3,
      "y": 39,
      "z": -6,
      "name": "Wood_Prehistoric_Branch_Long",
      "rotation": 5
    },
    {
      "x": -3,
      "y": 43,
      "z": -6,
      "name": "Plant_Leaves_Bamboo"
    },
    {
      "x": -3,
      "y": 44,
      "z": -6,
      "name": "Plant_Leaves_Bamboo"
    },
    {
      "x": -3,
      "y": 48,
      "z": -6,
      "name": "Plant_Leaves_Bamboo"
    },
    {
      "x": -3,
      "y": 4,
      "z": -5,
      "name": "Wood_Prehistoric_Trunk_Full"
    },
    {
      "x": -3,
      "y": 5,
      "z": -5,
      "name": "Wood_Prehistoric_Trunk_Full"
    },
    {
      "x": -3,
      "y": 23,
      "z": -5,
      "name": "Plant_Leaves_Bamboo",
      "rotation": 1
    },
    {
      "x": -3,
      "y": 25,
      "z": -5,
      "name": "Plant_Leaves_Bamboo",
      "rotation": 1
    },
    {
      "x": -3,
      "y": 34,
      "z": -5,
      "name": "Wood_Prehistoric_Trunk_Full"
    },
    {
      "x": -3,
      "y": 35,
      "z": -5,
      "name": "Wood_Prehistoric_Trunk_Full"
    },
    {
      "x": -3,
      "y": 36,
      "z": -5,
      "name": "Wood_Prehistoric_Trunk_Full"
    },
    {
      "x": -3,
      "y": 43,
      "z": -5,
      "name": "Plant_Leaves_Bamboo"
    },
    {
      "x": -3,
      "y": 44,
      "z": -5,
      "name": "Plant_Leaves_Bamboo"
    },
    {
      "x": -3,
      "y": 48,
      "z": -5,
      "name": "Plant_Leaves_Bamboo"
    },
    {
      "x": -3,
      "y": 49,
      "z": -5,
      "name": "Plant_Leaves_Bamboo"
    },
    {
      "x": -3,
      "y": 4,
      "z": -4,
      "name": "Wood_Prehistoric_Trunk_Full"
    },
    {
      "x": -3,
      "y": 5,
      "z": -4,
      "name": "Wood_Prehistoric_Trunk_Full"
    },
    {
      "x": -3,
      "y": 6,
      "z": -4,
      "name": "Wood_Prehistoric_Trunk_Full"
    },
    {
      "x": -3,
      "y": 18,
      "z": -4,
      "name": "Wood_Prehistoric_Trunk_Full",
      "rotation": 1
    },
    {
      "x": -3,
      "y": 19,
      "z": -4,
      "name": "Plant_Moss_Rug_Yellow",
      "rotation": 1
    },
    {
      "x": -3,
      "y": 23,
      "z": -4,
      "name": "Plant_Leaves_Bamboo",
      "rotation": 1
    },
    {
      "x": -3,
      "y": 31,
      "z": -4,
      "name": "Wood_Prehistoric_Trunk_Full"
    },
    {
      "x": -3,
      "y": 32,
      "z": -4,
      "name": "Wood_Prehistoric_Trunk_Full"
    },
    {
      "x": -3,
      "y": 33,
      "z": -4,
      "name": "Wood_Prehistoric_Trunk_Full"
    },
    {
      "x": -3,
      "y": 34,
      "z": -4,
      "name": "Wood_Prehistoric_Trunk_Full"
    },
    {
      "x": -3,
      "y": 35,
      "z": -4,
      "name": "Plant_Moss_Rug_Yellow"
    },
    {
      "x": -3,
      "y": 48,
      "z": -4,
      "name": "Plant_Leaves_Bamboo"
    },
    {
      "x": -3,
      "y": 49,
      "z": -4,
      "name": "Plant_Leaves_Bamboo"
    },
    {
      "x": -3,
      "y": 50,
      "z": -4,
      "name": "Plant_Leaves_Bamboo"
    },
    {
      "x": -3,
      "y": 18,
      "z": -3,
      "name": "Wood_Prehistoric_Trunk_Full",
      "rotation": 1
    },
    {
      "x": -3,
      "y": 19,
      "z": -3,
      "name": "Plant_Moss_Rug_Yellow",
      "rotation": 1
    },
    {
      "x": -3,
      "y": 30,
      "z": -3,
      "name": "Wood_Prehistoric_Trunk_Full"
    },
    {
      "x": -3,
      "y": 31,
      "z": -3,
      "name": "Wood_Prehistoric_Trunk_Full"
    },
    {
      "x": -3,
      "y": 32,
      "z": -3,
      "name": "Wood_Prehistoric_Trunk_Full"
    },
    {
      "x": -3,
      "y": 33,
      "z": -3,
      "name": "Wood_Prehistoric_Trunk_Full"
    },
    {
      "x": -3,
      "y": 34,
      "z": -3,
      "name": "Plant_Moss_Rug_Yellow"
    },
    {
      "x": -3,
      "y": 49,
      "z": -3,
      "name": "Plant_Leaves_Bamboo"
    },
    {
      "x": -3,
      "y": 4,
      "z": -2,
      "name": "Wood_Prehistoric_Trunk_Full"
    },
    {
      "x": -3,
      "y": 5,
      "z": -2,
      "name": "Wood_Prehistoric_Trunk_Full"
    },
    {
      "x": -3,
      "y": 6,
      "z": -2,
      "name": "Wood_Prehistoric_Trunk_Full"
    },
    {
      "x": -3,
      "y": 7,
      "z": -2,
      "name": "Wood_Prehistoric_Trunk_Full"
    },
    {
      "x": -3,
      "y": 8,
      "z": -2,
      "name": "Wood_Prehistoric_Trunk_Full"
    },
    {
      "x": -3,
      "y": 9,
      "z": -2,
      "name": "Wood_Prehistoric_Trunk_Full"
    },
    {
      "x": -3,
      "y": 10,
      "z": -2,
      "name": "Wood_Prehistoric_Trunk_Full"
    },
    {
      "x": -3,
      "y": 30,
      "z": -2,
      "name": "Wood_Prehistoric_Trunk_Full"
    },
    {
      "x": -3,
      "y": 31,
      "z": -2,
      "name": "Wood_Prehistoric_Trunk_Full"
    },
    {
      "x": -3,
      "y": 32,
      "z": -2,
      "name": "Plant_Moss_Rug_Yellow"
    },
    {
      "x": -3,
      "y": 49,
      "z": -2,
      "name": "Plant_Leaves_Bamboo"
    },
    {
      "x": -3,
      "y": 4,
      "z": -1,
      "name": "Wood_Prehistoric_Trunk_Full"
    },
    {
      "x": -3,
      "y": 5,
      "z": -1,
      "name": "Wood_Prehistoric_Trunk_Full"
    },
    {
      "x": -3,
      "y": 6,
      "z": -1,
      "name": "Wood_Prehistoric_Trunk_Full"
    },
    {
      "x": -3,
      "y": 7,
      "z": -1,
      "name": "Wood_Prehistoric_Trunk_Full"
    },
    {
      "x": -3,
      "y": 8,
      "z": -1,
      "name": "Wood_Prehistoric_Trunk_Full"
    },
    {
      "x": -3,
      "y": 9,
      "z": -1,
      "name": "Wood_Prehistoric_Trunk_Full"
    },
    {
      "x": -3,
      "y": 10,
      "z": -1,
      "name": "Wood_Prehistoric_Trunk_Full"
    },
    {
      "x": -3,
      "y": 11,
      "z": -1,
      "name": "Wood_Prehistoric_Trunk_Full"
    },
    {
      "x": -3,
      "y": 12,
      "z": -1,
      "name": "Wood_Prehistoric_Trunk_Full"
    },
    {
      "x": -3,
      "y": 13,
      "z": -1,
      "name": "Wood_Prehistoric_Trunk_Full"
    },
    {
      "x": -3,
      "y": 14,
      "z": -1,
      "name": "Wood_Prehistoric_Trunk_Full"
    },
    {
      "x": -3,
      "y": 15,
      "z": -1,
      "name": "Wood_Prehistoric_Trunk_Full"
    },
    {
      "x": -3,
      "y": 31,
      "z": -1,
      "name": "Wood_Prehistoric_Trunk_Full"
    },
    {
      "x": -3,
      "y": 32,
      "z": -1,
      "name": "Wood_Prehistoric_Trunk_Full"
    },
    {
      "x": -3,
      "y": 33,
      "z": -1,
      "name": "Plant_Moss_Rug_Yellow"
    },
    {
      "x": -3,
      "y": 48,
      "z": -1,
      "name": "Plant_Leaves_Bamboo"
    },
    {
      "x": -3,
      "y": 49,
      "z": -1,
      "name": "Plant_Leaves_Bamboo"
    },
    {
      "x": -3,
      "y": 50,
      "z": -1,
      "name": "Plant_Leaves_Bamboo"
    },
    {
      "x": -3,
      "y": 4,
      "z": 0,
      "name": "Wood_Prehistoric_Trunk_Full"
    },
    {
      "x": -3,
      "y": 5,
      "z": 0,
      "name": "Wood_Prehistoric_Trunk_Full"
    },
    {
      "x": -3,
      "y": 6,
      "z": 0,
      "name": "Wood_Prehistoric_Trunk_Full"
    },
    {
      "x": -3,
      "y": 7,
      "z": 0,
      "name": "Wood_Prehistoric_Trunk_Full"
    },
    {
      "x": -3,
      "y": 8,
      "z": 0,
      "name": "Wood_Prehistoric_Trunk_Full"
    },
    {
      "x": -3,
      "y": 9,
      "z": 0,
      "name": "Wood_Prehistoric_Trunk_Full"
    },
    {
      "x": -3,
      "y": 10,
      "z": 0,
      "name": "Wood_Prehistoric_Trunk_Full"
    },
    {
      "x": -3,
      "y": 32,
      "z": 0,
      "name": "Wood_Prehistoric_Trunk_Full"
    },
    {
      "x": -3,
      "y": 33,
      "z": 0,
      "name": "Wood_Prehistoric_Trunk_Full"
    },
    {
      "x": -3,
      "y": 34,
      "z": 0,
      "name": "Plant_Moss_Rug_Yellow"
    },
    {
      "x": -3,
      "y": 43,
      "z": 0,
      "name": "Wood_Prehistoric_Branch_Long",
      "rotation": 5
    },
    {
      "x": -3,
      "y": 48,
      "z": 0,
      "name": "Plant_Leaves_Bamboo"
    },
    {
      "x": -3,
      "y": 49,
      "z": 0,
      "name": "Plant_Leaves_Bamboo"
    },
    {
      "x": -3,
      "y": 50,
      "z": 0,
      "name": "Plant_Leaves_Bamboo"
    },
    {
      "x": -3,
      "y": 4,
      "z": 1,
      "name": "Wood_Prehistoric_Trunk_Full"
    },
    {
      "x": -3,
      "y": 5,
      "z": 1,
      "name": "Wood_Prehistoric_Trunk_Full"
    },
    {
      "x": -3,
      "y": 6,
      "z": 1,
      "name": "Wood_Prehistoric_Trunk_Full"
    },
    {
      "x": -3,
      "y": 7,
      "z": 1,
      "name": "Wood_Prehistoric_Trunk_Full"
    },
    {
      "x": -3,
      "y": 8,
      "z": 1,
      "name": "Wood_Prehistoric_Trunk_Full"
    },
    {
      "x": -3,
      "y": 32,
      "z": 1,
      "name": "Wood_Prehistoric_Trunk_Full"
    },
    {
      "x": -3,
      "y": 33,
      "z": 1,
      "name": "Wood_Prehistoric_Trunk_Full"
    },
    {
      "x": -3,
      "y": 34,
      "z": 1,
      "name": "Plant_Moss_Rug_Yellow"
    },
    {
      "x": -3,
      "y": 48,
      "z": 1,
      "name": "Plant_Leaves_Bamboo"
    },
    {
      "x": -3,
      "y": 49,
      "z": 1,
      "name": "Plant_Leaves_Bamboo"
    },
    {
      "x": -3,
      "y": 50,
      "z": 1,
      "name": "Plant_Leaves_Bamboo"
    },
    {
      "x": -3,
      "y": 32,
      "z": 2,
      "name": "Wood_Prehistoric_Trunk_Full"
    },
    {
      "x": -3,
      "y": 33,
      "z": 2,
      "name": "Wood_Prehistoric_Trunk_Full"
    },
    {
      "x": -3,
      "y": 34,
      "z": 2,
      "name": "Wood_Prehistoric_Trunk_Full"
    },
    {
      "x": -3,
      "y": 35,
      "z": 2,
      "name": "Wood_Prehistoric_Trunk_Full"
    },
    {
      "x": -3,
      "y": 36,
      "z": 2,
      "name": "Wood_Prehistoric_Trunk_Full"
    },
    {
      "x": -3,
      "y": 37,
      "z": 2,
      "name": "Plant_Moss_Rug_Yellow"
    },
    {
      "x": -3,
      "y": 47,
      "z": 2,
      "name": "Plant_Leaves_Bamboo"
    },
    {
      "x": -3,
      "y": 48,
      "z": 2,
      "name": "Plant_Leaves_Bamboo"
    },
    {
      "x": -3,
      "y": 49,
      "z": 2,
      "name": "Plant_Leaves_Bamboo"
    },
    {
      "x": -3,
      "y": 34,
      "z": 3,
      "name": "Wood_Prehistoric_Trunk_Full"
    },
    {
      "x": -3,
      "y": 35,
      "z": 3,
      "name": "Wood_Prehistoric_Trunk_Full"
    },
    {
      "x": -3,
      "y": 36,
      "z": 3,
      "name": "Wood_Prehistoric_Trunk_Full"
    },
    {
      "x": -3,
      "y": 37,
      "z": 3,
      "name": "Plant_Moss_Rug_Yellow"
    },
    {
      "x": -3,
      "y": 43,
      "z": 3,
      "name": "Plant_Leaves_Bamboo"
    },
    {
      "x": -3,
      "y": 47,
      "z": 3,
      "name": "Plant_Leaves_Bamboo"
    },
    {
      "x": -3,
      "y": 48,
      "z": 3,
      "name": "Plant_Leaves_Bamboo"
    },
    {
      "x": -3,
      "y": 49,
      "z": 3,
      "name": "Plant_Leaves_Bamboo"
    },
    {
      "x": -3,
      "y": 43,
      "z": 4,
      "name": "Plant_Leaves_Bamboo"
    },
    {
      "x": -3,
      "y": 47,
      "z": 4,
      "name": "Plant_Leaves_Bamboo"
    },
    {
      "x": -3,
      "y": 48,
      "z": 4,
      "name": "Plant_Leaves_Bamboo"
    },
    {
      "x": -3,
      "y": 43,
      "z": 5,
      "name": "Plant_Leaves_Bamboo"
    },
    {
      "x": -3,
      "y": 44,
      "z": 5,
      "name": "Plant_Leaves_Bamboo"
    },
    {
      "x": -3,
      "y": 43,
      "z": 6,
      "name": "Plant_Leaves_Bamboo"
    },
    {
      "x": -3,
      "y": 44,
      "z": 6,
      "name": "Plant_Leaves_Bamboo"
    },
    {
      "x": -3,
      "y": 43,
      "z": 7,
      "name": "Plant_Leaves_Bamboo"
    },
    {
      "x": -3,
      "y": 44,
      "z": 7,
      "name": "Plant_Leaves_Bamboo"
    },
    {
      "x": -3,
      "y": 42,
      "z": 8,
      "name": "Plant_Leaves_Bamboo"
    },
    {
      "x": -3,
      "y": 43,
      "z": 8,
      "name": "Plant_Leaves_Bamboo"
    },
    {
      "x": -3,
      "y": 43,
      "z": 9,
      "name": "Plant_Leaves_Bamboo"
    },
    {
      "x": -2,
      "y": 43,
      "z": -13,
      "name": "Plant_Leaves_Bamboo"
    },
    {
      "x": -2,
      "y": 43,
      "z": -12,
      "name": "Plant_Leaves_Bamboo"
    },
    {
      "x": -2,
      "y": 43,
      "z": -11,
      "name": "Plant_Leaves_Bamboo"
    },
    {
      "x": -2,
      "y": 44,
      "z": -11,
      "name": "Plant_Leaves_Bamboo"
    },
    {
      "x": -2,
      "y": 41,
      "z": -10,
      "name": "Wood_Prehistoric_Branch_Corner",
      "rotation": 2
    },
    {
      "x": -2,
      "y": 42,
      "z": -10,
      "name": "Wood_Prehistoric_Branch_Long"
    },
    {
      "x": -2,
      "y": 43,
      "z": -10,
      "name": "Plant_Leaves_Bamboo"
    },
    {
      "x": -2,
      "y": 44,
      "z": -10,
      "name": "Plant_Leaves_Bamboo"
    },
    {
      "x": -2,
      "y": 45,
      "z": -10,
      "name": "Plant_Leaves_Bamboo"
    },
    {
      "x": -2,
      "y": 41,
      "z": -9,
      "name": "Wood_Prehistoric_Branch_Long",
      "rotation": 4
    },
    {
      "x": -2,
      "y": 42,
      "z": -9,
      "name": "Plant_Leaves_Bamboo"
    },
    {
      "x": -2,
      "y": 43,
      "z": -9,
      "name": "Plant_Leaves_Bamboo"
    },
    {
      "x": -2,
      "y": 44,
      "z": -9,
      "name": "Plant_Leaves_Bamboo"
    },
    {
      "x": -2,
      "y": 45,
      "z": -9,
      "name": "Plant_Leaves_Bamboo"
    },
    {
      "x": -2,
      "y": 41,
      "z": -8,
      "name": "Wood_Prehistoric_Branch_Corner"
    },
    {
      "x": -2,
      "y": 42,
      "z": -8,
      "name": "Wood_Prehistoric_Branch_Corner",
      "rotation": 8
    },
    {
      "x": -2,
      "y": 43,
      "z": -8,
      "name": "Plant_Leaves_Bamboo"
    },
    {
      "x": -2,
      "y": 44,
      "z": -8,
      "name": "Plant_Leaves_Bamboo"
    },
    {
      "x": -2,
      "y": 45,
      "z": -8,
      "name": "Plant_Leaves_Bamboo"
    },
    {
      "x": -2,
      "y": 23,
      "z": -7,
      "name": "Plant_Leaves_Bamboo",
      "support": 15,
      "rotation": 1
    },
    {
      "x": -2,
      "y": 24,
      "z": -7,
      "name": "Plant_Leaves_Bamboo",
      "support": 15,
      "rotation": 1
    },
    {
      "x": -2,
      "y": 42,
      "z": -7,
      "name": "Wood_Prehistoric_Branch_Long",
      "rotation": 4
    },
    {
      "x": -2,
      "y": 43,
      "z": -7,
      "name": "Plant_Leaves_Bamboo"
    },
    {
      "x": -2,
      "y": 44,
      "z": -7,
      "name": "Plant_Leaves_Bamboo"
    },
    {
      "x": -2,
      "y": 45,
      "z": -7,
      "name": "Plant_Leaves_Bamboo"
    },
    {
      "x": -2,
      "y": 48,
      "z": -7,
      "name": "Plant_Leaves_Bamboo"
    },
    {
      "x": -2,
      "y": 21,
      "z": -6,
      "name": "Wood_Prehistoric_Branch_Corner",
      "rotation": 2
    },
    {
      "x": -2,
      "y": 22,
      "z": -6,
      "name": "Wood_Prehistoric_Branch_Long",
      "rotation": 1
    },
    {
      "x": -2,
      "y": 23,
      "z": -6,
      "name": "Wood_Prehistoric_Branch_Corner",
      "rotation": 34
    },
    {
      "x": -2,
      "y": 24,
      "z": -6,
      "name": "Plant_Leaves_Bamboo",
      "rotation": 1
    },
    {
      "x": -2,
      "y": 25,
      "z": -6,
      "name": "Plant_Leaves_Bamboo",
      "rotation": 1
    },
    {
      "x": -2,
      "y": 26,
      "z": -6,
      "name": "Plant_Leaves_Bamboo",
      "rotation": 1
    },
    {
      "x": -2,
      "y": 37,
      "z": -6,
      "name": "Wood_Prehistoric_Trunk_Full"
    },
    {
      "x": -2,
      "y": 38,
      "z": -6,
      "name": "Wood_Prehistoric_Trunk_Full"
    },
    {
      "x": -2,
      "y": 39,
      "z": -6,
      "name": "Wood_Prehistoric_Trunk_Full"
    },
    {
      "x": -2,
      "y": 40,
      "z": -6,
      "name": "Wood_Prehistoric_Trunk_Full"
    },
    {
      "x": -2,
      "y": 41,
      "z": -6,
      "name": "Wood_Prehistoric_Trunk_Full"
    },
    {
      "x": -2,
      "y": 42,
      "z": -6,
      "name": "Wood_Prehistoric_Trunk_Full"
    },
    {
      "x": -2,
      "y": 43,
      "z": -6,
      "name": "Plant_Leaves_Bamboo"
    },
    {
      "x": -2,
      "y": 44,
      "z": -6,
      "name": "Plant_Leaves_Bamboo"
    },
    {
      "x": -2,
      "y": 48,
      "z": -6,
      "name": "Plant_Leaves_Bamboo"
    },
    {
      "x": -2,
      "y": 4,
      "z": -5,
      "name": "Wood_Prehistoric_Trunk_Full"
    },
    {
      "x": -2,
      "y": 5,
      "z": -5,
      "name": "Wood_Prehistoric_Trunk_Full"
    },
    {
      "x": -2,
      "y": 21,
      "z": -5,
      "name": "Wood_Prehistoric_Branch_Long",
      "rotation": 6
    },
    {
      "x": -2,
      "y": 23,
      "z": -5,
      "name": "Wood_Prehistoric_Branch_Corner"
    },
    {
      "x": -2,
      "y": 24,
      "z": -5,
      "name": "Wood_Prehistoric_Branch_Long",
      "rotation": 1
    },
    {
      "x": -2,
      "y": 25,
      "z": -5,
      "name": "Plant_Leaves_Bamboo",
      "rotation": 1
    },
    {
      "x": -2,
      "y": 26,
      "z": -5,
      "name": "Plant_Leaves_Bamboo",
      "rotation": 1
    },
    {
      "x": -2,
      "y": 36,
      "z": -5,
      "name": "Wood_Prehistoric_Trunk_Full"
    },
    {
      "x": -2,
      "y": 37,
      "z": -5,
      "name": "Wood_Prehistoric_Trunk_Full"
    },
    {
      "x": -2,
      "y": 44,
      "z": -5,
      "name": "Plant_Leaves_Bamboo"
    },
    {
      "x": -2,
      "y": 48,
      "z": -5,
      "name": "Plant_Leaves_Bamboo"
    },
    {
      "x": -2,
      "y": 49,
      "z": -5,
      "name": "Plant_Leaves_Bamboo"
    },
    {
      "x": -2,
      "y": 4,
      "z": -4,
      "name": "Wood_Prehistoric_Trunk_Full"
    },
    {
      "x": -2,
      "y": 5,
      "z": -4,
      "name": "Wood_Prehistoric_Trunk_Full"
    },
    {
      "x": -2,
      "y": 6,
      "z": -4,
      "name": "Wood_Prehistoric_Trunk_Full"
    },
    {
      "x": -2,
      "y": 7,
      "z": -4,
      "name": "Wood_Prehistoric_Trunk_Full"
    },
    {
      "x": -2,
      "y": 16,
      "z": -4,
      "name": "Wood_Prehistoric_Trunk_Full",
      "rotation": 1
    },
    {
      "x": -2,
      "y": 17,
      "z": -4,
      "name": "Wood_Prehistoric_Trunk_Full",
      "rotation": 1
    },
    {
      "x": -2,
      "y": 18,
      "z": -4,
      "name": "Wood_Prehistoric_Trunk_Full",
      "rotation": 1
    },
    {
      "x": -2,
      "y": 19,
      "z": -4,
      "name": "Wood_Prehistoric_Trunk_Full",
      "rotation": 1
    },
    {
      "x": -2,
      "y": 20,
      "z": -4,
      "name": "Wood_Prehistoric_Trunk_Full",
      "rotation": 1
    },
    {
      "x": -2,
      "y": 21,
      "z": -4,
      "name": "Wood_Prehistoric_Trunk_Full",
      "rotation": 1
    },
    {
      "x": -2,
      "y": 47,
      "z": -4,
      "name": "Wood_Prehistoric_Branch_Corner",
      "rotation": 2
    },
    {
      "x": -2,
      "y": 48,
      "z": -4,
      "name": "Wood_Prehistoric_Branch_Long"
    },
    {
      "x": -2,
      "y": 49,
      "z": -4,
      "name": "Wood_Prehistoric_Branch_Long"
    },
    {
      "x": -2,
      "y": 50,
      "z": -4,
      "name": "Plant_Leaves_Bamboo"
    },
    {
      "x": -2,
      "y": 4,
      "z": -3,
      "name": "Wood_Prehistoric_Trunk_Full"
    },
    {
      "x": -2,
      "y": 5,
      "z": -3,
      "name": "Wood_Prehistoric_Trunk_Full"
    },
    {
      "x": -2,
      "y": 6,
      "z": -3,
      "name": "Wood_Prehistoric_Trunk_Full"
    },
    {
      "x": -2,
      "y": 7,
      "z": -3,
      "name": "Wood_Prehistoric_Trunk_Full"
    },
    {
      "x": -2,
      "y": 8,
      "z": -3,
      "name": "Wood_Prehistoric_Trunk_Full"
    },
    {
      "x": -2,
      "y": 9,
      "z": -3,
      "name": "Wood_Prehistoric_Trunk_Full"
    },
    {
      "x": -2,
      "y": 15,
      "z": -3,
      "name": "Wood_Prehistoric_Trunk_Full",
      "rotation": 1
    },
    {
      "x": -2,
      "y": 16,
      "z": -3,
      "name": "Wood_Prehistoric_Trunk_Full",
      "rotation": 1
    },
    {
      "x": -2,
      "y": 17,
      "z": -3,
      "name": "Plant_Moss_Rug_Yellow",
      "rotation": 1
    },
    {
      "x": -2,
      "y": 30,
      "z": -3,
      "name": "Wood_Prehistoric_Trunk_Full"
    },
    {
      "x": -2,
      "y": 31,
      "z": -3,
      "name": "Wood_Prehistoric_Trunk_Full"
    },
    {
      "x": -2,
      "y": 32,
      "z": -3,
      "name": "Plant_Moss_Rug_Yellow"
    },
    {
      "x": -2,
      "y": 47,
      "z": -3,
      "name": "Wood_Prehistoric_Branch_Long",
      "rotation": 4
    },
    {
      "x": -2,
      "y": 49,
      "z": -3,
      "name": "Plant_Leaves_Bamboo"
    },
    {
      "x": -2,
      "y": 50,
      "z": -3,
      "name": "Plant_Leaves_Bamboo"
    },
    {
      "x": -2,
      "y": 4,
      "z": -2,
      "name": "Wood_Prehistoric_Trunk_Full"
    },
    {
      "x": -2,
      "y": 5,
      "z": -2,
      "name": "Wood_Prehistoric_Trunk_Full"
    },
    {
      "x": -2,
      "y": 6,
      "z": -2,
      "name": "Wood_Prehistoric_Trunk_Full"
    },
    {
      "x": -2,
      "y": 7,
      "z": -2,
      "name": "Wood_Prehistoric_Trunk_Full"
    },
    {
      "x": -2,
      "y": 8,
      "z": -2,
      "name": "Wood_Prehistoric_Trunk_Full"
    },
    {
      "x": -2,
      "y": 9,
      "z": -2,
      "name": "Wood_Prehistoric_Trunk_Full"
    },
    {
      "x": -2,
      "y": 10,
      "z": -2,
      "name": "Wood_Prehistoric_Trunk_Full"
    },
    {
      "x": -2,
      "y": 11,
      "z": -2,
      "name": "Wood_Prehistoric_Trunk_Full"
    },
    {
      "x": -2,
      "y": 12,
      "z": -2,
      "name": "Wood_Prehistoric_Trunk_Full"
    },
    {
      "x": -2,
      "y": 13,
      "z": -2,
      "name": "Wood_Prehistoric_Trunk_Full"
    },
    {
      "x": -2,
      "y": 14,
      "z": -2,
      "name": "Wood_Prehistoric_Trunk_Full"
    },
    {
      "x": -2,
      "y": 15,
      "z": -2,
      "name": "Wood_Prehistoric_Trunk_Full"
    },
    {
      "x": -2,
      "y": 16,
      "z": -2,
      "name": "Wood_Prehistoric_Trunk_Full"
    },
    {
      "x": -2,
      "y": 17,
      "z": -2,
      "name": "Wood_Prehistoric_Trunk_Full"
    },
    {
      "x": -2,
      "y": 18,
      "z": -2,
      "name": "Wood_Prehistoric_Trunk_Full"
    },
    {
      "x": -2,
      "y": 19,
      "z": -2,
      "name": "Wood_Prehistoric_Trunk_Full"
    },
    {
      "x": -2,
      "y": 20,
      "z": -2,
      "name": "Wood_Prehistoric_Trunk_Full"
    },
    {
      "x": -2,
      "y": 21,
      "z": -2,
      "name": "Wood_Prehistoric_Trunk_Full"
    },
    {
      "x": -2,
      "y": 22,
      "z": -2,
      "name": "Wood_Prehistoric_Trunk_Full"
    },
    {
      "x": -2,
      "y": 23,
      "z": -2,
      "name": "Wood_Prehistoric_Trunk_Full"
    },
    {
      "x": -2,
      "y": 24,
      "z": -2,
      "name": "Wood_Prehistoric_Trunk_Full"
    },
    {
      "x": -2,
      "y": 25,
      "z": -2,
      "name": "Wood_Prehistoric_Trunk_Full"
    },
    {
      "x": -2,
      "y": 26,
      "z": -2,
      "name": "Wood_Prehistoric_Trunk_Full"
    },
    {
      "x": -2,
      "y": 27,
      "z": -2,
      "name": "Wood_Prehistoric_Trunk_Full"
    },
    {
      "x": -2,
      "y": 30,
      "z": -2,
      "name": "Wood_Prehistoric_Trunk_Full"
    },
    {
      "x": -2,
      "y": 31,
      "z": -2,
      "name": "Wood_Prehistoric_Trunk_Full"
    },
    {
      "x": -2,
      "y": 32,
      "z": -2,
      "name": "Plant_Moss_Rug_Yellow"
    },
    {
      "x": -2,
      "y": 46,
      "z": -2,
      "name": "Wood_Prehistoric_Branch_Corner",
      "rotation": 3
    },
    {
      "x": -2,
      "y": 47,
      "z": -2,
      "name": "Wood_Prehistoric_Branch_Corner",
      "rotation": 10
    },
    {
      "x": -2,
      "y": 49,
      "z": -2,
      "name": "Plant_Leaves_Bamboo"
    },
    {
      "x": -2,
      "y": 4,
      "z": -1,
      "name": "Wood_Prehistoric_Trunk_Full"
    },
    {
      "x": -2,
      "y": 5,
      "z": -1,
      "name": "Wood_Prehistoric_Trunk_Full"
    },
    {
      "x": -2,
      "y": 6,
      "z": -1,
      "name": "Wood_Prehistoric_Trunk_Full"
    },
    {
      "x": -2,
      "y": 7,
      "z": -1,
      "name": "Wood_Prehistoric_Trunk_Full"
    },
    {
      "x": -2,
      "y": 8,
      "z": -1,
      "name": "Wood_Prehistoric_Trunk_Full"
    },
    {
      "x": -2,
      "y": 9,
      "z": -1,
      "name": "Wood_Prehistoric_Trunk_Full"
    },
    {
      "x": -2,
      "y": 10,
      "z": -1,
      "name": "Wood_Prehistoric_Trunk_Full"
    },
    {
      "x": -2,
      "y": 11,
      "z": -1,
      "name": "Wood_Prehistoric_Trunk_Full"
    },
    {
      "x": -2,
      "y": 12,
      "z": -1,
      "name": "Wood_Prehistoric_Trunk_Full"
    },
    {
      "x": -2,
      "y": 13,
      "z": -1,
      "name": "Wood_Prehistoric_Trunk_Full"
    },
    {
      "x": -2,
      "y": 14,
      "z": -1,
      "name": "Wood_Prehistoric_Trunk_Full"
    },
    {
      "x": -2,
      "y": 15,
      "z": -1,
      "name": "Wood_Prehistoric_Trunk_Full"
    },
    {
      "x": -2,
      "y": 16,
      "z": -1,
      "name": "Wood_Prehistoric_Trunk_Full"
    },
    {
      "x": -2,
      "y": 17,
      "z": -1,
      "name": "Wood_Prehistoric_Trunk_Full"
    },
    {
      "x": -2,
      "y": 18,
      "z": -1,
      "name": "Wood_Prehistoric_Trunk_Full"
    },
    {
      "x": -2,
      "y": 19,
      "z": -1,
      "name": "Wood_Prehistoric_Trunk_Full"
    },
    {
      "x": -2,
      "y": 20,
      "z": -1,
      "name": "Wood_Prehistoric_Trunk_Full"
    },
    {
      "x": -2,
      "y": 21,
      "z": -1,
      "name": "Wood_Prehistoric_Trunk_Full"
    },
    {
      "x": -2,
      "y": 22,
      "z": -1,
      "name": "Wood_Prehistoric_Trunk_Full"
    },
    {
      "x": -2,
      "y": 23,
      "z": -1,
      "name": "Wood_Prehistoric_Trunk_Full"
    },
    {
      "x": -2,
      "y": 24,
      "z": -1,
      "name": "Wood_Prehistoric_Trunk_Full"
    },
    {
      "x": -2,
      "y": 25,
      "z": -1,
      "name": "Wood_Prehistoric_Trunk_Full"
    },
    {
      "x": -2,
      "y": 26,
      "z": -1,
      "name": "Wood_Prehistoric_Trunk_Full"
    },
    {
      "x": -2,
      "y": 27,
      "z": -1,
      "name": "Wood_Prehistoric_Trunk_Full"
    },
    {
      "x": -2,
      "y": 28,
      "z": -1,
      "name": "Wood_Prehistoric_Trunk_Full"
    },
    {
      "x": -2,
      "y": 29,
      "z": -1,
      "name": "Wood_Prehistoric_Trunk_Full"
    },
    {
      "x": -2,
      "y": 30,
      "z": -1,
      "name": "Wood_Prehistoric_Trunk_Full"
    },
    {
      "x": -2,
      "y": 31,
      "z": -1,
      "name": "Wood_Prehistoric_Trunk_Full"
    },
    {
      "x": -2,
      "y": 32,
      "z": -1,
      "name": "Wood_Prehistoric_Trunk_Full"
    },
    {
      "x": -2,
      "y": 33,
      "z": -1,
      "name": "Plant_Moss_Rug_Yellow"
    },
    {
      "x": -2,
      "y": 49,
      "z": -1,
      "name": "Plant_Leaves_Bamboo"
    },
    {
      "x": -2,
      "y": 50,
      "z": -1,
      "name": "Plant_Leaves_Bamboo"
    },
    {
      "x": -2,
      "y": 4,
      "z": 0,
      "name": "Wood_Prehistoric_Trunk_Full"
    },
    {
      "x": -2,
      "y": 5,
      "z": 0,
      "name": "Wood_Prehistoric_Trunk_Full"
    },
    {
      "x": -2,
      "y": 6,
      "z": 0,
      "name": "Wood_Prehistoric_Trunk_Full"
    },
    {
      "x": -2,
      "y": 7,
      "z": 0,
      "name": "Wood_Prehistoric_Trunk_Full"
    },
    {
      "x": -2,
      "y": 8,
      "z": 0,
      "name": "Wood_Prehistoric_Trunk_Full"
    },
    {
      "x": -2,
      "y": 9,
      "z": 0,
      "name": "Wood_Prehistoric_Trunk_Full"
    },
    {
      "x": -2,
      "y": 10,
      "z": 0,
      "name": "Wood_Prehistoric_Trunk_Full"
    },
    {
      "x": -2,
      "y": 11,
      "z": 0,
      "name": "Wood_Prehistoric_Trunk_Full"
    },
    {
      "x": -2,
      "y": 12,
      "z": 0,
      "name": "Wood_Prehistoric_Trunk_Full"
    },
    {
      "x": -2,
      "y": 13,
      "z": 0,
      "name": "Wood_Prehistoric_Trunk_Full"
    },
    {
      "x": -2,
      "y": 14,
      "z": 0,
      "name": "Wood_Prehistoric_Trunk_Full"
    },
    {
      "x": -2,
      "y": 15,
      "z": 0,
      "name": "Wood_Prehistoric_Trunk_Full"
    },
    {
      "x": -2,
      "y": 16,
      "z": 0,
      "name": "Wood_Prehistoric_Trunk_Full"
    },
    {
      "x": -2,
      "y": 17,
      "z": 0,
      "name": "Wood_Prehistoric_Trunk_Full"
    },
    {
      "x": -2,
      "y": 30,
      "z": 0,
      "name": "Wood_Prehistoric_Trunk_Full"
    },
    {
      "x": -2,
      "y": 31,
      "z": 0,
      "name": "Wood_Prehistoric_Trunk_Full"
    },
    {
      "x": -2,
      "y": 32,
      "z": 0,
      "name": "Wood_Prehistoric_Trunk_Full"
    },
    {
      "x": -2,
      "y": 33,
      "z": 0,
      "name": "Wood_Prehistoric_Trunk_Full"
    },
    {
      "x": -2,
      "y": 34,
      "z": 0,
      "name": "Wood_Prehistoric_Trunk_Full"
    },
    {
      "x": -2,
      "y": 35,
      "z": 0,
      "name": "Wood_Prehistoric_Trunk_Full"
    },
    {
      "x": -2,
      "y": 43,
      "z": 0,
      "name": "Wood_Prehistoric_Branch_Long",
      "rotation": 5
    },
    {
      "x": -2,
      "y": 48,
      "z": 0,
      "name": "Plant_Leaves_Bamboo"
    },
    {
      "x": -2,
      "y": 49,
      "z": 0,
      "name": "Plant_Leaves_Bamboo"
    },
    {
      "x": -2,
      "y": 50,
      "z": 0,
      "name": "Plant_Leaves_Bamboo"
    },
    {
      "x": -2,
      "y": 32,
      "z": 1,
      "name": "Wood_Prehistoric_Trunk_Full"
    },
    {
      "x": -2,
      "y": 33,
      "z": 1,
      "name": "Wood_Prehistoric_Trunk_Full"
    },
    {
      "x": -2,
      "y": 34,
      "z": 1,
      "name": "Plant_Moss_Rug_Yellow"
    },
    {
      "x": -2,
      "y": 48,
      "z": 1,
      "name": "Plant_Leaves_Bamboo"
    },
    {
      "x": -2,
      "y": 49,
      "z": 1,
      "name": "Plant_Leaves_Bamboo"
    },
    {
      "x": -2,
      "y": 50,
      "z": 1,
      "name": "Plant_Leaves_Bamboo"
    },
    {
      "x": -2,
      "y": 33,
      "z": 2,
      "name": "Wood_Prehistoric_Trunk_Full"
    },
    {
      "x": -2,
      "y": 34,
      "z": 2,
      "name": "Plant_Moss_Rug_Yellow"
    },
    {
      "x": -2,
      "y": 47,
      "z": 2,
      "name": "Plant_Leaves_Bamboo"
    },
    {
      "x": -2,
      "y": 48,
      "z": 2,
      "name": "Plant_Leaves_Bamboo"
    },
    {
      "x": -2,
      "y": 49,
      "z": 2,
      "name": "Plant_Leaves_Bamboo"
    },
    {
      "x": -2,
      "y": 4,
      "z": 3,
      "name": "Wood_Prehistoric_Trunk_Full"
    },
    {
      "x": -2,
      "y": 5,
      "z": 3,
      "name": "Wood_Prehistoric_Trunk_Full"
    },
    {
      "x": -2,
      "y": 6,
      "z": 3,
      "name": "Wood_Prehistoric_Trunk_Full"
    },
    {
      "x": -2,
      "y": 7,
      "z": 3,
      "name": "Wood_Prehistoric_Trunk_Full"
    },
    {
      "x": -2,
      "y": 36,
      "z": 3,
      "name": "Wood_Prehistoric_Trunk_Full"
    },
    {
      "x": -2,
      "y": 37,
      "z": 3,
      "name": "Plant_Moss_Rug_Yellow"
    },
    {
      "x": -2,
      "y": 43,
      "z": 3,
      "name": "Plant_Leaves_Bamboo"
    },
    {
      "x": -2,
      "y": 47,
      "z": 3,
      "name": "Plant_Leaves_Bamboo"
    },
    {
      "x": -2,
      "y": 48,
      "z": 3,
      "name": "Plant_Leaves_Bamboo"
    },
    {
      "x": -2,
      "y": 49,
      "z": 3,
      "name": "Plant_Leaves_Bamboo"
    },
    {
      "x": -2,
      "y": 4,
      "z": 4,
      "name": "Wood_Prehistoric_Trunk_Full"
    },
    {
      "x": -2,
      "y": 5,
      "z": 4,
      "name": "Wood_Prehistoric_Trunk_Full"
    },
    {
      "x": -2,
      "y": 43,
      "z": 4,
      "name": "Plant_Leaves_Bamboo"
    },
    {
      "x": -2,
      "y": 47,
      "z": 4,
      "name": "Plant_Leaves_Bamboo"
    },
    {
      "x": -2,
      "y": 48,
      "z": 4,
      "name": "Plant_Leaves_Bamboo"
    },
    {
      "x": -2,
      "y": 43,
      "z": 5,
      "name": "Plant_Leaves_Bamboo"
    },
    {
      "x": -2,
      "y": 44,
      "z": 5,
      "name": "Plant_Leaves_Bamboo"
    },
    {
      "x": -2,
      "y": 47,
      "z": 5,
      "name": "Plant_Leaves_Bamboo"
    },
    {
      "x": -2,
      "y": 41,
      "z": 6,
      "name": "Wood_Prehistoric_Branch_Corner",
      "rotation": 3
    },
    {
      "x": -2,
      "y": 42,
      "z": 6,
      "name": "Wood_Prehistoric_Branch_Long"
    },
    {
      "x": -2,
      "y": 43,
      "z": 6,
      "name": "Wood_Prehistoric_Branch_Long"
    },
    {
      "x": -2,
      "y": 44,
      "z": 6,
      "name": "Plant_Leaves_Bamboo"
    },
    {
      "x": -2,
      "y": 45,
      "z": 6,
      "name": "Plant_Leaves_Bamboo"
    },
    {
      "x": -2,
      "y": 43,
      "z": 7,
      "name": "Plant_Leaves_Bamboo"
    },
    {
      "x": -2,
      "y": 44,
      "z": 7,
      "name": "Plant_Leaves_Bamboo"
    },
    {
      "x": -2,
      "y": 43,
      "z": 8,
      "name": "Plant_Leaves_Bamboo"
    },
    {
      "x": -2,
      "y": 43,
      "z": 9,
      "name": "Plant_Leaves_Bamboo"
    },
    {
      "x": -1,
      "y": 43,
      "z": -13,
      "name": "Plant_Leaves_Bamboo"
    },
    {
      "x": -1,
      "y": 43,
      "z": -12,
      "name": "Plant_Leaves_Bamboo"
    },
    {
      "x": -1,
      "y": 42,
      "z": -11,
      "name": "Plant_Leaves_Bamboo"
    },
    {
      "x": -1,
      "y": 43,
      "z": -11,
      "name": "Plant_Leaves_Bamboo"
    },
    {
      "x": -1,
      "y": 44,
      "z": -11,
      "name": "Plant_Leaves_Bamboo"
    },
    {
      "x": -1,
      "y": 42,
      "z": -10,
      "name": "Plant_Leaves_Bamboo"
    },
    {
      "x": -1,
      "y": 43,
      "z": -10,
      "name": "Plant_Leaves_Bamboo"
    },
    {
      "x": -1,
      "y": 44,
      "z": -10,
      "name": "Plant_Leaves_Bamboo"
    },
    {
      "x": -1,
      "y": 42,
      "z": -9,
      "name": "Plant_Leaves_Bamboo"
    },
    {
      "x": -1,
      "y": 43,
      "z": -9,
      "name": "Plant_Leaves_Bamboo"
    },
    {
      "x": -1,
      "y": 44,
      "z": -9,
      "name": "Plant_Leaves_Bamboo"
    },
    {
      "x": -1,
      "y": 42,
      "z": -8,
      "name": "Plant_Leaves_Bamboo"
    },
    {
      "x": -1,
      "y": 43,
      "z": -8,
      "name": "Plant_Leaves_Bamboo"
    },
    {
      "x": -1,
      "y": 44,
      "z": -8,
      "name": "Plant_Leaves_Bamboo"
    },
    {
      "x": -1,
      "y": 43,
      "z": -7,
      "name": "Plant_Leaves_Bamboo"
    },
    {
      "x": -1,
      "y": 44,
      "z": -7,
      "name": "Plant_Leaves_Bamboo"
    },
    {
      "x": -1,
      "y": 48,
      "z": -7,
      "name": "Plant_Leaves_Bamboo"
    },
    {
      "x": -1,
      "y": 24,
      "z": -6,
      "name": "Plant_Leaves_Bamboo",
      "rotation": 1
    },
    {
      "x": -1,
      "y": 25,
      "z": -6,
      "name": "Plant_Leaves_Bamboo",
      "rotation": 1
    },
    {
      "x": -1,
      "y": 40,
      "z": -6,
      "name": "Wood_Prehistoric_Branch_Long",
      "rotation": 5
    },
    {
      "x": -1,
      "y": 43,
      "z": -6,
      "name": "Plant_Leaves_Bamboo"
    },
    {
      "x": -1,
      "y": 44,
      "z": -6,
      "name": "Plant_Leaves_Bamboo"
    },
    {
      "x": -1,
      "y": 48,
      "z": -6,
      "name": "Plant_Leaves_Bamboo"
    },
    {
      "x": -1,
      "y": 25,
      "z": -5,
      "name": "Plant_Leaves_Bamboo",
      "rotation": 1
    },
    {
      "x": -1,
      "y": 43,
      "z": -5,
      "name": "Plant_Leaves_Bamboo"
    },
    {
      "x": -1,
      "y": 48,
      "z": -5,
      "name": "Plant_Leaves_Bamboo"
    },
    {
      "x": -1,
      "y": 49,
      "z": -5,
      "name": "Plant_Leaves_Bamboo"
    },
    {
      "x": -1,
      "y": 4,
      "z": -4,
      "name": "Wood_Prehistoric_Trunk_Full"
    },
    {
      "x": -1,
      "y": 5,
      "z": -4,
      "name": "Wood_Prehistoric_Trunk_Full"
    },
    {
      "x": -1,
      "y": 6,
      "z": -4,
      "name": "Wood_Prehistoric_Trunk_Full"
    },
    {
      "x": -1,
      "y": 7,
      "z": -4,
      "name": "Wood_Prehistoric_Trunk_Full"
    },
    {
      "x": -1,
      "y": 8,
      "z": -4,
      "name": "Wood_Prehistoric_Trunk_Full"
    },
    {
      "x": -1,
      "y": 48,
      "z": -4,
      "name": "Plant_Leaves_Bamboo"
    },
    {
      "x": -1,
      "y": 49,
      "z": -4,
      "name": "Plant_Leaves_Bamboo"
    },
    {
      "x": -1,
      "y": 50,
      "z": -4,
      "name": "Plant_Leaves_Bamboo"
    },
    {
      "x": -1,
      "y": 4,
      "z": -3,
      "name": "Wood_Prehistoric_Trunk_Full"
    },
    {
      "x": -1,
      "y": 5,
      "z": -3,
      "name": "Wood_Prehistoric_Trunk_Full"
    },
    {
      "x": -1,
      "y": 6,
      "z": -3,
      "name": "Wood_Prehistoric_Trunk_Full"
    },
    {
      "x": -1,
      "y": 7,
      "z": -3,
      "name": "Wood_Prehistoric_Trunk_Full"
    },
    {
      "x": -1,
      "y": 8,
      "z": -3,
      "name": "Wood_Prehistoric_Trunk_Full"
    },
    {
      "x": -1,
      "y": 9,
      "z": -3,
      "name": "Wood_Prehistoric_Trunk_Full"
    },
    {
      "x": -1,
      "y": 10,
      "z": -3,
      "name": "Wood_Prehistoric_Trunk_Full"
    },
    {
      "x": -1,
      "y": 11,
      "z": -3,
      "name": "Wood_Prehistoric_Trunk_Full"
    },
    {
      "x": -1,
      "y": 12,
      "z": -3,
      "name": "Wood_Prehistoric_Trunk_Full"
    },
    {
      "x": -1,
      "y": 13,
      "z": -3,
      "name": "Wood_Prehistoric_Trunk_Full"
    },
    {
      "x": -1,
      "y": 14,
      "z": -3,
      "name": "Wood_Prehistoric_Trunk_Full"
    },
    {
      "x": -1,
      "y": 15,
      "z": -3,
      "name": "Wood_Prehistoric_Trunk_Full"
    },
    {
      "x": -1,
      "y": 16,
      "z": -3,
      "name": "Wood_Prehistoric_Trunk_Full"
    },
    {
      "x": -1,
      "y": 17,
      "z": -3,
      "name": "Wood_Prehistoric_Trunk_Full"
    },
    {
      "x": -1,
      "y": 18,
      "z": -3,
      "name": "Wood_Prehistoric_Trunk_Full"
    },
    {
      "x": -1,
      "y": 19,
      "z": -3,
      "name": "Wood_Prehistoric_Trunk_Full"
    },
    {
      "x": -1,
      "y": 20,
      "z": -3,
      "name": "Wood_Prehistoric_Trunk_Full"
    },
    {
      "x": -1,
      "y": 21,
      "z": -3,
      "name": "Wood_Prehistoric_Trunk_Full"
    },
    {
      "x": -1,
      "y": 22,
      "z": -3,
      "name": "Wood_Prehistoric_Trunk_Full"
    },
    {
      "x": -1,
      "y": 23,
      "z": -3,
      "name": "Wood_Prehistoric_Trunk_Full"
    },
    {
      "x": -1,
      "y": 24,
      "z": -3,
      "name": "Wood_Prehistoric_Trunk_Full"
    },
    {
      "x": -1,
      "y": 25,
      "z": -3,
      "name": "Wood_Prehistoric_Trunk_Full"
    },
    {
      "x": -1,
      "y": 26,
      "z": -3,
      "name": "Wood_Prehistoric_Trunk_Full"
    },
    {
      "x": -1,
      "y": 27,
      "z": -3,
      "name": "Wood_Prehistoric_Trunk_Full"
    },
    {
      "x": -1,
      "y": 28,
      "z": -3,
      "name": "Wood_Prehistoric_Trunk_Full"
    },
    {
      "x": -1,
      "y": 48,
      "z": -3,
      "name": "Plant_Leaves_Bamboo"
    },
    {
      "x": -1,
      "y": 49,
      "z": -3,
      "name": "Plant_Leaves_Bamboo"
    },
    {
      "x": -1,
      "y": 50,
      "z": -3,
      "name": "Plant_Leaves_Bamboo"
    },
    {
      "x": -1,
      "y": 4,
      "z": -2,
      "name": "Wood_Prehistoric_Trunk_Full"
    },
    {
      "x": -1,
      "y": 5,
      "z": -2,
      "name": "Wood_Prehistoric_Trunk_Full"
    },
    {
      "x": -1,
      "y": 6,
      "z": -2,
      "name": "Wood_Prehistoric_Trunk_Full"
    },
    {
      "x": -1,
      "y": 7,
      "z": -2,
      "name": "Wood_Prehistoric_Trunk_Full"
    },
    {
      "x": -1,
      "y": 8,
      "z": -2,
      "name": "Wood_Prehistoric_Trunk_Full"
    },
    {
      "x": -1,
      "y": 9,
      "z": -2,
      "name": "Wood_Prehistoric_Trunk_Full"
    },
    {
      "x": -1,
      "y": 10,
      "z": -2,
      "name": "Wood_Prehistoric_Trunk_Full"
    },
    {
      "x": -1,
      "y": 11,
      "z": -2,
      "name": "Wood_Prehistoric_Trunk_Full"
    },
    {
      "x": -1,
      "y": 12,
      "z": -2,
      "name": "Wood_Prehistoric_Trunk_Full"
    },
    {
      "x": -1,
      "y": 13,
      "z": -2,
      "name": "Wood_Prehistoric_Trunk_Full"
    },
    {
      "x": -1,
      "y": 14,
      "z": -2,
      "name": "Wood_Prehistoric_Trunk_Full"
    },
    {
      "x": -1,
      "y": 15,
      "z": -2,
      "name": "Wood_Prehistoric_Trunk_Full"
    },
    {
      "x": -1,
      "y": 16,
      "z": -2,
      "name": "Wood_Prehistoric_Trunk_Full"
    },
    {
      "x": -1,
      "y": 17,
      "z": -2,
      "name": "Wood_Prehistoric_Trunk_Full"
    },
    {
      "x": -1,
      "y": 18,
      "z": -2,
      "name": "Wood_Prehistoric_Trunk_Full"
    },
    {
      "x": -1,
      "y": 19,
      "z": -2,
      "name": "Wood_Prehistoric_Trunk_Full"
    },
    {
      "x": -1,
      "y": 20,
      "z": -2,
      "name": "Wood_Prehistoric_Trunk_Full"
    },
    {
      "x": -1,
      "y": 21,
      "z": -2,
      "name": "Wood_Prehistoric_Trunk_Full"
    },
    {
      "x": -1,
      "y": 22,
      "z": -2,
      "name": "Wood_Prehistoric_Trunk_Full"
    },
    {
      "x": -1,
      "y": 23,
      "z": -2,
      "name": "Wood_Prehistoric_Trunk_Full"
    },
    {
      "x": -1,
      "y": 24,
      "z": -2,
      "name": "Wood_Prehistoric_Trunk_Full"
    },
    {
      "x": -1,
      "y": 25,
      "z": -2,
      "name": "Wood_Prehistoric_Trunk_Full"
    },
    {
      "x": -1,
      "y": 26,
      "z": -2,
      "name": "Wood_Prehistoric_Trunk_Full"
    },
    {
      "x": -1,
      "y": 27,
      "z": -2,
      "name": "Wood_Prehistoric_Trunk_Full"
    },
    {
      "x": -1,
      "y": 28,
      "z": -2,
      "name": "Wood_Prehistoric_Trunk_Full"
    },
    {
      "x": -1,
      "y": 29,
      "z": -2,
      "name": "Wood_Prehistoric_Trunk_Full"
    },
    {
      "x": -1,
      "y": 30,
      "z": -2,
      "name": "Wood_Prehistoric_Trunk_Full"
    },
    {
      "x": -1,
      "y": 31,
      "z": -2,
      "name": "Wood_Prehistoric_Trunk_Full"
    },
    {
      "x": -1,
      "y": 32,
      "z": -2,
      "name": "Wood_Prehistoric_Trunk_Full"
    },
    {
      "x": -1,
      "y": 33,
      "z": -2,
      "name": "Plant_Moss_Rug_Yellow"
    },
    {
      "x": -1,
      "y": 45,
      "z": -2,
      "name": "Wood_Prehistoric_Branch_Corner",
      "rotation": 2
    },
    {
      "x": -1,
      "y": 46,
      "z": -2,
      "name": "Wood_Prehistoric_Branch_Corner",
      "rotation": 11
    },
    {
      "x": -1,
      "y": 49,
      "z": -2,
      "name": "Plant_Leaves_Bamboo"
    },
    {
      "x": -1,
      "y": 50,
      "z": -2,
      "name": "Plant_Leaves_Bamboo"
    },
    {
      "x": -1,
      "y": 4,
      "z": -1,
      "name": "Wood_Prehistoric_Trunk_Full"
    },
    {
      "x": -1,
      "y": 5,
      "z": -1,
      "name": "Wood_Prehistoric_Trunk_Full"
    },
    {
      "x": -1,
      "y": 6,
      "z": -1,
      "name": "Wood_Prehistoric_Trunk_Full"
    },
    {
      "x": -1,
      "y": 7,
      "z": -1,
      "name": "Wood_Prehistoric_Trunk_Full"
    },
    {
      "x": -1,
      "y": 8,
      "z": -1,
      "name": "Wood_Prehistoric_Trunk_Full"
    },
    {
      "x": -1,
      "y": 9,
      "z": -1,
      "name": "Wood_Prehistoric_Trunk_Full"
    },
    {
      "x": -1,
      "y": 10,
      "z": -1,
      "name": "Wood_Prehistoric_Trunk_Full"
    },
    {
      "x": -1,
      "y": 11,
      "z": -1,
      "name": "Wood_Prehistoric_Trunk_Full"
    },
    {
      "x": -1,
      "y": 12,
      "z": -1,
      "name": "Wood_Prehistoric_Trunk_Full"
    },
    {
      "x": -1,
      "y": 13,
      "z": -1,
      "name": "Wood_Prehistoric_Trunk_Full"
    },
    {
      "x": -1,
      "y": 14,
      "z": -1,
      "name": "Wood_Prehistoric_Trunk_Full"
    },
    {
      "x": -1,
      "y": 15,
      "z": -1,
      "name": "Wood_Prehistoric_Trunk_Full"
    },
    {
      "x": -1,
      "y": 16,
      "z": -1,
      "name": "Wood_Prehistoric_Trunk_Full"
    },
    {
      "x": -1,
      "y": 17,
      "z": -1,
      "name": "Wood_Prehistoric_Trunk_Full"
    },
    {
      "x": -1,
      "y": 18,
      "z": -1,
      "name": "Wood_Prehistoric_Trunk_Full"
    },
    {
      "x": -1,
      "y": 19,
      "z": -1,
      "name": "Wood_Prehistoric_Trunk_Full"
    },
    {
      "x": -1,
      "y": 20,
      "z": -1,
      "name": "Wood_Prehistoric_Trunk_Full"
    },
    {
      "x": -1,
      "y": 21,
      "z": -1,
      "name": "Wood_Prehistoric_Trunk_Full"
    },
    {
      "x": -1,
      "y": 22,
      "z": -1,
      "name": "Wood_Prehistoric_Trunk_Full"
    },
    {
      "x": -1,
      "y": 23,
      "z": -1,
      "name": "Wood_Prehistoric_Trunk_Full"
    },
    {
      "x": -1,
      "y": 24,
      "z": -1,
      "name": "Wood_Prehistoric_Trunk_Full"
    },
    {
      "x": -1,
      "y": 25,
      "z": -1,
      "name": "Wood_Prehistoric_Trunk_Full"
    },
    {
      "x": -1,
      "y": 26,
      "z": -1,
      "name": "Wood_Prehistoric_Trunk_Full"
    },
    {
      "x": -1,
      "y": 27,
      "z": -1,
      "name": "Wood_Prehistoric_Trunk_Full"
    },
    {
      "x": -1,
      "y": 28,
      "z": -1,
      "name": "Wood_Prehistoric_Trunk_Full"
    },
    {
      "x": -1,
      "y": 29,
      "z": -1,
      "name": "Wood_Prehistoric_Trunk_Full"
    },
    {
      "x": -1,
      "y": 30,
      "z": -1,
      "name": "Wood_Prehistoric_Trunk_Full"
    },
    {
      "x": -1,
      "y": 31,
      "z": -1,
      "name": "Wood_Prehistoric_Trunk_Full"
    },
    {
      "x": -1,
      "y": 32,
      "z": -1,
      "name": "Wood_Prehistoric_Trunk_Full"
    },
    {
      "x": -1,
      "y": 33,
      "z": -1,
      "name": "Plant_Moss_Rug_Yellow"
    },
    {
      "x": -1,
      "y": 45,
      "z": -1,
      "name": "Wood_Prehistoric_Branch_Long",
      "rotation": 4
    },
    {
      "x": -1,
      "y": 49,
      "z": -1,
      "name": "Plant_Leaves_Bamboo"
    },
    {
      "x": -1,
      "y": 50,
      "z": -1,
      "name": "Plant_Leaves_Bamboo"
    },
    {
      "x": -1,
      "y": 4,
      "z": 0,
      "name": "Wood_Prehistoric_Trunk_Full"
    },
    {
      "x": -1,
      "y": 5,
      "z": 0,
      "name": "Wood_Prehistoric_Trunk_Full"
    },
    {
      "x": -1,
      "y": 6,
      "z": 0,
      "name": "Wood_Prehistoric_Trunk_Full"
    },
    {
      "x": -1,
      "y": 7,
      "z": 0,
      "name": "Wood_Prehistoric_Trunk_Full"
    },
    {
      "x": -1,
      "y": 8,
      "z": 0,
      "name": "Wood_Prehistoric_Trunk_Full"
    },
    {
      "x": -1,
      "y": 9,
      "z": 0,
      "name": "Wood_Prehistoric_Trunk_Full"
    },
    {
      "x": -1,
      "y": 10,
      "z": 0,
      "name": "Wood_Prehistoric_Trunk_Full"
    },
    {
      "x": -1,
      "y": 11,
      "z": 0,
      "name": "Wood_Prehistoric_Trunk_Full"
    },
    {
      "x": -1,
      "y": 12,
      "z": 0,
      "name": "Wood_Prehistoric_Trunk_Full"
    },
    {
      "x": -1,
      "y": 13,
      "z": 0,
      "name": "Wood_Prehistoric_Trunk_Full"
    },
    {
      "x": -1,
      "y": 14,
      "z": 0,
      "name": "Wood_Prehistoric_Trunk_Full"
    },
    {
      "x": -1,
      "y": 15,
      "z": 0,
      "name": "Wood_Prehistoric_Trunk_Full"
    },
    {
      "x": -1,
      "y": 16,
      "z": 0,
      "name": "Wood_Prehistoric_Trunk_Full"
    },
    {
      "x": -1,
      "y": 17,
      "z": 0,
      "name": "Wood_Prehistoric_Trunk_Full"
    },
    {
      "x": -1,
      "y": 18,
      "z": 0,
      "name": "Wood_Prehistoric_Trunk_Full"
    },
    {
      "x": -1,
      "y": 19,
      "z": 0,
      "name": "Wood_Prehistoric_Trunk_Full"
    },
    {
      "x": -1,
      "y": 20,
      "z": 0,
      "name": "Wood_Prehistoric_Trunk_Full"
    },
    {
      "x": -1,
      "y": 21,
      "z": 0,
      "name": "Wood_Prehistoric_Trunk_Full"
    },
    {
      "x": -1,
      "y": 22,
      "z": 0,
      "name": "Wood_Prehistoric_Trunk_Full"
    },
    {
      "x": -1,
      "y": 23,
      "z": 0,
      "name": "Wood_Prehistoric_Trunk_Full"
    },
    {
      "x": -1,
      "y": 24,
      "z": 0,
      "name": "Wood_Prehistoric_Trunk_Full"
    },
    {
      "x": -1,
      "y": 25,
      "z": 0,
      "name": "Wood_Prehistoric_Trunk_Full"
    },
    {
      "x": -1,
      "y": 26,
      "z": 0,
      "name": "Wood_Prehistoric_Trunk_Full"
    },
    {
      "x": -1,
      "y": 27,
      "z": 0,
      "name": "Wood_Prehistoric_Trunk_Full"
    },
    {
      "x": -1,
      "y": 28,
      "z": 0,
      "name": "Wood_Prehistoric_Trunk_Full"
    },
    {
      "x": -1,
      "y": 29,
      "z": 0,
      "name": "Wood_Prehistoric_Trunk_Full"
    },
    {
      "x": -1,
      "y": 30,
      "z": 0,
      "name": "Wood_Prehistoric_Trunk_Full"
    },
    {
      "x": -1,
      "y": 31,
      "z": 0,
      "name": "Wood_Prehistoric_Trunk_Full"
    },
    {
      "x": -1,
      "y": 32,
      "z": 0,
      "name": "Wood_Prehistoric_Trunk_Full"
    },
    {
      "x": -1,
      "y": 33,
      "z": 0,
      "name": "Plant_Moss_Rug_Yellow"
    },
    {
      "x": -1,
      "y": 35,
      "z": 0,
      "name": "Wood_Prehistoric_Trunk_Full"
    },
    {
      "x": -1,
      "y": 36,
      "z": 0,
      "name": "Wood_Prehistoric_Trunk_Full"
    },
    {
      "x": -1,
      "y": 37,
      "z": 0,
      "name": "Wood_Prehistoric_Trunk_Full"
    },
    {
      "x": -1,
      "y": 40,
      "z": 0,
      "name": "Wood_Prehistoric_Trunk_Full"
    },
    {
      "x": -1,
      "y": 41,
      "z": 0,
      "name": "Wood_Prehistoric_Trunk_Full"
    },
    {
      "x": -1,
      "y": 42,
      "z": 0,
      "name": "Wood_Prehistoric_Trunk_Full"
    },
    {
      "x": -1,
      "y": 43,
      "z": 0,
      "name": "Wood_Prehistoric_Trunk_Full"
    },
    {
      "x": -1,
      "y": 44,
      "z": 0,
      "name": "Wood_Prehistoric_Trunk_Full"
    },
    {
      "x": -1,
      "y": 45,
      "z": 0,
      "name": "Wood_Prehistoric_Trunk_Full"
    },
    {
      "x": -1,
      "y": 46,
      "z": 0,
      "name": "Wood_Prehistoric_Trunk_Full"
    },
    {
      "x": -1,
      "y": 47,
      "z": 0,
      "name": "Wood_Prehistoric_Trunk_Full"
    },
    {
      "x": -1,
      "y": 48,
      "z": 0,
      "name": "Wood_Prehistoric_Trunk_Full"
    },
    {
      "x": -1,
      "y": 49,
      "z": 0,
      "name": "Plant_Leaves_Bamboo"
    },
    {
      "x": -1,
      "y": 50,
      "z": 0,
      "name": "Plant_Leaves_Bamboo"
    },
    {
      "x": -1,
      "y": 4,
      "z": 1,
      "name": "Wood_Prehistoric_Trunk_Full"
    },
    {
      "x": -1,
      "y": 5,
      "z": 1,
      "name": "Wood_Prehistoric_Trunk_Full"
    },
    {
      "x": -1,
      "y": 6,
      "z": 1,
      "name": "Wood_Prehistoric_Trunk_Full"
    },
    {
      "x": -1,
      "y": 7,
      "z": 1,
      "name": "Wood_Prehistoric_Trunk_Full"
    },
    {
      "x": -1,
      "y": 8,
      "z": 1,
      "name": "Wood_Prehistoric_Trunk_Full"
    },
    {
      "x": -1,
      "y": 9,
      "z": 1,
      "name": "Wood_Prehistoric_Trunk_Full"
    },
    {
      "x": -1,
      "y": 10,
      "z": 1,
      "name": "Wood_Prehistoric_Trunk_Full"
    },
    {
      "x": -1,
      "y": 11,
      "z": 1,
      "name": "Wood_Prehistoric_Trunk_Full"
    },
    {
      "x": -1,
      "y": 12,
      "z": 1,
      "name": "Wood_Prehistoric_Trunk_Full"
    },
    {
      "x": -1,
      "y": 13,
      "z": 1,
      "name": "Wood_Prehistoric_Trunk_Full"
    },
    {
      "x": -1,
      "y": 14,
      "z": 1,
      "name": "Wood_Prehistoric_Trunk_Full"
    },
    {
      "x": -1,
      "y": 15,
      "z": 1,
      "name": "Wood_Prehistoric_Trunk_Full"
    },
    {
      "x": -1,
      "y": 16,
      "z": 1,
      "name": "Wood_Prehistoric_Trunk_Full"
    },
    {
      "x": -1,
      "y": 17,
      "z": 1,
      "name": "Wood_Prehistoric_Trunk_Full"
    },
    {
      "x": -1,
      "y": 18,
      "z": 1,
      "name": "Wood_Prehistoric_Trunk_Full"
    },
    {
      "x": -1,
      "y": 19,
      "z": 1,
      "name": "Wood_Prehistoric_Trunk_Full"
    },
    {
      "x": -1,
      "y": 20,
      "z": 1,
      "name": "Wood_Prehistoric_Trunk_Full"
    },
    {
      "x": -1,
      "y": 21,
      "z": 1,
      "name": "Wood_Prehistoric_Trunk_Full"
    },
    {
      "x": -1,
      "y": 22,
      "z": 1,
      "name": "Wood_Prehistoric_Trunk_Full"
    },
    {
      "x": -1,
      "y": 23,
      "z": 1,
      "name": "Wood_Prehistoric_Trunk_Full"
    },
    {
      "x": -1,
      "y": 24,
      "z": 1,
      "name": "Wood_Prehistoric_Trunk_Full"
    },
    {
      "x": -1,
      "y": 25,
      "z": 1,
      "name": "Wood_Prehistoric_Trunk_Full"
    },
    {
      "x": -1,
      "y": 26,
      "z": 1,
      "name": "Wood_Prehistoric_Trunk_Full"
    },
    {
      "x": -1,
      "y": 27,
      "z": 1,
      "name": "Wood_Prehistoric_Trunk_Full"
    },
    {
      "x": -1,
      "y": 28,
      "z": 1,
      "name": "Wood_Prehistoric_Trunk_Full"
    },
    {
      "x": -1,
      "y": 30,
      "z": 1,
      "name": "Wood_Prehistoric_Trunk_Full"
    },
    {
      "x": -1,
      "y": 31,
      "z": 1,
      "name": "Wood_Prehistoric_Trunk_Full"
    },
    {
      "x": -1,
      "y": 46,
      "z": 1,
      "name": "Wood_Prehistoric_Branch_Long",
      "rotation": 4
    },
    {
      "x": -1,
      "y": 48,
      "z": 1,
      "name": "Plant_Leaves_Bamboo"
    },
    {
      "x": -1,
      "y": 49,
      "z": 1,
      "name": "Plant_Leaves_Bamboo"
    },
    {
      "x": -1,
      "y": 50,
      "z": 1,
      "name": "Plant_Leaves_Bamboo"
    },
    {
      "x": -1,
      "y": 4,
      "z": 2,
      "name": "Wood_Prehistoric_Trunk_Full"
    },
    {
      "x": -1,
      "y": 5,
      "z": 2,
      "name": "Wood_Prehistoric_Trunk_Full"
    },
    {
      "x": -1,
      "y": 6,
      "z": 2,
      "name": "Wood_Prehistoric_Trunk_Full"
    },
    {
      "x": -1,
      "y": 7,
      "z": 2,
      "name": "Wood_Prehistoric_Trunk_Full"
    },
    {
      "x": -1,
      "y": 8,
      "z": 2,
      "name": "Wood_Prehistoric_Trunk_Full"
    },
    {
      "x": -1,
      "y": 9,
      "z": 2,
      "name": "Wood_Prehistoric_Trunk_Full"
    },
    {
      "x": -1,
      "y": 10,
      "z": 2,
      "name": "Wood_Prehistoric_Trunk_Full"
    },
    {
      "x": -1,
      "y": 46,
      "z": 2,
      "name": "Wood_Prehistoric_Branch_Corner"
    },
    {
      "x": -1,
      "y": 47,
      "z": 2,
      "name": "Wood_Prehistoric_Branch_Long"
    },
    {
      "x": -1,
      "y": 48,
      "z": 2,
      "name": "Plant_Leaves_Bamboo"
    },
    {
      "x": -1,
      "y": 49,
      "z": 2,
      "name": "Plant_Leaves_Bamboo"
    },
    {
      "x": -1,
      "y": 4,
      "z": 3,
      "name": "Wood_Prehistoric_Trunk_Full"
    },
    {
      "x": -1,
      "y": 5,
      "z": 3,
      "name": "Wood_Prehistoric_Trunk_Full"
    },
    {
      "x": -1,
      "y": 6,
      "z": 3,
      "name": "Wood_Prehistoric_Trunk_Full"
    },
    {
      "x": -1,
      "y": 7,
      "z": 3,
      "name": "Wood_Prehistoric_Trunk_Full"
    },
    {
      "x": -1,
      "y": 8,
      "z": 3,
      "name": "Wood_Prehistoric_Trunk_Full"
    },
    {
      "x": -1,
      "y": 36,
      "z": 3,
      "name": "Wood_Prehistoric_Trunk_Full"
    },
    {
      "x": -1,
      "y": 37,
      "z": 3,
      "name": "Wood_Prehistoric_Trunk_Full"
    },
    {
      "x": -1,
      "y": 43,
      "z": 3,
      "name": "Plant_Leaves_Bamboo"
    },
    {
      "x": -1,
      "y": 47,
      "z": 3,
      "name": "Plant_Leaves_Bamboo"
    },
    {
      "x": -1,
      "y": 48,
      "z": 3,
      "name": "Plant_Leaves_Bamboo"
    },
    {
      "x": -1,
      "y": 49,
      "z": 3,
      "name": "Plant_Leaves_Bamboo"
    },
    {
      "x": -1,
      "y": 4,
      "z": 4,
      "name": "Wood_Prehistoric_Trunk_Full"
    },
    {
      "x": -1,
      "y": 5,
      "z": 4,
      "name": "Wood_Prehistoric_Trunk_Full"
    },
    {
      "x": -1,
      "y": 6,
      "z": 4,
      "name": "Wood_Prehistoric_Trunk_Full"
    },
    {
      "x": -1,
      "y": 37,
      "z": 4,
