{
  "version": 8,
  "blockIdVersion": 11,
  "anchorX": -1,
  "anchorY": 6,
  "anchorZ": 0,
  "blocks": [
    {
      "x": -5,
      "y": 17,
      "z": 0,
      "name": "Plant_Leaves_Bamboo"
    },
    {
      "x": -4,
      "y": 17,
      "z": -1,
      "name": "Plant_Leaves_Bamboo"
    },
    {
      "x": -4,
      "y": 17,
      "z": 0,
      "name": "Plant_Leaves_Bamboo"
    },
    {
      "x": -4,
      "y": 17,
      "z": 1,
      "name": "Plant_Leaves_Bamboo"
    },
    {
      "x": -4,
      "y": 18,
      "z": 1,
      "name": "Plant_Leaves_Bamboo"
    },
    {
      "x": -3,
      "y": 17,
      "z": -1,
      "name": "Plant_Leaves_Bamboo"
    },
    {
      "x": -3,
      "y": 18,
      "z": -1,
      "name": "Plant_Leaves_Bamboo"
    },
    {
      "x": -3,
      "y": 16,
      "z": 0,
      "name": "Wood_Prehistoric_Branch_Corner",
      "rotation": 3
    },
    {
      "x": -3,
      "y": 17,
      "z": 0,
      "name": "Wood_Prehistoric_Branch_Long"
    },
    {
      "x": -3,
      "y": 18,
      "z": 0,
      "name": "Plant_Leaves_Bamboo"
    },
    {
      "x": -3,
      "y": 17,
      "z": 1,
      "name": "Plant_Leaves_Bamboo"
    },
    {
      "x": -3,
      "y": 17,
      "z": 2,
      "name": "Plant_Leaves_Bamboo"
    },
    {
      "x": -2,
      "y": 17,
      "z": -1,
      "name": "Plant_Leaves_Bamboo"
    },
    {
      "x": -2,
      "y": 16,
      "z": 0,
      "name": "Wood_Prehistoric_Branch_Long",
      "rotation": 5
    },
    {
      "x": -2,
      "y": 17,
      "z": 0,
      "name": "Plant_Leaves_Bamboo"
    },
    {
      "x": -2,
      "y": 18,
      "z": 0,
      "name": "Plant_Leaves_Bamboo"
    },
    {
      "x": -2,
      "y": 27,
      "z": 3,
      "name": "Plant_Leaves_Bamboo",
      "rotation": 3
    },
    {
      "x": -1,
      "y": 16,
      "z": -3,
      "name": "Plant_Leaves_Bamboo"
    },
    {
      "x": -1,
      "y": 16,
      "z": -2,
      "name": "Plant_Leaves_Bamboo"
    },
    {
      "x": -1,
      "y": 5,
      "z": 0,
      "name": "Wood_Prehistoric_Trunk_Full"
    },
    {
      "x": -1,
      "y": 6,
      "z": 0,
      "name": "Wood_Prehistoric_Trunk_Full"
    },
    {
      "x": -1,
      "y": 7,
      "z": 0,
      "name": "Wood_Prehistoric_Trunk_Full"
    },
    {
      "x": -1,
      "y": 8,
      "z": 0,
      "name": "Wood_Prehistoric_Trunk_Full"
    },
    {
      "x": -1,
      "y": 9,
      "z": 0,
      "name": "Wood_Prehistoric_Trunk_Full"
    },
    {
      "x": -1,
      "y": 10,
      "z": 0,
      "name": "Wood_Prehistoric_Trunk_Full"
    },
    {
      "x": -1,
      "y": 11,
      "z": 0,
      "name": "Wood_Prehistoric_Trunk_Full"
    },
    {
      "x": -1,
      "y": 12,
      "z": 0,
      "name": "Wood_Prehistoric_Trunk_Full"
    },
    {
      "x": -1,
      "y": 13,
      "z": 0,
      "name": "Wood_Prehistoric_Trunk_Full"
    },
    {
      "x": -1,
      "y": 16,
      "z": 0,
      "name": "Wood_Prehistoric_Branch_Long",
      "rotation": 5
    },
    {
      "x": -1,
      "y": 15,
      "z": 2,
      "name": "Plant_Leaves_Bamboo"
    },
    {
      "x": -1,
      "y": 27,
      "z": 2,
      "name": "Plant_Leaves_Bamboo",
      "rotation": 3
    },
    {
      "x": -1,
      "y": 15,
      "z": 3,
      "name": "Plant_Leaves_Bamboo"
    },
    {
      "x": -1,
      "y": 26,
      "z": 3,
      "name": "Plant_Leaves_Bamboo",
      "rotation": 3
    },
    {
      "x": -1,
      "y": 27,
      "z": 3,
      "name": "Plant_Leaves_Bamboo",
      "rotation": 3
    },
    {
      "x": -1,
      "y": 15,
      "z": 4,
      "name": "Plant_Leaves_Bamboo"
    },
    {
      "x": 0,
      "y": 16,
      "z": -4,
      "name": "Plant_Leaves_Bamboo"
    },
    {
      "x": 0,
      "y": 16,
      "z": -3,
      "name": "Plant_Leaves_Bamboo"
    },
    {
      "x": 0,
      "y": 17,
      "z": -3,
      "name": "Plant_Leaves_Bamboo"
    },
    {
      "x": 0,
      "y": 15,
      "z": -2,
      "name": "Wood_Prehistoric_Branch_Corner",
      "rotation": 2
    },
    {
      "x": 0,
      "y": 16,
      "z": -2,
      "name": "Wood_Prehistoric_Branch_Long"
    },
    {
      "x": 0,
      "y": 17,
      "z": -2,
      "name": "Plant_Leaves_Bamboo"
    },
    {
      "x": 0,
      "y": 15,
      "z": -1,
      "name": "Wood_Prehistoric_Branch_Long",
      "rotation": 4
    },
    {
      "x": 0,
      "y": 16,
      "z": -1,
      "name": "Plant_Leaves_Bamboo"
    },
    {
      "x": 0,
      "y": 13,
      "z": 0,
      "name": "Wood_Prehistoric_Trunk_Full"
    },
    {
      "x": 0,
      "y": 14,
      "z": 0,
      "name": "Wood_Prehistoric_Trunk_Full"
    },
    {
      "x": 0,
      "y": 15,
      "z": 0,
      "name": "Wood_Prehistoric_Trunk_Full"
    },
    {
      "x": 0,
      "y": 16,
      "z": 0,
      "name": "Wood_Prehistoric_Trunk_Full"
    },
    {
      "x": 0,
      "y": 17,
      "z": 0,
      "name": "Wood_Prehistoric_Trunk_Full",
      "rotation": 3
    },
    {
      "x": 0,
      "y": 18,
      "z": 0,
      "name": "Wood_Prehistoric_Trunk_Full",
      "rotation": 3
    },
    {
      "x": 0,
      "y": 19,
      "z": 0,
      "name": "Plant_Moss_Rug_Yellow",
      "rotation": 3
    },
    {
      "x": 0,
      "y": 14,
      "z": 1,
      "name": "Wood_Prehistoric_Branch_Long",
      "rotation": 4
    },
    {
      "x": 0,
      "y": 18,
      "z": 1,
      "name": "Wood_Prehistoric_Trunk_Full",
      "rotation": 3
    },
    {
      "x": 0,
      "y": 19,
      "z": 1,
      "name": "Wood_Prehistoric_Trunk_Full",
      "rotation": 3
    },
    {
      "x": 0,
      "y": 20,
      "z": 1,
      "name": "Wood_Prehistoric_Trunk_Full",
      "rotation": 3
    },
    {
      "x": 0,
      "y": 21,
      "z": 1,
      "name": "Wood_Prehistoric_Trunk_Full",
      "rotation": 3
    },
    {
      "x": 0,
      "y": 22,
      "z": 1,
      "name": "Wood_Prehistoric_Trunk_Full",
      "rotation": 3
    },
    {
      "x": 0,
      "y": 23,
      "z": 1,
      "name": "Wood_Prehistoric_Trunk_Full",
      "rotation": 3
    },
    {
      "x": 0,
      "y": 14,
      "z": 2,
      "name": "Wood_Prehistoric_Branch_Long",
      "rotation": 4
    },
    {
      "x": 0,
      "y": 15,
      "z": 2,
      "name": "Plant_Leaves_Bamboo"
    },
    {
      "x": 0,
      "y": 23,
      "z": 2,
      "name": "Wood_Prehistoric_Branch_Long",
      "rotation": 4
    },
    {
      "x": 0,
      "y": 25,
      "z": 2,
      "name": "Wood_Prehistoric_Branch_Corner",
      "rotation": 2
    },
    {
      "x": 0,
      "y": 26,
      "z": 2,
      "name": "Wood_Prehistoric_Branch_Long",
      "rotation": 3
    },
    {
      "x": 0,
      "y": 27,
      "z": 2,
      "name": "Plant_Leaves_Bamboo",
      "rotation": 3
    },
    {
      "x": 0,
      "y": 28,
      "z": 2,
      "name": "Plant_Leaves_Bamboo",
      "rotation": 3
    },
    {
      "x": 0,
      "y": 14,
      "z": 3,
      "name": "Wood_Prehistoric_Branch_Corner"
    },
    {
      "x": 0,
      "y": 15,
      "z": 3,
      "name": "Wood_Prehistoric_Branch_Long"
    },
    {
      "x": 0,
      "y": 16,
      "z": 3,
      "name": "Plant_Leaves_Bamboo"
    },
    {
      "x": 0,
      "y": 23,
      "z": 3,
      "name": "Wood_Prehistoric_Branch_Corner"
    },
    {
      "x": 0,
      "y": 24,
      "z": 3,
      "name": "Wood_Prehistoric_Branch_Long",
      "rotation": 3
    },
    {
      "x": 0,
      "y": 25,
      "z": 3,
      "name": "Wood_Prehistoric_Branch_Corner",
      "rotation": 32
    },
    {
      "x": 0,
      "y": 26,
      "z": 3,
      "name": "Plant_Leaves_Bamboo",
      "rotation": 3
    },
    {
      "x": 0,
      "y": 27,
      "z": 3,
      "name": "Plant_Leaves_Bamboo",
      "rotation": 3
    },
    {
      "x": 0,
      "y": 28,
      "z": 3,
      "name": "Plant_Leaves_Bamboo",
      "rotation": 3
    },
    {
      "x": 0,
      "y": 15,
      "z": 4,
      "name": "Plant_Leaves_Bamboo"
    },
    {
      "x": 0,
      "y": 16,
      "z": 4,
      "name": "Plant_Leaves_Bamboo"
    },
    {
      "x": 0,
      "y": 25,
      "z": 4,
      "name": "Plant_Leaves_Bamboo",
      "support": 15,
      "rotation": 3
    },
    {
      "x": 0,
      "y": 26,
      "z": 4,
      "name": "Plant_Leaves_Bamboo",
      "support": 15,
      "rotation": 3
    },
    {
      "x": 0,
      "y": 15,
      "z": 5,
      "name": "Plant_Leaves_Bamboo"
    },
    {
      "x": 1,
      "y": 16,
      "z": -3,
      "name": "Plant_Leaves_Bamboo"
    },
    {
      "x": 1,
      "y": 17,
      "z": -3,
      "name": "Plant_Leaves_Bamboo"
    },
    {
      "x": 1,
      "y": 16,
      "z": -2,
      "name": "Plant_Leaves_Bamboo"
    },
    {
      "x": 1,
      "y": 20,
      "z": 0,
      "name": "Wood_Prehistoric_Trunk_Full",
      "rotation": 3
    },
    {
      "x": 1,
      "y": 21,
      "z": 0,
      "name": "Plant_Moss_Rug_Yellow",
      "rotation": 3
    },
    {
      "x": 1,
      "y": 20,
      "z": 1,
      "name": "Wood_Prehistoric_Trunk_Full",
      "rotation": 3
    },
    {
      "x": 1,
      "y": 21,
      "z": 1,
      "name": "Plant_Moss_Rug_Yellow",
      "rotation": 3
    },
    {
      "x": 1,
      "y": 25,
      "z": 1,
      "name": "Plant_Leaves_Bamboo",
      "rotation": 3
    },
    {
      "x": 1,
      "y": 25,
      "z": 2,
      "name": "Plant_Leaves_Bamboo",
      "rotation": 3
    },
    {
      "x": 1,
      "y": 27,
      "z": 2,
      "name": "Plant_Leaves_Bamboo",
      "rotation": 3
    },
    {
      "x": 1,
      "y": 15,
      "z": 3,
      "name": "Plant_Leaves_Bamboo"
    },
    {
      "x": 1,
      "y": 16,
      "z": 3,
      "name": "Plant_Leaves_Bamboo"
    },
    {
      "x": 1,
      "y": 26,
      "z": 3,
      "name": "Plant_Leaves_Bamboo",
      "rotation": 3
    },
    {
      "x": 1,
      "y": 27,
      "z": 3,
      "name": "Plant_Leaves_Bamboo",
      "rotation": 3
    },
    {
      "x": 1,
      "y": 15,
      "z": 4,
      "name": "Plant_Leaves_Bamboo"
    },
    {
      "x": 1,
      "y": 26,
      "z": 4,
      "name": "Plant_Leaves_Bamboo",
      "support": 15,
      "rotation": 3
    },
    {
      "x": 2,
      "y": 25,
      "z": -2,
      "name": "Wood_Prehistoric_Branch_Corner",
      "rotation": 2
    },
    {
      "x": 2,
      "y": 26,
      "z": -2,
      "name": "Wood_Prehistoric_Branch_Long",
      "rotation": 3
    },
    {
      "x": 2,
      "y": 27,
      "z": -2,
      "name": "Wood_Prehistoric_Branch_Corner",
      "rotation": 35
    },
    {
      "x": 2,
      "y": 25,
      "z": -1,
      "name": "Wood_Prehistoric_Branch_Long",
      "rotation": 4
    },
    {
      "x": 2,
      "y": 28,
      "z": -1,
      "name": "Plant_Leaves_Bamboo",
      "rotation": 3
    },
    {
      "x": 2,
      "y": 20,
      "z": 0,
      "name": "Wood_Prehistoric_Trunk_Full",
      "rotation": 3
    },
    {
      "x": 2,
      "y": 21,
      "z": 0,
      "name": "Wood_Prehistoric_Trunk_Full",
      "rotation": 3
    },
    {
      "x": 2,
      "y": 22,
      "z": 0,
      "name": "Wood_Prehistoric_Trunk_Full",
      "rotation": 3
    },
    {
      "x": 2,
      "y": 23,
      "z": 0,
      "name": "Wood_Prehistoric_Trunk_Full",
      "rotation": 3
    },
    {
      "x": 2,
      "y": 24,
      "z": 0,
      "name": "Wood_Prehistoric_Trunk_Full",
      "rotation": 3
    },
    {
      "x": 2,
      "y": 25,
      "z": 0,
      "name": "Wood_Prehistoric_Trunk_Full",
      "rotation": 3
    },
    {
      "x": 2,
      "y": 26,
      "z": 0,
      "name": "Plant_Leaves_Bamboo",
      "rotation": 3
    },
    {
      "x": 2,
      "y": 25,
      "z": 1,
      "name": "Plant_Leaves_Bamboo",
      "rotation": 3
    },
    {
      "x": 2,
      "y": 26,
      "z": 1,
      "name": "Plant_Leaves_Bamboo",
      "rotation": 3
    },
    {
      "x": 2,
      "y": 25,
      "z": 2,
      "name": "Plant_Leaves_Bamboo",
      "rotation": 3
    },
    {
      "x": 2,
      "y": 26,
      "z": 2,
      "name": "Plant_Leaves_Bamboo",
      "rotation": 3
    },
    {
      "x": 2,
      "y": 27,
      "z": 2,
      "name": "Plant_Leaves_Bamboo",
      "rotation": 3
    },
    {
      "x": 2,
      "y": 15,
      "z": 3,
      "name": "Plant_Leaves_Bamboo"
    },
    {
      "x": 2,
      "y": 26,
      "z": 3,
      "name": "Plant_Leaves_Bamboo",
      "rotation": 3
    },
    {
      "x": 2,
      "y": 27,
      "z": 3,
      "name": "Plant_Leaves_Bamboo",
      "rotation": 3
    },
    {
      "x": 3,
      "y": 28,
      "z": -3,
      "name": "Plant_Leaves_Bamboo",
      "support": 15,
      "rotation": 3
    },
    {
      "x": 3,
      "y": 27,
      "z": -2,
      "name": "Wood_Prehistoric_Branch_Corner",
      "rotation": 1
    },
    {
      "x": 3,
      "y": 28,
      "z": -2,
      "name": "Wood_Prehistoric_Branch_Long",
      "rotation": 3
    },
    {
      "x": 3,
      "y": 29,
      "z": -2,
      "name": "Plant_Leaves_Bamboo",
      "rotation": 3
    },
    {
      "x": 3,
      "y": 28,
      "z": -1,
      "name": "Plant_Leaves_Bamboo",
      "rotation": 3
    },
    {
      "x": 3,
      "y": 29,
      "z": -1,
      "name": "Plant_Leaves_Bamboo",
      "rotation": 3
    },
    {
      "x": 3,
      "y": 23,
      "z": 0,
      "name": "Wood_Prehistoric_Branch_Long",
      "rotation": 7
    },
    {
      "x": 3,
      "y": 25,
      "z": 0,
      "name": "Plant_Leaves_Bamboo",
      "rotation": 3
    },
    {
      "x": 3,
      "y": 26,
      "z": 0,
      "name": "Plant_Leaves_Bamboo",
      "rotation": 3
    },
    {
      "x": 3,
      "y": 27,
      "z": 0,
      "name": "Plant_Leaves_Bamboo",
      "rotation": 3
    },
    {
      "x": 3,
      "y": 28,
      "z": 0,
      "name": "Plant_Leaves_Bamboo",
      "rotation": 3
    },
    {
      "x": 3,
      "y": 25,
      "z": 1,
      "name": "Plant_Leaves_Bamboo",
      "rotation": 3
    },
    {
      "x": 3,
      "y": 26,
      "z": 1,
      "name": "Plant_Leaves_Bamboo",
      "rotation": 3
    },
    {
      "x": 3,
      "y": 25,
      "z": 2,
      "name": "Plant_Leaves_Bamboo",
      "rotation": 3
    },
    {
      "x": 4,
      "y": 26,
      "z": -2,
      "name": "Plant_Leaves_Bamboo",
      "support": 15,
      "rotation": 3
    },
    {
      "x": 4,
      "y": 28,
      "z": -2,
      "name": "Plant_Leaves_Bamboo",
      "rotation": 3
    },
    {
      "x": 4,
      "y": 29,
      "z": -2,
      "name": "Plant_Leaves_Bamboo",
      "rotation": 3
    },
    {
      "x": 4,
      "y": 25,
      "z": -1,
      "name": "Wood_Prehistoric_Branch_Corner",
      "rotation": 2
    },
    {
      "x": 4,
      "y": 26,
      "z": -1,
      "name": "Wood_Prehistoric_Branch_Long",
      "rotation": 3
    },
    {
      "x": 4,
      "y": 27,
      "z": -1,
      "name": "Plant_Leaves_Bamboo",
      "rotation": 3
    },
    {
      "x": 4,
      "y": 28,
      "z": -1,
      "name": "Plant_Leaves_Bamboo",
      "rotation": 3
    },
    {
      "x": 4,
      "y": 29,
      "z": -1,
      "name": "Plant_Leaves_Bamboo",
      "rotation": 3
    },
    {
      "x": 4,
      "y": 23,
      "z": 0,
      "name": "Wood_Prehistoric_Branch_Corner",
      "rotation": 1
    },
    {
      "x": 4,
      "y": 24,
      "z": 0,
      "name": "Wood_Prehistoric_Branch_Long",
      "rotation": 3
    },
    {
      "x": 4,
      "y": 25,
      "z": 0,
      "name": "Wood_Prehistoric_Branch_Corner",
      "rotation": 32
    },
    {
      "x": 4,
      "y": 26,
      "z": 0,
      "name": "Plant_Leaves_Bamboo",
      "support": 15,
      "rotation": 3
    },
    {
      "x": 4,
      "y": 27,
      "z": 0,
      "name": "Plant_Leaves_Bamboo",
      "rotation": 3
    },
    {
      "x": 4,
      "y": 28,
      "z": 0,
      "name": "Plant_Leaves_Bamboo",
      "rotation": 3
    },
    {
      "x": 4,
      "y": 25,
      "z": 1,
      "name": "Plant_Leaves_Bamboo",
      "rotation": 3
    },
    {
      "x": 4,
      "y": 27,
      "z": 1,
      "name": "Plant_Leaves_Bamboo",
      "rotation": 3
    },
    {
      "x": 5,
      "y": 26,
      "z": -2,
      "name": "Plant_Leaves_Bamboo",
      "support": 15,
      "rotation": 3
    },
    {
      "x": 5,
      "y": 26,
      "z": -1,
      "name": "Plant_Leaves_Bamboo",
      "support": 15,
      "rotation": 3
    },
    {
      "x": 5,
      "y": 26,
      "z": 0,
      "name": "Plant_Leaves_Bamboo",
      "support": 15,
      "rotation": 3
    },
    {
      "x": 5,
      "y": 26,
      "z": 1,
      "name": "Plant_Leaves_Bamboo",
      "support": 15,
      "rotation": 3
    }
  ]
}