{
  "version": 8,
  "blockIdVersion": 11,
  "anchorX": 0,
  "anchorY": 9,
  "anchorZ": -4,
  "blocks": [
    {
      "x": -12,
      "y": 46,
      "z": -4,
      "name": "Plant_Leaves_Beech_Max_Support",
      "support": 15
    },
    {
      "x": -11,
      "y": 48,
      "z": -6,
      "name": "Plant_Leaves_Beech_Max_Support",
      "support": 15
    },
    {
      "x": -11,
      "y": 50,
      "z": -6,
      "name": "Plant_Leaves_Beech_Max_Support"
    },
    {
      "x": -11,
      "y": 48,
      "z": -5,
      "name": "Plant_Leaves_Beech_Max_Support"
    },
    {
      "x": -11,
      "y": 46,
      "z": -4,
      "name": "Plant_Leaves_Beech_Max_Support",
      "support": 15
    },
    {
      "x": -11,
      "y": 49,
      "z": -4,
      "name": "Plant_Leaves_Beech_Max_Support"
    },
    {
      "x": -11,
      "y": 50,
      "z": -4,
      "name": "Plant_Leaves_Beech_Max_Support"
    },
    {
      "x": -11,
      "y": 37,
      "z": 0,
      "name": "Plant_Leaves_Beech_Max_Support",
      "support": 15
    },
    {
      "x": -10,
      "y": 47,
      "z": -9,
      "name": "Plant_Leaves_Beech_Max_Support",
      "support": 15
    },
    {
      "x": -10,
      "y": 22,
      "z": -8,
      "name": "Plant_Leaves_Beech_Max_Support",
      "support": 15
    },
    {
      "x": -10,
      "y": 46,
      "z": -8,
      "name": "Plant_Leaves_Beech_Max_Support",
      "support": 15
    },
    {
      "x": -10,
      "y": 47,
      "z": -8,
      "name": "Plant_Leaves_Beech_Max_Support",
      "support": 15
    },
    {
      "x": -10,
      "y": 48,
      "z": -8,
      "name": "Plant_Leaves_Beech_Max_Support",
      "support": 15
    },
    {
      "x": -10,
      "y": 40,
      "z": -7,
      "name": "Plant_Leaves_Beech_Max_Support"
    },
    {
      "x": -10,
      "y": 47,
      "z": -7,
      "name": "Plant_Leaves_Beech_Max_Support",
      "support": 15
    },
    {
      "x": -10,
      "y": 48,
      "z": -7,
      "name": "Plant_Leaves_Beech_Max_Support"
    },
    {
      "x": -10,
      "y": 49,
      "z": -7,
      "name": "Plant_Leaves_Beech_Max_Support",
      "support": 15
    },
    {
      "x": -10,
      "y": 50,
      "z": -7,
      "name": "Plant_Leaves_Beech_Max_Support"
    },
    {
      "x": -10,
      "y": 36,
      "z": -6,
      "name": "Plant_Leaves_Beech_Max_Support",
      "support": 15
    },
    {
      "x": -10,
      "y": 39,
      "z": -6,
      "name": "Plant_Leaves_Beech_Max_Support"
    },
    {
      "x": -10,
      "y": 47,
      "z": -6,
      "name": "Plant_Leaves_Beech_Max_Support"
    },
    {
      "x": -10,
      "y": 48,
      "z": -6,
      "name": "Plant_Leaves_Beech_Max_Support"
    },
    {
      "x": -10,
      "y": 51,
      "z": -6,
      "name": "Plant_Leaves_Beech_Max_Support"
    },
    {
      "x": -10,
      "y": 40,
      "z": -5,
      "name": "Plant_Leaves_Beech_Max_Support"
    },
    {
      "x": -10,
      "y": 46,
      "z": -5,
      "name": "Plant_Leaves_Beech_Max_Support",
      "support": 15
    },
    {
      "x": -10,
      "y": 47,
      "z": -5,
      "name": "Plant_Leaves_Beech_Max_Support"
    },
    {
      "x": -10,
      "y": 49,
      "z": -5,
      "name": "Plant_Leaves_Beech_Max_Support"
    },
    {
      "x": -10,
      "y": 50,
      "z": -5,
      "name": "Plant_Leaves_Beech_Max_Support"
    },
    {
      "x": -10,
      "y": 51,
      "z": -5,
      "name": "Plant_Leaves_Beech_Max_Support"
    },
    {
      "x": -10,
      "y": 46,
      "z": -4,
      "name": "Plant_Leaves_Beech_Max_Support",
      "support": 15
    },
    {
      "x": -10,
      "y": 47,
      "z": -4,
      "name": "Plant_Leaves_Beech_Max_Support"
    },
    {
      "x": -10,
      "y": 50,
      "z": -4,
      "name": "Plant_Leaves_Beech_Max_Support"
    },
    {
      "x": -10,
      "y": 51,
      "z": -4,
      "name": "Plant_Leaves_Beech_Max_Support"
    },
    {
      "x": -10,
      "y": 46,
      "z": -3,
      "name": "Plant_Leaves_Beech_Max_Support",
      "support": 15
    },
    {
      "x": -10,
      "y": 49,
      "z": -3,
      "name": "Plant_Leaves_Beech_Max_Support"
    },
    {
      "x": -10,
      "y": 38,
      "z": -2,
      "name": "Plant_Leaves_Beech_Max_Support"
    },
    {
      "x": -10,
      "y": 39,
      "z": -1,
      "name": "Plant_Leaves_Beech_Max_Support"
    },
    {
      "x": -10,
      "y": 37,
      "z": 0,
      "name": "Plant_Leaves_Beech_Max_Support",
      "support": 15
    },
    {
      "x": -10,
      "y": 38,
      "z": 0,
      "name": "Plant_Leaves_Beech_Max_Support"
    },
    {
      "x": -9,
      "y": 49,
      "z": -11,
      "name": "Plant_Leaves_Beech_Max_Support"
    },
    {
      "x": -9,
      "y": 51,
      "z": -11,
      "name": "Plant_Leaves_Beech_Max_Support"
    },
    {
      "x": -9,
      "y": 47,
      "z": -10,
      "name": "Plant_Leaves_Beech_Max_Support",
      "support": 15
    },
    {
      "x": -9,
      "y": 49,
      "z": -10,
      "name": "Plant_Leaves_Beech_Max_Support"
    },
    {
      "x": -9,
      "y": 50,
      "z": -10,
      "name": "Plant_Leaves_Beech_Max_Support"
    },
    {
      "x": -9,
      "y": 51,
      "z": -10,
      "name": "Plant_Leaves_Beech_Max_Support"
    },
    {
      "x": -9,
      "y": 22,
      "z": -9,
      "name": "Plant_Leaves_Beech_Max_Support"
    },
    {
      "x": -9,
      "y": 37,
      "z": -9,
      "name": "Plant_Leaves_Beech_Max_Support",
      "support": 15
    },
    {
      "x": -9,
      "y": 47,
      "z": -9,
      "name": "Plant_Leaves_Beech_Max_Support",
      "support": 15
    },
    {
      "x": -9,
      "y": 48,
      "z": -9,
      "name": "Plant_Leaves_Beech_Max_Support",
      "support": 15
    },
    {
      "x": -9,
      "y": 49,
      "z": -9,
      "name": "Plant_Leaves_Beech_Max_Support"
    },
    {
      "x": -9,
      "y": 21,
      "z": -8,
      "name": "Plant_Leaves_Beech_Max_Support"
    },
    {
      "x": -9,
      "y": 22,
      "z": -8,
      "name": "Plant_Leaves_Beech_Max_Support",
      "support": 15
    },
    {
      "x": -9,
      "y": 37,
      "z": -8,
      "name": "Plant_Leaves_Beech_Max_Support",
      "support": 15
    },
    {
      "x": -9,
      "y": 39,
      "z": -8,
      "name": "Plant_Leaves_Beech_Max_Support"
    },
    {
      "x": -9,
      "y": 40,
      "z": -8,
      "name": "Plant_Leaves_Beech_Max_Support"
    },
    {
      "x": -9,
      "y": 48,
      "z": -8,
      "name": "Plant_Leaves_Beech_Max_Support"
    },
    {
      "x": -9,
      "y": 49,
      "z": -8,
      "name": "Plant_Leaves_Beech_Max_Support",
      "support": 15
    },
    {
      "x": -9,
      "y": 51,
      "z": -8,
      "name": "Plant_Leaves_Beech_Max_Support"
    },
    {
      "x": -9,
      "y": 22,
      "z": -7,
      "name": "Plant_Leaves_Beech_Max_Support"
    },
    {
      "x": -9,
      "y": 35,
      "z": -7,
      "name": "Plant_Leaves_Beech_Max_Support",
      "support": 15
    },
    {
      "x": -9,
      "y": 36,
      "z": -7,
      "name": "Plant_Leaves_Beech_Max_Support",
      "support": 15
    },
    {
      "x": -9,
      "y": 37,
      "z": -7,
      "name": "Plant_Leaves_Beech_Max_Support"
    },
    {
      "x": -9,
      "y": 38,
      "z": -7,
      "name": "Plant_Leaves_Beech_Max_Support",
      "support": 15
    },
    {
      "x": -9,
      "y": 39,
      "z": -7,
      "name": "Plant_Leaves_Beech_Max_Support"
    },
    {
      "x": -9,
      "y": 40,
      "z": -7,
      "name": "Plant_Leaves_Beech_Max_Support"
    },
    {
      "x": -9,
      "y": 41,
      "z": -7,
      "name": "Plant_Leaves_Beech_Max_Support"
    },
    {
      "x": -9,
      "y": 47,
      "z": -7,
      "name": "Plant_Leaves_Beech_Max_Support"
    },
    {
      "x": -9,
      "y": 49,
      "z": -7,
      "name": "Plant_Leaves_Beech_Max_Support"
    },
    {
      "x": -9,
      "y": 50,
      "z": -7,
      "name": "Plant_Leaves_Beech_Max_Support"
    },
    {
      "x": -9,
      "y": 51,
      "z": -7,
      "name": "Plant_Leaves_Beech_Max_Support"
    },
    {
      "x": -9,
      "y": 36,
      "z": -6,
      "name": "Plant_Leaves_Beech_Max_Support",
      "support": 15
    },
    {
      "x": -9,
      "y": 37,
      "z": -6,
      "name": "Plant_Leaves_Beech_Max_Support"
    },
    {
      "x": -9,
      "y": 38,
      "z": -6,
      "name": "Plant_Leaves_Beech_Max_Support"
    },
    {
      "x": -9,
      "y": 39,
      "z": -6,
      "name": "Plant_Leaves_Beech_Max_Support"
    },
    {
      "x": -9,
      "y": 40,
      "z": -6,
      "name": "Plant_Leaves_Beech_Max_Support"
    },
    {
      "x": -9,
      "y": 41,
      "z": -6,
      "name": "Plant_Leaves_Beech_Max_Support"
    },
    {
      "x": -9,
      "y": 46,
      "z": -6,
      "name": "Plant_Leaves_Beech_Max_Support"
    },
    {
      "x": -9,
      "y": 49,
      "z": -6,
      "name": "Plant_Leaves_Beech_Max_Support"
    },
    {
      "x": -9,
      "y": 50,
      "z": -6,
      "name": "Plant_Leaves_Beech_Max_Support"
    },
    {
      "x": -9,
      "y": 51,
      "z": -6,
      "name": "Plant_Leaves_Beech_Max_Support"
    },
    {
      "x": -9,
      "y": 22,
      "z": -5,
      "name": "Plant_Leaves_Beech_Max_Support"
    },
    {
      "x": -9,
      "y": 23,
      "z": -5,
      "name": "Plant_Leaves_Beech_Max_Support"
    },
    {
      "x": -9,
      "y": 24,
      "z": -5,
      "name": "Plant_Leaves_Beech_Max_Support"
    },
    {
      "x": -9,
      "y": 36,
      "z": -5,
      "name": "Plant_Leaves_Beech_Max_Support",
      "support": 15
    },
    {
      "x": -9,
      "y": 37,
      "z": -5,
      "name": "Plant_Leaves_Beech_Max_Support"
    },
    {
      "x": -9,
      "y": 38,
      "z": -5,
      "name": "Plant_Leaves_Beech_Max_Support"
    },
    {
      "x": -9,
      "y": 39,
      "z": -5,
      "name": "Plant_Leaves_Beech_Max_Support"
    },
    {
      "x": -9,
      "y": 47,
      "z": -5,
      "name": "Plant_Leaves_Beech_Max_Support"
    },
    {
      "x": -9,
      "y": 49,
      "z": -5,
      "name": "Plant_Leaves_Beech_Max_Support"
    },
    {
      "x": -9,
      "y": 51,
      "z": -5,
      "name": "Plant_Leaves_Beech_Max_Support"
    },
    {
      "x": -9,
      "y": 52,
      "z": -5,
      "name": "Plant_Leaves_Beech_Max_Support"
    },
    {
      "x": -9,
      "y": 36,
      "z": -4,
      "name": "Plant_Leaves_Beech_Max_Support",
      "support": 15
    },
    {
      "x": -9,
      "y": 38,
      "z": -4,
      "name": "Plant_Leaves_Beech_Max_Support"
    },
    {
      "x": -9,
      "y": 39,
      "z": -4,
      "name": "Plant_Leaves_Beech_Max_Support"
    },
    {
      "x": -9,
      "y": 40,
      "z": -4,
      "name": "Plant_Leaves_Beech_Max_Support"
    },
    {
      "x": -9,
      "y": 48,
      "z": -4,
      "name": "Plant_Leaves_Beech_Max_Support"
    },
    {
      "x": -9,
      "y": 49,
      "z": -4,
      "name": "Plant_Leaves_Beech_Max_Support"
    },
    {
      "x": -9,
      "y": 50,
      "z": -4,
      "name": "Plant_Leaves_Beech_Max_Support"
    },
    {
      "x": -9,
      "y": 51,
      "z": -4,
      "name": "Plant_Leaves_Beech_Max_Support"
    },
    {
      "x": -9,
      "y": 52,
      "z": -4,
      "name": "Plant_Leaves_Beech_Max_Support"
    },
    {
      "x": -9,
      "y": 22,
      "z": -3,
      "name": "Plant_Leaves_Beech_Max_Support"
    },
    {
      "x": -9,
      "y": 24,
      "z": -3,
      "name": "Plant_Leaves_Beech_Max_Support"
    },
    {
      "x": -9,
      "y": 38,
      "z": -3,
      "name": "Plant_Leaves_Beech_Max_Support"
    },
    {
      "x": -9,
      "y": 46,
      "z": -3,
      "name": "Plant_Leaves_Beech_Max_Support",
      "support": 15
    },
    {
      "x": -9,
      "y": 47,
      "z": -3,
      "name": "Plant_Leaves_Beech_Max_Support",
      "support": 15
    },
    {
      "x": -9,
      "y": 48,
      "z": -3,
      "name": "Plant_Leaves_Beech_Max_Support"
    },
    {
      "x": -9,
      "y": 49,
      "z": -3,
      "name": "Plant_Leaves_Beech_Max_Support"
    },
    {
      "x": -9,
      "y": 51,
      "z": -3,
      "name": "Plant_Leaves_Beech_Max_Support"
    },
    {
      "x": -9,
      "y": 37,
      "z": -2,
      "name": "Plant_Leaves_Beech_Max_Support",
      "support": 15
    },
    {
      "x": -9,
      "y": 38,
      "z": -2,
      "name": "Plant_Leaves_Beech_Max_Support"
    },
    {
      "x": -9,
      "y": 39,
      "z": -2,
      "name": "Plant_Leaves_Beech_Max_Support"
    },
    {
      "x": -9,
      "y": 48,
      "z": -2,
      "name": "Plant_Leaves_Beech_Max_Support"
    },
    {
      "x": -9,
      "y": 36,
      "z": -1,
      "name": "Plant_Leaves_Beech_Max_Support"
    },
    {
      "x": -9,
      "y": 37,
      "z": -1,
      "name": "Plant_Leaves_Beech_Max_Support"
    },
    {
      "x": -9,
      "y": 39,
      "z": -1,
      "name": "Plant_Leaves_Beech_Max_Support"
    },
    {
      "x": -9,
      "y": 37,
      "z": 0,
      "name": "Plant_Leaves_Beech_Max_Support"
    },
    {
      "x": -9,
      "y": 39,
      "z": 0,
      "name": "Plant_Leaves_Beech_Max_Support"
    },
    {
      "x": -9,
      "y": 38,
      "z": 1,
      "name": "Plant_Leaves_Beech_Max_Support"
    },
    {
      "x": -9,
      "y": 39,
      "z": 1,
      "name": "Plant_Leaves_Beech_Max_Support"
    },
    {
      "x": -9,
      "y": 37,
      "z": 2,
      "name": "Plant_Leaves_Beech_Max_Support"
    },
    {
      "x": -9,
      "y": 38,
      "z": 2,
      "name": "Plant_Leaves_Beech_Max_Support"
    },
    {
      "x": -9,
      "y": 46,
      "z": 2,
      "name": "Plant_Leaves_Beech_Max_Support",
      "support": 15
    },
    {
      "x": -9,
      "y": 38,
      "z": 3,
      "name": "Plant_Leaves_Beech_Max_Support"
    },
    {
      "x": -9,
      "y": 45,
      "z": 4,
      "name": "Plant_Leaves_Beech_Max_Support",
      "support": 15
    },
    {
      "x": -8,
      "y": 47,
      "z": -12,
      "name": "Plant_Leaves_Beech_Max_Support",
      "support": 15
    },
    {
      "x": -8,
      "y": 51,
      "z": -12,
      "name": "Plant_Leaves_Beech_Max_Support"
    },
    {
      "x": -8,
      "y": 23,
      "z": -11,
      "name": "Plant_Leaves_Beech_Max_Support"
    },
    {
      "x": -8,
      "y": 24,
      "z": -11,
      "name": "Plant_Leaves_Beech_Max_Support"
    },
    {
      "x": -8,
      "y": 25,
      "z": -11,
      "name": "Plant_Leaves_Beech_Max_Support"
    },
    {
      "x": -8,
      "y": 47,
      "z": -11,
      "name": "Plant_Leaves_Beech_Max_Support",
      "support": 15
    },
    {
      "x": -8,
      "y": 48,
      "z": -11,
      "name": "Plant_Leaves_Beech_Max_Support"
    },
    {
      "x": -8,
      "y": 49,
      "z": -11,
      "name": "Plant_Leaves_Beech_Max_Support"
    },
    {
      "x": -8,
      "y": 52,
      "z": -11,
      "name": "Plant_Leaves_Beech_Max_Support"
    },
    {
      "x": -8,
      "y": 22,
      "z": -10,
      "name": "Plant_Leaves_Beech_Max_Support"
    },
    {
      "x": -8,
      "y": 23,
      "z": -10,
      "name": "Plant_Leaves_Beech_Max_Support"
    },
    {
      "x": -8,
      "y": 24,
      "z": -10,
      "name": "Plant_Leaves_Beech_Max_Support"
    },
    {
      "x": -8,
      "y": 47,
      "z": -10,
      "name": "Plant_Leaves_Beech_Max_Support",
      "support": 15
    },
    {
      "x": -8,
      "y": 48,
      "z": -10,
      "name": "Plant_Leaves_Beech_Max_Support"
    },
    {
      "x": -8,
      "y": 49,
      "z": -10,
      "name": "Plant_Leaves_Beech_Max_Support"
    },
    {
      "x": -8,
      "y": 50,
      "z": -10,
      "name": "Plant_Leaves_Beech_Max_Support"
    },
    {
      "x": -8,
      "y": 21,
      "z": -9,
      "name": "Plant_Leaves_Beech_Max_Support"
    },
    {
      "x": -8,
      "y": 22,
      "z": -9,
      "name": "Plant_Leaves_Beech_Max_Support"
    },
    {
      "x": -8,
      "y": 23,
      "z": -9,
      "name": "Plant_Leaves_Beech_Max_Support"
    },
    {
      "x": -8,
      "y": 24,
      "z": -9,
      "name": "Plant_Leaves_Beech_Max_Support"
    },
    {
      "x": -8,
      "y": 25,
      "z": -9,
      "name": "Plant_Leaves_Beech_Max_Support"
    },
    {
      "x": -8,
      "y": 36,
      "z": -9,
      "name": "Plant_Leaves_Beech_Max_Support",
      "support": 15
    },
    {
      "x": -8,
      "y": 39,
      "z": -9,
      "name": "Plant_Leaves_Beech_Max_Support"
    },
    {
      "x": -8,
      "y": 40,
      "z": -9,
      "name": "Plant_Leaves_Beech_Max_Support"
    },
    {
      "x": -8,
      "y": 47,
      "z": -9,
      "name": "Plant_Leaves_Beech_Max_Support",
      "support": 15
    },
    {
      "x": -8,
      "y": 48,
      "z": -9,
      "name": "Plant_Leaves_Beech_Max_Support"
    },
    {
      "x": -8,
      "y": 49,
      "z": -9,
      "name": "Plant_Leaves_Beech_Max_Support"
    },
    {
      "x": -8,
      "y": 50,
      "z": -9,
      "name": "Plant_Leaves_Beech_Max_Support"
    },
    {
      "x": -8,
      "y": 51,
      "z": -9,
      "name": "Plant_Leaves_Beech_Max_Support"
    },
    {
      "x": -8,
      "y": 21,
      "z": -8,
      "name": "Plant_Leaves_Beech_Max_Support"
    },
    {
      "x": -8,
      "y": 22,
      "z": -8,
      "name": "Plant_Leaves_Beech_Max_Support"
    },
    {
      "x": -8,
      "y": 23,
      "z": -8,
      "name": "Plant_Leaves_Beech_Max_Support"
    },
    {
      "x": -8,
      "y": 24,
      "z": -8,
      "name": "Plant_Leaves_Beech_Max_Support"
    },
    {
      "x": -8,
      "y": 36,
      "z": -8,
      "name": "Plant_Leaves_Beech_Max_Support",
      "support": 15
    },
    {
      "x": -8,
      "y": 37,
      "z": -8,
      "name": "Plant_Leaves_Beech_Max_Support",
      "support": 15
    },
    {
      "x": -8,
      "y": 38,
      "z": -8,
      "name": "Plant_Leaves_Beech_Max_Support"
    },
    {
      "x": -8,
      "y": 39,
      "z": -8,
      "name": "Plant_Leaves_Beech_Max_Support"
    },
    {
      "x": -8,
      "y": 40,
      "z": -8,
      "name": "Plant_Leaves_Beech_Max_Support"
    },
    {
      "x": -8,
      "y": 41,
      "z": -8,
      "name": "Plant_Leaves_Beech_Max_Support"
    },
    {
      "x": -8,
      "y": 48,
      "z": -8,
      "name": "Plant_Leaves_Beech_Max_Support"
    },
    {
      "x": -8,
      "y": 49,
      "z": -8,
      "name": "Plant_Leaves_Beech_Max_Support"
    },
    {
      "x": -8,
      "y": 50,
      "z": -8,
      "name": "Plant_Leaves_Beech_Max_Support"
    },
    {
      "x": -8,
      "y": 51,
      "z": -8,
      "name": "Plant_Leaves_Beech_Max_Support"
    },
    {
      "x": -8,
      "y": 52,
      "z": -8,
      "name": "Plant_Leaves_Beech_Max_Support"
    },
    {
      "x": -8,
      "y": 23,
      "z": -7,
      "name": "Plant_Leaves_Beech_Max_Support"
    },
    {
      "x": -8,
      "y": 25,
      "z": -7,
      "name": "Plant_Leaves_Beech_Max_Support"
    },
    {
      "x": -8,
      "y": 36,
      "z": -7,
      "name": "Plant_Leaves_Beech_Max_Support"
    },
    {
      "x": -8,
      "y": 40,
      "z": -7,
      "name": "Plant_Leaves_Beech_Max_Support"
    },
    {
      "x": -8,
      "y": 49,
      "z": -7,
      "name": "Wood_Gumboab_Trunk_Full"
    },
    {
      "x": -8,
      "y": 50,
      "z": -7,
      "name": "Plant_Leaves_Beech_Max_Support"
    },
    {
      "x": -8,
      "y": 51,
      "z": -7,
      "name": "Plant_Leaves_Beech_Max_Support"
    },
    {
      "x": -8,
      "y": 52,
      "z": -7,
      "name": "Plant_Leaves_Beech_Max_Support"
    },
    {
      "x": -8,
      "y": 22,
      "z": -6,
      "name": "Plant_Leaves_Beech_Max_Support"
    },
    {
      "x": -8,
      "y": 23,
      "z": -6,
      "name": "Plant_Leaves_Beech_Max_Support"
    },
    {
      "x": -8,
      "y": 24,
      "z": -6,
      "name": "Plant_Leaves_Beech_Max_Support"
    },
    {
      "x": -8,
      "y": 25,
      "z": -6,
      "name": "Plant_Leaves_Beech_Max_Support"
    },
    {
      "x": -8,
      "y": 36,
      "z": -6,
      "name": "Plant_Leaves_Beech_Max_Support"
    },
    {
      "x": -8,
      "y": 37,
      "z": -6,
      "name": "Plant_Leaves_Beech_Max_Support"
    },
    {
      "x": -8,
      "y": 41,
      "z": -6,
      "name": "Plant_Leaves_Beech_Max_Support"
    },
    {
      "x": -8,
      "y": 46,
      "z": -6,
      "name": "Plant_Leaves_Beech_Max_Support"
    },
    {
      "x": -8,
      "y": 47,
      "z": -6,
      "name": "Plant_Leaves_Beech_Max_Support"
    },
    {
      "x": -8,
      "y": 48,
      "z": -6,
      "name": "Wood_Gumboab_Trunk_Full"
    },
    {
      "x": -8,
      "y": 49,
      "z": -6,
      "name": "Wood_Gumboab_Trunk_Full"
    },
    {
      "x": -8,
      "y": 50,
      "z": -6,
      "name": "Plant_Leaves_Beech_Max_Support"
    },
    {
      "x": -8,
      "y": 51,
      "z": -6,
      "name": "Plant_Leaves_Beech_Max_Support"
    },
    {
      "x": -8,
      "y": 52,
      "z": -6,
      "name": "Plant_Leaves_Beech_Max_Support"
    },
    {
      "x": -8,
      "y": 22,
      "z": -5,
      "name": "Plant_Leaves_Beech_Max_Support"
    },
    {
      "x": -8,
      "y": 24,
      "z": -5,
      "name": "Plant_Leaves_Beech_Max_Support"
    },
    {
      "x": -8,
      "y": 25,
      "z": -5,
      "name": "Plant_Leaves_Beech_Max_Support"
    },
    {
      "x": -8,
      "y": 36,
      "z": -5,
      "name": "Plant_Leaves_Beech_Max_Support"
    },
    {
      "x": -8,
      "y": 37,
      "z": -5,
      "name": "Plant_Leaves_Beech_Max_Support"
    },
    {
      "x": -8,
      "y": 38,
      "z": -5,
      "name": "Plant_Leaves_Beech_Max_Support"
    },
    {
      "x": -8,
      "y": 39,
      "z": -5,
      "name": "Plant_Leaves_Beech_Max_Support"
    },
    {
      "x": -8,
      "y": 40,
      "z": -5,
      "name": "Plant_Leaves_Beech_Max_Support"
    },
    {
      "x": -8,
      "y": 42,
      "z": -5,
      "name": "Plant_Leaves_Beech_Max_Support"
    },
    {
      "x": -8,
      "y": 47,
      "z": -5,
      "name": "Plant_Leaves_Beech_Max_Support"
    },
    {
      "x": -8,
      "y": 48,
      "z": -5,
      "name": "Wood_Gumboab_Trunk_Full"
    },
    {
      "x": -8,
      "y": 49,
      "z": -5,
      "name": "Wood_Gumboab_Trunk_Full"
    },
    {
      "x": -8,
      "y": 50,
      "z": -5,
      "name": "Plant_Leaves_Beech_Max_Support"
    },
    {
      "x": -8,
      "y": 51,
      "z": -5,
      "name": "Plant_Leaves_Beech_Max_Support"
    },
    {
      "x": -8,
      "y": 21,
      "z": -4,
      "name": "Plant_Leaves_Beech_Max_Support"
    },
    {
      "x": -8,
      "y": 23,
      "z": -4,
      "name": "Plant_Leaves_Beech_Max_Support"
    },
    {
      "x": -8,
      "y": 24,
      "z": -4,
      "name": "Plant_Leaves_Beech_Max_Support"
    },
    {
      "x": -8,
      "y": 36,
      "z": -4,
      "name": "Plant_Leaves_Beech_Max_Support",
      "support": 15
    },
    {
      "x": -8,
      "y": 37,
      "z": -4,
      "name": "Plant_Leaves_Beech_Max_Support"
    },
    {
      "x": -8,
      "y": 38,
      "z": -4,
      "name": "Plant_Leaves_Beech_Max_Support"
    },
    {
      "x": -8,
      "y": 39,
      "z": -4,
      "name": "Plant_Leaves_Beech_Max_Support"
    },
    {
      "x": -8,
      "y": 41,
      "z": -4,
      "name": "Plant_Leaves_Beech_Max_Support"
    },
    {
      "x": -8,
      "y": 46,
      "z": -4,
      "name": "Plant_Leaves_Beech_Max_Support",
      "support": 15
    },
    {
      "x": -8,
      "y": 47,
      "z": -4,
      "name": "Plant_Leaves_Beech_Max_Support",
      "support": 15
    },
    {
      "x": -8,
      "y": 48,
      "z": -4,
      "name": "Wood_Gumboab_Trunk_Full"
    },
    {
      "x": -8,
      "y": 49,
      "z": -4,
      "name": "Plant_Leaves_Beech_Max_Support"
    },
    {
      "x": -8,
      "y": 52,
      "z": -4,
      "name": "Plant_Leaves_Beech_Max_Support"
    },
    {
      "x": -8,
      "y": 21,
      "z": -3,
      "name": "Plant_Leaves_Beech_Max_Support"
    },
    {
      "x": -8,
      "y": 22,
      "z": -3,
      "name": "Plant_Leaves_Beech_Max_Support"
    },
    {
      "x": -8,
      "y": 37,
      "z": -3,
      "name": "Plant_Leaves_Beech_Max_Support",
      "support": 15
    },
    {
      "x": -8,
      "y": 38,
      "z": -3,
      "name": "Plant_Leaves_Beech_Max_Support"
    },
    {
      "x": -8,
      "y": 39,
      "z": -3,
      "name": "Plant_Leaves_Beech_Max_Support"
    },
    {
      "x": -8,
      "y": 47,
      "z": -3,
      "name": "Plant_Leaves_Beech_Max_Support",
      "support": 15
    },
    {
      "x": -8,
      "y": 49,
      "z": -3,
      "name": "Plant_Leaves_Beech_Max_Support"
    },
    {
      "x": -8,
      "y": 50,
      "z": -3,
      "name": "Plant_Leaves_Beech_Max_Support"
    },
    {
      "x": -8,
      "y": 22,
      "z": -2,
      "name": "Plant_Leaves_Beech_Max_Support"
    },
    {
      "x": -8,
      "y": 38,
      "z": -2,
      "name": "Plant_Leaves_Beech_Max_Support"
    },
    {
      "x": -8,
      "y": 40,
      "z": -2,
      "name": "Plant_Leaves_Beech_Max_Support"
    },
    {
      "x": -8,
      "y": 49,
      "z": -2,
      "name": "Plant_Leaves_Beech_Max_Support"
    },
    {
      "x": -8,
      "y": 37,
      "z": -1,
      "name": "Plant_Leaves_Beech_Max_Support"
    },
    {
      "x": -8,
      "y": 38,
      "z": -1,
      "name": "Plant_Leaves_Beech_Max_Support"
    },
    {
      "x": -8,
      "y": 39,
      "z": -1,
      "name": "Plant_Leaves_Beech_Max_Support"
    },
    {
      "x": -8,
      "y": 40,
      "z": -1,
      "name": "Plant_Leaves_Beech_Max_Support"
    },
    {
      "x": -8,
      "y": 37,
      "z": 0,
      "name": "Plant_Leaves_Beech_Max_Support"
    },
    {
      "x": -8,
      "y": 39,
      "z": 0,
      "name": "Plant_Leaves_Beech_Max_Support"
    },
    {
      "x": -8,
      "y": 40,
      "z": 0,
      "name": "Plant_Leaves_Beech_Max_Support"
    },
    {
      "x": -8,
      "y": 41,
      "z": 0,
      "name": "Plant_Leaves_Beech_Max_Support"
    },
    {
      "x": -8,
      "y": 37,
      "z": 1,
      "name": "Plant_Leaves_Beech_Max_Support"
    },
    {
      "x": -8,
      "y": 38,
      "z": 1,
      "name": "Plant_Leaves_Beech_Max_Support"
    },
    {
      "x": -8,
      "y": 39,
      "z": 1,
      "name": "Plant_Leaves_Beech_Max_Support"
    },
    {
      "x": -8,
      "y": 40,
      "z": 1,
      "name": "Plant_Leaves_Beech_Max_Support"
    },
    {
      "x": -8,
      "y": 46,
      "z": 1,
      "name": "Plant_Leaves_Beech_Max_Support",
      "support": 15
    },
    {
      "x": -8,
      "y": 36,
      "z": 2,
      "name": "Plant_Leaves_Beech_Max_Support"
    },
    {
      "x": -8,
      "y": 37,
      "z": 2,
      "name": "Plant_Leaves_Beech_Max_Support"
    },
    {
      "x": -8,
      "y": 39,
      "z": 2,
      "name": "Plant_Leaves_Beech_Max_Support"
    },
    {
      "x": -8,
      "y": 46,
      "z": 2,
      "name": "Plant_Leaves_Beech_Max_Support"
    },
    {
      "x": -8,
      "y": 47,
      "z": 2,
      "name": "Plant_Leaves_Beech_Max_Support"
    },
    {
      "x": -8,
      "y": 48,
      "z": 2,
      "name": "Plant_Leaves_Beech_Max_Support"
    },
    {
      "x": -8,
      "y": 37,
      "z": 3,
      "name": "Plant_Leaves_Beech_Max_Support"
    },
    {
      "x": -8,
      "y": 38,
      "z": 3,
      "name": "Plant_Leaves_Beech_Max_Support"
    },
    {
      "x": -8,
      "y": 48,
      "z": 3,
      "name": "Plant_Leaves_Beech_Max_Support"
    },
    {
      "x": -8,
      "y": 45,
      "z": 4,
      "name": "Plant_Leaves_Beech_Max_Support",
      "support": 15
    },
    {
      "x": -8,
      "y": 46,
      "z": 4,
      "name": "Plant_Leaves_Beech_Max_Support"
    },
    {
      "x": -8,
      "y": 47,
      "z": 4,
      "name": "Plant_Leaves_Beech_Max_Support"
    },
    {
      "x": -8,
      "y": 29,
      "z": 7,
      "name": "Plant_Leaves_Beech_Max_Support",
      "support": 15
    },
    {
      "x": -7,
      "y": 49,
      "z": -13,
      "name": "Plant_Leaves_Beech_Max_Support"
    },
    {
      "x": -7,
      "y": 51,
      "z": -13,
      "name": "Plant_Leaves_Beech_Max_Support"
    },
    {
      "x": -7,
      "y": 22,
      "z": -12,
      "name": "Plant_Leaves_Beech_Max_Support"
    },
    {
      "x": -7,
      "y": 23,
      "z": -12,
      "name": "Plant_Leaves_Beech_Max_Support"
    },
    {
      "x": -7,
      "y": 24,
      "z": -12,
      "name": "Plant_Leaves_Beech_Max_Support"
    },
    {
      "x": -7,
      "y": 25,
      "z": -12,
      "name": "Plant_Leaves_Beech_Max_Support"
    },
    {
      "x": -7,
      "y": 47,
      "z": -12,
      "name": "Plant_Leaves_Beech_Max_Support",
      "support": 15
    },
    {
      "x": -7,
      "y": 48,
      "z": -12,
      "name": "Plant_Leaves_Beech_Max_Support"
    },
    {
      "x": -7,
      "y": 49,
      "z": -12,
      "name": "Plant_Leaves_Beech_Max_Support"
    },
    {
      "x": -7,
      "y": 50,
      "z": -12,
      "name": "Plant_Leaves_Beech_Max_Support"
    },
    {
      "x": -7,
      "y": 51,
      "z": -12,
      "name": "Plant_Leaves_Beech_Max_Support"
    },
    {
      "x": -7,
      "y": 52,
      "z": -12,
      "name": "Plant_Leaves_Beech_Max_Support"
    },
    {
      "x": -7,
      "y": 21,
      "z": -11,
      "name": "Plant_Leaves_Beech_Max_Support"
    },
    {
      "x": -7,
      "y": 22,
      "z": -11,
      "name": "Plant_Leaves_Beech_Max_Support"
    },
    {
      "x": -7,
      "y": 23,
      "z": -11,
      "name": "Plant_Leaves_Beech_Max_Support"
    },
    {
      "x": -7,
      "y": 24,
      "z": -11,
      "name": "Plant_Leaves_Beech_Max_Support"
    },
    {
      "x": -7,
      "y": 25,
      "z": -11,
      "name": "Plant_Leaves_Beech_Max_Support"
    },
    {
      "x": -7,
      "y": 26,
      "z": -11,
      "name": "Plant_Leaves_Beech_Max_Support"
    },
    {
      "x": -7,
      "y": 47,
      "z": -11,
      "name": "Plant_Leaves_Beech_Max_Support"
    },
    {
      "x": -7,
      "y": 48,
      "z": -11,
      "name": "Plant_Leaves_Beech_Max_Support"
    },
    {
      "x": -7,
      "y": 50,
      "z": -11,
      "name": "Plant_Leaves_Beech_Max_Support"
    },
    {
      "x": -7,
      "y": 52,
      "z": -11,
      "name": "Plant_Leaves_Beech_Max_Support"
    },
    {
      "x": -7,
      "y": 53,
      "z": -11,
      "name": "Plant_Leaves_Beech_Max_Support"
    },
    {
      "x": -7,
      "y": 21,
      "z": -10,
      "name": "Plant_Leaves_Beech_Max_Support"
    },
    {
      "x": -7,
      "y": 22,
      "z": -10,
      "name": "Plant_Leaves_Beech_Max_Support"
    },
    {
      "x": -7,
      "y": 23,
      "z": -10,
      "name": "Plant_Leaves_Beech_Max_Support"
    },
    {
      "x": -7,
      "y": 25,
      "z": -10,
      "name": "Plant_Leaves_Beech_Max_Support"
    },
    {
      "x": -7,
      "y": 49,
      "z": -10,
      "name": "Plant_Leaves_Beech_Max_Support"
    },
    {
      "x": -7,
      "y": 50,
      "z": -10,
      "name": "Plant_Leaves_Beech_Max_Support"
    },
    {
      "x": -7,
      "y": 51,
      "z": -10,
      "name": "Plant_Leaves_Beech_Max_Support"
    },
    {
      "x": -7,
      "y": 52,
      "z": -10,
      "name": "Plant_Leaves_Beech_Max_Support"
    },
    {
      "x": -7,
      "y": 20,
      "z": -9,
      "name": "Plant_Leaves_Beech_Max_Support"
    },
    {
      "x": -7,
      "y": 22,
      "z": -9,
      "name": "Plant_Leaves_Beech_Max_Support"
    },
    {
      "x": -7,
      "y": 23,
      "z": -9,
      "name": "Plant_Leaves_Beech_Max_Support"
    },
    {
      "x": -7,
      "y": 25,
      "z": -9,
      "name": "Plant_Leaves_Beech_Max_Support"
    },
    {
      "x": -7,
      "y": 26,
      "z": -9,
      "name": "Plant_Leaves_Beech_Max_Support"
    },
    {
      "x": -7,
      "y": 28,
      "z": -9,
      "name": "Plant_Leaves_Beech_Max_Support"
    },
    {
      "x": -7,
      "y": 38,
      "z": -9,
      "name": "Plant_Leaves_Beech_Max_Support"
    },
    {
      "x": -7,
      "y": 39,
      "z": -9,
      "name": "Plant_Leaves_Beech_Max_Support"
    },
    {
      "x": -7,
      "y": 48,
      "z": -9,
      "name": "Plant_Leaves_Beech_Max_Support"
    },
    {
      "x": -7,
      "y": 50,
      "z": -9,
      "name": "Plant_Leaves_Beech_Max_Support"
    },
    {
      "x": -7,
      "y": 51,
      "z": -9,
      "name": "Plant_Leaves_Beech_Max_Support"
    },
    {
      "x": -7,
      "y": 52,
      "z": -9,
      "name": "Plant_Leaves_Beech_Max_Support"
    },
    {
      "x": -7,
      "y": 21,
      "z": -8,
      "name": "Plant_Leaves_Beech_Max_Support"
    },
    {
      "x": -7,
      "y": 22,
      "z": -8,
      "name": "Plant_Leaves_Beech_Max_Support"
    },
    {
      "x": -7,
      "y": 23,
      "z": -8,
      "name": "Plant_Leaves_Beech_Max_Support"
    },
    {
      "x": -7,
      "y": 24,
      "z": -8,
      "name": "Plant_Leaves_Beech_Max_Support"
    },
    {
      "x": -7,
      "y": 25,
      "z": -8,
      "name": "Plant_Leaves_Beech_Max_Support"
    },
    {
      "x": -7,
      "y": 26,
      "z": -8,
      "name": "Plant_Leaves_Beech_Max_Support"
    },
    {
      "x": -7,
      "y": 27,
      "z": -8,
      "name": "Plant_Leaves_Beech_Max_Support"
    },
    {
      "x": -7,
      "y": 38,
      "z": -8,
      "name": "Plant_Leaves_Beech_Max_Support"
    },
    {
      "x": -7,
      "y": 39,
      "z": -8,
      "name": "Plant_Leaves_Beech_Max_Support"
    },
    {
      "x": -7,
      "y": 40,
      "z": -8,
      "name": "Plant_Leaves_Beech_Max_Support"
    },
    {
      "x": -7,
      "y": 41,
      "z": -8,
      "name": "Plant_Leaves_Beech_Max_Support"
    },
    {
      "x": -7,
      "y": 48,
      "z": -8,
      "name": "Plant_Leaves_Beech_Max_Support"
    },
    {
      "x": -7,
      "y": 49,
      "z": -8,
      "name": "Plant_Leaves_Beech_Max_Support"
    },
    {
      "x": -7,
      "y": 50,
      "z": -8,
      "name": "Plant_Leaves_Beech_Max_Support"
    },
    {
      "x": -7,
      "y": 52,
      "z": -8,
      "name": "Plant_Leaves_Beech_Max_Support"
    },
    {
      "x": -7,
      "y": 53,
      "z": -8,
      "name": "Plant_Leaves_Beech_Max_Support"
    },
    {
      "x": -7,
      "y": 22,
      "z": -7,
      "name": "Plant_Leaves_Beech_Max_Support"
    },
    {
      "x": -7,
      "y": 23,
      "z": -7,
      "name": "Plant_Leaves_Beech_Max_Support"
    },
    {
      "x": -7,
      "y": 24,
      "z": -7,
      "name": "Plant_Leaves_Beech_Max_Support"
    },
    {
      "x": -7,
      "y": 26,
      "z": -7,
      "name": "Plant_Leaves_Beech_Max_Support"
    },
    {
      "x": -7,
      "y": 37,
      "z": -7,
      "name": "Plant_Leaves_Beech_Max_Support"
    },
    {
      "x": -7,
      "y": 38,
      "z": -7,
      "name": "Plant_Leaves_Beech_Max_Support"
    },
    {
      "x": -7,
      "y": 39,
      "z": -7,
      "name": "Plant_Leaves_Beech_Max_Support"
    },
    {
      "x": -7,
      "y": 40,
      "z": -7,
      "name": "Plant_Leaves_Beech_Max_Support"
    },
    {
      "x": -7,
      "y": 47,
      "z": -7,
      "name": "Plant_Leaves_Beech_Max_Support"
    },
    {
      "x": -7,
      "y": 48,
      "z": -7,
      "name": "Wood_Gumboab_Trunk_Full"
    },
    {
      "x": -7,
      "y": 49,
      "z": -7,
      "name": "Wood_Gumboab_Trunk_Full"
    },
    {
      "x": -7,
      "y": 50,
      "z": -7,
      "name": "Plant_Leaves_Beech_Max_Support"
    },
    {
      "x": -7,
      "y": 51,
      "z": -7,
      "name": "Plant_Leaves_Beech_Max_Support"
    },
    {
      "x": -7,
      "y": 52,
      "z": -7,
      "name": "Plant_Leaves_Beech_Max_Support"
    },
    {
      "x": -7,
      "y": 53,
      "z": -7,
      "name": "Plant_Leaves_Beech_Max_Support"
    },
    {
      "x": -7,
      "y": 21,
      "z": -6,
      "name": "Plant_Leaves_Beech_Max_Support"
    },
    {
      "x": -7,
      "y": 22,
      "z": -6,
      "name": "Plant_Leaves_Beech_Max_Support"
    },
    {
      "x": -7,
      "y": 23,
      "z": -6,
      "name": "Plant_Leaves_Beech_Max_Support"
    },
    {
      "x": -7,
      "y": 24,
      "z": -6,
      "name": "Plant_Leaves_Beech_Max_Support"
    },
    {
      "x": -7,
      "y": 25,
      "z": -6,
      "name": "Plant_Leaves_Beech_Max_Support"
    },
    {
      "x": -7,
      "y": 26,
      "z": -6,
      "name": "Plant_Leaves_Beech_Max_Support"
    },
    {
      "x": -7,
      "y": 36,
      "z": -6,
      "name": "Plant_Leaves_Beech_Max_Support"
    },
    {
      "x": -7,
      "y": 38,
      "z": -6,
      "name": "Plant_Leaves_Beech_Max_Support"
    },
    {
      "x": -7,
      "y": 39,
      "z": -6,
      "name": "Plant_Leaves_Beech_Max_Support"
    },
    {
      "x": -7,
      "y": 40,
      "z": -6,
      "name": "Plant_Leaves_Beech_Max_Support"
    },
    {
      "x": -7,
      "y": 41,
      "z": -6,
      "name": "Plant_Leaves_Beech_Max_Support"
    },
    {
      "x": -7,
      "y": 46,
      "z": -6,
      "name": "Plant_Leaves_Beech_Max_Support"
    },
    {
      "x": -7,
      "y": 47,
      "z": -6,
      "name": "Plant_Leaves_Beech_Max_Support"
    },
    {
      "x": -7,
      "y": 48,
      "z": -6,
      "name": "Wood_Gumboab_Trunk_Full"
    },
    {
      "x": -7,
      "y": 49,
      "z": -6,
      "name": "Wood_Gumboab_Trunk_Full"
    },
    {
      "x": -7,
      "y": 50,
      "z": -6,
      "name": "Plant_Leaves_Beech_Max_Support"
    },
    {
      "x": -7,
      "y": 51,
      "z": -6,
      "name": "Plant_Leaves_Beech_Max_Support"
    },
    {
      "x": -7,
      "y": 52,
      "z": -6,
      "name": "Plant_Leaves_Beech_Max_Support"
    },
    {
      "x": -7,
      "y": 53,
      "z": -6,
      "name": "Plant_Leaves_Beech_Max_Support"
    },
    {
      "x": -7,
      "y": 23,
      "z": -5,
      "name": "Plant_Leaves_Beech_Max_Support"
    },
    {
      "x": -7,
      "y": 24,
      "z": -5,
      "name": "Plant_Leaves_Beech_Max_Support"
    },
    {
      "x": -7,
      "y": 26,
      "z": -5,
      "name": "Plant_Leaves_Beech_Max_Support"
    },
    {
      "x": -7,
      "y": 36,
      "z": -5,
      "name": "Plant_Leaves_Beech_Max_Support"
    },
    {
      "x": -7,
      "y": 37,
      "z": -5,
      "name": "Plant_Leaves_Beech_Max_Support"
    },
    {
      "x": -7,
      "y": 38,
      "z": -5,
      "name": "Plant_Leaves_Beech_Max_Support"
    },
    {
      "x": -7,
      "y": 39,
      "z": -5,
      "name": "Plant_Leaves_Beech_Max_Support"
    },
    {
      "x": -7,
      "y": 40,
      "z": -5,
      "name": "Plant_Leaves_Beech_Max_Support"
    },
    {
      "x": -7,
      "y": 41,
      "z": -5,
      "name": "Plant_Leaves_Beech_Max_Support"
    },
    {
      "x": -7,
      "y": 42,
      "z": -5,
      "name": "Plant_Leaves_Beech_Max_Support"
    },
    {
      "x": -7,
      "y": 46,
      "z": -5,
      "name": "Plant_Leaves_Beech_Max_Support"
    },
    {
      "x": -7,
      "y": 48,
      "z": -5,
      "name": "Plant_Leaves_Beech_Max_Support"
    },
    {
      "x": -7,
      "y": 49,
      "z": -5,
      "name": "Plant_Leaves_Beech_Max_Support"
    },
    {
      "x": -7,
      "y": 50,
      "z": -5,
      "name": "Plant_Leaves_Beech_Max_Support"
    },
    {
      "x": -7,
      "y": 51,
      "z": -5,
      "name": "Plant_Leaves_Beech_Max_Support"
    },
    {
      "x": -7,
      "y": 52,
      "z": -5,
      "name": "Plant_Leaves_Beech_Max_Support"
    },
    {
      "x": -7,
      "y": 22,
      "z": -4,
      "name": "Plant_Leaves_Beech_Max_Support"
    },
    {
      "x": -7,
      "y": 23,
      "z": -4,
      "name": "Plant_Leaves_Beech_Max_Support"
    },
    {
      "x": -7,
      "y": 24,
      "z": -4,
      "name": "Plant_Leaves_Beech_Max_Support"
    },
    {
      "x": -7,
      "y": 25,
      "z": -4,
      "name": "Plant_Leaves_Beech_Max_Support"
    },
    {
      "x": -7,
      "y": 26,
      "z": -4,
      "name": "Plant_Leaves_Beech_Max_Support"
    },
    {
      "x": -7,
      "y": 36,
      "z": -4,
      "name": "Plant_Leaves_Beech_Max_Support",
      "support": 15
    },
    {
      "x": -7,
      "y": 37,
      "z": -4,
      "name": "Plant_Leaves_Beech_Max_Support"
    },
    {
      "x": -7,
      "y": 39,
      "z": -4,
      "name": "Plant_Leaves_Beech_Max_Support"
    },
    {
      "x": -7,
      "y": 40,
      "z": -4,
      "name": "Plant_Leaves_Beech_Max_Support"
    },
    {
      "x": -7,
      "y": 41,
      "z": -4,
      "name": "Plant_Leaves_Beech_Max_Support"
    },
    {
      "x": -7,
      "y": 46,
      "z": -4,
      "name": "Plant_Leaves_Beech_Max_Support"
    },
    {
      "x": -7,
      "y": 47,
      "z": -4,
      "name": "Plant_Leaves_Beech_Max_Support"
    },
    {
      "x": -7,
      "y": 48,
      "z": -4,
      "name": "Plant_Leaves_Beech_Max_Support"
    },
    {
      "x": -7,
      "y": 49,
      "z": -4,
      "name": "Plant_Leaves_Beech_Max_Support"
    },
    {
      "x": -7,
      "y": 50,
      "z": -4,
      "name": "Plant_Leaves_Beech_Max_Support"
    },
    {
      "x": -7,
      "y": 51,
      "z": -4,
      "name": "Plant_Leaves_Beech_Max_Support"
    },
    {
      "x": -7,
      "y": 21,
      "z": -3,
      "name": "Plant_Leaves_Beech_Max_Support"
    },
    {
      "x": -7,
      "y": 23,
      "z": -3,
      "name": "Plant_Leaves_Beech_Max_Support"
    },
    {
      "x": -7,
      "y": 24,
      "z": -3,
      "name": "Plant_Leaves_Beech_Max_Support"
    },
    {
      "x": -7,
      "y": 25,
      "z": -3,
      "name": "Plant_Leaves_Beech_Max_Support"
    },
    {
      "x": -7,
      "y": 36,
      "z": -3,
      "name": "Plant_Leaves_Beech_Max_Support",
      "support": 15
    },
    {
      "x": -7,
      "y": 37,
      "z": -3,
      "name": "Plant_Leaves_Beech_Max_Support"
    },
    {
      "x": -7,
      "y": 38,
      "z": -3,
      "name": "Plant_Leaves_Beech_Max_Support"
    },
    {
      "x": -7,
      "y": 39,
      "z": -3,
      "name": "Plant_Leaves_Beech_Max_Support"
    },
    {
      "x": -7,
      "y": 41,
      "z": -3,
      "name": "Plant_Leaves_Beech_Max_Support"
    },
    {
      "x": -7,
      "y": 48,
      "z": -3,
      "name": "Plant_Leaves_Beech_Max_Support"
    },
    {
      "x": -7,
      "y": 49,
      "z": -3,
      "name": "Plant_Leaves_Beech_Max_Support"
    },
    {
      "x": -7,
      "y": 22,
      "z": -2,
      "name": "Plant_Leaves_Beech_Max_Support"
    },
    {
      "x": -7,
      "y": 23,
      "z": -2,
      "name": "Plant_Leaves_Beech_Max_Support"
    },
    {
      "x": -7,
      "y": 24,
      "z": -2,
      "name": "Plant_Leaves_Beech_Max_Support"
    },
    {
      "x": -7,
      "y": 25,
      "z": -2,
      "name": "Plant_Leaves_Beech_Max_Support"
    },
    {
      "x": -7,
      "y": 36,
      "z": -2,
      "name": "Plant_Leaves_Beech_Max_Support",
      "support": 15
    },
    {
      "x": -7,
      "y": 37,
      "z": -2,
      "name": "Plant_Leaves_Beech_Max_Support",
      "support": 15
    },
    {
      "x": -7,
      "y": 38,
      "z": -2,
      "name": "Plant_Leaves_Beech_Max_Support"
    },
    {
      "x": -7,
      "y": 39,
      "z": -2,
      "name": "Plant_Leaves_Beech_Max_Support"
    },
    {
      "x": -7,
      "y": 40,
      "z": -2,
      "name": "Plant_Leaves_Beech_Max_Support"
    },
    {
      "x": -7,
      "y": 48,
      "z": -2,
      "name": "Plant_Leaves_Beech_Max_Support"
    },
    {
      "x": -7,
      "y": 22,
      "z": -1,
      "name": "Plant_Leaves_Beech_Max_Support"
    },
    {
      "x": -7,
      "y": 23,
      "z": -1,
      "name": "Plant_Leaves_Beech_Max_Support"
    },
    {
      "x": -7,
      "y": 24,
      "z": -1,
      "name": "Plant_Leaves_Beech_Max_Support"
    },
    {
      "x": -7,
      "y": 37,
      "z": -1,
      "name": "Plant_Leaves_Beech_Max_Support"
    },
    {
      "x": -7,
      "y": 38,
      "z": -1,
      "name": "Plant_Leaves_Beech_Max_Support"
    },
    {
      "x": -7,
      "y": 39,
      "z": -1,
      "name": "Plant_Leaves_Beech_Max_Support"
    },
    {
      "x": -7,
      "y": 40,
      "z": -1,
      "name": "Plant_Leaves_Beech_Max_Support"
    },
    {
      "x": -7,
      "y": 46,
      "z": -1,
      "name": "Plant_Leaves_Beech_Max_Support"
    },
    {
      "x": -7,
      "y": 47,
      "z": -1,
      "name": "Plant_Leaves_Beech_Max_Support"
    },
    {
      "x": -7,
      "y": 37,
      "z": 0,
      "name": "Plant_Leaves_Beech_Max_Support"
    },
    {
      "x": -7,
      "y": 38,
      "z": 0,
      "name": "Plant_Leaves_Beech_Max_Support"
    },
    {
      "x": -7,
      "y": 39,
      "z": 0,
      "name": "Plant_Leaves_Beech_Max_Support"
    },
    {
      "x": -7,
      "y": 40,
      "z": 0,
      "name": "Plant_Leaves_Beech_Max_Support"
    },
    {
      "x": -7,
      "y": 41,
      "z": 0,
      "name": "Plant_Leaves_Beech_Max_Support"
    },
    {
      "x": -7,
      "y": 47,
      "z": 0,
      "name": "Plant_Leaves_Beech_Max_Support"
    },
    {
      "x": -7,
      "y": 48,
      "z": 0,
      "name": "Plant_Leaves_Beech_Max_Support"
    },
    {
      "x": -7,
      "y": 36,
      "z": 1,
      "name": "Plant_Leaves_Beech_Max_Support"
    },
    {
      "x": -7,
      "y": 37,
      "z": 1,
      "name": "Plant_Leaves_Beech_Max_Support"
    },
    {
      "x": -7,
      "y": 38,
      "z": 1,
      "name": "Plant_Leaves_Beech_Max_Support"
    },
    {
      "x": -7,
      "y": 40,
      "z": 1,
      "name": "Plant_Leaves_Beech_Max_Support"
    },
    {
      "x": -7,
      "y": 41,
      "z": 1,
      "name": "Plant_Leaves_Beech_Max_Support"
    },
    {
      "x": -7,
      "y": 46,
      "z": 1,
      "name": "Plant_Leaves_Beech_Max_Support"
    },
    {
      "x": -7,
      "y": 38,
      "z": 2,
      "name": "Plant_Leaves_Beech_Max_Support"
    },
    {
      "x": -7,
      "y": 39,
      "z": 2,
      "name": "Plant_Leaves_Beech_Max_Support"
    },
    {
      "x": -7,
      "y": 40,
      "z": 2,
      "name": "Plant_Leaves_Beech_Max_Support"
    },
    {
      "x": -7,
      "y": 45,
      "z": 2,
      "name": "Plant_Leaves_Beech_Max_Support"
    },
    {
      "x": -7,
      "y": 46,
      "z": 2,
      "name": "Plant_Leaves_Beech_Max_Support"
    },
    {
      "x": -7,
      "y": 47,
      "z": 2,
      "name": "Plant_Leaves_Beech_Max_Support"
    },
    {
      "x": -7,
      "y": 33,
      "z": 3,
      "name": "Plant_Leaves_Beech_Max_Support"
    },
    {
      "x": -7,
      "y": 34,
      "z": 3,
      "name": "Plant_Leaves_Beech_Max_Support"
    },
    {
      "x": -7,
      "y": 36,
      "z": 3,
      "name": "Plant_Leaves_Beech_Max_Support"
    },
    {
      "x": -7,
      "y": 38,
      "z": 3,
      "name": "Plant_Leaves_Beech_Max_Support"
    },
    {
      "x": -7,
      "y": 40,
      "z": 3,
      "name": "Plant_Leaves_Beech_Max_Support"
    },
    {
      "x": -7,
      "y": 46,
      "z": 3,
      "name": "Plant_Leaves_Beech_Max_Support"
    },
    {
      "x": -7,
      "y": 49,
      "z": 3,
      "name": "Plant_Leaves_Beech_Max_Support"
    },
    {
      "x": -7,
      "y": 35,
      "z": 4,
      "name": "Plant_Leaves_Beech_Max_Support"
    },
    {
      "x": -7,
      "y": 38,
      "z": 4,
      "name": "Plant_Leaves_Beech_Max_Support"
    },
    {
      "x": -7,
      "y": 45,
      "z": 4,
      "name": "Plant_Leaves_Beech_Max_Support"
    },
    {
      "x": -7,
      "y": 46,
      "z": 4,
      "name": "Plant_Leaves_Beech_Max_Support",
      "support": 15
    },
    {
      "x": -7,
      "y": 47,
      "z": 4,
      "name": "Plant_Leaves_Beech_Max_Support"
    },
    {
      "x": -7,
      "y": 48,
      "z": 4,
      "name": "Plant_Leaves_Beech_Max_Support"
    },
    {
      "x": -7,
      "y": 49,
      "z": 4,
      "name": "Plant_Leaves_Beech_Max_Support"
    },
    {
      "x": -7,
      "y": 30,
      "z": 5,
      "name": "Plant_Leaves_Beech_Max_Support",
      "support": 15
    },
    {
      "x": -7,
      "y": 32,
      "z": 5,
      "name": "Plant_Leaves_Beech_Max_Support"
    },
    {
      "x": -7,
      "y": 33,
      "z": 5,
      "name": "Plant_Leaves_Beech_Max_Support"
    },
    {
      "x": -7,
      "y": 45,
      "z": 5,
      "name": "Plant_Leaves_Beech_Max_Support",
      "support": 15
    },
    {
      "x": -7,
      "y": 47,
      "z": 5,
      "name": "Plant_Leaves_Beech_Max_Support"
    },
    {
      "x": -7,
      "y": 48,
      "z": 5,
      "name": "Plant_Leaves_Beech_Max_Support"
    },
    {
      "x": -7,
      "y": 29,
      "z": 6,
      "name": "Plant_Leaves_Beech_Max_Support",
      "support": 15
    },
    {
      "x": -7,
      "y": 32,
      "z": 6,
      "name": "Plant_Leaves_Beech_Max_Support"
    },
    {
      "x": -7,
      "y": 29,
      "z": 7,
      "name": "Plant_Leaves_Beech_Max_Support",
      "support": 15
    },
    {
      "x": -7,
      "y": 30,
      "z": 7,
      "name": "Plant_Leaves_Beech_Max_Support",
      "support": 15
    },
    {
      "x": -7,
      "y": 31,
      "z": 7,
      "name": "Plant_Leaves_Beech_Max_Support",
      "support": 15
    },
    {
      "x": -7,
      "y": 32,
      "z": 7,
      "name": "Plant_Leaves_Beech_Max_Support"
    },
    {
      "x": -7,
      "y": 29,
      "z": 9,
      "name": "Plant_Leaves_Beech_Max_Support",
      "support": 15
    },
    {
      "x": -7,
      "y": 30,
      "z": 9,
      "name": "Plant_Leaves_Beech_Max_Support"
    },
    {
      "x": -7,
      "y": 31,
      "z": 9,
      "name": "Plant_Leaves_Beech_Max_Support"
    },
    {
      "x": -7,
      "y": 29,
      "z": 10,
      "name": "Plant_Leaves_Beech_Max_Support",
      "support": 15
    },
    {
      "x": -7,
      "y": 31,
      "z": 10,
      "name": "Plant_Leaves_Beech_Max_Support"
    },
    {
      "x": -7,
      "y": 29,
      "z": 11,
      "name": "Plant_Leaves_Beech_Max_Support"
    },
    {
      "x": -7,
      "y": 30,
      "z": 11,
      "name": "Plant_Leaves_Beech_Max_Support"
    },
    {
      "x": -6,
      "y": 22,
      "z": -13,
      "name": "Plant_Leaves_Beech_Max_Support"
    },
    {
      "x": -6,
      "y": 23,
      "z": -13,
      "name": "Plant_Leaves_Beech_Max_Support"
    },
    {
      "x": -6,
      "y": 24,
      "z": -13,
      "name": "Plant_Leaves_Beech_Max_Support"
    },
    {
      "x": -6,
      "y": 25,
      "z": -13,
      "name": "Plant_Leaves_Beech_Max_Support"
    },
    {
      "x": -6,
      "y": 46,
      "z": -13,
      "name": "Plant_Leaves_Beech_Max_Support"
    },
    {
      "x": -6,
      "y": 47,
      "z": -13,
      "name": "Plant_Leaves_Beech_Max_Support",
      "support": 15
    },
    {
      "x": -6,
      "y": 48,
      "z": -13,
      "name": "Plant_Leaves_Beech_Max_Support"
    },
    {
      "x": -6,
      "y": 51,
      "z": -13,
      "name": "Plant_Leaves_Beech_Max_Support"
    },
    {
      "x": -6,
      "y": 21,
      "z": -12,
      "name": "Plant_Leaves_Beech_Max_Support"
    },
    {
      "x": -6,
      "y": 23,
      "z": -12,
      "name": "Plant_Leaves_Beech_Max_Support"
    },
    {
      "x": -6,
      "y": 25,
      "z": -12,
      "name": "Plant_Leaves_Beech_Max_Support"
    },
    {
      "x": -6,
      "y": 47,
      "z": -12,
      "name": "Plant_Leaves_Beech_Max_Support",
      "support": 15
    },
    {
      "x": -6,
      "y": 48,
      "z": -12,
      "name": "Plant_Leaves_Beech_Max_Support"
    },
    {
      "x": -6,
      "y": 49,
      "z": -12,
      "name": "Plant_Leaves_Beech_Max_Support"
    },
    {
      "x": -6,
      "y": 21,
      "z": -11,
      "name": "Plant_Leaves_Beech_Max_Support"
    },
    {
      "x": -6,
      "y": 23,
      "z": -11,
      "name": "Plant_Leaves_Beech_Max_Support"
    },
    {
      "x": -6,
      "y": 24,
      "z": -11,
      "name": "Plant_Leaves_Beech_Max_Support"
    },
    {
      "x": -6,
      "y": 25,
      "z": -11,
      "name": "Plant_Leaves_Beech_Max_Support"
    },
    {
      "x": -6,
      "y": 26,
      "z": -11,
      "name": "Plant_Leaves_Beech_Max_Support"
    },
    {
      "x": -6,
      "y": 27,
      "z": -11,
      "name": "Plant_Leaves_Beech_Max_Support"
    },
    {
      "x": -6,
      "y": 47,
      "z": -11,
      "name": "Plant_Leaves_Beech_Max_Support"
    },
    {
      "x": -6,
      "y": 50,
      "z": -11,
      "name": "Plant_Leaves_Beech_Max_Support"
    },
    {
      "x": -6,
      "y": 51,
      "z": -11,
      "name": "Plant_Leaves_Beech_Max_Support"
    },
    {
      "x": -6,
      "y": 52,
      "z": -11,
      "name": "Plant_Leaves_Beech_Max_Support"
    },
    {
      "x": -6,
      "y": 21,
      "z": -10,
      "name": "Plant_Leaves_Beech_Max_Support"
    },
    {
      "x": -6,
      "y": 22,
      "z": -10,
      "name": "Plant_Leaves_Beech_Max_Support"
    },
    {
      "x": -6,
      "y": 23,
      "z": -10,
      "name": "Plant_Leaves_Beech_Max_Support"
    },
    {
      "x": -6,
      "y": 25,
      "z": -10,
      "name": "Plant_Leaves_Beech_Max_Support"
    },
    {
      "x": -6,
      "y": 26,
      "z": -10,
      "name": "Plant_Leaves_Beech_Max_Support"
    },
    {
      "x": -6,
      "y": 27,
      "z": -10,
      "name": "Plant_Leaves_Beech_Max_Support"
    },
    {
      "x": -6,
      "y": 28,
      "z": -10,
      "name": "Plant_Leaves_Beech_Max_Support"
    },
    {
      "x": -6,
      "y": 47,
      "z": -10,
      "name": "Plant_Leaves_Beech_Max_Support"
    },
    {
      "x": -6,
      "y": 49,
      "z": -10,
      "name": "Plant_Leaves_Beech_Max_Support"
    },
    {
      "x": -6,
      "y": 50,
      "z": -10,
      "name": "Plant_Leaves_Beech_Max_Support"
    },
    {
      "x": -6,
      "y": 51,
      "z": -10,
      "name": "Plant_Leaves_Beech_Max_Support"
    },
    {
      "x": -6,
      "y": 52,
      "z": -10,
      "name": "Plant_Leaves_Beech_Max_Support"
    },
    {
      "x": -6,
      "y": 21,
      "z": -9,
      "name": "Plant_Leaves_Beech_Max_Support"
    },
    {
      "x": -6,
      "y": 22,
      "z": -9,
      "name": "Plant_Leaves_Beech_Max_Support"
    },
    {
      "x": -6,
      "y": 23,
      "z": -9,
      "name": "Plant_Leaves_Beech_Max_Support"
    },
    {
      "x": -6,
      "y": 24,
      "z": -9,
      "name": "Plant_Leaves_Beech_Max_Support"
    },
    {
      "x": -6,
      "y": 25,
      "z": -9,
      "name": "Plant_Leaves_Beech_Max_Support"
    },
    {
      "x": -6,
      "y": 26,
      "z": -9,
      "name": "Plant_Leaves_Beech_Max_Support"
    },
    {
      "x": -6,
      "y": 27,
      "z": -9,
      "name": "Plant_Leaves_Beech_Max_Support"
    },
    {
      "x": -6,
      "y": 28,
      "z": -9,
      "name": "Plant_Leaves_Beech_Max_Support"
    },
    {
      "x": -6,
      "y": 29,
      "z": -9,
      "name": "Plant_Leaves_Beech_Max_Support"
    },
    {
      "x": -6,
      "y": 38,
      "z": -9,
      "name": "Plant_Leaves_Beech_Max_Support"
    },
    {
      "x": -6,
      "y": 47,
      "z": -9,
      "name": "Plant_Leaves_Beech_Max_Support"
    },
    {
      "x": -6,
      "y": 48,
      "z": -9,
      "name": "Plant_Leaves_Beech_Max_Support"
    },
    {
      "x": -6,
      "y": 49,
      "z": -9,
      "name": "Plant_Leaves_Beech_Max_Support"
    },
    {
      "x": -6,
      "y": 51,
      "z": -9,
      "name": "Plant_Leaves_Beech_Max_Support"
    },
    {
      "x": -6,
      "y": 52,
      "z": -9,
      "name": "Plant_Leaves_Beech_Max_Support"
    },
    {
      "x": -6,
      "y": 53,
      "z": -9,
      "name": "Plant_Leaves_Beech_Max_Support"
    },
    {
      "x": -6,
      "y": 21,
      "z": -8,
      "name": "Plant_Leaves_Beech_Max_Support"
    },
    {
      "x": -6,
      "y": 22,
      "z": -8,
      "name": "Plant_Leaves_Beech_Max_Support"
    },
    {
      "x": -6,
      "y": 23,
      "z": -8,
      "name": "Plant_Leaves_Beech_Max_Support"
    },
    {
      "x": -6,
      "y": 24,
      "z": -8,
      "name": "Plant_Leaves_Beech_Max_Support"
    },
    {
      "x": -6,
      "y": 25,
      "z": -8,
      "name": "Plant_Leaves_Beech_Max_Support"
    },
    {
      "x": -6,
      "y": 26,
      "z": -8,
      "name": "Plant_Leaves_Beech_Max_Support"
    },
    {
      "x": -6,
      "y": 27,
      "z": -8,
      "name": "Plant_Leaves_Beech_Max_Support"
    },
    {
      "x": -6,
      "y": 36,
      "z": -8,
      "name": "Plant_Leaves_Beech_Max_Support",
      "support": 15
    },
    {
      "x": -6,
      "y": 37,
      "z": -8,
      "name": "Plant_Leaves_Beech_Max_Support"
    },
    {
      "x": -6,
      "y": 39,
      "z": -8,
      "name": "Plant_Leaves_Beech_Max_Support"
    },
    {
      "x": -6,
      "y": 40,
      "z": -8,
      "name": "Plant_Leaves_Beech_Max_Support"
    },
    {
      "x": -6,
      "y": 48,
      "z": -8,
      "name": "Wood_Gumboab_Trunk_Full"
    },
    {
      "x": -6,
      "y": 49,
      "z": -8,
      "name": "Plant_Leaves_Beech_Max_Support"
    },
    {
      "x": -6,
      "y": 50,
      "z": -8,
      "name": "Plant_Leaves_Beech_Max_Support"
    },
    {
      "x": -6,
      "y": 51,
      "z": -8,
      "name": "Plant_Leaves_Beech_Max_Support"
    },
    {
      "x": -6,
      "y": 52,
      "z": -8,
      "name": "Plant_Leaves_Beech_Max_Support"
    },
    {
      "x": -6,
      "y": 53,
      "z": -8,
      "name": "Plant_Leaves_Beech_Max_Support"
    },
    {
      "x": -6,
      "y": 21,
      "z": -7,
      "name": "Plant_Leaves_Beech_Max_Support"
    },
    {
      "x": -6,
      "y": 22,
      "z": -7,
      "name": "Wood_Gumboab_Trunk_Full"
    },
    {
      "x": -6,
      "y": 23,
      "z": -7,
      "name": "Plant_Leaves_Beech_Max_Support"
    },
    {
      "x": -6,
      "y": 24,
      "z": -7,
      "name": "Plant_Leaves_Beech_Max_Support"
    },
    {
      "x": -6,
      "y": 25,
      "z": -7,
      "name": "Plant_Leaves_Beech_Max_Support"
    },
    {
      "x": -6,
      "y": 26,
      "z": -7,
      "name": "Plant_Leaves_Beech_Max_Support"
    },
    {
      "x": -6,
      "y": 27,
      "z": -7,
      "name": "Plant_Leaves_Beech_Max_Support"
    },
    {
      "x": -6,
      "y": 28,
      "z": -7,
      "name": "Plant_Leaves_Beech_Max_Support"
    },
    {
      "x": -6,
      "y": 29,
      "z": -7,
      "name": "Plant_Leaves_Beech_Max_Support"
    },
    {
      "x": -6,
      "y": 36,
      "z": -7,
      "name": "Plant_Leaves_Beech_Max_Support"
    },
    {
      "x": -6,
      "y": 37,
      "z": -7,
      "name": "Plant_Leaves_Beech_Max_Support"
    },
    {
      "x": -6,
      "y": 38,
      "z": -7,
      "name": "Plant_Leaves_Beech_Max_Support"
    },
    {
      "x": -6,
      "y": 39,
      "z": -7,
      "name": "Plant_Leaves_Beech_Max_Support"
    },
    {
      "x": -6,
      "y": 40,
      "z": -7,
      "name": "Plant_Leaves_Beech_Max_Support"
    },
    {
      "x": -6,
      "y": 42,
      "z": -7,
      "name": "Plant_Leaves_Beech_Max_Support"
    },
    {
      "x": -6,
      "y": 47,
      "z": -7,
      "name": "Wood_Gumboab_Trunk_Full"
    },
    {
      "x": -6,
      "y": 48,
      "z": -7,
      "name": "Wood_Gumboab_Trunk_Full"
    },
    {
      "x": -6,
      "y": 49,
      "z": -7,
      "name": "Wood_Gumboab_Trunk_Full"
    },
    {
      "x": -6,
      "y": 50,
      "z": -7,
      "name": "Plant_Leaves_Beech_Max_Support"
    },
    {
      "x": -6,
      "y": 51,
      "z": -7,
      "name": "Plant_Leaves_Beech_Max_Support"
    },
    {
      "x": -6,
      "y": 52,
      "z": -7,
      "name": "Plant_Leaves_Beech_Max_Support"
    },
    {
      "x": -6,
      "y": 53,
      "z": -7,
      "name": "Plant_Leaves_Beech_Max_Support"
    },
    {
      "x": -6,
      "y": 22,
      "z": -6,
      "name": "Wood_Gumboab_Trunk_Full"
    },
    {
      "x": -6,
      "y": 23,
      "z": -6,
      "name": "Plant_Leaves_Beech_Max_Support"
    },
    {
      "x": -6,
      "y": 25,
      "z": -6,
      "name": "Plant_Leaves_Beech_Max_Support"
    },
    {
      "x": -6,
      "y": 26,
      "z": -6,
      "name": "Plant_Leaves_Beech_Max_Support"
    },
    {
      "x": -6,
      "y": 27,
      "z": -6,
      "name": "Plant_Leaves_Beech_Max_Support"
    },
    {
      "x": -6,
      "y": 28,
      "z": -6,
      "name": "Plant_Leaves_Beech_Max_Support"
    },
    {
      "x": -6,
      "y": 36,
      "z": -6,
      "name": "Plant_Leaves_Beech_Max_Support"
    },
    {
      "x": -6,
      "y": 37,
      "z": -6,
      "name": "Plant_Leaves_Beech_Max_Support"
    },
    {
      "x": -6,
      "y": 38,
      "z": -6,
      "name": "Plant_Leaves_Beech_Max_Support"
    },
    {
      "x": -6,
      "y": 39,
      "z": -6,
      "name": "Plant_Leaves_Beech_Max_Support"
    },
    {
      "x": -6,
      "y": 40,
      "z": -6,
      "name": "Plant_Leaves_Beech_Max_Support"
    },
    {
      "x": -6,
      "y": 41,
      "z": -6,
      "name": "Plant_Leaves_Beech_Max_Support"
    },
    {
      "x": -6,
      "y": 47,
      "z": -6,
      "name": "Plant_Leaves_Beech_Max_Support"
    },
    {
      "x": -6,
      "y": 48,
      "z": -6,
      "name": "Plant_Leaves_Beech_Max_Support"
    },
    {
      "x": -6,
      "y": 49,
      "z": -6,
      "name": "Plant_Leaves_Beech_Max_Support"
    },
    {
      "x": -6,
      "y": 50,
      "z": -6,
      "name": "Plant_Leaves_Beech_Max_Support"
    },
    {
      "x": -6,
      "y": 51,
      "z": -6,
      "name": "Plant_Leaves_Beech_Max_Support"
    },
    {
      "x": -6,
      "y": 52,
      "z": -6,
      "name": "Plant_Leaves_Beech_Max_Support"
    },
    {
      "x": -6,
      "y": 21,
      "z": -5,
      "name": "Plant_Leaves_Beech_Max_Support"
    },
    {
      "x": -6,
      "y": 22,
      "z": -5,
      "name": "Wood_Gumboab_Trunk_Full"
    },
    {
      "x": -6,
      "y": 23,
      "z": -5,
      "name": "Wood_Gumboab_Trunk_Full"
    },
    {
      "x": -6,
      "y": 24,
      "z": -5,
      "name": "Plant_Leaves_Beech_Max_Support"
    },
    {
      "x": -6,
      "y": 25,
      "z": -5,
      "name": "Plant_Leaves_Beech_Max_Support"
    },
    {
      "x": -6,
      "y": 36,
      "z": -5,
      "name": "Plant_Leaves_Beech_Max_Support"
    },
    {
      "x": -6,
      "y": 37,
      "z": -5,
      "name": "Plant_Leaves_Beech_Max_Support"
    },
    {
      "x": -6,
      "y": 38,
      "z": -5,
      "name": "Plant_Leaves_Beech_Max_Support"
    },
    {
      "x": -6,
      "y": 39,
      "z": -5,
      "name": "Plant_Leaves_Beech_Max_Support"
    },
    {
      "x": -6,
      "y": 40,
      "z": -5,
      "name": "Plant_Leaves_Beech_Max_Support"
    },
    {
      "x": -6,
      "y": 41,
      "z": -5,
      "name": "Plant_Leaves_Beech_Max_Support"
    },
    {
      "x": -6,
      "y": 42,
      "z": -5,
      "name": "Plant_Leaves_Beech_Max_Support"
    },
    {
      "x": -6,
      "y": 47,
      "z": -5,
      "name": "Plant_Leaves_Beech_Max_Support"
    },
    {
      "x": -6,
      "y": 48,
      "z": -5,
      "name": "Plant_Leaves_Beech_Max_Support"
    },
    {
      "x": -6,
      "y": 49,
      "z": -5,
      "name": "Plant_Leaves_Beech_Max_Support"
    },
    {
      "x": -6,
      "y": 50,
      "z": -5,
      "name": "Plant_Leaves_Beech_Max_Support"
    },
    {
      "x": -6,
      "y": 51,
      "z": -5,
      "name": "Plant_Leaves_Beech_Max_Support"
    },
    {
      "x": -6,
      "y": 52,
      "z": -5,
      "name": "Plant_Leaves_Beech_Max_Support"
    },
    {
      "x": -6,
      "y": 22,
      "z": -4,
      "name": "Wood_Gumboab_Trunk_Full"
    },
    {
      "x": -6,
      "y": 23,
      "z": -4,
      "name": "Wood_Gumboab_Trunk_Full"
    },
    {
      "x": -6,
      "y": 24,
      "z": -4,
      "name": "Plant_Leaves_Beech_Max_Support"
    },
    {
      "x": -6,
      "y": 25,
      "z": -4,
      "name": "Plant_Leaves_Beech_Max_Support"
    },
    {
      "x": -6,
      "y": 26,
      "z": -4,
      "name": "Plant_Leaves_Beech_Max_Support"
    },
    {
      "x": -6,
      "y": 37,
      "z": -4,
      "name": "Plant_Leaves_Beech_Max_Support"
    },
    {
      "x": -6,
      "y": 38,
      "z": -4,
      "name": "Plant_Leaves_Beech_Max_Support"
    },
    {
      "x": -6,
      "y": 39,
      "z": -4,
      "name": "Plant_Leaves_Beech_Max_Support"
    },
    {
      "x": -6,
      "y": 40,
      "z": -4,
      "name": "Plant_Leaves_Beech_Max_Support"
    },
    {
      "x": -6,
      "y": 41,
      "z": -4,
      "name": "Plant_Leaves_Beech_Max_Support"
    },
    {
      "x": -6,
      "y": 42,
      "z": -4,
      "name": "Plant_Leaves_Beech_Max_Support"
    },
    {
      "x": -6,
      "y": 47,
      "z": -4,
      "name": "Plant_Leaves_Beech_Max_Support"
    },
    {
      "x": -6,
      "y": 48,
      "z": -4,
      "name": "Plant_Leaves_Beech_Max_Support"
    },
    {
      "x": -6,
      "y": 49,
      "z": -4,
      "name": "Plant_Leaves_Beech_Max_Support"
    },
    {
      "x": -6,
      "y": 50,
      "z": -4,
      "name": "Plant_Leaves_Beech_Max_Support"
    },
    {
      "x": -6,
      "y": 51,
      "z": -4,
      "name": "Plant_Leaves_Beech_Max_Support"
    },
    {
      "x": -6,
      "y": 20,
      "z": -3,
      "name": "Plant_Leaves_Beech_Max_Support"
    },
    {
      "x": -6,
      "y": 21,
      "z": -3,
      "name": "Plant_Leaves_Beech_Max_Support"
    },
    {
      "x": -6,
      "y": 22,
      "z": -3,
      "name": "Plant_Leaves_Beech_Max_Support"
    },
    {
      "x": -6,
      "y": 23,
      "z": -3,
      "name": "Wood_Gumboab_Trunk_Full"
    },
    {
      "x": -6,
      "y": 24,
      "z": -3,
      "name": "Plant_Leaves_Beech_Max_Support"
    },
    {
      "x": -6,
      "y": 26,
      "z": -3,
      "name": "Plant_Leaves_Beech_Max_Support"
    },
    {
      "x": -6,
      "y": 36,
      "z": -3,
      "name": "Plant_Leaves_Beech_Max_Support",
      "support": 15
    },
    {
      "x": -6,
      "y": 37,
      "z": -3,
      "name": "Plant_Leaves_Beech_Max_Support",
      "support": 15
    },
    {
      "x": -6,
      "y": 38,
      "z": -3,
      "name": "Plant_Leaves_Beech_Max_Support"
    },
    {
      "x": -6,
      "y": 39,
      "z": -3,
      "name": "Plant_Leaves_Beech_Max_Support"
    },
    {
      "x": -6,
      "y": 40,
      "z": -3,
      "name": "Plant_Leaves_Beech_Max_Support"
    },
    {
      "x": -6,
      "y": 42,
      "z": -3,
      "name": "Plant_Leaves_Beech_Max_Support"
    },
    {
      "x": -6,
      "y": 46,
      "z": -3,
      "name": "Plant_Leaves_Beech_Max_Support"
    },
    {
      "x": -6,
      "y": 47,
      "z": -3,
      "name": "Plant_Leaves_Beech_Max_Support"
    },
    {
      "x": -6,
      "y": 48,
      "z": -3,
      "name": "Plant_Leaves_Beech_Max_Support"
    },
    {
      "x": -6,
      "y": 22,
      "z": -2,
      "name": "Plant_Leaves_Beech_Max_Support"
    },
    {
      "x": -6,
      "y": 23,
      "z": -2,
      "name": "Plant_Leaves_Beech_Max_Support"
    },
    {
      "x": -6,
      "y": 36,
      "z": -2,
      "name": "Plant_Leaves_Beech_Max_Support",
      "support": 15
    },
    {
      "x": -6,
      "y": 37,
      "z": -2,
      "name": "Plant_Leaves_Beech_Max_Support"
    },
    {
      "x": -6,
      "y": 38,
      "z": -2,
      "name": "Plant_Leaves_Beech_Max_Support"
    },
    {
      "x": -6,
      "y": 39,
      "z": -2,
      "name": "Plant_Leaves_Beech_Max_Support"
    },
    {
      "x": -6,
      "y": 46,
      "z": -2,
      "name": "Plant_Leaves_Beech_Max_Support"
    },
    {
      "x": -6,
      "y": 47,
      "z": -2,
      "name": "Plant_Leaves_Beech_Max_Support"
    },
    {
      "x": -6,
      "y": 48,
      "z": -2,
      "name": "Plant_Leaves_Beech_Max_Support"
    },
    {
      "x": -6,
      "y": 49,
      "z": -2,
      "name": "Plant_Leaves_Beech_Max_Support"
    },
    {
      "x": -6,
      "y": 50,
      "z": -2,
      "name": "Plant_Leaves_Beech_Max_Support"
    },
    {
      "x": -6,
      "y": 22,
      "z": -1,
      "name": "Plant_Leaves_Beech_Max_Support"
    },
    {
      "x": -6,
      "y": 38,
      "z": -1,
      "name": "Plant_Leaves_Beech_Max_Support"
    },
    {
      "x": -6,
      "y": 39,
      "z": -1,
      "name": "Plant_Leaves_Beech_Max_Support"
    },
    {
      "x": -6,
      "y": 40,
      "z": -1,
      "name": "Plant_Leaves_Beech_Max_Support"
    },
    {
      "x": -6,
      "y": 41,
      "z": -1,
      "name": "Plant_Leaves_Beech_Max_Support"
    },
    {
      "x": -6,
      "y": 45,
      "z": -1,
      "name": "Plant_Leaves_Beech_Max_Support"
    },
    {
      "x": -6,
      "y": 47,
      "z": -1,
      "name": "Plant_Leaves_Beech_Max_Support"
    },
    {
      "x": -6,
      "y": 48,
      "z": -1,
      "name": "Plant_Leaves_Beech_Max_Support"
    },
    {
      "x": -6,
      "y": 49,
      "z": -1,
      "name": "Plant_Leaves_Beech_Max_Support"
    },
    {
      "x": -6,
      "y": 36,
      "z": 0,
      "name": "Wood_Gumboab_Trunk_Full"
    },
    {
      "x": -6,
      "y": 37,
      "z": 0,
      "name": "Wood_Gumboab_Trunk_Full"
    },
    {
      "x": -6,
      "y": 38,
      "z": 0,
      "name": "Plant_Leaves_Beech_Max_Support"
    },
    {
      "x": -6,
      "y": 39,
      "z": 0,
      "name": "Plant_Leaves_Beech_Max_Support"
    },
    {
      "x": -6,
      "y": 40,
      "z": 0,
      "name": "Plant_Leaves_Beech_Max_Support"
    },
    {
      "x": -6,
      "y": 41,
      "z": 0,
      "name": "Plant_Leaves_Beech_Max_Support"
    },
    {
      "x": -6,
      "y": 48,
      "z": 0,
      "name": "Plant_Leaves_Beech_Max_Support"
    },
    {
      "x": -6,
      "y": 37,
      "z": 1,
      "name": "Plant_Leaves_Beech_Max_Support"
    },
    {
      "x": -6,
      "y": 38,
      "z": 1,
      "name": "Plant_Leaves_Beech_Max_Support"
    },
    {
      "x": -6,
      "y": 39,
      "z": 1,
      "name": "Plant_Leaves_Beech_Max_Support"
    },
    {
      "x": -6,
      "y": 40,
      "z": 1,
      "name": "Plant_Leaves_Beech_Max_Support"
    },
    {
      "x": -6,
      "y": 41,
      "z": 1,
      "name": "Plant_Leaves_Beech_Max_Support"
    },
    {
      "x": -6,
      "y": 47,
      "z": 1,
      "name": "Plant_Leaves_Beech_Max_Support"
    },
    {
      "x": -6,
      "y": 48,
      "z": 1,
      "name": "Plant_Leaves_Beech_Max_Support"
    },
    {
      "x": -6,
      "y": 49,
      "z": 1,
      "name": "Plant_Leaves_Beech_Max_Support"
    },
    {
      "x": -6,
      "y": 34,
      "z": 2,
      "name": "Plant_Leaves_Beech_Max_Support"
    },
    {
      "x": -6,
      "y": 35,
      "z": 2,
      "name": "Plant_Leaves_Beech_Max_Support"
    },
    {
      "x": -6,
      "y": 37,
      "z": 2,
      "name": "Plant_Leaves_Beech_Max_Support"
    },
    {
      "x": -6,
      "y": 39,
      "z": 2,
      "name": "Plant_Leaves_Beech_Max_Support"
    },
    {
      "x": -6,
      "y": 40,
      "z": 2,
      "name": "Plant_Leaves_Beech_Max_Support"
    },
    {
      "x": -6,
      "y": 44,
      "z": 2,
      "name": "Plant_Leaves_Beech_Max_Support"
    },
    {
      "x": -6,
      "y": 47,
      "z": 2,
      "name": "Plant_Leaves_Beech_Max_Support"
    },
    {
      "x": -6,
      "y": 48,
      "z": 2,
      "name": "Plant_Leaves_Beech_Max_Support"
    },
    {
      "x": -6,
      "y": 49,
      "z": 2,
      "name": "Plant_Leaves_Beech_Max_Support"
    },
    {
      "x": -6,
      "y": 33,
      "z": 3,
      "name": "Plant_Leaves_Beech_Max_Support"
    },
    {
      "x": -6,
      "y": 35,
      "z": 3,
      "name": "Plant_Leaves_Beech_Max_Support"
    },
    {
      "x": -6,
      "y": 36,
      "z": 3,
      "name": "Plant_Leaves_Beech_Max_Support"
    },
    {
      "x": -6,
      "y": 37,
      "z": 3,
      "name": "Plant_Leaves_Beech_Max_Support"
    },
    {
      "x": -6,
      "y": 38,
      "z": 3,
      "name": "Plant_Leaves_Beech_Max_Support"
    },
    {
      "x": -6,
      "y": 39,
      "z": 3,
      "name": "Plant_Leaves_Beech_Max_Support"
    },
    {
      "x": -6,
      "y": 40,
      "z": 3,
      "name": "Plant_Leaves_Beech_Max_Support"
    },
    {
      "x": -6,
      "y": 44,
      "z": 3,
      "name": "Plant_Leaves_Beech_Max_Support"
    },
    {
      "x": -6,
      "y": 45,
      "z": 3,
      "name": "Plant_Leaves_Beech_Max_Support"
    },
    {
      "x": -6,
      "y": 47,
      "z": 3,
      "name": "Plant_Leaves_Beech_Max_Support"
    },
    {
      "x": -6,
      "y": 48,
      "z": 3,
      "name": "Plant_Leaves_Beech_Max_Support"
    },
    {
      "x": -6,
      "y": 32,
      "z": 4,
      "name": "Plant_Leaves_Beech_Max_Support"
    },
    {
      "x": -6,
      "y": 36,
      "z": 4,
      "name": "Plant_Leaves_Beech_Max_Support"
    },
    {
      "x": -6,
      "y": 38,
      "z": 4,
      "name": "Plant_Leaves_Beech_Max_Support"
    },
    {
      "x": -6,
      "y": 44,
      "z": 4,
      "name": "Plant_Leaves_Beech_Max_Support"
    },
    {
      "x": -6,
      "y": 45,
      "z": 4,
      "name": "Plant_Leaves_Beech_Max_Support"
    },
    {
      "x": -6,
      "y": 46,
      "z": 4,
      "name": "Plant_Leaves_Beech_Max_Support"
    },
    {
      "x": -6,
      "y": 47,
      "z": 4,
      "name": "Plant_Leaves_Beech_Max_Support"
    },
    {
      "x": -6,
      "y": 48,
      "z": 4,
      "name": "Plant_Leaves_Beech_Max_Support"
    },
    {
      "x": -6,
      "y": 49,
      "z": 4,
      "name": "Plant_Leaves_Beech_Max_Support"
    },
    {
      "x": -6,
      "y": 30,
      "z": 5,
      "name": "Plant_Leaves_Beech_Max_Support"
    },
    {
      "x": -6,
      "y": 31,
      "z": 5,
      "name": "Plant_Leaves_Beech_Max_Support"
    },
    {
      "x": -6,
      "y": 32,
      "z": 5,
      "name": "Plant_Leaves_Beech_Max_Support"
    },
    {
      "x": -6,
      "y": 33,
      "z": 5,
      "name": "Plant_Leaves_Beech_Max_Support"
    },
    {
      "x": -6,
      "y": 34,
      "z": 5,
      "name": "Plant_Leaves_Beech_Max_Support"
    },
    {
      "x": -6,
      "y": 35,
      "z": 5,
      "name": "Plant_Leaves_Beech_Max_Support"
    },
    {
      "x": -6,
      "y": 45,
      "z": 5,
      "name": "Plant_Leaves_Beech_Max_Support"
    },
    {
      "x": -6,
      "y": 47,
      "z": 5,
      "name": "Plant_Leaves_Beech_Max_Support"
    },
    {
      "x": -6,
      "y": 29,
      "z": 6,
      "name": "Plant_Leaves_Beech_Max_Support"
    },
    {
      "x": -6,
      "y": 32,
      "z": 6,
      "name": "Plant_Leaves_Beech_Max_Support"
    },
    {
      "x": -6,
      "y": 33,
      "z": 6,
      "name": "Plant_Leaves_Beech_Max_Support"
    },
    {
      "x": -6,
      "y": 34,
      "z": 6,
      "name": "Plant_Leaves_Beech_Max_Support"
    },
    {
      "x": -6,
      "y": 45,
      "z": 6,
      "name": "Plant_Leaves_Beech_Max_Support",
      "support": 15
    },
    {
      "x": -6,
      "y": 47,
      "z": 6,
      "name": "Plant_Leaves_Beech_Max_Support"
    },
    {
      "x": -6,
      "y": 48,
      "z": 6,
      "name": "Plant_Leaves_Beech_Max_Support"
    },
    {
      "x": -6,
      "y": 29,
      "z": 7,
      "name": "Plant_Leaves_Beech_Max_Support",
      "support": 15
    },
    {
      "x": -6,
      "y": 30,
      "z": 7,
      "name": "Plant_Leaves_Beech_Max_Support"
    },
    {
      "x": -6,
      "y": 31,
      "z": 7,
      "name": "Plant_Leaves_Beech_Max_Support"
    },
    {
      "x": -6,
      "y": 32,
      "z": 7,
      "name": "Plant_Leaves_Beech_Max_Support"
    },
    {
      "x": -6,
      "y": 29,
      "z": 8,
      "name": "Plant_Leaves_Beech_Max_Support"
    },
    {
      "x": -6,
      "y": 30,
      "z": 8,
      "name": "Plant_Leaves_Beech_Max_Support"
    },
    {
      "x": -6,
      "y": 31,
      "z": 8,
      "name": "Plant_Leaves_Beech_Max_Support"
    },
    {
      "x": -6,
      "y": 32,
      "z": 8,
      "name": "Plant_Leaves_Beech_Max_Support"
    },
    {
      "x": -6,
      "y": 31,
      "z": 9,
      "name": "Plant_Leaves_Beech_Max_Support"
    },
    {
      "x": -6,
      "y": 32,
      "z": 9,
      "name": "Plant_Leaves_Beech_Max_Support"
    },
    {
      "x": -6,
      "y": 28,
      "z": 10,
      "name": "Plant_Leaves_Beech_Max_Support"
    },
    {
      "x": -6,
      "y": 29,
      "z": 10,
      "name": "Plant_Leaves_Beech_Max_Support"
    },
    {
      "x": -6,
      "y": 30,
      "z": 10,
      "name": "Plant_Leaves_Beech_Max_Support"
    },
    {
      "x": -6,
      "y": 31,
      "z": 10,
      "name": "Plant_Leaves_Beech_Max_Support"
    },
    {
      "x": -6,
      "y": 32,
      "z": 10,
      "name": "Plant_Leaves_Beech_Max_Support"
    },
    {
      "x": -6,
      "y": 33,
      "z": 10,
      "name": "Plant_Leaves_Beech_Max_Support"
    },
    {
      "x": -6,
      "y": 28,
      "z": 11,
      "name": "Plant_Leaves_Beech_Max_Support"
    },
    {
      "x": -6,
      "y": 29,
      "z": 11,
      "name": "Plant_Leaves_Beech_Max_Support"
    },
    {
      "x": -6,
      "y": 32,
      "z": 11,
      "name": "Plant_Leaves_Beech_Max_Support"
    },
    {
      "x": -6,
      "y": 29,
      "z": 12,
      "name": "Plant_Leaves_Beech_Max_Support"
    },
    {
      "x": -6,
      "y": 30,
      "z": 12,
      "name": "Plant_Leaves_Beech_Max_Support"
    },
    {
      "x": -6,
      "y": 31,
      "z": 12,
      "name": "Plant_Leaves_Beech_Max_Support"
    },
    {
      "x": -5,
      "y": 46,
      "z": -14,
      "name": "Plant_Leaves_Beech_Max_Support"
    },
    {
      "x": -5,
      "y": 47,
      "z": -14,
      "name": "Plant_Leaves_Beech_Max_Support"
    },
    {
      "x": -5,
      "y": 48,
      "z": -14,
      "name": "Plant_Leaves_Beech_Max_Support"
    },
    {
      "x": -5,
      "y": 21,
      "z": -13,
      "name": "Plant_Leaves_Beech_Max_Support"
    },
    {
      "x": -5,
      "y": 22,
      "z": -13,
      "name": "Plant_Leaves_Beech_Max_Support"
    },
    {
      "x": -5,
      "y": 23,
      "z": -13,
      "name": "Plant_Leaves_Beech_Max_Support"
    },
    {
      "x": -5,
      "y": 24,
      "z": -13,
      "name": "Plant_Leaves_Beech_Max_Support"
    },
    {
      "x": -5,
      "y": 45,
      "z": -13,
      "name": "Plant_Leaves_Beech_Max_Support"
    },
    {
      "x": -5,
      "y": 46,
      "z": -13,
      "name": "Plant_Leaves_Beech_Max_Support"
    },
    {
      "x": -5,
      "y": 47,
      "z": -13,
      "name": "Plant_Leaves_Beech_Max_Support"
    },
    {
      "x": -5,
      "y": 49,
      "z": -13,
      "name": "Plant_Leaves_Beech_Max_Support"
    },
    {
      "x": -5,
      "y": 51,
      "z": -13,
      "name": "Plant_Leaves_Beech_Max_Support"
    },
    {
      "x": -5,
      "y": 21,
      "z": -12,
      "name": "Plant_Leaves_Beech_Max_Support"
    },
    {
      "x": -5,
      "y": 22,
      "z": -12,
      "name": "Plant_Leaves_Beech_Max_Support"
    },
    {
      "x": -5,
      "y": 23,
      "z": -12,
      "name": "Plant_Leaves_Beech_Max_Support"
    },
    {
      "x": -5,
      "y": 24,
      "z": -12,
      "name": "Plant_Leaves_Beech_Max_Support"
    },
    {
      "x": -5,
      "y": 25,
      "z": -12,
      "name": "Plant_Leaves_Beech_Max_Support"
    },
    {
      "x": -5,
      "y": 46,
      "z": -12,
      "name": "Plant_Leaves_Beech_Max_Support"
    },
    {
      "x": -5,
      "y": 47,
      "z": -12,
      "name": "Plant_Leaves_Beech_Max_Support",
      "support": 15
    },
    {
      "x": -5,
      "y": 48,
      "z": -12,
      "name": "Plant_Leaves_Beech_Max_Support"
    },
    {
      "x": -5,
      "y": 52,
      "z": -12,
      "name": "Plant_Leaves_Beech_Max_Support"
    },
    {
      "x": -5,
      "y": 22,
      "z": -11,
      "name": "Plant_Leaves_Beech_Max_Support"
    },
    {
      "x": -5,
      "y": 23,
      "z": -11,
      "name": "Plant_Leaves_Beech_Max_Support"
    },
    {
      "x": -5,
      "y": 24,
      "z": -11,
      "name": "Plant_Leaves_Beech_Max_Support"
    },
    {
      "x": -5,
      "y": 25,
      "z": -11,
      "name": "Plant_Leaves_Beech_Max_Support"
    },
    {
      "x": -5,
      "y": 26,
      "z": -11,
      "name": "Plant_Leaves_Beech_Max_Support"
    },
    {
      "x": -5,
      "y": 27,
      "z": -11,
      "name": "Plant_Leaves_Beech_Max_Support"
    },
    {
      "x": -5,
      "y": 28,
      "z": -11,
      "name": "Plant_Leaves_Beech_Max_Support"
    },
    {
      "x": -5,
      "y": 47,
      "z": -11,
      "name": "Plant_Leaves_Beech_Max_Support"
    },
    {
      "x": -5,
      "y": 48,
      "z": -11,
      "name": "Plant_Leaves_Beech_Max_Support"
    },
    {
      "x": -5,
      "y": 50,
      "z": -11,
      "name": "Plant_Leaves_Beech_Max_Support"
    },
    {
      "x": -5,
      "y": 51,
      "z": -11,
      "name": "Plant_Leaves_Beech_Max_Support"
    },
    {
      "x": -5,
      "y": 52,
      "z": -11,
      "name": "Plant_Leaves_Beech_Max_Support"
    },
    {
      "x": -5,
      "y": 53,
      "z": -11,
      "name": "Plant_Leaves_Beech_Max_Support"
    },
    {
      "x": -5,
      "y": 21,
      "z": -10,
      "name": "Plant_Leaves_Beech_Max_Support"
    },
    {
      "x": -5,
      "y": 22,
      "z": -10,
      "name": "Plant_Leaves_Beech_Max_Support"
    },
    {
      "x": -5,
      "y": 23,
      "z": -10,
      "name": "Plant_Leaves_Beech_Max_Support"
    },
    {
      "x": -5,
      "y": 24,
      "z": -10,
      "name": "Plant_Leaves_Beech_Max_Support"
    },
    {
      "x": -5,
      "y": 25,
      "z": -10,
      "name": "Plant_Leaves_Beech_Max_Support"
    },
    {
      "x": -5,
      "y": 26,
      "z": -10,
      "name": "Plant_Leaves_Beech_Max_Support"
    },
    {
      "x": -5,
      "y": 27,
      "z": -10,
      "name": "Plant_Leaves_Beech_Max_Support"
    },
    {
      "x": -5,
      "y": 28,
      "z": -10,
      "name": "Plant_Leaves_Beech_Max_Support"
    },
    {
      "x": -5,
      "y": 38,
      "z": -10,
      "name": "Plant_Leaves_Beech_Max_Support",
      "support": 15
    },
    {
      "x": -5,
      "y": 48,
      "z": -10,
      "name": "Plant_Leaves_Beech_Max_Support"
    },
    {
      "x": -5,
      "y": 49,
      "z": -10,
      "name": "Plant_Leaves_Beech_Max_Support"
    },
    {
      "x": -5,
      "y": 50,
      "z": -10,
      "name": "Plant_Leaves_Beech_Max_Support"
    },
    {
      "x": -5,
      "y": 51,
      "z": -10,
      "name": "Plant_Leaves_Beech_Max_Support"
    },
    {
      "x": -5,
      "y": 52,
      "z": -10,
      "name": "Plant_Leaves_Beech_Max_Support"
    },
    {
      "x": -5,
      "y": 53,
      "z": -10,
      "name": "Plant_Leaves_Beech_Max_Support"
    },
    {
      "x": -5,
      "y": 21,
      "z": -9,
      "name": "Plant_Leaves_Beech_Max_Support"
    },
    {
      "x": -5,
      "y": 22,
      "z": -9,
      "name": "Plant_Leaves_Beech_Max_Support"
    },
    {
      "x": -5,
      "y": 23,
      "z": -9,
      "name": "Plant_Leaves_Beech_Max_Support"
    },
    {
      "x": -5,
      "y": 24,
      "z": -9,
      "name": "Plant_Leaves_Beech_Max_Support"
    },
    {
      "x": -5,
      "y": 25,
      "z": -9,
      "name": "Plant_Leaves_Beech_Max_Support"
    },
    {
      "x": -5,
      "y": 26,
      "z": -9,
      "name": "Plant_Leaves_Beech_Max_Support"
    },
    {
      "x": -5,
      "y": 27,
      "z": -9,
      "name": "Plant_Leaves_Beech_Max_Support"
    },
    {
      "x": -5,
      "y": 29,
      "z": -9,
      "name": "Plant_Leaves_Beech_Max_Support"
    },
    {
      "x": -5,
      "y": 30,
      "z": -9,
      "name": "Plant_Leaves_Beech_Max_Support"
    },
    {
      "x": -5,
      "y": 38,
      "z": -9,
      "name": "Plant_Leaves_Beech_Max_Support",
      "support": 15
    },
    {
      "x": -5,
      "y": 39,
      "z": -9,
      "name": "Plant_Leaves_Beech_Max_Support",
      "support": 15
    },
    {
      "x": -5,
      "y": 48,
      "z": -9,
      "name": "Plant_Leaves_Beech_Max_Support"
    },
    {
      "x": -5,
      "y": 49,
      "z": -9,
      "name": "Plant_Leaves_Beech_Max_Support"
    },
    {
      "x": -5,
      "y": 50,
      "z": -9,
      "name": "Plant_Leaves_Beech_Max_Support"
    },
    {
      "x": -5,
      "y": 51,
      "z": -9,
      "name": "Plant_Leaves_Beech_Max_Support"
    },
    {
      "x": -5,
      "y": 52,
      "z": -9,
      "name": "Plant_Leaves_Beech_Max_Support"
    },
    {
      "x": -5,
      "y": 53,
      "z": -9,
      "name": "Plant_Leaves_Beech_Max_Support"
    },
    {
      "x": -5,
      "y": 21,
      "z": -8,
      "name": "Wood_Gumboab_Trunk_Full"
    },
    {
      "x": -5,
      "y": 22,
      "z": -8,
      "name": "Wood_Gumboab_Trunk_Full"
    },
    {
      "x": -5,
      "y": 23,
      "z": -8,
      "name": "Plant_Leaves_Beech_Max_Support"
    },
    {
      "x": -5,
      "y": 24,
      "z": -8,
      "name": "Plant_Leaves_Beech_Max_Support"
    },
    {
      "x": -5,
      "y": 25,
      "z": -8,
      "name": "Plant_Leaves_Beech_Max_Support"
    },
    {
      "x": -5,
      "y": 26,
      "z": -8,
      "name": "Plant_Leaves_Beech_Max_Support"
    },
    {
      "x": -5,
      "y": 27,
      "z": -8,
      "name": "Plant_Leaves_Beech_Max_Support"
    },
    {
      "x": -5,
      "y": 28,
      "z": -8,
      "name": "Plant_Leaves_Beech_Max_Support"
    },
    {
      "x": -5,
      "y": 36,
      "z": -8,
      "name": "Plant_Leaves_Beech_Max_Support",
      "support": 15
    },
    {
      "x": -5,
      "y": 37,
      "z": -8,
      "name": "Plant_Leaves_Beech_Max_Support",
      "support": 15
    },
    {
      "x": -5,
      "y": 38,
      "z": -8,
      "name": "Plant_Leaves_Beech_Max_Support",
      "support": 15
    },
    {
      "x": -5,
      "y": 39,
      "z": -8,
      "name": "Plant_Leaves_Beech_Max_Support",
      "support": 15
    },
    {
      "x": -5,
      "y": 40,
      "z": -8,
      "name": "Plant_Leaves_Beech_Max_Support"
    },
    {
      "x": -5,
      "y": 47,
      "z": -8,
      "name": "Plant_Leaves_Beech_Max_Support"
    },
    {
      "x": -5,
      "y": 48,
      "z": -8,
      "name": "Wood_Gumboab_Trunk_Full"
    },
    {
      "x": -5,
      "y": 49,
      "z": -8,
      "name": "Plant_Leaves_Beech_Max_Support"
    },
    {
      "x": -5,
      "y": 50,
      "z": -8,
      "name": "Plant_Leaves_Beech_Max_Support"
    },
    {
      "x": -5,
      "y": 51,
      "z": -8,
      "name": "Plant_Leaves_Beech_Max_Support"
    },
    {
      "x": -5,
      "y": 52,
      "z": -8,
      "name": "Plant_Leaves_Beech_Max_Support"
    },
    {
      "x": -5,
      "y": 53,
      "z": -8,
      "name": "Plant_Leaves_Beech_Max_Support"
    },
    {
      "x": -5,
      "y": 3,
      "z": -7,
      "name": "Wood_Gumboab_Trunk_Full"
    },
    {
      "x": -5,
      "y": 4,
      "z": -7,
      "name": "Wood_Gumboab_Trunk_Full"
    },
    {
      "x": -5,
      "y": 5,
      "z": -7,
      "name": "Wood_Gumboab_Trunk_Full"
    },
    {
      "x": -5,
      "y": 21,
      "z": -7,
      "name": "Wood_Gumboab_Trunk_Full"
    },
    {
      "x": -5,
      "y": 22,
      "z": -7,
      "name": "Wood_Gumboab_Trunk_Full"
    },
    {
      "x": -5,
      "y": 23,
      "z": -7,
      "name": "Plant_Leaves_Beech_Max_Support"
    },
    {
      "x": -5,
      "y": 24,
      "z": -7,
      "name": "Plant_Leaves_Beech_Max_Support"
    },
    {
      "x": -5,
      "y": 25,
      "z": -7,
      "name": "Plant_Leaves_Beech_Max_Support"
    },
    {
      "x": -5,
      "y": 26,
      "z": -7,
      "name": "Plant_Leaves_Beech_Max_Support"
    },
    {
      "x": -5,
      "y": 27,
      "z": -7,
      "name": "Plant_Leaves_Beech_Max_Support"
    },
    {
      "x": -5,
      "y": 28,
      "z": -7,
      "name": "Plant_Leaves_Beech_Max_Support"
    },
    {
      "x": -5,
      "y": 29,
      "z": -7,
      "name": "Plant_Leaves_Beech_Max_Support"
    },
    {
      "x": -5,
      "y": 30,
      "z": -7,
      "name": "Plant_Leaves_Beech_Max_Support"
    },
    {
      "x": -5,
      "y": 37,
      "z": -7,
      "name": "Plant_Leaves_Beech_Max_Support"
    },
    {
      "x": -5,
      "y": 38,
      "z": -7,
      "name": "Plant_Leaves_Beech_Max_Support"
    },
    {
      "x": -5,
      "y": 39,
      "z": -7,
      "name": "Plant_Leaves_Beech_Max_Support"
    },
    {
      "x": -5,
      "y": 40,
      "z": -7,
      "name": "Plant_Leaves_Beech_Max_Support"
    },
    {
      "x": -5,
      "y": 41,
      "z": -7,
      "name": "Plant_Leaves_Beech_Max_Support"
    },
    {
      "x": -5,
      "y": 46,
      "z": -7,
      "name": "Wood_Gumboab_Trunk_Full"
    },
    {
      "x": -5,
      "y": 47,
      "z": -7,
      "name": "Wood_Gumboab_Trunk_Full"
    },
    {
      "x": -5,
      "y": 48,
      "z": -7,
      "name": "Wood_Gumboab_Trunk_Full"
    },
    {
      "x": -5,
      "y": 49,
      "z": -7,
      "name": "Plant_Leaves_Beech_Max_Support"
    },
    {
      "x": -5,
      "y": 50,
      "z": -7,
      "name": "Plant_Leaves_Beech_Max_Support"
    },
    {
      "x": -5,
      "y": 51,
      "z": -7,
      "name": "Plant_Leaves_Beech_Max_Support"
    },
    {
      "x": -5,
      "y": 52,
      "z": -7,
      "name": "Plant_Leaves_Beech_Max_Support"
    },
    {
      "x": -5,
      "y": 53,
      "z": -7,
      "name": "Plant_Leaves_Beech_Max_Support"
    },
    {
      "x": -5,
      "y": 1,
      "z": -6,
      "name": "Wood_Gumboab_Roots"
    },
    {
      "x": -5,
      "y": 2,
      "z": -6,
      "name": "Wood_Gumboab_Trunk_Full"
    },
    {
      "x": -5,
      "y": 3,
      "z": -6,
      "name": "Wood_Gumboab_Trunk_Full"
    },
    {
      "x": -5,
      "y": 4,
      "z": -6,
      "name": "Wood_Gumboab_Trunk_Full"
    },
    {
      "x": -5,
      "y": 5,
      "z": -6,
      "name": "Wood_Gumboab_Trunk_Full"
    },
    {
      "x": -5,
      "y": 21,
      "z": -6,
      "name": "Plant_Leaves_Beech_Max_Support"
    },
    {
      "x": -5,
      "y": 22,
      "z": -6,
      "name": "Wood_Gumboab_Trunk_Full"
    },
    {
      "x": -5,
      "y": 23,
      "z": -6,
      "name": "Plant_Leaves_Beech_Max_Support"
    },
    {
      "x": -5,
      "y": 24,
      "z": -6,
      "name": "Plant_Leaves_Beech_Max_Support"
    },
    {
      "x": -5,
      "y": 25,
      "z": -6,
      "name": "Plant_Leaves_Beech_Max_Support"
    },
    {
      "x": -5,
      "y": 26,
      "z": -6,
      "name": "Plant_Leaves_Beech_Max_Support"
    },
    {
      "x": -5,
      "y": 27,
      "z": -6,
      "name": "Plant_Leaves_Beech_Max_Support"
    },
    {
      "x": -5,
      "y": 28,
      "z": -6,
      "name": "Plant_Leaves_Beech_Max_Support"
    },
    {
      "x": -5,
      "y": 29,
      "z": -6,
      "name": "Plant_Leaves_Beech_Max_Support"
    },
    {
      "x": -5,
      "y": 35,
      "z": -6,
      "name": "Wood_Gumboab_Trunk_Full"
    },
    {
      "x": -5,
      "y": 36,
      "z": -6,
      "name": "Wood_Gumboab_Trunk_Full"
    },
    {
      "x": -5,
      "y": 38,
      "z": -6,
      "name": "Plant_Leaves_Beech_Max_Support"
    },
    {
      "x": -5,
      "y": 39,
      "z": -6,
      "name": "Plant_Leaves_Beech_Max_Support"
    },
    {
      "x": -5,
      "y": 40,
      "z": -6,
      "name": "Plant_Leaves_Beech_Max_Support"
    },
    {
      "x": -5,
      "y": 41,
      "z": -6,
      "name": "Plant_Leaves_Beech_Max_Support"
    },
    {
      "x": -5,
      "y": 46,
      "z": -6,
      "name": "Wood_Gumboab_Trunk_Full"
    },
    {
      "x": -5,
      "y": 47,
      "z": -6,
      "name": "Wood_Gumboab_Trunk_Full"
    },
    {
      "x": -5,
      "y": 48,
      "z": -6,
      "name": "Plant_Leaves_Beech_Max_Support"
    },
    {
      "x": -5,
      "y": 49,
      "z": -6,
      "name": "Plant_Leaves_Beech_Max_Support"
    },
    {
      "x": -5,
      "y": 50,
      "z": -6,
      "name": "Plant_Leaves_Beech_Max_Support"
    },
    {
      "x": -5,
      "y": 51,
      "z": -6,
      "name": "Plant_Leaves_Beech_Max_Support"
    },
    {
      "x": -5,
      "y": 52,
      "z": -6,
      "name": "Plant_Leaves_Beech_Max_Support"
    },
    {
      "x": -5,
      "y": 53,
      "z": -6,
      "name": "Plant_Leaves_Beech_Max_Support"
    },
    {
      "x": -5,
      "y": 2,
      "z": -5,
      "name": "Wood_Gumboab_Roots"
    },
    {
      "x": -5,
      "y": 3,
      "z": -5,
      "name": "Wood_Gumboab_Trunk_Full"
    },
    {
      "x": -5,
      "y": 21,
      "z": -5,
      "name": "Plant_Leaves_Beech_Max_Support"
    },
    {
      "x": -5,
      "y": 22,
      "z": -5,
      "name": "Wood_Gumboab_Trunk_Full"
    },
    {
      "x": -5,
      "y": 23,
      "z": -5,
      "name": "Plant_Leaves_Beech_Max_Support"
    },
    {
      "x": -5,
      "y": 25,
      "z": -5,
      "name": "Plant_Leaves_Beech_Max_Support"
    },
    {
      "x": -5,
      "y": 26,
      "z": -5,
      "name": "Plant_Leaves_Beech_Max_Support"
    },
    {
      "x": -5,
      "y": 27,
      "z": -5,
      "name": "Plant_Leaves_Beech_Max_Support"
    },
    {
      "x": -5,
      "y": 36,
      "z": -5,
      "name": "Wood_Gumboab_Trunk_Full"
    },
    {
      "x": -5,
      "y": 37,
      "z": -5,
      "name": "Plant_Leaves_Beech_Max_Support"
    },
    {
      "x": -5,
      "y": 38,
      "z": -5,
      "name": "Plant_Leaves_Beech_Max_Support"
    },
    {
      "x": -5,
      "y": 39,
      "z": -5,
      "name": "Plant_Leaves_Beech_Max_Support"
    },
    {
      "x": -5,
      "y": 40,
      "z": -5,
      "name": "Plant_Leaves_Beech_Max_Support"
    },
    {
      "x": -5,
      "y": 41,
      "z": -5,
      "name": "Plant_Leaves_Beech_Max_Support"
    },
    {
      "x": -5,
      "y": 46,
      "z": -5,
      "name": "Plant_Leaves_Beech_Max_Support"
    },
    {
      "x": -5,
      "y": 47,
      "z": -5,
      "name": "Plant_Leaves_Beech_Max_Support"
    },
    {
      "x": -5,
      "y": 48,
      "z": -5,
      "name": "Plant_Leaves_Beech_Max_Support"
    },
    {
      "x": -5,
      "y": 49,
      "z": -5,
      "name": "Plant_Leaves_Beech_Max_Support"
    },
    {
      "x": -5,
      "y": 50,
      "z": -5,
      "name": "Plant_Leaves_Beech_Max_Support"
    },
    {
      "x": -5,
      "y": 51,
      "z": -5,
      "name": "Plant_Leaves_Beech_Max_Support"
    },
    {
      "x": -5,
      "y": 52,
      "z": -5,
      "name": "Plant_Leaves_Beech_Max_Support"
    },
    {
      "x": -5,
      "y": 21,
      "z": -4,
      "name": "Plant_Leaves_Beech_Max_Support"
    },
    {
      "x": -5,
      "y": 22,
      "z": -4,
      "name": "Plant_Leaves_Beech_Max_Support"
    },
    {
      "x": -5,
      "y": 23,
      "z": -4,
      "name": "Plant_Leaves_Beech_Max_Support"
    },
    {
      "x": -5,
      "y": 24,
      "z": -4,
      "name": "Plant_Leaves_Beech_Max_Support"
    },
    {
      "x": -5,
      "y": 25,
      "z": -4,
      "name": "Plant_Leaves_Beech_Max_Support"
    },
    {
      "x": -5,
      "y": 26,
      "z": -4,
      "name": "Plant_Leaves_Beech_Max_Support"
    },
    {
      "x": -5,
      "y": 36,
      "z": -4,
      "name": "Wood_Gumboab_Trunk_Full"
    },
    {
      "x": -5,
      "y": 37,
      "z": -4,
      "name": "Plant_Leaves_Beech_Max_Support"
    },
    {
      "x": -5,
      "y": 38,
      "z": -4,
      "name": "Plant_Leaves_Beech_Max_Support"
    },
    {
      "x": -5,
      "y": 39,
      "z": -4,
      "name": "Plant_Leaves_Beech_Max_Support"
    },
    {
      "x": -5,
      "y": 40,
      "z": -4,
      "name": "Plant_Leaves_Beech_Max_Support"
    },
    {
      "x": -5,
      "y": 45,
      "z": -4,
      "name": "Plant_Leaves_Beech_Max_Support"
    },
    {
      "x": -5,
      "y": 46,
      "z": -4,
      "name": "Plant_Leaves_Beech_Max_Support"
    },
    {
      "x": -5,
      "y": 47,
      "z": -4,
      "name": "Plant_Leaves_Beech_Max_Support"
    },
    {
      "x": -5,
      "y": 48,
      "z": -4,
      "name": "Plant_Leaves_Beech_Max_Support"
    },
    {
      "x": -5,
      "y": 49,
      "z": -4,
      "name": "Plant_Leaves_Beech_Max_Support"
    },
    {
      "x": -5,
      "y": 50,
      "z": -4,
      "name": "Plant_Leaves_Beech_Max_Support"
    },
    {
      "x": -5,
      "y": 51,
      "z": -4,
      "name": "Plant_Leaves_Beech_Max_Support"
    },
    {
      "x": -5,
      "y": 25,
      "z": -3,
      "name": "Plant_Leaves_Beech_Max_Support"
    },
    {
      "x": -5,
      "y": 26,
      "z": -3,
      "name": "Plant_Leaves_Beech_Max_Support"
    },
    {
      "x": -5,
      "y": 36,
      "z": -3,
      "name": "Plant_Leaves_Beech_Max_Support"
    },
    {
      "x": -5,
      "y": 37,
      "z": -3,
      "name": "Plant_Leaves_Beech_Max_Support"
    },
    {
      "x": -5,
      "y": 38,
      "z": -3,
      "name": "Plant_Leaves_Beech_Max_Support"
    },
    {
      "x": -5,
      "y": 39,
      "z": -3,
      "name": "Plant_Leaves_Beech_Max_Support"
    },
    {
      "x": -5,
      "y": 40,
      "z": -3,
      "name": "Plant_Leaves_Beech_Max_Support"
    },
    {
      "x": -5,
      "y": 41,
      "z": -3,
      "name": "Plant_Leaves_Beech_Max_Support"
    },
    {
      "x": -5,
      "y": 45,
      "z": -3,
      "name": "Plant_Leaves_Beech_Max_Support"
    },
    {
      "x": -5,
      "y": 46,
      "z": -3,
      "name": "Plant_Leaves_Beech_Max_Support"
    },
    {
      "x": -5,
      "y": 47,
      "z": -3,
      "name": "Plant_Leaves_Beech_Max_Support"
    },
    {
      "x": -5,
      "y": 51,
      "z": -3,
      "name": "Plant_Leaves_Beech_Max_Support"
    },
    {
      "x": -5,
      "y": 5,
      "z": -2,
      "name": "Wood_Gumboab_Trunk_Full"
    },
    {
      "x": -5,
      "y": 6,
      "z": -2,
      "name": "Wood_Gumboab_Trunk_Full"
    },
    {
      "x": -5,
      "y": 22,
      "z": -2,
      "name": "Plant_Leaves_Beech_Max_Support"
    },
    {
      "x": -5,
      "y": 23,
      "z": -2,
      "name": "Plant_Leaves_Beech_Max_Support"
    },
    {
      "x": -5,
      "y": 25,
      "z": -2,
      "name": "Plant_Leaves_Beech_Max_Support"
    },
    {
      "x": -5,
      "y": 37,
      "z": -2,
      "name": "Plant_Leaves_Beech_Max_Support"
    },
    {
      "x": -5,
      "y": 38,
      "z": -2,
      "name": "Plant_Leaves_Beech_Max_Support"
    },
    {
      "x": -5,
      "y": 39,
      "z": -2,
      "name": "Plant_Leaves_Beech_Max_Support"
    },
    {
      "x": -5,
      "y": 40,
      "z": -2,
      "name": "Plant_Leaves_Beech_Max_Support"
    },
    {
      "x": -5,
      "y": 45,
      "z": -2,
      "name": "Plant_Leaves_Beech_Max_Support"
    },
    {
      "x": -5,
      "y": 48,
      "z": -2,
      "name": "Plant_Leaves_Beech_Max_Support"
    },
    {
      "x": -5,
      "y": 50,
      "z": -2,
      "name": "Plant_Leaves_Beech_Max_Support"
    },
    {
      "x": -5,
      "y": 51,
      "z": -2,
      "name": "Plant_Leaves_Beech_Max_Support"
    },
    {
      "x": -5,
      "y": 3,
      "z": -1,
      "name": "Wood_Gumboab_Roots"
    },
    {
      "x": -5,
      "y": 4,
      "z": -1,
      "name": "Wood_Gumboab_Trunk_Full"
    },
    {
      "x": -5,
      "y": 5,
      "z": -1,
      "name": "Wood_Gumboab_Trunk_Full"
    },
    {
      "x": -5,
      "y": 6,
      "z": -1,
      "name": "Wood_Gumboab_Trunk_Full"
    },
    {
      "x": -5,
      "y": 23,
      "z": -1,
      "name": "Plant_Leaves_Beech_Max_Support"
    },
    {
      "x": -5,
      "y": 24,
      "z": -1,
      "name": "Plant_Leaves_Beech_Max_Support"
    },
    {
      "x": -5,
      "y": 37,
      "z": -1,
      "name": "Plant_Leaves_Beech_Max_Support",
      "support": 15
    },
    {
      "x": -5,
      "y": 38,
      "z": -1,
      "name": "Plant_Leaves_Beech_Max_Support"
    },
    {
      "x": -5,
      "y": 39,
      "z": -1,
      "name": "Plant_Leaves_Beech_Max_Support"
    },
    {
      "x": -5,
      "y": 40,
      "z": -1,
      "name": "Plant_Leaves_Beech_Max_Support"
    },
    {
      "x": -5,
      "y": 41,
      "z": -1,
      "name": "Plant_Leaves_Beech_Max_Support"
    },
    {
      "x": -5,
      "y": 42,
      "z": -1,
      "name": "Plant_Leaves_Beech_Max_Support"
    },
    {
      "x": -5,
      "y": 45,
      "z": -1,
      "name": "Plant_Leaves_Beech_Max_Support"
    },
    {
      "x": -5,
      "y": 46,
      "z": -1,
      "name": "Plant_Leaves_Beech_Max_Support"
    },
    {
