{
  "version": 8,
  "blockIdVersion": 11,
  "anchorX": -2,
  "anchorY": 14,
  "anchorZ": -9,
  "blocks": [
    {
      "x": -19,
      "y": 33,
      "z": -6,
      "name": "Plant_Leaves_Beech_Max_Support"
    },
    {
      "x": -19,
      "y": 35,
      "z": -6,
      "name": "Plant_Leaves_Beech_Max_Support"
    },
    {
      "x": -19,
      "y": 34,
      "z": -5,
      "name": "Plant_Leaves_Beech_Max_Support"
    },
    {
      "x": -19,
      "y": 35,
      "z": -5,
      "name": "Plant_Leaves_Beech_Max_Support"
    },
    {
      "x": -19,
      "y": 35,
      "z": -4,
      "name": "Plant_Leaves_Beech_Max_Support"
    },
    {
      "x": -18,
      "y": 33,
      "z": -12,
      "name": "Plant_Leaves_Beech_Max_Support",
      "support": 15
    },
    {
      "x": -18,
      "y": 32,
      "z": -8,
      "name": "Plant_Leaves_Beech_Max_Support",
      "support": 15
    },
    {
      "x": -18,
      "y": 32,
      "z": -7,
      "name": "Plant_Leaves_Beech_Max_Support",
      "support": 15
    },
    {
      "x": -18,
      "y": 34,
      "z": -7,
      "name": "Plant_Leaves_Beech_Max_Support"
    },
    {
      "x": -18,
      "y": 35,
      "z": -7,
      "name": "Plant_Leaves_Beech_Max_Support"
    },
    {
      "x": -18,
      "y": 32,
      "z": -6,
      "name": "Plant_Leaves_Beech_Max_Support"
    },
    {
      "x": -18,
      "y": 33,
      "z": -6,
      "name": "Plant_Leaves_Beech_Max_Support"
    },
    {
      "x": -18,
      "y": 35,
      "z": -6,
      "name": "Plant_Leaves_Beech_Max_Support"
    },
    {
      "x": -18,
      "y": 36,
      "z": -6,
      "name": "Plant_Leaves_Beech_Max_Support"
    },
    {
      "x": -18,
      "y": 33,
      "z": -5,
      "name": "Plant_Leaves_Beech_Max_Support"
    },
    {
      "x": -18,
      "y": 34,
      "z": -5,
      "name": "Plant_Leaves_Beech_Max_Support"
    },
    {
      "x": -18,
      "y": 35,
      "z": -5,
      "name": "Plant_Leaves_Beech_Max_Support"
    },
    {
      "x": -18,
      "y": 36,
      "z": -5,
      "name": "Plant_Leaves_Beech_Max_Support"
    },
    {
      "x": -18,
      "y": 32,
      "z": -4,
      "name": "Plant_Leaves_Beech_Max_Support",
      "support": 15
    },
    {
      "x": -18,
      "y": 36,
      "z": -4,
      "name": "Plant_Leaves_Beech_Max_Support"
    },
    {
      "x": -18,
      "y": 34,
      "z": -3,
      "name": "Plant_Leaves_Beech_Max_Support"
    },
    {
      "x": -18,
      "y": 35,
      "z": -3,
      "name": "Plant_Leaves_Beech_Max_Support"
    },
    {
      "x": -17,
      "y": 33,
      "z": -12,
      "name": "Plant_Leaves_Beech_Max_Support"
    },
    {
      "x": -17,
      "y": 35,
      "z": -12,
      "name": "Plant_Leaves_Beech_Max_Support"
    },
    {
      "x": -17,
      "y": 3,
      "z": -11,
      "name": "Wood_Gumboab_Roots"
    },
    {
      "x": -17,
      "y": 4,
      "z": -11,
      "name": "Wood_Gumboab_Trunk_Full"
    },
    {
      "x": -17,
      "y": 5,
      "z": -11,
      "name": "Wood_Gumboab_Trunk_Full"
    },
    {
      "x": -17,
      "y": 34,
      "z": -11,
      "name": "Plant_Leaves_Beech_Max_Support"
    },
    {
      "x": -17,
      "y": 35,
      "z": -11,
      "name": "Plant_Leaves_Beech_Max_Support"
    },
    {
      "x": -17,
      "y": 33,
      "z": -10,
      "name": "Plant_Leaves_Beech_Max_Support",
      "support": 15
    },
    {
      "x": -17,
      "y": 32,
      "z": -8,
      "name": "Plant_Leaves_Beech_Max_Support"
    },
    {
      "x": -17,
      "y": 33,
      "z": -8,
      "name": "Plant_Leaves_Beech_Max_Support"
    },
    {
      "x": -17,
      "y": 34,
      "z": -8,
      "name": "Plant_Leaves_Beech_Max_Support"
    },
    {
      "x": -17,
      "y": 35,
      "z": -8,
      "name": "Plant_Leaves_Beech_Max_Support"
    },
    {
      "x": -17,
      "y": 32,
      "z": -7,
      "name": "Plant_Leaves_Beech_Max_Support"
    },
    {
      "x": -17,
      "y": 33,
      "z": -7,
      "name": "Plant_Leaves_Beech_Max_Support"
    },
    {
      "x": -17,
      "y": 34,
      "z": -7,
      "name": "Plant_Leaves_Beech_Max_Support"
    },
    {
      "x": -17,
      "y": 35,
      "z": -7,
      "name": "Plant_Leaves_Beech_Max_Support"
    },
    {
      "x": -17,
      "y": 36,
      "z": -7,
      "name": "Plant_Leaves_Beech_Max_Support"
    },
    {
      "x": -17,
      "y": 32,
      "z": -6,
      "name": "Plant_Leaves_Beech_Max_Support"
    },
    {
      "x": -17,
      "y": 33,
      "z": -6,
      "name": "Plant_Leaves_Beech_Max_Support"
    },
    {
      "x": -17,
      "y": 34,
      "z": -6,
      "name": "Plant_Leaves_Beech_Max_Support"
    },
    {
      "x": -17,
      "y": 35,
      "z": -6,
      "name": "Plant_Leaves_Beech_Max_Support"
    },
    {
      "x": -17,
      "y": 36,
      "z": -6,
      "name": "Plant_Leaves_Beech_Max_Support"
    },
    {
      "x": -17,
      "y": 31,
      "z": -5,
      "name": "Plant_Leaves_Beech_Max_Support"
    },
    {
      "x": -17,
      "y": 32,
      "z": -5,
      "name": "Plant_Leaves_Beech_Max_Support"
    },
    {
      "x": -17,
      "y": 34,
      "z": -5,
      "name": "Plant_Leaves_Beech_Max_Support"
    },
    {
      "x": -17,
      "y": 35,
      "z": -5,
      "name": "Plant_Leaves_Beech_Max_Support"
    },
    {
      "x": -17,
      "y": 36,
      "z": -5,
      "name": "Plant_Leaves_Beech_Max_Support"
    },
    {
      "x": -17,
      "y": 37,
      "z": -5,
      "name": "Plant_Leaves_Beech_Max_Support"
    },
    {
      "x": -17,
      "y": 32,
      "z": -4,
      "name": "Plant_Leaves_Beech_Max_Support",
      "support": 15
    },
    {
      "x": -17,
      "y": 34,
      "z": -4,
      "name": "Plant_Leaves_Beech_Max_Support"
    },
    {
      "x": -17,
      "y": 37,
      "z": -4,
      "name": "Plant_Leaves_Beech_Max_Support"
    },
    {
      "x": -17,
      "y": 32,
      "z": -3,
      "name": "Plant_Leaves_Beech_Max_Support"
    },
    {
      "x": -17,
      "y": 33,
      "z": -2,
      "name": "Plant_Leaves_Beech_Max_Support"
    },
    {
      "x": -17,
      "y": 34,
      "z": -2,
      "name": "Plant_Leaves_Beech_Max_Support"
    },
    {
      "x": -16,
      "y": 33,
      "z": -14,
      "name": "Plant_Leaves_Beech_Max_Support"
    },
    {
      "x": -16,
      "y": 34,
      "z": -14,
      "name": "Plant_Leaves_Beech_Max_Support"
    },
    {
      "x": -16,
      "y": 35,
      "z": -14,
      "name": "Plant_Leaves_Beech_Max_Support"
    },
    {
      "x": -16,
      "y": 33,
      "z": -13,
      "name": "Plant_Leaves_Beech_Max_Support"
    },
    {
      "x": -16,
      "y": 34,
      "z": -13,
      "name": "Plant_Leaves_Beech_Max_Support"
    },
    {
      "x": -16,
      "y": 35,
      "z": -13,
      "name": "Plant_Leaves_Beech_Max_Support"
    },
    {
      "x": -16,
      "y": 36,
      "z": -13,
      "name": "Plant_Leaves_Beech_Max_Support"
    },
    {
      "x": -16,
      "y": 32,
      "z": -12,
      "name": "Plant_Leaves_Beech_Max_Support"
    },
    {
      "x": -16,
      "y": 33,
      "z": -12,
      "name": "Plant_Leaves_Beech_Max_Support"
    },
    {
      "x": -16,
      "y": 35,
      "z": -12,
      "name": "Plant_Leaves_Beech_Max_Support"
    },
    {
      "x": -16,
      "y": 36,
      "z": -12,
      "name": "Plant_Leaves_Beech_Max_Support"
    },
    {
      "x": -16,
      "y": 3,
      "z": -11,
      "name": "Wood_Gumboab_Roots"
    },
    {
      "x": -16,
      "y": 4,
      "z": -11,
      "name": "Wood_Gumboab_Trunk_Full"
    },
    {
      "x": -16,
      "y": 5,
      "z": -11,
      "name": "Wood_Gumboab_Trunk_Full"
    },
    {
      "x": -16,
      "y": 6,
      "z": -11,
      "name": "Wood_Gumboab_Trunk_Full"
    },
    {
      "x": -16,
      "y": 7,
      "z": -11,
      "name": "Wood_Gumboab_Trunk_Full"
    },
    {
      "x": -16,
      "y": 8,
      "z": -11,
      "name": "Wood_Gumboab_Trunk_Full"
    },
    {
      "x": -16,
      "y": 32,
      "z": -11,
      "name": "Plant_Leaves_Beech_Max_Support"
    },
    {
      "x": -16,
      "y": 33,
      "z": -11,
      "name": "Plant_Leaves_Beech_Max_Support"
    },
    {
      "x": -16,
      "y": 34,
      "z": -11,
      "name": "Plant_Leaves_Beech_Max_Support"
    },
    {
      "x": -16,
      "y": 35,
      "z": -11,
      "name": "Plant_Leaves_Beech_Max_Support"
    },
    {
      "x": -16,
      "y": 36,
      "z": -11,
      "name": "Plant_Leaves_Beech_Max_Support"
    },
    {
      "x": -16,
      "y": 33,
      "z": -10,
      "name": "Plant_Leaves_Beech_Max_Support"
    },
    {
      "x": -16,
      "y": 33,
      "z": -9,
      "name": "Plant_Leaves_Beech_Max_Support",
      "support": 15
    },
    {
      "x": -16,
      "y": 34,
      "z": -9,
      "name": "Plant_Leaves_Beech_Max_Support"
    },
    {
      "x": -16,
      "y": 32,
      "z": -8,
      "name": "Plant_Leaves_Beech_Max_Support"
    },
    {
      "x": -16,
      "y": 33,
      "z": -8,
      "name": "Plant_Leaves_Beech_Max_Support"
    },
    {
      "x": -16,
      "y": 34,
      "z": -8,
      "name": "Plant_Leaves_Beech_Max_Support"
    },
    {
      "x": -16,
      "y": 35,
      "z": -8,
      "name": "Plant_Leaves_Beech_Max_Support"
    },
    {
      "x": -16,
      "y": 31,
      "z": -7,
      "name": "Plant_Leaves_Beech_Max_Support"
    },
    {
      "x": -16,
      "y": 32,
      "z": -7,
      "name": "Plant_Leaves_Beech_Max_Support"
    },
    {
      "x": -16,
      "y": 33,
      "z": -7,
      "name": "Plant_Leaves_Beech_Max_Support"
    },
    {
      "x": -16,
      "y": 35,
      "z": -7,
      "name": "Plant_Leaves_Beech_Max_Support"
    },
    {
      "x": -16,
      "y": 31,
      "z": -6,
      "name": "Plant_Leaves_Beech_Max_Support"
    },
    {
      "x": -16,
      "y": 32,
      "z": -6,
      "name": "Plant_Leaves_Beech_Max_Support"
    },
    {
      "x": -16,
      "y": 33,
      "z": -6,
      "name": "Plant_Leaves_Beech_Max_Support"
    },
    {
      "x": -16,
      "y": 34,
      "z": -6,
      "name": "Plant_Leaves_Beech_Max_Support"
    },
    {
      "x": -16,
      "y": 35,
      "z": -6,
      "name": "Plant_Leaves_Beech_Max_Support"
    },
    {
      "x": -16,
      "y": 37,
      "z": -6,
      "name": "Plant_Leaves_Beech_Max_Support"
    },
    {
      "x": -16,
      "y": 31,
      "z": -5,
      "name": "Plant_Leaves_Beech_Max_Support"
    },
    {
      "x": -16,
      "y": 32,
      "z": -5,
      "name": "Plant_Leaves_Beech_Max_Support"
    },
    {
      "x": -16,
      "y": 33,
      "z": -5,
      "name": "Plant_Leaves_Beech_Max_Support"
    },
    {
      "x": -16,
      "y": 34,
      "z": -5,
      "name": "Plant_Leaves_Beech_Max_Support"
    },
    {
      "x": -16,
      "y": 35,
      "z": -5,
      "name": "Plant_Leaves_Beech_Max_Support"
    },
    {
      "x": -16,
      "y": 36,
      "z": -5,
      "name": "Plant_Leaves_Beech_Max_Support"
    },
    {
      "x": -16,
      "y": 37,
      "z": -5,
      "name": "Plant_Leaves_Beech_Max_Support"
    },
    {
      "x": -16,
      "y": 31,
      "z": -4,
      "name": "Plant_Leaves_Beech_Max_Support"
    },
    {
      "x": -16,
      "y": 32,
      "z": -4,
      "name": "Plant_Leaves_Beech_Max_Support",
      "support": 15
    },
    {
      "x": -16,
      "y": 33,
      "z": -4,
      "name": "Plant_Leaves_Beech_Max_Support"
    },
    {
      "x": -16,
      "y": 34,
      "z": -4,
      "name": "Plant_Leaves_Beech_Max_Support"
    },
    {
      "x": -16,
      "y": 35,
      "z": -4,
      "name": "Plant_Leaves_Beech_Max_Support"
    },
    {
      "x": -16,
      "y": 36,
      "z": -4,
      "name": "Plant_Leaves_Beech_Max_Support"
    },
    {
      "x": -16,
      "y": 33,
      "z": -3,
      "name": "Plant_Leaves_Beech_Max_Support"
    },
    {
      "x": -16,
      "y": 34,
      "z": -3,
      "name": "Plant_Leaves_Beech_Max_Support"
    },
    {
      "x": -16,
      "y": 36,
      "z": -3,
      "name": "Plant_Leaves_Beech_Max_Support"
    },
    {
      "x": -16,
      "y": 34,
      "z": -2,
      "name": "Plant_Leaves_Beech_Max_Support"
    },
    {
      "x": -16,
      "y": 35,
      "z": -2,
      "name": "Plant_Leaves_Beech_Max_Support"
    },
    {
      "x": -16,
      "y": 35,
      "z": -1,
      "name": "Plant_Leaves_Beech_Max_Support"
    },
    {
      "x": -16,
      "y": 36,
      "z": -1,
      "name": "Plant_Leaves_Beech_Max_Support"
    },
    {
      "x": -16,
      "y": 37,
      "z": -1,
      "name": "Plant_Leaves_Beech_Max_Support"
    },
    {
      "x": -15,
      "y": 5,
      "z": -17,
      "name": "Wood_Gumboab_Trunk_Full"
    },
    {
      "x": -15,
      "y": 6,
      "z": -17,
      "name": "Wood_Gumboab_Trunk_Full"
    },
    {
      "x": -15,
      "y": 7,
      "z": -17,
      "name": "Wood_Gumboab_Trunk_Full"
    },
    {
      "x": -15,
      "y": 8,
      "z": -17,
      "name": "Wood_Gumboab_Trunk_Full"
    },
    {
      "x": -15,
      "y": 3,
      "z": -16,
      "name": "Wood_Gumboab_Roots"
    },
    {
      "x": -15,
      "y": 4,
      "z": -16,
      "name": "Wood_Gumboab_Trunk_Full"
    },
    {
      "x": -15,
      "y": 5,
      "z": -16,
      "name": "Wood_Gumboab_Trunk_Full"
    },
    {
      "x": -15,
      "y": 6,
      "z": -16,
      "name": "Wood_Gumboab_Trunk_Full"
    },
    {
      "x": -15,
      "y": 7,
      "z": -16,
      "name": "Wood_Gumboab_Trunk_Full"
    },
    {
      "x": -15,
      "y": 33,
      "z": -16,
      "name": "Plant_Leaves_Beech_Max_Support",
      "support": 15
    },
    {
      "x": -15,
      "y": 34,
      "z": -16,
      "name": "Plant_Leaves_Beech_Max_Support",
      "support": 15
    },
    {
      "x": -15,
      "y": 35,
      "z": -15,
      "name": "Plant_Leaves_Beech_Max_Support"
    },
    {
      "x": -15,
      "y": 32,
      "z": -14,
      "name": "Plant_Leaves_Beech_Max_Support",
      "support": 15
    },
    {
      "x": -15,
      "y": 33,
      "z": -14,
      "name": "Plant_Leaves_Beech_Max_Support"
    },
    {
      "x": -15,
      "y": 34,
      "z": -14,
      "name": "Plant_Leaves_Beech_Max_Support"
    },
    {
      "x": -15,
      "y": 9,
      "z": -13,
      "name": "Wood_Gumboab_Trunk_Full"
    },
    {
      "x": -15,
      "y": 32,
      "z": -13,
      "name": "Plant_Leaves_Beech_Max_Support"
    },
    {
      "x": -15,
      "y": 33,
      "z": -13,
      "name": "Plant_Leaves_Beech_Max_Support"
    },
    {
      "x": -15,
      "y": 8,
      "z": -12,
      "name": "Wood_Gumboab_Trunk_Full"
    },
    {
      "x": -15,
      "y": 9,
      "z": -12,
      "name": "Wood_Gumboab_Trunk_Full"
    },
    {
      "x": -15,
      "y": 31,
      "z": -12,
      "name": "Plant_Leaves_Beech_Max_Support"
    },
    {
      "x": -15,
      "y": 32,
      "z": -12,
      "name": "Plant_Leaves_Beech_Max_Support"
    },
    {
      "x": -15,
      "y": 33,
      "z": -12,
      "name": "Plant_Leaves_Beech_Max_Support"
    },
    {
      "x": -15,
      "y": 34,
      "z": -12,
      "name": "Plant_Leaves_Beech_Max_Support"
    },
    {
      "x": -15,
      "y": 37,
      "z": -12,
      "name": "Plant_Leaves_Beech_Max_Support"
    },
    {
      "x": -15,
      "y": 7,
      "z": -11,
      "name": "Wood_Gumboab_Trunk_Full"
    },
    {
      "x": -15,
      "y": 8,
      "z": -11,
      "name": "Wood_Gumboab_Trunk_Full"
    },
    {
      "x": -15,
      "y": 31,
      "z": -11,
      "name": "Plant_Leaves_Beech_Max_Support"
    },
    {
      "x": -15,
      "y": 32,
      "z": -11,
      "name": "Plant_Leaves_Beech_Max_Support"
    },
    {
      "x": -15,
      "y": 33,
      "z": -11,
      "name": "Plant_Leaves_Beech_Max_Support"
    },
    {
      "x": -15,
      "y": 34,
      "z": -11,
      "name": "Plant_Leaves_Beech_Max_Support"
    },
    {
      "x": -15,
      "y": 35,
      "z": -11,
      "name": "Plant_Leaves_Beech_Max_Support"
    },
    {
      "x": -15,
      "y": 31,
      "z": -10,
      "name": "Plant_Leaves_Beech_Max_Support"
    },
    {
      "x": -15,
      "y": 32,
      "z": -10,
      "name": "Plant_Leaves_Beech_Max_Support"
    },
    {
      "x": -15,
      "y": 33,
      "z": -10,
      "name": "Plant_Leaves_Beech_Max_Support"
    },
    {
      "x": -15,
      "y": 34,
      "z": -10,
      "name": "Plant_Leaves_Beech_Max_Support"
    },
    {
      "x": -15,
      "y": 35,
      "z": -10,
      "name": "Plant_Leaves_Beech_Max_Support"
    },
    {
      "x": -15,
      "y": 36,
      "z": -10,
      "name": "Plant_Leaves_Beech_Max_Support"
    },
    {
      "x": -15,
      "y": 31,
      "z": -9,
      "name": "Plant_Leaves_Beech_Max_Support"
    },
    {
      "x": -15,
      "y": 33,
      "z": -9,
      "name": "Plant_Leaves_Beech_Max_Support"
    },
    {
      "x": -15,
      "y": 34,
      "z": -9,
      "name": "Plant_Leaves_Beech_Max_Support"
    },
    {
      "x": -15,
      "y": 35,
      "z": -9,
      "name": "Plant_Leaves_Beech_Max_Support"
    },
    {
      "x": -15,
      "y": 31,
      "z": -8,
      "name": "Plant_Leaves_Beech_Max_Support"
    },
    {
      "x": -15,
      "y": 32,
      "z": -8,
      "name": "Plant_Leaves_Beech_Max_Support"
    },
    {
      "x": -15,
      "y": 33,
      "z": -8,
      "name": "Plant_Leaves_Beech_Max_Support"
    },
    {
      "x": -15,
      "y": 34,
      "z": -8,
      "name": "Plant_Leaves_Beech_Max_Support"
    },
    {
      "x": -15,
      "y": 35,
      "z": -8,
      "name": "Plant_Leaves_Beech_Max_Support"
    },
    {
      "x": -15,
      "y": 36,
      "z": -8,
      "name": "Plant_Leaves_Beech_Max_Support"
    },
    {
      "x": -15,
      "y": 32,
      "z": -7,
      "name": "Plant_Leaves_Beech_Max_Support"
    },
    {
      "x": -15,
      "y": 34,
      "z": -7,
      "name": "Plant_Leaves_Beech_Max_Support"
    },
    {
      "x": -15,
      "y": 35,
      "z": -7,
      "name": "Plant_Leaves_Beech_Max_Support"
    },
    {
      "x": -15,
      "y": 36,
      "z": -7,
      "name": "Plant_Leaves_Beech_Max_Support"
    },
    {
      "x": -15,
      "y": 30,
      "z": -6,
      "name": "Plant_Leaves_Beech_Max_Support"
    },
    {
      "x": -15,
      "y": 31,
      "z": -6,
      "name": "Plant_Leaves_Beech_Max_Support"
    },
    {
      "x": -15,
      "y": 32,
      "z": -6,
      "name": "Plant_Leaves_Beech_Max_Support"
    },
    {
      "x": -15,
      "y": 33,
      "z": -6,
      "name": "Plant_Leaves_Beech_Max_Support"
    },
    {
      "x": -15,
      "y": 34,
      "z": -6,
      "name": "Plant_Leaves_Beech_Max_Support"
    },
    {
      "x": -15,
      "y": 35,
      "z": -6,
      "name": "Plant_Leaves_Beech_Max_Support"
    },
    {
      "x": -15,
      "y": 36,
      "z": -6,
      "name": "Plant_Leaves_Beech_Max_Support"
    },
    {
      "x": -15,
      "y": 37,
      "z": -6,
      "name": "Plant_Leaves_Beech_Max_Support"
    },
    {
      "x": -15,
      "y": 31,
      "z": -5,
      "name": "Plant_Leaves_Beech_Max_Support"
    },
    {
      "x": -15,
      "y": 32,
      "z": -5,
      "name": "Plant_Leaves_Beech_Max_Support"
    },
    {
      "x": -15,
      "y": 33,
      "z": -5,
      "name": "Plant_Leaves_Beech_Max_Support"
    },
    {
      "x": -15,
      "y": 34,
      "z": -5,
      "name": "Plant_Leaves_Beech_Max_Support"
    },
    {
      "x": -15,
      "y": 35,
      "z": -5,
      "name": "Plant_Leaves_Beech_Max_Support"
    },
    {
      "x": -15,
      "y": 36,
      "z": -5,
      "name": "Plant_Leaves_Beech_Max_Support"
    },
    {
      "x": -15,
      "y": 37,
      "z": -5,
      "name": "Plant_Leaves_Beech_Max_Support"
    },
    {
      "x": -15,
      "y": 31,
      "z": -4,
      "name": "Plant_Leaves_Beech_Max_Support"
    },
    {
      "x": -15,
      "y": 32,
      "z": -4,
      "name": "Plant_Leaves_Beech_Max_Support",
      "support": 15
    },
    {
      "x": -15,
      "y": 33,
      "z": -4,
      "name": "Plant_Leaves_Beech_Max_Support"
    },
    {
      "x": -15,
      "y": 34,
      "z": -4,
      "name": "Plant_Leaves_Beech_Max_Support"
    },
    {
      "x": -15,
      "y": 35,
      "z": -4,
      "name": "Plant_Leaves_Beech_Max_Support"
    },
    {
      "x": -15,
      "y": 36,
      "z": -4,
      "name": "Plant_Leaves_Beech_Max_Support"
    },
    {
      "x": -15,
      "y": 37,
      "z": -4,
      "name": "Plant_Leaves_Beech_Max_Support"
    },
    {
      "x": -15,
      "y": 32,
      "z": -3,
      "name": "Plant_Leaves_Beech_Max_Support"
    },
    {
      "x": -15,
      "y": 34,
      "z": -3,
      "name": "Plant_Leaves_Beech_Max_Support"
    },
    {
      "x": -15,
      "y": 35,
      "z": -3,
      "name": "Plant_Leaves_Beech_Max_Support"
    },
    {
      "x": -15,
      "y": 36,
      "z": -3,
      "name": "Plant_Leaves_Beech_Max_Support"
    },
    {
      "x": -15,
      "y": 37,
      "z": -3,
      "name": "Plant_Leaves_Beech_Max_Support"
    },
    {
      "x": -15,
      "y": 38,
      "z": -3,
      "name": "Plant_Leaves_Beech_Max_Support"
    },
    {
      "x": -15,
      "y": 34,
      "z": -2,
      "name": "Plant_Leaves_Beech_Max_Support"
    },
    {
      "x": -15,
      "y": 35,
      "z": -2,
      "name": "Plant_Leaves_Beech_Max_Support"
    },
    {
      "x": -15,
      "y": 36,
      "z": -2,
      "name": "Plant_Leaves_Beech_Max_Support"
    },
    {
      "x": -15,
      "y": 37,
      "z": -2,
      "name": "Plant_Leaves_Beech_Max_Support"
    },
    {
      "x": -15,
      "y": 35,
      "z": -1,
      "name": "Plant_Leaves_Beech_Max_Support"
    },
    {
      "x": -15,
      "y": 37,
      "z": -1,
      "name": "Plant_Leaves_Beech_Max_Support"
    },
    {
      "x": -15,
      "y": 38,
      "z": -1,
      "name": "Plant_Leaves_Beech_Max_Support"
    },
    {
      "x": -15,
      "y": 34,
      "z": 0,
      "name": "Plant_Leaves_Beech_Max_Support",
      "support": 15
    },
    {
      "x": -15,
      "y": 35,
      "z": 0,
      "name": "Plant_Leaves_Beech_Max_Support"
    },
    {
      "x": -14,
      "y": 3,
      "z": -18,
      "name": "Plant_Vine_Jungle",
      "support": 15,
      "rotation": 2
    },
    {
      "x": -14,
      "y": 4,
      "z": -18,
      "name": "Plant_Vine_Jungle",
      "support": 15,
      "rotation": 2
    },
    {
      "x": -14,
      "y": 5,
      "z": -18,
      "name": "Plant_Vine_Jungle",
      "support": 15,
      "rotation": 2
    },
    {
      "x": -14,
      "y": 6,
      "z": -18,
      "name": "Plant_Vine_Jungle",
      "support": 15,
      "rotation": 2
    },
    {
      "x": -14,
      "y": 7,
      "z": -18,
      "name": "Plant_Vine_Jungle",
      "support": 15,
      "rotation": 2
    },
    {
      "x": -14,
      "y": 8,
      "z": -18,
      "name": "Plant_Vine_Jungle",
      "support": 15,
      "rotation": 2
    },
    {
      "x": -14,
      "y": 9,
      "z": -18,
      "name": "Plant_Vine_Jungle",
      "support": 15,
      "rotation": 2
    },
    {
      "x": -14,
      "y": 6,
      "z": -17,
      "name": "Wood_Gumboab_Trunk_Full"
    },
    {
      "x": -14,
      "y": 7,
      "z": -17,
      "name": "Wood_Gumboab_Trunk_Full"
    },
    {
      "x": -14,
      "y": 8,
      "z": -17,
      "name": "Wood_Gumboab_Trunk_Full"
    },
    {
      "x": -14,
      "y": 9,
      "z": -17,
      "name": "Wood_Gumboab_Trunk_Full"
    },
    {
      "x": -14,
      "y": 10,
      "z": -17,
      "name": "Wood_Gumboab_Trunk_Full"
    },
    {
      "x": -14,
      "y": 6,
      "z": -16,
      "name": "Wood_Gumboab_Trunk_Full"
    },
    {
      "x": -14,
      "y": 7,
      "z": -16,
      "name": "Wood_Gumboab_Trunk_Full"
    },
    {
      "x": -14,
      "y": 9,
      "z": -16,
      "name": "Wood_Gumboab_Trunk_Full"
    },
    {
      "x": -14,
      "y": 33,
      "z": -16,
      "name": "Plant_Leaves_Beech_Max_Support",
      "support": 15
    },
    {
      "x": -14,
      "y": 34,
      "z": -16,
      "name": "Plant_Leaves_Beech_Max_Support",
      "support": 15
    },
    {
      "x": -14,
      "y": 35,
      "z": -16,
      "name": "Plant_Leaves_Beech_Max_Support",
      "support": 15
    },
    {
      "x": -14,
      "y": 32,
      "z": -15,
      "name": "Plant_Leaves_Beech_Max_Support",
      "support": 15
    },
    {
      "x": -14,
      "y": 33,
      "z": -15,
      "name": "Plant_Leaves_Beech_Max_Support"
    },
    {
      "x": -14,
      "y": 34,
      "z": -15,
      "name": "Plant_Leaves_Beech_Max_Support"
    },
    {
      "x": -14,
      "y": 35,
      "z": -15,
      "name": "Plant_Leaves_Beech_Max_Support"
    },
    {
      "x": -14,
      "y": 33,
      "z": -14,
      "name": "Plant_Leaves_Beech_Max_Support"
    },
    {
      "x": -14,
      "y": 34,
      "z": -14,
      "name": "Plant_Leaves_Beech_Max_Support"
    },
    {
      "x": -14,
      "y": 35,
      "z": -14,
      "name": "Plant_Leaves_Beech_Max_Support"
    },
    {
      "x": -14,
      "y": 36,
      "z": -14,
      "name": "Plant_Leaves_Beech_Max_Support"
    },
    {
      "x": -14,
      "y": 9,
      "z": -13,
      "name": "Wood_Gumboab_Trunk_Full"
    },
    {
      "x": -14,
      "y": 31,
      "z": -13,
      "name": "Plant_Leaves_Beech_Max_Support"
    },
    {
      "x": -14,
      "y": 32,
      "z": -13,
      "name": "Plant_Leaves_Beech_Max_Support"
    },
    {
      "x": -14,
      "y": 33,
      "z": -13,
      "name": "Plant_Leaves_Beech_Max_Support"
    },
    {
      "x": -14,
      "y": 34,
      "z": -13,
      "name": "Plant_Leaves_Beech_Max_Support"
    },
    {
      "x": -14,
      "y": 35,
      "z": -13,
      "name": "Plant_Leaves_Beech_Max_Support"
    },
    {
      "x": -14,
      "y": 36,
      "z": -13,
      "name": "Plant_Leaves_Beech_Max_Support"
    },
    {
      "x": -14,
      "y": 37,
      "z": -13,
      "name": "Plant_Leaves_Beech_Max_Support"
    },
    {
      "x": -14,
      "y": 9,
      "z": -12,
      "name": "Wood_Gumboab_Trunk_Full"
    },
    {
      "x": -14,
      "y": 10,
      "z": -12,
      "name": "Wood_Gumboab_Trunk_Full"
    },
    {
      "x": -14,
      "y": 31,
      "z": -12,
      "name": "Plant_Leaves_Beech_Max_Support"
    },
    {
      "x": -14,
      "y": 32,
      "z": -12,
      "name": "Plant_Leaves_Beech_Max_Support"
    },
    {
      "x": -14,
      "y": 33,
      "z": -12,
      "name": "Plant_Leaves_Beech_Max_Support"
    },
    {
      "x": -14,
      "y": 34,
      "z": -12,
      "name": "Plant_Leaves_Beech_Max_Support"
    },
    {
      "x": -14,
      "y": 35,
      "z": -12,
      "name": "Plant_Leaves_Beech_Max_Support"
    },
    {
      "x": -14,
      "y": 36,
      "z": -12,
      "name": "Plant_Leaves_Beech_Max_Support"
    },
    {
      "x": -14,
      "y": 37,
      "z": -12,
      "name": "Plant_Leaves_Beech_Max_Support"
    },
    {
      "x": -14,
      "y": 30,
      "z": -11,
      "name": "Plant_Leaves_Beech_Max_Support"
    },
    {
      "x": -14,
      "y": 31,
      "z": -11,
      "name": "Plant_Leaves_Beech_Max_Support"
    },
    {
      "x": -14,
      "y": 32,
      "z": -11,
      "name": "Plant_Leaves_Beech_Max_Support"
    },
    {
      "x": -14,
      "y": 34,
      "z": -11,
      "name": "Plant_Leaves_Beech_Max_Support"
    },
    {
      "x": -14,
      "y": 35,
      "z": -11,
      "name": "Plant_Leaves_Beech_Max_Support"
    },
    {
      "x": -14,
      "y": 36,
      "z": -11,
      "name": "Plant_Leaves_Beech_Max_Support"
    },
    {
      "x": -14,
      "y": 37,
      "z": -11,
      "name": "Plant_Leaves_Beech_Max_Support"
    },
    {
      "x": -14,
      "y": 11,
      "z": -10,
      "name": "Wood_Gumboab_Trunk_Full"
    },
    {
      "x": -14,
      "y": 12,
      "z": -10,
      "name": "Wood_Gumboab_Trunk_Full"
    },
    {
      "x": -14,
      "y": 32,
      "z": -10,
      "name": "Plant_Leaves_Beech_Max_Support"
    },
    {
      "x": -14,
      "y": 33,
      "z": -10,
      "name": "Plant_Leaves_Beech_Max_Support"
    },
    {
      "x": -14,
      "y": 34,
      "z": -10,
      "name": "Plant_Leaves_Beech_Max_Support"
    },
    {
      "x": -14,
      "y": 35,
      "z": -10,
      "name": "Plant_Leaves_Beech_Max_Support"
    },
    {
      "x": -14,
      "y": 36,
      "z": -10,
      "name": "Plant_Leaves_Beech_Max_Support"
    },
    {
      "x": -14,
      "y": 11,
      "z": -9,
      "name": "Wood_Gumboab_Trunk_Full"
    },
    {
      "x": -14,
      "y": 12,
      "z": -9,
      "name": "Wood_Gumboab_Trunk_Full"
    },
    {
      "x": -14,
      "y": 31,
      "z": -9,
      "name": "Wood_Gumboab_Trunk_Full"
    },
    {
      "x": -14,
      "y": 33,
      "z": -9,
      "name": "Plant_Leaves_Beech_Max_Support"
    },
    {
      "x": -14,
      "y": 34,
      "z": -9,
      "name": "Plant_Leaves_Beech_Max_Support"
    },
    {
      "x": -14,
      "y": 35,
      "z": -9,
      "name": "Plant_Leaves_Beech_Max_Support"
    },
    {
      "x": -14,
      "y": 36,
      "z": -9,
      "name": "Plant_Leaves_Beech_Max_Support"
    },
    {
      "x": -14,
      "y": 10,
      "z": -8,
      "name": "Wood_Gumboab_Trunk_Full"
    },
    {
      "x": -14,
      "y": 11,
      "z": -8,
      "name": "Wood_Gumboab_Trunk_Full"
    },
    {
      "x": -14,
      "y": 30,
      "z": -8,
      "name": "Wood_Gumboab_Roots"
    },
    {
      "x": -14,
      "y": 31,
      "z": -8,
      "name": "Wood_Gumboab_Trunk_Full"
    },
    {
      "x": -14,
      "y": 32,
      "z": -8,
      "name": "Plant_Leaves_Beech_Max_Support"
    },
    {
      "x": -14,
      "y": 34,
      "z": -8,
      "name": "Plant_Leaves_Beech_Max_Support"
    },
    {
      "x": -14,
      "y": 35,
      "z": -8,
      "name": "Plant_Leaves_Beech_Max_Support"
    },
    {
      "x": -14,
      "y": 36,
      "z": -8,
      "name": "Plant_Leaves_Beech_Max_Support"
    },
    {
      "x": -14,
      "y": 8,
      "z": -7,
      "name": "Wood_Gumboab_Trunk_Full"
    },
    {
      "x": -14,
      "y": 9,
      "z": -7,
      "name": "Wood_Gumboab_Trunk_Full"
    },
    {
      "x": -14,
      "y": 10,
      "z": -7,
      "name": "Wood_Gumboab_Trunk_Full"
    },
    {
      "x": -14,
      "y": 11,
      "z": -7,
      "name": "Wood_Gumboab_Trunk_Full"
    },
    {
      "x": -14,
      "y": 31,
      "z": -7,
      "name": "Wood_Gumboab_Trunk_Full"
    },
    {
      "x": -14,
      "y": 32,
      "z": -7,
      "name": "Plant_Leaves_Beech_Max_Support"
    },
    {
      "x": -14,
      "y": 33,
      "z": -7,
      "name": "Plant_Leaves_Beech_Max_Support"
    },
    {
      "x": -14,
      "y": 34,
      "z": -7,
      "name": "Plant_Leaves_Beech_Max_Support"
    },
    {
      "x": -14,
      "y": 35,
      "z": -7,
      "name": "Plant_Leaves_Beech_Max_Support"
    },
    {
      "x": -14,
      "y": 36,
      "z": -7,
      "name": "Plant_Leaves_Beech_Max_Support"
    },
    {
      "x": -14,
      "y": 8,
      "z": -6,
      "name": "Wood_Gumboab_Trunk_Full"
    },
    {
      "x": -14,
      "y": 9,
      "z": -6,
      "name": "Wood_Gumboab_Trunk_Full"
    },
    {
      "x": -14,
      "y": 30,
      "z": -6,
      "name": "Plant_Leaves_Beech_Max_Support"
    },
    {
      "x": -14,
      "y": 31,
      "z": -6,
      "name": "Wood_Gumboab_Trunk_Full"
    },
    {
      "x": -14,
      "y": 32,
      "z": -6,
      "name": "Plant_Leaves_Beech_Max_Support"
    },
    {
      "x": -14,
      "y": 33,
      "z": -6,
      "name": "Plant_Leaves_Beech_Max_Support"
    },
    {
      "x": -14,
      "y": 34,
      "z": -6,
      "name": "Plant_Leaves_Beech_Max_Support"
    },
    {
      "x": -14,
      "y": 35,
      "z": -6,
      "name": "Plant_Leaves_Beech_Max_Support"
    },
    {
      "x": -14,
      "y": 36,
      "z": -6,
      "name": "Plant_Leaves_Beech_Max_Support"
    },
    {
      "x": -14,
      "y": 32,
      "z": -5,
      "name": "Plant_Leaves_Beech_Max_Support"
    },
    {
      "x": -14,
      "y": 33,
      "z": -5,
      "name": "Plant_Leaves_Beech_Max_Support"
    },
    {
      "x": -14,
      "y": 34,
      "z": -5,
      "name": "Plant_Leaves_Beech_Max_Support"
    },
    {
      "x": -14,
      "y": 35,
      "z": -5,
      "name": "Plant_Leaves_Beech_Max_Support"
    },
    {
      "x": -14,
      "y": 36,
      "z": -5,
      "name": "Plant_Leaves_Beech_Max_Support"
    },
    {
      "x": -14,
      "y": 32,
      "z": -4,
      "name": "Plant_Leaves_Beech_Max_Support"
    },
    {
      "x": -14,
      "y": 33,
      "z": -4,
      "name": "Plant_Leaves_Beech_Max_Support"
    },
    {
      "x": -14,
      "y": 34,
      "z": -4,
      "name": "Plant_Leaves_Beech_Max_Support"
    },
    {
      "x": -14,
      "y": 35,
      "z": -4,
      "name": "Plant_Leaves_Beech_Max_Support"
    },
    {
      "x": -14,
      "y": 37,
      "z": -4,
      "name": "Plant_Leaves_Beech_Max_Support"
    },
    {
      "x": -14,
      "y": 38,
      "z": -4,
      "name": "Plant_Leaves_Beech_Max_Support"
    },
    {
      "x": -14,
      "y": 33,
      "z": -3,
      "name": "Plant_Leaves_Beech_Max_Support"
    },
    {
      "x": -14,
      "y": 34,
      "z": -3,
      "name": "Plant_Leaves_Beech_Max_Support"
    },
    {
      "x": -14,
      "y": 35,
      "z": -3,
      "name": "Plant_Leaves_Beech_Max_Support"
    },
    {
      "x": -14,
      "y": 36,
      "z": -3,
      "name": "Plant_Leaves_Beech_Max_Support"
    },
    {
      "x": -14,
      "y": 38,
      "z": -3,
      "name": "Plant_Leaves_Beech_Max_Support"
    },
    {
      "x": -14,
      "y": 34,
      "z": -2,
      "name": "Wood_Gumboab_Trunk_Full"
    },
    {
      "x": -14,
      "y": 35,
      "z": -2,
      "name": "Plant_Leaves_Beech_Max_Support"
    },
    {
      "x": -14,
      "y": 38,
      "z": -2,
      "name": "Plant_Leaves_Beech_Max_Support"
    },
    {
      "x": -14,
      "y": 39,
      "z": -2,
      "name": "Plant_Leaves_Beech_Max_Support"
    },
    {
      "x": -14,
      "y": 33,
      "z": -1,
      "name": "Plant_Leaves_Beech_Max_Support"
    },
    {
      "x": -14,
      "y": 34,
      "z": -1,
      "name": "Wood_Gumboab_Trunk_Full"
    },
    {
      "x": -14,
      "y": 35,
      "z": -1,
      "name": "Plant_Leaves_Beech_Max_Support"
    },
    {
      "x": -14,
      "y": 37,
      "z": -1,
      "name": "Plant_Leaves_Beech_Max_Support"
    },
    {
      "x": -14,
      "y": 38,
      "z": -1,
      "name": "Plant_Leaves_Beech_Max_Support"
    },
    {
      "x": -14,
      "y": 39,
      "z": -1,
      "name": "Plant_Leaves_Beech_Max_Support"
    },
    {
      "x": -14,
      "y": 34,
      "z": 0,
      "name": "Plant_Leaves_Beech_Max_Support"
    },
    {
      "x": -14,
      "y": 35,
      "z": 0,
      "name": "Plant_Leaves_Beech_Max_Support"
    },
    {
      "x": -14,
      "y": 36,
      "z": 0,
      "name": "Plant_Leaves_Beech_Max_Support"
    },
    {
      "x": -14,
      "y": 37,
      "z": 0,
      "name": "Plant_Leaves_Beech_Max_Support"
    },
    {
      "x": -14,
      "y": 38,
      "z": 0,
      "name": "Plant_Leaves_Beech_Max_Support"
    },
    {
      "x": -14,
      "y": 36,
      "z": 1,
      "name": "Plant_Leaves_Beech_Max_Support"
    },
    {
      "x": -13,
      "y": 10,
      "z": -18,
      "name": "Wood_Gumboab_Trunk_Full"
    },
    {
      "x": -13,
      "y": 8,
      "z": -17,
      "name": "Wood_Gumboab_Trunk_Full"
    },
    {
      "x": -13,
      "y": 9,
      "z": -17,
      "name": "Wood_Gumboab_Trunk_Full"
    },
    {
      "x": -13,
      "y": 10,
      "z": -17,
      "name": "Wood_Gumboab_Trunk_Full"
    },
    {
      "x": -13,
      "y": 11,
      "z": -17,
      "name": "Wood_Gumboab_Trunk_Full"
    },
    {
      "x": -13,
      "y": 33,
      "z": -17,
      "name": "Plant_Leaves_Beech_Max_Support",
      "support": 15
    },
    {
      "x": -13,
      "y": 34,
      "z": -17,
      "name": "Plant_Leaves_Beech_Max_Support",
      "support": 15
    },
    {
      "x": -13,
      "y": 9,
      "z": -16,
      "name": "Wood_Gumboab_Trunk_Full"
    },
    {
      "x": -13,
      "y": 10,
      "z": -16,
      "name": "Wood_Gumboab_Trunk_Full"
    },
    {
      "x": -13,
      "y": 11,
      "z": -16,
      "name": "Wood_Gumboab_Trunk_Full"
    },
    {
      "x": -13,
      "y": 33,
      "z": -16,
      "name": "Plant_Leaves_Beech_Max_Support",
      "support": 15
    },
    {
      "x": -13,
      "y": 34,
      "z": -16,
      "name": "Plant_Leaves_Beech_Max_Support",
      "support": 15
    },
    {
      "x": -13,
      "y": 35,
      "z": -16,
      "name": "Plant_Leaves_Beech_Max_Support",
      "support": 15
    },
    {
      "x": -13,
      "y": 33,
      "z": -15,
      "name": "Plant_Leaves_Beech_Max_Support",
      "support": 15
    },
    {
      "x": -13,
      "y": 34,
      "z": -15,
      "name": "Wood_Gumboab_Trunk_Full"
    },
    {
      "x": -13,
      "y": 35,
      "z": -15,
      "name": "Plant_Leaves_Beech_Max_Support"
    },
    {
      "x": -13,
      "y": 36,
      "z": -15,
      "name": "Plant_Leaves_Beech_Max_Support",
      "support": 15
    },
    {
      "x": -13,
      "y": 10,
      "z": -14,
      "name": "Wood_Gumboab_Trunk_Full"
    },
    {
      "x": -13,
      "y": 32,
      "z": -14,
      "name": "Wood_Gumboab_Trunk_Full"
    },
    {
      "x": -13,
      "y": 33,
      "z": -14,
      "name": "Wood_Gumboab_Trunk_Full"
    },
    {
      "x": -13,
      "y": 34,
      "z": -14,
      "name": "Wood_Gumboab_Trunk_Full"
    },
    {
      "x": -13,
      "y": 35,
      "z": -14,
      "name": "Plant_Leaves_Beech_Max_Support"
    },
    {
      "x": -13,
      "y": 36,
      "z": -14,
      "name": "Plant_Leaves_Beech_Max_Support"
    },
    {
      "x": -13,
      "y": 9,
      "z": -13,
      "name": "Wood_Gumboab_Trunk_Full"
    },
    {
      "x": -13,
      "y": 10,
      "z": -13,
      "name": "Wood_Gumboab_Trunk_Full"
    },
    {
      "x": -13,
      "y": 31,
      "z": -13,
      "name": "Plant_Leaves_Beech_Max_Support"
    },
    {
      "x": -13,
      "y": 32,
      "z": -13,
      "name": "Wood_Gumboab_Trunk_Full"
    },
    {
      "x": -13,
      "y": 33,
      "z": -13,
      "name": "Wood_Gumboab_Trunk_Full"
    },
    {
      "x": -13,
      "y": 34,
      "z": -13,
      "name": "Plant_Leaves_Beech_Max_Support"
    },
    {
      "x": -13,
      "y": 35,
      "z": -13,
      "name": "Plant_Leaves_Beech_Max_Support"
    },
    {
      "x": -13,
      "y": 36,
      "z": -13,
      "name": "Plant_Leaves_Beech_Max_Support"
    },
    {
      "x": -13,
      "y": 37,
      "z": -13,
      "name": "Plant_Leaves_Beech_Max_Support"
    },
    {
      "x": -13,
      "y": 9,
      "z": -12,
      "name": "Wood_Gumboab_Trunk_Full"
    },
    {
      "x": -13,
      "y": 10,
      "z": -12,
      "name": "Wood_Gumboab_Trunk_Full"
    },
    {
      "x": -13,
      "y": 31,
      "z": -12,
      "name": "Plant_Leaves_Beech_Max_Support"
    },
    {
      "x": -13,
      "y": 32,
      "z": -12,
      "name": "Plant_Leaves_Beech_Max_Support"
    },
    {
      "x": -13,
      "y": 33,
      "z": -12,
      "name": "Plant_Leaves_Beech_Max_Support"
    },
    {
      "x": -13,
      "y": 34,
      "z": -12,
      "name": "Plant_Leaves_Beech_Max_Support"
    },
    {
      "x": -13,
      "y": 35,
      "z": -12,
      "name": "Plant_Leaves_Beech_Max_Support"
    },
    {
      "x": -13,
      "y": 36,
      "z": -12,
      "name": "Plant_Leaves_Beech_Max_Support"
    },
    {
      "x": -13,
      "y": 37,
      "z": -12,
      "name": "Plant_Leaves_Beech_Max_Support"
    },
    {
      "x": -13,
      "y": 11,
      "z": -11,
      "name": "Wood_Gumboab_Trunk_Full"
    },
    {
      "x": -13,
      "y": 12,
      "z": -11,
      "name": "Wood_Gumboab_Trunk_Full"
    },
    {
      "x": -13,
      "y": 32,
      "z": -11,
      "name": "Plant_Leaves_Beech_Max_Support"
    },
    {
      "x": -13,
      "y": 33,
      "z": -11,
      "name": "Plant_Leaves_Beech_Max_Support"
    },
    {
      "x": -13,
      "y": 34,
      "z": -11,
      "name": "Plant_Leaves_Beech_Max_Support"
    },
    {
      "x": -13,
      "y": 35,
      "z": -11,
      "name": "Plant_Leaves_Beech_Max_Support"
    },
    {
      "x": -13,
      "y": 36,
      "z": -11,
      "name": "Plant_Leaves_Beech_Max_Support"
    },
    {
      "x": -13,
      "y": 37,
      "z": -11,
      "name": "Plant_Leaves_Beech_Max_Support"
    },
    {
      "x": -13,
      "y": 11,
      "z": -10,
      "name": "Wood_Gumboab_Trunk_Full"
    },
    {
      "x": -13,
      "y": 12,
      "z": -10,
      "name": "Wood_Gumboab_Trunk_Full"
    },
    {
      "x": -13,
      "y": 30,
      "z": -10,
      "name": "Wood_Gumboab_Trunk_Full"
    },
    {
      "x": -13,
      "y": 31,
      "z": -10,
      "name": "Wood_Gumboab_Trunk_Full"
    },
    {
      "x": -13,
      "y": 32,
      "z": -10,
      "name": "Plant_Leaves_Beech_Max_Support"
    },
    {
      "x": -13,
      "y": 33,
      "z": -10,
      "name": "Plant_Leaves_Beech_Max_Support"
    },
    {
      "x": -13,
      "y": 34,
      "z": -10,
      "name": "Plant_Leaves_Beech_Max_Support"
    },
    {
      "x": -13,
      "y": 35,
      "z": -10,
      "name": "Plant_Leaves_Beech_Max_Support"
    },
    {
      "x": -13,
      "y": 36,
      "z": -10,
      "name": "Plant_Leaves_Beech_Max_Support"
    },
    {
      "x": -13,
      "y": 10,
      "z": -9,
      "name": "Wood_Gumboab_Trunk_Full"
    },
    {
      "x": -13,
      "y": 11,
      "z": -9,
      "name": "Wood_Gumboab_Trunk_Full"
    },
    {
      "x": -13,
      "y": 12,
      "z": -9,
      "name": "Wood_Gumboab_Trunk_Full"
    },
    {
      "x": -13,
      "y": 30,
      "z": -9,
      "name": "Wood_Gumboab_Trunk_Full"
    },
    {
      "x": -13,
      "y": 31,
      "z": -9,
      "name": "Wood_Gumboab_Trunk_Full"
    },
    {
      "x": -13,
      "y": 32,
      "z": -9,
      "name": "Plant_Leaves_Beech_Max_Support"
    },
    {
      "x": -13,
      "y": 33,
      "z": -9,
      "name": "Plant_Leaves_Beech_Max_Support"
    },
    {
      "x": -13,
      "y": 34,
      "z": -9,
      "name": "Plant_Leaves_Beech_Max_Support"
    },
    {
      "x": -13,
      "y": 35,
      "z": -9,
      "name": "Plant_Leaves_Beech_Max_Support"
    },
    {
      "x": -13,
      "y": 11,
      "z": -8,
      "name": "Wood_Gumboab_Trunk_Full"
    },
    {
      "x": -13,
      "y": 31,
      "z": -8,
      "name": "Wood_Gumboab_Trunk_Full"
    },
    {
      "x": -13,
      "y": 32,
      "z": -8,
      "name": "Plant_Leaves_Beech_Max_Support"
    },
    {
      "x": -13,
      "y": 35,
      "z": -8,
      "name": "Plant_Leaves_Beech_Max_Support"
    },
    {
      "x": -13,
      "y": 8,
      "z": -7,
      "name": "Wood_Gumboab_Trunk_Full"
    },
    {
      "x": -13,
      "y": 9,
      "z": -7,
      "name": "Wood_Gumboab_Trunk_Full"
    },
    {
      "x": -13,
      "y": 10,
      "z": -7,
      "name": "Wood_Gumboab_Trunk_Full"
    },
    {
      "x": -13,
      "y": 31,
      "z": -7,
      "name": "Wood_Gumboab_Trunk_Full"
    },
    {
      "x": -13,
      "y": 32,
      "z": -7,
      "name": "Plant_Leaves_Beech_Max_Support"
    },
    {
      "x": -13,
      "y": 33,
      "z": -7,
      "name": "Plant_Leaves_Beech_Max_Support"
    },
    {
      "x": -13,
      "y": 34,
      "z": -7,
      "name": "Plant_Leaves_Beech_Max_Support"
    },
    {
      "x": -13,
      "y": 7,
      "z": -6,
      "name": "Wood_Gumboab_Trunk_Full"
    },
    {
      "x": -13,
      "y": 8,
      "z": -6,
      "name": "Wood_Gumboab_Trunk_Full"
    },
    {
      "x": -13,
      "y": 9,
      "z": -6,
      "name": "Wood_Gumboab_Trunk_Full"
    },
    {
      "x": -13,
      "y": 30,
      "z": -6,
      "name": "Plant_Leaves_Beech_Max_Support"
    },
    {
      "x": -13,
      "y": 33,
      "z": -6,
      "name": "Plant_Leaves_Beech_Max_Support"
    },
    {
      "x": -13,
      "y": 34,
      "z": -6,
      "name": "Plant_Leaves_Beech_Max_Support"
    },
    {
      "x": -13,
      "y": 35,
      "z": -6,
      "name": "Plant_Leaves_Beech_Max_Support"
    },
    {
      "x": -13,
      "y": 36,
      "z": -6,
      "name": "Plant_Leaves_Beech_Max_Support"
    },
    {
      "x": -13,
      "y": 32,
      "z": -5,
      "name": "Plant_Leaves_Beech_Max_Support"
    },
    {
      "x": -13,
      "y": 33,
      "z": -5,
      "name": "Plant_Leaves_Beech_Max_Support"
    },
    {
      "x": -13,
      "y": 34,
      "z": -5,
      "name": "Plant_Leaves_Beech_Max_Support"
    },
    {
      "x": -13,
      "y": 35,
      "z": -5,
      "name": "Plant_Leaves_Beech_Max_Support"
    },
    {
      "x": -13,
      "y": 36,
      "z": -5,
      "name": "Plant_Leaves_Beech_Max_Support"
    },
    {
      "x": -13,
      "y": 37,
      "z": -5,
      "name": "Plant_Leaves_Beech_Max_Support"
    },
    {
      "x": -13,
      "y": 34,
      "z": -4,
      "name": "Plant_Leaves_Beech_Max_Support"
    },
    {
      "x": -13,
      "y": 35,
      "z": -4,
      "name": "Plant_Leaves_Beech_Max_Support"
    },
    {
      "x": -13,
      "y": 36,
      "z": -4,
      "name": "Plant_Leaves_Beech_Max_Support"
    },
    {
      "x": -13,
      "y": 38,
      "z": -4,
      "name": "Plant_Leaves_Beech_Max_Support"
    },
    {
      "x": -13,
      "y": 34,
      "z": -3,
      "name": "Plant_Leaves_Beech_Max_Support"
    },
    {
      "x": -13,
      "y": 35,
      "z": -3,
      "name": "Plant_Leaves_Beech_Max_Support"
    },
    {
      "x": -13,
      "y": 36,
      "z": -3,
      "name": "Plant_Leaves_Beech_Max_Support"
    },
    {
      "x": -13,
      "y": 37,
      "z": -3,
      "name": "Plant_Leaves_Beech_Max_Support"
    },
    {
      "x": -13,
      "y": 39,
      "z": -3,
      "name": "Plant_Leaves_Beech_Max_Support"
    },
    {
      "x": -13,
      "y": 33,
      "z": -2,
      "name": "Wood_Gumboab_Trunk_Full"
    },
    {
      "x": -13,
      "y": 34,
      "z": -2,
      "name": "Wood_Gumboab_Trunk_Full"
    },
    {
      "x": -13,
      "y": 35,
      "z": -2,
      "name": "Plant_Leaves_Beech_Max_Support"
    },
    {
      "x": -13,
      "y": 36,
      "z": -2,
      "name": "Plant_Leaves_Beech_Max_Support"
    },
    {
      "x": -13,
      "y": 37,
      "z": -2,
      "name": "Plant_Leaves_Beech_Max_Support"
    },
    {
      "x": -13,
      "y": 38,
      "z": -2,
      "name": "Plant_Leaves_Beech_Max_Support"
    },
    {
      "x": -13,
      "y": 33,
      "z": -1,
      "name": "Plant_Leaves_Beech_Max_Support"
    },
    {
      "x": -13,
      "y": 34,
      "z": -1,
      "name": "Wood_Gumboab_Trunk_Full"
    },
    {
      "x": -13,
      "y": 35,
      "z": -1,
      "name": "Plant_Leaves_Beech_Max_Support"
    },
    {
      "x": -13,
      "y": 37,
      "z": -1,
      "name": "Plant_Leaves_Beech_Max_Support"
    },
    {
      "x": -13,
      "y": 39,
      "z": -1,
      "name": "Plant_Leaves_Beech_Max_Support"
    },
    {
      "x": -13,
      "y": 34,
      "z": 0,
      "name": "Plant_Leaves_Beech_Max_Support",
      "support": 15
    },
    {
      "x": -13,
      "y": 35,
      "z": 0,
      "name": "Plant_Leaves_Beech_Max_Support"
    },
    {
      "x": -13,
      "y": 37,
      "z": 0,
      "name": "Plant_Leaves_Beech_Max_Support"
    },
    {
      "x": -13,
      "y": 34,
      "z": 1,
      "name": "Plant_Leaves_Beech_Max_Support",
      "support": 15
    },
    {
      "x": -13,
      "y": 35,
      "z": 1,
      "name": "Plant_Leaves_Beech_Max_Support"
    },
    {
      "x": -13,
      "y": 36,
      "z": 1,
      "name": "Plant_Leaves_Beech_Max_Support"
    },
    {
      "x": -13,
      "y": 37,
      "z": 1,
      "name": "Plant_Leaves_Beech_Max_Support"
    },
    {
      "x": -12,
      "y": 10,
      "z": -17,
      "name": "Wood_Gumboab_Trunk_Full"
    },
    {
      "x": -12,
      "y": 11,
      "z": -17,
      "name": "Wood_Gumboab_Trunk_Full"
    },
    {
      "x": -12,
      "y": 34,
      "z": -17,
      "name": "Plant_Leaves_Beech_Max_Support",
      "support": 15
    },
    {
      "x": -12,
      "y": 10,
      "z": -16,
      "name": "Wood_Gumboab_Trunk_Full"
    },
    {
      "x": -12,
      "y": 11,
      "z": -16,
      "name": "Wood_Gumboab_Trunk_Full"
    },
    {
      "x": -12,
      "y": 33,
      "z": -16,
      "name": "Plant_Leaves_Beech_Max_Support",
      "support": 15
    },
    {
      "x": -12,
      "y": 34,
      "z": -16,
      "name": "Plant_Leaves_Beech_Max_Support"
    },
    {
      "x": -12,
      "y": 35,
      "z": -16,
      "name": "Plant_Leaves_Beech_Max_Support"
    },
    {
      "x": -12,
      "y": 36,
      "z": -16,
      "name": "Plant_Leaves_Beech_Max_Support"
    },
    {
      "x": -12,
      "y": 10,
      "z": -15,
      "name": "Wood_Gumboab_Trunk_Full"
    },
    {
      "x": -12,
      "y": 11,
      "z": -15,
      "name": "Wood_Gumboab_Trunk_Full"
    },
    {
      "x": -12,
      "y": 33,
      "z": -15,
      "name": "Plant_Leaves_Beech_Max_Support"
    },
    {
      "x": -12,
      "y": 34,
      "z": -15,
      "name": "Plant_Leaves_Beech_Max_Support"
    },
    {
      "x": -12,
      "y": 37,
      "z": -15,
      "name": "Plant_Leaves_Beech_Max_Support"
    },
    {
      "x": -12,
      "y": 10,
      "z": -14,
      "name": "Wood_Gumboab_Trunk_Full"
    },
    {
      "x": -12,
      "y": 11,
      "z": -14,
      "name": "Wood_Gumboab_Trunk_Full"
    },
    {
      "x": -12,
      "y": 14,
      "z": -14,
      "name": "Plant_Vine_Jungle",
      "support": 15,
      "rotation": 2
    },
    {
      "x": -12,
      "y": 15,
      "z": -14,
      "name": "Plant_Vine_Jungle",
      "support": 15,
      "rotation": 2
    },
    {
      "x": -12,
      "y": 16,
      "z": -14,
      "name": "Plant_Vine_Jungle",
      "support": 15,
      "rotation": 2
    },
    {
      "x": -12,
      "y": 17,
      "z": -14,
      "name": "Plant_Vine_Jungle",
      "support": 15,
      "rotation": 2
    },
    {
      "x": -12,
      "y": 18,
      "z": -14,
      "name": "Plant_Vine_Jungle",
      "support": 15,
      "rotation": 2
    },
    {
      "x": -12,
      "y": 19,
      "z": -14,
      "name": "Plant_Vine_Jungle",
      "support": 15,
      "rotation": 2
    },
    {
      "x": -12,
      "y": 20,
      "z": -14,
      "name": "Plant_Vine_Jungle",
      "support": 15,
      "rotation": 2
    },
    {
      "x": -12,
      "y": 21,
      "z": -14,
      "name": "Plant_Vine_Jungle",
      "support": 15,
      "rotation": 2
    },
    {
      "x": -12,
      "y": 22,
      "z": -14,
      "name": "Plant_Vine_Jungle",
      "support": 15,
      "rotation": 2
    },
    {
      "x": -12,
      "y": 23,
      "z": -14,
      "name": "Plant_Vine_Jungle",
      "support": 15,
      "rotation": 2
    },
    {
      "x": -12,
      "y": 24,
      "z": -14,
      "name": "Plant_Vine_Jungle",
      "support": 15,
      "rotation": 2
    },
    {
      "x": -12,
      "y": 25,
      "z": -14,
      "name": "Plant_Vine_Jungle",
      "support": 15,
      "rotation": 2
    },
    {
      "x": -12,
      "y": 26,
      "z": -14,
      "name": "Plant_Vine_Jungle",
      "support": 15,
      "rotation": 2
    },
    {
      "x": -12,
      "y": 27,
      "z": -14,
      "name": "Plant_Vine_Jungle",
      "support": 15,
      "rotation": 2
    },
    {
      "x": -12,
      "y": 28,
      "z": -14,
      "name": "Plant_Vine_Jungle",
      "support": 15,
      "rotation": 2
    },
    {
      "x": -12,
      "y": 29,
      "z": -14,
      "name": "Plant_Vine_Jungle",
      "support": 15,
      "rotation": 2
    },
    {
      "x": -12,
      "y": 30,
      "z": -14,
      "name": "Plant_Vine_Jungle",
      "support": 15,
      "rotation": 2
    },
    {
      "x": -12,
      "y": 31,
      "z": -14,
      "name": "Plant_Vine_Jungle",
      "support": 15,
      "rotation": 2
    },
    {
      "x": -12,
      "y": 32,
      "z": -14,
      "name": "Wood_Gumboab_Trunk_Full"
    },
    {
      "x": -12,
      "y": 33,
      "z": -14,
      "name": "Wood_Gumboab_Trunk_Full"
    },
    {
      "x": -12,
      "y": 34,
      "z": -14,
      "name": "Wood_Gumboab_Trunk_Full"
    },
    {
      "x": -12,
      "y": 35,
      "z": -14,
      "name": "Plant_Leaves_Beech_Max_Support"
    },
    {
      "x": -12,
      "y": 36,
      "z": -14,
      "name": "Plant_Leaves_Beech_Max_Support"
    },
    {
      "x": -12,
      "y": 37,
      "z": -14,
      "name": "Plant_Leaves_Beech_Max_Support"
    },
    {
      "x": -12,
      "y": 38,
      "z": -14,
      "name": "Plant_Leaves_Beech_Max_Support"
    },
    {
      "x": -12,
      "y": 10,
      "z": -13,
      "name": "Wood_Gumboab_Trunk_Full"
    },
    {
      "x": -12,
      "y": 11,
      "z": -13,
      "name": "Wood_Gumboab_Trunk_Full"
    },
    {
      "x": -12,
      "y": 31,
      "z": -13,
      "name": "Wood_Gumboab_Trunk_Full"
    },
    {
      "x": -12,
      "y": 32,
      "z": -13,
      "name": "Wood_Gumboab_Trunk_Full"
    },
    {
      "x": -12,
      "y": 33,
      "z": -13,
      "name": "Wood_Gumboab_Trunk_Full"
    },
    {
      "x": -12,
      "y": 34,
      "z": -13,
      "name": "Plant_Leaves_Beech_Max_Support"
    },
    {
      "x": -12,
      "y": 35,
      "z": -13,
      "name": "Plant_Leaves_Beech_Max_Support"
    },
    {
      "x": -12,
      "y": 38,
      "z": -13,
      "name": "Plant_Leaves_Beech_Max_Support"
    },
    {
      "x": -12,
      "y": 31,
      "z": -12,
      "name": "Wood_Gumboab_Trunk_Full"
    },
    {
      "x": -12,
      "y": 32,
      "z": -12,
      "name": "Wood_Gumboab_Trunk_Full"
    },
    {
      "x": -12,
      "y": 33,
      "z": -12,
      "name": "Plant_Leaves_Beech_Max_Support"
    },
    {
      "x": -12,
      "y": 34,
      "z": -12,
      "name": "Plant_Leaves_Beech_Max_Support"
    },
    {
      "x": -12,
      "y": 35,
      "z": -12,
      "name": "Plant_Leaves_Beech_Max_Support"
    },
    {
      "x": -12,
      "y": 36,
      "z": -12,
      "name": "Plant_Leaves_Beech_Max_Support"
    },
    {
      "x": -12,
      "y": 37,
      "z": -12,
      "name": "Plant_Leaves_Beech_Max_Support"
    },
    {
      "x": -12,
      "y": 38,
      "z": -12,
      "name": "Plant_Leaves_Beech_Max_Support"
    },
    {
      "x": -12,
      "y": 11,
      "z": -11,
      "name": "Wood_Gumboab_Trunk_Full"
    },
    {
      "x": -12,
      "y": 12,
      "z": -11,
      "name": "Wood_Gumboab_Trunk_Full"
    },
    {
      "x": -12,
      "y": 13,
      "z": -11,
      "name": "Wood_Gumboab_Trunk_Full"
    },
    {
      "x": -12,
      "y": 32,
      "z": -11,
      "name": "Plant_Leaves_Beech_Max_Support"
    },
    {
      "x": -12,
      "y": 33,
      "z": -11,
      "name": "Plant_Leaves_Beech_Max_Support"
    },
    {
      "x": -12,
      "y": 34,
      "z": -11,
      "name": "Plant_Leaves_Beech_Max_Support"
    },
    {
      "x": -12,
      "y": 35,
      "z": -11,
      "name": "Plant_Leaves_Beech_Max_Support"
    },
    {
      "x": -12,
      "y": 36,
      "z": -11,
      "name": "Plant_Leaves_Beech_Max_Support"
    },
    {
      "x": -12,
      "y": 38,
      "z": -11,
      "name": "Plant_Leaves_Beech_Max_Support"
    },
    {
      "x": -12,
      "y": 11,
      "z": -10,
      "name": "Wood_Gumboab_Trunk_Full"
    },
    {
      "x": -12,
      "y": 12,
      "z": -10,
      "name": "Wood_Gumboab_Trunk_Full"
    },
    {
      "x": -12,
      "y": 13,
      "z": -10,
      "name": "Wood_Gumboab_Trunk_Full"
    },
    {
      "x": -12,
      "y": 30,
      "z": -10,
      "name": "Wood_Gumboab_Trunk_Full"
    },
    {
      "x": -12,
      "y": 31,
      "z": -10,
      "name": "Wood_Gumboab_Trunk_Full"
    },
    {
      "x": -12,
      "y": 33,
      "z": -10,
      "name": "Plant_Leaves_Beech_Max_Support"
    },
    {
      "x": -12,
      "y": 34,
      "z": -10,
      "name": "Plant_Leaves_Beech_Max_Support"
    },
    {
      "x": -12,
      "y": 35,
      "z": -10,
      "name": "Plant_Leaves_Beech_Max_Support"
    },
    {
      "x": -12,
      "y": 36,
      "z": -10,
      "name": "Plant_Leaves_Beech_Max_Support"
    },
    {
      "x": -12,
      "y": 37,
      "z": -10,
      "name": "Plant_Leaves_Beech_Max_Support"
    },
    {
      "x": -12,
      "y": 11,
      "z": -9,
      "name": "Wood_Gumboab_Trunk_Full"
    },
    {
      "x": -12,
      "y": 12,
      "z": -9,
      "name": "Wood_Gumboab_Trunk_Full"
    },
    {
      "x": -12,
      "y": 30,
      "z": -9,
      "name": "Wood_Gumboab_Trunk_Full"
    },
    {
      "x": -12,
      "y": 31,
      "z": -9,
      "name": "Wood_Gumboab_Trunk_Full"
    },
    {
      "x": -12,
      "y": 32,
      "z": -9,
      "name": "Plant_Leaves_Beech_Max_Support"
    },
    {
      "x": -12,
      "y": 33,
      "z": -9,
      "name": "Plant_Leaves_Beech_Max_Support"
    },
    {
      "x": -12,
      "y": 34,
      "z": -9,
      "name": "Plant_Leaves_Beech_Max_Support"
    },
    {
      "x": -12,
      "y": 35,
      "z": -9,
      "name": "Plant_Leaves_Beech_Max_Support"
    },
    {
      "x": -12,
      "y": 36,
      "z": -9,
      "name": "Plant_Leaves_Beech_Max_Support"
    },
    {
      "x": -12,
      "y": 31,
      "z": -8,
      "name": "Plant_Leaves_Beech_Max_Support"
    },
    {
      "x": -12,
      "y": 32,
      "z": -8,
      "name": "Plant_Leaves_Beech_Max_Support"
    },
    {
      "x": -12,
      "y": 33,
      "z": -8,
      "name": "Plant_Leaves_Beech_Max_Support"
    },
    {
      "x": -12,
      "y": 34,
      "z": -8,
      "name": "Plant_Leaves_Beech_Max_Support"
    },
    {
      "x": -12,
      "y": 35,
      "z": -8,
      "name": "Plant_Leaves_Beech_Max_Support"
    },
    {
      "x": -12,
      "y": 7,
      "z": -7,
      "name": "Wood_Gumboab_Trunk_Full"
    },
    {
      "x": -12,
      "y": 8,
      "z": -7,
      "name": "Wood_Gumboab_Trunk_Full"
    },
    {
      "x": -12,
      "y": 9,
      "z": -7,
      "name": "Wood_Gumboab_Trunk_Full"
    },
    {
      "x": -12,
      "y": 10,
      "z": -7,
      "name": "Wood_Gumboab_Trunk_Full"
    },
    {
      "x": -12,
      "y": 31,
      "z": -7,
      "name": "Plant_Leaves_Beech_Max_Support"
    },
    {
      "x": -12,
      "y": 32,
      "z": -7,
      "name": "Plant_Leaves_Beech_Max_Support"
    },
    {
      "x": -12,
      "y": 33,
      "z": -7,
      "name": "Plant_Leaves_Beech_Max_Support"
    },
    {
      "x": -12,
      "y": 34,
      "z": -7,
      "name": "Plant_Leaves_Beech_Max_Support"
    },
    {
      "x": -12,
      "y": 35,
      "z": -7,
      "name": "Plant_Leaves_Beech_Max_Support"
    },
    {
      "x": -12,
      "y": 36,
      "z": -7,
      "name": "Plant_Leaves_Beech_Max_Support"
    },
    {
      "x": -12,
      "y": 8,
      "z": -6,
      "name": "Wood_Gumboab_Trunk_Full"
    },
    {
      "x": -12,
      "y": 9,
      "z": -6,
      "name": "Wood_Gumboab_Trunk_Full"
    },
    {
      "x": -12,
      "y": 10,
      "z": -6,
      "name": "Wood_Gumboab_Trunk_Full"
    },
    {
      "x": -12,
      "y": 31,
      "z": -6,
      "name": "Plant_Leaves_Beech_Max_Support"
    },
    {
      "x": -12,
      "y": 35,
      "z": -6,
      "name": "Plant_Leaves_Beech_Max_Support"
    },
    {
      "x": -12,
      "y": 36,
      "z": -6,
      "name": "Plant_Leaves_Beech_Max_Support"
    },
    {
      "x": -12,
      "y": 33,
      "z": -5,
      "name": "Plant_Leaves_Beech_Max_Support"
    },
    {
      "x": -12,
      "y": 34,
      "z": -5,
      "name": "Plant_Leaves_Beech_Max_Support"
    },
    {
      "x": -12,
      "y": 35,
      "z": -5,
      "name": "Plant_Leaves_Beech_Max_Support"
    },
    {
      "x": -12,
      "y": 36,
      "z": -5,
      "name": "Plant_Leaves_Beech_Max_Support"
    },
    {
      "x": -12,
      "y": 37,
      "z": -5,
      "name": "Plant_Leaves_Beech_Max_Support"
    },
    {
      "x": -12,
      "y": 33,
      "z": -4,
      "name": "Plant_Leaves_Beech_Max_Support"
    },
    {
      "x": -12,
      "y": 34,
      "z": -4,
      "name": "Plant_Leaves_Beech_Max_Support"
    },
    {
      "x": -12,
      "y": 36,
      "z": -4,
      "name": "Plant_Leaves_Beech_Max_Support"
    },
    {
      "x": -12,
      "y": 37,
      "z": -4,
      "name": "Plant_Leaves_Beech_Max_Support"
    },
    {
      "x": -12,
      "y": 38,
      "z": -4,
      "name": "Plant_Leaves_Beech_Max_Support"
    },
    {
      "x": -12,
      "y": 32,
      "z": -3,
      "name": "Plant_Leaves_Beech_Max_Support"
    },
    {
      "x": -12,
      "y": 33,
      "z": -3,
      "name": "Wood_Gumboab_Trunk_Full"
    },
    {
      "x": -12,
      "y": 34,
      "z": -3,
      "name": "Plant_Leaves_Beech_Max_Support"
    },
    {
      "x": -12,
      "y": 35,
      "z": -3,
      "name": "Plant_Leaves_Beech_Max_Support"
    },
    {
      "x": -12,
      "y": 36,
      "z": -3,
      "name": "Plant_Leaves_Beech_Max_Support"
    },
    {
      "x": -12,
      "y": 37,
      "z": -3,
      "name": "Plant_Leaves_Beech_Max_Support"
    },
    {
      "x": -12,
      "y": 38,
      "z": -3,
      "name": "Plant_Leaves_Beech_Max_Support"
    },
    {
      "x": -12,
      "y": 39,
      "z": -3,
      "name": "Plant_Leaves_Beech_Max_Support"
    },
    {
      "x": -12,
      "y": 32,
      "z": -2,
      "name": "Wood_Gumboab_Trunk_Full"
    },
    {
      "x": -12,
      "y": 33,
      "z": -2,
      "name": "Wood_Gumboab_Trunk_Full"
    },
    {
      "x": -12,
      "y": 34,
      "z": -2,
      "name": "Wood_Gumboab_Trunk_Full"
    },
    {
      "x": -12,
      "y": 35,
      "z": -2,
      "name": "Plant_Leaves_Beech_Max_Support"
    },
    {
      "x": -12,
      "y": 36,
      "z": -2,
      "name": "Plant_Leaves_Beech_Max_Support"
    },
    {
      "x": -12,
      "y": 37,
      "z": -2,
      "name": "Plant_Leaves_Beech_Max_Support"
    },
    {
      "x": -12,
      "y": 38,
      "z": -2,
      "name": "Plant_Leaves_Beech_Max_Support"
    },
    {
      "x": -12,
      "y": 39,
      "z": -2,
      "name": "Plant_Leaves_Beech_Max_Support"
    },
    {
      "x": -12,
      "y": 33,
      "z": -1,
      "name": "Plant_Leaves_Beech_Max_Support"
    },
    {
      "x": -12,
      "y": 34,
      "z": -1,
      "name": "Plant_Leaves_Beech_Max_Support"
    },
    {
      "x": -12,
      "y": 35,
      "z": -1,
      "name": "Plant_Leaves_Beech_Max_Support"
    },
    {
      "x": -12,
      "y": 36,
      "z": -1,
      "name": "Plant_Leaves_Beech_Max_Support"
    },
    {
      "x": -12,
      "y": 33,
      "z": 0,
      "name": "Plant_Leaves_Beech_Max_Support",
      "support": 15
    },
    {
      "x": -12,
      "y": 34,
      "z": 0,
      "name": "Plant_Leaves_Beech_Max_Support"
    },
    {
      "x": -12,
      "y": 35,
      "z": 0,
      "name": "Plant_Leaves_Beech_Max_Support"
    },
    {
      "x": -12,
      "y": 36,
      "z": 0,
      "name": "Plant_Leaves_Beech_Max_Support"
    },
    {
      "x": -12,
      "y": 37,
      "z": 0,
      "name": "Plant_Leaves_Beech_Max_Support"
    },
    {
      "x": -12,
      "y": 34,
      "z": 1,
      "name": "Plant_Leaves_Beech_Max_Support"
    },
    {
      "x": -12,
      "y": 35,
      "z": 1,
      "name": "Plant_Leaves_Beech_Max_Support"
    },
    {
      "x": -12,
      "y": 36,
      "z": 1,
      "name": "Plant_Leaves_Beech_Max_Support"
    },
    {
      "x": -12,
      "y": 37,
      "z": 1,
      "name": "Plant_Leaves_Beech_Max_Support"
    },
    {
      "x": -11,
      "y": 10,
      "z": -17,
      "name": "Wood_Gumboab_Trunk_Full"
    },
    {
      "x": -11,
      "y": 11,
      "z": -17,
      "name": "Wood_Gumboab_Trunk_Full"
    },
    {
      "x": -11,
      "y": 33,
      "z": -17,
      "name": "Plant_Leaves_Beech_Max_Support",
      "support": 15
    },
    {
      "x": -11,
      "y": 10,
      "z": -16,
      "name": "Wood_Gumboab_Trunk_Full"
    },
    {
      "x": -11,
      "y": 11,
      "z": -16,
      "name": "Wood_Gumboab_Trunk_Full"
    },
    {
      "x": -11,
      "y": 12,
      "z": -16,
      "name": "Wood_Gumboab_Trunk_Full"
    },
    {
      "x": -11,
      "y": 33,
      "z": -16,
      "name": "Plant_Leaves_Beech_Max_Support",
      "support": 15
    },
    {
      "x": -11,
      "y": 34,
      "z": -16,
      "name": "Plant_Leaves_Beech_Max_Support"
    },
    {
      "x": -11,
      "y": 35,
      "z": -16,
      "name": "Plant_Leaves_Beech_Max_Support"
    },
    {
      "x": -11,
      "y": 36,
      "z": -16,
      "name": "Plant_Leaves_Beech_Max_Support"
    },
    {
      "x": -11,
      "y": 10,
      "z": -15,
      "name": "Wood_Gumboab_Trunk_Full"
    },
    {
      "x": -11,
      "y": 11,
      "z": -15,
      "name": "Wood_Gumboab_Trunk_Full"
    },
    {
      "x": -11,
      "y": 12,
      "z": -15,
      "name": "Wood_Gumboab_Trunk_Full"
    },
    {
      "x": -11,
      "y": 33,
      "z": -15,
      "name": "Plant_Leaves_Beech_Max_Support"
    },
    {
      "x": -11,
      "y": 34,
      "z": -15,
      "name": "Plant_Leaves_Beech_Max_Support"
    },
    {
      "x": -11,
      "y": 35,
      "z": -15,
      "name": "Plant_Leaves_Beech_Max_Support"
    },
    {
      "x": -11,
      "y": 36,
      "z": -15,
      "name": "Plant_Leaves_Beech_Max_Support"
    },
    {
      "x": -11,
      "y": 37,
      "z": -15,
      "name": "Plant_Leaves_Beech_Max_Support"
    },
    {
      "x": -11,
      "y": 10,
      "z": -14,
      "name": "Wood_Gumboab_Trunk_Full"
    },
    {
      "x": -11,
      "y": 11,
      "z": -14,
      "name": "Wood_Gumboab_Trunk_Full"
    },
    {
      "x": -11,
      "y": 32,
      "z": -14,
      "name": "Plant_Leaves_Beech_Max_Support"
    },
    {
      "x": -11,
      "y": 33,
      "z": -14,
      "name": "Plant_Leaves_Beech_Max_Support"
    },
    {
      "x": -11,
      "y": 34,
      "z": -14,
      "name": "Plant_Leaves_Beech_Max_Support"
    },
    {
      "x": -11,
      "y": 37,
      "z": -14,
      "name": "Plant_Leaves_Beech_Max_Support"
    },
    {
      "x": -11,
      "y": 38,
      "z": -14,
      "name": "Plant_Leaves_Beech_Max_Support"
    },
    {
      "x": -11,
      "y": 10,
      "z": -13,
      "name": "Wood_Gumboab_Trunk_Full"
    },
    {
      "x": -11,
      "y": 31,
      "z": -13,
      "name": "Wood_Gumboab_Trunk_Full"
    },
    {
      "x": -11,
      "y": 32,
      "z": -13,
      "name": "Plant_Leaves_Beech_Max_Support"
    },
    {
      "x": -11,
      "y": 33,
      "z": -13,
      "name": "Plant_Leaves_Beech_Max_Support"
    },
    {
      "x": -11,
      "y": 34,
      "z": -13,
      "name": "Plant_Leaves_Beech_Max_Support"
    },
    {
      "x": -11,
      "y": 35,
      "z": -13,
      "name": "Plant_Leaves_Beech_Max_Support"
    },
    {
      "x": -11,
      "y": 36,
      "z": -13,
      "name": "Plant_Leaves_Beech_Max_Support"
    },
    {
      "x": -11,
      "y": 37,
      "z": -13,
      "name": "Plant_Leaves_Beech_Max_Support"
    },
    {
      "x": -11,
      "y": 30,
      "z": -12,
      "name": "Wood_Gumboab_Trunk_Full"
    },
    {
      "x": -11,
      "y": 31,
      "z": -12,
      "name": "Wood_Gumboab_Trunk_Full"
    },
    {
      "x": -11,
      "y": 32,
      "z": -12,
      "name": "Plant_Leaves_Beech_Max_Support"
    },
    {
      "x": -11,
      "y": 33,
      "z": -12,
      "name": "Plant_Leaves_Beech_Max_Support"
    },
    {
      "x": -11,
      "y": 34,
      "z": -12,
      "name": "Plant_Leaves_Beech_Max_Support"
    },
    {
      "x": -11,
      "y": 35,
      "z": -12,
      "name": "Plant_Leaves_Beech_Max_Support"
    },
    {
      "x": -11,
      "y": 36,
      "z": -12,
      "name": "Plant_Leaves_Beech_Max_Support"
    },
    {
      "x": -11,
      "y": 37,
      "z": -12,
      "name": "Plant_Leaves_Beech_Max_Support"
    },
    {
      "x": -11,
      "y": 38,
      "z": -12,
      "name": "Plant_Leaves_Beech_Max_Support"
    },
    {
      "x": -11,
      "y": 11,
      "z": -11,
      "name": "Wood_Gumboab_Trunk_Full"
    },
    {
      "x": -11,
      "y": 12,
      "z": -11,
      "name": "Wood_Gumboab_Trunk_Full"
    },
    {
      "x": -11,
      "y": 13,
      "z": -11,
      "name": "Wood_Gumboab_Trunk_Full"
    },
    {
      "x": -11,
      "y": 30,
      "z": -11,
      "name": "Wood_Gumboab_Trunk_Full"
    },
    {
      "x": -11,
      "y": 31,
      "z": -11,
      "name": "Wood_Gumboab_Trunk_Full"
    },
    {
      "x": -11,
      "y": 32,
      "z": -11,
      "name": "Plant_Leaves_Beech_Max_Support"
    },
    {
      "x": -11,
      "y": 33,
      "z": -11,
      "name": "Plant_Leaves_Beech_Max_Support"
    },
    {
      "x": -11,
      "y": 34,
      "z": -11,
      "name": "Plant_Leaves_Beech_Max_Support"
    },
    {
      "x": -11,
      "y": 35,
      "z": -11,
      "name": "Plant_Leaves_Beech_Max_Support"
    },
    {
      "x": -11,
      "y": 36,
      "z": -11,
      "name": "Plant_Leaves_Beech_Max_Support"
    },
    {
      "x": -11,
      "y": 37,
      "z": -11,
      "name": "Plant_Leaves_Beech_Max_Support"
    },
    {
      "x": -11,
      "y": 9,
      "z": -10,
      "name": "Wood_Gumboab_Trunk_Full"
    },
    {
      "x": -11,
      "y": 11,
      "z": -10,
      "name": "Wood_Gumboab_Trunk_Full"
    },
    {
      "x": -11,
      "y": 12,
      "z": -10,
      "name": "Wood_Gumboab_Trunk_Full"
    },
    {
      "x": -11,
      "y": 13,
      "z": -10,
      "name": "Wood_Gumboab_Trunk_Full"
    },
    {
      "x": -11,
      "y": 30,
      "z": -10,
      "name": "Wood_Gumboab_Trunk_Full"
    },
    {
      "x": -11,
      "y": 31,
      "z": -10,
      "name": "Wood_Gumboab_Trunk_Full"
    },
    {
      "x": -11,
      "y": 32,
      "z": -10,
      "name": "Plant_Leaves_Beech_Max_Support"
    },
    {
      "x": -11,
      "y": 33,
      "z": -10,
      "name": "Plant_Leaves_Beech_Max_Support"
    },
    {
      "x": -11,
      "y": 34,
      "z": -10,
      "name": "Plant_Leaves_Beech_Max_Support"
    },
    {
      "x": -11,
      "y": 35,
      "z": -10,
      "name": "Plant_Leaves_Beech_Max_Support"
    },
    {
      "x": -11,
      "y": 36,
      "z": -10,
      "name": "Plant_Leaves_Beech_Max_Support"
    },
    {
      "x": -11,
      "y": 37,
      "z": -10,
      "name": "Plant_Leaves_Beech_Max_Support"
    },
    {
      "x": -11,
      "y": 12,
      "z": -9,
      "name": "Wood_Gumboab_Trunk_Full"
    },
    {
      "x": -11,
      "y": 30,
      "z": -9,
      "name": "Plant_Leaves_Beech_Max_Support"
    },
    {
      "x": -11,
      "y": 31,
      "z": -9,
      "name": "Plant_Leaves_Beech_Max_Support"
    },
    {
      "x": -11,
      "y": 33,
      "z": -9,
      "name": "Plant_Leaves_Beech_Max_Support"
    },
    {
      "x": -11,
      "y": 34,
      "z": -9,
      "name": "Plant_Leaves_Beech_Max_Support"
    },
    {
      "x": -11,
      "y": 35,
      "z": -9,
      "name": "Plant_Leaves_Beech_Max_Support"
    },
    {
      "x": -11,
      "y": 36,
      "z": -9,
      "name": "Plant_Leaves_Beech_Max_Support"
    },
    {
      "x": -11,
      "y": 5,
      "z": -8,
      "name": "Wood_Gumboab_Trunk_Full"
    },
    {
      "x": -11,
      "y": 31,
      "z": -8,
      "name": "Plant_Leaves_Beech_Max_Support"
    },
    {
      "x": -11,
      "y": 32,
      "z": -8,
      "name": "Plant_Leaves_Beech_Max_Support"
    },
    {
      "x": -11,
      "y": 33,
      "z": -8,
      "name": "Plant_Leaves_Beech_Max_Support"
    },
    {
      "x": -11,
      "y": 4,
      "z": -7,
      "name": "Wood_Gumboab_Roots"
    },
    {
      "x": -11,
      "y": 5,
      "z": -7,
      "name": "Wood_Gumboab_Trunk_Full"
    },
    {
      "x": -11,
      "y": 6,
      "z": -7,
      "name": "Wood_Gumboab_Trunk_Full"
    },
    {
      "x": -11,
      "y": 7,
      "z": -7,
      "name": "Wood_Gumboab_Trunk_Full"
    },
    {
      "x": -11,
      "y": 8,
      "z": -7,
      "name": "Wood_Gumboab_Trunk_Full"
    },
    {
      "x": -11,
      "y": 9,
      "z": -7,
      "name": "Wood_Gumboab_Trunk_Full"
    },
    {
      "x": -11,
      "y": 10,
      "z": -7,
      "name": "Wood_Gumboab_Trunk_Full"
    },
    {
      "x": -11,
      "y": 11,
      "z": -7,
      "name": "Wood_Gumboab_Trunk_Full"
    },
    {
      "x": -11,
      "y": 12,
      "z": -7,
      "name": "Wood_Gumboab_Trunk_Full"
    },
    {
      "x": -11,
      "y": 32,
      "z": -7,
      "name": "Plant_Leaves_Beech_Max_Support"
    },
    {
      "x": -11,
      "y": 34,
      "z": -7,
      "name": "Plant_Leaves_Beech_Max_Support"
    },
    {
      "x": -11,
      "y": 37,
      "z": -7,
      "name": "Plant_Leaves_Beech_Max_Support"
    },
    {
      "x": -11,
      "y": 9,
      "z": -6,
      "name": "Wood_Gumboab_Trunk_Full"
    },
    {
      "x": -11,
      "y": 10,
      "z": -6,
      "name": "Wood_Gumboab_Trunk_Full"
    },
    {
      "x": -11,
      "y": 11,
      "z": -6,
      "name": "Wood_Gumboab_Trunk_Full"
    },
    {
      "x": -11,
      "y": 12,
      "z": -6,
      "name": "Wood_Gumboab_Trunk_Full"
    },
    {
      "x": -11,
      "y": 32,
      "z": -6,
      "name": "Plant_Leaves_Beech_Max_Support"
    },
    {
      "x": -11,
      "y": 33,
      "z": -6,
      "name": "Plant_Leaves_Beech_Max_Support"
    },
    {
      "x": -11,
      "y": 34,
      "z": -6,
      "name": "Plant_Leaves_Beech_Max_Support"
    },
    {
      "x": -11,
      "y": 35,
      "z": -6,
      "name": "Plant_Leaves_Beech_Max_Support"
    },
    {
      "x": -11,
      "y": 37,
      "z": -6,
      "name": "Plant_Leaves_Beech_Max_Support"
    },
    {
      "x": -11,
      "y": 38,
      "z": -6,
      "name": "Plant_Leaves_Beech_Max_Support"
    },
    {
      "x": -11,
      "y": 11,
      "z": -5,
      "name": "Wood_Gumboab_Trunk_Full"
    },
    {
      "x": -11,
      "y": 34,
      "z": -5,
      "name": "Plant_Leaves_Beech_Max_Support"
    },
    {
      "x": -11,
      "y": 35,
      "z": -5,
      "name": "Plant_Leaves_Beech_Max_Support"
    },
    {
      "x": -11,
      "y": 36,
      "z": -5,
      "name": "Plant_Leaves_Beech_Max_Support"
    },
    {
      "x": -11,
      "y": 37,
      "z": -5,
      "name": "Plant_Leaves_Beech_Max_Support"
    },
    {
      "x": -11,
      "y": 38,
      "z": -5,
      "name": "Plant_Leaves_Beech_Max_Support"
    },
    {
      "x": -11,
      "y": 30,
      "z": -4,
      "name": "Wood_Gumboab_Branch_Short",
      "support": 15,
      "rotation": 3
    },
    {
      "x": -11,
      "y": 33,
      "z": -4,
      "name": "Plant_Leaves_Beech_Max_Support"
    },
    {
      "x": -11,
      "y": 35,
      "z": -4,
      "name": "Plant_Leaves_Beech_Max_Support"
    },
    {
      "x": -11,
      "y": 36,
      "z": -4,
      "name": "Plant_Leaves_Beech_Max_Support"
    },
    {
      "x": -11,
      "y": 37,
      "z": -4,
      "name": "Plant_Leaves_Beech_Max_Support"
    },
    {
      "x": -11,
      "y": 38,
      "z": -4,
      "name": "Plant_Leaves_Beech_Max_Support"
    },
    {
      "x": -11,
      "y": 6,
      "z": -3,
      "name": "Wood_Gumboab_Roots"
    },
    {
      "x": -11,
      "y": 7,
      "z": -3,
      "name": "Wood_Gumboab_Trunk_Full"
    },
    {
      "x": -11,
      "y": 31,
      "z": -3,
      "name": "Wood_Gumboab_Trunk_Full"
    },
    {
      "x": -11,
      "y": 32,
      "z": -3,
      "name": "Wood_Gumboab_Trunk_Full"
    },
    {
      "x": -11,
      "y": 33,
      "z": -3,
      "name": "Wood_Gumboab_Trunk_Full"
    },
    {
      "x": -11,
      "y": 35,
      "z": -3,
      "name": "Plant_Leaves_Beech_Max_Support"
    },
    {
      "x": -11,
      "y": 36,
      "z": -3,
      "name": "Plant_Leaves_Beech_Max_Support"
    },
    {
      "x": -11,
      "y": 37,
      "z": -3,
      "name": "Plant_Leaves_Beech_Max_Support"
    },
    {
      "x": -11,
      "y": 38,
      "z": -3,
      "name": "Plant_Leaves_Beech_Max_Support"
    },
    {
      "x": -11,
      "y": 39,
      "z": -3,
      "name": "Plant_Leaves_Beech_Max_Support"
    },
    {
      "x": -11,
      "y": 6,
      "z": -2,
      "name": "Wood_Gumboab_Roots"
    },
    {
      "x": -11,
      "y": 7,
      "z": -2,
      "name": "Wood_Gumboab_Trunk_Full"
    },
    {
      "x": -11,
      "y": 31,
      "z": -2,
      "name": "Wood_Gumboab_Roots"
    },
    {
      "x": -11,
      "y": 32,
      "z": -2,
      "name": "Wood_Gumboab_Trunk_Full"
    },
    {
      "x": -11,
      "y": 33,
      "z": -2,
      "name": "Wood_Gumboab_Trunk_Full"
    },
    {
      "x": -11,
      "y": 34,
      "z": -2,
      "name": "Wood_Gumboab_Trunk_Full"
    },
    {
      "x": -11,
      "y": 35,
      "z": -2,
      "name": "Plant_Leaves_Beech_Max_Support"
    },
    {
      "x": -11,
      "y": 36,
      "z": -2,
      "name": "Plant_Leaves_Beech_Max_Support"
    },
    {
      "x": -11,
      "y": 37,
      "z": -2,
      "name": "Plant_Leaves_Beech_Max_Support"
    },
    {
      "x": -11,
      "y": 38,
      "z": -2,
      "name": "Plant_Leaves_Beech_Max_Support"
    },
    {
      "x": -11,
      "y": 32,
      "z": -1,
      "name": "Plant_Leaves_Beech_Max_Support"
    },
    {
      "x": -11,
      "y": 35,
      "z": -1,
      "name": "Plant_Leaves_Beech_Max_Support"
    },
    {
      "x": -11,
      "y": 36,
      "z": -1,
      "name": "Plant_Leaves_Beech_Max_Support"
    },
    {
      "x": -11,
      "y": 37,
      "z": -1,
      "name": "Plant_Leaves_Beech_Max_Support"
    },
    {
      "x": -11,
      "y": 38,
      "z": -1,
      "name": "Plant_Leaves_Beech_Max_Support"
    },
    {
      "x": -11,
      "y": 33,
      "z": 0,
      "name": "Plant_Leaves_Beech_Max_Support"
    },
    {
      "x": -11,
      "y": 34,
      "z": 0,
      "name": "Plant_Leaves_Beech_Max_Support"
    },
    {
      "x": -11,
      "y": 35,
      "z": 0,
      "name": "Plant_Leaves_Beech_Max_Support"
    },
    {
      "x": -11,
      "y": 36,
      "z": 0,
      "name": "Plant_Leaves_Beech_Max_Support"
    },
    {
      "x": -11,
      "y": 37,
      "z": 0,
      "name": "Plant_Leaves_Beech_Max_Support"
    },
    {
      "x": -11,
      "y": 33,
      "z": 1,
      "name": "Plant_Leaves_Beech_Max_Support",
      "support": 15
    },
    {
      "x": -11,
      "y": 36,
      "z": 1,
      "name": "Plant_Leaves_Beech_Max_Support"
    },
    {
      "x": -10,
      "y": 10,
      "z": -16,
      "name": "Wood_Gumboab_Trunk_Full"
    },
    {
      "x": -10,
      "y": 11,
      "z": -16,
      "name": "Wood_Gumboab_Trunk_Full"
    },
    {
      "x": -10,
      "y": 12,
      "z": -16,
      "name": "Wood_Gumboab_Trunk_Full"
    },
    {
      "x": -10,
      "y": 34,
      "z": -16,
      "name": "Plant_Leaves_Beech_Max_Support"
    },
    {
      "x": -10,
      "y": 36,
      "z": -16,
      "name": "Plant_Leaves_Beech_Max_Support"
    },
    {
      "x": -10,
      "y": 10,
      "z": -15,
      "name": "Wood_Gumboab_Trunk_Full"
    },
    {
      "x": -10,
      "y": 11,
      "z": -15,
      "name": "Wood_Gumboab_Trunk_Full"
    },
    {
      "x": -10,
      "y": 12,
      "z": -15,
      "name": "Wood_Gumboab_Trunk_Full"
    },
    {
      "x": -10,
      "y": 34,
      "z": -15,
      "name": "Plant_Leaves_Beech_Max_Support"
    },
    {
      "x": -10,
      "y": 35,
      "z": -15,
      "name": "Plant_Leaves_Beech_Max_Support"
    },
    {
      "x": -10,
      "y": 36,
      "z": -15,
      "name": "Plant_Leaves_Beech_Max_Support"
    },
    {
      "x": -10,
      "y": 10,
      "z": -14,
      "name": "Wood_Gumboab_Trunk_Full"
    },
    {
      "x": -10,
      "y": 11,
      "z": -14,
      "name": "Wood_Gumboab_Trunk_Full"
    },
    {
      "x": -10,
      "y": 32,
      "z": -14,
      "name": "Plant_Leaves_Beech_Max_Support"
    },
    {
      "x": -10,
      "y": 34,
      "z": -14,
      "name": "Plant_Leaves_Beech_Max_Support"
    },
    {
      "x": -10,
      "y": 35,
      "z": -14,
      "name": "Plant_Leaves_Beech_Max_Support"
    },
    {
      "x": -10,
      "y": 37,
      "z": -14,
      "name": "Plant_Leaves_Beech_Max_Support"
    },
    {
      "x": -10,
      "y": 38,
      "z": -14,
      "name": "Plant_Leaves_Beech_Max_Support"
    },
    {
      "x": -10,
      "y": 31,
      "z": -13,
      "name": "Plant_Leaves_Beech_Max_Support"
    },
    {
      "x": -10,
      "y": 32,
      "z": -13,
      "name": "Plant_Leaves_Beech_Max_Support"
    },
    {
      "x": -10,
      "y": 33,
      "z": -13,
      "name": "Plant_Leaves_Beech_Max_Support",
      "support": 15
    },
    {
      "x": -10,
      "y": 34,
      "z": -13,
      "name": "Plant_Leaves_Beech_Max_Support"
    },
    {
      "x": -10,
      "y": 35,
      "z": -13,
      "name": "Plant_Leaves_Beech_Max_Support"
    },
    {
      "x": -10,
      "y": 36,
      "z": -13,
      "name": "Plant_Leaves_Beech_Max_Support"
    },
    {
      "x": -10,
      "y": 37,
      "z": -13,
      "name": "Plant_Leaves_Beech_Max_Support"
    },
    {
      "x": -10,
      "y": 30,
      "z": -12,
      "name": "Wood_Gumboab_Trunk_Full"
    },
    {
      "x": -10,
      "y": 31,
      "z": -12,
      "name": "Wood_Gumboab_Trunk_Full"
    },
    {
      "x": -10,
      "y": 32,
      "z": -12,
      "name": "Plant_Leaves_Beech_Max_Support"
    },
    {
      "x": -10,
      "y": 33,
      "z": -12,
      "name": "Plant_Leaves_Beech_Max_Support"
    },
    {
      "x": -10,
      "y": 34,
      "z": -12,
      "name": "Plant_Leaves_Beech_Max_Support"
    },
    {
      "x": -10,
      "y": 35,
      "z": -12,
      "name": "Plant_Leaves_Beech_Max_Support"
    },
    {
      "x": -10,
      "y": 36,
      "z": -12,
      "name": "Plant_Leaves_Beech_Max_Support"
    },
    {
      "x": -10,
      "y": 37,
      "z": -12,
      "name": "Plant_Leaves_Beech_Max_Support"
    },
    {
      "x": -10,
      "y": 38,
      "z": -12,
      "name": "Plant_Leaves_Beech_Max_Support"
    },
    {
      "x": -10,
      "y": 12,
      "z": -11,
      "name": "Wood_Gumboab_Trunk_Full"
    },
    {
      "x": -10,
      "y": 13,
      "z": -11,
      "name": "Wood_Gumboab_Trunk_Full"
    },
    {
      "x": -10,
      "y": 29,
      "z": -11,
      "name": "Wood_Gumboab_Trunk_Full"
    },
    {
      "x": -10,
      "y": 30,
      "z": -11,
      "name": "Wood_Gumboab_Trunk_Full"
    },
    {
      "x": -10,
      "y": 31,
      "z": -11,
      "name": "Wood_Gumboab_Trunk_Full"
    },
    {
      "x": -10,
      "y": 32,
      "z": -11,
      "name": "Plant_Leaves_Beech_Max_Support"
    },
    {
      "x": -10,
      "y": 33,
      "z": -11,
      "name": "Plant_Leaves_Beech_Max_Support"
    },
    {
      "x": -10,
      "y": 34,
      "z": -11,
      "name": "Plant_Leaves_Beech_Max_Support"
    },
    {
      "x": -10,
      "y": 36,
      "z": -11,
      "name": "Plant_Leaves_Beech_Max_Support"
    },
    {
      "x": -10,
      "y": 37,
      "z": -11,
      "name": "Plant_Leaves_Beech_Max_Support"
    },
    {
      "x": -10,
      "y": 8,
      "z": -10,
      "name": "Wood_Gumboab_Trunk_Full"
    },
    {
      "x": -10,
      "y": 9,
      "z": -10,
      "name": "Wood_Gumboab_Trunk_Full"
    },
    {
      "x": -10,
      "y": 10,
      "z": -10,
      "name": "Wood_Gumboab_Trunk_Full"
    },
    {
      "x": -10,
      "y": 11,
      "z": -10,
      "name": "Wood_Gumboab_Trunk_Full"
    },
    {
      "x": -10,
      "y": 12,
      "z": -10,
      "name": "Wood_Gumboab_Trunk_Full"
    },
    {
      "x": -10,
      "y": 13,
      "z": -10,
      "name": "Wood_Gumboab_Trunk_Full"
    },
    {
      "x": -10,
      "y": 30,
      "z": -10,
      "name": "Wood_Gumboab_Trunk_Full"
    },
    {
      "x": -10,
      "y": 31,
      "z": -10,
      "name": "Wood_Gumboab_Trunk_Full"
    },
    {
      "x": -10,
      "y": 32,
      "z": -10,
      "name": "Plant_Leaves_Beech_Max_Support"
    },
    {
      "x": -10,
      "y": 33,
      "z": -10,
      "name": "Plant_Leaves_Beech_Max_Support"
    },
    {
      "x": -10,
      "y": 34,
      "z": -10,
      "name": "Plant_Leaves_Beech_Max_Support"
    },
    {
      "x": -10,
      "y": 35,
      "z": -10,
      "name": "Plant_Leaves_Beech_Max_Support"
    },
    {
      "x": -10,
      "y": 36,
      "z": -10,
      "name": "Plant_Leaves_Beech_Max_Support"
    },
    {
      "x": -10,
      "y": 37,
      "z": -10,
      "name": "Plant_Leaves_Beech_Max_Support"
    },
    {
      "x": -10,
      "y": 8,
      "z": -9,
      "name": "Wood_Gumboab_Trunk_Full"
    },
    {
      "x": -10,
      "y": 9,
      "z": -9,
      "name": "Wood_Gumboab_Trunk_Full"
    },
    {
      "x": -10,
      "y": 10,
      "z": -9,
      "name": "Wood_Gumboab_Trunk_Full"
    },
    {
      "x": -10,
      "y": 30,
      "z": -9,
      "name": "Plant_Leaves_Beech_Max_Support"
    },
    {
      "x": -10,
      "y": 31,
      "z": -9,
      "name": "Plant_Leaves_Beech_Max_Support"
    },
    {
      "x": -10,
      "y": 32,
      "z": -9,
      "name": "Plant_Leaves_Beech_Max_Support"
    },
    {
      "x": -10,
      "y": 33,
      "z": -9,
      "name": "Plant_Leaves_Beech_Max_Support"
    },
    {
      "x": -10,
      "y": 34,
      "z": -9,
      "name": "Plant_Leaves_Beech_Max_Support"
    },
    {
      "x": -10,
      "y": 35,
      "z": -9,
      "name": "Plant_Leaves_Beech_Max_Support"
    },
    {
      "x": -10,
      "y": 36,
      "z": -9,
      "name": "Plant_Leaves_Beech_Max_Support"
    },
    {
      "x": -10,
      "y": 13,
      "z": -8,
      "name": "Wood_Gumboab_Trunk_Full"
    },
    {
      "x": -10,
      "y": 31,
      "z": -8,
      "name": "Plant_Leaves_Beech_Max_Support"
    },
    {
      "x": -10,
      "y": 33,
      "z": -8,
      "name": "Plant_Leaves_Beech_Max_Support"
    },
    {
      "x": -10,
      "y": 34,
      "z": -8,
      "name": "Plant_Leaves_Beech_Max_Support"
    },
    {
      "x": -10,
      "y": 35,
      "z": -8,
      "name": "Plant_Leaves_Beech_Max_Support"
    },
    {
      "x": -10,
      "y": 11,
      "z": -7,
      "name": "Wood_Gumboab_Trunk_Full"
    },
    {
      "x": -10,
      "y": 12,
      "z": -7,
      "name": "Wood_Gumboab_Trunk_Full"
    },
    {
      "x": -10,
      "y": 13,
      "z": -7,
      "name": "Wood_Gumboab_Trunk_Full"
    },
    {
      "x": -10,
      "y": 32,
      "z": -7,
      "name": "Plant_Leaves_Beech_Max_Support"
    },
    {
      "x": -10,
      "y": 33,
      "z": -7,
      "name": "Plant_Leaves_Beech_Max_Support"
    },
    {
      "x": -10,
      "y": 36,
      "z": -7,
      "name": "Plant_Leaves_Beech_Max_Support"
    },
    {
      "x": -10,
      "y": 11,
      "z": -6,
      "name": "Wood_Gumboab_Trunk_Full"
    },
    {
      "x": -10,
      "y": 12,
      "z": -6,
      "name": "Wood_Gumboab_Trunk_Full"
    },
    {
      "x": -10,
      "y": 13,
      "z": -6,
      "name": "Wood_Gumboab_Trunk_Full"
    },
    {
      "x": -10,
      "y": 30,
      "z": -6,
      "name": "Wood_Gumboab_Trunk_Full"
    },
    {
      "x": -10,
      "y": 34,
      "z": -6,
      "name": "Plant_Leaves_Beech_Max_Support"
    },
    {
      "x": -10,
      "y": 36,
      "z": -6,
      "name": "Plant_Leaves_Beech_Max_Support"
    },
    {
      "x": -10,
      "y": 37,
      "z": -6,
      "name": "Plant_Leaves_Beech_Max_Support"
    },
    {
      "x": -10,
      "y": 38,
      "z": -6,
      "name": "Plant_Leaves_Beech_Max_Support"
    },
    {
      "x": -10,
      "y": 11,
      "z": -5,
      "name": "Wood_Gumboab_Trunk_Full"
    },
    {
      "x": -10,
      "y": 12,
      "z": -5,
      "name": "Wood_Gumboab_Trunk_Full"
    },
    {
      "x": -10,
      "y": 30,
      "z": -5,
      "name": "Wood_Gumboab_Trunk_Full"
    },
    {
      "x": -10,
      "y": 31,
      "z": -5,
      "name": "Wood_Gumboab_Trunk_Full"
    },
    {
      "x": -10,
      "y": 34,
      "z": -5,
      "name": "Plant_Leaves_Beech_Max_Support"
    },
    {
      "x": -10,
      "y": 35,
      "z": -5,
      "name": "Plant_Leaves_Beech_Max_Support"
    },
    {
      "x": -10,
      "y": 36,
      "z": -5,
      "name": "Plant_Leaves_Beech_Max_Support"
    },
    {
      "x": -10,
      "y": 37,
      "z": -5,
      "name": "Plant_Leaves_Beech_Max_Support"
    },
    {
      "x": -10,
      "y": 38,
      "z": -5,
      "name": "Plant_Leaves_Beech_Max_Support"
    },
    {
      "x": -10,
      "y": 30,
      "z": -4,
      "name": "Wood_Gumboab_Trunk_Full"
    },
    {
      "x": -10,
      "y": 31,
      "z": -4,
      "name": "Wood_Gumboab_Trunk_Full"
    },
    {
      "x": -10,
      "y": 32,
      "z": -4,
      "name": "Wood_Gumboab_Trunk_Full"
    },
    {
      "x": -10,
      "y": 33,
      "z": -4,
      "name": "Plant_Leaves_Beech_Max_Support"
    },
    {
      "x": -10,
      "y": 34,
      "z": -4,
      "name": "Plant_Leaves_Beech_Max_Support"
    },
    {
      "x": -10,
      "y": 35,
      "z": -4,
      "name": "Plant_Leaves_Beech_Max_Support"
    },
    {
      "x": -10,
      "y": 36,
      "z": -4,
      "name": "Plant_Leaves_Beech_Max_Support"
    },
    {
      "x": -10,
      "y": 37,
      "z": -4,
      "name": "Plant_Leaves_Beech_Max_Support"
    },
    {
      "x": -10,
      "y": 39,
      "z": -4,
      "name": "Plant_Leaves_Beech_Max_Support"
    },
    {
      "x": -10,
      "y": 40,
      "z": -4,
      "name": "Plant_Leaves_Beech_Max_Support"
    },
    {
      "x": -10,
      "y": 6,
      "z": -3,
      "name": "Wood_Gumboab_Roots"
    },
    {
      "x": -10,
      "y": 7,
      "z": -3,
      "name": "Wood_Gumboab_Trunk_Full"
    },
    {
      "x": -10,
      "y": 8,
      "z": -3,
      "name": "Wood_Gumboab_Trunk_Full"
    },
    {
      "x": -10,
      "y": 9,
      "z": -3,
      "name": "Wood_Gumboab_Trunk_Full"
    },
    {
      "x": -10,
      "y": 31,
      "z": -3,
      "name": "Wood_Gumboab_Trunk_Full"
    },
    {
      "x": -10,
      "y": 32,
      "z": -3,
      "name": "Wood_Gumboab_Trunk_Full"
    },
    {
      "x": -10,
      "y": 33,
      "z": -3,
      "name": "Wood_Gumboab_Trunk_Full"
    },
    {
      "x": -10,
      "y": 34,
      "z": -3,
      "name": "Plant_Leaves_Beech_Max_Support"
    },
    {
      "x": -10,
      "y": 35,
      "z": -3,
      "name": "Plant_Leaves_Beech_Max_Support"
    },
    {
      "x": -10,
      "y": 36,
      "z": -3,
      "name": "Plant_Leaves_Beech_Max_Support"
    },
    {
      "x": -10,
      "y": 37,
      "z": -3,
      "name": "Plant_Leaves_Beech_Max_Support"
    },
    {
      "x": -10,
      "y": 38,
      "z": -3,
      "name": "Plant_Leaves_Beech_Max_Support"
    },
    {
      "x": -10,
      "y": 39,
      "z": -3,
      "name": "Plant_Leaves_Beech_Max_Support"
    },
    {
      "x": -10,
      "y": 40,
      "z": -3,
      "name": "Plant_Leaves_Beech_Max_Support"
    },
    {
      "x": -10,
      "y": 31,
      "z": -2,
      "name": "Wood_Gumboab_Trunk_Full"
    },
    {
      "x": -10,
      "y": 32,
      "z": -2,
      "name": "Wood_Gumboab_Trunk_Full"
    },
    {
      "x": -10,
      "y": 33,
      "z": -2,
      "name": "Wood_Gumboab_Trunk_Full"
    },
    {
      "x": -10,
      "y": 34,
      "z": -2,
      "name": "Plant_Leaves_Beech_Max_Support"
    },
    {
      "x": -10,
      "y": 35,
      "z": -2,
      "name": "Plant_Leaves_Beech_Max_Support"
    },
    {
      "x": -10,
      "y": 36,
      "z": -2,
      "name": "Plant_Leaves_Beech_Max_Support"
    },
    {
      "x": -10,
      "y": 37,
      "z": -2,
      "name": "Plant_Leaves_Beech_Max_Support"
    },
    {
      "x": -10,
      "y": 38,
      "z": -2,
      "name": "Plant_Leaves_Beech_Max_Support"
    },
    {
      "x": -10,
      "y": 39,
      "z": -2,
      "name": "Plant_Leaves_Beech_Max_Support"
    },
    {
      "x": -10,
      "y": 32,
      "z": -1,
      "name": "Plant_Leaves_Beech_Max_Support"
    },
    {
      "x": -10,
      "y": 33,
      "z": -1,
      "name": "Plant_Leaves_Beech_Max_Support"
    },
    {
      "x": -10,
      "y": 34,
      "z": -1,
      "name": "Plant_Leaves_Beech_Max_Support"
    },
    {
      "x": -10,
      "y": 35,
      "z": -1,
      "name": "Plant_Leaves_Beech_Max_Support"
    },
    {
      "x": -10,
      "y": 36,
      "z": -1,
      "name": "Plant_Leaves_Beech_Max_Support"
    },
    {
      "x": -10,
      "y": 37,
      "z": -1,
      "name": "Plant_Leaves_Beech_Max_Support"
    },
    {
      "x": -10,
      "y": 38,
      "z": -1,
      "name": "Plant_Leaves_Beech_Max_Support"
    },
    {
      "x": -10,
      "y": 39,
      "z": -1,
      "name": "Plant_Leaves_Beech_Max_Support"
    },
    {
      "x": -10,
      "y": 33,
      "z": 0,
      "name": "Plant_Leaves_Beech_Max_Support"
    },
    {
      "x": -10,
      "y": 35,
      "z": 0,
      "name": "Plant_Leaves_Beech_Max_Support"
    },
    {
      "x": -10,
      "y": 36,
      "z": 0,
      "name": "Plant_Leaves_Beech_Max_Support"
    },
    {
      "x": -10,
      "y": 38,
      "z": 0,
      "name": "Plant_Leaves_Beech_Max_Support"
    },
    {
      "x": -10,
      "y": 33,
      "z": 1,
      "name": "Plant_Leaves_Beech_Max_Support",
      "support": 15
    },
    {
      "x": -10,
      "y": 35,
      "z": 1,
      "name": "Plant_Leaves_Beech_Max_Support"
    },
    {
      "x": -10,
      "y": 36,
      "z": 1,
      "name": "Plant_Leaves_Beech_Max_Support"
    },
    {
      "x": -9,
      "y": 11,
      "z": -16,
      "name": "Wood_Gumboab_Trunk_Full"
    },
    {
      "x": -9,
      "y": 9,
      "z": -15,
      "name": "Wood_Gumboab_Trunk_Full"
    },
    {
      "x": -9,
      "y": 10,
      "z": -15,
      "name": "Wood_Gumboab_Trunk_Full"
    },
    {
      "x": -9,
      "y": 11,
      "z": -15,
      "name": "Wood_Gumboab_Trunk_Full"
    },
    {
      "x": -9,
      "y": 34,
      "z": -15,
      "name": "Plant_Leaves_Beech_Max_Support"
    },
    {
      "x": -9,
      "y": 35,
      "z": -15,
      "name": "Plant_Leaves_Beech_Max_Support"
    },
    {
      "x": -9,
      "y": 9,
      "z": -14,
      "name": "Wood_Gumboab_Trunk_Full"
    },
    {
      "x": -9,
      "y": 10,
      "z": -14,
      "name": "Wood_Gumboab_Trunk_Full"
    },
    {
      "x": -9,
      "y": 11,
      "z": -14,
      "name": "Wood_Gumboab_Trunk_Full"
    },
    {
      "x": -9,
      "y": 33,
      "z": -14,
      "name": "Plant_Leaves_Beech_Max_Support"
    },
    {
      "x": -9,
      "y": 35,
      "z": -14,
      "name": "Plant_Leaves_Beech_Max_Support"
    },
    {
      "x": -9,
      "y": 36,
      "z": -14,
      "name": "Plant_Leaves_Beech_Max_Support"
    },
    {
      "x": -9,
      "y": 9,
      "z": -13,
      "name": "Wood_Gumboab_Trunk_Full"
    },
    {
      "x": -9,
      "y": 10,
      "z": -13,
      "name": "Wood_Gumboab_Trunk_Full"
    },
    {
      "x": -9,
      "y": 32,
      "z": -13,
      "name": "Plant_Leaves_Beech_Max_Support"
    },
    {
      "x": -9,
      "y": 33,
      "z": -13,
      "name": "Plant_Leaves_Beech_Max_Support"
    },
    {
      "x": -9,
      "y": 34,
      "z": -13,
      "name": "Plant_Leaves_Beech_Max_Support"
    },
    {
      "x": -9,
      "y": 35,
      "z": -13,
      "name": "Plant_Leaves_Beech_Max_Support"
    },
    {
      "x": -9,
      "y": 36,
      "z": -13,
      "name": "Plant_Leaves_Beech_Max_Support"
    },
    {
      "x": -9,
      "y": 37,
      "z": -13,
      "name": "Plant_Leaves_Beech_Max_Support"
    },
    {
      "x": -9,
      "y": 30,
      "z": -12,
      "name": "Wood_Gumboab_Trunk_Full"
    },
    {
      "x": -9,
      "y": 31,
      "z": -12,
      "name": "Plant_Leaves_Beech_Max_Support"
    },
    {
      "x": -9,
      "y": 32,
      "z": -12,
      "name": "Plant_Leaves_Beech_Max_Support"
    },
    {
      "x": -9,
      "y": 33,
      "z": -12,
      "name": "Plant_Leaves_Beech_Max_Support"
    },
    {
      "x": -9,
      "y": 36,
      "z": -12,
      "name": "Plant_Leaves_Beech_Max_Support"
    },
    {
      "x": -9,
      "y": 37,
      "z": -12,
      "name": "Plant_Leaves_Beech_Max_Support"
    },
    {
      "x": -9,
      "y": 12,
      "z": -11,
      "name": "Wood_Gumboab_Trunk_Full"
    },
    {
      "x": -9,
      "y": 13,
      "z": -11,
      "name": "Wood_Gumboab_Trunk_Full"
    },
    {
      "x": -9,
      "y": 29,
      "z": -11,
      "name": "Wood_Gumboab_Trunk_Full"
    },
    {
      "x": -9,
      "y": 30,
      "z": -11,
      "name": "Wood_Gumboab_Trunk_Full"
    },
    {
      "x": -9,
      "y": 31,
      "z": -11,
      "name": "Wood_Gumboab_Trunk_Full"
    },
    {
      "x": -9,
      "y": 33,
      "z": -11,
      "name": "Plant_Leaves_Beech_Max_Support"
    },
    {
      "x": -9,
      "y": 34,
      "z": -11,
      "name": "Plant_Leaves_Beech_Max_Support"
    },
    {
      "x": -9,
      "y": 35,
      "z": -11,
      "name": "Plant_Leaves_Beech_Max_Support"
    },
    {
      "x": -9,
      "y": 36,
      "z": -11,
      "name": "Plant_Leaves_Beech_Max_Support"
    },
    {
      "x": -9,
      "y": 37,
      "z": -11,
      "name": "Plant_Leaves_Beech_Max_Support"
    },
    {
      "x": -9,
      "y": 8,
      "z": -10,
      "name": "Wood_Gumboab_Trunk_Full"
    },
    {
      "x": -9,
      "y": 9,
      "z": -10,
      "name": "Wood_Gumboab_Trunk_Full"
    },
    {
      "x": -9,
      "y": 12,
      "z": -10,
      "name": "Wood_Gumboab_Trunk_Full"
    },
    {
      "x": -9,
      "y": 13,
      "z": -10,
      "name": "Wood_Gumboab_Trunk_Full"
    },
    {
      "x": -9,
      "y": 29,
      "z": -10,
      "name": "Wood_Gumboab_Trunk_Full"
    },
    {
      "x": -9,
      "y": 30,
      "z": -10,
      "name": "Wood_Gumboab_Trunk_Full"
    },
    {
      "x": -9,
      "y": 31,
      "z": -10,
      "name": "Wood_Gumboab_Trunk_Full"
    },
    {
      "x": -9,
      "y": 32,
      "z": -10,
      "name": "Plant_Leaves_Beech_Max_Support"
    },
    {
      "x": -9,
      "y": 33,
      "z": -10,
      "name": "Plant_Leaves_Beech_Max_Support"
    },
    {
      "x": -9,
      "y": 34,
      "z": -10,
      "name": "Plant_Leaves_Beech_Max_Support"
    },
    {
      "x": -9,
      "y": 35,
      "z": -10,
      "name": "Plant_Leaves_Beech_Max_Support"
    },
    {
      "x": -9,
      "y": 36,
      "z": -10,
      "name": "Plant_Leaves_Beech_Max_Support"
    },
    {
      "x": -9,
      "y": 37,
      "z": -10,
      "name": "Plant_Leaves_Beech_Max_Support"
    },
    {
      "x": -9,
      "y": 6,
      "z": -9,
      "name": "Wood_Gumboab_Trunk_Full"
    },
    {
      "x": -9,
      "y": 7,
      "z": -9,
      "name": "Wood_Gumboab_Trunk_Full"
    },
    {
      "x": -9,
      "y": 8,
      "z": -9,
      "name": "Wood_Gumboab_Trunk_Full"
    },
    {
      "x": -9,
      "y": 9,
      "z": -9,
      "name": "Wood_Gumboab_Trunk_Full"
    },
    {
      "x": -9,
      "y": 12,
      "z": -9,
      "name": "Wood_Gumboab_Trunk_Full"
    },
    {
      "x": -9,
      "y": 13,
      "z": -9,
      "name": "Wood_Gumboab_Trunk_Full"
    },
    {
      "x": -9,
      "y": 30,
      "z": -9,
      "name": "Plant_Leaves_Beech_Max_Support"
    },
    {
      "x": -9,
      "y": 31,
      "z": -9,
      "name": "Plant_Leaves_Beech_Max_Support"
    },
    {
      "x": -9,
      "y": 32,
      "z": -9,
      "name": "Plant_Leaves_Beech_Max_Support"
    },
    {
      "x": -9,
      "y": 33,
      "z": -9,
      "name": "Plant_Leaves_Beech_Max_Support"
    },
    {
      "x": -9,
      "y": 34,
      "z": -9,
      "name": "Plant_Leaves_Beech_Max_Support"
    },
    {
      "x": -9,
      "y": 35,
      "z": -9,
      "name": "Plant_Leaves_Beech_Max_Support"
    },
    {
      "x": -9,
      "y": 36,
      "z": -9,
      "name": "Plant_Leaves_Beech_Max_Support"
    },
    {
      "x": -9,
      "y": 4,
      "z": -8,
      "name": "Wood_Gumboab_Roots"
    },
    {
      "x": -9,
      "y": 5,
      "z": -8,
      "name": "Wood_Gumboab_Trunk_Full"
    },
    {
      "x": -9,
      "y": 6,
      "z": -8,
      "name": "Wood_Gumboab_Trunk_Full"
    },
    {
      "x": -9,
      "y": 7,
      "z": -8,
      "name": "Wood_Gumboab_Trunk_Full"
    },
    {
      "x": -9,
      "y": 12,
      "z": -8,
