{
  "version": 8,
  "blockIdVersion": 11,
  "anchorX": 8,
  "anchorY": 10,
  "anchorZ": 2,
  "blocks": [
    {
      "x": -21,
      "y": 50,
      "z": 0,
      "name": "Plant_Leaves_Beech_Max_Support",
      "support": 15
    },
    {
      "x": -21,
      "y": 50,
      "z": 1,
      "name": "Plant_Leaves_Beech_Max_Support",
      "support": 15
    },
    {
      "x": -21,
      "y": 51,
      "z": 1,
      "name": "Plant_Leaves_Beech_Max_Support"
    },
    {
      "x": -21,
      "y": 52,
      "z": 1,
      "name": "Plant_Leaves_Beech_Max_Support"
    },
    {
      "x": -21,
      "y": 50,
      "z": 2,
      "name": "Plant_Leaves_Beech_Max_Support",
      "support": 15
    },
    {
      "x": -21,
      "y": 52,
      "z": 2,
      "name": "Plant_Leaves_Beech_Max_Support"
    },
    {
      "x": -20,
      "y": 50,
      "z": -1,
      "name": "Plant_Leaves_Beech_Max_Support",
      "support": 15
    },
    {
      "x": -20,
      "y": 51,
      "z": -1,
      "name": "Plant_Leaves_Beech_Max_Support"
    },
    {
      "x": -20,
      "y": 53,
      "z": -1,
      "name": "Plant_Leaves_Beech_Max_Support"
    },
    {
      "x": -20,
      "y": 50,
      "z": 0,
      "name": "Plant_Leaves_Beech_Max_Support"
    },
    {
      "x": -20,
      "y": 51,
      "z": 0,
      "name": "Plant_Leaves_Beech_Max_Support"
    },
    {
      "x": -20,
      "y": 53,
      "z": 0,
      "name": "Plant_Leaves_Beech_Max_Support"
    },
    {
      "x": -20,
      "y": 50,
      "z": 1,
      "name": "Plant_Leaves_Beech_Max_Support"
    },
    {
      "x": -20,
      "y": 51,
      "z": 1,
      "name": "Plant_Leaves_Beech_Max_Support"
    },
    {
      "x": -20,
      "y": 53,
      "z": 1,
      "name": "Plant_Leaves_Beech_Max_Support"
    },
    {
      "x": -20,
      "y": 54,
      "z": 1,
      "name": "Plant_Leaves_Beech_Max_Support"
    },
    {
      "x": -20,
      "y": 50,
      "z": 2,
      "name": "Plant_Leaves_Beech_Max_Support"
    },
    {
      "x": -20,
      "y": 51,
      "z": 2,
      "name": "Plant_Leaves_Beech_Max_Support"
    },
    {
      "x": -20,
      "y": 54,
      "z": 2,
      "name": "Plant_Leaves_Beech_Max_Support"
    },
    {
      "x": -20,
      "y": 51,
      "z": 3,
      "name": "Plant_Leaves_Beech_Max_Support"
    },
    {
      "x": -19,
      "y": 50,
      "z": -2,
      "name": "Plant_Leaves_Beech_Max_Support",
      "support": 15
    },
    {
      "x": -19,
      "y": 51,
      "z": -2,
      "name": "Plant_Leaves_Beech_Max_Support"
    },
    {
      "x": -19,
      "y": 50,
      "z": -1,
      "name": "Plant_Leaves_Beech_Max_Support",
      "support": 15
    },
    {
      "x": -19,
      "y": 51,
      "z": -1,
      "name": "Plant_Leaves_Beech_Max_Support"
    },
    {
      "x": -19,
      "y": 52,
      "z": -1,
      "name": "Plant_Leaves_Beech_Max_Support"
    },
    {
      "x": -19,
      "y": 53,
      "z": -1,
      "name": "Plant_Leaves_Beech_Max_Support"
    },
    {
      "x": -19,
      "y": 49,
      "z": 0,
      "name": "Plant_Leaves_Beech_Max_Support"
    },
    {
      "x": -19,
      "y": 51,
      "z": 0,
      "name": "Plant_Leaves_Beech_Max_Support"
    },
    {
      "x": -19,
      "y": 54,
      "z": 0,
      "name": "Plant_Leaves_Beech_Max_Support"
    },
    {
      "x": -19,
      "y": 55,
      "z": 0,
      "name": "Plant_Leaves_Beech_Max_Support"
    },
    {
      "x": -19,
      "y": 49,
      "z": 1,
      "name": "Plant_Leaves_Beech_Max_Support"
    },
    {
      "x": -19,
      "y": 52,
      "z": 1,
      "name": "Plant_Leaves_Beech_Max_Support"
    },
    {
      "x": -19,
      "y": 53,
      "z": 1,
      "name": "Plant_Leaves_Beech_Max_Support"
    },
    {
      "x": -19,
      "y": 54,
      "z": 1,
      "name": "Plant_Leaves_Beech_Max_Support"
    },
    {
      "x": -19,
      "y": 55,
      "z": 1,
      "name": "Plant_Leaves_Beech_Max_Support"
    },
    {
      "x": -19,
      "y": 49,
      "z": 2,
      "name": "Plant_Leaves_Beech_Max_Support"
    },
    {
      "x": -19,
      "y": 53,
      "z": 2,
      "name": "Plant_Leaves_Beech_Max_Support"
    },
    {
      "x": -19,
      "y": 54,
      "z": 2,
      "name": "Plant_Leaves_Beech_Max_Support"
    },
    {
      "x": -19,
      "y": 55,
      "z": 2,
      "name": "Plant_Leaves_Beech_Max_Support"
    },
    {
      "x": -19,
      "y": 50,
      "z": 3,
      "name": "Plant_Leaves_Beech_Max_Support",
      "support": 15
    },
    {
      "x": -19,
      "y": 51,
      "z": 3,
      "name": "Plant_Leaves_Beech_Max_Support"
    },
    {
      "x": -19,
      "y": 52,
      "z": 3,
      "name": "Plant_Leaves_Beech_Max_Support"
    },
    {
      "x": -19,
      "y": 53,
      "z": 3,
      "name": "Plant_Leaves_Beech_Max_Support"
    },
    {
      "x": -19,
      "y": 54,
      "z": 3,
      "name": "Plant_Leaves_Beech_Max_Support"
    },
    {
      "x": -19,
      "y": 55,
      "z": 3,
      "name": "Plant_Leaves_Beech_Max_Support"
    },
    {
      "x": -19,
      "y": 50,
      "z": 4,
      "name": "Plant_Leaves_Beech_Max_Support",
      "support": 15
    },
    {
      "x": -19,
      "y": 52,
      "z": 4,
      "name": "Plant_Leaves_Beech_Max_Support"
    },
    {
      "x": -19,
      "y": 53,
      "z": 4,
      "name": "Plant_Leaves_Beech_Max_Support"
    },
    {
      "x": -18,
      "y": 50,
      "z": -2,
      "name": "Plant_Leaves_Beech_Max_Support",
      "support": 15
    },
    {
      "x": -18,
      "y": 52,
      "z": -2,
      "name": "Plant_Leaves_Beech_Max_Support"
    },
    {
      "x": -18,
      "y": 53,
      "z": -2,
      "name": "Plant_Leaves_Beech_Max_Support"
    },
    {
      "x": -18,
      "y": 50,
      "z": -1,
      "name": "Plant_Leaves_Beech_Max_Support"
    },
    {
      "x": -18,
      "y": 52,
      "z": -1,
      "name": "Plant_Leaves_Beech_Max_Support"
    },
    {
      "x": -18,
      "y": 53,
      "z": -1,
      "name": "Plant_Leaves_Beech_Max_Support"
    },
    {
      "x": -18,
      "y": 49,
      "z": 0,
      "name": "Plant_Leaves_Beech_Max_Support",
      "support": 15
    },
    {
      "x": -18,
      "y": 53,
      "z": 0,
      "name": "Plant_Leaves_Beech_Max_Support"
    },
    {
      "x": -18,
      "y": 54,
      "z": 0,
      "name": "Plant_Leaves_Beech_Max_Support"
    },
    {
      "x": -18,
      "y": 55,
      "z": 0,
      "name": "Plant_Leaves_Beech_Max_Support"
    },
    {
      "x": -18,
      "y": 49,
      "z": 1,
      "name": "Plant_Leaves_Beech_Max_Support"
    },
    {
      "x": -18,
      "y": 51,
      "z": 1,
      "name": "Plant_Leaves_Beech_Max_Support"
    },
    {
      "x": -18,
      "y": 52,
      "z": 1,
      "name": "Plant_Leaves_Beech_Max_Support"
    },
    {
      "x": -18,
      "y": 53,
      "z": 1,
      "name": "Plant_Leaves_Beech_Max_Support"
    },
    {
      "x": -18,
      "y": 54,
      "z": 1,
      "name": "Plant_Leaves_Beech_Max_Support"
    },
    {
      "x": -18,
      "y": 55,
      "z": 1,
      "name": "Plant_Leaves_Beech_Max_Support"
    },
    {
      "x": -18,
      "y": 50,
      "z": 2,
      "name": "Plant_Leaves_Beech_Max_Support"
    },
    {
      "x": -18,
      "y": 51,
      "z": 2,
      "name": "Plant_Leaves_Beech_Max_Support"
    },
    {
      "x": -18,
      "y": 53,
      "z": 2,
      "name": "Plant_Leaves_Beech_Max_Support"
    },
    {
      "x": -18,
      "y": 54,
      "z": 2,
      "name": "Plant_Leaves_Beech_Max_Support"
    },
    {
      "x": -18,
      "y": 55,
      "z": 2,
      "name": "Plant_Leaves_Beech_Max_Support"
    },
    {
      "x": -18,
      "y": 50,
      "z": 3,
      "name": "Plant_Leaves_Beech_Max_Support"
    },
    {
      "x": -18,
      "y": 51,
      "z": 3,
      "name": "Plant_Leaves_Beech_Max_Support"
    },
    {
      "x": -18,
      "y": 52,
      "z": 3,
      "name": "Plant_Leaves_Beech_Max_Support"
    },
    {
      "x": -18,
      "y": 53,
      "z": 3,
      "name": "Plant_Leaves_Beech_Max_Support"
    },
    {
      "x": -18,
      "y": 55,
      "z": 3,
      "name": "Plant_Leaves_Beech_Max_Support"
    },
    {
      "x": -18,
      "y": 56,
      "z": 3,
      "name": "Plant_Leaves_Beech_Max_Support"
    },
    {
      "x": -18,
      "y": 51,
      "z": 4,
      "name": "Plant_Leaves_Beech_Max_Support",
      "support": 15
    },
    {
      "x": -18,
      "y": 53,
      "z": 4,
      "name": "Plant_Leaves_Beech_Max_Support"
    },
    {
      "x": -18,
      "y": 54,
      "z": 4,
      "name": "Plant_Leaves_Beech_Max_Support"
    },
    {
      "x": -18,
      "y": 55,
      "z": 4,
      "name": "Plant_Leaves_Beech_Max_Support"
    },
    {
      "x": -18,
      "y": 50,
      "z": 5,
      "name": "Plant_Leaves_Beech_Max_Support",
      "support": 15
    },
    {
      "x": -17,
      "y": 50,
      "z": -6,
      "name": "Plant_Leaves_Beech_Max_Support"
    },
    {
      "x": -17,
      "y": 51,
      "z": -6,
      "name": "Plant_Leaves_Beech_Max_Support"
    },
    {
      "x": -17,
      "y": 52,
      "z": -6,
      "name": "Plant_Leaves_Beech_Max_Support"
    },
    {
      "x": -17,
      "y": 49,
      "z": -5,
      "name": "Plant_Leaves_Beech_Max_Support",
      "support": 15
    },
    {
      "x": -17,
      "y": 50,
      "z": -5,
      "name": "Plant_Leaves_Beech_Max_Support"
    },
    {
      "x": -17,
      "y": 51,
      "z": -5,
      "name": "Plant_Leaves_Beech_Max_Support"
    },
    {
      "x": -17,
      "y": 52,
      "z": -5,
      "name": "Plant_Leaves_Beech_Max_Support"
    },
    {
      "x": -17,
      "y": 49,
      "z": -4,
      "name": "Plant_Leaves_Beech_Max_Support",
      "support": 15
    },
    {
      "x": -17,
      "y": 51,
      "z": -4,
      "name": "Plant_Leaves_Beech_Max_Support"
    },
    {
      "x": -17,
      "y": 51,
      "z": -2,
      "name": "Plant_Leaves_Beech_Max_Support"
    },
    {
      "x": -17,
      "y": 52,
      "z": -2,
      "name": "Plant_Leaves_Beech_Max_Support"
    },
    {
      "x": -17,
      "y": 53,
      "z": -2,
      "name": "Plant_Leaves_Beech_Max_Support"
    },
    {
      "x": -17,
      "y": 50,
      "z": -1,
      "name": "Plant_Leaves_Beech_Max_Support"
    },
    {
      "x": -17,
      "y": 51,
      "z": -1,
      "name": "Plant_Leaves_Beech_Max_Support"
    },
    {
      "x": -17,
      "y": 52,
      "z": -1,
      "name": "Plant_Leaves_Beech_Max_Support"
    },
    {
      "x": -17,
      "y": 53,
      "z": -1,
      "name": "Plant_Leaves_Beech_Max_Support"
    },
    {
      "x": -17,
      "y": 54,
      "z": -1,
      "name": "Plant_Leaves_Beech_Max_Support"
    },
    {
      "x": -17,
      "y": 55,
      "z": -1,
      "name": "Plant_Leaves_Beech_Max_Support"
    },
    {
      "x": -17,
      "y": 49,
      "z": 0,
      "name": "Plant_Leaves_Beech_Max_Support"
    },
    {
      "x": -17,
      "y": 50,
      "z": 0,
      "name": "Plant_Leaves_Beech_Max_Support"
    },
    {
      "x": -17,
      "y": 51,
      "z": 0,
      "name": "Plant_Leaves_Beech_Max_Support"
    },
    {
      "x": -17,
      "y": 52,
      "z": 0,
      "name": "Plant_Leaves_Beech_Max_Support"
    },
    {
      "x": -17,
      "y": 54,
      "z": 0,
      "name": "Plant_Leaves_Beech_Max_Support"
    },
    {
      "x": -17,
      "y": 55,
      "z": 0,
      "name": "Plant_Leaves_Beech_Max_Support"
    },
    {
      "x": -17,
      "y": 56,
      "z": 0,
      "name": "Plant_Leaves_Beech_Max_Support"
    },
    {
      "x": -17,
      "y": 49,
      "z": 1,
      "name": "Plant_Leaves_Beech_Max_Support"
    },
    {
      "x": -17,
      "y": 50,
      "z": 1,
      "name": "Plant_Leaves_Beech_Max_Support"
    },
    {
      "x": -17,
      "y": 51,
      "z": 1,
      "name": "Plant_Leaves_Beech_Max_Support"
    },
    {
      "x": -17,
      "y": 52,
      "z": 1,
      "name": "Plant_Leaves_Beech_Max_Support"
    },
    {
      "x": -17,
      "y": 53,
      "z": 1,
      "name": "Plant_Leaves_Beech_Max_Support"
    },
    {
      "x": -17,
      "y": 54,
      "z": 1,
      "name": "Plant_Leaves_Beech_Max_Support"
    },
    {
      "x": -17,
      "y": 55,
      "z": 1,
      "name": "Plant_Leaves_Beech_Max_Support"
    },
    {
      "x": -17,
      "y": 56,
      "z": 1,
      "name": "Plant_Leaves_Beech_Max_Support"
    },
    {
      "x": -17,
      "y": 51,
      "z": 2,
      "name": "Plant_Leaves_Beech_Max_Support"
    },
    {
      "x": -17,
      "y": 53,
      "z": 2,
      "name": "Plant_Leaves_Beech_Max_Support"
    },
    {
      "x": -17,
      "y": 54,
      "z": 2,
      "name": "Plant_Leaves_Beech_Max_Support"
    },
    {
      "x": -17,
      "y": 55,
      "z": 2,
      "name": "Plant_Leaves_Beech_Max_Support"
    },
    {
      "x": -17,
      "y": 56,
      "z": 2,
      "name": "Plant_Leaves_Beech_Max_Support"
    },
    {
      "x": -17,
      "y": 57,
      "z": 2,
      "name": "Plant_Leaves_Beech_Max_Support"
    },
    {
      "x": -17,
      "y": 50,
      "z": 3,
      "name": "Plant_Leaves_Beech_Max_Support"
    },
    {
      "x": -17,
      "y": 51,
      "z": 3,
      "name": "Plant_Leaves_Beech_Max_Support"
    },
    {
      "x": -17,
      "y": 52,
      "z": 3,
      "name": "Plant_Leaves_Beech_Max_Support"
    },
    {
      "x": -17,
      "y": 53,
      "z": 3,
      "name": "Plant_Leaves_Beech_Max_Support"
    },
    {
      "x": -17,
      "y": 54,
      "z": 3,
      "name": "Plant_Leaves_Beech_Max_Support"
    },
    {
      "x": -17,
      "y": 50,
      "z": 4,
      "name": "Plant_Leaves_Beech_Max_Support",
      "support": 15
    },
    {
      "x": -17,
      "y": 51,
      "z": 4,
      "name": "Plant_Leaves_Beech_Max_Support",
      "support": 15
    },
    {
      "x": -17,
      "y": 52,
      "z": 4,
      "name": "Plant_Leaves_Beech_Max_Support"
    },
    {
      "x": -17,
      "y": 53,
      "z": 4,
      "name": "Plant_Leaves_Beech_Max_Support"
    },
    {
      "x": -17,
      "y": 54,
      "z": 4,
      "name": "Plant_Leaves_Beech_Max_Support"
    },
    {
      "x": -17,
      "y": 50,
      "z": 5,
      "name": "Plant_Leaves_Beech_Max_Support",
      "support": 15
    },
    {
      "x": -17,
      "y": 51,
      "z": 5,
      "name": "Plant_Leaves_Beech_Max_Support",
      "support": 15
    },
    {
      "x": -17,
      "y": 53,
      "z": 5,
      "name": "Plant_Leaves_Beech_Max_Support"
    },
    {
      "x": -16,
      "y": 50,
      "z": -7,
      "name": "Plant_Leaves_Beech_Max_Support"
    },
    {
      "x": -16,
      "y": 49,
      "z": -6,
      "name": "Plant_Leaves_Beech_Max_Support"
    },
    {
      "x": -16,
      "y": 50,
      "z": -6,
      "name": "Plant_Leaves_Beech_Max_Support"
    },
    {
      "x": -16,
      "y": 51,
      "z": -6,
      "name": "Plant_Leaves_Beech_Max_Support"
    },
    {
      "x": -16,
      "y": 52,
      "z": -6,
      "name": "Plant_Leaves_Beech_Max_Support"
    },
    {
      "x": -16,
      "y": 48,
      "z": -5,
      "name": "Plant_Leaves_Beech_Max_Support",
      "support": 15
    },
    {
      "x": -16,
      "y": 49,
      "z": -5,
      "name": "Plant_Leaves_Beech_Max_Support",
      "support": 15
    },
    {
      "x": -16,
      "y": 50,
      "z": -5,
      "name": "Plant_Leaves_Beech_Max_Support"
    },
    {
      "x": -16,
      "y": 52,
      "z": -5,
      "name": "Plant_Leaves_Beech_Max_Support"
    },
    {
      "x": -16,
      "y": 53,
      "z": -5,
      "name": "Plant_Leaves_Beech_Max_Support"
    },
    {
      "x": -16,
      "y": 49,
      "z": -4,
      "name": "Plant_Leaves_Beech_Max_Support"
    },
    {
      "x": -16,
      "y": 50,
      "z": -4,
      "name": "Plant_Leaves_Beech_Max_Support"
    },
    {
      "x": -16,
      "y": 51,
      "z": -4,
      "name": "Plant_Leaves_Beech_Max_Support"
    },
    {
      "x": -16,
      "y": 52,
      "z": -4,
      "name": "Plant_Leaves_Beech_Max_Support"
    },
    {
      "x": -16,
      "y": 53,
      "z": -4,
      "name": "Plant_Leaves_Beech_Max_Support"
    },
    {
      "x": -16,
      "y": 50,
      "z": -3,
      "name": "Plant_Leaves_Beech_Max_Support"
    },
    {
      "x": -16,
      "y": 51,
      "z": -3,
      "name": "Plant_Leaves_Beech_Max_Support"
    },
    {
      "x": -16,
      "y": 52,
      "z": -3,
      "name": "Plant_Leaves_Beech_Max_Support"
    },
    {
      "x": -16,
      "y": 51,
      "z": -2,
      "name": "Plant_Leaves_Beech_Max_Support"
    },
    {
      "x": -16,
      "y": 52,
      "z": -2,
      "name": "Plant_Leaves_Beech_Max_Support"
    },
    {
      "x": -16,
      "y": 53,
      "z": -2,
      "name": "Plant_Leaves_Beech_Max_Support"
    },
    {
      "x": -16,
      "y": 54,
      "z": -2,
      "name": "Plant_Leaves_Beech_Max_Support"
    },
    {
      "x": -16,
      "y": 51,
      "z": -1,
      "name": "Plant_Leaves_Beech_Max_Support"
    },
    {
      "x": -16,
      "y": 52,
      "z": -1,
      "name": "Plant_Leaves_Beech_Max_Support"
    },
    {
      "x": -16,
      "y": 53,
      "z": -1,
      "name": "Plant_Leaves_Beech_Max_Support"
    },
    {
      "x": -16,
      "y": 54,
      "z": -1,
      "name": "Plant_Leaves_Beech_Max_Support"
    },
    {
      "x": -16,
      "y": 55,
      "z": -1,
      "name": "Plant_Leaves_Beech_Max_Support"
    },
    {
      "x": -16,
      "y": 50,
      "z": 0,
      "name": "Plant_Leaves_Beech_Max_Support"
    },
    {
      "x": -16,
      "y": 51,
      "z": 0,
      "name": "Plant_Leaves_Beech_Max_Support"
    },
    {
      "x": -16,
      "y": 52,
      "z": 0,
      "name": "Plant_Leaves_Beech_Max_Support"
    },
    {
      "x": -16,
      "y": 53,
      "z": 0,
      "name": "Plant_Leaves_Beech_Max_Support"
    },
    {
      "x": -16,
      "y": 54,
      "z": 0,
      "name": "Plant_Leaves_Beech_Max_Support"
    },
    {
      "x": -16,
      "y": 55,
      "z": 0,
      "name": "Plant_Leaves_Beech_Max_Support"
    },
    {
      "x": -16,
      "y": 56,
      "z": 0,
      "name": "Plant_Leaves_Beech_Max_Support"
    },
    {
      "x": -16,
      "y": 48,
      "z": 1,
      "name": "Wood_Gumboab_Roots"
    },
    {
      "x": -16,
      "y": 49,
      "z": 1,
      "name": "Wood_Gumboab_Trunk_Full"
    },
    {
      "x": -16,
      "y": 50,
      "z": 1,
      "name": "Wood_Gumboab_Trunk_Full"
    },
    {
      "x": -16,
      "y": 51,
      "z": 1,
      "name": "Plant_Leaves_Beech_Max_Support"
    },
    {
      "x": -16,
      "y": 52,
      "z": 1,
      "name": "Plant_Leaves_Beech_Max_Support"
    },
    {
      "x": -16,
      "y": 53,
      "z": 1,
      "name": "Plant_Leaves_Beech_Max_Support"
    },
    {
      "x": -16,
      "y": 54,
      "z": 1,
      "name": "Plant_Leaves_Beech_Max_Support"
    },
    {
      "x": -16,
      "y": 55,
      "z": 1,
      "name": "Plant_Leaves_Beech_Max_Support"
    },
    {
      "x": -16,
      "y": 50,
      "z": 2,
      "name": "Wood_Gumboab_Trunk_Full"
    },
    {
      "x": -16,
      "y": 51,
      "z": 2,
      "name": "Plant_Leaves_Beech_Max_Support"
    },
    {
      "x": -16,
      "y": 52,
      "z": 2,
      "name": "Plant_Leaves_Beech_Max_Support"
    },
    {
      "x": -16,
      "y": 53,
      "z": 2,
      "name": "Plant_Leaves_Beech_Max_Support"
    },
    {
      "x": -16,
      "y": 54,
      "z": 2,
      "name": "Plant_Leaves_Beech_Max_Support"
    },
    {
      "x": -16,
      "y": 55,
      "z": 2,
      "name": "Plant_Leaves_Beech_Max_Support"
    },
    {
      "x": -16,
      "y": 56,
      "z": 2,
      "name": "Plant_Leaves_Beech_Max_Support"
    },
    {
      "x": -16,
      "y": 57,
      "z": 2,
      "name": "Plant_Leaves_Beech_Max_Support"
    },
    {
      "x": -16,
      "y": 51,
      "z": 3,
      "name": "Plant_Leaves_Beech_Max_Support"
    },
    {
      "x": -16,
      "y": 52,
      "z": 3,
      "name": "Plant_Leaves_Beech_Max_Support"
    },
    {
      "x": -16,
      "y": 53,
      "z": 3,
      "name": "Plant_Leaves_Beech_Max_Support"
    },
    {
      "x": -16,
      "y": 57,
      "z": 3,
      "name": "Plant_Leaves_Beech_Max_Support"
    },
    {
      "x": -16,
      "y": 50,
      "z": 4,
      "name": "Plant_Leaves_Beech_Max_Support"
    },
    {
      "x": -16,
      "y": 53,
      "z": 4,
      "name": "Plant_Leaves_Beech_Max_Support"
    },
    {
      "x": -16,
      "y": 54,
      "z": 4,
      "name": "Plant_Leaves_Beech_Max_Support"
    },
    {
      "x": -16,
      "y": 55,
      "z": 4,
      "name": "Plant_Leaves_Beech_Max_Support"
    },
    {
      "x": -16,
      "y": 51,
      "z": 5,
      "name": "Plant_Leaves_Beech_Max_Support"
    },
    {
      "x": -16,
      "y": 52,
      "z": 5,
      "name": "Plant_Leaves_Beech_Max_Support"
    },
    {
      "x": -16,
      "y": 53,
      "z": 5,
      "name": "Plant_Leaves_Beech_Max_Support"
    },
    {
      "x": -16,
      "y": 54,
      "z": 5,
      "name": "Plant_Leaves_Beech_Max_Support"
    },
    {
      "x": -15,
      "y": 50,
      "z": -8,
      "name": "Plant_Leaves_Beech_Max_Support"
    },
    {
      "x": -15,
      "y": 52,
      "z": -8,
      "name": "Plant_Leaves_Beech_Max_Support"
    },
    {
      "x": -15,
      "y": 51,
      "z": -7,
      "name": "Plant_Leaves_Beech_Max_Support"
    },
    {
      "x": -15,
      "y": 53,
      "z": -7,
      "name": "Plant_Leaves_Beech_Max_Support"
    },
    {
      "x": -15,
      "y": 48,
      "z": -6,
      "name": "Plant_Leaves_Beech_Max_Support",
      "support": 15
    },
    {
      "x": -15,
      "y": 49,
      "z": -6,
      "name": "Plant_Leaves_Beech_Max_Support"
    },
    {
      "x": -15,
      "y": 50,
      "z": -6,
      "name": "Plant_Leaves_Beech_Max_Support"
    },
    {
      "x": -15,
      "y": 53,
      "z": -6,
      "name": "Plant_Leaves_Beech_Max_Support"
    },
    {
      "x": -15,
      "y": 48,
      "z": -5,
      "name": "Plant_Leaves_Beech_Max_Support"
    },
    {
      "x": -15,
      "y": 49,
      "z": -5,
      "name": "Plant_Leaves_Beech_Max_Support"
    },
    {
      "x": -15,
      "y": 50,
      "z": -5,
      "name": "Plant_Leaves_Beech_Max_Support"
    },
    {
      "x": -15,
      "y": 51,
      "z": -5,
      "name": "Plant_Leaves_Beech_Max_Support"
    },
    {
      "x": -15,
      "y": 51,
      "z": -4,
      "name": "Plant_Leaves_Beech_Max_Support"
    },
    {
      "x": -15,
      "y": 52,
      "z": -4,
      "name": "Plant_Leaves_Beech_Max_Support"
    },
    {
      "x": -15,
      "y": 54,
      "z": -4,
      "name": "Plant_Leaves_Beech_Max_Support"
    },
    {
      "x": -15,
      "y": 49,
      "z": -3,
      "name": "Plant_Leaves_Beech_Max_Support"
    },
    {
      "x": -15,
      "y": 51,
      "z": -3,
      "name": "Plant_Leaves_Beech_Max_Support"
    },
    {
      "x": -15,
      "y": 52,
      "z": -3,
      "name": "Plant_Leaves_Beech_Max_Support"
    },
    {
      "x": -15,
      "y": 53,
      "z": -3,
      "name": "Plant_Leaves_Beech_Max_Support"
    },
    {
      "x": -15,
      "y": 54,
      "z": -3,
      "name": "Plant_Leaves_Beech_Max_Support"
    },
    {
      "x": -15,
      "y": 50,
      "z": -2,
      "name": "Plant_Leaves_Beech_Max_Support"
    },
    {
      "x": -15,
      "y": 51,
      "z": -2,
      "name": "Plant_Leaves_Beech_Max_Support"
    },
    {
      "x": -15,
      "y": 52,
      "z": -2,
      "name": "Plant_Leaves_Beech_Max_Support"
    },
    {
      "x": -15,
      "y": 53,
      "z": -2,
      "name": "Plant_Leaves_Beech_Max_Support"
    },
    {
      "x": -15,
      "y": 54,
      "z": -2,
      "name": "Plant_Leaves_Beech_Max_Support"
    },
    {
      "x": -15,
      "y": 55,
      "z": -2,
      "name": "Plant_Leaves_Beech_Max_Support"
    },
    {
      "x": -15,
      "y": 49,
      "z": -1,
      "name": "Plant_Leaves_Beech_Max_Support",
      "support": 15
    },
    {
      "x": -15,
      "y": 50,
      "z": -1,
      "name": "Plant_Leaves_Beech_Max_Support"
    },
    {
      "x": -15,
      "y": 51,
      "z": -1,
      "name": "Plant_Leaves_Beech_Max_Support"
    },
    {
      "x": -15,
      "y": 52,
      "z": -1,
      "name": "Plant_Leaves_Beech_Max_Support"
    },
    {
      "x": -15,
      "y": 53,
      "z": -1,
      "name": "Plant_Leaves_Beech_Max_Support"
    },
    {
      "x": -15,
      "y": 54,
      "z": -1,
      "name": "Plant_Leaves_Beech_Max_Support"
    },
    {
      "x": -15,
      "y": 56,
      "z": -1,
      "name": "Plant_Leaves_Beech_Max_Support"
    },
    {
      "x": -15,
      "y": 49,
      "z": 0,
      "name": "Wood_Gumboab_Trunk_Full"
    },
    {
      "x": -15,
      "y": 51,
      "z": 0,
      "name": "Plant_Leaves_Beech_Max_Support"
    },
    {
      "x": -15,
      "y": 52,
      "z": 0,
      "name": "Plant_Leaves_Beech_Max_Support"
    },
    {
      "x": -15,
      "y": 53,
      "z": 0,
      "name": "Plant_Leaves_Beech_Max_Support"
    },
    {
      "x": -15,
      "y": 55,
      "z": 0,
      "name": "Plant_Leaves_Beech_Max_Support"
    },
    {
      "x": -15,
      "y": 56,
      "z": 0,
      "name": "Plant_Leaves_Beech_Max_Support"
    },
    {
      "x": -15,
      "y": 49,
      "z": 1,
      "name": "Wood_Gumboab_Trunk_Full"
    },
    {
      "x": -15,
      "y": 50,
      "z": 1,
      "name": "Wood_Gumboab_Trunk_Full"
    },
    {
      "x": -15,
      "y": 51,
      "z": 1,
      "name": "Plant_Leaves_Beech_Max_Support"
    },
    {
      "x": -15,
      "y": 52,
      "z": 1,
      "name": "Plant_Leaves_Beech_Max_Support"
    },
    {
      "x": -15,
      "y": 53,
      "z": 1,
      "name": "Plant_Leaves_Beech_Max_Support"
    },
    {
      "x": -15,
      "y": 54,
      "z": 1,
      "name": "Plant_Leaves_Beech_Max_Support"
    },
    {
      "x": -15,
      "y": 56,
      "z": 1,
      "name": "Plant_Leaves_Beech_Max_Support"
    },
    {
      "x": -15,
      "y": 29,
      "z": 2,
      "name": "Plant_Vine_Jungle",
      "support": 15
    },
    {
      "x": -15,
      "y": 30,
      "z": 2,
      "name": "Plant_Vine_Jungle",
      "support": 15
    },
    {
      "x": -15,
      "y": 31,
      "z": 2,
      "name": "Plant_Vine_Jungle",
      "support": 15
    },
    {
      "x": -15,
      "y": 32,
      "z": 2,
      "name": "Plant_Vine_Jungle",
      "support": 15
    },
    {
      "x": -15,
      "y": 33,
      "z": 2,
      "name": "Plant_Vine_Jungle",
      "support": 15
    },
    {
      "x": -15,
      "y": 34,
      "z": 2,
      "name": "Plant_Vine_Jungle",
      "support": 15
    },
    {
      "x": -15,
      "y": 35,
      "z": 2,
      "name": "Plant_Vine_Jungle",
      "support": 15
    },
    {
      "x": -15,
      "y": 36,
      "z": 2,
      "name": "Plant_Vine_Jungle",
      "support": 15
    },
    {
      "x": -15,
      "y": 37,
      "z": 2,
      "name": "Plant_Vine_Jungle",
      "support": 15
    },
    {
      "x": -15,
      "y": 38,
      "z": 2,
      "name": "Plant_Vine_Jungle",
      "support": 15
    },
    {
      "x": -15,
      "y": 39,
      "z": 2,
      "name": "Plant_Vine_Jungle",
      "support": 15
    },
    {
      "x": -15,
      "y": 40,
      "z": 2,
      "name": "Plant_Vine_Jungle",
      "support": 15
    },
    {
      "x": -15,
      "y": 41,
      "z": 2,
      "name": "Plant_Vine_Jungle",
      "support": 15
    },
    {
      "x": -15,
      "y": 42,
      "z": 2,
      "name": "Plant_Vine_Jungle",
      "support": 15
    },
    {
      "x": -15,
      "y": 43,
      "z": 2,
      "name": "Plant_Vine_Jungle",
      "support": 15
    },
    {
      "x": -15,
      "y": 44,
      "z": 2,
      "name": "Plant_Vine_Jungle",
      "support": 15
    },
    {
      "x": -15,
      "y": 45,
      "z": 2,
      "name": "Plant_Vine_Jungle",
      "support": 15
    },
    {
      "x": -15,
      "y": 46,
      "z": 2,
      "name": "Plant_Vine_Jungle",
      "support": 15
    },
    {
      "x": -15,
      "y": 47,
      "z": 2,
      "name": "Plant_Vine_Jungle",
      "support": 15
    },
    {
      "x": -15,
      "y": 48,
      "z": 2,
      "name": "Plant_Vine_Jungle",
      "support": 15
    },
    {
      "x": -15,
      "y": 49,
      "z": 2,
      "name": "Plant_Vine_Jungle",
      "support": 15
    },
    {
      "x": -15,
      "y": 51,
      "z": 2,
      "name": "Plant_Leaves_Beech_Max_Support"
    },
    {
      "x": -15,
      "y": 52,
      "z": 2,
      "name": "Plant_Leaves_Beech_Max_Support"
    },
    {
      "x": -15,
      "y": 53,
      "z": 2,
      "name": "Plant_Leaves_Beech_Max_Support"
    },
    {
      "x": -15,
      "y": 54,
      "z": 2,
      "name": "Plant_Leaves_Beech_Max_Support"
    },
    {
      "x": -15,
      "y": 55,
      "z": 2,
      "name": "Plant_Leaves_Beech_Max_Support"
    },
    {
      "x": -15,
      "y": 49,
      "z": 3,
      "name": "Plant_Leaves_Beech_Max_Support"
    },
    {
      "x": -15,
      "y": 50,
      "z": 3,
      "name": "Plant_Leaves_Beech_Max_Support"
    },
    {
      "x": -15,
      "y": 51,
      "z": 3,
      "name": "Plant_Leaves_Beech_Max_Support"
    },
    {
      "x": -15,
      "y": 53,
      "z": 3,
      "name": "Plant_Leaves_Beech_Max_Support"
    },
    {
      "x": -15,
      "y": 54,
      "z": 3,
      "name": "Plant_Leaves_Beech_Max_Support"
    },
    {
      "x": -15,
      "y": 55,
      "z": 3,
      "name": "Plant_Leaves_Beech_Max_Support"
    },
    {
      "x": -15,
      "y": 56,
      "z": 3,
      "name": "Plant_Leaves_Beech_Max_Support"
    },
    {
      "x": -15,
      "y": 57,
      "z": 3,
      "name": "Plant_Leaves_Beech_Max_Support"
    },
    {
      "x": -15,
      "y": 52,
      "z": 4,
      "name": "Plant_Leaves_Beech_Max_Support"
    },
    {
      "x": -15,
      "y": 53,
      "z": 4,
      "name": "Plant_Leaves_Beech_Max_Support"
    },
    {
      "x": -15,
      "y": 54,
      "z": 4,
      "name": "Plant_Leaves_Beech_Max_Support"
    },
    {
      "x": -15,
      "y": 55,
      "z": 4,
      "name": "Plant_Leaves_Beech_Max_Support"
    },
    {
      "x": -15,
      "y": 56,
      "z": 4,
      "name": "Plant_Leaves_Beech_Max_Support"
    },
    {
      "x": -15,
      "y": 50,
      "z": 5,
      "name": "Plant_Leaves_Beech_Max_Support"
    },
    {
      "x": -15,
      "y": 52,
      "z": 5,
      "name": "Plant_Leaves_Beech_Max_Support"
    },
    {
      "x": -15,
      "y": 53,
      "z": 5,
      "name": "Plant_Leaves_Beech_Max_Support"
    },
    {
      "x": -15,
      "y": 54,
      "z": 5,
      "name": "Plant_Leaves_Beech_Max_Support"
    },
    {
      "x": -15,
      "y": 55,
      "z": 5,
      "name": "Plant_Leaves_Beech_Max_Support"
    },
    {
      "x": -15,
      "y": 51,
      "z": 6,
      "name": "Plant_Leaves_Beech_Max_Support"
    },
    {
      "x": -14,
      "y": 49,
      "z": -8,
      "name": "Plant_Leaves_Beech_Max_Support"
    },
    {
      "x": -14,
      "y": 50,
      "z": -8,
      "name": "Plant_Leaves_Beech_Max_Support"
    },
    {
      "x": -14,
      "y": 51,
      "z": -8,
      "name": "Plant_Leaves_Beech_Max_Support"
    },
    {
      "x": -14,
      "y": 52,
      "z": -8,
      "name": "Plant_Leaves_Beech_Max_Support"
    },
    {
      "x": -14,
      "y": 48,
      "z": -7,
      "name": "Plant_Leaves_Beech_Max_Support"
    },
    {
      "x": -14,
      "y": 50,
      "z": -7,
      "name": "Plant_Leaves_Beech_Max_Support"
    },
    {
      "x": -14,
      "y": 52,
      "z": -7,
      "name": "Plant_Leaves_Beech_Max_Support"
    },
    {
      "x": -14,
      "y": 48,
      "z": -6,
      "name": "Plant_Leaves_Beech_Max_Support"
    },
    {
      "x": -14,
      "y": 50,
      "z": -6,
      "name": "Plant_Leaves_Beech_Max_Support"
    },
    {
      "x": -14,
      "y": 51,
      "z": -6,
      "name": "Plant_Leaves_Beech_Max_Support"
    },
    {
      "x": -14,
      "y": 54,
      "z": -6,
      "name": "Plant_Leaves_Beech_Max_Support"
    },
    {
      "x": -14,
      "y": 48,
      "z": -5,
      "name": "Plant_Leaves_Beech_Max_Support"
    },
    {
      "x": -14,
      "y": 49,
      "z": -5,
      "name": "Plant_Leaves_Beech_Max_Support"
    },
    {
      "x": -14,
      "y": 51,
      "z": -5,
      "name": "Plant_Leaves_Beech_Max_Support"
    },
    {
      "x": -14,
      "y": 54,
      "z": -5,
      "name": "Plant_Leaves_Beech_Max_Support"
    },
    {
      "x": -14,
      "y": 48,
      "z": -4,
      "name": "Plant_Leaves_Beech_Max_Support"
    },
    {
      "x": -14,
      "y": 49,
      "z": -4,
      "name": "Plant_Leaves_Beech_Max_Support"
    },
    {
      "x": -14,
      "y": 50,
      "z": -4,
      "name": "Plant_Leaves_Beech_Max_Support"
    },
    {
      "x": -14,
      "y": 51,
      "z": -4,
      "name": "Plant_Leaves_Beech_Max_Support"
    },
    {
      "x": -14,
      "y": 52,
      "z": -4,
      "name": "Plant_Leaves_Beech_Max_Support"
    },
    {
      "x": -14,
      "y": 54,
      "z": -4,
      "name": "Plant_Leaves_Beech_Max_Support"
    },
    {
      "x": -14,
      "y": 49,
      "z": -3,
      "name": "Plant_Leaves_Beech_Max_Support"
    },
    {
      "x": -14,
      "y": 50,
      "z": -3,
      "name": "Plant_Leaves_Beech_Max_Support"
    },
    {
      "x": -14,
      "y": 51,
      "z": -3,
      "name": "Plant_Leaves_Beech_Max_Support"
    },
    {
      "x": -14,
      "y": 52,
      "z": -3,
      "name": "Plant_Leaves_Beech_Max_Support"
    },
    {
      "x": -14,
      "y": 53,
      "z": -3,
      "name": "Plant_Leaves_Beech_Max_Support"
    },
    {
      "x": -14,
      "y": 54,
      "z": -3,
      "name": "Plant_Leaves_Beech_Max_Support"
    },
    {
      "x": -14,
      "y": 49,
      "z": -2,
      "name": "Wood_Gumboab_Trunk_Full"
    },
    {
      "x": -14,
      "y": 50,
      "z": -2,
      "name": "Plant_Leaves_Beech_Max_Support"
    },
    {
      "x": -14,
      "y": 51,
      "z": -2,
      "name": "Plant_Leaves_Beech_Max_Support"
    },
    {
      "x": -14,
      "y": 52,
      "z": -2,
      "name": "Plant_Leaves_Beech_Max_Support"
    },
    {
      "x": -14,
      "y": 54,
      "z": -2,
      "name": "Plant_Leaves_Beech_Max_Support"
    },
    {
      "x": -14,
      "y": 55,
      "z": -2,
      "name": "Plant_Leaves_Beech_Max_Support"
    },
    {
      "x": -14,
      "y": 49,
      "z": -1,
      "name": "Plant_Leaves_Beech_Max_Support"
    },
    {
      "x": -14,
      "y": 51,
      "z": -1,
      "name": "Plant_Leaves_Beech_Max_Support"
    },
    {
      "x": -14,
      "y": 52,
      "z": -1,
      "name": "Plant_Leaves_Beech_Max_Support"
    },
    {
      "x": -14,
      "y": 54,
      "z": -1,
      "name": "Plant_Leaves_Beech_Max_Support"
    },
    {
      "x": -14,
      "y": 55,
      "z": -1,
      "name": "Plant_Leaves_Beech_Max_Support"
    },
    {
      "x": -14,
      "y": 49,
      "z": 0,
      "name": "Wood_Gumboab_Trunk_Full"
    },
    {
      "x": -14,
      "y": 50,
      "z": 0,
      "name": "Plant_Leaves_Beech_Max_Support"
    },
    {
      "x": -14,
      "y": 51,
      "z": 0,
      "name": "Plant_Leaves_Beech_Max_Support"
    },
    {
      "x": -14,
      "y": 52,
      "z": 0,
      "name": "Plant_Leaves_Beech_Max_Support"
    },
    {
      "x": -14,
      "y": 53,
      "z": 0,
      "name": "Plant_Leaves_Beech_Max_Support"
    },
    {
      "x": -14,
      "y": 54,
      "z": 0,
      "name": "Plant_Leaves_Beech_Max_Support"
    },
    {
      "x": -14,
      "y": 49,
      "z": 1,
      "name": "Wood_Gumboab_Trunk_Full"
    },
    {
      "x": -14,
      "y": 51,
      "z": 1,
      "name": "Plant_Leaves_Beech_Max_Support"
    },
    {
      "x": -14,
      "y": 52,
      "z": 1,
      "name": "Plant_Leaves_Beech_Max_Support"
    },
    {
      "x": -14,
      "y": 53,
      "z": 1,
      "name": "Plant_Leaves_Beech_Max_Support"
    },
    {
      "x": -14,
      "y": 54,
      "z": 1,
      "name": "Plant_Leaves_Beech_Max_Support"
    },
    {
      "x": -14,
      "y": 55,
      "z": 1,
      "name": "Plant_Leaves_Beech_Max_Support"
    },
    {
      "x": -14,
      "y": 50,
      "z": 2,
      "name": "Plant_Leaves_Beech_Max_Support"
    },
    {
      "x": -14,
      "y": 51,
      "z": 2,
      "name": "Plant_Leaves_Beech_Max_Support"
    },
    {
      "x": -14,
      "y": 52,
      "z": 2,
      "name": "Plant_Leaves_Beech_Max_Support"
    },
    {
      "x": -14,
      "y": 53,
      "z": 2,
      "name": "Plant_Leaves_Beech_Max_Support"
    },
    {
      "x": -14,
      "y": 54,
      "z": 2,
      "name": "Plant_Leaves_Beech_Max_Support"
    },
    {
      "x": -14,
      "y": 55,
      "z": 2,
      "name": "Plant_Leaves_Beech_Max_Support"
    },
    {
      "x": -14,
      "y": 49,
      "z": 3,
      "name": "Plant_Leaves_Beech_Max_Support"
    },
    {
      "x": -14,
      "y": 50,
      "z": 3,
      "name": "Plant_Leaves_Beech_Max_Support"
    },
    {
      "x": -14,
      "y": 51,
      "z": 3,
      "name": "Plant_Leaves_Beech_Max_Support"
    },
    {
      "x": -14,
      "y": 52,
      "z": 3,
      "name": "Plant_Leaves_Beech_Max_Support"
    },
    {
      "x": -14,
      "y": 53,
      "z": 3,
      "name": "Plant_Leaves_Beech_Max_Support"
    },
    {
      "x": -14,
      "y": 54,
      "z": 3,
      "name": "Plant_Leaves_Beech_Max_Support"
    },
    {
      "x": -14,
      "y": 55,
      "z": 3,
      "name": "Plant_Leaves_Beech_Max_Support"
    },
    {
      "x": -14,
      "y": 56,
      "z": 3,
      "name": "Plant_Leaves_Beech_Max_Support"
    },
    {
      "x": -14,
      "y": 49,
      "z": 4,
      "name": "Plant_Leaves_Beech_Max_Support"
    },
    {
      "x": -14,
      "y": 50,
      "z": 4,
      "name": "Plant_Leaves_Beech_Max_Support"
    },
    {
      "x": -14,
      "y": 51,
      "z": 4,
      "name": "Plant_Leaves_Beech_Max_Support"
    },
    {
      "x": -14,
      "y": 52,
      "z": 4,
      "name": "Plant_Leaves_Beech_Max_Support"
    },
    {
      "x": -14,
      "y": 53,
      "z": 4,
      "name": "Plant_Leaves_Beech_Max_Support"
    },
    {
      "x": -14,
      "y": 54,
      "z": 4,
      "name": "Plant_Leaves_Beech_Max_Support"
    },
    {
      "x": -14,
      "y": 55,
      "z": 4,
      "name": "Plant_Leaves_Beech_Max_Support"
    },
    {
      "x": -14,
      "y": 50,
      "z": 5,
      "name": "Plant_Leaves_Beech_Max_Support"
    },
    {
      "x": -14,
      "y": 51,
      "z": 5,
      "name": "Plant_Leaves_Beech_Max_Support"
    },
    {
      "x": -14,
      "y": 51,
      "z": 6,
      "name": "Plant_Leaves_Beech_Max_Support"
    },
    {
      "x": -14,
      "y": 52,
      "z": 6,
      "name": "Plant_Leaves_Beech_Max_Support"
    },
    {
      "x": -14,
      "y": 53,
      "z": 6,
      "name": "Plant_Leaves_Beech_Max_Support"
    },
    {
      "x": -13,
      "y": 51,
      "z": -9,
      "name": "Plant_Leaves_Beech_Max_Support"
    },
    {
      "x": -13,
      "y": 48,
      "z": -8,
      "name": "Plant_Leaves_Beech_Max_Support"
    },
    {
      "x": -13,
      "y": 49,
      "z": -8,
      "name": "Plant_Leaves_Beech_Max_Support"
    },
    {
      "x": -13,
      "y": 50,
      "z": -8,
      "name": "Plant_Leaves_Beech_Max_Support"
    },
    {
      "x": -13,
      "y": 51,
      "z": -8,
      "name": "Plant_Leaves_Beech_Max_Support"
    },
    {
      "x": -13,
      "y": 52,
      "z": -8,
      "name": "Plant_Leaves_Beech_Max_Support"
    },
    {
      "x": -13,
      "y": 47,
      "z": -7,
      "name": "Plant_Leaves_Beech_Max_Support"
    },
    {
      "x": -13,
      "y": 48,
      "z": -7,
      "name": "Plant_Leaves_Beech_Max_Support"
    },
    {
      "x": -13,
      "y": 49,
      "z": -7,
      "name": "Plant_Leaves_Beech_Max_Support"
    },
    {
      "x": -13,
      "y": 50,
      "z": -7,
      "name": "Plant_Leaves_Beech_Max_Support"
    },
    {
      "x": -13,
      "y": 52,
      "z": -7,
      "name": "Plant_Leaves_Beech_Max_Support"
    },
    {
      "x": -13,
      "y": 53,
      "z": -7,
      "name": "Plant_Leaves_Beech_Max_Support"
    },
    {
      "x": -13,
      "y": 47,
      "z": -6,
      "name": "Plant_Leaves_Beech_Max_Support"
    },
    {
      "x": -13,
      "y": 48,
      "z": -6,
      "name": "Plant_Leaves_Beech_Max_Support"
    },
    {
      "x": -13,
      "y": 49,
      "z": -6,
      "name": "Plant_Leaves_Beech_Max_Support"
    },
    {
      "x": -13,
      "y": 50,
      "z": -6,
      "name": "Plant_Leaves_Beech_Max_Support"
    },
    {
      "x": -13,
      "y": 51,
      "z": -6,
      "name": "Plant_Leaves_Beech_Max_Support"
    },
    {
      "x": -13,
      "y": 52,
      "z": -6,
      "name": "Plant_Leaves_Beech_Max_Support"
    },
    {
      "x": -13,
      "y": 53,
      "z": -6,
      "name": "Plant_Leaves_Beech_Max_Support"
    },
    {
      "x": -13,
      "y": 54,
      "z": -6,
      "name": "Plant_Leaves_Beech_Max_Support"
    },
    {
      "x": -13,
      "y": 47,
      "z": -5,
      "name": "Plant_Leaves_Beech_Max_Support"
    },
    {
      "x": -13,
      "y": 49,
      "z": -5,
      "name": "Plant_Leaves_Beech_Max_Support"
    },
    {
      "x": -13,
      "y": 50,
      "z": -5,
      "name": "Plant_Leaves_Beech_Max_Support"
    },
    {
      "x": -13,
      "y": 51,
      "z": -5,
      "name": "Plant_Leaves_Beech_Max_Support"
    },
    {
      "x": -13,
      "y": 52,
      "z": -5,
      "name": "Plant_Leaves_Beech_Max_Support"
    },
    {
      "x": -13,
      "y": 53,
      "z": -5,
      "name": "Plant_Leaves_Beech_Max_Support"
    },
    {
      "x": -13,
      "y": 48,
      "z": -4,
      "name": "Plant_Leaves_Beech_Max_Support"
    },
    {
      "x": -13,
      "y": 49,
      "z": -4,
      "name": "Plant_Leaves_Beech_Max_Support"
    },
    {
      "x": -13,
      "y": 50,
      "z": -4,
      "name": "Wood_Gumboab_Trunk_Full"
    },
    {
      "x": -13,
      "y": 51,
      "z": -4,
      "name": "Plant_Leaves_Beech_Max_Support"
    },
    {
      "x": -13,
      "y": 52,
      "z": -4,
      "name": "Plant_Leaves_Beech_Max_Support"
    },
    {
      "x": -13,
      "y": 53,
      "z": -4,
      "name": "Plant_Leaves_Beech_Max_Support"
    },
    {
      "x": -13,
      "y": 54,
      "z": -4,
      "name": "Plant_Leaves_Beech_Max_Support"
    },
    {
      "x": -13,
      "y": 49,
      "z": -3,
      "name": "Wood_Gumboab_Trunk_Full"
    },
    {
      "x": -13,
      "y": 50,
      "z": -3,
      "name": "Wood_Gumboab_Trunk_Full"
    },
    {
      "x": -13,
      "y": 51,
      "z": -3,
      "name": "Plant_Leaves_Beech_Max_Support"
    },
    {
      "x": -13,
      "y": 52,
      "z": -3,
      "name": "Plant_Leaves_Beech_Max_Support"
    },
    {
      "x": -13,
      "y": 53,
      "z": -3,
      "name": "Plant_Leaves_Beech_Max_Support"
    },
    {
      "x": -13,
      "y": 55,
      "z": -3,
      "name": "Plant_Leaves_Beech_Max_Support"
    },
    {
      "x": -13,
      "y": 49,
      "z": -2,
      "name": "Wood_Gumboab_Trunk_Full"
    },
    {
      "x": -13,
      "y": 50,
      "z": -2,
      "name": "Wood_Gumboab_Trunk_Full"
    },
    {
      "x": -13,
      "y": 51,
      "z": -2,
      "name": "Plant_Leaves_Beech_Max_Support"
    },
    {
      "x": -13,
      "y": 52,
      "z": -2,
      "name": "Plant_Leaves_Beech_Max_Support"
    },
    {
      "x": -13,
      "y": 53,
      "z": -2,
      "name": "Plant_Leaves_Beech_Max_Support"
    },
    {
      "x": -13,
      "y": 54,
      "z": -2,
      "name": "Plant_Leaves_Beech_Max_Support"
    },
    {
      "x": -13,
      "y": 55,
      "z": -2,
      "name": "Plant_Leaves_Beech_Max_Support"
    },
    {
      "x": -13,
      "y": 49,
      "z": -1,
      "name": "Wood_Gumboab_Trunk_Full"
    },
    {
      "x": -13,
      "y": 50,
      "z": -1,
      "name": "Wood_Gumboab_Trunk_Full"
    },
    {
      "x": -13,
      "y": 51,
      "z": -1,
      "name": "Plant_Leaves_Beech_Max_Support"
    },
    {
      "x": -13,
      "y": 52,
      "z": -1,
      "name": "Plant_Leaves_Beech_Max_Support"
    },
    {
      "x": -13,
      "y": 53,
      "z": -1,
      "name": "Plant_Leaves_Beech_Max_Support"
    },
    {
      "x": -13,
      "y": 54,
      "z": -1,
      "name": "Plant_Leaves_Beech_Max_Support"
    },
    {
      "x": -13,
      "y": 55,
      "z": -1,
      "name": "Plant_Leaves_Beech_Max_Support"
    },
    {
      "x": -13,
      "y": 56,
      "z": -1,
      "name": "Plant_Leaves_Beech_Max_Support"
    },
    {
      "x": -13,
      "y": 49,
      "z": 0,
      "name": "Wood_Gumboab_Trunk_Full"
    },
    {
      "x": -13,
      "y": 51,
      "z": 0,
      "name": "Plant_Leaves_Beech_Max_Support"
    },
    {
      "x": -13,
      "y": 52,
      "z": 0,
      "name": "Plant_Leaves_Beech_Max_Support"
    },
    {
      "x": -13,
      "y": 53,
      "z": 0,
      "name": "Plant_Leaves_Beech_Max_Support"
    },
    {
      "x": -13,
      "y": 54,
      "z": 0,
      "name": "Plant_Leaves_Beech_Max_Support"
    },
    {
      "x": -13,
      "y": 55,
      "z": 0,
      "name": "Plant_Leaves_Beech_Max_Support"
    },
    {
      "x": -13,
      "y": 51,
      "z": 1,
      "name": "Plant_Leaves_Beech_Max_Support"
    },
    {
      "x": -13,
      "y": 52,
      "z": 1,
      "name": "Plant_Leaves_Beech_Max_Support"
    },
    {
      "x": -13,
      "y": 53,
      "z": 1,
      "name": "Plant_Leaves_Beech_Max_Support"
    },
    {
      "x": -13,
      "y": 55,
      "z": 1,
      "name": "Plant_Leaves_Beech_Max_Support"
    },
    {
      "x": -13,
      "y": 49,
      "z": 2,
      "name": "Plant_Leaves_Beech_Max_Support"
    },
    {
      "x": -13,
      "y": 51,
      "z": 2,
      "name": "Plant_Leaves_Beech_Max_Support"
    },
    {
      "x": -13,
      "y": 52,
      "z": 2,
      "name": "Plant_Leaves_Beech_Max_Support"
    },
    {
      "x": -13,
      "y": 53,
      "z": 2,
      "name": "Plant_Leaves_Beech_Max_Support"
    },
    {
      "x": -13,
      "y": 54,
      "z": 2,
      "name": "Plant_Leaves_Beech_Max_Support"
    },
    {
      "x": -13,
      "y": 55,
      "z": 2,
      "name": "Plant_Leaves_Beech_Max_Support"
    },
    {
      "x": -13,
      "y": 49,
      "z": 3,
      "name": "Plant_Leaves_Beech_Max_Support"
    },
    {
      "x": -13,
      "y": 51,
      "z": 3,
      "name": "Plant_Leaves_Beech_Max_Support"
    },
    {
      "x": -13,
      "y": 52,
      "z": 3,
      "name": "Plant_Leaves_Beech_Max_Support"
    },
    {
      "x": -13,
      "y": 53,
      "z": 3,
      "name": "Plant_Leaves_Beech_Max_Support"
    },
    {
      "x": -13,
      "y": 54,
      "z": 3,
      "name": "Plant_Leaves_Beech_Max_Support"
    },
    {
      "x": -13,
      "y": 55,
      "z": 3,
      "name": "Plant_Leaves_Beech_Max_Support"
    },
    {
      "x": -13,
      "y": 51,
      "z": 4,
      "name": "Plant_Leaves_Beech_Max_Support"
    },
    {
      "x": -13,
      "y": 52,
      "z": 4,
      "name": "Plant_Leaves_Beech_Max_Support"
    },
    {
      "x": -13,
      "y": 53,
      "z": 4,
      "name": "Plant_Leaves_Beech_Max_Support"
    },
    {
      "x": -13,
      "y": 54,
      "z": 4,
      "name": "Plant_Leaves_Beech_Max_Support"
    },
    {
      "x": -13,
      "y": 51,
      "z": 5,
      "name": "Plant_Leaves_Beech_Max_Support"
    },
    {
      "x": -13,
      "y": 52,
      "z": 5,
      "name": "Plant_Leaves_Beech_Max_Support"
    },
    {
      "x": -13,
      "y": 53,
      "z": 5,
      "name": "Plant_Leaves_Beech_Max_Support"
    },
    {
      "x": -13,
      "y": 53,
      "z": 6,
      "name": "Plant_Leaves_Beech_Max_Support"
    },
    {
      "x": -12,
      "y": 49,
      "z": -9,
      "name": "Plant_Leaves_Beech_Max_Support"
    },
    {
      "x": -12,
      "y": 48,
      "z": -8,
      "name": "Plant_Leaves_Beech_Max_Support"
    },
    {
      "x": -12,
      "y": 50,
      "z": -8,
      "name": "Plant_Leaves_Beech_Max_Support"
    },
    {
      "x": -12,
      "y": 51,
      "z": -8,
      "name": "Plant_Leaves_Beech_Max_Support"
    },
    {
      "x": -12,
      "y": 47,
      "z": -7,
      "name": "Plant_Leaves_Beech_Max_Support"
    },
    {
      "x": -12,
      "y": 48,
      "z": -7,
      "name": "Plant_Leaves_Beech_Max_Support"
    },
    {
      "x": -12,
      "y": 49,
      "z": -7,
      "name": "Plant_Leaves_Beech_Max_Support"
    },
    {
      "x": -12,
      "y": 50,
      "z": -7,
      "name": "Plant_Leaves_Beech_Max_Support"
    },
    {
      "x": -12,
      "y": 51,
      "z": -7,
      "name": "Plant_Leaves_Beech_Max_Support"
    },
    {
      "x": -12,
      "y": 52,
      "z": -7,
      "name": "Plant_Leaves_Beech_Max_Support"
    },
    {
      "x": -12,
      "y": 53,
      "z": -7,
      "name": "Plant_Leaves_Beech_Max_Support"
    },
    {
      "x": -12,
      "y": 47,
      "z": -6,
      "name": "Plant_Leaves_Beech_Max_Support"
    },
    {
      "x": -12,
      "y": 48,
      "z": -6,
      "name": "Wood_Gumboab_Trunk_Full"
    },
    {
      "x": -12,
      "y": 49,
      "z": -6,
      "name": "Wood_Gumboab_Trunk_Full"
    },
    {
      "x": -12,
      "y": 50,
      "z": -6,
      "name": "Plant_Leaves_Beech_Max_Support"
    },
    {
      "x": -12,
      "y": 51,
      "z": -6,
      "name": "Plant_Leaves_Beech_Max_Support"
    },
    {
      "x": -12,
      "y": 52,
      "z": -6,
      "name": "Plant_Leaves_Beech_Max_Support"
    },
    {
      "x": -12,
      "y": 47,
      "z": -5,
      "name": "Plant_Leaves_Beech_Max_Support"
    },
    {
      "x": -12,
      "y": 48,
      "z": -5,
      "name": "Wood_Gumboab_Trunk_Full"
    },
    {
      "x": -12,
      "y": 49,
      "z": -5,
      "name": "Wood_Gumboab_Trunk_Full"
    },
    {
      "x": -12,
      "y": 50,
      "z": -5,
      "name": "Plant_Leaves_Beech_Max_Support"
    },
    {
      "x": -12,
      "y": 51,
      "z": -5,
      "name": "Plant_Leaves_Beech_Max_Support"
    },
    {
      "x": -12,
      "y": 53,
      "z": -5,
      "name": "Plant_Leaves_Beech_Max_Support"
    },
    {
      "x": -12,
      "y": 48,
      "z": -4,
      "name": "Wood_Gumboab_Trunk_Full"
    },
    {
      "x": -12,
      "y": 49,
      "z": -4,
      "name": "Wood_Gumboab_Trunk_Full"
    },
    {
      "x": -12,
      "y": 50,
      "z": -4,
      "name": "Plant_Leaves_Beech_Max_Support"
    },
    {
      "x": -12,
      "y": 51,
      "z": -4,
      "name": "Plant_Leaves_Beech_Max_Support"
    },
    {
      "x": -12,
      "y": 52,
      "z": -4,
      "name": "Plant_Leaves_Beech_Max_Support"
    },
    {
      "x": -12,
      "y": 53,
      "z": -4,
      "name": "Plant_Leaves_Beech_Max_Support"
    },
    {
      "x": -12,
      "y": 48,
      "z": -3,
      "name": "Wood_Gumboab_Trunk_Full"
    },
    {
      "x": -12,
      "y": 49,
      "z": -3,
      "name": "Wood_Gumboab_Trunk_Full"
    },
    {
      "x": -12,
      "y": 50,
      "z": -3,
      "name": "Plant_Leaves_Beech_Max_Support"
    },
    {
      "x": -12,
      "y": 51,
      "z": -3,
      "name": "Plant_Leaves_Beech_Max_Support"
    },
    {
      "x": -12,
      "y": 52,
      "z": -3,
      "name": "Plant_Leaves_Beech_Max_Support"
    },
    {
      "x": -12,
      "y": 53,
      "z": -3,
      "name": "Plant_Leaves_Beech_Max_Support"
    },
    {
      "x": -12,
      "y": 54,
      "z": -3,
      "name": "Plant_Leaves_Beech_Max_Support"
    },
    {
      "x": -12,
      "y": 55,
      "z": -3,
      "name": "Plant_Leaves_Beech_Max_Support"
    },
    {
      "x": -12,
      "y": 47,
      "z": -2,
      "name": "Wood_Gumboab_Roots"
    },
    {
      "x": -12,
      "y": 48,
      "z": -2,
      "name": "Wood_Gumboab_Trunk_Full"
    },
    {
      "x": -12,
      "y": 49,
      "z": -2,
      "name": "Plant_Leaves_Beech_Max_Support"
    },
    {
      "x": -12,
      "y": 50,
      "z": -2,
      "name": "Plant_Leaves_Beech_Max_Support"
    },
    {
      "x": -12,
      "y": 51,
      "z": -2,
      "name": "Plant_Leaves_Beech_Max_Support"
    },
    {
      "x": -12,
      "y": 52,
      "z": -2,
      "name": "Plant_Leaves_Beech_Max_Support"
    },
    {
      "x": -12,
      "y": 53,
      "z": -2,
      "name": "Plant_Leaves_Beech_Max_Support"
    },
    {
      "x": -12,
      "y": 54,
      "z": -2,
      "name": "Plant_Leaves_Beech_Max_Support"
    },
    {
      "x": -12,
      "y": 55,
      "z": -2,
      "name": "Plant_Leaves_Beech_Max_Support"
    },
    {
      "x": -12,
      "y": 49,
      "z": -1,
      "name": "Wood_Gumboab_Trunk_Full"
    },
    {
      "x": -12,
      "y": 50,
      "z": -1,
      "name": "Wood_Gumboab_Trunk_Full"
    },
    {
      "x": -12,
      "y": 51,
      "z": -1,
      "name": "Plant_Leaves_Beech_Max_Support"
    },
    {
      "x": -12,
      "y": 52,
      "z": -1,
      "name": "Plant_Leaves_Beech_Max_Support"
    },
    {
      "x": -12,
      "y": 53,
      "z": -1,
      "name": "Plant_Leaves_Beech_Max_Support"
    },
    {
      "x": -12,
      "y": 54,
      "z": -1,
      "name": "Plant_Leaves_Beech_Max_Support"
    },
    {
      "x": -12,
      "y": 55,
      "z": -1,
      "name": "Plant_Leaves_Beech_Max_Support"
    },
    {
      "x": -12,
      "y": 56,
      "z": -1,
      "name": "Plant_Leaves_Beech_Max_Support"
    },
    {
      "x": -12,
      "y": 49,
      "z": 0,
      "name": "Wood_Gumboab_Trunk_Full"
    },
    {
      "x": -12,
      "y": 50,
      "z": 0,
      "name": "Wood_Gumboab_Trunk_Full"
    },
    {
      "x": -12,
      "y": 51,
      "z": 0,
      "name": "Plant_Leaves_Beech_Max_Support"
    },
    {
      "x": -12,
      "y": 52,
      "z": 0,
      "name": "Plant_Leaves_Beech_Max_Support"
    },
    {
      "x": -12,
      "y": 53,
      "z": 0,
      "name": "Plant_Leaves_Beech_Max_Support"
    },
    {
      "x": -12,
      "y": 54,
      "z": 0,
      "name": "Plant_Leaves_Beech_Max_Support"
    },
    {
      "x": -12,
      "y": 55,
      "z": 0,
      "name": "Plant_Leaves_Beech_Max_Support"
    },
    {
      "x": -12,
      "y": 56,
      "z": 0,
      "name": "Plant_Leaves_Beech_Max_Support"
    },
    {
      "x": -12,
      "y": 51,
      "z": 1,
      "name": "Plant_Leaves_Beech_Max_Support"
    },
    {
      "x": -12,
      "y": 52,
      "z": 1,
      "name": "Plant_Leaves_Beech_Max_Support"
    },
    {
      "x": -12,
      "y": 53,
      "z": 1,
      "name": "Plant_Leaves_Beech_Max_Support"
    },
    {
      "x": -12,
      "y": 54,
      "z": 1,
      "name": "Plant_Leaves_Beech_Max_Support"
    },
    {
      "x": -12,
      "y": 55,
      "z": 1,
      "name": "Plant_Leaves_Beech_Max_Support"
    },
    {
      "x": -12,
      "y": 50,
      "z": 2,
      "name": "Plant_Leaves_Beech_Max_Support"
    },
    {
      "x": -12,
      "y": 51,
      "z": 2,
      "name": "Plant_Leaves_Beech_Max_Support"
    },
    {
      "x": -12,
      "y": 52,
      "z": 2,
      "name": "Plant_Leaves_Beech_Max_Support"
    },
    {
      "x": -12,
      "y": 53,
      "z": 2,
      "name": "Plant_Leaves_Beech_Max_Support"
    },
    {
      "x": -12,
      "y": 54,
      "z": 2,
      "name": "Plant_Leaves_Beech_Max_Support"
    },
    {
      "x": -12,
      "y": 56,
      "z": 2,
      "name": "Plant_Leaves_Beech_Max_Support"
    },
    {
      "x": -12,
      "y": 50,
      "z": 3,
      "name": "Plant_Leaves_Beech_Max_Support"
    },
    {
      "x": -12,
      "y": 51,
      "z": 3,
      "name": "Plant_Leaves_Beech_Max_Support"
    },
    {
      "x": -12,
      "y": 52,
      "z": 3,
      "name": "Plant_Leaves_Beech_Max_Support"
    },
    {
      "x": -12,
      "y": 53,
      "z": 3,
      "name": "Plant_Leaves_Beech_Max_Support"
    },
    {
      "x": -12,
      "y": 54,
      "z": 3,
      "name": "Plant_Leaves_Beech_Max_Support"
    },
    {
      "x": -12,
      "y": 55,
      "z": 3,
      "name": "Plant_Leaves_Beech_Max_Support"
    },
    {
      "x": -12,
      "y": 51,
      "z": 4,
      "name": "Plant_Leaves_Beech_Max_Support"
    },
    {
      "x": -12,
      "y": 52,
      "z": 4,
      "name": "Plant_Leaves_Beech_Max_Support"
    },
    {
      "x": -12,
      "y": 53,
      "z": 4,
      "name": "Plant_Leaves_Beech_Max_Support"
    },
    {
      "x": -12,
      "y": 54,
      "z": 4,
      "name": "Plant_Leaves_Beech_Max_Support"
    },
    {
      "x": -12,
      "y": 51,
      "z": 5,
      "name": "Plant_Leaves_Beech_Max_Support"
    },
    {
      "x": -12,
      "y": 52,
      "z": 5,
      "name": "Plant_Leaves_Beech_Max_Support"
    },
    {
      "x": -12,
      "y": 53,
      "z": 5,
      "name": "Plant_Leaves_Beech_Max_Support"
    },
    {
      "x": -11,
      "y": 49,
      "z": -9,
      "name": "Plant_Leaves_Beech_Max_Support"
    },
    {
      "x": -11,
      "y": 50,
      "z": -9,
      "name": "Plant_Leaves_Beech_Max_Support"
    },
    {
      "x": -11,
      "y": 47,
      "z": -8,
      "name": "Plant_Leaves_Beech_Max_Support"
    },
    {
      "x": -11,
      "y": 48,
      "z": -8,
      "name": "Plant_Leaves_Beech_Max_Support"
    },
    {
      "x": -11,
      "y": 49,
      "z": -8,
      "name": "Plant_Leaves_Beech_Max_Support"
    },
    {
      "x": -11,
      "y": 50,
      "z": -8,
      "name": "Plant_Leaves_Beech_Max_Support"
    },
    {
      "x": -11,
      "y": 51,
      "z": -8,
      "name": "Plant_Leaves_Beech_Max_Support"
    },
    {
      "x": -11,
      "y": 46,
      "z": -7,
      "name": "Plant_Leaves_Beech_Max_Support"
    },
    {
      "x": -11,
      "y": 47,
      "z": -7,
      "name": "Plant_Leaves_Beech_Max_Support"
    },
    {
      "x": -11,
      "y": 48,
      "z": -7,
      "name": "Wood_Gumboab_Trunk_Full"
    },
    {
      "x": -11,
      "y": 49,
      "z": -7,
      "name": "Wood_Gumboab_Trunk_Full"
    },
    {
      "x": -11,
      "y": 50,
      "z": -7,
      "name": "Plant_Leaves_Beech_Max_Support"
    },
    {
      "x": -11,
      "y": 51,
      "z": -7,
      "name": "Plant_Leaves_Beech_Max_Support"
    },
    {
      "x": -11,
      "y": 46,
      "z": -6,
      "name": "Plant_Leaves_Beech_Max_Support"
    },
    {
      "x": -11,
      "y": 47,
      "z": -6,
      "name": "Plant_Leaves_Beech_Max_Support"
    },
    {
      "x": -11,
      "y": 48,
      "z": -6,
      "name": "Wood_Gumboab_Trunk_Full"
    },
    {
      "x": -11,
      "y": 49,
      "z": -6,
      "name": "Wood_Gumboab_Trunk_Full"
    },
    {
      "x": -11,
      "y": 50,
      "z": -6,
      "name": "Plant_Leaves_Beech_Max_Support"
    },
    {
      "x": -11,
      "y": 51,
      "z": -6,
      "name": "Plant_Leaves_Beech_Max_Support"
    },
    {
      "x": -11,
      "y": 52,
      "z": -6,
      "name": "Plant_Leaves_Beech_Max_Support"
    },
    {
      "x": -11,
      "y": 53,
      "z": -6,
      "name": "Plant_Leaves_Beech_Max_Support"
    },
    {
      "x": -11,
      "y": 46,
      "z": -5,
      "name": "Plant_Leaves_Beech_Max_Support"
    },
    {
      "x": -11,
      "y": 47,
      "z": -5,
      "name": "Plant_Leaves_Beech_Max_Support"
    },
    {
      "x": -11,
      "y": 48,
      "z": -5,
      "name": "Wood_Gumboab_Trunk_Full"
    },
    {
      "x": -11,
      "y": 49,
      "z": -5,
      "name": "Wood_Gumboab_Trunk_Full"
    },
    {
      "x": -11,
      "y": 50,
      "z": -5,
      "name": "Plant_Leaves_Beech_Max_Support"
    },
    {
      "x": -11,
      "y": 51,
      "z": -5,
      "name": "Plant_Leaves_Beech_Max_Support"
    },
    {
      "x": -11,
      "y": 52,
      "z": -5,
      "name": "Plant_Leaves_Beech_Max_Support"
    },
    {
      "x": -11,
      "y": 53,
      "z": -5,
      "name": "Plant_Leaves_Beech_Max_Support"
    },
    {
      "x": -11,
      "y": 48,
      "z": -4,
      "name": "Wood_Gumboab_Trunk_Full"
    },
    {
      "x": -11,
      "y": 49,
      "z": -4,
      "name": "Wood_Gumboab_Trunk_Full"
    },
    {
      "x": -11,
      "y": 50,
      "z": -4,
      "name": "Plant_Leaves_Beech_Max_Support"
    },
    {
      "x": -11,
      "y": 51,
      "z": -4,
      "name": "Plant_Leaves_Beech_Max_Support"
    },
    {
      "x": -11,
      "y": 52,
      "z": -4,
      "name": "Plant_Leaves_Beech_Max_Support"
    },
    {
      "x": -11,
      "y": 53,
      "z": -4,
      "name": "Plant_Leaves_Beech_Max_Support"
    },
    {
      "x": -11,
      "y": 48,
      "z": -3,
      "name": "Wood_Gumboab_Trunk_Full"
    },
    {
      "x": -11,
      "y": 49,
      "z": -3,
      "name": "Wood_Gumboab_Trunk_Full"
    },
    {
      "x": -11,
      "y": 50,
      "z": -3,
      "name": "Plant_Leaves_Beech_Max_Support"
    },
    {
      "x": -11,
      "y": 51,
      "z": -3,
      "name": "Plant_Leaves_Beech_Max_Support"
    },
    {
      "x": -11,
      "y": 52,
      "z": -3,
      "name": "Plant_Leaves_Beech_Max_Support"
    },
    {
      "x": -11,
      "y": 53,
      "z": -3,
      "name": "Plant_Leaves_Beech_Max_Support"
    },
    {
      "x": -11,
      "y": 54,
      "z": -3,
      "name": "Plant_Leaves_Beech_Max_Support"
    },
    {
      "x": -11,
      "y": 48,
      "z": -2,
      "name": "Wood_Gumboab_Trunk_Full"
    },
    {
      "x": -11,
      "y": 49,
      "z": -2,
      "name": "Wood_Gumboab_Trunk_Full"
    },
    {
      "x": -11,
      "y": 50,
      "z": -2,
      "name": "Plant_Leaves_Beech_Max_Support"
    },
    {
      "x": -11,
      "y": 51,
      "z": -2,
      "name": "Plant_Leaves_Beech_Max_Support"
    },
    {
      "x": -11,
      "y": 52,
      "z": -2,
      "name": "Plant_Leaves_Beech_Max_Support"
    },
    {
      "x": -11,
      "y": 53,
      "z": -2,
      "name": "Plant_Leaves_Beech_Max_Support"
    },
    {
      "x": -11,
      "y": 55,
      "z": -2,
      "name": "Plant_Leaves_Beech_Max_Support"
    },
    {
      "x": -11,
      "y": 48,
      "z": -1,
      "name": "Wood_Gumboab_Trunk_Full"
    },
    {
      "x": -11,
      "y": 49,
      "z": -1,
      "name": "Wood_Gumboab_Trunk_Full"
    },
    {
      "x": -11,
      "y": 50,
      "z": -1,
      "name": "Plant_Leaves_Beech_Max_Support"
    },
    {
      "x": -11,
      "y": 51,
      "z": -1,
      "name": "Plant_Leaves_Beech_Max_Support"
    },
    {
      "x": -11,
      "y": 52,
      "z": -1,
      "name": "Plant_Leaves_Beech_Max_Support"
    },
    {
      "x": -11,
      "y": 53,
      "z": -1,
      "name": "Plant_Leaves_Beech_Max_Support"
    },
    {
      "x": -11,
      "y": 54,
      "z": -1,
      "name": "Plant_Leaves_Beech_Max_Support"
    },
    {
      "x": -11,
      "y": 55,
      "z": -1,
      "name": "Plant_Leaves_Beech_Max_Support"
    },
    {
      "x": -11,
      "y": 56,
      "z": -1,
      "name": "Plant_Leaves_Beech_Max_Support"
    },
    {
      "x": -11,
      "y": 48,
      "z": 0,
      "name": "Wood_Gumboab_Trunk_Full"
    },
    {
      "x": -11,
      "y": 49,
      "z": 0,
      "name": "Wood_Gumboab_Trunk_Full"
    },
    {
      "x": -11,
      "y": 50,
      "z": 0,
      "name": "Plant_Leaves_Beech_Max_Support"
    },
    {
      "x": -11,
      "y": 51,
      "z": 0,
      "name": "Plant_Leaves_Beech_Max_Support"
    },
    {
      "x": -11,
      "y": 52,
      "z": 0,
      "name": "Plant_Leaves_Beech_Max_Support"
    },
    {
      "x": -11,
      "y": 53,
      "z": 0,
      "name": "Plant_Leaves_Beech_Max_Support"
    },
    {
      "x": -11,
      "y": 54,
      "z": 0,
      "name": "Plant_Leaves_Beech_Max_Support"
    },
    {
      "x": -11,
      "y": 55,
      "z": 0,
      "name": "Plant_Leaves_Beech_Max_Support"
    },
    {
      "x": -11,
      "y": 56,
      "z": 0,
      "name": "Plant_Leaves_Beech_Max_Support"
    },
    {
      "x": -11,
      "y": 57,
      "z": 0,
      "name": "Plant_Leaves_Beech_Max_Support"
    },
    {
      "x": -11,
      "y": 50,
      "z": 1,
      "name": "Plant_Leaves_Beech_Max_Support"
    },
    {
      "x": -11,
      "y": 51,
      "z": 1,
      "name": "Plant_Leaves_Beech_Max_Support"
    },
    {
      "x": -11,
      "y": 52,
      "z": 1,
      "name": "Plant_Leaves_Beech_Max_Support"
    },
    {
      "x": -11,
      "y": 53,
      "z": 1,
      "name": "Plant_Leaves_Beech_Max_Support"
    },
    {
      "x": -11,
      "y": 54,
      "z": 1,
      "name": "Plant_Leaves_Beech_Max_Support"
    },
    {
      "x": -11,
      "y": 56,
      "z": 1,
      "name": "Plant_Leaves_Beech_Max_Support"
    },
    {
      "x": -11,
      "y": 50,
      "z": 2,
      "name": "Plant_Leaves_Beech_Max_Support"
    },
    {
      "x": -11,
      "y": 51,
      "z": 2,
      "name": "Plant_Leaves_Beech_Max_Support"
    },
    {
      "x": -11,
      "y": 52,
      "z": 2,
      "name": "Plant_Leaves_Beech_Max_Support"
    },
    {
      "x": -11,
      "y": 53,
      "z": 2,
      "name": "Plant_Leaves_Beech_Max_Support"
    },
    {
      "x": -11,
      "y": 54,
      "z": 2,
      "name": "Plant_Leaves_Beech_Max_Support"
    },
    {
      "x": -11,
      "y": 55,
      "z": 2,
      "name": "Plant_Leaves_Beech_Max_Support"
    },
    {
      "x": -11,
      "y": 56,
      "z": 2,
      "name": "Plant_Leaves_Beech_Max_Support"
    },
    {
      "x": -11,
      "y": 50,
      "z": 3,
      "name": "Plant_Leaves_Beech_Max_Support"
    },
    {
      "x": -11,
      "y": 51,
      "z": 3,
      "name": "Plant_Leaves_Beech_Max_Support"
    },
    {
      "x": -11,
      "y": 52,
      "z": 3,
      "name": "Plant_Leaves_Beech_Max_Support"
    },
    {
      "x": -11,
      "y": 53,
      "z": 3,
      "name": "Plant_Leaves_Beech_Max_Support"
    },
    {
      "x": -11,
      "y": 54,
      "z": 3,
      "name": "Plant_Leaves_Beech_Max_Support"
    },
    {
      "x": -11,
      "y": 55,
      "z": 3,
      "name": "Plant_Leaves_Beech_Max_Support"
    },
    {
      "x": -11,
      "y": 56,
      "z": 3,
      "name": "Plant_Leaves_Beech_Max_Support"
    },
    {
      "x": -11,
      "y": 52,
      "z": 4,
      "name": "Plant_Leaves_Beech_Max_Support"
    },
    {
      "x": -11,
      "y": 53,
      "z": 4,
      "name": "Plant_Leaves_Beech_Max_Support"
    },
    {
      "x": -11,
      "y": 55,
      "z": 4,
      "name": "Plant_Leaves_Beech_Max_Support"
    },
    {
      "x": -11,
      "y": 51,
      "z": 5,
      "name": "Plant_Leaves_Beech_Max_Support"
    },
    {
      "x": -11,
      "y": 52,
      "z": 5,
      "name": "Plant_Leaves_Beech_Max_Support"
    },
    {
      "x": -11,
      "y": 50,
      "z": 6,
      "name": "Plant_Leaves_Beech_Max_Support"
    },
    {
      "x": -11,
      "y": 51,
      "z": 6,
      "name": "Plant_Leaves_Beech_Max_Support"
    },
    {
      "x": -11,
      "y": 50,
      "z": 7,
      "name": "Plant_Leaves_Beech_Max_Support"
    },
    {
      "x": -11,
      "y": 52,
      "z": 7,
      "name": "Plant_Leaves_Beech_Max_Support"
    },
    {
      "x": -11,
      "y": 50,
      "z": 8,
      "name": "Plant_Leaves_Beech_Max_Support"
    },
    {
      "x": -11,
      "y": 51,
      "z": 8,
      "name": "Plant_Leaves_Beech_Max_Support"
    },
    {
      "x": -11,
      "y": 48,
      "z": 9,
      "name": "Plant_Leaves_Beech_Max_Support",
      "support": 15
    },
    {
      "x": -10,
      "y": 48,
      "z": -9,
      "name": "Plant_Leaves_Beech_Max_Support"
    },
    {
      "x": -10,
      "y": 50,
      "z": -9,
      "name": "Plant_Leaves_Beech_Max_Support"
    },
    {
      "x": -10,
      "y": 47,
      "z": -8,
      "name": "Plant_Leaves_Beech_Max_Support"
    },
    {
      "x": -10,
      "y": 48,
      "z": -8,
      "name": "Plant_Leaves_Beech_Max_Support"
    },
    {
      "x": -10,
      "y": 49,
      "z": -8,
      "name": "Plant_Leaves_Beech_Max_Support"
    },
    {
      "x": -10,
      "y": 50,
      "z": -8,
      "name": "Plant_Leaves_Beech_Max_Support"
    },
    {
      "x": -10,
      "y": 51,
      "z": -8,
      "name": "Plant_Leaves_Beech_Max_Support"
    },
    {
      "x": -10,
      "y": 46,
      "z": -7,
      "name": "Plant_Leaves_Beech_Max_Support"
    },
    {
      "x": -10,
      "y": 48,
      "z": -7,
      "name": "Wood_Gumboab_Trunk_Full"
    },
    {
      "x": -10,
      "y": 49,
      "z": -7,
      "name": "Wood_Gumboab_Trunk_Full"
    },
    {
      "x": -10,
      "y": 50,
      "z": -7,
      "name": "Plant_Leaves_Beech_Max_Support"
    },
    {
      "x": -10,
      "y": 51,
      "z": -7,
      "name": "Plant_Leaves_Beech_Max_Support"
    },
    {
      "x": -10,
      "y": 46,
      "z": -6,
      "name": "Plant_Leaves_Beech_Max_Support"
    },
    {
      "x": -10,
      "y": 48,
      "z": -6,
      "name": "Wood_Gumboab_Trunk_Full"
    },
    {
      "x": -10,
      "y": 49,
      "z": -6,
      "name": "Wood_Gumboab_Trunk_Full"
    },
    {
      "x": -10,
      "y": 50,
      "z": -6,
      "name": "Plant_Leaves_Beech_Max_Support"
    },
    {
      "x": -10,
      "y": 52,
      "z": -6,
      "name": "Plant_Leaves_Beech_Max_Support"
    },
    {
      "x": -10,
      "y": 47,
      "z": -5,
      "name": "Plant_Leaves_Beech_Max_Support"
    },
    {
      "x": -10,
      "y": 48,
      "z": -5,
      "name": "Plant_Leaves_Beech_Max_Support"
    },
    {
      "x": -10,
      "y": 49,
      "z": -5,
      "name": "Plant_Leaves_Beech_Max_Support"
    },
    {
      "x": -10,
      "y": 50,
      "z": -5,
      "name": "Plant_Leaves_Beech_Max_Support"
    },
    {
      "x": -10,
      "y": 51,
      "z": -5,
      "name": "Plant_Leaves_Beech_Max_Support"
    },
    {
      "x": -10,
      "y": 52,
      "z": -5,
      "name": "Plant_Leaves_Beech_Max_Support"
    },
    {
      "x": -10,
      "y": 53,
      "z": -5,
      "name": "Plant_Leaves_Beech_Max_Support"
    },
    {
      "x": -10,
      "y": 48,
      "z": -4,
      "name": "Plant_Leaves_Beech_Max_Support"
    },
    {
      "x": -10,
      "y": 49,
      "z": -4,
      "name": "Wood_Gumboab_Trunk_Full"
    },
    {
      "x": -10,
      "y": 50,
      "z": -4,
      "name": "Wood_Gumboab_Trunk_Full"
    },
    {
      "x": -10,
      "y": 51,
      "z": -4,
      "name": "Plant_Leaves_Beech_Max_Support"
    },
    {
      "x": -10,
      "y": 52,
      "z": -4,
      "name": "Plant_Leaves_Beech_Max_Support"
    },
    {
      "x": -10,
      "y": 53,
      "z": -4,
      "name": "Plant_Leaves_Beech_Max_Support"
    },
    {
      "x": -10,
      "y": 54,
      "z": -4,
      "name": "Plant_Leaves_Beech_Max_Support"
    },
    {
      "x": -10,
      "y": 55,
      "z": -4,
      "name": "Plant_Leaves_Beech_Max_Support"
    },
    {
      "x": -10,
      "y": 48,
      "z": -3,
      "name": "Wood_Gumboab_Trunk_Full"
    },
    {
      "x": -10,
      "y": 49,
      "z": -3,
      "name": "Wood_Gumboab_Trunk_Full"
    },
    {
      "x": -10,
      "y": 50,
      "z": -3,
      "name": "Wood_Gumboab_Trunk_Full"
    },
    {
      "x": -10,
      "y": 51,
      "z": -3,
      "name": "Plant_Leaves_Beech_Max_Support"
    },
    {
      "x": -10,
      "y": 52,
      "z": -3,
      "name": "Plant_Leaves_Beech_Max_Support"
    },
    {
      "x": -10,
      "y": 53,
      "z": -3,
      "name": "Plant_Leaves_Beech_Max_Support"
    },
    {
      "x": -10,
      "y": 54,
      "z": -3,
      "name": "Plant_Leaves_Beech_Max_Support"
    },
    {
      "x": -10,
      "y": 55,
      "z": -3,
      "name": "Plant_Leaves_Beech_Max_Support"
    },
    {
      "x": -10,
      "y": 48,
      "z": -2,
      "name": "Wood_Gumboab_Trunk_Full"
    },
    {
      "x": -10,
      "y": 49,
      "z": -2,
      "name": "Wood_Gumboab_Trunk_Full"
    },
    {
      "x": -10,
      "y": 50,
      "z": -2,
      "name": "Plant_Leaves_Beech_Max_Support"
    },
    {
      "x": -10,
      "y": 51,
      "z": -2,
      "name": "Plant_Leaves_Beech_Max_Support"
    },
    {
      "x": -10,
      "y": 52,
      "z": -2,
      "name": "Plant_Leaves_Beech_Max_Support"
    },
    {
      "x": -10,
      "y": 53,
      "z": -2,
      "name": "Plant_Leaves_Beech_Max_Support"
    },
    {
      "x": -10,
      "y": 54,
      "z": -2,
      "name": "Plant_Leaves_Beech_Max_Support"
    },
    {
      "x": -10,
      "y": 48,
      "z": -1,
      "name": "Wood_Gumboab_Trunk_Full"
    },
    {
      "x": -10,
      "y": 49,
      "z": -1,
      "name": "Wood_Gumboab_Trunk_Full"
    },
    {
      "x": -10,
      "y": 50,
      "z": -1,
      "name": "Plant_Leaves_Beech_Max_Support"
    },
    {
      "x": -10,
      "y": 51,
      "z": -1,
      "name": "Plant_Leaves_Beech_Max_Support"
    },
    {
      "x": -10,
      "y": 52,
      "z": -1,
      "name": "Plant_Leaves_Beech_Max_Support"
    },
    {
      "x": -10,
      "y": 53,
      "z": -1,
      "name": "Plant_Leaves_Beech_Max_Support"
    },
    {
      "x": -10,
      "y": 54,
      "z": -1,
      "name": "Plant_Leaves_Beech_Max_Support"
    },
    {
      "x": -10,
      "y": 55,
      "z": -1,
      "name": "Plant_Leaves_Beech_Max_Support"
    },
    {
      "x": -10,
      "y": 56,
      "z": -1,
      "name": "Plant_Leaves_Beech_Max_Support"
    },
    {
      "x": -10,
      "y": 57,
      "z": -1,
      "name": "Plant_Leaves_Beech_Max_Support"
    },
    {
      "x": -10,
      "y": 38,
      "z": 0,
      "name": "Plant_Leaves_Beech_Max_Support"
    },
    {
      "x": -10,
      "y": 48,
      "z": 0,
      "name": "Wood_Gumboab_Trunk_Full"
    },
    {
      "x": -10,
      "y": 49,
      "z": 0,
      "name": "Wood_Gumboab_Trunk_Full"
    },
    {
      "x": -10,
      "y": 50,
      "z": 0,
      "name": "Plant_Leaves_Beech_Max_Support"
    },
    {
      "x": -10,
      "y": 51,
      "z": 0,
      "name": "Plant_Leaves_Beech_Max_Support"
    },
    {
      "x": -10,
      "y": 52,
      "z": 0,
      "name": "Plant_Leaves_Beech_Max_Support"
    },
    {
      "x": -10,
      "y": 53,
      "z": 0,
      "name": "Plant_Leaves_Beech_Max_Support"
    },
    {
      "x": -10,
      "y": 54,
      "z": 0,
      "name": "Plant_Leaves_Beech_Max_Support"
    },
    {
      "x": -10,
      "y": 55,
      "z": 0,
      "name": "Plant_Leaves_Beech_Max_Support"
    },
    {
      "x": -10,
      "y": 56,
      "z": 0,
      "name": "Plant_Leaves_Beech_Max_Support"
    },
    {
      "x": -10,
      "y": 38,
      "z": 1,
      "name": "Plant_Leaves_Beech_Max_Support"
    },
    {
      "x": -10,
      "y": 50,
      "z": 1,
      "name": "Plant_Leaves_Beech_Max_Support"
    },
    {
      "x": -10,
      "y": 51,
      "z": 1,
      "name": "Plant_Leaves_Beech_Max_Support"
    },
    {
      "x": -10,
      "y": 52,
      "z": 1,
      "name": "Plant_Leaves_Beech_Max_Support"
    },
    {
      "x": -10,
      "y": 53,
      "z": 1,
      "name": "Plant_Leaves_Beech_Max_Support"
    },
    {
      "x": -10,
      "y": 54,
      "z": 1,
      "name": "Plant_Leaves_Beech_Max_Support"
    },
    {
      "x": -10,
      "y": 55,
      "z": 1,
      "name": "Plant_Leaves_Beech_Max_Support"
    },
    {
      "x": -10,
      "y": 56,
      "z": 1,
      "name": "Plant_Leaves_Beech_Max_Support"
    },
    {
      "x": -10,
      "y": 38,
      "z": 2,
      "name": "Plant_Leaves_Beech_Max_Support"
    },
    {
      "x": -10,
      "y": 51,
      "z": 2,
      "name": "Plant_Leaves_Beech_Max_Support"
    },
    {
      "x": -10,
      "y": 52,
      "z": 2,
      "name": "Plant_Leaves_Beech_Max_Support"
    },
    {
      "x": -10,
      "y": 53,
      "z": 2,
      "name": "Plant_Leaves_Beech_Max_Support"
    },
    {
      "x": -10,
      "y": 54,
      "z": 2,
      "name": "Plant_Leaves_Beech_Max_Support"
    },
    {
      "x": -10,
      "y": 55,
      "z": 2,
      "name": "Plant_Leaves_Beech_Max_Support"
    },
    {
      "x": -10,
      "y": 56,
      "z": 2,
      "name": "Plant_Leaves_Beech_Max_Support"
    },
    {
      "x": -10,
      "y": 50,
      "z": 3,
      "name": "Plant_Leaves_Beech_Max_Support"
    },
    {
      "x": -10,
      "y": 51,
      "z": 3,
      "name": "Plant_Leaves_Beech_Max_Support"
    },
    {
      "x": -10,
      "y": 52,
      "z": 3,
      "name": "Plant_Leaves_Beech_Max_Support"
    },
    {
      "x": -10,
      "y": 53,
      "z": 3,
      "name": "Plant_Leaves_Beech_Max_Support"
    },
    {
      "x": -10,
      "y": 54,
      "z": 3,
      "name": "Plant_Leaves_Beech_Max_Support"
    },
    {
      "x": -10,
      "y": 55,
      "z": 3,
      "name": "Plant_Leaves_Beech_Max_Support"
    },
    {
      "x": -10,
      "y": 56,
      "z": 3,
      "name": "Plant_Leaves_Beech_Max_Support"
    },
    {
      "x": -10,
      "y": 51,
      "z": 4,
      "name": "Plant_Leaves_Beech_Max_Support"
    },
    {
      "x": -10,
      "y": 52,
      "z": 4,
      "name": "Plant_Leaves_Beech_Max_Support"
    },
    {
      "x": -10,
      "y": 53,
      "z": 4,
      "name": "Plant_Leaves_Beech_Max_Support"
    },
    {
      "x": -10,
      "y": 54,
      "z": 4,
      "name": "Plant_Leaves_Beech_Max_Support"
    },
    {
      "x": -10,
      "y": 55,
      "z": 4,
      "name": "Plant_Leaves_Beech_Max_Support"
    },
    {
      "x": -10,
      "y": 50,
      "z": 5,
      "name": "Plant_Leaves_Beech_Max_Support"
    },
    {
      "x": -10,
      "y": 51,
      "z": 5,
      "name": "Plant_Leaves_Beech_Max_Support"
    },
    {
      "x": -10,
      "y": 52,
      "z": 5,
      "name": "Plant_Leaves_Beech_Max_Support"
    },
    {
      "x": -10,
      "y": 51,
      "z": 6,
      "name": "Plant_Leaves_Beech_Max_Support"
    },
    {
      "x": -10,
      "y": 52,
      "z": 6,
      "name": "Plant_Leaves_Beech_Max_Support"
    },
    {
      "x": -10,
      "y": 53,
      "z": 6,
      "name": "Plant_Leaves_Beech_Max_Support"
    },
    {
      "x": -10,
      "y": 49,
      "z": 7,
      "name": "Plant_Leaves_Beech_Max_Support"
    },
    {
      "x": -10,
      "y": 51,
      "z": 7,
      "name": "Plant_Leaves_Beech_Max_Support"
    },
    {
      "x": -10,
      "y": 50,
      "z": 8,
      "name": "Plant_Leaves_Beech_Max_Support"
    },
    {
      "x": -10,
      "y": 53,
      "z": 8,
      "name": "Plant_Leaves_Beech_Max_Support"
    },
    {
      "x": -10,
      "y": 48,
      "z": 9,
      "name": "Plant_Leaves_Beech_Max_Support",
      "support": 15
    },
    {
      "x": -10,
      "y": 49,
      "z": 9,
      "name": "Plant_Leaves_Beech_Max_Support"
    },
    {
      "x": -10,
      "y": 50,
      "z": 9,
      "name": "Plant_Leaves_Beech_Max_Support"
    },
    {
      "x": -10,
      "y": 51,
      "z": 9,
      "name": "Plant_Leaves_Beech_Max_Support"
    },
    {
      "x": -10,
      "y": 52,
      "z": 9,
      "name": "Plant_Leaves_Beech_Max_Support"
    },
    {
      "x": -10,
      "y": 48,
      "z": 10,
      "name": "Plant_Leaves_Beech_Max_Support",
      "support": 15
    },
    {
      "x": -10,
      "y": 49,
      "z": 10,
      "name": "Plant_Leaves_Beech_Max_Support"
    },
    {
      "x": -10,
      "y": 50,
      "z": 10,
      "name": "Plant_Leaves_Beech_Max_Support"
    },
    {
      "x": -10,
      "y": 51,
      "z": 10,
      "name": "Plant_Leaves_Beech_Max_Support"
    },
    {
      "x": -10,
      "y": 48,
      "z": 11,
      "name": "Plant_Leaves_Beech_Max_Support",
      "support": 15
    },
    {
      "x": -10,
      "y": 49,
      "z": 11,
      "name": "Plant_Leaves_Beech_Max_Support"
    },
    {
      "x": -10,
      "y": 50,
      "z": 11,
      "name": "Plant_Leaves_Beech_Max_Support"
    },
    {
      "x": -9,
      "y": 48,
      "z": -9,
      "name": "Plant_Leaves_Beech_Max_Support"
    },
    {
      "x": -9,
      "y": 50,
      "z": -9,
      "name": "Plant_Leaves_Beech_Max_Support"
    },
    {
      "x": -9,
      "y": 47,
      "z": -8,
      "name": "Plant_Leaves_Beech_Max_Support"
    },
    {
      "x": -9,
      "y": 48,
      "z": -8,
      "name": "Plant_Leaves_Beech_Max_Support"
    },
    {
      "x": -9,
      "y": 49,
      "z": -8,
      "name": "Plant_Leaves_Beech_Max_Support"
    },
    {
      "x": -9,
      "y": 51,
      "z": -8,
      "name": "Plant_Leaves_Beech_Max_Support"
    },
    {
      "x": -9,
      "y": 46,
      "z": -7,
      "name": "Plant_Leaves_Beech_Max_Support"
    },
    {
      "x": -9,
      "y": 50,
      "z": -7,
      "name": "Plant_Leaves_Beech_Max_Support"
    },
    {
      "x": -9,
      "y": 52,
      "z": -7,
      "name": "Plant_Leaves_Beech_Max_Support"
    },
    {
      "x": -9,
      "y": 46,
      "z": -6,
      "name": "Plant_Leaves_Beech_Max_Support"
    },
    {
      "x": -9,
      "y": 48,
      "z": -6,
      "name": "Plant_Leaves_Beech_Max_Support"
    },
    {
      "x": -9,
      "y": 49,
      "z": -6,
      "name": "Plant_Leaves_Beech_Max_Support"
    },
    {
      "x": -9,
      "y": 51,
      "z": -6,
      "name": "Plant_Leaves_Beech_Max_Support"
    },
    {
      "x": -9,
      "y": 49,
      "z": -5,
      "name": "Plant_Leaves_Beech_Max_Support"
    },
    {
      "x": -9,
      "y": 50,
      "z": -5,
      "name": "Wood_Gumboab_Trunk_Full"
    },
    {
      "x": -9,
      "y": 51,
      "z": -5,
      "name": "Plant_Leaves_Beech_Max_Support"
    },
    {
      "x": -9,
      "y": 52,
      "z": -5,
      "name": "Plant_Leaves_Beech_Max_Support"
    },
    {
      "x": -9,
      "y": 48,
      "z": -4,
      "name": "Plant_Leaves_Beech_Max_Support"
    },
    {
      "x": -9,
      "y": 49,
      "z": -4,
      "name": "Wood_Gumboab_Trunk_Full"
    },
    {
      "x": -9,
      "y": 50,
      "z": -4,
      "name": "Wood_Gumboab_Trunk_Full"
    },
    {
      "x": -9,
      "y": 51,
      "z": -4,
      "name": "Plant_Leaves_Beech_Max_Support"
    },
    {
      "x": -9,
      "y": 52,
      "z": -4,
      "name": "Plant_Leaves_Beech_Max_Support"
    },
    {
      "x": -9,
      "y": 53,
      "z": -4,
      "name": "Plant_Leaves_Beech_Max_Support"
    },
    {
      "x": -9,
      "y": 54,
      "z": -4,
      "name": "Plant_Leaves_Beech_Max_Support"
    },
    {
      "x": -9,
      "y": 49,
      "z": -3,
      "name": "Plant_Leaves_Beech_Max_Support"
    },
    {
      "x": -9,
      "y": 50,
      "z": -3,
      "name": "Plant_Leaves_Beech_Max_Support"
    },
    {
      "x": -9,
      "y": 51,
      "z": -3,
      "name": "Plant_Leaves_Beech_Max_Support"
    },
    {
      "x": -9,
      "y": 52,
      "z": -3,
      "name": "Plant_Leaves_Beech_Max_Support"
    },
    {
      "x": -9,
      "y": 53,
      "z": -3,
      "name": "Plant_Leaves_Beech_Max_Support"
    },
    {
      "x": -9,
      "y": 54,
      "z": -3,
      "name": "Plant_Leaves_Beech_Max_Support"
    },
    {
      "x": -9,
      "y": 56,
      "z": -3,
      "name": "Plant_Leaves_Beech_Max_Support"
    },
    {
      "x": -9,
      "y": 49,
      "z": -2,
      "name": "Plant_Leaves_Beech_Max_Support"
    },
    {
      "x": -9,
      "y": 50,
      "z": -2,
      "name": "Plant_Leaves_Beech_Max_Support"
    },
    {
      "x": -9,
      "y": 51,
      "z": -2,
      "name": "Plant_Leaves_Beech_Max_Support"
    },
    {
      "x": -9,
      "y": 52,
      "z": -2,
      "name": "Plant_Leaves_Beech_Max_Support"
    },
    {
      "x": -9,
      "y": 53,
      "z": -2,
      "name": "Plant_Leaves_Beech_Max_Support"
    },
    {
      "x": -9,
      "y": 54,
      "z": -2,
      "name": "Plant_Leaves_Beech_Max_Support"
    },
    {
      "x": -9,
      "y": 56,
      "z": -2,
      "name": "Plant_Leaves_Beech_Max_Support"
    },
    {
      "x": -9,
      "y": 57,
      "z": -2,
      "name": "Plant_Leaves_Beech_Max_Support"
    },
    {
      "x": -9,
      "y": 47,
      "z": -1,
      "name": "Wood_Gumboab_Roots"
    },
    {
      "x": -9,
      "y": 48,
      "z": -1,
      "name": "Wood_Gumboab_Trunk_Full"
    },
    {
      "x": -9,
      "y": 49,
      "z": -1,
      "name": "Wood_Gumboab_Trunk_Full"
    },
    {
      "x": -9,
      "y": 51,
      "z": -1,
      "name": "Plant_Leaves_Beech_Max_Support"
    },
    {
      "x": -9,
      "y": 52,
      "z": -1,
      "name": "Plant_Leaves_Beech_Max_Support"
    },
    {
      "x": -9,
      "y": 53,
      "z": -1,
      "name": "Plant_Leaves_Beech_Max_Support"
    },
    {
      "x": -9,
      "y": 54,
      "z": -1,
      "name": "Plant_Leaves_Beech_Max_Support"
    },
    {
      "x": -9,
      "y": 56,
      "z": -1,
      "name": "Plant_Leaves_Beech_Max_Support"
    },
    {
      "x": -9,
      "y": 37,
      "z": 0,
      "name": "Plant_Leaves_Beech_Max_Support"
    },
    {
      "x": -9,
      "y": 39,
      "z": 0,
      "name": "Plant_Leaves_Beech_Max_Support"
    },
    {
      "x": -9,
      "y": 48,
      "z": 0,
      "name": "Wood_Gumboab_Trunk_Full"
    },
    {
      "x": -9,
      "y": 49,
      "z": 0,
      "name": "Wood_Gumboab_Trunk_Full"
    },
    {
      "x": -9,
      "y": 50,
      "z": 0,
      "name": "Plant_Leaves_Beech_Max_Support"
    },
    {
      "x": -9,
      "y": 51,
      "z": 0,
      "name": "Plant_Leaves_Beech_Max_Support"
    },
    {
      "x": -9,
      "y": 52,
      "z": 0,
      "name": "Plant_Leaves_Beech_Max_Support"
    },
    {
      "x": -9,
      "y": 53,
      "z": 0,
      "name": "Plant_Leaves_Beech_Max_Support"
    },
    {
      "x": -9,
      "y": 54,
      "z": 0,
      "name": "Plant_Leaves_Beech_Max_Support"
    },
    {
      "x": -9,
      "y": 55,
      "z": 0,
      "name": "Plant_Leaves_Beech_Max_Support"
    },
    {
      "x": -9,
      "y": 56,
      "z": 0,
      "name": "Plant_Leaves_Beech_Max_Support"
    },
    {
      "x": -9,
      "y": 57,
      "z": 0,
      "name": "Plant_Leaves_Beech_Max_Support"
    },
    {
      "x": -9,
      "y": 36,
      "z": 1,
      "name": "Plant_Leaves_Beech_Max_Support"
    },
    {
      "x": -9,
      "y": 38,
      "z": 1,
      "name": "Plant_Leaves_Beech_Max_Support"
    },
    {
      "x": -9,
      "y": 39,
      "z": 1,
      "name": "Plant_Leaves_Beech_Max_Support"
    },
    {
      "x": -9,
      "y": 40,
      "z": 1,
      "name": "Plant_Leaves_Beech_Max_Support"
    },
    {
      "x": -9,
      "y": 48,
      "z": 1,
      "name": "Wood_Gumboab_Trunk_Full"
    },
    {
      "x": -9,
      "y": 49,
      "z": 1,
      "name": "Wood_Gumboab_Trunk_Full"
    },
    {
      "x": -9,
      "y": 50,
      "z": 1,
      "name": "Plant_Leaves_Beech_Max_Support"
    },
    {
      "x": -9,
      "y": 51,
      "z": 1,
      "name": "Plant_Leaves_Beech_Max_Support"
    },
    {
      "x": -9,
      "y": 52,
      "z": 1,
      "name": "Plant_Leaves_Beech_Max_Support"
    },
    {
      "x": -9,
      "y": 53,
      "z": 1,
      "name": "Plant_Leaves_Beech_Max_Support"
    },
    {
      "x": -9,
      "y": 54,
      "z": 1,
      "name": "Plant_Leaves_Beech_Max_Support"
    },
    {
      "x": -9,
      "y": 55,
      "z": 1,
      "name": "Plant_Leaves_Beech_Max_Support"
    },
    {
      "x": -9,
      "y": 56,
      "z": 1,
      "name": "Plant_Leaves_Beech_Max_Support"
    },
    {
      "x": -9,
      "y": 39,
      "z": 2,
      "name": "Plant_Leaves_Beech_Max_Support"
    },
    {
      "x": -9,
      "y": 50,
      "z": 2,
      "name": "Wood_Gumboab_Trunk_Full"
    },
    {
      "x": -9,
      "y": 51,
      "z": 2,
      "name": "Wood_Gumboab_Trunk_Full"
    },
    {
      "x": -9,
      "y": 52,
      "z": 2,
      "name": "Plant_Leaves_Beech_Max_Support"
    },
    {
      "x": -9,
      "y": 53,
      "z": 2,
      "name": "Plant_Leaves_Beech_Max_Support"
    },
    {
      "x": -9,
      "y": 54,
      "z": 2,
      "name": "Plant_Leaves_Beech_Max_Support"
    },
    {
      "x": -9,
      "y": 55,
      "z": 2,
      "name": "Plant_Leaves_Beech_Max_Support"
    },
    {
      "x": -9,
      "y": 56,
      "z": 2,
      "name": "Plant_Leaves_Beech_Max_Support"
    },
    {
      "x": -9,
      "y": 38,
      "z": 3,
      "name": "Plant_Leaves_Beech_Max_Support"
    },
    {
      "x": -9,
      "y": 49,
      "z": 3,
      "name": "Plant_Leaves_Beech_Max_Support"
    },
    {
      "x": -9,
      "y": 50,
      "z": 3,
      "name": "Wood_Gumboab_Trunk_Full"
    },
    {
      "x": -9,
      "y": 51,
      "z": 3,
      "name": "Wood_Gumboab_Trunk_Full"
    },
    {
      "x": -9,
      "y": 52,
      "z": 3,
      "name": "Plant_Leaves_Beech_Max_Support"
    },
    {
      "x": -9,
      "y": 53,
      "z": 3,
      "name": "Plant_Leaves_Beech_Max_Support"
    },
    {
      "x": -9,
      "y": 55,
      "z": 3,
      "name": "Plant_Leaves_Beech_Max_Support"
    },
    {
      "x": -9,
      "y": 56,
      "z": 3,
      "name": "Plant_Leaves_Beech_Max_Support"
    },
    {
      "x": -9,
      "y": 40,
      "z": 4,
      "name": "Plant_Leaves_Beech_Max_Support"
    },
    {
      "x": -9,
      "y": 50,
      "z": 4,
      "name": "Plant_Leaves_Beech_Max_Support"
    },
    {
      "x": -9,
      "y": 51,
      "z": 4,
      "name": "Plant_Leaves_Beech_Max_Support"
    },
    {
      "x": -9,
      "y": 52,
      "z": 4,
      "name": "Plant_Leaves_Beech_Max_Support"
    },
    {
      "x": -9,
      "y": 53,
      "z": 4,
      "name": "Plant_Leaves_Beech_Max_Support"
    },
    {
      "x": -9,
      "y": 54,
      "z": 4,
      "name": "Plant_Leaves_Beech_Max_Support"
    },
    {
      "x": -9,
      "y": 55,
      "z": 4,
      "name": "Plant_Leaves_Beech_Max_Support"
    },
    {
      "x": -9,
      "y": 40,
      "z": 5,
      "name": "Plant_Leaves_Beech_Max_Support"
    },
    {
      "x": -9,
      "y": 41,
      "z": 5,
      "name": "Plant_Leaves_Beech_Max_Support"
    },
    {
      "x": -9,
      "y": 51,
      "z": 5,
      "name": "Plant_Leaves_Beech_Max_Support"
    },
    {
      "x": -9,
      "y": 52,
      "z": 5,
      "name": "Plant_Leaves_Beech_Max_Support"
    },
    {
      "x": -9,
      "y": 53,
      "z": 5,
      "name": "Plant_Leaves_Beech_Max_Support"
    },
    {
      "x": -9,
      "y": 55,
      "z": 5,
      "name": "Plant_Leaves_Beech_Max_Support"
    },
    {
      "x": -9,
      "y": 38,
      "z": 6,
      "name": "Plant_Leaves_Beech_Max_Support",
      "support": 15
    },
    {
      "x": -9,
      "y": 40,
      "z": 6,
      "name": "Plant_Leaves_Beech_Max_Support"
    },
    {
      "x": -9,
      "y": 50,
      "z": 6,
      "name": "Plant_Leaves_Beech_Max_Support"
    },
    {
      "x": -9,
      "y": 51,
      "z": 6,
      "name": "Plant_Leaves_Beech_Max_Support"
    },
    {
      "x": -9,
      "y": 52,
      "z": 6,
      "name": "Plant_Leaves_Beech_Max_Support"
    },
    {
      "x": -9,
      "y": 53,
      "z": 6,
      "name": "Plant_Leaves_Beech_Max_Support"
    },
    {
      "x": -9,
      "y": 54,
      "z": 6,
      "name": "Plant_Leaves_Beech_Max_Support"
    },
    {
      "x": -9,
      "y": 48,
      "z": 7,
      "name": "Plant_Leaves_Beech_Max_Support"
    },
    {
      "x": -9,
      "y": 50,
      "z": 7,
      "name": "Plant_Leaves_Beech_Max_Support"
    },
    {
      "x": -9,
      "y": 51,
      "z": 7,
      "name": "Plant_Leaves_Beech_Max_Support"
    },
    {
      "x": -9,
      "y": 52,
      "z": 7,
      "name": "Plant_Leaves_Beech_Max_Support"
    },
    {
      "x": -9,
      "y": 53,
      "z": 7,
      "name": "Plant_Leaves_Beech_Max_Support"
    },
    {
      "x": -9,
      "y": 48,
      "z": 8,
      "name": "Plant_Leaves_Beech_Max_Support"
    },
    {
      "x": -9,
      "y": 49,
      "z": 8,
      "name": "Plant_Leaves_Beech_Max_Support"
    },
    {
      "x": -9,
      "y": 50,
      "z": 8,
      "name": "Plant_Leaves_Beech_Max_Support"
    },
    {
      "x": -9,
      "y": 51,
      "z": 8,
      "name": "Plant_Leaves_Beech_Max_Support"
    },
    {
      "x": -9,
      "y": 54,
      "z": 8,
      "name": "Plant_Leaves_Beech_Max_Support"
    },
    {
      "x": -9,
      "y": 48,
      "z": 9,
      "name": "Plant_Leaves_Beech_Max_Support"
    },
    {
      "x": -9,
      "y": 49,
      "z": 9,
      "name": "Plant_Leaves_Beech_Max_Support"
    },
    {
      "x": -9,
      "y": 50,
      "z": 9,
      "name": "Plant_Leaves_Beech_Max_Support"
    },
    {
      "x": -9,
      "y": 51,
      "z": 9,
      "name": "Plant_Leaves_Beech_Max_Support"
    },
    {
      "x": -9,
      "y": 52,
      "z": 9,
      "name": "Plant_Leaves_Beech_Max_Support"
    },
    {
      "x": -9,
      "y": 47,
      "z": 10,
      "name": "Plant_Leaves_Beech_Max_Support",
      "support": 15
    },
    {
      "x": -9,
      "y": 48,
      "z": 10,
      "name": "Plant_Leaves_Beech_Max_Support"
    },
    {
      "x": -9,
      "y": 49,
      "z": 10,
      "name": "Plant_Leaves_Beech_Max_Support"
    },
    {
      "x": -9,
      "y": 50,
      "z": 10,
      "name": "Plant_Leaves_Beech_Max_Support"
    },
    {
      "x": -9,
      "y": 51,
      "z": 10,
      "name": "Plant_Leaves_Beech_Max_Support"
    },
    {
      "x": -9,
      "y": 52,
      "z": 10,
      "name": "Plant_Leaves_Beech_Max_Support"
    },
    {
      "x": -9,
      "y": 47,
      "z": 11,
      "name": "Plant_Leaves_Beech_Max_Support",
      "support": 15
    },
    {
      "x": -9,
      "y": 48,
      "z": 11,
      "name": "Plant_Leaves_Beech_Max_Support",
      "support": 15
    },
    {
      "x": -9,
      "y": 50,
      "z": 11,
      "name": "Plant_Leaves_Beech_Max_Support"
    },
    {
      "x": -9,
      "y": 51,
      "z": 11,
      "name": "Plant_Leaves_Beech_Max_Support"
    },
    {
      "x": -9,
      "y": 52,
      "z": 11,
      "name": "Plant_Leaves_Beech_Max_Support"
    },
    {
      "x": -9,
      "y": 47,
      "z": 12,
      "name": "Plant_Leaves_Beech_Max_Support",
      "support": 15
    },
    {
      "x": -9,
      "y": 50,
      "z": 12,
      "name": "Plant_Leaves_Beech_Max_Support"
    },
    {
      "x": -9,
      "y": 51,
      "z": 12,
      "name": "Plant_Leaves_Beech_Max_Support"
    },
    {
      "x": -8,
      "y": 48,
      "z": -8,
      "name": "Plant_Leaves_Beech_Max_Support"
    },
    {
      "x": -8,
      "y": 49,
      "z": -8,
      "name": "Plant_Leaves_Beech_Max_Support"
    },
    {
      "x": -8,
      "y": 50,
      "z": -8,
      "name": "Plant_Leaves_Beech_Max_Support"
    },
    {
      "x": -8,
      "y": 47,
      "z": -7,
      "name": "Plant_Leaves_Beech_Max_Support"
    },
    {
      "x": -8,
      "y": 48,
      "z": -7,
      "name": "Plant_Leaves_Beech_Max_Support"
    },
    {
      "x": -8,
      "y": 48,
      "z": -6,
      "name": "Plant_Leaves_Beech_Max_Support"
    },
    {
      "x": -8,
      "y": 49,
      "z": -6,
      "name": "Plant_Leaves_Beech_Max_Support"
    },
    {
      "x": -8,
      "y": 51,
      "z": -6,
      "name": "Plant_Leaves_Beech_Max_Support"
    },
    {
      "x": -8,
      "y": 47,
      "z": -5,
      "name": "Plant_Leaves_Beech_Max_Support"
    },
    {
      "x": -8,
      "y": 48,
      "z": -5,
      "name": "Plant_Leaves_Beech_Max_Support"
    },
    {
      "x": -8,
      "y": 49,
      "z": -5,
      "name": "Plant_Leaves_Beech_Max_Support"
    },
    {
      "x": -8,
      "y": 50,
      "z": -5,
      "name": "Wood_Gumboab_Trunk_Full"
    },
    {
      "x": -8,
      "y": 51,
      "z": -5,
      "name": "Wood_Gumboab_Trunk_Full"
    },
    {
      "x": -8,
      "y": 48,
      "z": -4,
      "name": "Plant_Leaves_Beech_Max_Support"
    },
    {
      "x": -8,
      "y": 49,
      "z": -4,
      "name": "Plant_Leaves_Beech_Max_Support"
    },
    {
      "x": -8,
      "y": 50,
      "z": -4,
      "name": "Wood_Gumboab_Trunk_Full"
    },
    {
      "x": -8,
      "y": 51,
      "z": -4,
      "name": "Plant_Leaves_Beech_Max_Support"
    },
    {
      "x": -8,
      "y": 53,
      "z": -4,
      "name": "Plant_Leaves_Beech_Max_Support"
    },
    {
      "x": -8,
      "y": 48,
      "z": -3,
      "name": "Plant_Leaves_Beech_Max_Support"
    },
    {
      "x": -8,
      "y": 49,
      "z": -3,
      "name": "Plant_Leaves_Beech_Max_Support"
    },
    {
      "x": -8,
      "y": 50,
      "z": -3,
      "name": "Plant_Leaves_Beech_Max_Support"
    },
    {
      "x": -8,
      "y": 51,
      "z": -3,
      "name": "Plant_Leaves_Beech_Max_Support"
    },
    {
      "x": -8,
      "y": 52,
      "z": -3,
      "name": "Plant_Leaves_Beech_Max_Support"
    },
    {
      "x": -8,
      "y": 53,
      "z": -3,
      "name": "Plant_Leaves_Beech_Max_Support"
    },
    {
      "x": -8,
      "y": 54,
      "z": -3,
      "name": "Plant_Leaves_Beech_Max_Support"
    },
    {
      "x": -8,
      "y": 38,
      "z": -2,
      "name": "Plant_Leaves_Beech_Max_Support",
      "support": 15
    },
    {
      "x": -8,
      "y": 48,
      "z": -2,
      "name": "Plant_Leaves_Beech_Max_Support"
    },
    {
      "x": -8,
      "y": 50,
      "z": -2,
      "name": "Plant_Leaves_Beech_Max_Support"
    },
    {
      "x": -8,
      "y": 51,
      "z": -2,
      "name": "Plant_Leaves_Beech_Max_Support"
    },
    {
      "x": -8,
      "y": 52,
      "z": -2,
      "name": "Plant_Leaves_Beech_Max_Support"
    },
    {
      "x": -8,
      "y": 53,
      "z": -2,
      "name": "Plant_Leaves_Beech_Max_Support"
    },
    {
      "x": -8,
      "y": 54,
      "z": -2,
      "name": "Plant_Leaves_Beech_Max_Support"
    },
    {
      "x": -8,
      "y": 55,
      "z": -2,
      "name": "Plant_Leaves_Beech_Max_Support"
    },
    {
      "x": -8,
      "y": 56,
      "z": -2,
      "name": "Plant_Leaves_Beech_Max_Support"
    },
    {
      "x": -8,
      "y": 36,
      "z": -1,
      "name": "Plant_Leaves_Beech_Max_Support",
      "support": 15
    },
    {
      "x": -8,
      "y": 37,
      "z": -1,
      "name": "Plant_Leaves_Beech_Max_Support"
    },
    {
      "x": -8,
      "y": 38,
      "z": -1,
      "name": "Plant_Leaves_Beech_Max_Support"
    },
    {
      "x": -8,
      "y": 39,
      "z": -1,
      "name": "Plant_Leaves_Beech_Max_Support"
    },
    {
      "x": -8,
      "y": 48,
      "z": -1,
      "name": "Wood_Gumboab_Trunk_Full"
    },
    {
      "x": -8,
      "y": 50,
      "z": -1,
      "name": "Plant_Leaves_Beech_Max_Support"
    },
    {
      "x": -8,
      "y": 51,
      "z": -1,
      "name": "Plant_Leaves_Beech_Max_Support"
    },
    {
      "x": -8,
      "y": 52,
      "z": -1,
      "name": "Plant_Leaves_Beech_Max_Support"
    },
    {
      "x": -8,
      "y": 53,
      "z": -1,
      "name": "Plant_Leaves_Beech_Max_Support"
    },
    {
      "x": -8,
      "y": 54,
      "z": -1,
      "name": "Plant_Leaves_Beech_Max_Support"
    },
    {
      "x": -8,
      "y": 55,
      "z": -1,
      "name": "Plant_Leaves_Beech_Max_Support"
    },
    {
      "x": -8,
      "y": 56,
      "z": -1,
      "name": "Plant_Leaves_Beech_Max_Support"
    },
    {
      "x": -8,
      "y": 36,
      "z": 0,
      "name": "Plant_Leaves_Beech_Max_Support"
    },
    {
      "x": -8,
      "y": 38,
      "z": 0,
      "name": "Plant_Leaves_Beech_Max_Support"
    },
    {
      "x": -8,
      "y": 39,
      "z": 0,
      "name": "Plant_Leaves_Beech_Max_Support"
    },
    {
      "x": -8,
      "y": 48,
      "z": 0,
      "name": "Wood_Gumboab_Trunk_Full"
    },
    {
      "x": -8,
      "y": 49,
      "z": 0,
      "name": "Wood_Gumboab_Trunk_Full"
    },
    {
      "x": -8,
      "y": 51,
      "z": 0,
      "name": "Plant_Leaves_Beech_Max_Support"
    },
    {
      "x": -8,
      "y": 52,
      "z": 0,
      "name": "Plant_Leaves_Beech_Max_Support"
    },
    {
      "x": -8,
      "y": 53,
      "z": 0,
      "name": "Plant_Leaves_Beech_Max_Support"
    },
    {
      "x": -8,
      "y": 54,
      "z": 0,
      "name": "Plant_Leaves_Beech_Max_Support"
    },
    {
      "x": -8,
      "y": 55,
      "z": 0,
      "name": "Plant_Leaves_Beech_Max_Support"
    },
    {
      "x": -8,
      "y": 56,
      "z": 0,
      "name": "Plant_Leaves_Beech_Max_Support"
    },
    {
      "x": -8,
      "y": 38,
      "z": 1,
      "name": "Plant_Leaves_Beech_Max_Support"
    },
    {
      "x": -8,
      "y": 39,
      "z": 1,
      "name": "Plant_Leaves_Beech_Max_Support"
    },
    {
      "x": -8,
      "y": 40,
      "z": 1,
      "name": "Plant_Leaves_Beech_Max_Support"
    },
    {
      "x": -8,
      "y": 48,
      "z": 1,
      "name": "Wood_Gumboab_Trunk_Full"
    },
    {
      "x": -8,
      "y": 49,
      "z": 1,
      "name": "Wood_Gumboab_Trunk_Full"
    },
    {
      "x": -8,
      "y": 50,
