{
  "version": 8,
  "blockIdVersion": 11,
  "anchorX": 3,
  "anchorY": 10,
  "anchorZ": 2,
  "blocks": [
    {
      "x": -16,
      "y": 39,
      "z": -3,
      "name": "Plant_Leaves_Jungle_Max_Support"
    },
    {
      "x": -16,
      "y": 40,
      "z": -3,
      "name": "Plant_Leaves_Jungle_Max_Support"
    },
    {
      "x": -16,
      "y": 38,
      "z": -2,
      "name": "Plant_Leaves_Jungle_Max_Support"
    },
    {
      "x": -16,
      "y": 39,
      "z": -2,
      "name": "Plant_Leaves_Jungle_Max_Support"
    },
    {
      "x": -16,
      "y": 40,
      "z": -2,
      "name": "Plant_Leaves_Jungle_Max_Support"
    },
    {
      "x": -16,
      "y": 39,
      "z": -1,
      "name": "Plant_Leaves_Jungle_Max_Support"
    },
    {
      "x": -16,
      "y": 40,
      "z": -1,
      "name": "Plant_Leaves_Jungle_Max_Support"
    },
    {
      "x": -15,
      "y": 38,
      "z": -4,
      "name": "Plant_Leaves_Jungle_Max_Support"
    },
    {
      "x": -15,
      "y": 39,
      "z": -4,
      "name": "Plant_Leaves_Jungle_Max_Support"
    },
    {
      "x": -15,
      "y": 37,
      "z": -3,
      "name": "Plant_Leaves_Jungle_Max_Support"
    },
    {
      "x": -15,
      "y": 38,
      "z": -3,
      "name": "Plant_Leaves_Jungle_Max_Support"
    },
    {
      "x": -15,
      "y": 41,
      "z": -3,
      "name": "Plant_Leaves_Jungle_Max_Support"
    },
    {
      "x": -15,
      "y": 37,
      "z": -2,
      "name": "Plant_Leaves_Jungle_Max_Support"
    },
    {
      "x": -15,
      "y": 40,
      "z": -2,
      "name": "Plant_Leaves_Jungle_Max_Support"
    },
    {
      "x": -15,
      "y": 37,
      "z": -1,
      "name": "Plant_Leaves_Jungle_Max_Support"
    },
    {
      "x": -15,
      "y": 38,
      "z": -1,
      "name": "Plant_Leaves_Jungle_Max_Support"
    },
    {
      "x": -15,
      "y": 41,
      "z": -1,
      "name": "Plant_Leaves_Jungle_Max_Support"
    },
    {
      "x": -15,
      "y": 39,
      "z": 0,
      "name": "Plant_Leaves_Jungle_Max_Support"
    },
    {
      "x": -15,
      "y": 40,
      "z": 0,
      "name": "Plant_Leaves_Jungle_Max_Support"
    },
    {
      "x": -15,
      "y": 37,
      "z": 4,
      "name": "Plant_Leaves_Jungle_Max_Support"
    },
    {
      "x": -15,
      "y": 38,
      "z": 4,
      "name": "Plant_Leaves_Jungle_Max_Support"
    },
    {
      "x": -15,
      "y": 39,
      "z": 4,
      "name": "Plant_Leaves_Jungle_Max_Support"
    },
    {
      "x": -15,
      "y": 38,
      "z": 5,
      "name": "Plant_Leaves_Jungle_Max_Support"
    },
    {
      "x": -15,
      "y": 39,
      "z": 6,
      "name": "Plant_Leaves_Jungle_Max_Support"
    },
    {
      "x": -15,
      "y": 40,
      "z": 6,
      "name": "Plant_Leaves_Jungle_Max_Support"
    },
    {
      "x": -15,
      "y": 41,
      "z": 6,
      "name": "Plant_Leaves_Jungle_Max_Support"
    },
    {
      "x": -15,
      "y": 40,
      "z": 7,
      "name": "Plant_Leaves_Jungle_Max_Support"
    },
    {
      "x": -14,
      "y": 38,
      "z": -5,
      "name": "Plant_Leaves_Jungle_Max_Support"
    },
    {
      "x": -14,
      "y": 39,
      "z": -5,
      "name": "Plant_Leaves_Jungle_Max_Support"
    },
    {
      "x": -14,
      "y": 40,
      "z": -5,
      "name": "Plant_Leaves_Jungle_Max_Support"
    },
    {
      "x": -14,
      "y": 41,
      "z": -4,
      "name": "Plant_Leaves_Jungle_Max_Support"
    },
    {
      "x": -14,
      "y": 37,
      "z": -3,
      "name": "Plant_Leaves_Jungle_Max_Support"
    },
    {
      "x": -14,
      "y": 38,
      "z": -3,
      "name": "Plant_Leaves_Jungle_Max_Support"
    },
    {
      "x": -14,
      "y": 39,
      "z": -3,
      "name": "Plant_Leaves_Jungle_Max_Support"
    },
    {
      "x": -14,
      "y": 42,
      "z": -3,
      "name": "Plant_Leaves_Jungle_Max_Support"
    },
    {
      "x": -14,
      "y": 36,
      "z": -2,
      "name": "Plant_Leaves_Jungle_Max_Support"
    },
    {
      "x": -14,
      "y": 37,
      "z": -2,
      "name": "Plant_Leaves_Jungle_Max_Support"
    },
    {
      "x": -14,
      "y": 42,
      "z": -2,
      "name": "Plant_Leaves_Jungle_Max_Support"
    },
    {
      "x": -14,
      "y": 36,
      "z": -1,
      "name": "Plant_Leaves_Jungle_Max_Support"
    },
    {
      "x": -14,
      "y": 37,
      "z": -1,
      "name": "Plant_Leaves_Jungle_Max_Support"
    },
    {
      "x": -14,
      "y": 39,
      "z": -1,
      "name": "Plant_Leaves_Jungle_Max_Support"
    },
    {
      "x": -14,
      "y": 42,
      "z": -1,
      "name": "Plant_Leaves_Jungle_Max_Support"
    },
    {
      "x": -14,
      "y": 37,
      "z": 0,
      "name": "Plant_Leaves_Jungle_Max_Support"
    },
    {
      "x": -14,
      "y": 38,
      "z": 0,
      "name": "Plant_Leaves_Jungle_Max_Support"
    },
    {
      "x": -14,
      "y": 39,
      "z": 0,
      "name": "Plant_Leaves_Jungle_Max_Support"
    },
    {
      "x": -14,
      "y": 41,
      "z": 0,
      "name": "Plant_Leaves_Jungle_Max_Support"
    },
    {
      "x": -14,
      "y": 38,
      "z": 1,
      "name": "Plant_Leaves_Jungle_Max_Support"
    },
    {
      "x": -14,
      "y": 39,
      "z": 1,
      "name": "Plant_Leaves_Jungle_Max_Support"
    },
    {
      "x": -14,
      "y": 38,
      "z": 2,
      "name": "Plant_Leaves_Jungle_Max_Support"
    },
    {
      "x": -14,
      "y": 36,
      "z": 4,
      "name": "Plant_Leaves_Jungle_Max_Support"
    },
    {
      "x": -14,
      "y": 37,
      "z": 4,
      "name": "Plant_Leaves_Jungle_Max_Support"
    },
    {
      "x": -14,
      "y": 40,
      "z": 4,
      "name": "Plant_Leaves_Jungle_Max_Support"
    },
    {
      "x": -14,
      "y": 38,
      "z": 5,
      "name": "Plant_Leaves_Jungle_Max_Support"
    },
    {
      "x": -14,
      "y": 39,
      "z": 5,
      "name": "Plant_Leaves_Jungle_Max_Support"
    },
    {
      "x": -14,
      "y": 40,
      "z": 5,
      "name": "Plant_Leaves_Jungle_Max_Support"
    },
    {
      "x": -14,
      "y": 38,
      "z": 6,
      "name": "Plant_Leaves_Jungle_Max_Support"
    },
    {
      "x": -14,
      "y": 39,
      "z": 6,
      "name": "Plant_Leaves_Jungle_Max_Support"
    },
    {
      "x": -14,
      "y": 39,
      "z": 7,
      "name": "Plant_Leaves_Jungle_Max_Support"
    },
    {
      "x": -14,
      "y": 40,
      "z": 7,
      "name": "Plant_Leaves_Jungle_Max_Support"
    },
    {
      "x": -14,
      "y": 41,
      "z": 7,
      "name": "Plant_Leaves_Jungle_Max_Support"
    },
    {
      "x": -13,
      "y": 37,
      "z": -10,
      "name": "Plant_Leaves_Jungle_Max_Support"
    },
    {
      "x": -13,
      "y": 36,
      "z": -9,
      "name": "Plant_Leaves_Jungle_Max_Support"
    },
    {
      "x": -13,
      "y": 37,
      "z": -9,
      "name": "Plant_Leaves_Jungle_Max_Support"
    },
    {
      "x": -13,
      "y": 38,
      "z": -9,
      "name": "Plant_Leaves_Jungle_Max_Support"
    },
    {
      "x": -13,
      "y": 37,
      "z": -8,
      "name": "Plant_Leaves_Jungle_Max_Support"
    },
    {
      "x": -13,
      "y": 38,
      "z": -5,
      "name": "Plant_Leaves_Jungle_Max_Support"
    },
    {
      "x": -13,
      "y": 39,
      "z": -5,
      "name": "Plant_Leaves_Jungle_Max_Support"
    },
    {
      "x": -13,
      "y": 40,
      "z": -4,
      "name": "Plant_Leaves_Jungle_Max_Support"
    },
    {
      "x": -13,
      "y": 36,
      "z": -3,
      "name": "Plant_Leaves_Jungle_Max_Support"
    },
    {
      "x": -13,
      "y": 38,
      "z": -3,
      "name": "Plant_Leaves_Jungle_Max_Support"
    },
    {
      "x": -13,
      "y": 39,
      "z": -3,
      "name": "Plant_Leaves_Jungle_Max_Support"
    },
    {
      "x": -13,
      "y": 40,
      "z": -3,
      "name": "Plant_Leaves_Jungle_Max_Support"
    },
    {
      "x": -13,
      "y": 42,
      "z": -3,
      "name": "Plant_Leaves_Jungle_Max_Support"
    },
    {
      "x": -13,
      "y": 36,
      "z": -2,
      "name": "Plant_Leaves_Jungle_Max_Support"
    },
    {
      "x": -13,
      "y": 37,
      "z": -2,
      "name": "Plant_Leaves_Jungle_Max_Support"
    },
    {
      "x": -13,
      "y": 38,
      "z": -2,
      "name": "Plant_Leaves_Jungle_Max_Support"
    },
    {
      "x": -13,
      "y": 39,
      "z": -2,
      "name": "Plant_Leaves_Jungle_Max_Support"
    },
    {
      "x": -13,
      "y": 40,
      "z": -2,
      "name": "Plant_Leaves_Jungle_Max_Support"
    },
    {
      "x": -13,
      "y": 42,
      "z": -2,
      "name": "Plant_Leaves_Jungle_Max_Support"
    },
    {
      "x": -13,
      "y": 36,
      "z": -1,
      "name": "Plant_Leaves_Jungle_Max_Support"
    },
    {
      "x": -13,
      "y": 39,
      "z": -1,
      "name": "Plant_Leaves_Jungle_Max_Support"
    },
    {
      "x": -13,
      "y": 41,
      "z": -1,
      "name": "Plant_Leaves_Jungle_Max_Support"
    },
    {
      "x": -13,
      "y": 42,
      "z": -1,
      "name": "Plant_Leaves_Jungle_Max_Support"
    },
    {
      "x": -13,
      "y": 37,
      "z": 0,
      "name": "Plant_Leaves_Jungle_Max_Support"
    },
    {
      "x": -13,
      "y": 38,
      "z": 0,
      "name": "Plant_Leaves_Jungle_Max_Support"
    },
    {
      "x": -13,
      "y": 39,
      "z": 0,
      "name": "Plant_Leaves_Jungle_Max_Support"
    },
    {
      "x": -13,
      "y": 40,
      "z": 0,
      "name": "Plant_Leaves_Jungle_Max_Support"
    },
    {
      "x": -13,
      "y": 41,
      "z": 0,
      "name": "Plant_Leaves_Jungle_Max_Support"
    },
    {
      "x": -13,
      "y": 38,
      "z": 1,
      "name": "Plant_Leaves_Jungle_Max_Support"
    },
    {
      "x": -13,
      "y": 39,
      "z": 1,
      "name": "Plant_Leaves_Jungle_Max_Support"
    },
    {
      "x": -13,
      "y": 37,
      "z": 2,
      "name": "Plant_Leaves_Jungle_Max_Support"
    },
    {
      "x": -13,
      "y": 39,
      "z": 2,
      "name": "Plant_Leaves_Jungle_Max_Support"
    },
    {
      "x": -13,
      "y": 40,
      "z": 2,
      "name": "Plant_Leaves_Jungle_Max_Support"
    },
    {
      "x": -13,
      "y": 36,
      "z": 3,
      "name": "Plant_Leaves_Jungle_Max_Support"
    },
    {
      "x": -13,
      "y": 39,
      "z": 3,
      "name": "Plant_Leaves_Jungle_Max_Support"
    },
    {
      "x": -13,
      "y": 40,
      "z": 3,
      "name": "Plant_Leaves_Jungle_Max_Support"
    },
    {
      "x": -13,
      "y": 37,
      "z": 4,
      "name": "Plant_Leaves_Jungle_Max_Support"
    },
    {
      "x": -13,
      "y": 38,
      "z": 4,
      "name": "Plant_Leaves_Jungle_Max_Support"
    },
    {
      "x": -13,
      "y": 39,
      "z": 4,
      "name": "Plant_Leaves_Jungle_Max_Support"
    },
    {
      "x": -13,
      "y": 40,
      "z": 4,
      "name": "Plant_Leaves_Jungle_Max_Support"
    },
    {
      "x": -13,
      "y": 41,
      "z": 4,
      "name": "Plant_Leaves_Jungle_Max_Support"
    },
    {
      "x": -13,
      "y": 36,
      "z": 5,
      "name": "Plant_Leaves_Jungle_Max_Support"
    },
    {
      "x": -13,
      "y": 37,
      "z": 5,
      "name": "Plant_Leaves_Jungle_Max_Support"
    },
    {
      "x": -13,
      "y": 38,
      "z": 5,
      "name": "Plant_Leaves_Jungle_Max_Support"
    },
    {
      "x": -13,
      "y": 39,
      "z": 5,
      "name": "Plant_Leaves_Jungle_Max_Support"
    },
    {
      "x": -13,
      "y": 40,
      "z": 5,
      "name": "Plant_Leaves_Jungle_Max_Support"
    },
    {
      "x": -13,
      "y": 42,
      "z": 5,
      "name": "Plant_Leaves_Jungle_Max_Support"
    },
    {
      "x": -13,
      "y": 37,
      "z": 6,
      "name": "Plant_Leaves_Jungle_Max_Support"
    },
    {
      "x": -13,
      "y": 40,
      "z": 6,
      "name": "Plant_Leaves_Jungle_Max_Support"
    },
    {
      "x": -13,
      "y": 41,
      "z": 6,
      "name": "Plant_Leaves_Jungle_Max_Support"
    },
    {
      "x": -13,
      "y": 38,
      "z": 7,
      "name": "Plant_Leaves_Jungle_Max_Support"
    },
    {
      "x": -13,
      "y": 40,
      "z": 7,
      "name": "Plant_Leaves_Jungle_Max_Support"
    },
    {
      "x": -13,
      "y": 41,
      "z": 7,
      "name": "Plant_Leaves_Jungle_Max_Support"
    },
    {
      "x": -13,
      "y": 42,
      "z": 7,
      "name": "Plant_Leaves_Jungle_Max_Support"
    },
    {
      "x": -13,
      "y": 39,
      "z": 8,
      "name": "Plant_Leaves_Jungle_Max_Support"
    },
    {
      "x": -13,
      "y": 41,
      "z": 8,
      "name": "Plant_Leaves_Jungle_Max_Support"
    },
    {
      "x": -13,
      "y": 42,
      "z": 8,
      "name": "Plant_Leaves_Jungle_Max_Support"
    },
    {
      "x": -12,
      "y": 36,
      "z": -12,
      "name": "Plant_Leaves_Jungle_Max_Support"
    },
    {
      "x": -12,
      "y": 37,
      "z": -12,
      "name": "Plant_Leaves_Jungle_Max_Support"
    },
    {
      "x": -12,
      "y": 37,
      "z": -11,
      "name": "Plant_Leaves_Jungle_Max_Support"
    },
    {
      "x": -12,
      "y": 37,
      "z": -10,
      "name": "Plant_Leaves_Jungle_Max_Support"
    },
    {
      "x": -12,
      "y": 35,
      "z": -9,
      "name": "Plant_Leaves_Jungle_Max_Support"
    },
    {
      "x": -12,
      "y": 36,
      "z": -9,
      "name": "Plant_Leaves_Jungle_Max_Support"
    },
    {
      "x": -12,
      "y": 38,
      "z": -9,
      "name": "Plant_Leaves_Jungle_Max_Support"
    },
    {
      "x": -12,
      "y": 38,
      "z": -8,
      "name": "Plant_Leaves_Jungle_Max_Support"
    },
    {
      "x": -12,
      "y": 39,
      "z": -8,
      "name": "Plant_Leaves_Jungle_Max_Support"
    },
    {
      "x": -12,
      "y": 37,
      "z": -7,
      "name": "Plant_Leaves_Jungle_Max_Support"
    },
    {
      "x": -12,
      "y": 38,
      "z": -7,
      "name": "Plant_Leaves_Jungle_Max_Support"
    },
    {
      "x": -12,
      "y": 41,
      "z": -7,
      "name": "Plant_Leaves_Jungle_Max_Support"
    },
    {
      "x": -12,
      "y": 40,
      "z": -6,
      "name": "Plant_Leaves_Jungle_Max_Support"
    },
    {
      "x": -12,
      "y": 39,
      "z": -5,
      "name": "Plant_Leaves_Jungle_Max_Support"
    },
    {
      "x": -12,
      "y": 37,
      "z": -4,
      "name": "Plant_Leaves_Jungle_Max_Support"
    },
    {
      "x": -12,
      "y": 39,
      "z": -4,
      "name": "Plant_Leaves_Jungle_Max_Support"
    },
    {
      "x": -12,
      "y": 40,
      "z": -4,
      "name": "Plant_Leaves_Jungle_Max_Support"
    },
    {
      "x": -12,
      "y": 41,
      "z": -4,
      "name": "Plant_Leaves_Jungle_Max_Support"
    },
    {
      "x": -12,
      "y": 36,
      "z": -3,
      "name": "Wood_Jungle_Trunk_Full"
    },
    {
      "x": -12,
      "y": 37,
      "z": -3,
      "name": "Plant_Leaves_Jungle_Max_Support"
    },
    {
      "x": -12,
      "y": 38,
      "z": -3,
      "name": "Plant_Leaves_Jungle_Max_Support"
    },
    {
      "x": -12,
      "y": 39,
      "z": -3,
      "name": "Plant_Leaves_Jungle_Max_Support"
    },
    {
      "x": -12,
      "y": 40,
      "z": -3,
      "name": "Plant_Leaves_Jungle_Max_Support"
    },
    {
      "x": -12,
      "y": 41,
      "z": -3,
      "name": "Plant_Leaves_Jungle_Max_Support"
    },
    {
      "x": -12,
      "y": 35,
      "z": -2,
      "name": "Wood_Jungle_Trunk_Full"
    },
    {
      "x": -12,
      "y": 36,
      "z": -2,
      "name": "Wood_Jungle_Trunk_Full"
    },
    {
      "x": -12,
      "y": 37,
      "z": -2,
      "name": "Plant_Leaves_Jungle_Max_Support"
    },
    {
      "x": -12,
      "y": 38,
      "z": -2,
      "name": "Plant_Leaves_Jungle_Max_Support"
    },
    {
      "x": -12,
      "y": 39,
      "z": -2,
      "name": "Plant_Leaves_Jungle_Max_Support"
    },
    {
      "x": -12,
      "y": 40,
      "z": -2,
      "name": "Plant_Leaves_Jungle_Max_Support"
    },
    {
      "x": -12,
      "y": 36,
      "z": -1,
      "name": "Plant_Leaves_Jungle_Max_Support"
    },
    {
      "x": -12,
      "y": 37,
      "z": -1,
      "name": "Plant_Leaves_Jungle_Max_Support"
    },
    {
      "x": -12,
      "y": 38,
      "z": -1,
      "name": "Plant_Leaves_Jungle_Max_Support"
    },
    {
      "x": -12,
      "y": 39,
      "z": -1,
      "name": "Plant_Leaves_Jungle_Max_Support"
    },
    {
      "x": -12,
      "y": 40,
      "z": -1,
      "name": "Plant_Leaves_Jungle_Max_Support"
    },
    {
      "x": -12,
      "y": 41,
      "z": -1,
      "name": "Plant_Leaves_Jungle_Max_Support"
    },
    {
      "x": -12,
      "y": 42,
      "z": -1,
      "name": "Plant_Leaves_Jungle_Max_Support"
    },
    {
      "x": -12,
      "y": 38,
      "z": 0,
      "name": "Plant_Leaves_Jungle_Max_Support"
    },
    {
      "x": -12,
      "y": 39,
      "z": 0,
      "name": "Plant_Leaves_Jungle_Max_Support"
    },
    {
      "x": -12,
      "y": 40,
      "z": 0,
      "name": "Plant_Leaves_Jungle_Max_Support"
    },
    {
      "x": -12,
      "y": 41,
      "z": 0,
      "name": "Plant_Leaves_Jungle_Max_Support"
    },
    {
      "x": -12,
      "y": 38,
      "z": 1,
      "name": "Plant_Leaves_Jungle_Max_Support"
    },
    {
      "x": -12,
      "y": 40,
      "z": 1,
      "name": "Plant_Leaves_Jungle_Max_Support"
    },
    {
      "x": -12,
      "y": 38,
      "z": 2,
      "name": "Plant_Leaves_Jungle_Max_Support"
    },
    {
      "x": -12,
      "y": 40,
      "z": 2,
      "name": "Plant_Leaves_Jungle_Max_Support"
    },
    {
      "x": -12,
      "y": 37,
      "z": 3,
      "name": "Plant_Leaves_Jungle_Max_Support"
    },
    {
      "x": -12,
      "y": 38,
      "z": 3,
      "name": "Plant_Leaves_Jungle_Max_Support"
    },
    {
      "x": -12,
      "y": 39,
      "z": 3,
      "name": "Plant_Leaves_Jungle_Max_Support"
    },
    {
      "x": -12,
      "y": 40,
      "z": 3,
      "name": "Plant_Leaves_Jungle_Max_Support"
    },
    {
      "x": -12,
      "y": 41,
      "z": 3,
      "name": "Plant_Leaves_Jungle_Max_Support"
    },
    {
      "x": -12,
      "y": 36,
      "z": 4,
      "name": "Plant_Leaves_Jungle_Max_Support"
    },
    {
      "x": -12,
      "y": 38,
      "z": 4,
      "name": "Plant_Leaves_Jungle_Max_Support"
    },
    {
      "x": -12,
      "y": 39,
      "z": 4,
      "name": "Plant_Leaves_Jungle_Max_Support"
    },
    {
      "x": -12,
      "y": 40,
      "z": 4,
      "name": "Plant_Leaves_Jungle_Max_Support"
    },
    {
      "x": -12,
      "y": 37,
      "z": 5,
      "name": "Plant_Leaves_Jungle_Max_Support"
    },
    {
      "x": -12,
      "y": 38,
      "z": 5,
      "name": "Plant_Leaves_Jungle_Max_Support"
    },
    {
      "x": -12,
      "y": 39,
      "z": 5,
      "name": "Plant_Leaves_Jungle_Max_Support"
    },
    {
      "x": -12,
      "y": 40,
      "z": 5,
      "name": "Plant_Leaves_Jungle_Max_Support"
    },
    {
      "x": -12,
      "y": 41,
      "z": 5,
      "name": "Plant_Leaves_Jungle_Max_Support"
    },
    {
      "x": -12,
      "y": 39,
      "z": 6,
      "name": "Plant_Leaves_Jungle_Max_Support"
    },
    {
      "x": -12,
      "y": 40,
      "z": 6,
      "name": "Plant_Leaves_Jungle_Max_Support"
    },
    {
      "x": -12,
      "y": 41,
      "z": 6,
      "name": "Plant_Leaves_Jungle_Max_Support"
    },
    {
      "x": -12,
      "y": 42,
      "z": 6,
      "name": "Plant_Leaves_Jungle_Max_Support"
    },
    {
      "x": -12,
      "y": 39,
      "z": 7,
      "name": "Plant_Leaves_Jungle_Max_Support"
    },
    {
      "x": -12,
      "y": 40,
      "z": 7,
      "name": "Plant_Leaves_Jungle_Max_Support"
    },
    {
      "x": -12,
      "y": 41,
      "z": 7,
      "name": "Plant_Leaves_Jungle_Max_Support"
    },
    {
      "x": -12,
      "y": 43,
      "z": 7,
      "name": "Plant_Leaves_Jungle_Max_Support"
    },
    {
      "x": -12,
      "y": 41,
      "z": 8,
      "name": "Plant_Leaves_Jungle_Max_Support"
    },
    {
      "x": -12,
      "y": 42,
      "z": 8,
      "name": "Plant_Leaves_Jungle_Max_Support"
    },
    {
      "x": -12,
      "y": 43,
      "z": 8,
      "name": "Plant_Leaves_Jungle_Max_Support"
    },
    {
      "x": -12,
      "y": 40,
      "z": 9,
      "name": "Plant_Leaves_Jungle_Max_Support"
    },
    {
      "x": -12,
      "y": 41,
      "z": 9,
      "name": "Plant_Leaves_Jungle_Max_Support"
    },
    {
      "x": -12,
      "y": 42,
      "z": 9,
      "name": "Plant_Leaves_Jungle_Max_Support"
    },
    {
      "x": -11,
      "y": 37,
      "z": -14,
      "name": "Plant_Leaves_Jungle_Max_Support"
    },
    {
      "x": -11,
      "y": 36,
      "z": -13,
      "name": "Plant_Leaves_Jungle_Max_Support"
    },
    {
      "x": -11,
      "y": 37,
      "z": -13,
      "name": "Plant_Leaves_Jungle_Max_Support"
    },
    {
      "x": -11,
      "y": 38,
      "z": -13,
      "name": "Plant_Leaves_Jungle_Max_Support"
    },
    {
      "x": -11,
      "y": 39,
      "z": -13,
      "name": "Plant_Leaves_Jungle_Max_Support"
    },
    {
      "x": -11,
      "y": 35,
      "z": -12,
      "name": "Plant_Leaves_Jungle_Max_Support"
    },
    {
      "x": -11,
      "y": 38,
      "z": -12,
      "name": "Plant_Leaves_Jungle_Max_Support"
    },
    {
      "x": -11,
      "y": 36,
      "z": -11,
      "name": "Plant_Leaves_Jungle_Max_Support"
    },
    {
      "x": -11,
      "y": 37,
      "z": -11,
      "name": "Plant_Leaves_Jungle_Max_Support"
    },
    {
      "x": -11,
      "y": 38,
      "z": -11,
      "name": "Plant_Leaves_Jungle_Max_Support"
    },
    {
      "x": -11,
      "y": 39,
      "z": -11,
      "name": "Plant_Leaves_Jungle_Max_Support"
    },
    {
      "x": -11,
      "y": 40,
      "z": -11,
      "name": "Plant_Leaves_Jungle_Max_Support"
    },
    {
      "x": -11,
      "y": 35,
      "z": -10,
      "name": "Plant_Leaves_Jungle_Max_Support"
    },
    {
      "x": -11,
      "y": 37,
      "z": -10,
      "name": "Plant_Leaves_Jungle_Max_Support"
    },
    {
      "x": -11,
      "y": 38,
      "z": -10,
      "name": "Plant_Leaves_Jungle_Max_Support"
    },
    {
      "x": -11,
      "y": 35,
      "z": -9,
      "name": "Plant_Leaves_Jungle_Max_Support"
    },
    {
      "x": -11,
      "y": 37,
      "z": -9,
      "name": "Plant_Leaves_Jungle_Max_Support"
    },
    {
      "x": -11,
      "y": 38,
      "z": -9,
      "name": "Plant_Leaves_Jungle_Max_Support"
    },
    {
      "x": -11,
      "y": 39,
      "z": -9,
      "name": "Plant_Leaves_Jungle_Max_Support"
    },
    {
      "x": -11,
      "y": 40,
      "z": -9,
      "name": "Plant_Leaves_Jungle_Max_Support"
    },
    {
      "x": -11,
      "y": 35,
      "z": -8,
      "name": "Plant_Leaves_Jungle_Max_Support"
    },
    {
      "x": -11,
      "y": 36,
      "z": -8,
      "name": "Plant_Leaves_Jungle_Max_Support"
    },
    {
      "x": -11,
      "y": 37,
      "z": -8,
      "name": "Plant_Leaves_Jungle_Max_Support"
    },
    {
      "x": -11,
      "y": 38,
      "z": -8,
      "name": "Plant_Leaves_Jungle_Max_Support"
    },
    {
      "x": -11,
      "y": 39,
      "z": -8,
      "name": "Plant_Leaves_Jungle_Max_Support"
    },
    {
      "x": -11,
      "y": 41,
      "z": -8,
      "name": "Plant_Leaves_Jungle_Max_Support"
    },
    {
      "x": -11,
      "y": 37,
      "z": -7,
      "name": "Plant_Leaves_Jungle_Max_Support"
    },
    {
      "x": -11,
      "y": 38,
      "z": -7,
      "name": "Plant_Leaves_Jungle_Max_Support"
    },
    {
      "x": -11,
      "y": 39,
      "z": -7,
      "name": "Plant_Leaves_Jungle_Max_Support"
    },
    {
      "x": -11,
      "y": 41,
      "z": -7,
      "name": "Plant_Leaves_Jungle_Max_Support"
    },
    {
      "x": -11,
      "y": 42,
      "z": -7,
      "name": "Plant_Leaves_Jungle_Max_Support"
    },
    {
      "x": -11,
      "y": 38,
      "z": -6,
      "name": "Plant_Leaves_Jungle_Max_Support"
    },
    {
      "x": -11,
      "y": 40,
      "z": -6,
      "name": "Plant_Leaves_Jungle_Max_Support"
    },
    {
      "x": -11,
      "y": 41,
      "z": -6,
      "name": "Plant_Leaves_Jungle_Max_Support"
    },
    {
      "x": -11,
      "y": 37,
      "z": -5,
      "name": "Plant_Leaves_Jungle_Max_Support"
    },
    {
      "x": -11,
      "y": 38,
      "z": -5,
      "name": "Plant_Leaves_Jungle_Max_Support"
    },
    {
      "x": -11,
      "y": 36,
      "z": -4,
      "name": "Plant_Leaves_Jungle_Max_Support"
    },
    {
      "x": -11,
      "y": 37,
      "z": -4,
      "name": "Plant_Leaves_Jungle_Max_Support"
    },
    {
      "x": -11,
      "y": 38,
      "z": -4,
      "name": "Plant_Leaves_Jungle_Max_Support"
    },
    {
      "x": -11,
      "y": 39,
      "z": -4,
      "name": "Plant_Leaves_Jungle_Max_Support"
    },
    {
      "x": -11,
      "y": 40,
      "z": -4,
      "name": "Plant_Leaves_Jungle_Max_Support"
    },
    {
      "x": -11,
      "y": 35,
      "z": -3,
      "name": "Plant_Leaves_Jungle_Max_Support"
    },
    {
      "x": -11,
      "y": 36,
      "z": -3,
      "name": "Wood_Jungle_Trunk_Full"
    },
    {
      "x": -11,
      "y": 37,
      "z": -3,
      "name": "Plant_Leaves_Jungle_Max_Support"
    },
    {
      "x": -11,
      "y": 38,
      "z": -3,
      "name": "Plant_Leaves_Jungle_Max_Support"
    },
    {
      "x": -11,
      "y": 39,
      "z": -3,
      "name": "Plant_Leaves_Jungle_Max_Support"
    },
    {
      "x": -11,
      "y": 40,
      "z": -3,
      "name": "Plant_Leaves_Jungle_Max_Support"
    },
    {
      "x": -11,
      "y": 41,
      "z": -3,
      "name": "Plant_Leaves_Jungle_Max_Support"
    },
    {
      "x": -11,
      "y": 35,
      "z": -2,
      "name": "Wood_Jungle_Trunk_Full"
    },
    {
      "x": -11,
      "y": 36,
      "z": -2,
      "name": "Wood_Jungle_Trunk_Full"
    },
    {
      "x": -11,
      "y": 37,
      "z": -2,
      "name": "Plant_Leaves_Jungle_Max_Support"
    },
    {
      "x": -11,
      "y": 38,
      "z": -2,
      "name": "Plant_Leaves_Jungle_Max_Support"
    },
    {
      "x": -11,
      "y": 39,
      "z": -2,
      "name": "Plant_Leaves_Jungle_Max_Support"
    },
    {
      "x": -11,
      "y": 41,
      "z": -2,
      "name": "Plant_Leaves_Jungle_Max_Support"
    },
    {
      "x": -11,
      "y": 35,
      "z": -1,
      "name": "Wood_Jungle_Trunk_Full"
    },
    {
      "x": -11,
      "y": 36,
      "z": -1,
      "name": "Wood_Jungle_Trunk_Full"
    },
    {
      "x": -11,
      "y": 37,
      "z": -1,
      "name": "Plant_Leaves_Jungle_Max_Support"
    },
    {
      "x": -11,
      "y": 38,
      "z": -1,
      "name": "Plant_Leaves_Jungle_Max_Support"
    },
    {
      "x": -11,
      "y": 39,
      "z": -1,
      "name": "Plant_Leaves_Jungle_Max_Support"
    },
    {
      "x": -11,
      "y": 40,
      "z": -1,
      "name": "Plant_Leaves_Jungle_Max_Support"
    },
    {
      "x": -11,
      "y": 41,
      "z": -1,
      "name": "Plant_Leaves_Jungle_Max_Support"
    },
    {
      "x": -11,
      "y": 37,
      "z": 0,
      "name": "Plant_Leaves_Jungle_Max_Support"
    },
    {
      "x": -11,
      "y": 38,
      "z": 0,
      "name": "Plant_Leaves_Jungle_Max_Support"
    },
    {
      "x": -11,
      "y": 39,
      "z": 0,
      "name": "Plant_Leaves_Jungle_Max_Support"
    },
    {
      "x": -11,
      "y": 40,
      "z": 0,
      "name": "Plant_Leaves_Jungle_Max_Support"
    },
    {
      "x": -11,
      "y": 39,
      "z": 1,
      "name": "Plant_Leaves_Jungle_Max_Support"
    },
    {
      "x": -11,
      "y": 40,
      "z": 1,
      "name": "Plant_Leaves_Jungle_Max_Support"
    },
    {
      "x": -11,
      "y": 41,
      "z": 1,
      "name": "Plant_Leaves_Jungle_Max_Support"
    },
    {
      "x": -11,
      "y": 38,
      "z": 2,
      "name": "Plant_Leaves_Jungle_Max_Support"
    },
    {
      "x": -11,
      "y": 38,
      "z": 3,
      "name": "Plant_Leaves_Jungle_Max_Support"
    },
    {
      "x": -11,
      "y": 39,
      "z": 3,
      "name": "Plant_Leaves_Jungle_Max_Support"
    },
    {
      "x": -11,
      "y": 40,
      "z": 3,
      "name": "Plant_Leaves_Jungle_Max_Support"
    },
    {
      "x": -11,
      "y": 41,
      "z": 3,
      "name": "Plant_Leaves_Jungle_Max_Support"
    },
    {
      "x": -11,
      "y": 45,
      "z": 3,
      "name": "Plant_Leaves_Jungle_Max_Support"
    },
    {
      "x": -11,
      "y": 47,
      "z": 3,
      "name": "Plant_Leaves_Jungle_Max_Support"
    },
    {
      "x": -11,
      "y": 37,
      "z": 4,
      "name": "Plant_Leaves_Jungle_Max_Support"
    },
    {
      "x": -11,
      "y": 38,
      "z": 4,
      "name": "Plant_Leaves_Jungle_Max_Support"
    },
    {
      "x": -11,
      "y": 39,
      "z": 4,
      "name": "Plant_Leaves_Jungle_Max_Support"
    },
    {
      "x": -11,
      "y": 40,
      "z": 4,
      "name": "Plant_Leaves_Jungle_Max_Support"
    },
    {
      "x": -11,
      "y": 41,
      "z": 4,
      "name": "Plant_Leaves_Jungle_Max_Support"
    },
    {
      "x": -11,
      "y": 42,
      "z": 4,
      "name": "Plant_Leaves_Jungle_Max_Support"
    },
    {
      "x": -11,
      "y": 45,
      "z": 4,
      "name": "Plant_Leaves_Jungle_Max_Support"
    },
    {
      "x": -11,
      "y": 47,
      "z": 4,
      "name": "Plant_Leaves_Jungle_Max_Support"
    },
    {
      "x": -11,
      "y": 37,
      "z": 5,
      "name": "Plant_Leaves_Jungle_Max_Support"
    },
    {
      "x": -11,
      "y": 38,
      "z": 5,
      "name": "Wood_Jungle_Trunk_Full"
    },
    {
      "x": -11,
      "y": 39,
      "z": 5,
      "name": "Plant_Leaves_Jungle_Max_Support"
    },
    {
      "x": -11,
      "y": 40,
      "z": 5,
      "name": "Plant_Leaves_Jungle_Max_Support"
    },
    {
      "x": -11,
      "y": 41,
      "z": 5,
      "name": "Plant_Leaves_Jungle_Max_Support"
    },
    {
      "x": -11,
      "y": 42,
      "z": 5,
      "name": "Plant_Leaves_Jungle_Max_Support"
    },
    {
      "x": -11,
      "y": 46,
      "z": 5,
      "name": "Plant_Leaves_Jungle_Max_Support"
    },
    {
      "x": -11,
      "y": 47,
      "z": 5,
      "name": "Plant_Leaves_Jungle_Max_Support"
    },
    {
      "x": -11,
      "y": 38,
      "z": 6,
      "name": "Wood_Jungle_Trunk_Full"
    },
    {
      "x": -11,
      "y": 39,
      "z": 6,
      "name": "Plant_Leaves_Jungle_Max_Support"
    },
    {
      "x": -11,
      "y": 40,
      "z": 6,
      "name": "Plant_Leaves_Jungle_Max_Support"
    },
    {
      "x": -11,
      "y": 41,
      "z": 6,
      "name": "Plant_Leaves_Jungle_Max_Support"
    },
    {
      "x": -11,
      "y": 42,
      "z": 6,
      "name": "Plant_Leaves_Jungle_Max_Support"
    },
    {
      "x": -11,
      "y": 43,
      "z": 6,
      "name": "Plant_Leaves_Jungle_Max_Support"
    },
    {
      "x": -11,
      "y": 44,
      "z": 6,
      "name": "Plant_Leaves_Jungle_Max_Support"
    },
    {
      "x": -11,
      "y": 39,
      "z": 7,
      "name": "Plant_Leaves_Jungle_Max_Support"
    },
    {
      "x": -11,
      "y": 40,
      "z": 7,
      "name": "Plant_Leaves_Jungle_Max_Support"
    },
    {
      "x": -11,
      "y": 41,
      "z": 7,
      "name": "Plant_Leaves_Jungle_Max_Support"
    },
    {
      "x": -11,
      "y": 42,
      "z": 7,
      "name": "Plant_Leaves_Jungle_Max_Support"
    },
    {
      "x": -11,
      "y": 43,
      "z": 7,
      "name": "Plant_Leaves_Jungle_Max_Support"
    },
    {
      "x": -11,
      "y": 38,
      "z": 8,
      "name": "Plant_Leaves_Jungle_Max_Support"
    },
    {
      "x": -11,
      "y": 41,
      "z": 8,
      "name": "Plant_Leaves_Jungle_Max_Support"
    },
    {
      "x": -11,
      "y": 43,
      "z": 8,
      "name": "Plant_Leaves_Jungle_Max_Support"
    },
    {
      "x": -11,
      "y": 44,
      "z": 8,
      "name": "Plant_Leaves_Jungle_Max_Support"
    },
    {
      "x": -11,
      "y": 39,
      "z": 9,
      "name": "Plant_Leaves_Jungle_Max_Support"
    },
    {
      "x": -11,
      "y": 40,
      "z": 9,
      "name": "Plant_Leaves_Jungle_Max_Support"
    },
    {
      "x": -11,
      "y": 41,
      "z": 9,
      "name": "Plant_Leaves_Jungle_Max_Support"
    },
    {
      "x": -11,
      "y": 42,
      "z": 9,
      "name": "Plant_Leaves_Jungle_Max_Support"
    },
    {
      "x": -11,
      "y": 43,
      "z": 9,
      "name": "Plant_Leaves_Jungle_Max_Support"
    },
    {
      "x": -11,
      "y": 40,
      "z": 10,
      "name": "Plant_Leaves_Jungle_Max_Support"
    },
    {
      "x": -11,
      "y": 41,
      "z": 10,
      "name": "Plant_Leaves_Jungle_Max_Support"
    },
    {
      "x": -10,
      "y": 37,
      "z": -14,
      "name": "Plant_Leaves_Jungle_Max_Support"
    },
    {
      "x": -10,
      "y": 38,
      "z": -14,
      "name": "Plant_Leaves_Jungle_Max_Support"
    },
    {
      "x": -10,
      "y": 40,
      "z": -14,
      "name": "Plant_Leaves_Jungle_Max_Support"
    },
    {
      "x": -10,
      "y": 36,
      "z": -13,
      "name": "Plant_Leaves_Jungle_Max_Support"
    },
    {
      "x": -10,
      "y": 37,
      "z": -13,
      "name": "Plant_Leaves_Jungle_Max_Support"
    },
    {
      "x": -10,
      "y": 38,
      "z": -13,
      "name": "Plant_Leaves_Jungle_Max_Support"
    },
    {
      "x": -10,
      "y": 39,
      "z": -13,
      "name": "Plant_Leaves_Jungle_Max_Support"
    },
    {
      "x": -10,
      "y": 40,
      "z": -13,
      "name": "Plant_Leaves_Jungle_Max_Support"
    },
    {
      "x": -10,
      "y": 41,
      "z": -13,
      "name": "Plant_Leaves_Jungle_Max_Support"
    },
    {
      "x": -10,
      "y": 35,
      "z": -12,
      "name": "Plant_Leaves_Jungle_Max_Support"
    },
    {
      "x": -10,
      "y": 37,
      "z": -12,
      "name": "Plant_Leaves_Jungle_Max_Support"
    },
    {
      "x": -10,
      "y": 38,
      "z": -12,
      "name": "Plant_Leaves_Jungle_Max_Support"
    },
    {
      "x": -10,
      "y": 39,
      "z": -12,
      "name": "Plant_Leaves_Jungle_Max_Support"
    },
    {
      "x": -10,
      "y": 40,
      "z": -12,
      "name": "Plant_Leaves_Jungle_Max_Support"
    },
    {
      "x": -10,
      "y": 37,
      "z": -11,
      "name": "Plant_Leaves_Jungle_Max_Support"
    },
    {
      "x": -10,
      "y": 38,
      "z": -11,
      "name": "Plant_Leaves_Jungle_Max_Support"
    },
    {
      "x": -10,
      "y": 39,
      "z": -11,
      "name": "Plant_Leaves_Jungle_Max_Support"
    },
    {
      "x": -10,
      "y": 40,
      "z": -11,
      "name": "Plant_Leaves_Jungle_Max_Support"
    },
    {
      "x": -10,
      "y": 41,
      "z": -11,
      "name": "Plant_Leaves_Jungle_Max_Support"
    },
    {
      "x": -10,
      "y": 36,
      "z": -10,
      "name": "Plant_Leaves_Jungle_Max_Support"
    },
    {
      "x": -10,
      "y": 37,
      "z": -10,
      "name": "Plant_Leaves_Jungle_Max_Support"
    },
    {
      "x": -10,
      "y": 38,
      "z": -10,
      "name": "Plant_Leaves_Jungle_Max_Support"
    },
    {
      "x": -10,
      "y": 39,
      "z": -10,
      "name": "Plant_Leaves_Jungle_Max_Support"
    },
    {
      "x": -10,
      "y": 36,
      "z": -9,
      "name": "Plant_Leaves_Jungle_Max_Support"
    },
    {
      "x": -10,
      "y": 37,
      "z": -9,
      "name": "Plant_Leaves_Jungle_Max_Support"
    },
    {
      "x": -10,
      "y": 39,
      "z": -9,
      "name": "Plant_Leaves_Jungle_Max_Support"
    },
    {
      "x": -10,
      "y": 40,
      "z": -9,
      "name": "Plant_Leaves_Jungle_Max_Support"
    },
    {
      "x": -10,
      "y": 41,
      "z": -9,
      "name": "Plant_Leaves_Jungle_Max_Support"
    },
    {
      "x": -10,
      "y": 37,
      "z": -8,
      "name": "Plant_Leaves_Jungle_Max_Support"
    },
    {
      "x": -10,
      "y": 38,
      "z": -8,
      "name": "Plant_Leaves_Jungle_Max_Support"
    },
    {
      "x": -10,
      "y": 39,
      "z": -8,
      "name": "Plant_Leaves_Jungle_Max_Support"
    },
    {
      "x": -10,
      "y": 40,
      "z": -8,
      "name": "Plant_Leaves_Jungle_Max_Support"
    },
    {
      "x": -10,
      "y": 41,
      "z": -8,
      "name": "Plant_Leaves_Jungle_Max_Support"
    },
    {
      "x": -10,
      "y": 42,
      "z": -8,
      "name": "Plant_Leaves_Jungle_Max_Support"
    },
    {
      "x": -10,
      "y": 36,
      "z": -7,
      "name": "Plant_Leaves_Jungle_Max_Support"
    },
    {
      "x": -10,
      "y": 37,
      "z": -7,
      "name": "Plant_Leaves_Jungle_Max_Support"
    },
    {
      "x": -10,
      "y": 39,
      "z": -7,
      "name": "Plant_Leaves_Jungle_Max_Support"
    },
    {
      "x": -10,
      "y": 40,
      "z": -7,
      "name": "Plant_Leaves_Jungle_Max_Support"
    },
    {
      "x": -10,
      "y": 37,
      "z": -6,
      "name": "Plant_Leaves_Jungle_Max_Support"
    },
    {
      "x": -10,
      "y": 38,
      "z": -6,
      "name": "Plant_Leaves_Jungle_Max_Support"
    },
    {
      "x": -10,
      "y": 39,
      "z": -6,
      "name": "Plant_Leaves_Jungle_Max_Support"
    },
    {
      "x": -10,
      "y": 40,
      "z": -6,
      "name": "Plant_Leaves_Jungle_Max_Support"
    },
    {
      "x": -10,
      "y": 41,
      "z": -6,
      "name": "Plant_Leaves_Jungle_Max_Support"
    },
    {
      "x": -10,
      "y": 37,
      "z": -5,
      "name": "Plant_Leaves_Jungle_Max_Support"
    },
    {
      "x": -10,
      "y": 38,
      "z": -5,
      "name": "Plant_Leaves_Jungle_Max_Support"
    },
    {
      "x": -10,
      "y": 39,
      "z": -5,
      "name": "Plant_Leaves_Jungle_Max_Support"
    },
    {
      "x": -10,
      "y": 40,
      "z": -5,
      "name": "Plant_Leaves_Jungle_Max_Support"
    },
    {
      "x": -10,
      "y": 41,
      "z": -5,
      "name": "Plant_Leaves_Jungle_Max_Support"
    },
    {
      "x": -10,
      "y": 36,
      "z": -4,
      "name": "Plant_Leaves_Jungle_Max_Support"
    },
    {
      "x": -10,
      "y": 38,
      "z": -4,
      "name": "Plant_Leaves_Jungle_Max_Support"
    },
    {
      "x": -10,
      "y": 39,
      "z": -4,
      "name": "Plant_Leaves_Jungle_Max_Support"
    },
    {
      "x": -10,
      "y": 40,
      "z": -4,
      "name": "Plant_Leaves_Jungle_Max_Support"
    },
    {
      "x": -10,
      "y": 37,
      "z": -3,
      "name": "Plant_Leaves_Jungle_Max_Support"
    },
    {
      "x": -10,
      "y": 38,
      "z": -3,
      "name": "Plant_Leaves_Jungle_Max_Support"
    },
    {
      "x": -10,
      "y": 39,
      "z": -3,
      "name": "Plant_Leaves_Jungle_Max_Support"
    },
    {
      "x": -10,
      "y": 40,
      "z": -3,
      "name": "Plant_Leaves_Jungle_Max_Support"
    },
    {
      "x": -10,
      "y": 41,
      "z": -3,
      "name": "Plant_Leaves_Jungle_Max_Support"
    },
    {
      "x": -10,
      "y": 35,
      "z": -2,
      "name": "Wood_Jungle_Trunk_Full"
    },
    {
      "x": -10,
      "y": 36,
      "z": -2,
      "name": "Plant_Leaves_Jungle_Max_Support"
    },
    {
      "x": -10,
      "y": 37,
      "z": -2,
      "name": "Plant_Leaves_Jungle_Max_Support"
    },
    {
      "x": -10,
      "y": 38,
      "z": -2,
      "name": "Plant_Leaves_Jungle_Max_Support"
    },
    {
      "x": -10,
      "y": 39,
      "z": -2,
      "name": "Plant_Leaves_Jungle_Max_Support"
    },
    {
      "x": -10,
      "y": 40,
      "z": -2,
      "name": "Plant_Leaves_Jungle_Max_Support"
    },
    {
      "x": -10,
      "y": 41,
      "z": -2,
      "name": "Plant_Leaves_Jungle_Max_Support"
    },
    {
      "x": -10,
      "y": 34,
      "z": -1,
      "name": "Wood_Jungle_Trunk_Full"
    },
    {
      "x": -10,
      "y": 35,
      "z": -1,
      "name": "Wood_Jungle_Trunk_Full"
    },
    {
      "x": -10,
      "y": 36,
      "z": -1,
      "name": "Wood_Jungle_Trunk_Full"
    },
    {
      "x": -10,
      "y": 37,
      "z": -1,
      "name": "Plant_Leaves_Jungle_Max_Support"
    },
    {
      "x": -10,
      "y": 38,
      "z": -1,
      "name": "Plant_Leaves_Jungle_Max_Support"
    },
    {
      "x": -10,
      "y": 39,
      "z": -1,
      "name": "Plant_Leaves_Jungle_Max_Support"
    },
    {
      "x": -10,
      "y": 41,
      "z": -1,
      "name": "Plant_Leaves_Jungle_Max_Support"
    },
    {
      "x": -10,
      "y": 34,
      "z": 0,
      "name": "Wood_Jungle_Trunk_Full"
    },
    {
      "x": -10,
      "y": 35,
      "z": 0,
      "name": "Wood_Jungle_Trunk_Full"
    },
    {
      "x": -10,
      "y": 36,
      "z": 0,
      "name": "Plant_Leaves_Jungle_Max_Support"
    },
    {
      "x": -10,
      "y": 37,
      "z": 0,
      "name": "Plant_Leaves_Jungle_Max_Support"
    },
    {
      "x": -10,
      "y": 38,
      "z": 0,
      "name": "Plant_Leaves_Jungle_Max_Support"
    },
    {
      "x": -10,
      "y": 39,
      "z": 0,
      "name": "Plant_Leaves_Jungle_Max_Support"
    },
    {
      "x": -10,
      "y": 36,
      "z": 1,
      "name": "Plant_Leaves_Jungle_Max_Support"
    },
    {
      "x": -10,
      "y": 37,
      "z": 1,
      "name": "Plant_Leaves_Jungle_Max_Support"
    },
    {
      "x": -10,
      "y": 39,
      "z": 1,
      "name": "Plant_Leaves_Jungle_Max_Support"
    },
    {
      "x": -10,
      "y": 40,
      "z": 1,
      "name": "Plant_Leaves_Jungle_Max_Support"
    },
    {
      "x": -10,
      "y": 45,
      "z": 1,
      "name": "Plant_Leaves_Jungle_Max_Support"
    },
    {
      "x": -10,
      "y": 39,
      "z": 2,
      "name": "Plant_Leaves_Jungle_Max_Support"
    },
    {
      "x": -10,
      "y": 40,
      "z": 2,
      "name": "Plant_Leaves_Jungle_Max_Support"
    },
    {
      "x": -10,
      "y": 41,
      "z": 2,
      "name": "Plant_Leaves_Jungle_Max_Support"
    },
    {
      "x": -10,
      "y": 45,
      "z": 2,
      "name": "Plant_Leaves_Jungle_Max_Support"
    },
    {
      "x": -10,
      "y": 46,
      "z": 2,
      "name": "Plant_Leaves_Jungle_Max_Support"
    },
    {
      "x": -10,
      "y": 47,
      "z": 2,
      "name": "Plant_Leaves_Jungle_Max_Support"
    },
    {
      "x": -10,
      "y": 38,
      "z": 3,
      "name": "Plant_Leaves_Jungle_Max_Support"
    },
    {
      "x": -10,
      "y": 39,
      "z": 3,
      "name": "Plant_Leaves_Jungle_Max_Support"
    },
    {
      "x": -10,
      "y": 40,
      "z": 3,
      "name": "Plant_Leaves_Jungle_Max_Support"
    },
    {
      "x": -10,
      "y": 41,
      "z": 3,
      "name": "Plant_Leaves_Jungle_Max_Support"
    },
    {
      "x": -10,
      "y": 42,
      "z": 3,
      "name": "Plant_Leaves_Jungle_Max_Support"
    },
    {
      "x": -10,
      "y": 44,
      "z": 3,
      "name": "Plant_Leaves_Jungle_Max_Support"
    },
    {
      "x": -10,
      "y": 45,
      "z": 3,
      "name": "Plant_Leaves_Jungle_Max_Support"
    },
    {
      "x": -10,
      "y": 46,
      "z": 3,
      "name": "Plant_Leaves_Jungle_Max_Support"
    },
    {
      "x": -10,
      "y": 38,
      "z": 4,
      "name": "Plant_Leaves_Jungle_Max_Support"
    },
    {
      "x": -10,
      "y": 39,
      "z": 4,
      "name": "Plant_Leaves_Jungle_Max_Support"
    },
    {
      "x": -10,
      "y": 40,
      "z": 4,
      "name": "Plant_Leaves_Jungle_Max_Support"
    },
    {
      "x": -10,
      "y": 41,
      "z": 4,
      "name": "Plant_Leaves_Jungle_Max_Support"
    },
    {
      "x": -10,
      "y": 42,
      "z": 4,
      "name": "Plant_Leaves_Jungle_Max_Support"
    },
    {
      "x": -10,
      "y": 44,
      "z": 4,
      "name": "Plant_Leaves_Jungle_Max_Support"
    },
    {
      "x": -10,
      "y": 45,
      "z": 4,
      "name": "Plant_Leaves_Jungle_Max_Support"
    },
    {
      "x": -10,
      "y": 46,
      "z": 4,
      "name": "Plant_Leaves_Jungle_Max_Support"
    },
    {
      "x": -10,
      "y": 47,
      "z": 4,
      "name": "Plant_Leaves_Jungle_Max_Support"
    },
    {
      "x": -10,
      "y": 48,
      "z": 4,
      "name": "Plant_Leaves_Jungle_Max_Support"
    },
    {
      "x": -10,
      "y": 37,
      "z": 5,
      "name": "Wood_Jungle_Trunk_Full"
    },
    {
      "x": -10,
      "y": 38,
      "z": 5,
      "name": "Wood_Jungle_Trunk_Full"
    },
    {
      "x": -10,
      "y": 39,
      "z": 5,
      "name": "Plant_Leaves_Jungle_Max_Support"
    },
    {
      "x": -10,
      "y": 40,
      "z": 5,
      "name": "Plant_Leaves_Jungle_Max_Support"
    },
    {
      "x": -10,
      "y": 41,
      "z": 5,
      "name": "Plant_Leaves_Jungle_Max_Support"
    },
    {
      "x": -10,
      "y": 42,
      "z": 5,
      "name": "Plant_Leaves_Jungle_Max_Support"
    },
    {
      "x": -10,
      "y": 43,
      "z": 5,
      "name": "Plant_Leaves_Jungle_Max_Support"
    },
    {
      "x": -10,
      "y": 44,
      "z": 5,
      "name": "Plant_Leaves_Jungle_Max_Support"
    },
    {
      "x": -10,
      "y": 45,
      "z": 5,
      "name": "Plant_Leaves_Jungle_Max_Support"
    },
    {
      "x": -10,
      "y": 46,
      "z": 5,
      "name": "Plant_Leaves_Jungle_Max_Support"
    },
    {
      "x": -10,
      "y": 47,
      "z": 5,
      "name": "Plant_Leaves_Jungle_Max_Support"
    },
    {
      "x": -10,
      "y": 37,
      "z": 6,
      "name": "Wood_Jungle_Trunk_Full"
    },
    {
      "x": -10,
      "y": 38,
      "z": 6,
      "name": "Wood_Jungle_Trunk_Full"
    },
    {
      "x": -10,
      "y": 39,
      "z": 6,
      "name": "Plant_Leaves_Jungle_Max_Support"
    },
    {
      "x": -10,
      "y": 40,
      "z": 6,
      "name": "Plant_Leaves_Jungle_Max_Support"
    },
    {
      "x": -10,
      "y": 41,
      "z": 6,
      "name": "Plant_Leaves_Jungle_Max_Support"
    },
    {
      "x": -10,
      "y": 43,
      "z": 6,
      "name": "Plant_Leaves_Jungle_Max_Support"
    },
    {
      "x": -10,
      "y": 44,
      "z": 6,
      "name": "Plant_Leaves_Jungle_Max_Support"
    },
    {
      "x": -10,
      "y": 45,
      "z": 6,
      "name": "Plant_Leaves_Jungle_Max_Support"
    },
    {
      "x": -10,
      "y": 46,
      "z": 6,
      "name": "Plant_Leaves_Jungle_Max_Support"
    },
    {
      "x": -10,
      "y": 38,
      "z": 7,
      "name": "Plant_Leaves_Jungle_Max_Support"
    },
    {
      "x": -10,
      "y": 39,
      "z": 7,
      "name": "Plant_Leaves_Jungle_Max_Support"
    },
    {
      "x": -10,
      "y": 40,
      "z": 7,
      "name": "Plant_Leaves_Jungle_Max_Support"
    },
    {
      "x": -10,
      "y": 41,
      "z": 7,
      "name": "Plant_Leaves_Jungle_Max_Support"
    },
    {
      "x": -10,
      "y": 42,
      "z": 7,
      "name": "Plant_Leaves_Jungle_Max_Support"
    },
    {
      "x": -10,
      "y": 44,
      "z": 7,
      "name": "Plant_Leaves_Jungle_Max_Support"
    },
    {
      "x": -10,
      "y": 39,
      "z": 8,
      "name": "Plant_Leaves_Jungle_Max_Support"
    },
    {
      "x": -10,
      "y": 40,
      "z": 8,
      "name": "Plant_Leaves_Jungle_Max_Support"
    },
    {
      "x": -10,
      "y": 41,
      "z": 8,
      "name": "Plant_Leaves_Jungle_Max_Support"
    },
    {
      "x": -10,
      "y": 42,
      "z": 8,
      "name": "Plant_Leaves_Jungle_Max_Support"
    },
    {
      "x": -10,
      "y": 44,
      "z": 8,
      "name": "Plant_Leaves_Jungle_Max_Support"
    },
    {
      "x": -10,
      "y": 39,
      "z": 9,
      "name": "Plant_Leaves_Jungle_Max_Support"
    },
    {
      "x": -10,
      "y": 41,
      "z": 9,
      "name": "Plant_Leaves_Jungle_Max_Support"
    },
    {
      "x": -10,
      "y": 42,
      "z": 9,
      "name": "Plant_Leaves_Jungle_Max_Support"
    },
    {
      "x": -10,
      "y": 43,
      "z": 9,
      "name": "Plant_Leaves_Jungle_Max_Support"
    },
    {
      "x": -10,
      "y": 40,
      "z": 10,
      "name": "Plant_Leaves_Jungle_Max_Support"
    },
    {
      "x": -10,
      "y": 41,
      "z": 10,
      "name": "Plant_Leaves_Jungle_Max_Support"
    },
    {
      "x": -10,
      "y": 42,
      "z": 10,
      "name": "Plant_Leaves_Jungle_Max_Support"
    },
    {
      "x": -9,
      "y": 38,
      "z": -15,
      "name": "Plant_Leaves_Jungle_Max_Support"
    },
    {
      "x": -9,
      "y": 39,
      "z": -15,
      "name": "Plant_Leaves_Jungle_Max_Support"
    },
    {
      "x": -9,
      "y": 37,
      "z": -14,
      "name": "Plant_Leaves_Jungle_Max_Support"
    },
    {
      "x": -9,
      "y": 38,
      "z": -14,
      "name": "Plant_Leaves_Jungle_Max_Support"
    },
    {
      "x": -9,
      "y": 40,
      "z": -14,
      "name": "Plant_Leaves_Jungle_Max_Support"
    },
    {
      "x": -9,
      "y": 41,
      "z": -14,
      "name": "Plant_Leaves_Jungle_Max_Support"
    },
    {
      "x": -9,
      "y": 36,
      "z": -13,
      "name": "Plant_Leaves_Jungle_Max_Support"
    },
    {
      "x": -9,
      "y": 37,
      "z": -13,
      "name": "Plant_Leaves_Jungle_Max_Support"
    },
    {
      "x": -9,
      "y": 38,
      "z": -13,
      "name": "Wood_Jungle_Trunk_Full"
    },
    {
      "x": -9,
      "y": 39,
      "z": -13,
      "name": "Wood_Jungle_Trunk_Full"
    },
    {
      "x": -9,
      "y": 41,
      "z": -13,
      "name": "Plant_Leaves_Jungle_Max_Support"
    },
    {
      "x": -9,
      "y": 36,
      "z": -12,
      "name": "Plant_Leaves_Jungle_Max_Support"
    },
    {
      "x": -9,
      "y": 38,
      "z": -12,
      "name": "Wood_Jungle_Trunk_Full"
    },
    {
      "x": -9,
      "y": 39,
      "z": -12,
      "name": "Wood_Jungle_Trunk_Full"
    },
    {
      "x": -9,
      "y": 41,
      "z": -12,
      "name": "Plant_Leaves_Jungle_Max_Support"
    },
    {
      "x": -9,
      "y": 42,
      "z": -12,
      "name": "Plant_Leaves_Jungle_Max_Support"
    },
    {
      "x": -9,
      "y": 31,
      "z": -11,
      "name": "Plant_Leaves_Jungle_Max_Support",
      "support": 15
    },
    {
      "x": -9,
      "y": 33,
      "z": -11,
      "name": "Plant_Leaves_Jungle_Max_Support"
    },
    {
      "x": -9,
      "y": 34,
      "z": -11,
      "name": "Plant_Leaves_Jungle_Max_Support"
    },
    {
      "x": -9,
      "y": 36,
      "z": -11,
      "name": "Plant_Leaves_Jungle_Max_Support"
    },
    {
      "x": -9,
      "y": 37,
      "z": -11,
      "name": "Wood_Jungle_Trunk_Full"
    },
    {
      "x": -9,
      "y": 38,
      "z": -11,
      "name": "Wood_Jungle_Trunk_Full"
    },
    {
      "x": -9,
      "y": 40,
      "z": -11,
      "name": "Plant_Leaves_Jungle_Max_Support"
    },
    {
      "x": -9,
      "y": 41,
      "z": -11,
      "name": "Plant_Leaves_Jungle_Max_Support"
    },
    {
      "x": -9,
      "y": 42,
      "z": -11,
      "name": "Plant_Leaves_Jungle_Max_Support"
    },
    {
      "x": -9,
      "y": 31,
      "z": -10,
      "name": "Plant_Leaves_Jungle_Max_Support",
      "support": 15
    },
    {
      "x": -9,
      "y": 32,
      "z": -10,
      "name": "Plant_Leaves_Jungle_Max_Support",
      "support": 15
    },
    {
      "x": -9,
      "y": 37,
      "z": -10,
      "name": "Plant_Leaves_Jungle_Max_Support"
    },
    {
      "x": -9,
      "y": 38,
      "z": -10,
      "name": "Wood_Jungle_Trunk_Full"
    },
    {
      "x": -9,
      "y": 39,
      "z": -10,
      "name": "Plant_Leaves_Jungle_Max_Support"
    },
    {
      "x": -9,
      "y": 40,
      "z": -10,
      "name": "Plant_Leaves_Jungle_Max_Support"
    },
    {
      "x": -9,
      "y": 41,
      "z": -10,
      "name": "Plant_Leaves_Jungle_Max_Support"
    },
    {
      "x": -9,
      "y": 31,
      "z": -9,
      "name": "Plant_Leaves_Jungle_Max_Support"
    },
    {
      "x": -9,
      "y": 32,
      "z": -9,
      "name": "Plant_Leaves_Jungle_Max_Support"
    },
    {
      "x": -9,
      "y": 33,
      "z": -9,
      "name": "Plant_Leaves_Jungle_Max_Support"
    },
    {
      "x": -9,
      "y": 34,
      "z": -9,
      "name": "Plant_Leaves_Jungle_Max_Support"
    },
    {
      "x": -9,
      "y": 35,
      "z": -9,
      "name": "Plant_Leaves_Jungle_Max_Support"
    },
    {
      "x": -9,
      "y": 37,
      "z": -9,
      "name": "Plant_Leaves_Jungle_Max_Support"
    },
    {
      "x": -9,
      "y": 38,
      "z": -9,
      "name": "Plant_Leaves_Jungle_Max_Support"
    },
    {
      "x": -9,
      "y": 39,
      "z": -9,
      "name": "Plant_Leaves_Jungle_Max_Support"
    },
    {
      "x": -9,
      "y": 40,
      "z": -9,
      "name": "Plant_Leaves_Jungle_Max_Support"
    },
    {
      "x": -9,
      "y": 41,
      "z": -9,
      "name": "Plant_Leaves_Jungle_Max_Support"
    },
    {
      "x": -9,
      "y": 32,
      "z": -8,
      "name": "Plant_Leaves_Jungle_Max_Support",
      "support": 15
    },
    {
      "x": -9,
      "y": 34,
      "z": -8,
      "name": "Plant_Leaves_Jungle_Max_Support",
      "support": 15
    },
    {
      "x": -9,
      "y": 36,
      "z": -8,
      "name": "Plant_Leaves_Jungle_Max_Support"
    },
    {
      "x": -9,
      "y": 37,
      "z": -8,
      "name": "Plant_Leaves_Jungle_Max_Support"
    },
    {
      "x": -9,
      "y": 38,
      "z": -8,
      "name": "Plant_Leaves_Jungle_Max_Support"
    },
    {
      "x": -9,
      "y": 39,
      "z": -8,
      "name": "Plant_Leaves_Jungle_Max_Support"
    },
    {
      "x": -9,
      "y": 40,
      "z": -8,
      "name": "Plant_Leaves_Jungle_Max_Support"
    },
    {
      "x": -9,
      "y": 41,
      "z": -8,
      "name": "Plant_Leaves_Jungle_Max_Support"
    },
    {
      "x": -9,
      "y": 32,
      "z": -7,
      "name": "Plant_Leaves_Jungle_Max_Support",
      "support": 15
    },
    {
      "x": -9,
      "y": 33,
      "z": -7,
      "name": "Plant_Leaves_Jungle_Max_Support"
    },
    {
      "x": -9,
      "y": 37,
      "z": -7,
      "name": "Plant_Leaves_Jungle_Max_Support"
    },
    {
      "x": -9,
      "y": 38,
      "z": -7,
      "name": "Plant_Leaves_Jungle_Max_Support"
    },
    {
      "x": -9,
      "y": 39,
      "z": -7,
      "name": "Plant_Leaves_Jungle_Max_Support"
    },
    {
      "x": -9,
      "y": 40,
      "z": -7,
      "name": "Plant_Leaves_Jungle_Max_Support"
    },
    {
      "x": -9,
      "y": 41,
      "z": -7,
      "name": "Plant_Leaves_Jungle_Max_Support"
    },
    {
      "x": -9,
      "y": 36,
      "z": -6,
      "name": "Plant_Leaves_Jungle_Max_Support"
    },
    {
      "x": -9,
      "y": 38,
      "z": -6,
      "name": "Plant_Leaves_Jungle_Max_Support"
    },
    {
      "x": -9,
      "y": 39,
      "z": -6,
      "name": "Plant_Leaves_Jungle_Max_Support"
    },
    {
      "x": -9,
      "y": 40,
      "z": -6,
      "name": "Plant_Leaves_Jungle_Max_Support"
    },
    {
      "x": -9,
      "y": 41,
      "z": -6,
      "name": "Plant_Leaves_Jungle_Max_Support"
    },
    {
      "x": -9,
      "y": 36,
      "z": -5,
      "name": "Plant_Leaves_Jungle_Max_Support"
    },
    {
      "x": -9,
      "y": 37,
      "z": -5,
      "name": "Plant_Leaves_Jungle_Max_Support"
    },
    {
      "x": -9,
      "y": 38,
      "z": -5,
      "name": "Plant_Leaves_Jungle_Max_Support"
    },
    {
      "x": -9,
      "y": 40,
      "z": -5,
      "name": "Plant_Leaves_Jungle_Max_Support"
    },
    {
      "x": -9,
      "y": 36,
      "z": -4,
      "name": "Plant_Leaves_Jungle_Max_Support"
    },
    {
      "x": -9,
      "y": 37,
      "z": -4,
      "name": "Plant_Leaves_Jungle_Max_Support"
    },
    {
      "x": -9,
      "y": 39,
      "z": -4,
      "name": "Plant_Leaves_Jungle_Max_Support"
    },
    {
      "x": -9,
      "y": 35,
      "z": -3,
      "name": "Plant_Leaves_Jungle_Max_Support"
    },
    {
      "x": -9,
      "y": 36,
      "z": -3,
      "name": "Plant_Leaves_Jungle_Max_Support"
    },
    {
      "x": -9,
      "y": 37,
      "z": -3,
      "name": "Plant_Leaves_Jungle_Max_Support"
    },
    {
      "x": -9,
      "y": 38,
      "z": -3,
      "name": "Plant_Leaves_Jungle_Max_Support"
    },
    {
      "x": -9,
      "y": 39,
      "z": -3,
      "name": "Plant_Leaves_Jungle_Max_Support"
    },
    {
      "x": -9,
      "y": 40,
      "z": -3,
      "name": "Plant_Leaves_Jungle_Max_Support"
    },
    {
      "x": -9,
      "y": 41,
      "z": -3,
      "name": "Plant_Leaves_Jungle_Max_Support"
    },
    {
      "x": -9,
      "y": 34,
      "z": -2,
      "name": "Plant_Leaves_Jungle_Max_Support"
    },
    {
      "x": -9,
      "y": 35,
      "z": -2,
      "name": "Plant_Leaves_Jungle_Max_Support"
    },
    {
      "x": -9,
      "y": 36,
      "z": -2,
      "name": "Plant_Leaves_Jungle_Max_Support"
    },
    {
      "x": -9,
      "y": 37,
      "z": -2,
      "name": "Plant_Leaves_Jungle_Max_Support"
    },
    {
      "x": -9,
      "y": 38,
      "z": -2,
      "name": "Plant_Leaves_Jungle_Max_Support"
    },
    {
      "x": -9,
      "y": 39,
      "z": -2,
      "name": "Plant_Leaves_Jungle_Max_Support"
    },
    {
      "x": -9,
      "y": 40,
      "z": -2,
      "name": "Plant_Leaves_Jungle_Max_Support"
    },
    {
      "x": -9,
      "y": 41,
      "z": -2,
      "name": "Plant_Leaves_Jungle_Max_Support"
    },
    {
      "x": -9,
      "y": 34,
      "z": -1,
      "name": "Wood_Jungle_Trunk_Full"
    },
    {
      "x": -9,
      "y": 35,
      "z": -1,
      "name": "Wood_Jungle_Trunk_Full"
    },
    {
      "x": -9,
      "y": 36,
      "z": -1,
      "name": "Plant_Leaves_Jungle_Max_Support"
    },
    {
      "x": -9,
      "y": 37,
      "z": -1,
      "name": "Plant_Leaves_Jungle_Max_Support"
    },
    {
      "x": -9,
      "y": 38,
      "z": -1,
      "name": "Plant_Leaves_Jungle_Max_Support"
    },
    {
      "x": -9,
      "y": 39,
      "z": -1,
      "name": "Plant_Leaves_Jungle_Max_Support"
    },
    {
      "x": -9,
      "y": 40,
      "z": -1,
      "name": "Plant_Leaves_Jungle_Max_Support"
    },
    {
      "x": -9,
      "y": 34,
      "z": 0,
      "name": "Wood_Jungle_Trunk_Full"
    },
    {
      "x": -9,
      "y": 35,
      "z": 0,
      "name": "Wood_Jungle_Trunk_Full"
    },
    {
      "x": -9,
      "y": 36,
      "z": 0,
      "name": "Plant_Leaves_Jungle_Max_Support"
    },
    {
      "x": -9,
      "y": 37,
      "z": 0,
      "name": "Plant_Leaves_Jungle_Max_Support"
    },
    {
      "x": -9,
      "y": 38,
      "z": 0,
      "name": "Plant_Leaves_Jungle_Max_Support"
    },
    {
      "x": -9,
      "y": 39,
      "z": 0,
      "name": "Plant_Leaves_Jungle_Max_Support"
    },
    {
      "x": -9,
      "y": 40,
      "z": 0,
      "name": "Plant_Leaves_Jungle_Max_Support"
    },
    {
      "x": -9,
      "y": 46,
      "z": 0,
      "name": "Plant_Leaves_Jungle_Max_Support"
    },
    {
      "x": -9,
      "y": 35,
      "z": 1,
      "name": "Plant_Leaves_Jungle_Max_Support"
    },
    {
      "x": -9,
      "y": 36,
      "z": 1,
      "name": "Plant_Leaves_Jungle_Max_Support"
    },
    {
      "x": -9,
      "y": 37,
      "z": 1,
      "name": "Plant_Leaves_Jungle_Max_Support"
    },
    {
      "x": -9,
      "y": 38,
      "z": 1,
      "name": "Plant_Leaves_Jungle_Max_Support"
    },
    {
      "x": -9,
      "y": 39,
      "z": 1,
      "name": "Plant_Leaves_Jungle_Max_Support"
    },
    {
      "x": -9,
      "y": 45,
      "z": 1,
      "name": "Plant_Leaves_Jungle_Max_Support"
    },
    {
      "x": -9,
      "y": 46,
      "z": 1,
      "name": "Plant_Leaves_Jungle_Max_Support"
    },
    {
      "x": -9,
      "y": 47,
      "z": 1,
      "name": "Plant_Leaves_Jungle_Max_Support"
    },
    {
      "x": -9,
      "y": 36,
      "z": 2,
      "name": "Plant_Leaves_Jungle_Max_Support"
    },
    {
      "x": -9,
      "y": 37,
      "z": 2,
      "name": "Plant_Leaves_Jungle_Max_Support"
    },
    {
      "x": -9,
      "y": 38,
      "z": 2,
      "name": "Plant_Leaves_Jungle_Max_Support"
    },
    {
      "x": -9,
      "y": 39,
      "z": 2,
      "name": "Plant_Leaves_Jungle_Max_Support"
    },
    {
      "x": -9,
      "y": 40,
      "z": 2,
      "name": "Plant_Leaves_Jungle_Max_Support"
    },
    {
      "x": -9,
      "y": 41,
      "z": 2,
      "name": "Plant_Leaves_Jungle_Max_Support"
    },
    {
      "x": -9,
      "y": 44,
      "z": 2,
      "name": "Plant_Leaves_Jungle_Max_Support"
    },
    {
      "x": -9,
      "y": 45,
      "z": 2,
      "name": "Plant_Leaves_Jungle_Max_Support"
    },
    {
      "x": -9,
      "y": 46,
      "z": 2,
      "name": "Plant_Leaves_Jungle_Max_Support"
    },
    {
      "x": -9,
      "y": 47,
      "z": 2,
      "name": "Plant_Leaves_Jungle_Max_Support"
    },
    {
      "x": -9,
      "y": 48,
      "z": 2,
      "name": "Plant_Leaves_Jungle_Max_Support"
    },
    {
      "x": -9,
      "y": 38,
      "z": 3,
      "name": "Plant_Leaves_Jungle_Max_Support"
    },
    {
      "x": -9,
      "y": 39,
      "z": 3,
      "name": "Plant_Leaves_Jungle_Max_Support"
    },
    {
      "x": -9,
      "y": 40,
      "z": 3,
      "name": "Plant_Leaves_Jungle_Max_Support"
    },
    {
      "x": -9,
      "y": 41,
      "z": 3,
      "name": "Plant_Leaves_Jungle_Max_Support"
    },
    {
      "x": -9,
      "y": 42,
      "z": 3,
      "name": "Plant_Leaves_Jungle_Max_Support"
    },
    {
      "x": -9,
      "y": 44,
      "z": 3,
      "name": "Plant_Leaves_Jungle_Max_Support"
    },
    {
      "x": -9,
      "y": 45,
      "z": 3,
      "name": "Plant_Leaves_Jungle_Max_Support"
    },
    {
      "x": -9,
      "y": 46,
      "z": 3,
      "name": "Plant_Leaves_Jungle_Max_Support"
    },
    {
      "x": -9,
      "y": 47,
      "z": 3,
      "name": "Plant_Leaves_Jungle_Max_Support"
    },
    {
      "x": -9,
      "y": 49,
      "z": 3,
      "name": "Plant_Leaves_Jungle_Max_Support"
    },
    {
      "x": -9,
      "y": 37,
      "z": 4,
      "name": "Plant_Leaves_Jungle_Max_Support"
    },
    {
      "x": -9,
      "y": 38,
      "z": 4,
      "name": "Plant_Leaves_Jungle_Max_Support"
    },
    {
      "x": -9,
      "y": 39,
      "z": 4,
      "name": "Plant_Leaves_Jungle_Max_Support"
    },
    {
      "x": -9,
      "y": 40,
      "z": 4,
      "name": "Plant_Leaves_Jungle_Max_Support"
    },
    {
      "x": -9,
      "y": 41,
      "z": 4,
      "name": "Plant_Leaves_Jungle_Max_Support"
    },
    {
      "x": -9,
      "y": 42,
      "z": 4,
      "name": "Plant_Leaves_Jungle_Max_Support"
    },
    {
      "x": -9,
      "y": 45,
      "z": 4,
      "name": "Plant_Leaves_Jungle_Max_Support"
    },
    {
      "x": -9,
      "y": 47,
      "z": 4,
      "name": "Plant_Leaves_Jungle_Max_Support"
    },
    {
      "x": -9,
      "y": 37,
      "z": 5,
      "name": "Wood_Jungle_Trunk_Full"
    },
    {
      "x": -9,
      "y": 38,
      "z": 5,
      "name": "Wood_Jungle_Trunk_Full"
    },
    {
      "x": -9,
      "y": 39,
      "z": 5,
      "name": "Plant_Leaves_Jungle_Max_Support"
    },
    {
      "x": -9,
      "y": 40,
      "z": 5,
      "name": "Plant_Leaves_Jungle_Max_Support"
    },
    {
      "x": -9,
      "y": 41,
      "z": 5,
      "name": "Plant_Leaves_Jungle_Max_Support"
    },
    {
      "x": -9,
      "y": 42,
      "z": 5,
      "name": "Plant_Leaves_Jungle_Max_Support"
    },
    {
      "x": -9,
      "y": 43,
      "z": 5,
      "name": "Plant_Leaves_Jungle_Max_Support"
    },
    {
      "x": -9,
      "y": 45,
      "z": 5,
      "name": "Plant_Leaves_Jungle_Max_Support"
    },
    {
      "x": -9,
      "y": 47,
      "z": 5,
      "name": "Plant_Leaves_Jungle_Max_Support"
    },
    {
      "x": -9,
      "y": 48,
      "z": 5,
      "name": "Plant_Leaves_Jungle_Max_Support"
    },
    {
      "x": -9,
      "y": 49,
      "z": 5,
      "name": "Plant_Leaves_Jungle_Max_Support"
    },
    {
      "x": -9,
      "y": 37,
      "z": 6,
      "name": "Wood_Jungle_Trunk_Full"
    },
    {
      "x": -9,
      "y": 38,
      "z": 6,
      "name": "Plant_Leaves_Jungle_Max_Support"
    },
    {
      "x": -9,
      "y": 39,
      "z": 6,
      "name": "Plant_Leaves_Jungle_Max_Support"
    },
    {
      "x": -9,
      "y": 40,
      "z": 6,
      "name": "Plant_Leaves_Jungle_Max_Support"
    },
    {
      "x": -9,
      "y": 41,
      "z": 6,
      "name": "Plant_Leaves_Jungle_Max_Support"
    },
    {
      "x": -9,
      "y": 43,
      "z": 6,
      "name": "Plant_Leaves_Jungle_Max_Support"
    },
    {
      "x": -9,
      "y": 44,
      "z": 6,
      "name": "Plant_Leaves_Jungle_Max_Support"
    },
    {
      "x": -9,
      "y": 45,
      "z": 6,
      "name": "Plant_Leaves_Jungle_Max_Support"
    },
    {
      "x": -9,
      "y": 46,
      "z": 6,
      "name": "Plant_Leaves_Jungle_Max_Support"
    },
    {
      "x": -9,
      "y": 38,
      "z": 7,
      "name": "Plant_Leaves_Jungle_Max_Support"
    },
    {
      "x": -9,
      "y": 39,
      "z": 7,
      "name": "Plant_Leaves_Jungle_Max_Support"
    },
    {
      "x": -9,
      "y": 40,
      "z": 7,
      "name": "Plant_Leaves_Jungle_Max_Support"
    },
    {
      "x": -9,
      "y": 42,
      "z": 7,
      "name": "Plant_Leaves_Jungle_Max_Support"
    },
    {
      "x": -9,
      "y": 43,
      "z": 7,
      "name": "Plant_Leaves_Jungle_Max_Support"
    },
    {
      "x": -9,
      "y": 44,
      "z": 7,
      "name": "Plant_Leaves_Jungle_Max_Support"
    },
    {
      "x": -9,
      "y": 45,
      "z": 7,
      "name": "Plant_Leaves_Jungle_Max_Support"
    },
    {
      "x": -9,
      "y": 47,
      "z": 7,
      "name": "Plant_Leaves_Jungle_Max_Support"
    },
    {
      "x": -9,
      "y": 38,
      "z": 8,
      "name": "Plant_Leaves_Jungle_Max_Support"
    },
    {
      "x": -9,
      "y": 40,
      "z": 8,
      "name": "Plant_Leaves_Jungle_Max_Support"
    },
    {
      "x": -9,
      "y": 42,
      "z": 8,
      "name": "Plant_Leaves_Jungle_Max_Support"
    },
    {
      "x": -9,
      "y": 43,
      "z": 8,
      "name": "Plant_Leaves_Jungle_Max_Support"
    },
    {
      "x": -9,
      "y": 44,
      "z": 8,
      "name": "Plant_Leaves_Jungle_Max_Support"
    },
    {
      "x": -9,
      "y": 39,
      "z": 9,
      "name": "Plant_Leaves_Jungle_Max_Support"
    },
    {
      "x": -9,
      "y": 40,
      "z": 9,
      "name": "Plant_Leaves_Jungle_Max_Support"
    },
    {
      "x": -9,
      "y": 42,
      "z": 9,
      "name": "Plant_Leaves_Jungle_Max_Support"
    },
    {
      "x": -9,
      "y": 40,
      "z": 10,
      "name": "Plant_Leaves_Jungle_Max_Support"
    },
    {
      "x": -9,
      "y": 41,
      "z": 10,
      "name": "Plant_Leaves_Jungle_Max_Support"
    },
    {
      "x": -8,
      "y": 38,
      "z": -15,
      "name": "Plant_Leaves_Jungle_Max_Support"
    },
    {
      "x": -8,
      "y": 37,
      "z": -14,
      "name": "Plant_Leaves_Jungle_Max_Support"
    },
    {
      "x": -8,
      "y": 38,
      "z": -14,
      "name": "Plant_Leaves_Jungle_Max_Support"
    },
    {
      "x": -8,
      "y": 39,
      "z": -14,
      "name": "Plant_Leaves_Jungle_Max_Support"
    },
    {
      "x": -8,
      "y": 41,
      "z": -14,
      "name": "Plant_Leaves_Jungle_Max_Support"
    },
    {
      "x": -8,
      "y": 37,
      "z": -13,
      "name": "Plant_Leaves_Jungle_Max_Support"
    },
    {
      "x": -8,
      "y": 38,
      "z": -13,
      "name": "Wood_Jungle_Trunk_Full"
    },
    {
      "x": -8,
      "y": 39,
      "z": -13,
      "name": "Wood_Jungle_Trunk_Full"
    },
    {
      "x": -8,
      "y": 40,
      "z": -13,
      "name": "Plant_Leaves_Jungle_Max_Support"
    },
    {
      "x": -8,
      "y": 42,
      "z": -13,
      "name": "Plant_Leaves_Jungle_Max_Support"
    },
    {
      "x": -8,
      "y": 35,
      "z": -12,
      "name": "Plant_Leaves_Jungle_Max_Support"
    },
    {
      "x": -8,
      "y": 37,
      "z": -12,
      "name": "Plant_Leaves_Jungle_Max_Support"
    },
    {
      "x": -8,
      "y": 38,
      "z": -12,
      "name": "Wood_Jungle_Trunk_Full"
    },
    {
      "x": -8,
      "y": 39,
      "z": -12,
      "name": "Wood_Jungle_Trunk_Full"
    },
    {
      "x": -8,
      "y": 40,
      "z": -12,
      "name": "Plant_Leaves_Jungle_Max_Support"
    },
    {
      "x": -8,
      "y": 41,
      "z": -12,
      "name": "Plant_Leaves_Jungle_Max_Support"
    },
    {
      "x": -8,
      "y": 32,
      "z": -11,
      "name": "Plant_Leaves_Jungle_Max_Support"
    },
    {
      "x": -8,
      "y": 34,
      "z": -11,
      "name": "Plant_Leaves_Jungle_Max_Support"
    },
    {
      "x": -8,
      "y": 36,
      "z": -11,
      "name": "Plant_Leaves_Jungle_Max_Support"
    },
    {
      "x": -8,
      "y": 38,
      "z": -11,
      "name": "Wood_Jungle_Trunk_Full"
    },
    {
      "x": -8,
      "y": 39,
      "z": -11,
      "name": "Plant_Leaves_Jungle_Max_Support"
    },
    {
      "x": -8,
      "y": 40,
      "z": -11,
      "name": "Plant_Leaves_Jungle_Max_Support"
    },
    {
      "x": -8,
      "y": 42,
      "z": -11,
      "name": "Plant_Leaves_Jungle_Max_Support"
    },
    {
      "x": -8,
      "y": 31,
      "z": -10,
      "name": "Plant_Leaves_Jungle_Max_Support"
    },
    {
      "x": -8,
      "y": 32,
      "z": -10,
      "name": "Plant_Leaves_Jungle_Max_Support"
    },
    {
      "x": -8,
      "y": 33,
      "z": -10,
      "name": "Plant_Leaves_Jungle_Max_Support"
    },
    {
      "x": -8,
      "y": 34,
      "z": -10,
      "name": "Plant_Leaves_Jungle_Max_Support"
    },
    {
      "x": -8,
      "y": 35,
      "z": -10,
      "name": "Plant_Leaves_Jungle_Max_Support"
    },
    {
      "x": -8,
      "y": 36,
      "z": -10,
      "name": "Plant_Leaves_Jungle_Max_Support"
    },
    {
      "x": -8,
      "y": 37,
      "z": -10,
      "name": "Wood_Jungle_Trunk_Full"
    },
    {
      "x": -8,
      "y": 38,
      "z": -10,
      "name": "Wood_Jungle_Trunk_Full"
    },
    {
      "x": -8,
      "y": 40,
      "z": -10,
      "name": "Plant_Leaves_Jungle_Max_Support"
    },
    {
      "x": -8,
      "y": 33,
      "z": -9,
      "name": "Plant_Leaves_Jungle_Max_Support"
    },
    {
      "x": -8,
      "y": 35,
      "z": -9,
      "name": "Plant_Leaves_Jungle_Max_Support"
    },
    {
      "x": -8,
      "y": 36,
      "z": -9,
      "name": "Plant_Leaves_Jungle_Max_Support"
    },
    {
      "x": -8,
      "y": 37,
      "z": -9,
      "name": "Wood_Jungle_Trunk_Full"
    },
    {
      "x": -8,
      "y": 38,
      "z": -9,
      "name": "Wood_Jungle_Trunk_Full"
    },
    {
      "x": -8,
      "y": 39,
      "z": -9,
      "name": "Plant_Leaves_Jungle_Max_Support"
    },
    {
      "x": -8,
      "y": 40,
      "z": -9,
      "name": "Plant_Leaves_Jungle_Max_Support"
    },
    {
      "x": -8,
      "y": 42,
      "z": -9,
      "name": "Plant_Leaves_Jungle_Max_Support"
    },
    {
      "x": -8,
      "y": 32,
      "z": -8,
      "name": "Plant_Leaves_Jungle_Max_Support",
      "support": 15
    },
    {
      "x": -8,
      "y": 33,
      "z": -8,
      "name": "Plant_Leaves_Jungle_Max_Support"
    },
    {
      "x": -8,
      "y": 34,
      "z": -8,
      "name": "Plant_Leaves_Jungle_Max_Support"
    },
    {
      "x": -8,
      "y": 37,
      "z": -8,
      "name": "Wood_Jungle_Trunk_Full"
    },
    {
      "x": -8,
      "y": 38,
      "z": -8,
      "name": "Wood_Jungle_Trunk_Full"
    },
    {
      "x": -8,
      "y": 39,
      "z": -8,
      "name": "Plant_Leaves_Jungle_Max_Support"
    },
    {
      "x": -8,
      "y": 40,
      "z": -8,
      "name": "Plant_Leaves_Jungle_Max_Support"
    },
    {
      "x": -8,
      "y": 41,
      "z": -8,
      "name": "Plant_Leaves_Jungle_Max_Support"
    },
    {
      "x": -8,
      "y": 32,
      "z": -7,
      "name": "Plant_Leaves_Jungle_Max_Support",
      "support": 15
    },
    {
      "x": -8,
      "y": 33,
      "z": -7,
      "name": "Plant_Leaves_Jungle_Max_Support",
      "support": 15
    },
    {
      "x": -8,
      "y": 34,
      "z": -7,
      "name": "Plant_Leaves_Jungle_Max_Support"
    },
    {
      "x": -8,
      "y": 37,
      "z": -7,
      "name": "Plant_Leaves_Jungle_Max_Support"
    },
    {
      "x": -8,
      "y": 38,
      "z": -7,
      "name": "Plant_Leaves_Jungle_Max_Support"
    },
    {
      "x": -8,
      "y": 39,
      "z": -7,
      "name": "Plant_Leaves_Jungle_Max_Support"
    },
    {
      "x": -8,
      "y": 40,
      "z": -7,
      "name": "Plant_Leaves_Jungle_Max_Support"
    },
    {
      "x": -8,
      "y": 41,
      "z": -7,
      "name": "Plant_Leaves_Jungle_Max_Support"
    },
    {
      "x": -8,
      "y": 42,
      "z": -7,
      "name": "Plant_Leaves_Jungle_Max_Support"
    },
    {
      "x": -8,
      "y": 33,
      "z": -6,
      "name": "Plant_Leaves_Jungle_Max_Support",
      "support": 15
    },
    {
      "x": -8,
      "y": 36,
      "z": -6,
      "name": "Plant_Leaves_Jungle_Max_Support"
    },
    {
      "x": -8,
      "y": 37,
      "z": -6,
      "name": "Plant_Leaves_Jungle_Max_Support"
    },
    {
      "x": -8,
      "y": 38,
      "z": -6,
      "name": "Plant_Leaves_Jungle_Max_Support"
    },
    {
      "x": -8,
      "y": 39,
      "z": -6,
      "name": "Plant_Leaves_Jungle_Max_Support"
    },
    {
      "x": -8,
      "y": 40,
      "z": -6,
      "name": "Plant_Leaves_Jungle_Max_Support"
    },
    {
      "x": -8,
      "y": 41,
      "z": -6,
      "name": "Plant_Leaves_Jungle_Max_Support"
    },
    {
      "x": -8,
      "y": 42,
      "z": -6,
      "name": "Plant_Leaves_Jungle_Max_Support"
    },
    {
      "x": -8,
      "y": 37,
      "z": -5,
      "name": "Plant_Leaves_Jungle_Max_Support"
    },
    {
      "x": -8,
      "y": 38,
      "z": -5,
      "name": "Plant_Leaves_Jungle_Max_Support"
    },
    {
      "x": -8,
      "y": 39,
      "z": -5,
      "name": "Plant_Leaves_Jungle_Max_Support"
    },
    {
      "x": -8,
      "y": 40,
      "z": -5,
      "name": "Plant_Leaves_Jungle_Max_Support"
    },
    {
      "x": -8,
      "y": 41,
      "z": -5,
      "name": "Plant_Leaves_Jungle_Max_Support"
    },
    {
      "x": -8,
      "y": 36,
      "z": -4,
      "name": "Plant_Leaves_Jungle_Max_Support"
    },
    {
      "x": -8,
      "y": 38,
      "z": -4,
      "name": "Plant_Leaves_Jungle_Max_Support"
    },
    {
      "x": -8,
      "y": 39,
      "z": -4,
      "name": "Plant_Leaves_Jungle_Max_Support"
    },
    {
      "x": -8,
      "y": 40,
      "z": -4,
      "name": "Plant_Leaves_Jungle_Max_Support"
    },
    {
      "x": -8,
      "y": 41,
      "z": -4,
      "name": "Plant_Leaves_Jungle_Max_Support"
    },
    {
      "x": -8,
      "y": 42,
      "z": -4,
      "name": "Plant_Leaves_Jungle_Max_Support"
    },
    {
      "x": -8,
      "y": 35,
      "z": -3,
      "name": "Plant_Leaves_Jungle_Max_Support"
    },
    {
      "x": -8,
      "y": 36,
      "z": -3,
      "name": "Plant_Leaves_Jungle_Max_Support"
    },
    {
      "x": -8,
      "y": 37,
      "z": -3,
      "name": "Plant_Leaves_Jungle_Max_Support"
    },
    {
      "x": -8,
      "y": 38,
      "z": -3,
      "name": "Plant_Leaves_Jungle_Max_Support"
    },
    {
      "x": -8,
      "y": 39,
      "z": -3,
      "name": "Plant_Leaves_Jungle_Max_Support"
    },
    {
      "x": -8,
      "y": 40,
      "z": -3,
      "name": "Plant_Leaves_Jungle_Max_Support"
    },
    {
      "x": -8,
      "y": 42,
      "z": -3,
      "name": "Plant_Leaves_Jungle_Max_Support"
    },
    {
      "x": -8,
      "y": 43,
      "z": -3,
      "name": "Plant_Leaves_Jungle_Max_Support"
    },
    {
      "x": -8,
      "y": 35,
      "z": -2,
      "name": "Plant_Leaves_Jungle_Max_Support"
    },
    {
      "x": -8,
      "y": 36,
      "z": -2,
      "name": "Plant_Leaves_Jungle_Max_Support"
    },
    {
      "x": -8,
      "y": 37,
      "z": -2,
      "name": "Plant_Leaves_Jungle_Max_Support"
    },
    {
      "x": -8,
      "y": 38,
      "z": -2,
      "name": "Plant_Leaves_Jungle_Max_Support"
    },
    {
      "x": -8,
      "y": 39,
      "z": -2,
      "name": "Plant_Leaves_Jungle_Max_Support"
    },
    {
      "x": -8,
      "y": 40,
      "z": -2,
      "name": "Plant_Leaves_Jungle_Max_Support"
    },
    {
      "x": -8,
      "y": 43,
      "z": -2,
      "name": "Plant_Leaves_Jungle_Max_Support"
    },
    {
      "x": -8,
      "y": 34,
      "z": -1,
      "name": "Wood_Jungle_Trunk_Full"
    },
    {
      "x": -8,
      "y": 35,
      "z": -1,
      "name": "Wood_Jungle_Trunk_Full"
    },
    {
      "x": -8,
      "y": 37,
      "z": -1,
      "name": "Plant_Leaves_Jungle_Max_Support"
    },
    {
      "x": -8,
      "y": 40,
      "z": -1,
      "name": "Plant_Leaves_Jungle_Max_Support"
    },
    {
      "x": -8,
      "y": 41,
      "z": -1,
      "name": "Plant_Leaves_Jungle_Max_Support"
    },
    {
      "x": -8,
      "y": 45,
      "z": -1,
      "name": "Plant_Leaves_Jungle_Max_Support"
    },
    {
      "x": -8,
      "y": 47,
      "z": -1,
      "name": "Plant_Leaves_Jungle_Max_Support"
    },
    {
      "x": -8,
      "y": 34,
      "z": 0,
      "name": "Wood_Jungle_Trunk_Full"
    },
    {
      "x": -8,
      "y": 35,
      "z": 0,
      "name": "Wood_Jungle_Trunk_Full"
    },
    {
      "x": -8,
      "y": 36,
      "z": 0,
      "name": "Plant_Leaves_Jungle_Max_Support"
    },
    {
      "x": -8,
      "y": 37,
      "z": 0,
      "name": "Plant_Leaves_Jungle_Max_Support"
    },
    {
      "x": -8,
      "y": 38,
      "z": 0,
      "name": "Plant_Leaves_Jungle_Max_Support"
    },
    {
      "x": -8,
      "y": 39,
      "z": 0,
      "name": "Plant_Leaves_Jungle_Max_Support"
    },
    {
      "x": -8,
      "y": 45,
      "z": 0,
      "name": "Plant_Leaves_Jungle_Max_Support"
    },
    {
      "x": -8,
      "y": 46,
      "z": 0,
      "name": "Plant_Leaves_Jungle_Max_Support"
    },
    {
      "x": -8,
      "y": 48,
      "z": 0,
      "name": "Plant_Leaves_Jungle_Max_Support"
    },
    {
      "x": -8,
      "y": 35,
      "z": 1,
      "name": "Plant_Leaves_Jungle_Max_Support"
    },
    {
      "x": -8,
      "y": 36,
      "z": 1,
      "name": "Plant_Leaves_Jungle_Max_Support"
    },
    {
      "x": -8,
      "y": 37,
      "z": 1,
      "name": "Plant_Leaves_Jungle_Max_Support"
    },
    {
      "x": -8,
      "y": 38,
      "z": 1,
      "name": "Plant_Leaves_Jungle_Max_Support"
    },
    {
      "x": -8,
      "y": 46,
      "z": 1,
      "name": "Plant_Leaves_Jungle_Max_Support"
    },
    {
      "x": -8,
      "y": 47,
      "z": 1,
      "name": "Plant_Leaves_Jungle_Max_Support"
    },
    {
      "x": -8,
      "y": 49,
      "z": 1,
      "name": "Plant_Leaves_Jungle_Max_Support"
    },
    {
      "x": -8,
      "y": 36,
      "z": 2,
      "name": "Plant_Leaves_Jungle_Max_Support"
    },
    {
      "x": -8,
      "y": 39,
      "z": 2,
      "name": "Plant_Leaves_Jungle_Max_Support"
    },
    {
      "x": -8,
      "y": 40,
      "z": 2,
      "name": "Plant_Leaves_Jungle_Max_Support"
    },
    {
      "x": -8,
      "y": 41,
      "z": 2,
      "name": "Plant_Leaves_Jungle_Max_Support"
    },
    {
      "x": -8,
      "y": 44,
      "z": 2,
      "name": "Plant_Leaves_Jungle_Max_Support"
    },
    {
      "x": -8,
      "y": 45,
      "z": 2,
      "name": "Plant_Leaves_Jungle_Max_Support"
    },
    {
      "x": -8,
      "y": 46,
      "z": 2,
      "name": "Plant_Leaves_Jungle_Max_Support"
    },
    {
      "x": -8,
      "y": 47,
      "z": 2,
      "name": "Plant_Leaves_Jungle_Max_Support"
    },
    {
      "x": -8,
      "y": 48,
      "z": 2,
      "name": "Plant_Leaves_Jungle_Max_Support"
    },
    {
      "x": -8,
      "y": 49,
      "z": 2,
      "name": "Plant_Leaves_Jungle_Max_Support"
    },
    {
      "x": -8,
      "y": 37,
      "z": 3,
      "name": "Plant_Leaves_Jungle_Max_Support"
    },
    {
      "x": -8,
      "y": 38,
      "z": 3,
      "name": "Plant_Leaves_Jungle_Max_Support"
    },
    {
      "x": -8,
      "y": 39,
      "z": 3,
      "name": "Plant_Leaves_Jungle_Max_Support"
    },
    {
      "x": -8,
      "y": 40,
      "z": 3,
      "name": "Plant_Leaves_Jungle_Max_Support"
    },
    {
      "x": -8,
      "y": 41,
      "z": 3,
      "name": "Plant_Leaves_Jungle_Max_Support"
    },
    {
      "x": -8,
      "y": 43,
      "z": 3,
      "name": "Plant_Leaves_Jungle_Max_Support"
    },
    {
      "x": -8,
      "y": 44,
      "z": 3,
      "name": "Plant_Leaves_Jungle_Max_Support"
    },
    {
      "x": -8,
      "y": 46,
      "z": 3,
      "name": "Plant_Leaves_Jungle_Max_Support"
    },
    {
      "x": -8,
      "y": 47,
      "z": 3,
      "name": "Plant_Leaves_Jungle_Max_Support"
    },
    {
      "x": -8,
      "y": 49,
      "z": 3,
      "name": "Plant_Leaves_Jungle_Max_Support"
    },
    {
      "x": -8,
      "y": 37,
      "z": 4,
      "name": "Wood_Jungle_Trunk_Full"
    },
    {
      "x": -8,
      "y": 38,
      "z": 4,
      "name": "Plant_Leaves_Jungle_Max_Support"
    },
    {
      "x": -8,
      "y": 39,
      "z": 4,
      "name": "Plant_Leaves_Jungle_Max_Support"
    },
    {
      "x": -8,
      "y": 40,
      "z": 4,
      "name": "Plant_Leaves_Jungle_Max_Support"
    },
    {
      "x": -8,
      "y": 41,
      "z": 4,
      "name": "Plant_Leaves_Jungle_Max_Support"
    },
    {
      "x": -8,
      "y": 43,
      "z": 4,
      "name": "Plant_Leaves_Jungle_Max_Support"
    },
    {
      "x": -8,
      "y": 44,
      "z": 4,
      "name": "Plant_Leaves_Jungle_Max_Support"
    },
    {
      "x": -8,
      "y": 45,
      "z": 4,
      "name": "Plant_Leaves_Jungle_Max_Support"
    },
    {
      "x": -8,
      "y": 46,
      "z": 4,
      "name": "Plant_Leaves_Jungle_Max_Support"
    },
    {
      "x": -8,
      "y": 47,
      "z": 4,
      "name": "Plant_Leaves_Jungle_Max_Support"
    },
    {
      "x": -8,
      "y": 48,
      "z": 4,
      "name": "Plant_Leaves_Jungle_Max_Support"
    },
    {
      "x": -8,
      "y": 49,
      "z": 4,
      "name": "Plant_Leaves_Jungle_Max_Support"
    },
    {
      "x": -8,
      "y": 37,
      "z": 5,
      "name": "Wood_Jungle_Trunk_Full"
    },
    {
      "x": -8,
      "y": 38,
      "z": 5,
      "name": "Plant_Leaves_Jungle_Max_Support"
    },
    {
      "x": -8,
      "y": 40,
      "z": 5,
      "name": "Plant_Leaves_Jungle_Max_Support"
    },
    {
      "x": -8,
      "y": 41,
      "z": 5,
      "name": "Plant_Leaves_Jungle_Max_Support"
    },
    {
      "x": -8,
      "y": 42,
      "z": 5,
      "name": "Plant_Leaves_Jungle_Max_Support"
    },
    {
      "x": -8,
      "y": 43,
      "z": 5,
      "name": "Plant_Leaves_Jungle_Max_Support"
    },
    {
      "x": -8,
      "y": 44,
      "z": 5,
      "name": "Plant_Leaves_Jungle_Max_Support"
    },
    {
      "x": -8,
      "y": 45,
      "z": 5,
      "name": "Plant_Leaves_Jungle_Max_Support"
    },
    {
      "x": -8,
      "y": 46,
      "z": 5,
      "name": "Plant_Leaves_Jungle_Max_Support"
    },
    {
      "x": -8,
      "y": 47,
      "z": 5,
      "name": "Plant_Leaves_Jungle_Max_Support"
    },
    {
      "x": -8,
      "y": 49,
      "z": 5,
      "name": "Plant_Leaves_Jungle_Max_Support"
    },
    {
      "x": -8,
      "y": 37,
      "z": 6,
      "name": "Wood_Jungle_Trunk_Full"
    },
    {
      "x": -8,
      "y": 39,
      "z": 6,
      "name": "Plant_Leaves_Jungle_Max_Support"
    },
    {
      "x": -8,
      "y": 40,
      "z": 6,
      "name": "Plant_Leaves_Jungle_Max_Support"
    },
    {
      "x": -8,
      "y": 41,
      "z": 6,
      "name": "Plant_Leaves_Jungle_Max_Support"
    },
    {
      "x": -8,
      "y": 43,
      "z": 6,
      "name": "Plant_Leaves_Jungle_Max_Support"
    },
    {
      "x": -8,
      "y": 44,
      "z": 6,
      "name": "Plant_Leaves_Jungle_Max_Support"
    },
    {
      "x": -8,
      "y": 45,
      "z": 6,
      "name": "Plant_Leaves_Jungle_Max_Support"
    },
    {
      "x": -8,
      "y": 38,
      "z": 7,
      "name": "Plant_Leaves_Jungle_Max_Support"
    },
    {
      "x": -8,
      "y": 39,
      "z": 7,
      "name": "Plant_Leaves_Jungle_Max_Support"
    },
    {
      "x": -8,
      "y": 40,
      "z": 7,
      "name": "Plant_Leaves_Jungle_Max_Support"
    },
    {
      "x": -8,
      "y": 41,
      "z": 7,
      "name": "Plant_Leaves_Jungle_Max_Support"
    },
    {
      "x": -8,
      "y": 42,
      "z": 7,
      "name": "Plant_Leaves_Jungle_Max_Support"
    },
    {
      "x": -8,
      "y": 45,
      "z": 7,
      "name": "Plant_Leaves_Jungle_Max_Support"
    },
    {
      "x": -8,
      "y": 47,
      "z": 7,
      "name": "Plant_Leaves_Jungle_Max_Support"
    },
    {
      "x": -8,
      "y": 39,
      "z": 8,
      "name": "Plant_Leaves_Jungle_Max_Support"
    },
    {
      "x": -8,
      "y": 40,
      "z": 8,
      "name": "Plant_Leaves_Jungle_Max_Support"
    },
    {
      "x": -8,
      "y": 42,
      "z": 8,
      "name": "Plant_Leaves_Jungle_Max_Support"
    },
    {
      "x": -8,
      "y": 43,
      "z": 8,
      "name": "Plant_Leaves_Jungle_Max_Support"
    },
    {
      "x": -8,
      "y": 41,
      "z": 9,
      "name": "Plant_Leaves_Jungle_Max_Support"
    },
    {
      "x": -7,
      "y": 40,
      "z": -15,
      "name": "Plant_Leaves_Jungle_Max_Support"
    },
    {
      "x": -7,
      "y": 37,
      "z": -14,
      "name": "Plant_Leaves_Jungle_Max_Support"
    },
    {
      "x": -7,
      "y": 38,
      "z": -14,
      "name": "Plant_Leaves_Jungle_Max_Support"
    },
    {
      "x": -7,
      "y": 39,
      "z": -14,
      "name": "Plant_Leaves_Jungle_Max_Support"
    },
    {
      "x": -7,
      "y": 40,
      "z": -14,
      "name": "Plant_Leaves_Jungle_Max_Support"
    },
    {
      "x": -7,
      "y": 41,
      "z": -14,
      "name": "Plant_Leaves_Jungle_Max_Support"
    },
    {
      "x": -7,
      "y": 33,
      "z": -13,
      "name": "Plant_Leaves_Jungle_Max_Support"
    },
    {
      "x": -7,
      "y": 35,
      "z": -13,
      "name": "Plant_Leaves_Jungle_Max_Support"
    },
    {
      "x": -7,
      "y": 36,
      "z": -13,
      "name": "Plant_Leaves_Jungle_Max_Support"
    },
    {
      "x": -7,
      "y": 37,
      "z": -13,
      "name": "Plant_Leaves_Jungle_Max_Support"
    },
    {
      "x": -7,
      "y": 38,
      "z": -13,
      "name": "Plant_Leaves_Jungle_Max_Support"
    },
    {
      "x": -7,
      "y": 39,
      "z": -13,
      "name": "Plant_Leaves_Jungle_Max_Support"
    },
    {
      "x": -7,
      "y": 40,
      "z": -13,
      "name": "Plant_Leaves_Jungle_Max_Support"
    },
    {
      "x": -7,
      "y": 42,
      "z": -13,
      "name": "Plant_Leaves_Jungle_Max_Support"
    },
    {
      "x": -7,
      "y": 32,
      "z": -12,
      "name": "Plant_Leaves_Jungle_Max_Support"
    },
    {
      "x": -7,
      "y": 35,
      "z": -12,
      "name": "Plant_Leaves_Jungle_Max_Support"
    },
    {
      "x": -7,
      "y": 38,
      "z": -12,
      "name": "Plant_Leaves_Jungle_Max_Support"
    },
    {
      "x": -7,
      "y": 39,
      "z": -12,
      "name": "Plant_Leaves_Jungle_Max_Support"
    },
    {
      "x": -7,
      "y": 40,
      "z": -12,
      "name": "Plant_Leaves_Jungle_Max_Support"
    },
    {
      "x": -7,
      "y": 41,
      "z": -12,
      "name": "Plant_Leaves_Jungle_Max_Support"
    },
    {
      "x": -7,
      "y": 42,
      "z": -12,
      "name": "Plant_Leaves_Jungle_Max_Support"
    },
    {
      "x": -7,
      "y": 32,
      "z": -11,
      "name": "Plant_Leaves_Jungle_Max_Support"
    },
    {
      "x": -7,
      "y": 34,
      "z": -11,
      "name": "Plant_Leaves_Jungle_Max_Support"
    },
    {
      "x": -7,
      "y": 37,
      "z": -11,
      "name": "Plant_Leaves_Jungle_Max_Support"
    },
    {
      "x": -7,
      "y": 38,
      "z": -11,
      "name": "Plant_Leaves_Jungle_Max_Support"
    },
    {
      "x": -7,
      "y": 40,
      "z": -11,
      "name": "Plant_Leaves_Jungle_Max_Support"
    },
    {
      "x": -7,
      "y": 31,
      "z": -10,
      "name": "Plant_Leaves_Jungle_Max_Support"
    },
    {
      "x": -7,
      "y": 33,
      "z": -10,
      "name": "Plant_Leaves_Jungle_Max_Support"
    },
    {
      "x": -7,
      "y": 34,
      "z": -10,
      "name": "Plant_Leaves_Jungle_Max_Support"
    },
    {
      "x": -7,
      "y": 36,
      "z": -10,
      "name": "Plant_Leaves_Jungle_Max_Support"
    },
    {
      "x": -7,
      "y": 37,
      "z": -10,
      "name": "Plant_Leaves_Jungle_Max_Support"
    },
    {
      "x": -7,
      "y": 38,
      "z": -10,
      "name": "Wood_Jungle_Trunk_Full"
    },
    {
      "x": -7,
      "y": 40,
      "z": -10,
      "name": "Plant_Leaves_Jungle_Max_Support"
    },
    {
      "x": -7,
      "y": 41,
      "z": -10,
      "name": "Plant_Leaves_Jungle_Max_Support"
    },
    {
      "x": -7,
      "y": 32,
      "z": -9,
      "name": "Plant_Leaves_Jungle_Max_Support"
    },
    {
      "x": -7,
      "y": 33,
      "z": -9,
      "name": "Plant_Leaves_Jungle_Max_Support"
    },
    {
      "x": -7,
      "y": 34,
      "z": -9,
      "name": "Plant_Leaves_Jungle_Max_Support"
    },
    {
      "x": -7,
      "y": 35,
      "z": -9,
      "name": "Plant_Leaves_Jungle_Max_Support"
    },
    {
      "x": -7,
      "y": 36,
      "z": -9,
      "name": "Plant_Leaves_Jungle_Max_Support"
    },
    {
      "x": -7,
      "y": 37,
      "z": -9,
      "name": "Wood_Jungle_Trunk_Full"
    },
    {
      "x": -7,
      "y": 38,
      "z": -9,
      "name": "Wood_Jungle_Trunk_Full"
    },
    {
      "x": -7,
      "y": 39,
      "z": -9,
      "name": "Plant_Leaves_Jungle_Max_Support"
    },
    {
      "x": -7,
      "y": 40,
      "z": -9,
      "name": "Plant_Leaves_Jungle_Max_Support"
    },
    {
      "x": -7,
      "y": 41,
      "z": -9,
      "name": "Plant_Leaves_Jungle_Max_Support"
    },
    {
      "x": -7,
      "y": 32,
      "z": -8,
      "name": "Wood_Jungle_Trunk_Full"
    },
    {
      "x": -7,
      "y": 33,
      "z": -8,
      "name": "Plant_Leaves_Jungle_Max_Support"
    },
    {
      "x": -7,
      "y": 34,
      "z": -8,
      "name": "Plant_Leaves_Jungle_Max_Support"
    },
    {
      "x": -7,
      "y": 35,
      "z": -8,
      "name": "Plant_Leaves_Jungle_Max_Support"
    },
    {
      "x": -7,
      "y": 36,
      "z": -8,
      "name": "Plant_Leaves_Jungle_Max_Support"
    },
    {
      "x": -7,
      "y": 37,
      "z": -8,
      "name": "Wood_Jungle_Trunk_Full"
    },
    {
      "x": -7,
      "y": 38,
      "z": -8,
      "name": "Wood_Jungle_Trunk_Full"
    },
    {
      "x": -7,
      "y": 39,
      "z": -8,
      "name": "Wood_Jungle_Trunk_Full"
    },
    {
      "x": -7,
      "y": 40,
      "z": -8,
      "name": "Plant_Leaves_Jungle_Max_Support"
    },
    {
      "x": -7,
      "y": 41,
      "z": -8,
      "name": "Plant_Leaves_Jungle_Max_Support"
    },
    {
      "x": -7,
      "y": 32,
      "z": -7,
      "name": "Wood_Jungle_Trunk_Full"
    },
    {
      "x": -7,
      "y": 33,
      "z": -7,
      "name": "Plant_Leaves_Jungle_Max_Support"
    },
    {
      "x": -7,
      "y": 34,
      "z": -7,
      "name": "Plant_Leaves_Jungle_Max_Support"
    },
    {
      "x": -7,
      "y": 35,
      "z": -7,
      "name": "Plant_Leaves_Jungle_Max_Support"
    },
    {
      "x": -7,
      "y": 36,
      "z": -7,
      "name": "Plant_Leaves_Jungle_Max_Support"
    },
    {
      "x": -7,
      "y": 37,
      "z": -7,
      "name": "Wood_Jungle_Trunk_Full"
    },
    {
      "x": -7,
      "y": 38,
      "z": -7,
      "name": "Wood_Jungle_Trunk_Full"
    },
    {
      "x": -7,
      "y": 39,
      "z": -7,
      "name": "Plant_Leaves_Jungle_Max_Support"
    },
    {
      "x": -7,
      "y": 40,
      "z": -7,
      "name": "Plant_Leaves_Jungle_Max_Support"
    },
    {
      "x": -7,
      "y": 41,
      "z": -7,
      "name": "Plant_Leaves_Jungle_Max_Support"
    },
    {
      "x": -7,
      "y": 42,
      "z": -7,
      "name": "Plant_Leaves_Jungle_Max_Support"
    },
    {
      "x": -7,
      "y": 32,
      "z": -6,
      "name": "Plant_Leaves_Jungle_Max_Support"
    },
    {
      "x": -7,
      "y": 33,
      "z": -6,
      "name": "Plant_Leaves_Jungle_Max_Support",
      "support": 15
    },
    {
      "x": -7,
      "y": 35,
      "z": -6,
      "name": "Plant_Leaves_Jungle_Max_Support",
      "support": 15
    },
    {
      "x": -7,
      "y": 37,
      "z": -6,
      "name": "Plant_Leaves_Jungle_Max_Support"
    },
    {
      "x": -7,
      "y": 38,
      "z": -6,
      "name": "Plant_Leaves_Jungle_Max_Support"
    },
    {
      "x": -7,
      "y": 39,
      "z": -6,
      "name": "Plant_Leaves_Jungle_Max_Support"
    },
    {
      "x": -7,
      "y": 40,
      "z": -6,
      "name": "Plant_Leaves_Jungle_Max_Support"
    },
    {
      "x": -7,
      "y": 41,
      "z": -6,
      "name": "Plant_Leaves_Jungle_Max_Support"
    },
    {
      "x": -7,
      "y": 42,
      "z": -6,
      "name": "Plant_Leaves_Jungle_Max_Support"
    },
    {
      "x": -7,
      "y": 43,
      "z": -6,
      "name": "Plant_Leaves_Jungle_Max_Support"
    },
    {
      "x": -7,
      "y": 32,
      "z": -5,
      "name": "Plant_Leaves_Jungle_Max_Support"
    },
    {
      "x": -7,
      "y": 39,
      "z": -5,
      "name": "Plant_Leaves_Jungle_Max_Support"
    },
    {
      "x": -7,
      "y": 40,
      "z": -5,
      "name": "Plant_Leaves_Jungle_Max_Support"
    },
    {
      "x": -7,
      "y": 41,
      "z": -5,
      "name": "Plant_Leaves_Jungle_Max_Support"
    },
    {
      "x": -7,
      "y": 42,
      "z": -5,
      "name": "Plant_Leaves_Jungle_Max_Support"
    },
    {
      "x": -7,
      "y": 43,
      "z": -5,
      "name": "Plant_Leaves_Jungle_Max_Support"
    },
    {
      "x": -7,
      "y": 35,
      "z": -4,
      "name": "Plant_Leaves_Jungle_Max_Support"
    },
    {
      "x": -7,
      "y": 36,
      "z": -4,
      "name": "Plant_Leaves_Jungle_Max_Support"
    },
    {
      "x": -7,
      "y": 37,
      "z": -4,
      "name": "Plant_Leaves_Jungle_Max_Support"
    },
    {
      "x": -7,
      "y": 38,
      "z": -4,
      "name": "Plant_Leaves_Jungle_Max_Support"
    },
    {
      "x": -7,
      "y": 41,
      "z": -4,
      "name": "Plant_Leaves_Jungle_Max_Support"
    },
    {
      "x": -7,
      "y": 42,
      "z": -4,
      "name": "Plant_Leaves_Jungle_Max_Support"
    },
    {
      "x": -7,
      "y": 43,
      "z": -4,
      "name": "Plant_Leaves_Jungle_Max_Support"
    },
    {
      "x": -7,
      "y": 35,
      "z": -3,
      "name": "Plant_Leaves_Jungle_Max_Support"
    },
    {
      "x": -7,
      "y": 36,
      "z": -3,
      "name": "Plant_Leaves_Jungle_Max_Support"
    },
    {
      "x": -7,
      "y": 37,
      "z": -3,
      "name": "Plant_Leaves_Jungle_Max_Support"
    },
    {
      "x": -7,
      "y": 38,
      "z": -3,
      "name": "Plant_Leaves_Jungle_Max_Support"
    },
    {
      "x": -7,
      "y": 39,
      "z": -3,
      "name": "Plant_Leaves_Jungle_Max_Support"
    },
    {
      "x": -7,
      "y": 40,
      "z": -3,
      "name": "Plant_Leaves_Jungle_Max_Support"
    },
    {
      "x": -7,
      "y": 41,
      "z": -3,
      "name": "Plant_Leaves_Jungle_Max_Support"
    },
    {
      "x": -7,
      "y": 42,
      "z": -3,
      "name": "Plant_Leaves_Jungle_Max_Support"
    },
    {
      "x": -7,
      "y": 43,
      "z": -3,
      "name": "Plant_Leaves_Jungle_Max_Support"
    },
    {
      "x": -7,
      "y": 33,
      "z": -2,
      "name": "Plant_Leaves_Jungle_Max_Support"
    },
    {
      "x": -7,
      "y": 34,
      "z": -2,
      "name": "Plant_Leaves_Jungle_Max_Support"
    },
    {
      "x": -7,
      "y": 35,
      "z": -2,
      "name": "Plant_Leaves_Jungle_Max_Support"
    },
    {
      "x": -7,
      "y": 36,
      "z": -2,
      "name": "Plant_Leaves_Jungle_Max_Support"
    },
    {
      "x": -7,
      "y": 37,
      "z": -2,
      "name": "Plant_Leaves_Jungle_Max_Support"
    },
    {
      "x": -7,
      "y": 38,
      "z": -2,
      "name": "Plant_Leaves_Jungle_Max_Support"
    },
    {
      "x": -7,
      "y": 39,
      "z": -2,
      "name": "Plant_Leaves_Jungle_Max_Support"
    },
    {
      "x": -7,
      "y": 41,
      "z": -2,
      "name": "Plant_Leaves_Jungle_Max_Support"
    },
    {
      "x": -7,
      "y": 42,
      "z": -2,
      "name": "Plant_Leaves_Jungle_Max_Support"
    },
    {
      "x": -7,
      "y": 33,
      "z": -1,
      "name": "Wood_Jungle_Trunk_Full"
    },
    {
      "x": -7,
      "y": 34,
      "z": -1,
      "name": "Wood_Jungle_Trunk_Full"
    },
    {
      "x": -7,
      "y": 35,
      "z": -1,
      "name": "Wood_Jungle_Trunk_Full"
    },
    {
      "x": -7,
      "y": 36,
      "z": -1,
      "name": "Plant_Leaves_Jungle_Max_Support"
    },
    {
      "x": -7,
      "y": 37,
      "z": -1,
      "name": "Plant_Leaves_Jungle_Max_Support"
    },
    {
      "x": -7,
      "y": 38,
      "z": -1,
      "name": "Plant_Leaves_Jungle_Max_Support"
    },
    {
      "x": -7,
      "y": 39,
      "z": -1,
      "name": "Plant_Leaves_Jungle_Max_Support"
    },
    {
      "x": -7,
      "y": 40,
      "z": -1,
      "name": "Plant_Leaves_Jungle_Max_Support"
    },
    {
      "x": -7,
      "y": 41,
      "z": -1,
      "name": "Plant_Leaves_Jungle_Max_Support"
    },
    {
      "x": -7,
      "y": 44,
      "z": -1,
      "name": "Plant_Leaves_Jungle_Max_Support"
    },
    {
      "x": -7,
      "y": 47,
      "z": -1,
      "name": "Plant_Leaves_Jungle_Max_Support"
    },
    {
      "x": -7,
      "y": 34,
      "z": 0,
      "name": "Wood_Jungle_Trunk_Full"
    },
    {
      "x": -7,
      "y": 35,
      "z": 0,
      "name": "Wood_Jungle_Trunk_Full"
    },
    {
      "x": -7,
      "y": 36,
      "z": 0,
      "name": "Plant_Leaves_Jungle_Max_Support"
    },
    {
      "x": -7,
      "y": 37,
      "z": 0,
      "name": "Plant_Leaves_Jungle_Max_Support"
    },
    {
      "x": -7,
      "y": 38,
      "z": 0,
      "name": "Plant_Leaves_Jungle_Max_Support"
    },
    {
      "x": -7,
      "y": 39,
      "z": 0,
      "name": "Plant_Leaves_Jungle_Max_Support"
    },
    {
      "x": -7,
      "y": 40,
      "z": 0,
      "name": "Plant_Leaves_Jungle_Max_Support"
    },
    {
      "x": -7,
      "y": 41,
      "z": 0,
      "name": "Plant_Leaves_Jungle_Max_Support"
    },
    {
      "x": -7,
      "y": 42,
      "z": 0,
      "name": "Plant_Leaves_Jungle_Max_Support"
    },
    {
      "x": -7,
      "y": 43,
      "z": 0,
      "name": "Plant_Leaves_Jungle_Max_Support"
    },
    {
      "x": -7,
      "y": 46,
      "z": 0,
      "name": "Plant_Leaves_Jungle_Max_Support"
    },
    {
      "x": -7,
      "y": 47,
      "z": 0,
      "name": "Plant_Leaves_Jungle_Max_Support"
    },
    {
      "x": -7,
      "y": 48,
      "z": 0,
      "name": "Plant_Leaves_Jungle_Max_Support"
    },
    {
      "x": -7,
      "y": 35,
      "z": 1,
      "name": "Plant_Leaves_Jungle_Max_Support"
    },
    {
      "x": -7,
      "y": 37,
      "z": 1,
      "name": "Plant_Leaves_Jungle_Max_Support"
    },
    {
      "x": -7,
      "y": 38,
      "z": 1,
      "name": "Plant_Leaves_Jungle_Max_Support"
    },
    {
      "x": -7,
      "y": 39,
      "z": 1,
      "name": "Plant_Leaves_Jungle_Max_Support"
    },
    {
      "x": -7,
      "y": 40,
      "z": 1,
      "name": "Plant_Leaves_Jungle_Max_Support"
    },
    {
      "x": -7,
      "y": 45,
      "z": 1,
      "name": "Plant_Leaves_Jungle_Max_Support"
    },
    {
      "x": -7,
      "y": 46,
      "z": 1,
      "name": "Plant_Leaves_Jungle_Max_Support"
    },
    {
      "x": -7,
      "y": 47,
      "z": 1,
      "name": "Plant_Leaves_Jungle_Max_Support"
    },
    {
      "x": -7,
      "y": 48,
      "z": 1,
      "name": "Plant_Leaves_Jungle_Max_Support"
    },
    {
      "x": -7,
      "y": 49,
      "z": 1,
      "name": "Plant_Leaves_Jungle_Max_Support"
    },
    {
      "x": -7,
      "y": 35,
      "z": 2,
      "name": "Wood_Jungle_Trunk_Full"
    },
    {
      "x": -7,
      "y": 36,
      "z": 2,
      "name": "Plant_Leaves_Jungle_Max_Support"
    },
    {
      "x": -7,
      "y": 37,
      "z": 2,
      "name": "Plant_Leaves_Jungle_Max_Support"
    },
    {
      "x": -7,
      "y": 38,
      "z": 2,
      "name": "Plant_Leaves_Jungle_Max_Support"
    },
    {
      "x": -7,
      "y": 39,
      "z": 2,
      "name": "Plant_Leaves_Jungle_Max_Support"
    },
    {
      "x": -7,
      "y": 41,
      "z": 2,
      "name": "Plant_Leaves_Jungle_Max_Support"
    },
    {
